,ts_recv,ts_event,rtype,publisher_id,instrument_id,action,side,depth,price,size,flags,ts_in_delta,sequence,bid_px_00,bid_sz_00,bid_ct_00,ask_px_00,ask_sz_00,ask_ct_00,bid_px_01,bid_sz_01,bid_ct_01,ask_px_01,ask_sz_01,ask_ct_01,bid_px_02,bid_sz_02,bid_ct_02,ask_px_02,ask_sz_02,ask_ct_02,bid_px_03,bid_sz_03,bid_ct_03,ask_px_03,ask_sz_03,ask_ct_03,bid_px_04,bid_sz_04,bid_ct_04,ask_px_04,ask_sz_04,ask_ct_04,bid_px_05,bid_sz_05,bid_ct_05,ask_px_05,ask_sz_05,ask_ct_05,bid_px_06,bid_sz_06,bid_ct_06,ask_px_06,ask_sz_06,ask_ct_06,bid_px_07,bid_sz_07,bid_ct_07,ask_px_07,ask_sz_07,ask_ct_07,bid_px_08,bid_sz_08,bid_ct_08,ask_px_08,ask_sz_08,ask_ct_08,bid_px_09,bid_sz_09,bid_ct_09,ask_px_09,ask_sz_09,ask_ct_09,symbol,order_id
422,2025-07-17T13:30:43.953528491Z,2025-07-17T13:30:43.953363128Z,160,2,1108,A,A,0,13.40000000,24,130,165363,33659657,13.25000000,11,1,13.20000000,28,1,12.99000000,100,1,12.73000000,100,1,12.67000000,100,1,12.47000000,100,1,12.46000000,100,1,12.42000000,700,1,12.37000000,700,1,12.36000000,200,2,13.40000000,56,4,13.67000000,100,1,13.93000000,100,1,14.00000000,100,1,14.20000000,200,2,14.26000000,700,1,14.27000000,700,1,14.29000000,200,2,14.34000000,200,2,14.43000000,2,1,ARL,46613073
423,2025-07-17T13:30:47.814275253Z,2025-07-17T13:30:47.814108950Z,160,2,1108,A,A,0,13.40000000,10,130,166303,34075767,13.25000000,11,1,13.20000000,28,1,12.99000000,100,1,12.73000000,100,1,12.67000000,100,1,12.47000000,100,1,12.46000000,100,1,12.42000000,700,1,12.37000000,700,1,12.36000000,200,2,13.40000000,66,5,13.67000000,100,1,13.93000000,100,1,14.00000000,100,1,14.20000000,200,2,14.26000000,700,1,14.27000000,700,1,14.29000000,200,2,14.34000000,200,2,14.43000000,2,1,ARL,46784085
424,2025-07-17T13:30:48.271777831Z,2025-07-17T13:30:48.271611303Z,160,2,1108,C,A,0,13.40000000,10,130,166528,34129837,13.25000000,11,1,13.20000000,28,1,12.99000000,100,1,12.73000000,100,1,12.67000000,100,1,12.47000000,100,1,12.46000000,100,1,12.42000000,700,1,12.37000000,700,1,12.36000000,200,2,13.40000000,66,5,13.67000000,100,1,13.93000000,100,1,14.00000000,100,1,14.20000000,200,2,14.26000000,700,1,14.27000000,700,1,14.29000000,200,2,14.34000000,200,2,14.43000000,2,1,ARL,46784085
425,2025-07-17T13:30:56.518448581Z,2025-07-17T13:30:56.518283181Z,160,2,1108,A,A,0,13.40000000,10,130,165400,34951153,13.25000000,11,1,13.20000000,28,1,12.99000000,100,1,12.73000000,100,1,12.67000000,100,1,12.47000000,100,1,12.46000000,100,1,12.42000000,700,1,12.37000000,700,1,12.36000000,200,2,13.40000000,76,6,13.67000000,100,1,13.93000000,100,1,14.00000000,100,1,14.20000000,200,2,14.26000000,700,1,14.27000000,700,1,14.29000000,200,2,14.34000000,200,2,14.43000000,2,1,ARL,47164169
426,2025-07-17T13:31:01.011909405Z,2025-07-17T13:31:01.011743292Z,160,2,1108,A,A,0,14.20000000,700,128,166113,35180694,13.25000000,11,1,13.20000000,28,1,12.99000000,100,1,12.73000000,100,1,12.67000000,100,1,12.47000000,100,1,12.46000000,100,1,12.42000000,700,1,12.37000000,700,1,12.36000000,200,2,13.40000000,76,6,13.67000000,100,1,13.93000000,100,1,14.00000000,100,1,14.20000000,900,3,14.26000000,700,1,14.27000000,700,1,14.29000000,200,2,14.34000000,200,2,14.43000000,2,1,ARL,47376925
427,2025-07-17T13:31:01.029013770Z,2025-07-17T13:31:01.028848502Z,160,2,1108,A,B,0,12.43000000,700,130,165268,35188622,13.25000000,11,1,13.20000000,28,1,12.99000000,100,1,12.73000000,100,1,12.67000000,100,1,12.47000000,100,1,12.46000000,100,1,12.43000000,700,1,12.42000000,700,1,12.37000000,700,1,13.40000000,76,6,13.67000000,100,1,13.93000000,100,1,14.00000000,100,1,14.20000000,900,3,14.26000000,700,1,14.27000000,700,1,14.29000000,200,2,14.34000000,200,2,14.43000000,2,1,ARL,47383873
428,2025-07-17T13:31:01.131725810Z,2025-07-17T13:31:01.131557345Z,160,2,1108,C,A,0,13.40000000,10,128,168465,35203355,13.25000000,11,1,13.20000000,28,1,12.99000000,100,1,12.73000000,100,1,12.67000000,100,1,12.47000000,100,1,12.46000000,100,1,12.43000000,700,1,12.42000000,700,1,12.37000000,700,1,13.40000000,76,6,13.67000000,100,1,13.93000000,100,1,14.00000000,100,1,14.20000000,900,3,14.26000000,700,1,14.27000000,700,1,14.29000000,200,2,14.34000000,200,2,14.43000000,2,1,ARL,47164169
429,2025-07-17T13:31:08.376486633Z,2025-07-17T13:31:08.376321454Z,160,2,1108,C,A,0,13.40000000,24,130,165179,35703639,13.25000000,11,1,13.20000000,28,1,12.99000000,100,1,12.73000000,100,1,12.67000000,100,1,12.47000000,100,1,12.46000000,100,1,12.43000000,700,1,12.42000000,700,1,12.37000000,700,1,13.40000000,76,6,13.67000000,100,1,13.93000000,100,1,14.00000000,100,1,14.20000000,900,3,14.26000000,700,1,14.27000000,700,1,14.29000000,200,2,14.34000000,200,2,14.43000000,2,1,ARL,46613073
430,2025-07-17T13:31:08.376858048Z,2025-07-17T13:31:08.376692815Z,160,2,1108,A,A,0,13.40000000,18,130,165233,35703653,13.25000000,11,1,13.20000000,28,1,12.99000000,100,1,12.73000000,100,1,12.67000000,100,1,12.47000000,100,1,12.46000000,100,1,12.43000000,700,1,12.42000000,700,1,12.37000000,700,1,13.40000000,94,7,13.67000000,100,1,13.93000000,100,1,14.00000000,100,1,14.20000000,900,3,14.26000000,700,1,14.27000000,700,1,14.29000000,200,2,14.34000000,200,2,14.43000000,2,1,ARL,47873813
431,2025-07-17T13:31:08.377188468Z,2025-07-17T13:31:08.377022927Z,160,2,1108,C,A,0,14.29000000,100,0,165541,35703666,13.25000000,11,1,13.20000000,28,1,12.99000000,100,1,12.73000000,100,1,12.67000000,100,1,12.47000000,100,1,12.46000000,100,1,12.43000000,700,1,12.42000000,700,1,12.37000000,700,1,13.40000000,94,7,13.67000000,100,1,13.93000000,100,1,14.00000000,100,1,14.20000000,900,3,14.26000000,700,1,14.27000000,700,1,14.29000000,200,2,14.34000000,200,2,14.43000000,2,1,ARL,44720033
432,2025-07-17T13:31:08.377188468Z,2025-07-17T13:31:08.377022927Z,160,2,1108,A,A,0,14.56000000,100,130,165541,35703666,13.25000000,11,1,13.20000000,28,1,12.99000000,100,1,12.73000000,100,1,12.67000000,100,1,12.47000000,100,1,12.46000000,100,1,12.43000000,700,1,12.42000000,700,1,12.37000000,700,1,13.40000000,94,7,13.67000000,100,1,13.93000000,100,1,14.00000000,100,1,14.20000000,900,3,14.26000000,700,1,14.27000000,700,1,14.29000000,200,2,14.34000000,200,2,14.43000000,2,1,ARL,47873821
433,2025-07-17T13:31:09.400094773Z,2025-07-17T13:31:09.399928944Z,160,2,1108,C,A,0,14.56000000,100,0,165829,35758774,13.25000000,11,1,13.20000000,28,1,12.99000000,100,1,12.73000000,100,1,12.67000000,100,1,12.47000000,100,1,12.46000000,100,1,12.43000000,700,1,12.42000000,700,1,12.37000000,700,1,13.40000000,94,7,13.67000000,100,1,13.93000000,100,1,14.00000000,100,1,14.20000000,900,3,14.26000000,700,1,14.27000000,700,1,14.29000000,200,2,14.34000000,200,2,14.43000000,2,1,ARL,47873821
434,2025-07-17T13:31:09.400094773Z,2025-07-17T13:31:09.399928944Z,160,2,1108,A,A,0,14.29000000,100,130,165829,35758774,13.25000000,11,1,13.20000000,28,1,12.99000000,100,1,12.73000000,100,1,12.67000000,100,1,12.47000000,100,1,12.46000000,100,1,12.43000000,700,1,12.42000000,700,1,12.37000000,700,1,13.40000000,94,7,13.67000000,100,1,13.93000000,100,1,14.00000000,100,1,14.20000000,900,3,14.26000000,700,1,14.27000000,700,1,14.29000000,300,3,14.34000000,200,2,14.43000000,2,1,ARL,47927629
435,2025-07-17T13:31:16.539042057Z,2025-07-17T13:31:16.538876621Z,160,2,1108,A,A,0,13.40000000,10,130,165436,36186495,13.25000000,11,1,13.20000000,28,1,12.99000000,100,1,12.73000000,100,1,12.67000000,100,1,12.47000000,100,1,12.46000000,100,1,12.43000000,700,1,12.42000000,700,1,12.37000000,700,1,13.40000000,104,8,13.67000000,100,1,13.93000000,100,1,14.00000000,100,1,14.20000000,900,3,14.26000000,700,1,14.27000000,700,1,14.29000000,300,3,14.34000000,200,2,14.43000000,2,1,ARL,48315949
436,2025-07-17T13:31:17.448727976Z,2025-07-17T13:31:17.448559991Z,160,2,1108,C,A,0,13.40000000,10,128,167985,36232894,13.25000000,11,1,13.20000000,28,1,12.99000000,100,1,12.73000000,100,1,12.67000000,100,1,12.47000000,100,1,12.46000000,100,1,12.43000000,700,1,12.42000000,700,1,12.37000000,700,1,13.40000000,104,8,13.67000000,100,1,13.93000000,100,1,14.00000000,100,1,14.20000000,900,3,14.26000000,700,1,14.27000000,700,1,14.29000000,300,3,14.34000000,200,2,14.43000000,2,1,ARL,48315949
437,2025-07-17T13:31:34.836102962Z,2025-07-17T13:31:34.835937627Z,160,2,1108,C,A,0,13.40000000,18,130,165335,37177882,13.25000000,11,1,13.20000000,28,1,12.99000000,100,1,12.73000000,100,1,12.67000000,100,1,12.47000000,100,1,12.46000000,100,1,12.43000000,700,1,12.42000000,700,1,12.37000000,700,1,13.40000000,104,8,13.67000000,100,1,13.93000000,100,1,14.00000000,100,1,14.20000000,900,3,14.26000000,700,1,14.27000000,700,1,14.29000000,300,3,14.34000000,200,2,14.43000000,2,1,ARL,47873813
438,2025-07-17T13:31:34.836860858Z,2025-07-17T13:31:34.836694504Z,160,2,1108,C,A,0,14.29000000,100,0,166354,37177896,13.25000000,11,1,13.20000000,28,1,12.99000000,100,1,12.73000000,100,1,12.67000000,100,1,12.47000000,100,1,12.46000000,100,1,12.43000000,700,1,12.42000000,700,1,12.37000000,700,1,13.40000000,104,8,13.67000000,100,1,13.93000000,100,1,14.00000000,100,1,14.20000000,900,3,14.26000000,700,1,14.27000000,700,1,14.29000000,300,3,14.34000000,200,2,14.43000000,2,1,ARL,44719985
439,2025-07-17T13:31:34.836860858Z,2025-07-17T13:31:34.836694504Z,160,2,1108,A,A,0,14.56000000,100,130,166354,37177896,13.25000000,11,1,13.20000000,28,1,12.99000000,100,1,12.73000000,100,1,12.67000000,100,1,12.47000000,100,1,12.46000000,100,1,12.43000000,700,1,12.42000000,700,1,12.37000000,700,1,13.40000000,104,8,13.67000000,100,1,13.93000000,100,1,14.00000000,100,1,14.20000000,900,3,14.26000000,700,1,14.27000000,700,1,14.29000000,300,3,14.34000000,200,2,14.43000000,2,1,ARL,49226081
440,2025-07-17T13:31:34.837265065Z,2025-07-17T13:31:34.837099615Z,160,2,1108,C,A,0,14.29000000,100,0,165450,37177905,13.25000000,11,1,13.20000000,28,1,12.99000000,100,1,12.73000000,100,1,12.67000000,100,1,12.47000000,100,1,12.46000000,100,1,12.43000000,700,1,12.42000000,700,1,12.37000000,700,1,13.40000000,104,8,13.67000000,100,1,13.93000000,100,1,14.00000000,100,1,14.20000000,900,3,14.26000000,700,1,14.27000000,700,1,14.29000000,300,3,14.34000000,200,2,14.43000000,2,1,ARL,47927629
441,2025-07-17T13:31:34.837265065Z,2025-07-17T13:31:34.837099615Z,160,2,1108,A,A,0,14.56000000,100,130,165450,37177905,13.25000000,11,1,13.20000000,28,1,12.99000000,100,1,12.73000000,100,1,12.67000000,100,1,12.47000000,100,1,12.46000000,100,1,12.43000000,700,1,12.42000000,700,1,12.37000000,700,1,13.40000000,104,8,13.67000000,100,1,13.93000000,100,1,14.00000000,100,1,14.20000000,900,3,14.26000000,700,1,14.27000000,700,1,14.29000000,300,3,14.34000000,200,2,14.43000000,2,1,ARL,49226101
442,2025-07-17T13:35:00.187694195Z,2025-07-17T13:35:00.187526221Z,160,2,1108,C,B,0,12.33000000,2,0,167974,45447658,13.25000000,11,1,13.20000000,28,1,12.99000000,100,1,12.73000000,100,1,12.67000000,100,1,12.47000000,100,1,12.46000000,100,1,12.43000000,700,1,12.42000000,700,1,12.37000000,700,1,13.40000000,104,8,13.67000000,100,1,13.93000000,100,1,14.00000000,100,1,14.20000000,900,3,14.26000000,700,1,14.27000000,700,1,14.29000000,300,3,14.34000000,200,2,14.43000000,2,1,ARL,43692153
443,2025-07-17T13:35:00.187694195Z,2025-07-17T13:35:00.187526221Z,160,2,1108,A,B,0,12.88000000,2,128,167974,45447658,13.25000000,11,1,13.20000000,28,1,12.99000000,100,1,12.88000000,2,1,12.73000000,100,1,12.67000000,100,1,12.47000000,100,1,12.46000000,100,1,12.43000000,700,1,12.42000000,700,1,13.40000000,104,8,13.67000000,100,1,13.93000000,100,1,14.00000000,100,1,14.20000000,900,3,14.26000000,700,1,14.27000000,700,1,14.29000000,300,3,14.34000000,200,2,14.43000000,2,1,ARL,58709193
444,2025-07-17T13:35:00.187694720Z,2025-07-17T13:35:00.187528642Z,160,2,1108,C,A,0,14.43000000,2,0,166078,45447661,13.25000000,11,1,13.20000000,28,1,12.99000000,100,1,12.88000000,2,1,12.73000000,100,1,12.67000000,100,1,12.47000000,100,1,12.46000000,100,1,12.43000000,700,1,12.42000000,700,1,13.40000000,104,8,13.67000000,100,1,13.93000000,100,1,14.00000000,100,1,14.20000000,900,3,14.26000000,700,1,14.27000000,700,1,14.29000000,300,3,14.34000000,200,2,14.43000000,2,1,ARL,44904733
445,2025-07-17T13:35:00.187694720Z,2025-07-17T13:35:00.187528642Z,160,2,1108,A,A,0,13.78000000,2,130,166078,45447661,13.25000000,11,1,13.20000000,28,1,12.99000000,100,1,12.88000000,2,1,12.73000000,100,1,12.67000000,100,1,12.47000000,100,1,12.46000000,100,1,12.43000000,700,1,12.42000000,700,1,13.40000000,104,8,13.67000000,100,1,13.78000000,2,1,13.93000000,100,1,14.00000000,100,1,14.20000000,900,3,14.26000000,700,1,14.27000000,700,1,14.29000000,300,3,14.34000000,200,2,ARL,58709197
446,2025-07-17T13:37:31.076320046Z,2025-07-17T13:37:31.076154614Z,160,2,1108,C,A,0,14.56000000,100,0,165432,51978366,13.25000000,11,1,13.20000000,28,1,12.99000000,100,1,12.88000000,2,1,12.73000000,100,1,12.67000000,100,1,12.47000000,100,1,12.46000000,100,1,12.43000000,700,1,12.42000000,700,1,13.40000000,104,8,13.67000000,100,1,13.78000000,2,1,13.93000000,100,1,14.00000000,100,1,14.20000000,900,3,14.26000000,700,1,14.27000000,700,1,14.29000000,300,3,14.34000000,200,2,ARL,49226101
447,2025-07-17T13:37:31.076320046Z,2025-07-17T13:37:31.076154614Z,160,2,1108,A,A,0,14.29000000,100,130,165432,51978366,13.25000000,11,1,13.20000000,28,1,12.99000000,100,1,12.88000000,2,1,12.73000000,100,1,12.67000000,100,1,12.47000000,100,1,12.46000000,100,1,12.43000000,700,1,12.42000000,700,1,13.40000000,104,8,13.67000000,100,1,13.78000000,2,1,13.93000000,100,1,14.00000000,100,1,14.20000000,900,3,14.26000000,700,1,14.27000000,700,1,14.29000000,400,4,14.34000000,200,2,ARL,65160189
448,2025-07-17T13:37:31.076496403Z,2025-07-17T13:37:31.076330756Z,160,2,1108,C,A,0,14.56000000,100,0,165647,51978372,13.25000000,11,1,13.20000000,28,1,12.99000000,100,1,12.88000000,2,1,12.73000000,100,1,12.67000000,100,1,12.47000000,100,1,12.46000000,100,1,12.43000000,700,1,12.42000000,700,1,13.40000000,104,8,13.67000000,100,1,13.78000000,2,1,13.93000000,100,1,14.00000000,100,1,14.20000000,900,3,14.26000000,700,1,14.27000000,700,1,14.29000000,400,4,14.34000000,200,2,ARL,49226081
449,2025-07-17T13:37:31.076496403Z,2025-07-17T13:37:31.076330756Z,160,2,1108,A,A,0,14.29000000,100,130,165647,51978372,13.25000000,11,1,13.20000000,28,1,12.99000000,100,1,12.88000000,2,1,12.73000000,100,1,12.67000000,100,1,12.47000000,100,1,12.46000000,100,1,12.43000000,700,1,12.42000000,700,1,13.40000000,104,8,13.67000000,100,1,13.78000000,2,1,13.93000000,100,1,14.00000000,100,1,14.20000000,900,3,14.26000000,700,1,14.27000000,700,1,14.29000000,500,5,14.34000000,200,2,ARL,65160193
450,2025-07-17T13:38:08.679910189Z,2025-07-17T13:38:08.679744459Z,160,2,1108,C,A,0,14.29000000,100,0,165730,53264917,13.25000000,11,1,13.20000000,28,1,12.99000000,100,1,12.88000000,2,1,12.73000000,100,1,12.67000000,100,1,12.47000000,100,1,12.46000000,100,1,12.43000000,700,1,12.42000000,700,1,13.40000000,104,8,13.67000000,100,1,13.78000000,2,1,13.93000000,100,1,14.00000000,100,1,14.20000000,900,3,14.26000000,700,1,14.27000000,700,1,14.29000000,500,5,14.34000000,200,2,ARL,65160189
451,2025-07-17T13:38:08.679910189Z,2025-07-17T13:38:08.679744459Z,160,2,1108,A,A,0,14.56000000,100,130,165730,53264917,13.25000000,11,1,13.20000000,28,1,12.99000000,100,1,12.88000000,2,1,12.73000000,100,1,12.67000000,100,1,12.47000000,100,1,12.46000000,100,1,12.43000000,700,1,12.42000000,700,1,13.40000000,104,8,13.67000000,100,1,13.78000000,2,1,13.93000000,100,1,14.00000000,100,1,14.20000000,900,3,14.26000000,700,1,14.27000000,700,1,14.29000000,500,5,14.34000000,200,2,ARL,66501333
452,2025-07-17T13:38:08.679917832Z,2025-07-17T13:38:08.679752190Z,160,2,1108,C,A,0,14.29000000,100,0,165642,53264918,13.25000000,11,1,13.20000000,28,1,12.99000000,100,1,12.88000000,2,1,12.73000000,100,1,12.67000000,100,1,12.47000000,100,1,12.46000000,100,1,12.43000000,700,1,12.42000000,700,1,13.40000000,104,8,13.67000000,100,1,13.78000000,2,1,13.93000000,100,1,14.00000000,100,1,14.20000000,900,3,14.26000000,700,1,14.27000000,700,1,14.29000000,500,5,14.34000000,200,2,ARL,65160193
453,2025-07-17T13:38:08.679917832Z,2025-07-17T13:38:08.679752190Z,160,2,1108,A,A,0,14.56000000,100,130,165642,53264918,13.25000000,11,1,13.20000000,28,1,12.99000000,100,1,12.88000000,2,1,12.73000000,100,1,12.67000000,100,1,12.47000000,100,1,12.46000000,100,1,12.43000000,700,1,12.42000000,700,1,13.40000000,104,8,13.67000000,100,1,13.78000000,2,1,13.93000000,100,1,14.00000000,100,1,14.20000000,900,3,14.26000000,700,1,14.27000000,700,1,14.29000000,500,5,14.34000000,200,2,ARL,66501341
454,2025-07-17T13:38:09.687028970Z,2025-07-17T13:38:09.686863512Z,160,2,1108,C,A,0,14.56000000,100,0,165458,53302839,13.25000000,11,1,13.20000000,28,1,12.99000000,100,1,12.88000000,2,1,12.73000000,100,1,12.67000000,100,1,12.47000000,100,1,12.46000000,100,1,12.43000000,700,1,12.42000000,700,1,13.40000000,104,8,13.67000000,100,1,13.78000000,2,1,13.93000000,100,1,14.00000000,100,1,14.20000000,900,3,14.26000000,700,1,14.27000000,700,1,14.29000000,500,5,14.34000000,200,2,ARL,66501333
455,2025-07-17T13:38:09.687028970Z,2025-07-17T13:38:09.686863512Z,160,2,1108,A,A,0,14.29000000,100,130,165458,53302839,13.25000000,11,1,13.20000000,28,1,12.99000000,100,1,12.88000000,2,1,12.73000000,100,1,12.67000000,100,1,12.47000000,100,1,12.46000000,100,1,12.43000000,700,1,12.42000000,700,1,13.40000000,104,8,13.67000000,100,1,13.78000000,2,1,13.93000000,100,1,14.00000000,100,1,14.20000000,900,3,14.26000000,700,1,14.27000000,700,1,14.29000000,600,6,14.34000000,200,2,ARL,66538149
456,2025-07-17T13:38:09.708195003Z,2025-07-17T13:38:09.708029202Z,160,2,1108,C,A,0,14.56000000,100,0,165801,53303094,13.25000000,11,1,13.20000000,28,1,12.99000000,100,1,12.88000000,2,1,12.73000000,100,1,12.67000000,100,1,12.47000000,100,1,12.46000000,100,1,12.43000000,700,1,12.42000000,700,1,13.40000000,104,8,13.67000000,100,1,13.78000000,2,1,13.93000000,100,1,14.00000000,100,1,14.20000000,900,3,14.26000000,700,1,14.27000000,700,1,14.29000000,600,6,14.34000000,200,2,ARL,66501341
457,2025-07-17T13:38:09.708195003Z,2025-07-17T13:38:09.708029202Z,160,2,1108,A,A,0,14.29000000,100,130,165801,53303094,13.25000000,11,1,13.20000000,28,1,12.99000000,100,1,12.88000000,2,1,12.73000000,100,1,12.67000000,100,1,12.47000000,100,1,12.46000000,100,1,12.43000000,700,1,12.42000000,700,1,13.40000000,104,8,13.67000000,100,1,13.78000000,2,1,13.93000000,100,1,14.00000000,100,1,14.20000000,900,3,14.26000000,700,1,14.27000000,700,1,14.29000000,700,7,14.34000000,200,2,ARL,66538573
458,2025-07-17T13:38:44.679122862Z,2025-07-17T13:38:44.678957477Z,160,2,1108,A,A,0,13.40000000,15,130,165385,54485050,13.25000000,11,1,13.20000000,28,1,12.99000000,100,1,12.88000000,2,1,12.73000000,100,1,12.67000000,100,1,12.47000000,100,1,12.46000000,100,1,12.43000000,700,1,12.42000000,700,1,13.40000000,119,9,13.67000000,100,1,13.78000000,2,1,13.93000000,100,1,14.00000000,100,1,14.20000000,900,3,14.26000000,700,1,14.27000000,700,1,14.29000000,700,7,14.34000000,200,2,ARL,67832461
459,2025-07-17T13:38:44.679444346Z,2025-07-17T13:38:44.679278833Z,160,2,1108,C,A,0,14.29000000,100,0,165513,54485052,13.25000000,11,1,13.20000000,28,1,12.99000000,100,1,12.88000000,2,1,12.73000000,100,1,12.67000000,100,1,12.47000000,100,1,12.46000000,100,1,12.43000000,700,1,12.42000000,700,1,13.40000000,119,9,13.67000000,100,1,13.78000000,2,1,13.93000000,100,1,14.00000000,100,1,14.20000000,900,3,14.26000000,700,1,14.27000000,700,1,14.29000000,700,7,14.34000000,200,2,ARL,66538149
460,2025-07-17T13:38:44.679444346Z,2025-07-17T13:38:44.679278833Z,160,2,1108,A,A,0,14.56000000,100,130,165513,54485052,13.25000000,11,1,13.20000000,28,1,12.99000000,100,1,12.88000000,2,1,12.73000000,100,1,12.67000000,100,1,12.47000000,100,1,12.46000000,100,1,12.43000000,700,1,12.42000000,700,1,13.40000000,119,9,13.67000000,100,1,13.78000000,2,1,13.93000000,100,1,14.00000000,100,1,14.20000000,900,3,14.26000000,700,1,14.27000000,700,1,14.29000000,700,7,14.34000000,200,2,ARL,67832465
461,2025-07-17T13:38:45.695430520Z,2025-07-17T13:38:45.695265148Z,160,2,1108,C,A,0,14.56000000,100,0,165372,54508575,13.25000000,11,1,13.20000000,28,1,12.99000000,100,1,12.88000000,2,1,12.73000000,100,1,12.67000000,100,1,12.47000000,100,1,12.46000000,100,1,12.43000000,700,1,12.42000000,700,1,13.40000000,119,9,13.67000000,100,1,13.78000000,2,1,13.93000000,100,1,14.00000000,100,1,14.20000000,900,3,14.26000000,700,1,14.27000000,700,1,14.29000000,700,7,14.34000000,200,2,ARL,67832465
462,2025-07-17T13:38:45.695430520Z,2025-07-17T13:38:45.695265148Z,160,2,1108,A,A,0,14.29000000,100,130,165372,54508575,13.25000000,11,1,13.20000000,28,1,12.99000000,100,1,12.88000000,2,1,12.73000000,100,1,12.67000000,100,1,12.47000000,100,1,12.46000000,100,1,12.43000000,700,1,12.42000000,700,1,13.40000000,119,9,13.67000000,100,1,13.78000000,2,1,13.93000000,100,1,14.00000000,100,1,14.20000000,900,3,14.26000000,700,1,14.27000000,700,1,14.29000000,800,8,14.34000000,200,2,ARL,67857641
463,2025-07-17T13:39:08.714072882Z,2025-07-17T13:39:08.713907562Z,160,2,1108,C,A,0,13.40000000,15,130,165320,55204868,13.25000000,11,1,13.20000000,28,1,12.99000000,100,1,12.88000000,2,1,12.73000000,100,1,12.67000000,100,1,12.47000000,100,1,12.46000000,100,1,12.43000000,700,1,12.42000000,700,1,13.40000000,119,9,13.67000000,100,1,13.78000000,2,1,13.93000000,100,1,14.00000000,100,1,14.20000000,900,3,14.26000000,700,1,14.27000000,700,1,14.29000000,800,8,14.34000000,200,2,ARL,67832461
464,2025-07-17T13:39:08.714449550Z,2025-07-17T13:39:08.714284059Z,160,2,1108,A,A,0,13.40000000,24,130,165491,55204884,13.25000000,11,1,13.20000000,28,1,12.99000000,100,1,12.88000000,2,1,12.73000000,100,1,12.67000000,100,1,12.47000000,100,1,12.46000000,100,1,12.43000000,700,1,12.42000000,700,1,13.40000000,143,10,13.67000000,100,1,13.78000000,2,1,13.93000000,100,1,14.00000000,100,1,14.20000000,900,3,14.26000000,700,1,14.27000000,700,1,14.29000000,800,8,14.34000000,200,2,ARL,68625181
465,2025-07-17T13:39:39.996603180Z,2025-07-17T13:39:39.996436857Z,160,2,1108,T,B,0,13.40000000,1,130,166323,56150102,13.25000000,11,1,13.20000000,28,1,12.99000000,100,1,12.88000000,2,1,12.73000000,100,1,12.67000000,100,1,12.47000000,100,1,12.46000000,100,1,12.43000000,700,1,12.42000000,700,1,13.40000000,142,9,13.67000000,100,1,13.78000000,2,1,13.93000000,100,1,14.00000000,100,1,14.20000000,900,3,14.26000000,700,1,14.27000000,700,1,14.29000000,800,8,14.34000000,200,2,ARL,0
466,2025-07-17T13:39:39.996603180Z,2025-07-17T13:39:39.996436857Z,160,2,1108,F,A,0,13.40000000,1,130,166323,56150102,13.25000000,11,1,13.20000000,28,1,12.99000000,100,1,12.88000000,2,1,12.73000000,100,1,12.67000000,100,1,12.47000000,100,1,12.46000000,100,1,12.43000000,700,1,12.42000000,700,1,13.40000000,142,9,13.67000000,100,1,13.78000000,2,1,13.93000000,100,1,14.00000000,100,1,14.20000000,900,3,14.26000000,700,1,14.27000000,700,1,14.29000000,800,8,14.34000000,200,2,ARL,68625181
467,2025-07-17T13:39:39.996603180Z,2025-07-17T13:39:39.996436857Z,160,2,1108,C,A,0,13.40000000,1,130,166323,56150102,13.25000000,11,1,13.20000000,28,1,12.99000000,100,1,12.88000000,2,1,12.73000000,100,1,12.67000000,100,1,12.47000000,100,1,12.46000000,100,1,12.43000000,700,1,12.42000000,700,1,13.40000000,142,9,13.67000000,100,1,13.78000000,2,1,13.93000000,100,1,14.00000000,100,1,14.20000000,900,3,14.26000000,700,1,14.27000000,700,1,14.29000000,800,8,14.34000000,200,2,ARL,68625181
468,2025-07-17T13:39:39.996998334Z,2025-07-17T13:39:39.996833282Z,160,2,1108,C,A,0,13.40000000,23,130,165052,56150114,13.25000000,11,1,13.20000000,28,1,12.99000000,100,1,12.88000000,2,1,12.73000000,100,1,12.67000000,100,1,12.47000000,100,1,12.46000000,100,1,12.43000000,700,1,12.42000000,700,1,13.40000000,142,9,13.67000000,100,1,13.78000000,2,1,13.93000000,100,1,14.00000000,100,1,14.20000000,900,3,14.26000000,700,1,14.27000000,700,1,14.29000000,800,8,14.34000000,200,2,ARL,68625181
469,2025-07-17T13:39:39.997309515Z,2025-07-17T13:39:39.997144158Z,160,2,1108,C,A,0,14.29000000,100,0,165357,56150130,13.25000000,11,1,13.20000000,28,1,12.99000000,100,1,12.88000000,2,1,12.73000000,100,1,12.67000000,100,1,12.47000000,100,1,12.46000000,100,1,12.43000000,700,1,12.42000000,700,1,13.40000000,142,9,13.67000000,100,1,13.78000000,2,1,13.93000000,100,1,14.00000000,100,1,14.20000000,900,3,14.26000000,700,1,14.27000000,700,1,14.29000000,800,8,14.34000000,200,2,ARL,66538573
470,2025-07-17T13:39:39.997309515Z,2025-07-17T13:39:39.997144158Z,160,2,1108,A,A,0,14.57000000,100,130,165357,56150130,13.25000000,11,1,13.20000000,28,1,12.99000000,100,1,12.88000000,2,1,12.73000000,100,1,12.67000000,100,1,12.47000000,100,1,12.46000000,100,1,12.43000000,700,1,12.42000000,700,1,13.40000000,142,9,13.67000000,100,1,13.78000000,2,1,13.93000000,100,1,14.00000000,100,1,14.20000000,900,3,14.26000000,700,1,14.27000000,700,1,14.29000000,800,8,14.34000000,200,2,ARL,69677517
471,2025-07-17T13:39:39.997376873Z,2025-07-17T13:39:39.997211562Z,160,2,1108,A,A,0,13.40000000,24,130,165311,56150131,13.25000000,11,1,13.20000000,28,1,12.99000000,100,1,12.88000000,2,1,12.73000000,100,1,12.67000000,100,1,12.47000000,100,1,12.46000000,100,1,12.43000000,700,1,12.42000000,700,1,13.40000000,166,10,13.67000000,100,1,13.78000000,2,1,13.93000000,100,1,14.00000000,100,1,14.20000000,900,3,14.26000000,700,1,14.27000000,700,1,14.29000000,800,8,14.34000000,200,2,ARL,69677521
472,2025-07-17T13:39:41.018948933Z,2025-07-17T13:39:41.018783466Z,160,2,1108,C,A,0,14.57000000,100,0,165467,56183429,13.25000000,11,1,13.20000000,28,1,12.99000000,100,1,12.88000000,2,1,12.73000000,100,1,12.67000000,100,1,12.47000000,100,1,12.46000000,100,1,12.43000000,700,1,12.42000000,700,1,13.40000000,166,10,13.67000000,100,1,13.78000000,2,1,13.93000000,100,1,14.00000000,100,1,14.20000000,900,3,14.26000000,700,1,14.27000000,700,1,14.29000000,800,8,14.34000000,200,2,ARL,69677517
473,2025-07-17T13:39:41.018948933Z,2025-07-17T13:39:41.018783466Z,160,2,1108,A,A,0,14.30000000,100,130,165467,56183429,13.25000000,11,1,13.20000000,28,1,12.99000000,100,1,12.88000000,2,1,12.73000000,100,1,12.67000000,100,1,12.47000000,100,1,12.46000000,100,1,12.43000000,700,1,12.42000000,700,1,13.40000000,166,10,13.67000000,100,1,13.78000000,2,1,13.93000000,100,1,14.00000000,100,1,14.20000000,900,3,14.26000000,700,1,14.27000000,700,1,14.29000000,800,8,14.30000000,100,1,ARL,69725541
474,2025-07-17T13:40:08.782549047Z,2025-07-17T13:40:08.782383621Z,160,2,1108,C,A,0,13.40000000,24,130,165426,57235944,13.25000000,11,1,13.20000000,28,1,12.99000000,100,1,12.88000000,2,1,12.73000000,100,1,12.67000000,100,1,12.47000000,100,1,12.46000000,100,1,12.43000000,700,1,12.42000000,700,1,13.40000000,166,10,13.67000000,100,1,13.78000000,2,1,13.93000000,100,1,14.00000000,100,1,14.20000000,900,3,14.26000000,700,1,14.27000000,700,1,14.29000000,800,8,14.30000000,100,1,ARL,69677521
475,2025-07-17T13:40:08.782923978Z,2025-07-17T13:40:08.782758499Z,160,2,1108,A,A,0,13.40000000,18,130,165479,57235956,13.25000000,11,1,13.20000000,28,1,12.99000000,100,1,12.88000000,2,1,12.73000000,100,1,12.67000000,100,1,12.47000000,100,1,12.46000000,100,1,12.43000000,700,1,12.42000000,700,1,13.40000000,184,11,13.67000000,100,1,13.78000000,2,1,13.93000000,100,1,14.00000000,100,1,14.20000000,900,3,14.26000000,700,1,14.27000000,700,1,14.29000000,800,8,14.30000000,100,1,ARL,70897053
476,2025-07-17T13:41:08.818876572Z,2025-07-17T13:41:08.818711250Z,160,2,1108,C,A,0,13.40000000,18,130,165322,59313726,13.25000000,11,1,13.20000000,28,1,12.99000000,100,1,12.88000000,2,1,12.73000000,100,1,12.67000000,100,1,12.47000000,100,1,12.46000000,100,1,12.43000000,700,1,12.42000000,700,1,13.40000000,184,11,13.67000000,100,1,13.78000000,2,1,13.93000000,100,1,14.00000000,100,1,14.20000000,900,3,14.26000000,700,1,14.27000000,700,1,14.29000000,800,8,14.30000000,100,1,ARL,70897053
477,2025-07-17T13:41:08.819249545Z,2025-07-17T13:41:08.819083504Z,160,2,1108,A,A,0,13.40000000,24,130,166041,59313736,13.25000000,11,1,13.20000000,28,1,12.99000000,100,1,12.88000000,2,1,12.73000000,100,1,12.67000000,100,1,12.47000000,100,1,12.46000000,100,1,12.43000000,700,1,12.42000000,700,1,13.40000000,208,12,13.67000000,100,1,13.78000000,2,1,13.93000000,100,1,14.00000000,100,1,14.20000000,900,3,14.26000000,700,1,14.27000000,700,1,14.29000000,800,8,14.30000000,100,1,ARL,73109413
478,2025-07-17T13:41:08.819270512Z,2025-07-17T13:41:08.819104931Z,160,2,1108,C,A,0,14.30000000,100,0,165581,59313739,13.25000000,11,1,13.20000000,28,1,12.99000000,100,1,12.88000000,2,1,12.73000000,100,1,12.67000000,100,1,12.47000000,100,1,12.46000000,100,1,12.43000000,700,1,12.42000000,700,1,13.40000000,208,12,13.67000000,100,1,13.78000000,2,1,13.93000000,100,1,14.00000000,100,1,14.20000000,900,3,14.26000000,700,1,14.27000000,700,1,14.29000000,800,8,14.30000000,100,1,ARL,69725541
479,2025-07-17T13:41:08.819270512Z,2025-07-17T13:41:08.819104931Z,160,2,1108,A,A,0,14.57000000,100,130,165581,59313739,13.25000000,11,1,13.20000000,28,1,12.99000000,100,1,12.88000000,2,1,12.73000000,100,1,12.67000000,100,1,12.47000000,100,1,12.46000000,100,1,12.43000000,700,1,12.42000000,700,1,13.40000000,208,12,13.67000000,100,1,13.78000000,2,1,13.93000000,100,1,14.00000000,100,1,14.20000000,900,3,14.26000000,700,1,14.27000000,700,1,14.29000000,800,8,14.30000000,100,1,ARL,73109417
480,2025-07-17T13:41:09.881251193Z,2025-07-17T13:41:09.881085734Z,160,2,1108,C,A,0,14.57000000,100,0,165459,59383199,13.25000000,11,1,13.20000000,28,1,12.99000000,100,1,12.88000000,2,1,12.73000000,100,1,12.67000000,100,1,12.47000000,100,1,12.46000000,100,1,12.43000000,700,1,12.42000000,700,1,13.40000000,208,12,13.67000000,100,1,13.78000000,2,1,13.93000000,100,1,14.00000000,100,1,14.20000000,900,3,14.26000000,700,1,14.27000000,700,1,14.29000000,800,8,14.30000000,100,1,ARL,73109417
481,2025-07-17T13:41:09.881251193Z,2025-07-17T13:41:09.881085734Z,160,2,1108,A,A,0,14.30000000,100,130,165459,59383199,13.25000000,11,1,13.20000000,28,1,12.99000000,100,1,12.88000000,2,1,12.73000000,100,1,12.67000000,100,1,12.47000000,100,1,12.46000000,100,1,12.43000000,700,1,12.42000000,700,1,13.40000000,208,12,13.67000000,100,1,13.78000000,2,1,13.93000000,100,1,14.00000000,100,1,14.20000000,900,3,14.26000000,700,1,14.27000000,700,1,14.29000000,800,8,14.30000000,200,2,ARL,73183421
482,2025-07-17T13:41:44.348660105Z,2025-07-17T13:41:44.348494744Z,160,2,1108,C,A,0,13.40000000,24,130,165361,60614543,13.25000000,11,1,13.20000000,28,1,12.99000000,100,1,12.88000000,2,1,12.73000000,100,1,12.67000000,100,1,12.47000000,100,1,12.46000000,100,1,12.43000000,700,1,12.42000000,700,1,13.40000000,208,12,13.67000000,100,1,13.78000000,2,1,13.93000000,100,1,14.00000000,100,1,14.20000000,900,3,14.26000000,700,1,14.27000000,700,1,14.29000000,800,8,14.30000000,200,2,ARL,73109413
483,2025-07-17T13:41:44.349581977Z,2025-07-17T13:41:44.349416601Z,160,2,1108,C,A,0,14.30000000,100,0,165376,60614557,13.25000000,11,1,13.20000000,28,1,12.99000000,100,1,12.88000000,2,1,12.73000000,100,1,12.67000000,100,1,12.47000000,100,1,12.46000000,100,1,12.43000000,700,1,12.42000000,700,1,13.40000000,208,12,13.67000000,100,1,13.78000000,2,1,13.93000000,100,1,14.00000000,100,1,14.20000000,900,3,14.26000000,700,1,14.27000000,700,1,14.29000000,800,8,14.30000000,200,2,ARL,73183421
484,2025-07-17T13:41:44.349581977Z,2025-07-17T13:41:44.349416601Z,160,2,1108,A,A,0,14.57000000,100,130,165376,60614557,13.25000000,11,1,13.20000000,28,1,12.99000000,100,1,12.88000000,2,1,12.73000000,100,1,12.67000000,100,1,12.47000000,100,1,12.46000000,100,1,12.43000000,700,1,12.42000000,700,1,13.40000000,208,12,13.67000000,100,1,13.78000000,2,1,13.93000000,100,1,14.00000000,100,1,14.20000000,900,3,14.26000000,700,1,14.27000000,700,1,14.29000000,800,8,14.30000000,200,2,ARL,74549681
485,2025-07-17T13:41:45.405178844Z,2025-07-17T13:41:45.405013016Z,160,2,1108,C,A,0,14.57000000,100,0,165828,60651462,13.25000000,11,1,13.20000000,28,1,12.99000000,100,1,12.88000000,2,1,12.73000000,100,1,12.67000000,100,1,12.47000000,100,1,12.46000000,100,1,12.43000000,700,1,12.42000000,700,1,13.40000000,208,12,13.67000000,100,1,13.78000000,2,1,13.93000000,100,1,14.00000000,100,1,14.20000000,900,3,14.26000000,700,1,14.27000000,700,1,14.29000000,800,8,14.30000000,200,2,ARL,74549681
486,2025-07-17T13:41:45.405178844Z,2025-07-17T13:41:45.405013016Z,160,2,1108,A,A,0,14.30000000,100,130,165828,60651462,13.25000000,11,1,13.20000000,28,1,12.99000000,100,1,12.88000000,2,1,12.73000000,100,1,12.67000000,100,1,12.47000000,100,1,12.46000000,100,1,12.43000000,700,1,12.42000000,700,1,13.40000000,208,12,13.67000000,100,1,13.78000000,2,1,13.93000000,100,1,14.00000000,100,1,14.20000000,900,3,14.26000000,700,1,14.27000000,700,1,14.29000000,800,8,14.30000000,300,3,ARL,74589605
487,2025-07-17T13:42:08.821320823Z,2025-07-17T13:42:08.821155108Z,160,2,1108,C,A,0,14.29000000,100,0,165715,61488742,13.25000000,11,1,13.20000000,28,1,12.99000000,100,1,12.88000000,2,1,12.73000000,100,1,12.67000000,100,1,12.47000000,100,1,12.46000000,100,1,12.43000000,700,1,12.42000000,700,1,13.40000000,208,12,13.67000000,100,1,13.78000000,2,1,13.93000000,100,1,14.00000000,100,1,14.20000000,900,3,14.26000000,700,1,14.27000000,700,1,14.29000000,800,8,14.30000000,300,3,ARL,67857641
488,2025-07-17T13:42:08.821320823Z,2025-07-17T13:42:08.821155108Z,160,2,1108,A,A,0,14.57000000,100,130,165715,61488742,13.25000000,11,1,13.20000000,28,1,12.99000000,100,1,12.88000000,2,1,12.73000000,100,1,12.67000000,100,1,12.47000000,100,1,12.46000000,100,1,12.43000000,700,1,12.42000000,700,1,13.40000000,208,12,13.67000000,100,1,13.78000000,2,1,13.93000000,100,1,14.00000000,100,1,14.20000000,900,3,14.26000000,700,1,14.27000000,700,1,14.29000000,800,8,14.30000000,300,3,ARL,75537553
489,2025-07-17T13:42:09.827057338Z,2025-07-17T13:42:09.826891682Z,160,2,1108,C,A,0,14.57000000,100,0,165656,61523538,13.25000000,11,1,13.20000000,28,1,12.99000000,100,1,12.88000000,2,1,12.73000000,100,1,12.67000000,100,1,12.47000000,100,1,12.46000000,100,1,12.43000000,700,1,12.42000000,700,1,13.40000000,208,12,13.67000000,100,1,13.78000000,2,1,13.93000000,100,1,14.00000000,100,1,14.20000000,900,3,14.26000000,700,1,14.27000000,700,1,14.29000000,800,8,14.30000000,300,3,ARL,75537553
490,2025-07-17T13:42:09.827057338Z,2025-07-17T13:42:09.826891682Z,160,2,1108,A,A,0,14.30000000,100,130,165656,61523538,13.25000000,11,1,13.20000000,28,1,12.99000000,100,1,12.88000000,2,1,12.73000000,100,1,12.67000000,100,1,12.47000000,100,1,12.46000000,100,1,12.43000000,700,1,12.42000000,700,1,13.40000000,208,12,13.67000000,100,1,13.78000000,2,1,13.93000000,100,1,14.00000000,100,1,14.20000000,900,3,14.26000000,700,1,14.27000000,700,1,14.29000000,800,8,14.30000000,400,4,ARL,75577257
491,2025-07-17T13:43:08.826244125Z,2025-07-17T13:43:08.826078491Z,160,2,1108,C,A,0,14.30000000,100,0,165634,63579150,13.25000000,11,1,13.20000000,28,1,12.99000000,100,1,12.88000000,2,1,12.73000000,100,1,12.67000000,100,1,12.47000000,100,1,12.46000000,100,1,12.43000000,700,1,12.42000000,700,1,13.40000000,208,12,13.67000000,100,1,13.78000000,2,1,13.93000000,100,1,14.00000000,100,1,14.20000000,900,3,14.26000000,700,1,14.27000000,700,1,14.29000000,800,8,14.30000000,400,4,ARL,75577257
492,2025-07-17T13:43:08.826244125Z,2025-07-17T13:43:08.826078491Z,160,2,1108,A,A,0,14.57000000,100,130,165634,63579150,13.25000000,11,1,13.20000000,28,1,12.99000000,100,1,12.88000000,2,1,12.73000000,100,1,12.67000000,100,1,12.47000000,100,1,12.46000000,100,1,12.43000000,700,1,12.42000000,700,1,13.40000000,208,12,13.67000000,100,1,13.78000000,2,1,13.93000000,100,1,14.00000000,100,1,14.20000000,900,3,14.26000000,700,1,14.27000000,700,1,14.29000000,800,8,14.30000000,400,4,ARL,77879933
493,2025-07-17T13:43:09.832572415Z,2025-07-17T13:43:09.832406764Z,160,2,1108,C,A,0,14.57000000,100,0,165651,63604352,13.25000000,11,1,13.20000000,28,1,12.99000000,100,1,12.88000000,2,1,12.73000000,100,1,12.67000000,100,1,12.47000000,100,1,12.46000000,100,1,12.43000000,700,1,12.42000000,700,1,13.40000000,208,12,13.67000000,100,1,13.78000000,2,1,13.93000000,100,1,14.00000000,100,1,14.20000000,900,3,14.26000000,700,1,14.27000000,700,1,14.29000000,800,8,14.30000000,400,4,ARL,77879933
494,2025-07-17T13:43:09.832572415Z,2025-07-17T13:43:09.832406764Z,160,2,1108,A,A,0,14.30000000,100,130,165651,63604352,13.25000000,11,1,13.20000000,28,1,12.99000000,100,1,12.88000000,2,1,12.73000000,100,1,12.67000000,100,1,12.47000000,100,1,12.46000000,100,1,12.43000000,700,1,12.42000000,700,1,13.40000000,208,12,13.67000000,100,1,13.78000000,2,1,13.93000000,100,1,14.00000000,100,1,14.20000000,900,3,14.26000000,700,1,14.27000000,700,1,14.29000000,800,8,14.30000000,500,5,ARL,77910357
495,2025-07-17T13:46:09.541016899Z,2025-07-17T13:46:09.540851349Z,160,2,1108,C,A,0,14.20000000,700,130,165550,69578535,13.25000000,11,1,13.20000000,28,1,12.99000000,100,1,12.88000000,2,1,12.73000000,100,1,12.67000000,100,1,12.47000000,100,1,12.46000000,100,1,12.43000000,700,1,12.42000000,700,1,13.40000000,208,12,13.67000000,100,1,13.78000000,2,1,13.93000000,100,1,14.00000000,100,1,14.20000000,900,3,14.26000000,700,1,14.27000000,700,1,14.29000000,800,8,14.30000000,500,5,ARL,47376925
496,2025-07-17T13:46:09.541058233Z,2025-07-17T13:46:09.540892810Z,160,2,1108,A,A,0,14.36000000,700,130,165423,69578537,13.25000000,11,1,13.20000000,28,1,12.99000000,100,1,12.88000000,2,1,12.73000000,100,1,12.67000000,100,1,12.47000000,100,1,12.46000000,100,1,12.43000000,700,1,12.42000000,700,1,13.40000000,208,12,13.67000000,100,1,13.78000000,2,1,13.93000000,100,1,14.00000000,100,1,14.20000000,900,3,14.26000000,700,1,14.27000000,700,1,14.29000000,800,8,14.30000000,500,5,ARL,84607761
497,2025-07-17T13:46:09.541097538Z,2025-07-17T13:46:09.540932260Z,160,2,1108,A,A,0,15.59000000,100,130,165278,69578539,13.25000000,11,1,13.20000000,28,1,12.99000000,100,1,12.88000000,2,1,12.73000000,100,1,12.67000000,100,1,12.47000000,100,1,12.46000000,100,1,12.43000000,700,1,12.42000000,700,1,13.40000000,208,12,13.67000000,100,1,13.78000000,2,1,13.93000000,100,1,14.00000000,100,1,14.20000000,900,3,14.26000000,700,1,14.27000000,700,1,14.29000000,800,8,14.30000000,500,5,ARL,84607765
498,2025-07-17T13:46:09.541109881Z,2025-07-17T13:46:09.540944549Z,160,2,1108,C,A,0,15.28000000,100,130,165332,69578540,13.25000000,11,1,13.20000000,28,1,12.99000000,100,1,12.88000000,2,1,12.73000000,100,1,12.67000000,100,1,12.47000000,100,1,12.46000000,100,1,12.43000000,700,1,12.42000000,700,1,13.40000000,208,12,13.67000000,100,1,13.78000000,2,1,13.93000000,100,1,14.00000000,100,1,14.20000000,900,3,14.26000000,700,1,14.27000000,700,1,14.29000000,800,8,14.30000000,500,5,ARL,43373085
499,2025-07-17T13:46:09.541434576Z,2025-07-17T13:46:09.541269186Z,160,2,1108,C,A,0,14.44000000,100,0,165390,69578543,13.25000000,11,1,13.20000000,28,1,12.99000000,100,1,12.88000000,2,1,12.73000000,100,1,12.67000000,100,1,12.47000000,100,1,12.46000000,100,1,12.43000000,700,1,12.42000000,700,1,13.40000000,208,12,13.67000000,100,1,13.78000000,2,1,13.93000000,100,1,14.00000000,100,1,14.20000000,900,3,14.26000000,700,1,14.27000000,700,1,14.29000000,800,8,14.30000000,500,5,ARL,43373009
500,2025-07-17T13:46:09.541434576Z,2025-07-17T13:46:09.541269186Z,160,2,1108,A,A,0,14.49000000,100,130,165390,69578543,13.25000000,11,1,13.20000000,28,1,12.99000000,100,1,12.88000000,2,1,12.73000000,100,1,12.67000000,100,1,12.47000000,100,1,12.46000000,100,1,12.43000000,700,1,12.42000000,700,1,13.40000000,208,12,13.67000000,100,1,13.78000000,2,1,13.93000000,100,1,14.00000000,100,1,14.20000000,900,3,14.26000000,700,1,14.27000000,700,1,14.29000000,800,8,14.30000000,500,5,ARL,84607785
501,2025-07-17T13:46:09.541492629Z,2025-07-17T13:46:09.541327298Z,160,2,1108,C,A,0,14.00000000,100,130,165331,69578544,13.25000000,11,1,13.20000000,28,1,12.99000000,100,1,12.88000000,2,1,12.73000000,100,1,12.67000000,100,1,12.47000000,100,1,12.46000000,100,1,12.43000000,700,1,12.42000000,700,1,13.40000000,208,12,13.67000000,100,1,13.78000000,2,1,13.93000000,100,1,14.00000000,100,1,14.20000000,900,3,14.26000000,700,1,14.27000000,700,1,14.29000000,800,8,14.30000000,500,5,ARL,43663233
502,2025-07-17T13:46:09.541795256Z,2025-07-17T13:46:09.541629920Z,160,2,1108,C,A,0,14.34000000,100,0,165336,69578547,13.25000000,11,1,13.20000000,28,1,12.99000000,100,1,12.88000000,2,1,12.73000000,100,1,12.67000000,100,1,12.47000000,100,1,12.46000000,100,1,12.43000000,700,1,12.42000000,700,1,13.40000000,208,12,13.67000000,100,1,13.78000000,2,1,13.93000000,100,1,14.00000000,100,1,14.20000000,900,3,14.26000000,700,1,14.27000000,700,1,14.29000000,800,8,14.30000000,500,5,ARL,43755821
503,2025-07-17T13:46:09.541795256Z,2025-07-17T13:46:09.541629920Z,160,2,1108,A,A,0,14.63000000,100,130,165336,69578547,13.25000000,11,1,13.20000000,28,1,12.99000000,100,1,12.88000000,2,1,12.73000000,100,1,12.67000000,100,1,12.47000000,100,1,12.46000000,100,1,12.43000000,700,1,12.42000000,700,1,13.40000000,208,12,13.67000000,100,1,13.78000000,2,1,13.93000000,100,1,14.00000000,100,1,14.20000000,900,3,14.26000000,700,1,14.27000000,700,1,14.29000000,800,8,14.30000000,500,5,ARL,84607801
504,2025-07-17T13:46:09.541846554Z,2025-07-17T13:46:09.541680473Z,160,2,1108,C,A,0,14.74000000,100,0,166081,69578550,13.25000000,11,1,13.20000000,28,1,12.99000000,100,1,12.88000000,2,1,12.73000000,100,1,12.67000000,100,1,12.47000000,100,1,12.46000000,100,1,12.43000000,700,1,12.42000000,700,1,13.40000000,208,12,13.67000000,100,1,13.78000000,2,1,13.93000000,100,1,14.00000000,100,1,14.20000000,900,3,14.26000000,700,1,14.27000000,700,1,14.29000000,800,8,14.30000000,500,5,ARL,43357029
505,2025-07-17T13:46:09.541846554Z,2025-07-17T13:46:09.541680473Z,160,2,1108,A,A,0,15.04000000,100,130,166081,69578550,13.25000000,11,1,13.20000000,28,1,12.99000000,100,1,12.88000000,2,1,12.73000000,100,1,12.67000000,100,1,12.47000000,100,1,12.46000000,100,1,12.43000000,700,1,12.42000000,700,1,13.40000000,208,12,13.67000000,100,1,13.78000000,2,1,13.93000000,100,1,14.00000000,100,1,14.20000000,900,3,14.26000000,700,1,14.27000000,700,1,14.29000000,800,8,14.30000000,500,5,ARL,84607805
506,2025-07-17T13:46:09.541847519Z,2025-07-17T13:46:09.541682402Z,160,2,1108,A,A,0,14.28000000,100,130,165117,69578551,13.25000000,11,1,13.20000000,28,1,12.99000000,100,1,12.88000000,2,1,12.73000000,100,1,12.67000000,100,1,12.47000000,100,1,12.46000000,100,1,12.43000000,700,1,12.42000000,700,1,13.40000000,208,12,13.67000000,100,1,13.78000000,2,1,13.93000000,100,1,14.00000000,100,1,14.20000000,900,3,14.26000000,700,1,14.27000000,700,1,14.28000000,100,1,14.29000000,800,8,ARL,84607809
507,2025-07-17T13:46:09.542961756Z,2025-07-17T13:46:09.542796050Z,160,2,1108,C,A,0,15.41000000,100,0,165706,69578574,13.25000000,11,1,13.20000000,28,1,12.99000000,100,1,12.88000000,2,1,12.73000000,100,1,12.67000000,100,1,12.47000000,100,1,12.46000000,100,1,12.43000000,700,1,12.42000000,700,1,13.40000000,208,12,13.67000000,100,1,13.78000000,2,1,13.93000000,100,1,14.00000000,100,1,14.20000000,900,3,14.26000000,700,1,14.27000000,700,1,14.28000000,100,1,14.29000000,800,8,ARL,43826805
508,2025-07-17T13:46:09.542961756Z,2025-07-17T13:46:09.542796050Z,160,2,1108,A,A,0,15.73000000,100,130,165706,69578574,13.25000000,11,1,13.20000000,28,1,12.99000000,100,1,12.88000000,2,1,12.73000000,100,1,12.67000000,100,1,12.47000000,100,1,12.46000000,100,1,12.43000000,700,1,12.42000000,700,1,13.40000000,208,12,13.67000000,100,1,13.78000000,2,1,13.93000000,100,1,14.00000000,100,1,14.20000000,900,3,14.26000000,700,1,14.27000000,700,1,14.28000000,100,1,14.29000000,800,8,ARL,84607837
509,2025-07-17T13:46:09.543510155Z,2025-07-17T13:46:09.543344724Z,160,2,1108,C,A,0,17.02000000,100,0,165431,69578598,13.25000000,11,1,13.20000000,28,1,12.99000000,100,1,12.88000000,2,1,12.73000000,100,1,12.67000000,100,1,12.47000000,100,1,12.46000000,100,1,12.43000000,700,1,12.42000000,700,1,13.40000000,208,12,13.67000000,100,1,13.78000000,2,1,13.93000000,100,1,14.00000000,100,1,14.20000000,900,3,14.26000000,700,1,14.27000000,700,1,14.28000000,100,1,14.29000000,800,8,ARL,44082969
510,2025-07-17T13:46:09.543510155Z,2025-07-17T13:46:09.543344724Z,160,2,1108,A,A,0,17.37000000,100,130,165431,69578598,13.25000000,11,1,13.20000000,28,1,12.99000000,100,1,12.88000000,2,1,12.73000000,100,1,12.67000000,100,1,12.47000000,100,1,12.46000000,100,1,12.43000000,700,1,12.42000000,700,1,13.40000000,208,12,13.67000000,100,1,13.78000000,2,1,13.93000000,100,1,14.00000000,100,1,14.20000000,900,3,14.26000000,700,1,14.27000000,700,1,14.28000000,100,1,14.29000000,800,8,ARL,84607861
511,2025-07-17T13:46:09.546546482Z,2025-07-17T13:46:09.546381306Z,160,2,1108,C,A,0,14.20000000,100,130,165176,69578814,13.25000000,11,1,13.20000000,28,1,12.99000000,100,1,12.88000000,2,1,12.73000000,100,1,12.67000000,100,1,12.47000000,100,1,12.46000000,100,1,12.43000000,700,1,12.42000000,700,1,13.40000000,208,12,13.67000000,100,1,13.78000000,2,1,13.93000000,100,1,14.00000000,100,1,14.20000000,900,3,14.26000000,700,1,14.27000000,700,1,14.28000000,100,1,14.29000000,800,8,ARL,43554141
512,2025-07-17T13:46:09.546656996Z,2025-07-17T13:46:09.546491223Z,160,2,1108,A,A,0,14.47000000,100,130,165773,69578831,13.25000000,11,1,13.20000000,28,1,12.99000000,100,1,12.88000000,2,1,12.73000000,100,1,12.67000000,100,1,12.47000000,100,1,12.46000000,100,1,12.43000000,700,1,12.42000000,700,1,13.40000000,208,12,13.67000000,100,1,13.78000000,2,1,13.93000000,100,1,14.00000000,100,1,14.20000000,900,3,14.26000000,700,1,14.27000000,700,1,14.28000000,100,1,14.29000000,800,8,ARL,84608321
513,2025-07-17T13:46:09.560918620Z,2025-07-17T13:46:09.560753276Z,160,2,1108,C,A,0,13.67000000,100,130,165344,69579444,13.25000000,11,1,13.20000000,28,1,12.99000000,100,1,12.88000000,2,1,12.73000000,100,1,12.67000000,100,1,12.47000000,100,1,12.46000000,100,1,12.43000000,700,1,12.42000000,700,1,13.40000000,208,12,13.67000000,100,1,13.78000000,2,1,13.93000000,100,1,14.00000000,100,1,14.20000000,900,3,14.26000000,700,1,14.27000000,700,1,14.28000000,100,1,14.29000000,800,8,ARL,43953649
514,2025-07-17T13:46:09.560953850Z,2025-07-17T13:46:09.560789009Z,160,2,1108,C,A,0,14.36000000,700,130,164841,69579446,13.25000000,11,1,13.20000000,28,1,12.99000000,100,1,12.88000000,2,1,12.73000000,100,1,12.67000000,100,1,12.47000000,100,1,12.46000000,100,1,12.43000000,700,1,12.42000000,700,1,13.40000000,208,12,13.67000000,100,1,13.78000000,2,1,13.93000000,100,1,14.00000000,100,1,14.20000000,900,3,14.26000000,700,1,14.27000000,700,1,14.28000000,100,1,14.29000000,800,8,ARL,84607761
515,2025-07-17T13:46:09.560968819Z,2025-07-17T13:46:09.560803559Z,160,2,1108,A,A,0,13.94000000,100,130,165260,69579448,13.25000000,11,1,13.20000000,28,1,12.99000000,100,1,12.88000000,2,1,12.73000000,100,1,12.67000000,100,1,12.47000000,100,1,12.46000000,100,1,12.43000000,700,1,12.42000000,700,1,13.40000000,208,12,13.67000000,100,1,13.78000000,2,1,13.93000000,100,1,13.94000000,100,1,14.00000000,100,1,14.20000000,900,3,14.26000000,700,1,14.27000000,700,1,14.28000000,100,1,ARL,84609305
516,2025-07-17T13:46:09.560981020Z,2025-07-17T13:46:09.560815603Z,160,2,1108,C,A,0,14.27000000,700,130,165417,69579449,13.25000000,11,1,13.20000000,28,1,12.99000000,100,1,12.88000000,2,1,12.73000000,100,1,12.67000000,100,1,12.47000000,100,1,12.46000000,100,1,12.43000000,700,1,12.42000000,700,1,13.40000000,208,12,13.67000000,100,1,13.78000000,2,1,13.93000000,100,1,13.94000000,100,1,14.00000000,100,1,14.20000000,900,3,14.26000000,700,1,14.27000000,700,1,14.28000000,100,1,ARL,44491681
517,2025-07-17T13:46:09.560990769Z,2025-07-17T13:46:09.560825413Z,160,2,1108,A,A,0,15.89000000,100,130,165356,69579450,13.25000000,11,1,13.20000000,28,1,12.99000000,100,1,12.88000000,2,1,12.73000000,100,1,12.67000000,100,1,12.47000000,100,1,12.46000000,100,1,12.43000000,700,1,12.42000000,700,1,13.40000000,208,12,13.67000000,100,1,13.78000000,2,1,13.93000000,100,1,13.94000000,100,1,14.00000000,100,1,14.20000000,900,3,14.26000000,700,1,14.27000000,700,1,14.28000000,100,1,ARL,84609309
518,2025-07-17T13:46:09.561002700Z,2025-07-17T13:46:09.560837771Z,160,2,1108,C,A,0,15.59000000,100,130,164929,69579453,13.25000000,11,1,13.20000000,28,1,12.99000000,100,1,12.88000000,2,1,12.73000000,100,1,12.67000000,100,1,12.47000000,100,1,12.46000000,100,1,12.43000000,700,1,12.42000000,700,1,13.40000000,208,12,13.67000000,100,1,13.78000000,2,1,13.93000000,100,1,13.94000000,100,1,14.00000000,100,1,14.20000000,900,3,14.26000000,700,1,14.27000000,700,1,14.28000000,100,1,ARL,84607765
519,2025-07-17T13:46:09.561059021Z,2025-07-17T13:46:09.560893546Z,160,2,1108,A,A,0,14.70000000,700,130,165475,69579455,13.25000000,11,1,13.20000000,28,1,12.99000000,100,1,12.88000000,2,1,12.73000000,100,1,12.67000000,100,1,12.47000000,100,1,12.46000000,100,1,12.43000000,700,1,12.42000000,700,1,13.40000000,208,12,13.67000000,100,1,13.78000000,2,1,13.93000000,100,1,13.94000000,100,1,14.00000000,100,1,14.20000000,900,3,14.26000000,700,1,14.27000000,700,1,14.28000000,100,1,ARL,84609321
520,2025-07-17T13:46:09.561710911Z,2025-07-17T13:46:09.561543868Z,160,2,1108,C,A,0,14.26000000,700,128,167043,69579488,13.25000000,11,1,13.20000000,28,1,12.99000000,100,1,12.88000000,2,1,12.73000000,100,1,12.67000000,100,1,12.47000000,100,1,12.46000000,100,1,12.43000000,700,1,12.42000000,700,1,13.40000000,208,12,13.67000000,100,1,13.78000000,2,1,13.93000000,100,1,13.94000000,100,1,14.00000000,100,1,14.20000000,900,3,14.26000000,700,1,14.27000000,700,1,14.28000000,100,1,ARL,44598153
521,2025-07-17T13:46:09.561954989Z,2025-07-17T13:46:09.561788417Z,160,2,1108,C,A,0,15.04000000,100,0,166572,69579536,13.25000000,11,1,13.20000000,28,1,12.99000000,100,1,12.88000000,2,1,12.73000000,100,1,12.67000000,100,1,12.47000000,100,1,12.46000000,100,1,12.43000000,700,1,12.42000000,700,1,13.40000000,208,12,13.67000000,100,1,13.78000000,2,1,13.93000000,100,1,13.94000000,100,1,14.00000000,100,1,14.20000000,900,3,14.26000000,700,1,14.27000000,700,1,14.28000000,100,1,ARL,84607805
522,2025-07-17T13:46:09.561954989Z,2025-07-17T13:46:09.561788417Z,160,2,1108,A,A,0,15.33000000,100,0,166572,69579536,13.25000000,11,1,13.20000000,28,1,12.99000000,100,1,12.88000000,2,1,12.73000000,100,1,12.67000000,100,1,12.47000000,100,1,12.46000000,100,1,12.43000000,700,1,12.42000000,700,1,13.40000000,208,12,13.67000000,100,1,13.78000000,2,1,13.93000000,100,1,13.94000000,100,1,14.00000000,100,1,14.20000000,900,3,14.26000000,700,1,14.27000000,700,1,14.28000000,100,1,ARL,84609385
523,2025-07-17T13:46:09.561954989Z,2025-07-17T13:46:09.561788902Z,160,2,1108,C,A,0,14.63000000,100,0,166087,69579537,13.25000000,11,1,13.20000000,28,1,12.99000000,100,1,12.88000000,2,1,12.73000000,100,1,12.67000000,100,1,12.47000000,100,1,12.46000000,100,1,12.43000000,700,1,12.42000000,700,1,13.40000000,208,12,13.67000000,100,1,13.78000000,2,1,13.93000000,100,1,13.94000000,100,1,14.00000000,100,1,14.20000000,900,3,14.26000000,700,1,14.27000000,700,1,14.28000000,100,1,ARL,84607801
524,2025-07-17T13:46:09.561954989Z,2025-07-17T13:46:09.561788902Z,160,2,1108,A,A,0,14.91000000,100,130,166087,69579537,13.25000000,11,1,13.20000000,28,1,12.99000000,100,1,12.88000000,2,1,12.73000000,100,1,12.67000000,100,1,12.47000000,100,1,12.46000000,100,1,12.43000000,700,1,12.42000000,700,1,13.40000000,208,12,13.67000000,100,1,13.78000000,2,1,13.93000000,100,1,13.94000000,100,1,14.00000000,100,1,14.20000000,900,3,14.26000000,700,1,14.27000000,700,1,14.28000000,100,1,ARL,84609389
525,2025-07-17T13:46:09.562157451Z,2025-07-17T13:46:09.561992206Z,160,2,1108,A,A,0,14.67000000,700,130,165245,69579579,13.25000000,11,1,13.20000000,28,1,12.99000000,100,1,12.88000000,2,1,12.73000000,100,1,12.67000000,100,1,12.47000000,100,1,12.46000000,100,1,12.43000000,700,1,12.42000000,700,1,13.40000000,208,12,13.67000000,100,1,13.78000000,2,1,13.93000000,100,1,13.94000000,100,1,14.00000000,100,1,14.20000000,900,3,14.26000000,700,1,14.27000000,700,1,14.28000000,100,1,ARL,84609409
526,2025-07-17T13:46:09.563782397Z,2025-07-17T13:46:09.563617017Z,160,2,1108,C,A,0,17.37000000,100,0,165380,69579787,13.25000000,11,1,13.20000000,28,1,12.99000000,100,1,12.88000000,2,1,12.73000000,100,1,12.67000000,100,1,12.47000000,100,1,12.46000000,100,1,12.43000000,700,1,12.42000000,700,1,13.40000000,208,12,13.67000000,100,1,13.78000000,2,1,13.93000000,100,1,13.94000000,100,1,14.00000000,100,1,14.20000000,900,3,14.26000000,700,1,14.27000000,700,1,14.28000000,100,1,ARL,84607861
527,2025-07-17T13:46:09.563782397Z,2025-07-17T13:46:09.563617017Z,160,2,1108,A,A,0,17.70000000,100,130,165380,69579787,13.25000000,11,1,13.20000000,28,1,12.99000000,100,1,12.88000000,2,1,12.73000000,100,1,12.67000000,100,1,12.47000000,100,1,12.46000000,100,1,12.43000000,700,1,12.42000000,700,1,13.40000000,208,12,13.67000000,100,1,13.78000000,2,1,13.93000000,100,1,13.94000000,100,1,14.00000000,100,1,14.20000000,900,3,14.26000000,700,1,14.27000000,700,1,14.28000000,100,1,ARL,84609557
528,2025-07-17T13:46:09.565379544Z,2025-07-17T13:46:09.565213822Z,160,2,1108,C,A,0,13.78000000,2,0,165722,69579892,13.25000000,11,1,13.20000000,28,1,12.99000000,100,1,12.88000000,2,1,12.73000000,100,1,12.67000000,100,1,12.47000000,100,1,12.46000000,100,1,12.43000000,700,1,12.42000000,700,1,13.40000000,208,12,13.67000000,100,1,13.78000000,2,1,13.93000000,100,1,13.94000000,100,1,14.00000000,100,1,14.20000000,900,3,14.26000000,700,1,14.27000000,700,1,14.28000000,100,1,ARL,58709197
529,2025-07-17T13:46:09.565379544Z,2025-07-17T13:46:09.565213822Z,160,2,1108,A,A,0,13.93000000,2,130,165722,69579892,13.25000000,11,1,13.20000000,28,1,12.99000000,100,1,12.88000000,2,1,12.73000000,100,1,12.67000000,100,1,12.47000000,100,1,12.46000000,100,1,12.43000000,700,1,12.42000000,700,1,13.40000000,208,12,13.67000000,100,1,13.78000000,2,1,13.93000000,102,2,13.94000000,100,1,14.00000000,100,1,14.20000000,900,3,14.26000000,700,1,14.27000000,700,1,14.28000000,100,1,ARL,84609637
530,2025-07-17T13:46:09.565403598Z,2025-07-17T13:46:09.565237899Z,160,2,1108,C,A,0,15.73000000,100,0,165699,69579893,13.25000000,11,1,13.20000000,28,1,12.99000000,100,1,12.88000000,2,1,12.73000000,100,1,12.67000000,100,1,12.47000000,100,1,12.46000000,100,1,12.43000000,700,1,12.42000000,700,1,13.40000000,208,12,13.67000000,100,1,13.78000000,2,1,13.93000000,102,2,13.94000000,100,1,14.00000000,100,1,14.20000000,900,3,14.26000000,700,1,14.27000000,700,1,14.28000000,100,1,ARL,84607837
531,2025-07-17T13:46:09.565403598Z,2025-07-17T13:46:09.565237899Z,160,2,1108,A,A,0,16.02000000,100,130,165699,69579893,13.25000000,11,1,13.20000000,28,1,12.99000000,100,1,12.88000000,2,1,12.73000000,100,1,12.67000000,100,1,12.47000000,100,1,12.46000000,100,1,12.43000000,700,1,12.42000000,700,1,13.40000000,208,12,13.67000000,100,1,13.78000000,2,1,13.93000000,102,2,13.94000000,100,1,14.00000000,100,1,14.20000000,900,3,14.26000000,700,1,14.27000000,700,1,14.28000000,100,1,ARL,84609645
532,2025-07-17T13:46:09.566687064Z,2025-07-17T13:46:09.566522227Z,160,2,1108,C,A,0,13.94000000,100,130,164837,69579922,13.25000000,11,1,13.20000000,28,1,12.99000000,100,1,12.88000000,2,1,12.73000000,100,1,12.67000000,100,1,12.47000000,100,1,12.46000000,100,1,12.43000000,700,1,12.42000000,700,1,13.40000000,208,12,13.67000000,100,1,13.78000000,2,1,13.93000000,102,2,13.94000000,100,1,14.00000000,100,1,14.20000000,900,3,14.26000000,700,1,14.27000000,700,1,14.28000000,100,1,ARL,84609305
533,2025-07-17T13:46:09.566736503Z,2025-07-17T13:46:09.566571131Z,160,2,1108,A,A,0,14.21000000,100,130,165372,69579923,13.25000000,11,1,13.20000000,28,1,12.99000000,100,1,12.88000000,2,1,12.73000000,100,1,12.67000000,100,1,12.47000000,100,1,12.46000000,100,1,12.43000000,700,1,12.42000000,700,1,13.40000000,208,12,13.67000000,100,1,13.78000000,2,1,13.93000000,102,2,13.94000000,100,1,14.00000000,100,1,14.20000000,900,3,14.21000000,100,1,14.26000000,700,1,14.27000000,700,1,ARL,84609733
534,2025-07-17T13:46:09.583735074Z,2025-07-17T13:46:09.583569619Z,160,2,1108,C,A,0,14.74000000,100,0,165455,69580598,13.25000000,11,1,13.20000000,28,1,12.99000000,100,1,12.88000000,2,1,12.73000000,100,1,12.67000000,100,1,12.47000000,100,1,12.46000000,100,1,12.43000000,700,1,12.42000000,700,1,13.40000000,208,12,13.67000000,100,1,13.78000000,2,1,13.93000000,102,2,13.94000000,100,1,14.00000000,100,1,14.20000000,900,3,14.21000000,100,1,14.26000000,700,1,14.27000000,700,1,ARL,43852129
535,2025-07-17T13:46:09.583735074Z,2025-07-17T13:46:09.583569619Z,160,2,1108,A,A,0,15.33000000,100,130,165455,69580598,13.25000000,11,1,13.20000000,28,1,12.99000000,100,1,12.88000000,2,1,12.73000000,100,1,12.67000000,100,1,12.47000000,100,1,12.46000000,100,1,12.43000000,700,1,12.42000000,700,1,13.40000000,208,12,13.67000000,100,1,13.78000000,2,1,13.93000000,102,2,13.94000000,100,1,14.00000000,100,1,14.20000000,900,3,14.21000000,100,1,14.26000000,700,1,14.27000000,700,1,ARL,84611025
536,2025-07-17T13:46:09.591552337Z,2025-07-17T13:46:09.591386919Z,160,2,1108,C,A,0,14.49000000,100,0,165418,69581249,13.25000000,11,1,13.20000000,28,1,12.99000000,100,1,12.88000000,2,1,12.73000000,100,1,12.67000000,100,1,12.47000000,100,1,12.46000000,100,1,12.43000000,700,1,12.42000000,700,1,13.40000000,208,12,13.67000000,100,1,13.78000000,2,1,13.93000000,102,2,13.94000000,100,1,14.00000000,100,1,14.20000000,900,3,14.21000000,100,1,14.26000000,700,1,14.27000000,700,1,ARL,84607785
537,2025-07-17T13:46:09.591552337Z,2025-07-17T13:46:09.591386919Z,160,2,1108,A,A,0,15.01000000,100,130,165418,69581249,13.25000000,11,1,13.20000000,28,1,12.99000000,100,1,12.88000000,2,1,12.73000000,100,1,12.67000000,100,1,12.47000000,100,1,12.46000000,100,1,12.43000000,700,1,12.42000000,700,1,13.40000000,208,12,13.67000000,100,1,13.78000000,2,1,13.93000000,102,2,13.94000000,100,1,14.00000000,100,1,14.20000000,900,3,14.21000000,100,1,14.26000000,700,1,14.27000000,700,1,ARL,84611613
538,2025-07-17T13:46:09.595667047Z,2025-07-17T13:46:09.595500037Z,160,2,1108,A,A,0,14.63000000,700,128,167010,69582059,13.25000000,11,1,13.20000000,28,1,12.99000000,100,1,12.88000000,2,1,12.73000000,100,1,12.67000000,100,1,12.47000000,100,1,12.46000000,100,1,12.43000000,700,1,12.42000000,700,1,13.40000000,208,12,13.67000000,100,1,13.78000000,2,1,13.93000000,102,2,13.94000000,100,1,14.00000000,100,1,14.20000000,900,3,14.21000000,100,1,14.26000000,700,1,14.27000000,700,1,ARL,84612081
539,2025-07-17T13:46:09.610291566Z,2025-07-17T13:46:09.610126066Z,160,2,1108,C,A,0,14.34000000,100,0,165500,69582709,13.25000000,11,1,13.20000000,28,1,12.99000000,100,1,12.88000000,2,1,12.73000000,100,1,12.67000000,100,1,12.47000000,100,1,12.46000000,100,1,12.43000000,700,1,12.42000000,700,1,13.40000000,208,12,13.67000000,100,1,13.78000000,2,1,13.93000000,102,2,13.94000000,100,1,14.00000000,100,1,14.20000000,900,3,14.21000000,100,1,14.26000000,700,1,14.27000000,700,1,ARL,44088637
540,2025-07-17T13:46:09.610291566Z,2025-07-17T13:46:09.610126066Z,160,2,1108,A,A,0,14.91000000,100,130,165500,69582709,13.25000000,11,1,13.20000000,28,1,12.99000000,100,1,12.88000000,2,1,12.73000000,100,1,12.67000000,100,1,12.47000000,100,1,12.46000000,100,1,12.43000000,700,1,12.42000000,700,1,13.40000000,208,12,13.67000000,100,1,13.78000000,2,1,13.93000000,102,2,13.94000000,100,1,14.00000000,100,1,14.20000000,900,3,14.21000000,100,1,14.26000000,700,1,14.27000000,700,1,ARL,84612773
541,2025-07-17T13:46:09.812938843Z,2025-07-17T13:46:09.812773551Z,160,2,1108,A,A,0,14.76000000,100,130,165292,69586965,13.25000000,11,1,13.20000000,28,1,12.99000000,100,1,12.88000000,2,1,12.73000000,100,1,12.67000000,100,1,12.47000000,100,1,12.46000000,100,1,12.43000000,700,1,12.42000000,700,1,13.40000000,208,12,13.67000000,100,1,13.78000000,2,1,13.93000000,102,2,13.94000000,100,1,14.00000000,100,1,14.20000000,900,3,14.21000000,100,1,14.26000000,700,1,14.27000000,700,1,ARL,84618189
542,2025-07-17T13:46:09.812950020Z,2025-07-17T13:46:09.812784722Z,160,2,1108,C,A,0,14.20000000,100,130,165298,69586966,13.25000000,11,1,13.20000000,28,1,12.99000000,100,1,12.88000000,2,1,12.73000000,100,1,12.67000000,100,1,12.47000000,100,1,12.46000000,100,1,12.43000000,700,1,12.42000000,700,1,13.40000000,208,12,13.67000000,100,1,13.78000000,2,1,13.93000000,102,2,13.94000000,100,1,14.00000000,100,1,14.20000000,900,3,14.21000000,100,1,14.26000000,700,1,14.27000000,700,1,ARL,43804081
543,2025-07-17T13:46:09.936895839Z,2025-07-17T13:46:09.936730596Z,160,2,1108,C,A,0,13.93000000,100,130,165243,69592193,13.25000000,11,1,13.20000000,28,1,12.99000000,100,1,12.88000000,2,1,12.73000000,100,1,12.67000000,100,1,12.47000000,100,1,12.46000000,100,1,12.43000000,700,1,12.42000000,700,1,13.40000000,208,12,13.67000000,100,1,13.78000000,2,1,13.93000000,102,2,13.94000000,100,1,14.00000000,100,1,14.20000000,900,3,14.21000000,100,1,14.26000000,700,1,14.27000000,700,1,ARL,44066417
544,2025-07-17T13:46:09.936896832Z,2025-07-17T13:46:09.936731544Z,160,2,1108,A,A,0,14.48000000,100,130,165288,69592194,13.25000000,11,1,13.20000000,28,1,12.99000000,100,1,12.88000000,2,1,12.73000000,100,1,12.67000000,100,1,12.47000000,100,1,12.46000000,100,1,12.43000000,700,1,12.42000000,700,1,13.40000000,208,12,13.67000000,100,1,13.78000000,2,1,13.93000000,102,2,13.94000000,100,1,14.00000000,100,1,14.20000000,900,3,14.21000000,100,1,14.26000000,700,1,14.27000000,700,1,ARL,84624129
545,2025-07-17T13:46:09.937622396Z,2025-07-17T13:46:09.937457145Z,160,2,1108,C,A,0,15.01000000,100,0,165251,69592231,13.25000000,11,1,13.20000000,28,1,12.99000000,100,1,12.88000000,2,1,12.73000000,100,1,12.67000000,100,1,12.47000000,100,1,12.46000000,100,1,12.43000000,700,1,12.42000000,700,1,13.40000000,208,12,13.67000000,100,1,13.78000000,2,1,13.93000000,102,2,13.94000000,100,1,14.00000000,100,1,14.20000000,900,3,14.21000000,100,1,14.26000000,700,1,14.27000000,700,1,ARL,84611613
546,2025-07-17T13:46:09.937622396Z,2025-07-17T13:46:09.937457145Z,160,2,1108,A,A,0,15.06000000,100,130,165251,69592231,13.25000000,11,1,13.20000000,28,1,12.99000000,100,1,12.88000000,2,1,12.73000000,100,1,12.67000000,100,1,12.47000000,100,1,12.46000000,100,1,12.43000000,700,1,12.42000000,700,1,13.40000000,208,12,13.67000000,100,1,13.78000000,2,1,13.93000000,102,2,13.94000000,100,1,14.00000000,100,1,14.20000000,900,3,14.21000000,100,1,14.26000000,700,1,14.27000000,700,1,ARL,84624201
547,2025-07-17T13:46:10.046960966Z,2025-07-17T13:46:10.046795728Z,160,2,1108,C,A,0,14.70000000,700,130,165238,69596523,13.25000000,11,1,13.20000000,28,1,12.99000000,100,1,12.88000000,2,1,12.73000000,100,1,12.67000000,100,1,12.47000000,100,1,12.46000000,100,1,12.43000000,700,1,12.42000000,700,1,13.40000000,208,12,13.67000000,100,1,13.78000000,2,1,13.93000000,102,2,13.94000000,100,1,14.00000000,100,1,14.20000000,900,3,14.21000000,100,1,14.26000000,700,1,14.27000000,700,1,ARL,84609321
548,2025-07-17T13:46:10.046962793Z,2025-07-17T13:46:10.046796743Z,160,2,1108,C,A,0,14.63000000,700,130,166050,69596524,13.25000000,11,1,13.20000000,28,1,12.99000000,100,1,12.88000000,2,1,12.73000000,100,1,12.67000000,100,1,12.47000000,100,1,12.46000000,100,1,12.43000000,700,1,12.42000000,700,1,13.40000000,208,12,13.67000000,100,1,13.78000000,2,1,13.93000000,102,2,13.94000000,100,1,14.00000000,100,1,14.20000000,900,3,14.21000000,100,1,14.26000000,700,1,14.27000000,700,1,ARL,84612081
549,2025-07-17T13:46:10.047001176Z,2025-07-17T13:46:10.046834863Z,160,2,1108,A,A,0,14.99000000,700,0,166313,69596525,13.25000000,11,1,13.20000000,28,1,12.99000000,100,1,12.88000000,2,1,12.73000000,100,1,12.67000000,100,1,12.47000000,100,1,12.46000000,100,1,12.43000000,700,1,12.42000000,700,1,13.40000000,208,12,13.67000000,100,1,13.78000000,2,1,13.93000000,102,2,13.94000000,100,1,14.00000000,100,1,14.20000000,900,3,14.21000000,100,1,14.26000000,700,1,14.27000000,700,1,ARL,84628757
550,2025-07-17T13:46:10.047001176Z,2025-07-17T13:46:10.046835277Z,160,2,1108,A,A,0,14.91000000,700,130,165899,69596526,13.25000000,11,1,13.20000000,28,1,12.99000000,100,1,12.88000000,2,1,12.73000000,100,1,12.67000000,100,1,12.47000000,100,1,12.46000000,100,1,12.43000000,700,1,12.42000000,700,1,13.40000000,208,12,13.67000000,100,1,13.78000000,2,1,13.93000000,102,2,13.94000000,100,1,14.00000000,100,1,14.20000000,900,3,14.21000000,100,1,14.26000000,700,1,14.27000000,700,1,ARL,84628761
551,2025-07-17T13:46:10.047030471Z,2025-07-17T13:46:10.046864551Z,160,2,1108,A,A,0,16.20000000,100,130,165920,69596527,13.25000000,11,1,13.20000000,28,1,12.99000000,100,1,12.88000000,2,1,12.73000000,100,1,12.67000000,100,1,12.47000000,100,1,12.46000000,100,1,12.43000000,700,1,12.42000000,700,1,13.40000000,208,12,13.67000000,100,1,13.78000000,2,1,13.93000000,102,2,13.94000000,100,1,14.00000000,100,1,14.20000000,900,3,14.21000000,100,1,14.26000000,700,1,14.27000000,700,1,ARL,84628765
552,2025-07-17T13:46:10.047042954Z,2025-07-17T13:46:10.046877789Z,160,2,1108,C,A,0,15.89000000,100,130,165165,69596529,13.25000000,11,1,13.20000000,28,1,12.99000000,100,1,12.88000000,2,1,12.73000000,100,1,12.67000000,100,1,12.47000000,100,1,12.46000000,100,1,12.43000000,700,1,12.42000000,700,1,13.40000000,208,12,13.67000000,100,1,13.78000000,2,1,13.93000000,102,2,13.94000000,100,1,14.00000000,100,1,14.20000000,900,3,14.21000000,100,1,14.26000000,700,1,14.27000000,700,1,ARL,84609309
553,2025-07-17T13:46:10.047089640Z,2025-07-17T13:46:10.046924268Z,160,2,1108,C,A,0,13.93000000,2,0,165372,69596531,13.25000000,11,1,13.20000000,28,1,12.99000000,100,1,12.88000000,2,1,12.73000000,100,1,12.67000000,100,1,12.47000000,100,1,12.46000000,100,1,12.43000000,700,1,12.42000000,700,1,13.40000000,208,12,13.67000000,100,1,13.78000000,2,1,13.93000000,102,2,13.94000000,100,1,14.00000000,100,1,14.20000000,900,3,14.21000000,100,1,14.26000000,700,1,14.27000000,700,1,ARL,84609637
554,2025-07-17T13:46:10.047089640Z,2025-07-17T13:46:10.046924268Z,160,2,1108,A,A,0,14.20000000,2,130,165372,69596531,13.25000000,11,1,13.20000000,28,1,12.99000000,100,1,12.88000000,2,1,12.73000000,100,1,12.67000000,100,1,12.47000000,100,1,12.46000000,100,1,12.43000000,700,1,12.42000000,700,1,13.40000000,208,12,13.67000000,100,1,13.78000000,2,1,13.93000000,102,2,13.94000000,100,1,14.00000000,100,1,14.20000000,902,4,14.21000000,100,1,14.26000000,700,1,14.27000000,700,1,ARL,84628773
555,2025-07-17T13:46:10.047429477Z,2025-07-17T13:46:10.047264301Z,160,2,1108,C,A,0,14.28000000,100,130,165176,69596542,13.25000000,11,1,13.20000000,28,1,12.99000000,100,1,12.88000000,2,1,12.73000000,100,1,12.67000000,100,1,12.47000000,100,1,12.46000000,100,1,12.43000000,700,1,12.42000000,700,1,13.40000000,208,12,13.67000000,100,1,13.78000000,2,1,13.93000000,102,2,13.94000000,100,1,14.00000000,100,1,14.20000000,902,4,14.21000000,100,1,14.26000000,700,1,14.27000000,700,1,ARL,84607809
556,2025-07-17T13:46:10.047479201Z,2025-07-17T13:46:10.047313929Z,160,2,1108,C,A,0,14.67000000,700,130,165272,69596543,13.25000000,11,1,13.20000000,28,1,12.99000000,100,1,12.88000000,2,1,12.73000000,100,1,12.67000000,100,1,12.47000000,100,1,12.46000000,100,1,12.43000000,700,1,12.42000000,700,1,13.40000000,208,12,13.67000000,100,1,13.78000000,2,1,13.93000000,102,2,13.94000000,100,1,14.00000000,100,1,14.20000000,902,4,14.21000000,100,1,14.26000000,700,1,14.27000000,700,1,ARL,84609409
557,2025-07-17T13:46:10.047784342Z,2025-07-17T13:46:10.047618250Z,160,2,1108,A,A,0,14.83000000,100,128,166092,69596548,13.25000000,11,1,13.20000000,28,1,12.99000000,100,1,12.88000000,2,1,12.73000000,100,1,12.67000000,100,1,12.47000000,100,1,12.46000000,100,1,12.43000000,700,1,12.42000000,700,1,13.40000000,208,12,13.67000000,100,1,13.78000000,2,1,13.93000000,102,2,13.94000000,100,1,14.00000000,100,1,14.20000000,902,4,14.21000000,100,1,14.26000000,700,1,14.27000000,700,1,ARL,84628793
558,2025-07-17T13:46:10.047806230Z,2025-07-17T13:46:10.047640842Z,160,2,1108,C,A,0,14.46000000,700,130,165388,69596550,13.25000000,11,1,13.20000000,28,1,12.99000000,100,1,12.88000000,2,1,12.73000000,100,1,12.67000000,100,1,12.47000000,100,1,12.46000000,100,1,12.43000000,700,1,12.42000000,700,1,13.40000000,208,12,13.67000000,100,1,13.78000000,2,1,13.93000000,102,2,13.94000000,100,1,14.00000000,100,1,14.20000000,902,4,14.21000000,100,1,14.26000000,700,1,14.27000000,700,1,ARL,44548325
559,2025-07-17T13:46:10.047885265Z,2025-07-17T13:46:10.047719954Z,160,2,1108,A,A,0,14.95000000,700,130,165311,69596551,13.25000000,11,1,13.20000000,28,1,12.99000000,100,1,12.88000000,2,1,12.73000000,100,1,12.67000000,100,1,12.47000000,100,1,12.46000000,100,1,12.43000000,700,1,12.42000000,700,1,13.40000000,208,12,13.67000000,100,1,13.78000000,2,1,13.93000000,102,2,13.94000000,100,1,14.00000000,100,1,14.20000000,902,4,14.21000000,100,1,14.26000000,700,1,14.27000000,700,1,ARL,84628797
560,2025-07-17T13:46:10.047929072Z,2025-07-17T13:46:10.047763743Z,160,2,1108,C,A,0,14.91000000,100,0,165329,69596552,13.25000000,11,1,13.20000000,28,1,12.99000000,100,1,12.88000000,2,1,12.73000000,100,1,12.67000000,100,1,12.47000000,100,1,12.46000000,100,1,12.43000000,700,1,12.42000000,700,1,13.40000000,208,12,13.67000000,100,1,13.78000000,2,1,13.93000000,102,2,13.94000000,100,1,14.00000000,100,1,14.20000000,902,4,14.21000000,100,1,14.26000000,700,1,14.27000000,700,1,ARL,84609389
561,2025-07-17T13:46:10.047929072Z,2025-07-17T13:46:10.047763743Z,160,2,1108,A,A,0,15.20000000,100,130,165329,69596552,13.25000000,11,1,13.20000000,28,1,12.99000000,100,1,12.88000000,2,1,12.73000000,100,1,12.67000000,100,1,12.47000000,100,1,12.46000000,100,1,12.43000000,700,1,12.42000000,700,1,13.40000000,208,12,13.67000000,100,1,13.78000000,2,1,13.93000000,102,2,13.94000000,100,1,14.00000000,100,1,14.20000000,902,4,14.21000000,100,1,14.26000000,700,1,14.27000000,700,1,ARL,84628801
562,2025-07-17T13:46:10.047983286Z,2025-07-17T13:46:10.047817649Z,160,2,1108,C,A,0,15.06000000,100,0,165637,69596553,13.25000000,11,1,13.20000000,28,1,12.99000000,100,1,12.88000000,2,1,12.73000000,100,1,12.67000000,100,1,12.47000000,100,1,12.46000000,100,1,12.43000000,700,1,12.42000000,700,1,13.40000000,208,12,13.67000000,100,1,13.78000000,2,1,13.93000000,102,2,13.94000000,100,1,14.00000000,100,1,14.20000000,902,4,14.21000000,100,1,14.26000000,700,1,14.27000000,700,1,ARL,84624201
563,2025-07-17T13:46:10.047983286Z,2025-07-17T13:46:10.047817649Z,160,2,1108,A,A,0,15.30000000,100,130,165637,69596553,13.25000000,11,1,13.20000000,28,1,12.99000000,100,1,12.88000000,2,1,12.73000000,100,1,12.67000000,100,1,12.47000000,100,1,12.46000000,100,1,12.43000000,700,1,12.42000000,700,1,13.40000000,208,12,13.67000000,100,1,13.78000000,2,1,13.93000000,102,2,13.94000000,100,1,14.00000000,100,1,14.20000000,902,4,14.21000000,100,1,14.26000000,700,1,14.27000000,700,1,ARL,84628813
564,2025-07-17T13:46:10.048529147Z,2025-07-17T13:46:10.048363798Z,160,2,1108,A,A,0,15.14000000,700,130,165349,69596568,13.25000000,11,1,13.20000000,28,1,12.99000000,100,1,12.88000000,2,1,12.73000000,100,1,12.67000000,100,1,12.47000000,100,1,12.46000000,100,1,12.43000000,700,1,12.42000000,700,1,13.40000000,208,12,13.67000000,100,1,13.78000000,2,1,13.93000000,102,2,13.94000000,100,1,14.00000000,100,1,14.20000000,902,4,14.21000000,100,1,14.26000000,700,1,14.27000000,700,1,ARL,84628829
565,2025-07-17T13:46:10.048840949Z,2025-07-17T13:46:10.048674815Z,160,2,1108,C,A,0,15.33000000,100,0,166134,69596577,13.25000000,11,1,13.20000000,28,1,12.99000000,100,1,12.88000000,2,1,12.73000000,100,1,12.67000000,100,1,12.47000000,100,1,12.46000000,100,1,12.43000000,700,1,12.42000000,700,1,13.40000000,208,12,13.67000000,100,1,13.78000000,2,1,13.93000000,102,2,13.94000000,100,1,14.00000000,100,1,14.20000000,902,4,14.21000000,100,1,14.26000000,700,1,14.27000000,700,1,ARL,84609385
566,2025-07-17T13:46:10.048840949Z,2025-07-17T13:46:10.048674815Z,160,2,1108,A,A,0,15.64000000,100,130,166134,69596577,13.25000000,11,1,13.20000000,28,1,12.99000000,100,1,12.88000000,2,1,12.73000000,100,1,12.67000000,100,1,12.47000000,100,1,12.46000000,100,1,12.43000000,700,1,12.42000000,700,1,13.40000000,208,12,13.67000000,100,1,13.78000000,2,1,13.93000000,102,2,13.94000000,100,1,14.00000000,100,1,14.20000000,902,4,14.21000000,100,1,14.26000000,700,1,14.27000000,700,1,ARL,84628833
567,2025-07-17T13:46:10.051935025Z,2025-07-17T13:46:10.051769303Z,160,2,1108,C,A,0,17.70000000,100,0,165722,69596649,13.25000000,11,1,13.20000000,28,1,12.99000000,100,1,12.88000000,2,1,12.73000000,100,1,12.67000000,100,1,12.47000000,100,1,12.46000000,100,1,12.43000000,700,1,12.42000000,700,1,13.40000000,208,12,13.67000000,100,1,13.78000000,2,1,13.93000000,102,2,13.94000000,100,1,14.00000000,100,1,14.20000000,902,4,14.21000000,100,1,14.26000000,700,1,14.27000000,700,1,ARL,84609557
568,2025-07-17T13:46:10.051935025Z,2025-07-17T13:46:10.051769303Z,160,2,1108,A,A,0,18.05000000,100,130,165722,69596649,13.25000000,11,1,13.20000000,28,1,12.99000000,100,1,12.88000000,2,1,12.73000000,100,1,12.67000000,100,1,12.47000000,100,1,12.46000000,100,1,12.43000000,700,1,12.42000000,700,1,13.40000000,208,12,13.67000000,100,1,13.78000000,2,1,13.93000000,102,2,13.94000000,100,1,14.00000000,100,1,14.20000000,902,4,14.21000000,100,1,14.26000000,700,1,14.27000000,700,1,ARL,84628913
569,2025-07-17T13:46:10.054332558Z,2025-07-17T13:46:10.054167322Z,160,2,1108,C,A,0,16.02000000,100,0,165236,69596777,13.25000000,11,1,13.20000000,28,1,12.99000000,100,1,12.88000000,2,1,12.73000000,100,1,12.67000000,100,1,12.47000000,100,1,12.46000000,100,1,12.43000000,700,1,12.42000000,700,1,13.40000000,208,12,13.67000000,100,1,13.78000000,2,1,13.93000000,102,2,13.94000000,100,1,14.00000000,100,1,14.20000000,902,4,14.21000000,100,1,14.26000000,700,1,14.27000000,700,1,ARL,84609645
570,2025-07-17T13:46:10.054332558Z,2025-07-17T13:46:10.054167322Z,160,2,1108,A,A,0,16.35000000,100,130,165236,69596777,13.25000000,11,1,13.20000000,28,1,12.99000000,100,1,12.88000000,2,1,12.73000000,100,1,12.67000000,100,1,12.47000000,100,1,12.46000000,100,1,12.43000000,700,1,12.42000000,700,1,13.40000000,208,12,13.67000000,100,1,13.78000000,2,1,13.93000000,102,2,13.94000000,100,1,14.00000000,100,1,14.20000000,902,4,14.21000000,100,1,14.26000000,700,1,14.27000000,700,1,ARL,84629065
571,2025-07-17T13:46:10.055434148Z,2025-07-17T13:46:10.055269067Z,160,2,1108,C,A,0,14.21000000,100,130,165081,69596798,13.25000000,11,1,13.20000000,28,1,12.99000000,100,1,12.88000000,2,1,12.73000000,100,1,12.67000000,100,1,12.47000000,100,1,12.46000000,100,1,12.43000000,700,1,12.42000000,700,1,13.40000000,208,12,13.67000000,100,1,13.78000000,2,1,13.93000000,102,2,13.94000000,100,1,14.00000000,100,1,14.20000000,902,4,14.21000000,100,1,14.26000000,700,1,14.27000000,700,1,ARL,84609733
572,2025-07-17T13:46:10.055483249Z,2025-07-17T13:46:10.055317945Z,160,2,1108,A,A,0,14.48000000,100,130,165304,69596799,13.25000000,11,1,13.20000000,28,1,12.99000000,100,1,12.88000000,2,1,12.73000000,100,1,12.67000000,100,1,12.47000000,100,1,12.46000000,100,1,12.43000000,700,1,12.42000000,700,1,13.40000000,208,12,13.67000000,100,1,13.78000000,2,1,13.93000000,102,2,13.94000000,100,1,14.00000000,100,1,14.20000000,902,4,14.21000000,100,1,14.26000000,700,1,14.27000000,700,1,ARL,84629093
573,2025-07-17T13:46:10.061411059Z,2025-07-17T13:46:10.061246123Z,160,2,1108,C,A,0,14.48000000,100,130,164936,69596987,13.25000000,11,1,13.20000000,28,1,12.99000000,100,1,12.88000000,2,1,12.73000000,100,1,12.67000000,100,1,12.47000000,100,1,12.46000000,100,1,12.43000000,700,1,12.42000000,700,1,13.40000000,208,12,13.67000000,100,1,13.78000000,2,1,13.93000000,102,2,13.94000000,100,1,14.00000000,100,1,14.20000000,902,4,14.21000000,100,1,14.26000000,700,1,14.27000000,700,1,ARL,84629093
574,2025-07-17T13:46:10.061459915Z,2025-07-17T13:46:10.061294728Z,160,2,1108,A,A,0,14.59000000,100,130,165187,69596990,13.25000000,11,1,13.20000000,28,1,12.99000000,100,1,12.88000000,2,1,12.73000000,100,1,12.67000000,100,1,12.47000000,100,1,12.46000000,100,1,12.43000000,700,1,12.42000000,700,1,13.40000000,208,12,13.67000000,100,1,13.78000000,2,1,13.93000000,102,2,13.94000000,100,1,14.00000000,100,1,14.20000000,902,4,14.21000000,100,1,14.26000000,700,1,14.27000000,700,1,ARL,84629329
575,2025-07-17T13:46:10.087891846Z,2025-07-17T13:46:10.087725560Z,160,2,1108,C,A,0,15.33000000,100,0,166286,69597697,13.25000000,11,1,13.20000000,28,1,12.99000000,100,1,12.88000000,2,1,12.73000000,100,1,12.67000000,100,1,12.47000000,100,1,12.46000000,100,1,12.43000000,700,1,12.42000000,700,1,13.40000000,208,12,13.67000000,100,1,13.78000000,2,1,13.93000000,102,2,13.94000000,100,1,14.00000000,100,1,14.20000000,902,4,14.21000000,100,1,14.26000000,700,1,14.27000000,700,1,ARL,84611025
576,2025-07-17T13:46:10.087891846Z,2025-07-17T13:46:10.087725560Z,160,2,1108,A,A,0,15.73000000,100,128,166286,69597697,13.25000000,11,1,13.20000000,28,1,12.99000000,100,1,12.88000000,2,1,12.73000000,100,1,12.67000000,100,1,12.47000000,100,1,12.46000000,100,1,12.43000000,700,1,12.42000000,700,1,13.40000000,208,12,13.67000000,100,1,13.78000000,2,1,13.93000000,102,2,13.94000000,100,1,14.00000000,100,1,14.20000000,902,4,14.21000000,100,1,14.26000000,700,1,14.27000000,700,1,ARL,84629953
577,2025-07-17T13:46:10.098194757Z,2025-07-17T13:46:10.098029439Z,160,2,1108,C,A,0,15.30000000,100,0,165318,69597813,13.25000000,11,1,13.20000000,28,1,12.99000000,100,1,12.88000000,2,1,12.73000000,100,1,12.67000000,100,1,12.47000000,100,1,12.46000000,100,1,12.43000000,700,1,12.42000000,700,1,13.40000000,208,12,13.67000000,100,1,13.78000000,2,1,13.93000000,102,2,13.94000000,100,1,14.00000000,100,1,14.20000000,902,4,14.21000000,100,1,14.26000000,700,1,14.27000000,700,1,ARL,84628813
578,2025-07-17T13:46:10.098194757Z,2025-07-17T13:46:10.098029439Z,160,2,1108,A,A,0,15.41000000,100,130,165318,69597813,13.25000000,11,1,13.20000000,28,1,12.99000000,100,1,12.88000000,2,1,12.73000000,100,1,12.67000000,100,1,12.47000000,100,1,12.46000000,100,1,12.43000000,700,1,12.42000000,700,1,13.40000000,208,12,13.67000000,100,1,13.78000000,2,1,13.93000000,102,2,13.94000000,100,1,14.00000000,100,1,14.20000000,902,4,14.21000000,100,1,14.26000000,700,1,14.27000000,700,1,ARL,84630217
579,2025-07-17T13:46:10.109235050Z,2025-07-17T13:46:10.109069598Z,160,2,1108,C,A,0,14.91000000,100,0,165452,69598154,13.25000000,11,1,13.20000000,28,1,12.99000000,100,1,12.88000000,2,1,12.73000000,100,1,12.67000000,100,1,12.47000000,100,1,12.46000000,100,1,12.43000000,700,1,12.42000000,700,1,13.40000000,208,12,13.67000000,100,1,13.78000000,2,1,13.93000000,102,2,13.94000000,100,1,14.00000000,100,1,14.20000000,902,4,14.21000000,100,1,14.26000000,700,1,14.27000000,700,1,ARL,84612773
580,2025-07-17T13:46:10.109235050Z,2025-07-17T13:46:10.109069598Z,160,2,1108,A,A,0,15.31000000,100,130,165452,69598154,13.25000000,11,1,13.20000000,28,1,12.99000000,100,1,12.88000000,2,1,12.73000000,100,1,12.67000000,100,1,12.47000000,100,1,12.46000000,100,1,12.43000000,700,1,12.42000000,700,1,13.40000000,208,12,13.67000000,100,1,13.78000000,2,1,13.93000000,102,2,13.94000000,100,1,14.00000000,100,1,14.20000000,902,4,14.21000000,100,1,14.26000000,700,1,14.27000000,700,1,ARL,84630849
581,2025-07-17T13:46:10.551481906Z,2025-07-17T13:46:10.551316402Z,160,2,1108,C,A,0,14.47000000,100,0,165504,69614455,13.25000000,11,1,13.20000000,28,1,12.99000000,100,1,12.88000000,2,1,12.73000000,100,1,12.67000000,100,1,12.47000000,100,1,12.46000000,100,1,12.43000000,700,1,12.42000000,700,1,13.40000000,208,12,13.67000000,100,1,13.78000000,2,1,13.93000000,102,2,13.94000000,100,1,14.00000000,100,1,14.20000000,902,4,14.21000000,100,1,14.26000000,700,1,14.27000000,700,1,ARL,84608321
582,2025-07-17T13:46:10.551481906Z,2025-07-17T13:46:10.551316402Z,160,2,1108,A,A,0,15.09000000,100,130,165504,69614455,13.25000000,11,1,13.20000000,28,1,12.99000000,100,1,12.88000000,2,1,12.73000000,100,1,12.67000000,100,1,12.47000000,100,1,12.46000000,100,1,12.43000000,700,1,12.42000000,700,1,13.40000000,208,12,13.67000000,100,1,13.78000000,2,1,13.93000000,102,2,13.94000000,100,1,14.00000000,100,1,14.20000000,902,4,14.21000000,100,1,14.26000000,700,1,14.27000000,700,1,ARL,84650629
583,2025-07-17T13:46:10.904838107Z,2025-07-17T13:46:10.904672934Z,160,2,1108,A,A,0,15.16000000,100,130,165173,69628781,13.25000000,11,1,13.20000000,28,1,12.99000000,100,1,12.88000000,2,1,12.73000000,100,1,12.67000000,100,1,12.47000000,100,1,12.46000000,100,1,12.43000000,700,1,12.42000000,700,1,13.40000000,208,12,13.67000000,100,1,13.78000000,2,1,13.93000000,102,2,13.94000000,100,1,14.00000000,100,1,14.20000000,902,4,14.21000000,100,1,14.26000000,700,1,14.27000000,700,1,ARL,84668677
584,2025-07-17T13:46:10.904858553Z,2025-07-17T13:46:10.904693578Z,160,2,1108,C,A,0,14.76000000,100,130,164975,69628783,13.25000000,11,1,13.20000000,28,1,12.99000000,100,1,12.88000000,2,1,12.73000000,100,1,12.67000000,100,1,12.47000000,100,1,12.46000000,100,1,12.43000000,700,1,12.42000000,700,1,13.40000000,208,12,13.67000000,100,1,13.78000000,2,1,13.93000000,102,2,13.94000000,100,1,14.00000000,100,1,14.20000000,902,4,14.21000000,100,1,14.26000000,700,1,14.27000000,700,1,ARL,84618189
585,2025-07-17T13:46:11.840882444Z,2025-07-17T13:46:11.840717150Z,160,2,1108,A,A,0,14.87000000,100,130,165294,69663346,13.25000000,11,1,13.20000000,28,1,12.99000000,100,1,12.88000000,2,1,12.73000000,100,1,12.67000000,100,1,12.47000000,100,1,12.46000000,100,1,12.43000000,700,1,12.42000000,700,1,13.40000000,208,12,13.67000000,100,1,13.78000000,2,1,13.93000000,102,2,13.94000000,100,1,14.00000000,100,1,14.20000000,902,4,14.21000000,100,1,14.26000000,700,1,14.27000000,700,1,ARL,84708037
586,2025-07-17T13:46:11.840894787Z,2025-07-17T13:46:11.840729407Z,160,2,1108,C,A,0,14.48000000,100,130,165380,69663347,13.25000000,11,1,13.20000000,28,1,12.99000000,100,1,12.88000000,2,1,12.73000000,100,1,12.67000000,100,1,12.47000000,100,1,12.46000000,100,1,12.43000000,700,1,12.42000000,700,1,13.40000000,208,12,13.67000000,100,1,13.78000000,2,1,13.93000000,102,2,13.94000000,100,1,14.00000000,100,1,14.20000000,902,4,14.21000000,100,1,14.26000000,700,1,14.27000000,700,1,ARL,84624129
587,2025-07-17T13:46:23.920813185Z,2025-07-17T13:46:23.920647302Z,160,2,1108,C,B,0,12.88000000,2,0,165883,70104076,13.25000000,11,1,13.20000000,28,1,12.99000000,100,1,12.88000000,2,1,12.73000000,100,1,12.67000000,100,1,12.47000000,100,1,12.46000000,100,1,12.43000000,700,1,12.42000000,700,1,13.40000000,208,12,13.67000000,100,1,13.78000000,2,1,13.93000000,102,2,13.94000000,100,1,14.00000000,100,1,14.20000000,902,4,14.21000000,100,1,14.26000000,700,1,14.27000000,700,1,ARL,58709193
588,2025-07-17T13:46:23.920813185Z,2025-07-17T13:46:23.920647302Z,160,2,1108,A,B,0,13.12000000,2,130,165883,70104076,13.25000000,11,1,13.20000000,28,1,13.12000000,2,1,12.99000000,100,1,12.88000000,2,1,12.73000000,100,1,12.67000000,100,1,12.47000000,100,1,12.46000000,100,1,12.43000000,700,1,13.40000000,208,12,13.67000000,100,1,13.78000000,2,1,13.93000000,102,2,13.94000000,100,1,14.00000000,100,1,14.20000000,902,4,14.21000000,100,1,14.26000000,700,1,14.27000000,700,1,ARL,85194077
589,2025-07-17T13:46:45.786579604Z,2025-07-17T13:46:45.786413307Z,160,2,1108,C,B,0,13.12000000,2,0,166297,70834235,13.25000000,11,1,13.20000000,28,1,13.12000000,2,1,12.99000000,100,1,12.88000000,2,1,12.73000000,100,1,12.67000000,100,1,12.47000000,100,1,12.46000000,100,1,12.43000000,700,1,13.40000000,208,12,13.67000000,100,1,13.78000000,2,1,13.93000000,102,2,13.94000000,100,1,14.00000000,100,1,14.20000000,902,4,14.21000000,100,1,14.26000000,700,1,14.27000000,700,1,ARL,85194077
590,2025-07-17T13:46:45.786579604Z,2025-07-17T13:46:45.786413307Z,160,2,1108,A,B,0,13.20000000,2,130,166297,70834235,13.25000000,11,1,13.20000000,30,2,13.12000000,2,1,12.99000000,100,1,12.88000000,2,1,12.73000000,100,1,12.67000000,100,1,12.47000000,100,1,12.46000000,100,1,12.43000000,700,1,13.40000000,208,12,13.67000000,100,1,13.78000000,2,1,13.93000000,102,2,13.94000000,100,1,14.00000000,100,1,14.20000000,902,4,14.21000000,100,1,14.26000000,700,1,14.27000000,700,1,ARL,86056033
591,2025-07-17T13:47:34.987167177Z,2025-07-17T13:47:34.987001473Z,160,2,1108,C,B,0,13.20000000,2,0,165704,72269967,13.25000000,11,1,13.20000000,30,2,13.12000000,2,1,12.99000000,100,1,12.88000000,2,1,12.73000000,100,1,12.67000000,100,1,12.47000000,100,1,12.46000000,100,1,12.43000000,700,1,13.40000000,208,12,13.67000000,100,1,13.78000000,2,1,13.93000000,102,2,13.94000000,100,1,14.00000000,100,1,14.20000000,902,4,14.21000000,100,1,14.26000000,700,1,14.27000000,700,1,ARL,86056033
592,2025-07-17T13:47:34.987167177Z,2025-07-17T13:47:34.987001473Z,160,2,1108,A,B,0,13.26000000,2,130,165704,72269967,13.26000000,2,1,13.25000000,11,1,13.20000000,30,2,13.12000000,2,1,12.99000000,100,1,12.88000000,2,1,12.73000000,100,1,12.67000000,100,1,12.47000000,100,1,12.46000000,100,1,13.40000000,208,12,13.67000000,100,1,13.78000000,2,1,13.93000000,102,2,13.94000000,100,1,14.00000000,100,1,14.20000000,902,4,14.21000000,100,1,14.26000000,700,1,14.27000000,700,1,ARL,87750309
593,2025-07-17T13:49:46.533586484Z,2025-07-17T13:49:46.533420775Z,160,2,1108,C,A,0,14.30000000,100,0,165709,76393090,13.26000000,2,1,13.25000000,11,1,13.20000000,30,2,13.12000000,2,1,12.99000000,100,1,12.88000000,2,1,12.73000000,100,1,12.67000000,100,1,12.47000000,100,1,12.46000000,100,1,13.40000000,208,12,13.67000000,100,1,13.78000000,2,1,13.93000000,102,2,13.94000000,100,1,14.00000000,100,1,14.20000000,902,4,14.21000000,100,1,14.26000000,700,1,14.27000000,700,1,ARL,77910357
594,2025-07-17T13:49:46.533586484Z,2025-07-17T13:49:46.533420775Z,160,2,1108,A,A,0,15.26000000,100,130,165709,76393090,13.26000000,2,1,13.25000000,11,1,13.20000000,30,2,13.12000000,2,1,12.99000000,100,1,12.88000000,2,1,12.73000000,100,1,12.67000000,100,1,12.47000000,100,1,12.46000000,100,1,13.40000000,208,12,13.67000000,100,1,13.78000000,2,1,13.93000000,102,2,13.94000000,100,1,14.00000000,100,1,14.20000000,902,4,14.21000000,100,1,14.26000000,700,1,14.27000000,700,1,ARL,92510725
595,2025-07-17T13:49:46.533732414Z,2025-07-17T13:49:46.533566805Z,160,2,1108,C,A,0,14.30000000,100,0,165609,76393092,13.26000000,2,1,13.25000000,11,1,13.20000000,30,2,13.12000000,2,1,12.99000000,100,1,12.88000000,2,1,12.73000000,100,1,12.67000000,100,1,12.47000000,100,1,12.46000000,100,1,13.40000000,208,12,13.67000000,100,1,13.78000000,2,1,13.93000000,102,2,13.94000000,100,1,14.00000000,100,1,14.20000000,902,4,14.21000000,100,1,14.26000000,700,1,14.27000000,700,1,ARL,74589605
596,2025-07-17T13:49:46.533732414Z,2025-07-17T13:49:46.533566805Z,160,2,1108,A,A,0,15.26000000,100,130,165609,76393092,13.26000000,2,1,13.25000000,11,1,13.20000000,30,2,13.12000000,2,1,12.99000000,100,1,12.88000000,2,1,12.73000000,100,1,12.67000000,100,1,12.47000000,100,1,12.46000000,100,1,13.40000000,208,12,13.67000000,100,1,13.78000000,2,1,13.93000000,102,2,13.94000000,100,1,14.00000000,100,1,14.20000000,902,4,14.21000000,100,1,14.26000000,700,1,14.27000000,700,1,ARL,92510729
597,2025-07-17T13:49:46.533768662Z,2025-07-17T13:49:46.533603070Z,160,2,1108,C,A,0,14.91000000,700,130,165592,76393093,13.26000000,2,1,13.25000000,11,1,13.20000000,30,2,13.12000000,2,1,12.99000000,100,1,12.88000000,2,1,12.73000000,100,1,12.67000000,100,1,12.47000000,100,1,12.46000000,100,1,13.40000000,208,12,13.67000000,100,1,13.78000000,2,1,13.93000000,102,2,13.94000000,100,1,14.00000000,100,1,14.20000000,902,4,14.21000000,100,1,14.26000000,700,1,14.27000000,700,1,ARL,84628761
598,2025-07-17T13:49:46.533810238Z,2025-07-17T13:49:46.533644528Z,160,2,1108,A,A,0,15.07000000,700,130,165710,76393094,13.26000000,2,1,13.25000000,11,1,13.20000000,30,2,13.12000000,2,1,12.99000000,100,1,12.88000000,2,1,12.73000000,100,1,12.67000000,100,1,12.47000000,100,1,12.46000000,100,1,13.40000000,208,12,13.67000000,100,1,13.78000000,2,1,13.93000000,102,2,13.94000000,100,1,14.00000000,100,1,14.20000000,902,4,14.21000000,100,1,14.26000000,700,1,14.27000000,700,1,ARL,92510741
599,2025-07-17T13:49:46.534488891Z,2025-07-17T13:49:46.534323177Z,160,2,1108,C,A,0,15.41000000,100,0,165714,76393099,13.26000000,2,1,13.25000000,11,1,13.20000000,30,2,13.12000000,2,1,12.99000000,100,1,12.88000000,2,1,12.73000000,100,1,12.67000000,100,1,12.47000000,100,1,12.46000000,100,1,13.40000000,208,12,13.67000000,100,1,13.78000000,2,1,13.93000000,102,2,13.94000000,100,1,14.00000000,100,1,14.20000000,902,4,14.21000000,100,1,14.26000000,700,1,14.27000000,700,1,ARL,84630217
600,2025-07-17T13:49:46.534488891Z,2025-07-17T13:49:46.534323177Z,160,2,1108,A,A,0,15.46000000,100,130,165714,76393099,13.26000000,2,1,13.25000000,11,1,13.20000000,30,2,13.12000000,2,1,12.99000000,100,1,12.88000000,2,1,12.73000000,100,1,12.67000000,100,1,12.47000000,100,1,12.46000000,100,1,13.40000000,208,12,13.67000000,100,1,13.78000000,2,1,13.93000000,102,2,13.94000000,100,1,14.00000000,100,1,14.20000000,902,4,14.21000000,100,1,14.26000000,700,1,14.27000000,700,1,ARL,92510753
601,2025-07-17T13:49:46.534555834Z,2025-07-17T13:49:46.534390219Z,160,2,1108,C,A,0,15.20000000,100,0,165615,76393100,13.26000000,2,1,13.25000000,11,1,13.20000000,30,2,13.12000000,2,1,12.99000000,100,1,12.88000000,2,1,12.73000000,100,1,12.67000000,100,1,12.47000000,100,1,12.46000000,100,1,13.40000000,208,12,13.67000000,100,1,13.78000000,2,1,13.93000000,102,2,13.94000000,100,1,14.00000000,100,1,14.20000000,902,4,14.21000000,100,1,14.26000000,700,1,14.27000000,700,1,ARL,84628801
602,2025-07-17T13:49:46.534555834Z,2025-07-17T13:49:46.534390219Z,160,2,1108,A,A,0,15.36000000,100,130,165615,76393100,13.26000000,2,1,13.25000000,11,1,13.20000000,30,2,13.12000000,2,1,12.99000000,100,1,12.88000000,2,1,12.73000000,100,1,12.67000000,100,1,12.47000000,100,1,12.46000000,100,1,13.40000000,208,12,13.67000000,100,1,13.78000000,2,1,13.93000000,102,2,13.94000000,100,1,14.00000000,100,1,14.20000000,902,4,14.21000000,100,1,14.26000000,700,1,14.27000000,700,1,ARL,92510761
603,2025-07-17T13:49:46.535182699Z,2025-07-17T13:49:46.535017084Z,160,2,1108,C,A,0,16.35000000,100,0,165615,76393115,13.26000000,2,1,13.25000000,11,1,13.20000000,30,2,13.12000000,2,1,12.99000000,100,1,12.88000000,2,1,12.73000000,100,1,12.67000000,100,1,12.47000000,100,1,12.46000000,100,1,13.40000000,208,12,13.67000000,100,1,13.78000000,2,1,13.93000000,102,2,13.94000000,100,1,14.00000000,100,1,14.20000000,902,4,14.21000000,100,1,14.26000000,700,1,14.27000000,700,1,ARL,84629065
604,2025-07-17T13:49:46.535182699Z,2025-07-17T13:49:46.535017084Z,160,2,1108,A,A,0,16.51000000,100,130,165615,76393115,13.26000000,2,1,13.25000000,11,1,13.20000000,30,2,13.12000000,2,1,12.99000000,100,1,12.88000000,2,1,12.73000000,100,1,12.67000000,100,1,12.47000000,100,1,12.46000000,100,1,13.40000000,208,12,13.67000000,100,1,13.78000000,2,1,13.93000000,102,2,13.94000000,100,1,14.00000000,100,1,14.20000000,902,4,14.21000000,100,1,14.26000000,700,1,14.27000000,700,1,ARL,92510813
605,2025-07-17T13:49:46.535737854Z,2025-07-17T13:49:46.535572067Z,160,2,1108,C,A,0,18.05000000,100,0,165787,76393138,13.26000000,2,1,13.25000000,11,1,13.20000000,30,2,13.12000000,2,1,12.99000000,100,1,12.88000000,2,1,12.73000000,100,1,12.67000000,100,1,12.47000000,100,1,12.46000000,100,1,13.40000000,208,12,13.67000000,100,1,13.78000000,2,1,13.93000000,102,2,13.94000000,100,1,14.00000000,100,1,14.20000000,902,4,14.21000000,100,1,14.26000000,700,1,14.27000000,700,1,ARL,84628913
606,2025-07-17T13:49:46.535737854Z,2025-07-17T13:49:46.535572067Z,160,2,1108,A,A,0,18.23000000,100,130,165787,76393138,13.26000000,2,1,13.25000000,11,1,13.20000000,30,2,13.12000000,2,1,12.99000000,100,1,12.88000000,2,1,12.73000000,100,1,12.67000000,100,1,12.47000000,100,1,12.46000000,100,1,13.40000000,208,12,13.67000000,100,1,13.78000000,2,1,13.93000000,102,2,13.94000000,100,1,14.00000000,100,1,14.20000000,902,4,14.21000000,100,1,14.26000000,700,1,14.27000000,700,1,ARL,92510841
607,2025-07-17T13:56:11.001810226Z,2025-07-17T13:56:11.001642441Z,160,2,1108,A,B,0,13.28000000,1,128,167785,89819278,13.28000000,1,1,13.26000000,2,1,13.25000000,11,1,13.20000000,30,2,13.12000000,2,1,12.99000000,100,1,12.88000000,2,1,12.73000000,100,1,12.67000000,100,1,12.47000000,100,1,13.40000000,208,12,13.67000000,100,1,13.78000000,2,1,13.93000000,102,2,13.94000000,100,1,14.00000000,100,1,14.20000000,902,4,14.21000000,100,1,14.26000000,700,1,14.27000000,700,1,ARL,107702381
608,2025-07-17T13:56:11.005550129Z,2025-07-17T13:56:11.005384065Z,160,2,1108,A,B,0,13.28000000,10,130,166064,89819705,13.28000000,11,2,13.26000000,2,1,13.25000000,11,1,13.20000000,30,2,13.12000000,2,1,12.99000000,100,1,12.88000000,2,1,12.73000000,100,1,12.67000000,100,1,12.47000000,100,1,13.40000000,208,12,13.67000000,100,1,13.78000000,2,1,13.93000000,102,2,13.94000000,100,1,14.00000000,100,1,14.20000000,902,4,14.21000000,100,1,14.26000000,700,1,14.27000000,700,1,ARL,107702861
609,2025-07-17T13:56:11.005550669Z,2025-07-17T13:56:11.005385425Z,160,2,1108,A,A,0,13.94000000,10,130,165244,89819706,13.28000000,11,2,13.26000000,2,1,13.25000000,11,1,13.20000000,30,2,13.12000000,2,1,12.99000000,100,1,12.88000000,2,1,12.73000000,100,1,12.67000000,100,1,12.47000000,100,1,13.40000000,208,12,13.67000000,100,1,13.78000000,2,1,13.93000000,102,2,13.94000000,110,2,14.00000000,100,1,14.20000000,902,4,14.21000000,100,1,14.26000000,700,1,14.27000000,700,1,ARL,107702865
610,2025-07-17T13:56:11.013819857Z,2025-07-17T13:56:11.013654317Z,160,2,1108,C,A,0,15.26000000,100,0,165540,89820163,13.28000000,11,2,13.26000000,2,1,13.25000000,11,1,13.20000000,30,2,13.12000000,2,1,12.99000000,100,1,12.88000000,2,1,12.73000000,100,1,12.67000000,100,1,12.47000000,100,1,13.40000000,208,12,13.67000000,100,1,13.78000000,2,1,13.93000000,102,2,13.94000000,110,2,14.00000000,100,1,14.20000000,902,4,14.21000000,100,1,14.26000000,700,1,14.27000000,700,1,ARL,92510729
611,2025-07-17T13:56:11.013819857Z,2025-07-17T13:56:11.013654317Z,160,2,1108,A,A,0,14.84000000,100,130,165540,89820163,13.28000000,11,2,13.26000000,2,1,13.25000000,11,1,13.20000000,30,2,13.12000000,2,1,12.99000000,100,1,12.88000000,2,1,12.73000000,100,1,12.67000000,100,1,12.47000000,100,1,13.40000000,208,12,13.67000000,100,1,13.78000000,2,1,13.93000000,102,2,13.94000000,110,2,14.00000000,100,1,14.20000000,902,4,14.21000000,100,1,14.26000000,700,1,14.27000000,700,1,ARL,107703205
612,2025-07-17T13:56:11.026680779Z,2025-07-17T13:56:11.026515306Z,160,2,1108,C,A,0,15.26000000,100,0,165473,89820408,13.28000000,11,2,13.26000000,2,1,13.25000000,11,1,13.20000000,30,2,13.12000000,2,1,12.99000000,100,1,12.88000000,2,1,12.73000000,100,1,12.67000000,100,1,12.47000000,100,1,13.40000000,208,12,13.67000000,100,1,13.78000000,2,1,13.93000000,102,2,13.94000000,110,2,14.00000000,100,1,14.20000000,902,4,14.21000000,100,1,14.26000000,700,1,14.27000000,700,1,ARL,92510725
613,2025-07-17T13:56:11.026680779Z,2025-07-17T13:56:11.026515306Z,160,2,1108,A,A,0,14.84000000,100,130,165473,89820408,13.28000000,11,2,13.26000000,2,1,13.25000000,11,1,13.20000000,30,2,13.12000000,2,1,12.99000000,100,1,12.88000000,2,1,12.73000000,100,1,12.67000000,100,1,12.47000000,100,1,13.40000000,208,12,13.67000000,100,1,13.78000000,2,1,13.93000000,102,2,13.94000000,110,2,14.00000000,100,1,14.20000000,902,4,14.21000000,100,1,14.26000000,700,1,14.27000000,700,1,ARL,107703433
614,2025-07-17T13:56:11.101916770Z,2025-07-17T13:56:11.101751649Z,160,2,1108,C,B,0,13.28000000,1,130,165121,89823845,13.28000000,11,2,13.26000000,2,1,13.25000000,11,1,13.20000000,30,2,13.12000000,2,1,12.99000000,100,1,12.88000000,2,1,12.73000000,100,1,12.67000000,100,1,12.47000000,100,1,13.40000000,208,12,13.67000000,100,1,13.78000000,2,1,13.93000000,102,2,13.94000000,110,2,14.00000000,100,1,14.20000000,902,4,14.21000000,100,1,14.26000000,700,1,14.27000000,700,1,ARL,107702381
615,2025-07-17T13:56:19.511755342Z,2025-07-17T13:56:19.511590204Z,160,2,1108,C,B,0,13.28000000,10,130,165138,90148349,13.28000000,11,2,13.26000000,2,1,13.25000000,11,1,13.20000000,30,2,13.12000000,2,1,12.99000000,100,1,12.88000000,2,1,12.73000000,100,1,12.67000000,100,1,12.47000000,100,1,13.40000000,208,12,13.67000000,100,1,13.78000000,2,1,13.93000000,102,2,13.94000000,110,2,14.00000000,100,1,14.20000000,902,4,14.21000000,100,1,14.26000000,700,1,14.27000000,700,1,ARL,107702861
616,2025-07-17T13:56:22.512134723Z,2025-07-17T13:56:22.511968820Z,160,2,1108,C,A,0,13.94000000,10,130,165903,90281309,13.28000000,11,2,13.26000000,2,1,13.25000000,11,1,13.20000000,30,2,13.12000000,2,1,12.99000000,100,1,12.88000000,2,1,12.73000000,100,1,12.67000000,100,1,12.47000000,100,1,13.40000000,208,12,13.67000000,100,1,13.78000000,2,1,13.93000000,102,2,13.94000000,110,2,14.00000000,100,1,14.20000000,902,4,14.21000000,100,1,14.26000000,700,1,14.27000000,700,1,ARL,107702865
617,2025-07-17T13:56:22.517155918Z,2025-07-17T13:56:22.516990420Z,160,2,1108,C,A,0,14.84000000,100,0,165498,90281853,13.28000000,11,2,13.26000000,2,1,13.25000000,11,1,13.20000000,30,2,13.12000000,2,1,12.99000000,100,1,12.88000000,2,1,12.73000000,100,1,12.67000000,100,1,12.47000000,100,1,13.40000000,208,12,13.67000000,100,1,13.78000000,2,1,13.93000000,102,2,13.94000000,110,2,14.00000000,100,1,14.20000000,902,4,14.21000000,100,1,14.26000000,700,1,14.27000000,700,1,ARL,107703205
618,2025-07-17T13:56:22.517155918Z,2025-07-17T13:56:22.516990420Z,160,2,1108,A,A,0,15.26000000,100,130,165498,90281853,13.28000000,11,2,13.26000000,2,1,13.25000000,11,1,13.20000000,30,2,13.12000000,2,1,12.99000000,100,1,12.88000000,2,1,12.73000000,100,1,12.67000000,100,1,12.47000000,100,1,13.40000000,208,12,13.67000000,100,1,13.78000000,2,1,13.93000000,102,2,13.94000000,110,2,14.00000000,100,1,14.20000000,902,4,14.21000000,100,1,14.26000000,700,1,14.27000000,700,1,ARL,108217045
619,2025-07-17T13:56:22.517527654Z,2025-07-17T13:56:22.517362170Z,160,2,1108,C,A,0,14.84000000,100,0,165484,90281893,13.28000000,11,2,13.26000000,2,1,13.25000000,11,1,13.20000000,30,2,13.12000000,2,1,12.99000000,100,1,12.88000000,2,1,12.73000000,100,1,12.67000000,100,1,12.47000000,100,1,13.40000000,208,12,13.67000000,100,1,13.78000000,2,1,13.93000000,102,2,13.94000000,110,2,14.00000000,100,1,14.20000000,902,4,14.21000000,100,1,14.26000000,700,1,14.27000000,700,1,ARL,107703433
620,2025-07-17T13:56:22.517527654Z,2025-07-17T13:56:22.517362170Z,160,2,1108,A,A,0,15.26000000,100,130,165484,90281893,13.28000000,11,2,13.26000000,2,1,13.25000000,11,1,13.20000000,30,2,13.12000000,2,1,12.99000000,100,1,12.88000000,2,1,12.73000000,100,1,12.67000000,100,1,12.47000000,100,1,13.40000000,208,12,13.67000000,100,1,13.78000000,2,1,13.93000000,102,2,13.94000000,110,2,14.00000000,100,1,14.20000000,902,4,14.21000000,100,1,14.26000000,700,1,14.27000000,700,1,ARL,108217173
621,2025-07-17T13:56:40.757800894Z,2025-07-17T13:56:40.757635216Z,160,2,1108,C,A,0,14.20000000,2,0,165678,90866180,13.28000000,11,2,13.26000000,2,1,13.25000000,11,1,13.20000000,30,2,13.12000000,2,1,12.99000000,100,1,12.88000000,2,1,12.73000000,100,1,12.67000000,100,1,12.47000000,100,1,13.40000000,208,12,13.67000000,100,1,13.78000000,2,1,13.93000000,102,2,13.94000000,110,2,14.00000000,100,1,14.20000000,902,4,14.21000000,100,1,14.26000000,700,1,14.27000000,700,1,ARL,84628773
622,2025-07-17T13:56:40.757800894Z,2025-07-17T13:56:40.757635216Z,160,2,1108,A,A,0,14.36000000,2,130,165678,90866180,13.28000000,11,2,13.26000000,2,1,13.25000000,11,1,13.20000000,30,2,13.12000000,2,1,12.99000000,100,1,12.88000000,2,1,12.73000000,100,1,12.67000000,100,1,12.47000000,100,1,13.40000000,208,12,13.67000000,100,1,13.78000000,2,1,13.93000000,102,2,13.94000000,110,2,14.00000000,100,1,14.20000000,902,4,14.21000000,100,1,14.26000000,700,1,14.27000000,700,1,ARL,108872153
623,2025-07-17T13:57:40.142022323Z,2025-07-17T13:57:40.141855674Z,160,2,1108,C,B,0,13.26000000,2,0,166649,92821039,13.28000000,11,2,13.26000000,2,1,13.25000000,11,1,13.20000000,30,2,13.12000000,2,1,12.99000000,100,1,12.88000000,2,1,12.73000000,100,1,12.67000000,100,1,12.47000000,100,1,13.40000000,208,12,13.67000000,100,1,13.78000000,2,1,13.93000000,102,2,13.94000000,110,2,14.00000000,100,1,14.20000000,902,4,14.21000000,100,1,14.26000000,700,1,14.27000000,700,1,ARL,87750309
624,2025-07-17T13:57:40.142022323Z,2025-07-17T13:57:40.141855674Z,160,2,1108,A,B,0,13.12000000,2,128,166649,92821039,13.28000000,11,2,13.26000000,2,1,13.25000000,11,1,13.20000000,30,2,13.12000000,4,2,12.99000000,100,1,12.88000000,2,1,12.73000000,100,1,12.67000000,100,1,12.47000000,100,1,13.40000000,208,12,13.67000000,100,1,13.78000000,2,1,13.93000000,102,2,13.94000000,110,2,14.00000000,100,1,14.20000000,902,4,14.21000000,100,1,14.26000000,700,1,14.27000000,700,1,ARL,111169049
625,2025-07-17T13:57:44.947757237Z,2025-07-17T13:57:44.947591620Z,160,2,1108,C,A,0,14.36000000,2,0,165617,92961696,13.28000000,11,2,13.26000000,2,1,13.25000000,11,1,13.20000000,30,2,13.12000000,4,2,12.99000000,100,1,12.88000000,2,1,12.73000000,100,1,12.67000000,100,1,12.47000000,100,1,13.40000000,208,12,13.67000000,100,1,13.78000000,2,1,13.93000000,102,2,13.94000000,110,2,14.00000000,100,1,14.20000000,902,4,14.21000000,100,1,14.26000000,700,1,14.27000000,700,1,ARL,108872153
626,2025-07-17T13:57:44.947757237Z,2025-07-17T13:57:44.947591620Z,160,2,1108,A,A,0,14.50000000,2,130,165617,92961696,13.28000000,11,2,13.26000000,2,1,13.25000000,11,1,13.20000000,30,2,13.12000000,4,2,12.99000000,100,1,12.88000000,2,1,12.73000000,100,1,12.67000000,100,1,12.47000000,100,1,13.40000000,208,12,13.67000000,100,1,13.78000000,2,1,13.93000000,102,2,13.94000000,110,2,14.00000000,100,1,14.20000000,902,4,14.21000000,100,1,14.26000000,700,1,14.27000000,700,1,ARL,111347121
627,2025-07-17T13:59:50.477911158Z,2025-07-17T13:59:50.477745739Z,160,2,1108,C,B,0,13.25000000,11,130,165419,96389796,13.28000000,11,2,13.26000000,2,1,13.25000000,11,1,13.20000000,30,2,13.12000000,4,2,12.99000000,100,1,12.88000000,2,1,12.73000000,100,1,12.67000000,100,1,12.47000000,100,1,13.40000000,208,12,13.67000000,100,1,13.78000000,2,1,13.93000000,102,2,13.94000000,110,2,14.00000000,100,1,14.20000000,902,4,14.21000000,100,1,14.26000000,700,1,14.27000000,700,1,ARL,44586753
628,2025-07-17T13:59:50.479576984Z,2025-07-17T13:59:50.479411482Z,160,2,1108,C,B,0,12.36000000,100,0,165502,96389821,13.28000000,11,2,13.26000000,2,1,13.25000000,11,1,13.20000000,30,2,13.12000000,4,2,12.99000000,100,1,12.88000000,2,1,12.73000000,100,1,12.67000000,100,1,12.47000000,100,1,13.40000000,208,12,13.67000000,100,1,13.78000000,2,1,13.93000000,102,2,13.94000000,110,2,14.00000000,100,1,14.20000000,902,4,14.21000000,100,1,14.26000000,700,1,14.27000000,700,1,ARL,43787977
629,2025-07-17T13:59:50.479576984Z,2025-07-17T13:59:50.479411482Z,160,2,1108,A,B,0,12.51000000,100,130,165502,96389821,13.28000000,11,2,13.26000000,2,1,13.25000000,11,1,13.20000000,30,2,13.12000000,4,2,12.99000000,100,1,12.88000000,2,1,12.73000000,100,1,12.67000000,100,1,12.51000000,100,1,13.40000000,208,12,13.67000000,100,1,13.78000000,2,1,13.93000000,102,2,13.94000000,110,2,14.00000000,100,1,14.20000000,902,4,14.21000000,100,1,14.26000000,700,1,14.27000000,700,1,ARL,115474337
630,2025-07-17T13:59:50.480863637Z,2025-07-17T13:59:50.480698233Z,160,2,1108,C,B,0,12.36000000,100,0,165404,96389845,13.28000000,11,2,13.26000000,2,1,13.25000000,11,1,13.20000000,30,2,13.12000000,4,2,12.99000000,100,1,12.88000000,2,1,12.73000000,100,1,12.67000000,100,1,12.51000000,100,1,13.40000000,208,12,13.67000000,100,1,13.78000000,2,1,13.93000000,102,2,13.94000000,110,2,14.00000000,100,1,14.20000000,902,4,14.21000000,100,1,14.26000000,700,1,14.27000000,700,1,ARL,43781537
631,2025-07-17T13:59:50.480863637Z,2025-07-17T13:59:50.480698233Z,160,2,1108,A,B,0,12.51000000,100,130,165404,96389845,13.28000000,11,2,13.26000000,2,1,13.25000000,11,1,13.20000000,30,2,13.12000000,4,2,12.99000000,100,1,12.88000000,2,1,12.73000000,100,1,12.67000000,100,1,12.51000000,200,2,13.40000000,208,12,13.67000000,100,1,13.78000000,2,1,13.93000000,102,2,13.94000000,110,2,14.00000000,100,1,14.20000000,902,4,14.21000000,100,1,14.26000000,700,1,14.27000000,700,1,ARL,115474357
632,2025-07-17T14:00:00.063037446Z,2025-07-17T14:00:00.062872132Z,160,2,1108,A,B,0,13.11000000,100,130,165314,96673952,13.28000000,11,2,13.26000000,2,1,13.25000000,11,1,13.20000000,30,2,13.12000000,4,2,13.11000000,100,1,12.99000000,100,1,12.88000000,2,1,12.73000000,100,1,12.67000000,100,1,13.40000000,208,12,13.67000000,100,1,13.78000000,2,1,13.93000000,102,2,13.94000000,110,2,14.00000000,100,1,14.20000000,902,4,14.21000000,100,1,14.26000000,700,1,14.27000000,700,1,ARL,115813253
633,2025-07-17T14:00:00.063056200Z,2025-07-17T14:00:00.062890891Z,160,2,1108,A,A,0,14.51000000,100,130,165309,96673954,13.28000000,11,2,13.26000000,2,1,13.25000000,11,1,13.20000000,30,2,13.12000000,4,2,13.11000000,100,1,12.99000000,100,1,12.88000000,2,1,12.73000000,100,1,12.67000000,100,1,13.40000000,208,12,13.67000000,100,1,13.78000000,2,1,13.93000000,102,2,13.94000000,110,2,14.00000000,100,1,14.20000000,902,4,14.21000000,100,1,14.26000000,700,1,14.27000000,700,1,ARL,115813261
634,2025-07-17T14:02:01.157985602Z,2025-07-17T14:02:01.157819863Z,160,2,1108,C,B,0,13.12000000,2,0,165739,101310413,13.28000000,11,2,13.26000000,2,1,13.25000000,11,1,13.20000000,30,2,13.12000000,4,2,13.11000000,100,1,12.99000000,100,1,12.88000000,2,1,12.73000000,100,1,12.67000000,100,1,13.40000000,208,12,13.67000000,100,1,13.78000000,2,1,13.93000000,102,2,13.94000000,110,2,14.00000000,100,1,14.20000000,902,4,14.21000000,100,1,14.26000000,700,1,14.27000000,700,1,ARL,111169049
635,2025-07-17T14:02:01.157985602Z,2025-07-17T14:02:01.157819863Z,160,2,1108,A,B,0,13.26000000,2,130,165739,101310413,13.28000000,11,2,13.26000000,4,2,13.25000000,11,1,13.20000000,30,2,13.12000000,4,2,13.11000000,100,1,12.99000000,100,1,12.88000000,2,1,12.73000000,100,1,12.67000000,100,1,13.40000000,208,12,13.67000000,100,1,13.78000000,2,1,13.93000000,102,2,13.94000000,110,2,14.00000000,100,1,14.20000000,902,4,14.21000000,100,1,14.26000000,700,1,14.27000000,700,1,ARL,121098337
636,2025-07-17T14:02:01.157986499Z,2025-07-17T14:02:01.157820985Z,160,2,1108,C,A,0,14.50000000,2,0,165514,101310414,13.28000000,11,2,13.26000000,4,2,13.25000000,11,1,13.20000000,30,2,13.12000000,4,2,13.11000000,100,1,12.99000000,100,1,12.88000000,2,1,12.73000000,100,1,12.67000000,100,1,13.40000000,208,12,13.67000000,100,1,13.78000000,2,1,13.93000000,102,2,13.94000000,110,2,14.00000000,100,1,14.20000000,902,4,14.21000000,100,1,14.26000000,700,1,14.27000000,700,1,ARL,111347121
637,2025-07-17T14:02:01.157986499Z,2025-07-17T14:02:01.157820985Z,160,2,1108,A,A,0,14.36000000,2,130,165514,101310414,13.28000000,11,2,13.26000000,4,2,13.25000000,11,1,13.20000000,30,2,13.12000000,4,2,13.11000000,100,1,12.99000000,100,1,12.88000000,2,1,12.73000000,100,1,12.67000000,100,1,13.40000000,208,12,13.67000000,100,1,13.78000000,2,1,13.93000000,102,2,13.94000000,110,2,14.00000000,100,1,14.20000000,902,4,14.21000000,100,1,14.26000000,700,1,14.27000000,700,1,ARL,121098341
638,2025-07-17T14:02:01.283528838Z,2025-07-17T14:02:01.283363185Z,160,2,1108,C,B,0,13.11000000,100,0,165653,101317376,13.28000000,11,2,13.26000000,4,2,13.25000000,11,1,13.20000000,30,2,13.12000000,4,2,13.11000000,100,1,12.99000000,100,1,12.88000000,2,1,12.73000000,100,1,12.67000000,100,1,13.40000000,208,12,13.67000000,100,1,13.78000000,2,1,13.93000000,102,2,13.94000000,110,2,14.00000000,100,1,14.20000000,902,4,14.21000000,100,1,14.26000000,700,1,14.27000000,700,1,ARL,115813253
639,2025-07-17T14:02:01.283528838Z,2025-07-17T14:02:01.283363185Z,160,2,1108,A,B,0,13.25000000,100,130,165653,101317376,13.28000000,11,2,13.26000000,4,2,13.25000000,111,2,13.20000000,30,2,13.12000000,4,2,13.11000000,100,1,12.99000000,100,1,12.88000000,2,1,12.73000000,100,1,12.67000000,100,1,13.40000000,208,12,13.67000000,100,1,13.78000000,2,1,13.93000000,102,2,13.94000000,110,2,14.00000000,100,1,14.20000000,902,4,14.21000000,100,1,14.26000000,700,1,14.27000000,700,1,ARL,121107957
640,2025-07-17T14:02:01.283544588Z,2025-07-17T14:02:01.283378637Z,160,2,1108,C,A,0,14.51000000,100,0,165951,101317377,13.28000000,11,2,13.26000000,4,2,13.25000000,111,2,13.20000000,30,2,13.12000000,4,2,13.11000000,100,1,12.99000000,100,1,12.88000000,2,1,12.73000000,100,1,12.67000000,100,1,13.40000000,208,12,13.67000000,100,1,13.78000000,2,1,13.93000000,102,2,13.94000000,110,2,14.00000000,100,1,14.20000000,902,4,14.21000000,100,1,14.26000000,700,1,14.27000000,700,1,ARL,115813261
641,2025-07-17T14:02:01.283544588Z,2025-07-17T14:02:01.283378637Z,160,2,1108,A,A,0,14.37000000,100,130,165951,101317377,13.28000000,11,2,13.26000000,4,2,13.25000000,111,2,13.20000000,30,2,13.12000000,4,2,13.11000000,100,1,12.99000000,100,1,12.88000000,2,1,12.73000000,100,1,12.67000000,100,1,13.40000000,208,12,13.67000000,100,1,13.78000000,2,1,13.93000000,102,2,13.94000000,110,2,14.00000000,100,1,14.20000000,902,4,14.21000000,100,1,14.26000000,700,1,14.27000000,700,1,ARL,121107961
642,2025-07-17T14:04:21.248906318Z,2025-07-17T14:04:21.248740930Z,160,2,1108,A,A,0,14.35000000,1,130,165388,106336852,13.28000000,11,2,13.26000000,4,2,13.25000000,111,2,13.20000000,30,2,13.12000000,4,2,13.11000000,100,1,12.99000000,100,1,12.88000000,2,1,12.73000000,100,1,12.67000000,100,1,13.40000000,208,12,13.67000000,100,1,13.78000000,2,1,13.93000000,102,2,13.94000000,110,2,14.00000000,100,1,14.20000000,902,4,14.21000000,100,1,14.26000000,700,1,14.27000000,700,1,ARL,126872197
643,2025-07-17T14:04:21.250325900Z,2025-07-17T14:04:21.250160548Z,160,2,1108,C,B,0,12.51000000,100,0,165352,106336976,13.28000000,11,2,13.26000000,4,2,13.25000000,111,2,13.20000000,30,2,13.12000000,4,2,13.11000000,100,1,12.99000000,100,1,12.88000000,2,1,12.73000000,100,1,12.67000000,100,1,13.40000000,208,12,13.67000000,100,1,13.78000000,2,1,13.93000000,102,2,13.94000000,110,2,14.00000000,100,1,14.20000000,902,4,14.21000000,100,1,14.26000000,700,1,14.27000000,700,1,ARL,115474357
644,2025-07-17T14:04:21.250325900Z,2025-07-17T14:04:21.250160548Z,160,2,1108,A,B,0,12.36000000,100,130,165352,106336976,13.28000000,11,2,13.26000000,4,2,13.25000000,111,2,13.20000000,30,2,13.12000000,4,2,13.11000000,100,1,12.99000000,100,1,12.88000000,2,1,12.73000000,100,1,12.67000000,100,1,13.40000000,208,12,13.67000000,100,1,13.78000000,2,1,13.93000000,102,2,13.94000000,110,2,14.00000000,100,1,14.20000000,902,4,14.21000000,100,1,14.26000000,700,1,14.27000000,700,1,ARL,126872345
645,2025-07-17T14:04:21.250797741Z,2025-07-17T14:04:21.250632048Z,160,2,1108,C,B,0,12.51000000,100,0,165693,106337002,13.28000000,11,2,13.26000000,4,2,13.25000000,111,2,13.20000000,30,2,13.12000000,4,2,13.11000000,100,1,12.99000000,100,1,12.88000000,2,1,12.73000000,100,1,12.67000000,100,1,13.40000000,208,12,13.67000000,100,1,13.78000000,2,1,13.93000000,102,2,13.94000000,110,2,14.00000000,100,1,14.20000000,902,4,14.21000000,100,1,14.26000000,700,1,14.27000000,700,1,ARL,115474337
646,2025-07-17T14:04:21.250797741Z,2025-07-17T14:04:21.250632048Z,160,2,1108,A,B,0,12.36000000,100,130,165693,106337002,13.28000000,11,2,13.26000000,4,2,13.25000000,111,2,13.20000000,30,2,13.12000000,4,2,13.11000000,100,1,12.99000000,100,1,12.88000000,2,1,12.73000000,100,1,12.67000000,100,1,13.40000000,208,12,13.67000000,100,1,13.78000000,2,1,13.93000000,102,2,13.94000000,110,2,14.00000000,100,1,14.20000000,902,4,14.21000000,100,1,14.26000000,700,1,14.27000000,700,1,ARL,126872361
647,2025-07-17T14:04:21.350207939Z,2025-07-17T14:04:21.350041949Z,160,2,1108,C,A,0,14.35000000,1,128,165990,106339204,13.28000000,11,2,13.26000000,4,2,13.25000000,111,2,13.20000000,30,2,13.12000000,4,2,13.11000000,100,1,12.99000000,100,1,12.88000000,2,1,12.73000000,100,1,12.67000000,100,1,13.40000000,208,12,13.67000000,100,1,13.78000000,2,1,13.93000000,102,2,13.94000000,110,2,14.00000000,100,1,14.20000000,902,4,14.21000000,100,1,14.26000000,700,1,14.27000000,700,1,ARL,126872197
648,2025-07-17T14:04:54.699926747Z,2025-07-17T14:04:54.699761263Z,160,2,1108,C,A,0,15.46000000,100,0,165484,107313441,13.28000000,11,2,13.26000000,4,2,13.25000000,111,2,13.20000000,30,2,13.12000000,4,2,13.11000000,100,1,12.99000000,100,1,12.88000000,2,1,12.73000000,100,1,12.67000000,100,1,13.40000000,208,12,13.67000000,100,1,13.78000000,2,1,13.93000000,102,2,13.94000000,110,2,14.00000000,100,1,14.20000000,902,4,14.21000000,100,1,14.26000000,700,1,14.27000000,700,1,ARL,92510753
649,2025-07-17T14:04:54.699926747Z,2025-07-17T14:04:54.699761263Z,160,2,1108,A,A,0,15.34000000,100,130,165484,107313441,13.28000000,11,2,13.26000000,4,2,13.25000000,111,2,13.20000000,30,2,13.12000000,4,2,13.11000000,100,1,12.99000000,100,1,12.88000000,2,1,12.73000000,100,1,12.67000000,100,1,13.40000000,208,12,13.67000000,100,1,13.78000000,2,1,13.93000000,102,2,13.94000000,110,2,14.00000000,100,1,14.20000000,902,4,14.21000000,100,1,14.26000000,700,1,14.27000000,700,1,ARL,127999501
650,2025-07-17T14:05:10.258855609Z,2025-07-17T14:05:10.258689253Z,160,2,1108,A,A,0,14.08000000,1,130,166356,107833096,13.28000000,11,2,13.26000000,4,2,13.25000000,111,2,13.20000000,30,2,13.12000000,4,2,13.11000000,100,1,12.99000000,100,1,12.88000000,2,1,12.73000000,100,1,12.67000000,100,1,13.40000000,208,12,13.67000000,100,1,13.78000000,2,1,13.93000000,102,2,13.94000000,110,2,14.00000000,100,1,14.08000000,1,1,14.20000000,902,4,14.21000000,100,1,14.26000000,700,1,ARL,128570149
651,2025-07-17T14:05:10.259513876Z,2025-07-17T14:05:10.259348471Z,160,2,1108,C,A,0,15.26000000,100,0,165405,107833168,13.28000000,11,2,13.26000000,4,2,13.25000000,111,2,13.20000000,30,2,13.12000000,4,2,13.11000000,100,1,12.99000000,100,1,12.88000000,2,1,12.73000000,100,1,12.67000000,100,1,13.40000000,208,12,13.67000000,100,1,13.78000000,2,1,13.93000000,102,2,13.94000000,110,2,14.00000000,100,1,14.08000000,1,1,14.20000000,902,4,14.21000000,100,1,14.26000000,700,1,ARL,108217173
652,2025-07-17T14:05:10.259513876Z,2025-07-17T14:05:10.259348471Z,160,2,1108,A,A,0,14.98000000,100,130,165405,107833168,13.28000000,11,2,13.26000000,4,2,13.25000000,111,2,13.20000000,30,2,13.12000000,4,2,13.11000000,100,1,12.99000000,100,1,12.88000000,2,1,12.73000000,100,1,12.67000000,100,1,13.40000000,208,12,13.67000000,100,1,13.78000000,2,1,13.93000000,102,2,13.94000000,110,2,14.00000000,100,1,14.08000000,1,1,14.20000000,902,4,14.21000000,100,1,14.26000000,700,1,ARL,128570229
653,2025-07-17T14:05:10.259895236Z,2025-07-17T14:05:10.259729446Z,160,2,1108,C,A,0,15.26000000,100,0,165790,107833188,13.28000000,11,2,13.26000000,4,2,13.25000000,111,2,13.20000000,30,2,13.12000000,4,2,13.11000000,100,1,12.99000000,100,1,12.88000000,2,1,12.73000000,100,1,12.67000000,100,1,13.40000000,208,12,13.67000000,100,1,13.78000000,2,1,13.93000000,102,2,13.94000000,110,2,14.00000000,100,1,14.08000000,1,1,14.20000000,902,4,14.21000000,100,1,14.26000000,700,1,ARL,108217045
654,2025-07-17T14:05:10.259895236Z,2025-07-17T14:05:10.259729446Z,160,2,1108,A,A,0,14.98000000,100,130,165790,107833188,13.28000000,11,2,13.26000000,4,2,13.25000000,111,2,13.20000000,30,2,13.12000000,4,2,13.11000000,100,1,12.99000000,100,1,12.88000000,2,1,12.73000000,100,1,12.67000000,100,1,13.40000000,208,12,13.67000000,100,1,13.78000000,2,1,13.93000000,102,2,13.94000000,110,2,14.00000000,100,1,14.08000000,1,1,14.20000000,902,4,14.21000000,100,1,14.26000000,700,1,ARL,128570237
655,2025-07-17T14:05:10.262461863Z,2025-07-17T14:05:10.262295631Z,160,2,1108,C,A,0,14.37000000,100,0,166232,107833310,13.28000000,11,2,13.26000000,4,2,13.25000000,111,2,13.20000000,30,2,13.12000000,4,2,13.11000000,100,1,12.99000000,100,1,12.88000000,2,1,12.73000000,100,1,12.67000000,100,1,13.40000000,208,12,13.67000000,100,1,13.78000000,2,1,13.93000000,102,2,13.94000000,110,2,14.00000000,100,1,14.08000000,1,1,14.20000000,902,4,14.21000000,100,1,14.26000000,700,1,ARL,121107961
656,2025-07-17T14:05:10.262461863Z,2025-07-17T14:05:10.262295631Z,160,2,1108,A,A,0,14.09000000,100,130,166232,107833310,13.28000000,11,2,13.26000000,4,2,13.25000000,111,2,13.20000000,30,2,13.12000000,4,2,13.11000000,100,1,12.99000000,100,1,12.88000000,2,1,12.73000000,100,1,12.67000000,100,1,13.40000000,208,12,13.67000000,100,1,13.78000000,2,1,13.93000000,102,2,13.94000000,110,2,14.00000000,100,1,14.08000000,1,1,14.09000000,100,1,14.20000000,902,4,14.21000000,100,1,ARL,128570317
657,2025-07-17T14:05:10.262866527Z,2025-07-17T14:05:10.262701351Z,160,2,1108,C,A,0,14.08000000,1,130,165176,107833359,13.28000000,11,2,13.26000000,4,2,13.25000000,111,2,13.20000000,30,2,13.12000000,4,2,13.11000000,100,1,12.99000000,100,1,12.88000000,2,1,12.73000000,100,1,12.67000000,100,1,13.40000000,208,12,13.67000000,100,1,13.78000000,2,1,13.93000000,102,2,13.94000000,110,2,14.00000000,100,1,14.08000000,1,1,14.09000000,100,1,14.20000000,902,4,14.21000000,100,1,ARL,128570149
658,2025-07-17T14:05:10.263188035Z,2025-07-17T14:05:10.263022539Z,160,2,1108,C,A,0,15.34000000,100,0,165496,107833371,13.28000000,11,2,13.26000000,4,2,13.25000000,111,2,13.20000000,30,2,13.12000000,4,2,13.11000000,100,1,12.99000000,100,1,12.88000000,2,1,12.73000000,100,1,12.67000000,100,1,13.40000000,208,12,13.67000000,100,1,13.78000000,2,1,13.93000000,102,2,13.94000000,110,2,14.00000000,100,1,14.08000000,1,1,14.09000000,100,1,14.20000000,902,4,14.21000000,100,1,ARL,127999501
659,2025-07-17T14:05:10.263188035Z,2025-07-17T14:05:10.263022539Z,160,2,1108,A,A,0,15.18000000,100,130,165496,107833371,13.28000000,11,2,13.26000000,4,2,13.25000000,111,2,13.20000000,30,2,13.12000000,4,2,13.11000000,100,1,12.99000000,100,1,12.88000000,2,1,12.73000000,100,1,12.67000000,100,1,13.40000000,208,12,13.67000000,100,1,13.78000000,2,1,13.93000000,102,2,13.94000000,110,2,14.00000000,100,1,14.08000000,1,1,14.09000000,100,1,14.20000000,902,4,14.21000000,100,1,ARL,128570417
660,2025-07-17T14:05:10.264495078Z,2025-07-17T14:05:10.264329670Z,160,2,1108,C,A,0,15.36000000,100,0,165408,107833404,13.28000000,11,2,13.26000000,4,2,13.25000000,111,2,13.20000000,30,2,13.12000000,4,2,13.11000000,100,1,12.99000000,100,1,12.88000000,2,1,12.73000000,100,1,12.67000000,100,1,13.40000000,208,12,13.67000000,100,1,13.78000000,2,1,13.93000000,102,2,13.94000000,110,2,14.00000000,100,1,14.08000000,1,1,14.09000000,100,1,14.20000000,902,4,14.21000000,100,1,ARL,92510761
661,2025-07-17T14:05:10.264495078Z,2025-07-17T14:05:10.264329670Z,160,2,1108,A,A,0,15.08000000,100,130,165408,107833404,13.28000000,11,2,13.26000000,4,2,13.25000000,111,2,13.20000000,30,2,13.12000000,4,2,13.11000000,100,1,12.99000000,100,1,12.88000000,2,1,12.73000000,100,1,12.67000000,100,1,13.40000000,208,12,13.67000000,100,1,13.78000000,2,1,13.93000000,102,2,13.94000000,110,2,14.00000000,100,1,14.08000000,1,1,14.09000000,100,1,14.20000000,902,4,14.21000000,100,1,ARL,128570449
662,2025-07-17T14:05:10.264590318Z,2025-07-17T14:05:10.264425026Z,160,2,1108,C,A,0,15.09000000,100,130,165292,107833406,13.28000000,11,2,13.26000000,4,2,13.25000000,111,2,13.20000000,30,2,13.12000000,4,2,13.11000000,100,1,12.99000000,100,1,12.88000000,2,1,12.73000000,100,1,12.67000000,100,1,13.40000000,208,12,13.67000000,100,1,13.78000000,2,1,13.93000000,102,2,13.94000000,110,2,14.00000000,100,1,14.08000000,1,1,14.09000000,100,1,14.20000000,902,4,14.21000000,100,1,ARL,84650629
663,2025-07-17T14:05:10.264715723Z,2025-07-17T14:05:10.264550510Z,160,2,1108,A,A,0,14.89000000,100,130,165213,107833407,13.28000000,11,2,13.26000000,4,2,13.25000000,111,2,13.20000000,30,2,13.12000000,4,2,13.11000000,100,1,12.99000000,100,1,12.88000000,2,1,12.73000000,100,1,12.67000000,100,1,13.40000000,208,12,13.67000000,100,1,13.78000000,2,1,13.93000000,102,2,13.94000000,110,2,14.00000000,100,1,14.08000000,1,1,14.09000000,100,1,14.20000000,902,4,14.21000000,100,1,ARL,128570453
664,2025-07-17T14:05:10.269943051Z,2025-07-17T14:05:10.269777131Z,160,2,1108,C,A,0,14.59000000,100,128,165920,107833716,13.28000000,11,2,13.26000000,4,2,13.25000000,111,2,13.20000000,30,2,13.12000000,4,2,13.11000000,100,1,12.99000000,100,1,12.88000000,2,1,12.73000000,100,1,12.67000000,100,1,13.40000000,208,12,13.67000000,100,1,13.78000000,2,1,13.93000000,102,2,13.94000000,110,2,14.00000000,100,1,14.08000000,1,1,14.09000000,100,1,14.20000000,902,4,14.21000000,100,1,ARL,84629329
665,2025-07-17T14:05:10.269997960Z,2025-07-17T14:05:10.269832842Z,160,2,1108,A,A,0,14.37000000,100,130,165118,107833720,13.28000000,11,2,13.26000000,4,2,13.25000000,111,2,13.20000000,30,2,13.12000000,4,2,13.11000000,100,1,12.99000000,100,1,12.88000000,2,1,12.73000000,100,1,12.67000000,100,1,13.40000000,208,12,13.67000000,100,1,13.78000000,2,1,13.93000000,102,2,13.94000000,110,2,14.00000000,100,1,14.08000000,1,1,14.09000000,100,1,14.20000000,902,4,14.21000000,100,1,ARL,128570621
666,2025-07-17T14:05:10.271865423Z,2025-07-17T14:05:10.271699633Z,160,2,1108,C,A,0,18.23000000,100,0,165790,107833881,13.28000000,11,2,13.26000000,4,2,13.25000000,111,2,13.20000000,30,2,13.12000000,4,2,13.11000000,100,1,12.99000000,100,1,12.88000000,2,1,12.73000000,100,1,12.67000000,100,1,13.40000000,208,12,13.67000000,100,1,13.78000000,2,1,13.93000000,102,2,13.94000000,110,2,14.00000000,100,1,14.08000000,1,1,14.09000000,100,1,14.20000000,902,4,14.21000000,100,1,ARL,92510841
667,2025-07-17T14:05:10.271865423Z,2025-07-17T14:05:10.271699633Z,160,2,1108,A,A,0,17.90000000,100,130,165790,107833881,13.28000000,11,2,13.26000000,4,2,13.25000000,111,2,13.20000000,30,2,13.12000000,4,2,13.11000000,100,1,12.99000000,100,1,12.88000000,2,1,12.73000000,100,1,12.67000000,100,1,13.40000000,208,12,13.67000000,100,1,13.78000000,2,1,13.93000000,102,2,13.94000000,110,2,14.00000000,100,1,14.08000000,1,1,14.09000000,100,1,14.20000000,902,4,14.21000000,100,1,ARL,128570685
668,2025-07-17T14:05:10.276320920Z,2025-07-17T14:05:10.276155439Z,160,2,1108,C,A,0,16.51000000,100,0,165481,107834635,13.28000000,11,2,13.26000000,4,2,13.25000000,111,2,13.20000000,30,2,13.12000000,4,2,13.11000000,100,1,12.99000000,100,1,12.88000000,2,1,12.73000000,100,1,12.67000000,100,1,13.40000000,208,12,13.67000000,100,1,13.78000000,2,1,13.93000000,102,2,13.94000000,110,2,14.00000000,100,1,14.08000000,1,1,14.09000000,100,1,14.20000000,902,4,14.21000000,100,1,ARL,92510813
669,2025-07-17T14:05:10.276320920Z,2025-07-17T14:05:10.276155439Z,160,2,1108,A,A,0,16.21000000,100,130,165481,107834635,13.28000000,11,2,13.26000000,4,2,13.25000000,111,2,13.20000000,30,2,13.12000000,4,2,13.11000000,100,1,12.99000000,100,1,12.88000000,2,1,12.73000000,100,1,12.67000000,100,1,13.40000000,208,12,13.67000000,100,1,13.78000000,2,1,13.93000000,102,2,13.94000000,110,2,14.00000000,100,1,14.08000000,1,1,14.09000000,100,1,14.20000000,902,4,14.21000000,100,1,ARL,128570977
670,2025-07-17T14:05:10.342982797Z,2025-07-17T14:05:10.342817229Z,160,2,1108,C,A,0,15.31000000,100,0,165568,107837761,13.28000000,11,2,13.26000000,4,2,13.25000000,111,2,13.20000000,30,2,13.12000000,4,2,13.11000000,100,1,12.99000000,100,1,12.88000000,2,1,12.73000000,100,1,12.67000000,100,1,13.40000000,208,12,13.67000000,100,1,13.78000000,2,1,13.93000000,102,2,13.94000000,110,2,14.00000000,100,1,14.08000000,1,1,14.09000000,100,1,14.20000000,902,4,14.21000000,100,1,ARL,84630849
671,2025-07-17T14:05:10.342982797Z,2025-07-17T14:05:10.342817229Z,160,2,1108,A,A,0,15.08000000,100,130,165568,107837761,13.28000000,11,2,13.26000000,4,2,13.25000000,111,2,13.20000000,30,2,13.12000000,4,2,13.11000000,100,1,12.99000000,100,1,12.88000000,2,1,12.73000000,100,1,12.67000000,100,1,13.40000000,208,12,13.67000000,100,1,13.78000000,2,1,13.93000000,102,2,13.94000000,110,2,14.00000000,100,1,14.08000000,1,1,14.09000000,100,1,14.20000000,902,4,14.21000000,100,1,ARL,128573957
672,2025-07-17T14:05:31.418741362Z,2025-07-17T14:05:31.418575692Z,160,2,1108,C,A,0,14.36000000,2,0,165670,108664911,13.28000000,11,2,13.26000000,4,2,13.25000000,111,2,13.20000000,30,2,13.12000000,4,2,13.11000000,100,1,12.99000000,100,1,12.88000000,2,1,12.73000000,100,1,12.67000000,100,1,13.40000000,208,12,13.67000000,100,1,13.78000000,2,1,13.93000000,102,2,13.94000000,110,2,14.00000000,100,1,14.08000000,1,1,14.09000000,100,1,14.20000000,902,4,14.21000000,100,1,ARL,121098341
673,2025-07-17T14:05:31.418741362Z,2025-07-17T14:05:31.418575692Z,160,2,1108,A,A,0,14.26000000,2,130,165670,108664911,13.28000000,11,2,13.26000000,4,2,13.25000000,111,2,13.20000000,30,2,13.12000000,4,2,13.11000000,100,1,12.99000000,100,1,12.88000000,2,1,12.73000000,100,1,12.67000000,100,1,13.40000000,208,12,13.67000000,100,1,13.78000000,2,1,13.93000000,102,2,13.94000000,110,2,14.00000000,100,1,14.08000000,1,1,14.09000000,100,1,14.20000000,902,4,14.21000000,100,1,ARL,129518753
674,2025-07-17T14:06:01.386006059Z,2025-07-17T14:06:01.385840471Z,160,2,1108,C,B,0,13.26000000,2,0,165588,109685525,13.28000000,11,2,13.26000000,4,2,13.25000000,111,2,13.20000000,30,2,13.12000000,4,2,13.11000000,100,1,12.99000000,100,1,12.88000000,2,1,12.73000000,100,1,12.67000000,100,1,13.40000000,208,12,13.67000000,100,1,13.78000000,2,1,13.93000000,102,2,13.94000000,110,2,14.00000000,100,1,14.08000000,1,1,14.09000000,100,1,14.20000000,902,4,14.21000000,100,1,ARL,121098337
675,2025-07-17T14:06:01.386006059Z,2025-07-17T14:06:01.385840471Z,160,2,1108,A,B,0,13.15000000,2,130,165588,109685525,13.28000000,11,2,13.26000000,4,2,13.25000000,111,2,13.20000000,30,2,13.15000000,2,1,13.12000000,4,2,13.11000000,100,1,12.99000000,100,1,12.88000000,2,1,12.73000000,100,1,13.40000000,208,12,13.67000000,100,1,13.78000000,2,1,13.93000000,102,2,13.94000000,110,2,14.00000000,100,1,14.08000000,1,1,14.09000000,100,1,14.20000000,902,4,14.21000000,100,1,ARL,130693973
676,2025-07-17T14:13:11.346377890Z,2025-07-17T14:13:11.346212166Z,160,2,1108,C,A,0,15.18000000,100,0,165724,123937587,13.28000000,11,2,13.26000000,4,2,13.25000000,111,2,13.20000000,30,2,13.15000000,2,1,13.12000000,4,2,13.11000000,100,1,12.99000000,100,1,12.88000000,2,1,12.73000000,100,1,13.40000000,208,12,13.67000000,100,1,13.78000000,2,1,13.93000000,102,2,13.94000000,110,2,14.00000000,100,1,14.08000000,1,1,14.09000000,100,1,14.20000000,902,4,14.21000000,100,1,ARL,128570417
677,2025-07-17T14:13:11.346377890Z,2025-07-17T14:13:11.346212166Z,160,2,1108,A,A,0,15.09000000,100,130,165724,123937587,13.28000000,11,2,13.26000000,4,2,13.25000000,111,2,13.20000000,30,2,13.15000000,2,1,13.12000000,4,2,13.11000000,100,1,12.99000000,100,1,12.88000000,2,1,12.73000000,100,1,13.40000000,208,12,13.67000000,100,1,13.78000000,2,1,13.93000000,102,2,13.94000000,110,2,14.00000000,100,1,14.08000000,1,1,14.09000000,100,1,14.20000000,902,4,14.21000000,100,1,ARL,146955361
678,2025-07-17T14:13:11.358916626Z,2025-07-17T14:13:11.358751092Z,160,2,1108,C,A,0,14.37000000,100,130,165534,123938202,13.28000000,11,2,13.26000000,4,2,13.25000000,111,2,13.20000000,30,2,13.15000000,2,1,13.12000000,4,2,13.11000000,100,1,12.99000000,100,1,12.88000000,2,1,12.73000000,100,1,13.40000000,208,12,13.67000000,100,1,13.78000000,2,1,13.93000000,102,2,13.94000000,110,2,14.00000000,100,1,14.08000000,1,1,14.09000000,100,1,14.20000000,902,4,14.21000000,100,1,ARL,128570621
679,2025-07-17T14:13:11.358968656Z,2025-07-17T14:13:11.358802966Z,160,2,1108,A,A,0,14.28000000,100,130,165690,123938203,13.28000000,11,2,13.26000000,4,2,13.25000000,111,2,13.20000000,30,2,13.15000000,2,1,13.12000000,4,2,13.11000000,100,1,12.99000000,100,1,12.88000000,2,1,12.73000000,100,1,13.40000000,208,12,13.67000000,100,1,13.78000000,2,1,13.93000000,102,2,13.94000000,110,2,14.00000000,100,1,14.08000000,1,1,14.09000000,100,1,14.20000000,902,4,14.21000000,100,1,ARL,146956357
680,2025-07-17T14:13:11.393088913Z,2025-07-17T14:13:11.392923396Z,160,2,1108,C,A,0,15.73000000,100,0,165517,123939815,13.28000000,11,2,13.26000000,4,2,13.25000000,111,2,13.20000000,30,2,13.15000000,2,1,13.12000000,4,2,13.11000000,100,1,12.99000000,100,1,12.88000000,2,1,12.73000000,100,1,13.40000000,208,12,13.67000000,100,1,13.78000000,2,1,13.93000000,102,2,13.94000000,110,2,14.00000000,100,1,14.08000000,1,1,14.09000000,100,1,14.20000000,902,4,14.21000000,100,1,ARL,84629953
681,2025-07-17T14:13:11.393088913Z,2025-07-17T14:13:11.392923396Z,160,2,1108,A,A,0,15.40000000,100,130,165517,123939815,13.28000000,11,2,13.26000000,4,2,13.25000000,111,2,13.20000000,30,2,13.15000000,2,1,13.12000000,4,2,13.11000000,100,1,12.99000000,100,1,12.88000000,2,1,12.73000000,100,1,13.40000000,208,12,13.67000000,100,1,13.78000000,2,1,13.93000000,102,2,13.94000000,110,2,14.00000000,100,1,14.08000000,1,1,14.09000000,100,1,14.20000000,902,4,14.21000000,100,1,ARL,146959177
682,2025-07-17T14:13:11.423482323Z,2025-07-17T14:13:11.423316840Z,160,2,1108,A,A,0,14.56000000,100,130,165483,123940437,13.28000000,11,2,13.26000000,4,2,13.25000000,111,2,13.20000000,30,2,13.15000000,2,1,13.12000000,4,2,13.11000000,100,1,12.99000000,100,1,12.88000000,2,1,12.73000000,100,1,13.40000000,208,12,13.67000000,100,1,13.78000000,2,1,13.93000000,102,2,13.94000000,110,2,14.00000000,100,1,14.08000000,1,1,14.09000000,100,1,14.20000000,902,4,14.21000000,100,1,ARL,146960005
683,2025-07-17T14:13:11.423483431Z,2025-07-17T14:13:11.423317922Z,160,2,1108,C,A,0,14.87000000,100,130,165509,123940438,13.28000000,11,2,13.26000000,4,2,13.25000000,111,2,13.20000000,30,2,13.15000000,2,1,13.12000000,4,2,13.11000000,100,1,12.99000000,100,1,12.88000000,2,1,12.73000000,100,1,13.40000000,208,12,13.67000000,100,1,13.78000000,2,1,13.93000000,102,2,13.94000000,110,2,14.00000000,100,1,14.08000000,1,1,14.09000000,100,1,14.20000000,902,4,14.21000000,100,1,ARL,84708037
684,2025-07-17T14:13:11.555808541Z,2025-07-17T14:13:11.555642984Z,160,2,1108,A,A,0,14.84000000,100,130,165557,123942727,13.28000000,11,2,13.26000000,4,2,13.25000000,111,2,13.20000000,30,2,13.15000000,2,1,13.12000000,4,2,13.11000000,100,1,12.99000000,100,1,12.88000000,2,1,12.73000000,100,1,13.40000000,208,12,13.67000000,100,1,13.78000000,2,1,13.93000000,102,2,13.94000000,110,2,14.00000000,100,1,14.08000000,1,1,14.09000000,100,1,14.20000000,902,4,14.21000000,100,1,ARL,146962993
685,2025-07-17T14:13:11.555828856Z,2025-07-17T14:13:11.555663413Z,160,2,1108,C,A,0,15.16000000,100,130,165443,123942728,13.28000000,11,2,13.26000000,4,2,13.25000000,111,2,13.20000000,30,2,13.15000000,2,1,13.12000000,4,2,13.11000000,100,1,12.99000000,100,1,12.88000000,2,1,12.73000000,100,1,13.40000000,208,12,13.67000000,100,1,13.78000000,2,1,13.93000000,102,2,13.94000000,110,2,14.00000000,100,1,14.08000000,1,1,14.09000000,100,1,14.20000000,902,4,14.21000000,100,1,ARL,84668677
686,2025-07-17T14:13:19.230983072Z,2025-07-17T14:13:19.230817808Z,160,2,1108,A,A,0,14.91000000,700,130,165264,124169794,13.28000000,11,2,13.26000000,4,2,13.25000000,111,2,13.20000000,30,2,13.15000000,2,1,13.12000000,4,2,13.11000000,100,1,12.99000000,100,1,12.88000000,2,1,12.73000000,100,1,13.40000000,208,12,13.67000000,100,1,13.78000000,2,1,13.93000000,102,2,13.94000000,110,2,14.00000000,100,1,14.08000000,1,1,14.09000000,100,1,14.20000000,902,4,14.21000000,100,1,ARL,147217629
687,2025-07-17T14:13:19.231778755Z,2025-07-17T14:13:19.231613044Z,160,2,1108,C,A,0,15.14000000,700,130,165711,124169802,13.28000000,11,2,13.26000000,4,2,13.25000000,111,2,13.20000000,30,2,13.15000000,2,1,13.12000000,4,2,13.11000000,100,1,12.99000000,100,1,12.88000000,2,1,12.73000000,100,1,13.40000000,208,12,13.67000000,100,1,13.78000000,2,1,13.93000000,102,2,13.94000000,110,2,14.00000000,100,1,14.08000000,1,1,14.09000000,100,1,14.20000000,902,4,14.21000000,100,1,ARL,84628829
688,2025-07-17T14:22:28.338174848Z,2025-07-17T14:22:28.338009329Z,160,2,1108,A,A,0,14.00000000,1,130,165519,142657338,13.28000000,11,2,13.26000000,4,2,13.25000000,111,2,13.20000000,30,2,13.15000000,2,1,13.12000000,4,2,13.11000000,100,1,12.99000000,100,1,12.88000000,2,1,12.73000000,100,1,13.40000000,208,12,13.67000000,100,1,13.78000000,2,1,13.93000000,102,2,13.94000000,110,2,14.00000000,101,2,14.08000000,1,1,14.09000000,100,1,14.20000000,902,4,14.21000000,100,1,ARL,168073025
689,2025-07-17T14:22:29.994011311Z,2025-07-17T14:22:29.993845812Z,160,2,1108,C,A,0,14.09000000,100,0,165499,142715813,13.28000000,11,2,13.26000000,4,2,13.25000000,111,2,13.20000000,30,2,13.15000000,2,1,13.12000000,4,2,13.11000000,100,1,12.99000000,100,1,12.88000000,2,1,12.73000000,100,1,13.40000000,208,12,13.67000000,100,1,13.78000000,2,1,13.93000000,102,2,13.94000000,110,2,14.00000000,101,2,14.08000000,1,1,14.09000000,100,1,14.20000000,902,4,14.21000000,100,1,ARL,128570317
690,2025-07-17T14:22:29.994011311Z,2025-07-17T14:22:29.993845812Z,160,2,1108,A,A,0,14.01000000,100,130,165499,142715813,13.28000000,11,2,13.26000000,4,2,13.25000000,111,2,13.20000000,30,2,13.15000000,2,1,13.12000000,4,2,13.11000000,100,1,12.99000000,100,1,12.88000000,2,1,12.73000000,100,1,13.40000000,208,12,13.67000000,100,1,13.78000000,2,1,13.93000000,102,2,13.94000000,110,2,14.00000000,101,2,14.01000000,100,1,14.08000000,1,1,14.09000000,100,1,14.20000000,902,4,ARL,168141389
691,2025-07-17T14:32:58.233129156Z,2025-07-17T14:32:58.232963791Z,160,2,1108,C,B,0,13.25000000,100,130,165365,162140358,13.28000000,11,2,13.26000000,4,2,13.25000000,111,2,13.20000000,30,2,13.15000000,2,1,13.12000000,4,2,13.11000000,100,1,12.99000000,100,1,12.88000000,2,1,12.73000000,100,1,13.40000000,208,12,13.67000000,100,1,13.78000000,2,1,13.93000000,102,2,13.94000000,110,2,14.00000000,101,2,14.01000000,100,1,14.08000000,1,1,14.09000000,100,1,14.20000000,902,4,ARL,121107957
692,2025-07-17T14:32:58.714015555Z,2025-07-17T14:32:58.713850212Z,160,2,1108,A,B,0,13.14000000,100,130,165343,162149922,13.28000000,11,2,13.26000000,4,2,13.25000000,111,2,13.20000000,30,2,13.15000000,2,1,13.14000000,100,1,13.12000000,4,2,13.11000000,100,1,12.99000000,100,1,12.88000000,2,1,13.40000000,208,12,13.67000000,100,1,13.78000000,2,1,13.93000000,102,2,13.94000000,110,2,14.00000000,101,2,14.01000000,100,1,14.08000000,1,1,14.09000000,100,1,14.20000000,902,4,ARL,190326921
693,2025-07-17T14:34:48.346344959Z,2025-07-17T14:34:48.346179643Z,160,2,1108,C,A,0,14.00000000,1,130,165316,164925706,13.28000000,11,2,13.26000000,4,2,13.25000000,111,2,13.20000000,30,2,13.15000000,2,1,13.14000000,100,1,13.12000000,4,2,13.11000000,100,1,12.99000000,100,1,12.88000000,2,1,13.40000000,208,12,13.67000000,100,1,13.78000000,2,1,13.93000000,102,2,13.94000000,110,2,14.00000000,101,2,14.01000000,100,1,14.08000000,1,1,14.09000000,100,1,14.20000000,902,4,ARL,168073025
694,2025-07-17T14:47:30.548081358Z,2025-07-17T14:47:30.547915870Z,160,2,1108,A,B,0,13.38000000,33,130,165488,183466992,13.38000000,33,1,13.28000000,11,2,13.26000000,4,2,13.25000000,111,2,13.20000000,30,2,13.15000000,2,1,13.14000000,100,1,13.12000000,4,2,13.11000000,100,1,12.99000000,100,1,13.40000000,208,12,13.67000000,100,1,13.78000000,2,1,13.93000000,102,2,13.94000000,110,2,14.00000000,101,2,14.01000000,100,1,14.08000000,1,1,14.09000000,100,1,14.20000000,902,4,ARL,215999733
695,2025-07-17T14:47:30.548346701Z,2025-07-17T14:47:30.548180936Z,160,2,1108,C,B,0,13.14000000,100,0,165765,183466994,13.38000000,33,1,13.28000000,11,2,13.26000000,4,2,13.25000000,111,2,13.20000000,30,2,13.15000000,2,1,13.14000000,100,1,13.12000000,4,2,13.11000000,100,1,12.99000000,100,1,13.40000000,208,12,13.67000000,100,1,13.78000000,2,1,13.93000000,102,2,13.94000000,110,2,14.00000000,101,2,14.01000000,100,1,14.08000000,1,1,14.09000000,100,1,14.20000000,902,4,ARL,190326921
696,2025-07-17T14:47:30.548346701Z,2025-07-17T14:47:30.548180936Z,160,2,1108,A,B,0,13.37000000,100,130,165765,183466994,13.38000000,33,1,13.37000000,100,1,13.28000000,11,2,13.26000000,4,2,13.25000000,111,2,13.20000000,30,2,13.15000000,2,1,13.14000000,100,1,13.12000000,4,2,13.11000000,100,1,13.40000000,208,12,13.67000000,100,1,13.78000000,2,1,13.93000000,102,2,13.94000000,110,2,14.00000000,101,2,14.01000000,100,1,14.08000000,1,1,14.09000000,100,1,14.20000000,902,4,ARL,215999737
697,2025-07-17T14:47:30.548831608Z,2025-07-17T14:47:30.548666035Z,160,2,1108,C,B,0,12.36000000,100,0,165573,183467001,13.38000000,33,1,13.37000000,100,1,13.28000000,11,2,13.26000000,4,2,13.25000000,111,2,13.20000000,30,2,13.15000000,2,1,13.14000000,100,1,13.12000000,4,2,13.11000000,100,1,13.40000000,208,12,13.67000000,100,1,13.78000000,2,1,13.93000000,102,2,13.94000000,110,2,14.00000000,101,2,14.01000000,100,1,14.08000000,1,1,14.09000000,100,1,14.20000000,902,4,ARL,126872345
698,2025-07-17T14:47:30.548831608Z,2025-07-17T14:47:30.548666035Z,160,2,1108,A,B,0,12.48000000,100,130,165573,183467001,13.38000000,33,1,13.37000000,100,1,13.28000000,11,2,13.26000000,4,2,13.25000000,111,2,13.20000000,30,2,13.15000000,2,1,13.14000000,100,1,13.12000000,4,2,13.11000000,100,1,13.40000000,208,12,13.67000000,100,1,13.78000000,2,1,13.93000000,102,2,13.94000000,110,2,14.00000000,101,2,14.01000000,100,1,14.08000000,1,1,14.09000000,100,1,14.20000000,902,4,ARL,215999741
699,2025-07-17T14:47:30.549090785Z,2025-07-17T14:47:30.548925394Z,160,2,1108,C,B,0,12.23000000,100,0,165391,183467002,13.38000000,33,1,13.37000000,100,1,13.28000000,11,2,13.26000000,4,2,13.25000000,111,2,13.20000000,30,2,13.15000000,2,1,13.14000000,100,1,13.12000000,4,2,13.11000000,100,1,13.40000000,208,12,13.67000000,100,1,13.78000000,2,1,13.93000000,102,2,13.94000000,110,2,14.00000000,101,2,14.01000000,100,1,14.08000000,1,1,14.09000000,100,1,14.20000000,902,4,ARL,43317473
700,2025-07-17T14:47:30.549090785Z,2025-07-17T14:47:30.548925394Z,160,2,1108,A,B,0,12.33000000,100,130,165391,183467002,13.38000000,33,1,13.37000000,100,1,13.28000000,11,2,13.26000000,4,2,13.25000000,111,2,13.20000000,30,2,13.15000000,2,1,13.14000000,100,1,13.12000000,4,2,13.11000000,100,1,13.40000000,208,12,13.67000000,100,1,13.78000000,2,1,13.93000000,102,2,13.94000000,110,2,14.00000000,101,2,14.01000000,100,1,14.08000000,1,1,14.09000000,100,1,14.20000000,902,4,ARL,215999753
701,2025-07-17T14:47:30.549341156Z,2025-07-17T14:47:30.549175659Z,160,2,1108,C,B,0,12.36000000,100,0,165497,183467004,13.38000000,33,1,13.37000000,100,1,13.28000000,11,2,13.26000000,4,2,13.25000000,111,2,13.20000000,30,2,13.15000000,2,1,13.14000000,100,1,13.12000000,4,2,13.11000000,100,1,13.40000000,208,12,13.67000000,100,1,13.78000000,2,1,13.93000000,102,2,13.94000000,110,2,14.00000000,101,2,14.01000000,100,1,14.08000000,1,1,14.09000000,100,1,14.20000000,902,4,ARL,126872361
702,2025-07-17T14:47:30.549341156Z,2025-07-17T14:47:30.549175659Z,160,2,1108,A,B,0,12.48000000,100,130,165497,183467004,13.38000000,33,1,13.37000000,100,1,13.28000000,11,2,13.26000000,4,2,13.25000000,111,2,13.20000000,30,2,13.15000000,2,1,13.14000000,100,1,13.12000000,4,2,13.11000000,100,1,13.40000000,208,12,13.67000000,100,1,13.78000000,2,1,13.93000000,102,2,13.94000000,110,2,14.00000000,101,2,14.01000000,100,1,14.08000000,1,1,14.09000000,100,1,14.20000000,902,4,ARL,215999761
703,2025-07-17T14:47:30.571385383Z,2025-07-17T14:47:30.571220121Z,160,2,1108,C,B,0,12.99000000,100,130,165262,183468111,13.38000000,33,1,13.37000000,100,1,13.28000000,11,2,13.26000000,4,2,13.25000000,111,2,13.20000000,30,2,13.15000000,2,1,13.14000000,100,1,13.12000000,4,2,13.11000000,100,1,13.40000000,208,12,13.67000000,100,1,13.78000000,2,1,13.93000000,102,2,13.94000000,110,2,14.00000000,101,2,14.01000000,100,1,14.08000000,1,1,14.09000000,100,1,14.20000000,902,4,ARL,43805737
704,2025-07-17T14:47:30.571436944Z,2025-07-17T14:47:30.571271737Z,160,2,1108,A,B,0,13.10000000,100,130,165207,183468112,13.38000000,33,1,13.37000000,100,1,13.28000000,11,2,13.26000000,4,2,13.25000000,111,2,13.20000000,30,2,13.15000000,2,1,13.14000000,100,1,13.12000000,4,2,13.11000000,100,1,13.40000000,208,12,13.67000000,100,1,13.78000000,2,1,13.93000000,102,2,13.94000000,110,2,14.00000000,101,2,14.01000000,100,1,14.08000000,1,1,14.09000000,100,1,14.20000000,902,4,ARL,216001413
705,2025-07-17T14:47:37.384610677Z,2025-07-17T14:47:37.384441232Z,160,2,1108,A,B,0,12.50000000,700,130,169445,183649796,13.38000000,33,1,13.37000000,100,1,13.28000000,11,2,13.26000000,4,2,13.25000000,111,2,13.20000000,30,2,13.15000000,2,1,13.14000000,100,1,13.12000000,4,2,13.11000000,100,1,13.40000000,208,12,13.67000000,100,1,13.78000000,2,1,13.93000000,102,2,13.94000000,110,2,14.00000000,101,2,14.01000000,100,1,14.08000000,1,1,14.09000000,100,1,14.20000000,902,4,ARL,216223005
706,2025-07-17T14:47:37.385400265Z,2025-07-17T14:47:37.385234288Z,160,2,1108,C,B,0,12.26000000,700,130,165977,183649801,13.38000000,33,1,13.37000000,100,1,13.28000000,11,2,13.26000000,4,2,13.25000000,111,2,13.20000000,30,2,13.15000000,2,1,13.14000000,100,1,13.12000000,4,2,13.11000000,100,1,13.40000000,208,12,13.67000000,100,1,13.78000000,2,1,13.93000000,102,2,13.94000000,110,2,14.00000000,101,2,14.01000000,100,1,14.08000000,1,1,14.09000000,100,1,14.20000000,902,4,ARL,44570585
707,2025-07-17T14:52:02.610481877Z,2025-07-17T14:52:02.610315566Z,160,2,1108,T,N,0,13.41000000,1,130,166311,189559140,13.38000000,33,1,13.37000000,100,1,13.28000000,11,2,13.26000000,4,2,13.25000000,111,2,13.20000000,30,2,13.15000000,2,1,13.14000000,100,1,13.12000000,4,2,13.11000000,100,1,13.40000000,208,12,13.67000000,100,1,13.78000000,2,1,13.93000000,102,2,13.94000000,110,2,14.00000000,101,2,14.01000000,100,1,14.08000000,1,1,14.09000000,100,1,14.20000000,902,4,ARL,0
708,2025-07-17T14:52:02.610509102Z,2025-07-17T14:52:02.610343819Z,160,2,1108,A,A,0,13.71000000,1,130,165283,189559141,13.38000000,33,1,13.37000000,100,1,13.28000000,11,2,13.26000000,4,2,13.25000000,111,2,13.20000000,30,2,13.15000000,2,1,13.14000000,100,1,13.12000000,4,2,13.11000000,100,1,13.40000000,208,12,13.67000000,100,1,13.71000000,1,1,13.78000000,2,1,13.93000000,102,2,13.94000000,110,2,14.00000000,101,2,14.01000000,100,1,14.08000000,1,1,14.09000000,100,1,ARL,223347833
709,2025-07-17T14:52:02.611701408Z,2025-07-17T14:52:02.611536221Z,160,2,1108,C,A,0,13.71000000,1,130,165187,189559156,13.38000000,33,1,13.37000000,100,1,13.28000000,11,2,13.26000000,4,2,13.25000000,111,2,13.20000000,30,2,13.15000000,2,1,13.14000000,100,1,13.12000000,4,2,13.11000000,100,1,13.40000000,208,12,13.67000000,100,1,13.71000000,1,1,13.78000000,2,1,13.93000000,102,2,13.94000000,110,2,14.00000000,101,2,14.01000000,100,1,14.08000000,1,1,14.09000000,100,1,ARL,223347833
710,2025-07-17T15:00:11.560678862Z,2025-07-17T15:00:11.560513555Z,160,2,1108,C,B,0,13.38000000,33,130,165307,200140364,13.38000000,33,1,13.37000000,100,1,13.28000000,11,2,13.26000000,4,2,13.25000000,111,2,13.20000000,30,2,13.15000000,2,1,13.14000000,100,1,13.12000000,4,2,13.11000000,100,1,13.40000000,208,12,13.67000000,100,1,13.71000000,1,1,13.78000000,2,1,13.93000000,102,2,13.94000000,110,2,14.00000000,101,2,14.01000000,100,1,14.08000000,1,1,14.09000000,100,1,ARL,215999733
711,2025-07-17T15:00:11.563053782Z,2025-07-17T15:00:11.562887948Z,160,2,1108,C,B,0,12.48000000,100,0,165834,200140389,13.38000000,33,1,13.37000000,100,1,13.28000000,11,2,13.26000000,4,2,13.25000000,111,2,13.20000000,30,2,13.15000000,2,1,13.14000000,100,1,13.12000000,4,2,13.11000000,100,1,13.40000000,208,12,13.67000000,100,1,13.71000000,1,1,13.78000000,2,1,13.93000000,102,2,13.94000000,110,2,14.00000000,101,2,14.01000000,100,1,14.08000000,1,1,14.09000000,100,1,ARL,215999761
712,2025-07-17T15:00:11.563053782Z,2025-07-17T15:00:11.562887948Z,160,2,1108,A,B,0,12.65000000,100,130,165834,200140389,13.38000000,33,1,13.37000000,100,1,13.28000000,11,2,13.26000000,4,2,13.25000000,111,2,13.20000000,30,2,13.15000000,2,1,13.14000000,100,1,13.12000000,4,2,13.11000000,100,1,13.40000000,208,12,13.67000000,100,1,13.71000000,1,1,13.78000000,2,1,13.93000000,102,2,13.94000000,110,2,14.00000000,101,2,14.01000000,100,1,14.08000000,1,1,14.09000000,100,1,ARL,236179089
713,2025-07-17T15:00:12.536218524Z,2025-07-17T15:00:12.536052536Z,160,2,1108,C,B,0,12.48000000,100,0,165988,200161810,13.38000000,33,1,13.37000000,100,1,13.28000000,11,2,13.26000000,4,2,13.25000000,111,2,13.20000000,30,2,13.15000000,2,1,13.14000000,100,1,13.12000000,4,2,13.11000000,100,1,13.40000000,208,12,13.67000000,100,1,13.71000000,1,1,13.78000000,2,1,13.93000000,102,2,13.94000000,110,2,14.00000000,101,2,14.01000000,100,1,14.08000000,1,1,14.09000000,100,1,ARL,215999741
714,2025-07-17T15:00:12.536218524Z,2025-07-17T15:00:12.536052536Z,160,2,1108,A,B,0,12.65000000,100,130,165988,200161810,13.38000000,33,1,13.37000000,100,1,13.28000000,11,2,13.26000000,4,2,13.25000000,111,2,13.20000000,30,2,13.15000000,2,1,13.14000000,100,1,13.12000000,4,2,13.11000000,100,1,13.40000000,208,12,13.67000000,100,1,13.71000000,1,1,13.78000000,2,1,13.93000000,102,2,13.94000000,110,2,14.00000000,101,2,14.01000000,100,1,14.08000000,1,1,14.09000000,100,1,ARL,236206261
715,2025-07-17T15:01:11.658789910Z,2025-07-17T15:01:11.658624662Z,160,2,1108,A,A,0,13.98000000,10,130,165248,201616674,13.38000000,33,1,13.37000000,100,1,13.28000000,11,2,13.26000000,4,2,13.25000000,111,2,13.20000000,30,2,13.15000000,2,1,13.14000000,100,1,13.12000000,4,2,13.11000000,100,1,13.40000000,208,12,13.67000000,100,1,13.71000000,1,1,13.78000000,2,1,13.93000000,102,2,13.94000000,110,2,13.98000000,10,1,14.00000000,101,2,14.01000000,100,1,14.08000000,1,1,ARL,237940713
716,2025-07-17T15:01:12.948386121Z,2025-07-17T15:01:12.948220412Z,160,2,1108,C,A,0,14.01000000,100,0,165709,201642675,13.38000000,33,1,13.37000000,100,1,13.28000000,11,2,13.26000000,4,2,13.25000000,111,2,13.20000000,30,2,13.15000000,2,1,13.14000000,100,1,13.12000000,4,2,13.11000000,100,1,13.40000000,208,12,13.67000000,100,1,13.71000000,1,1,13.78000000,2,1,13.93000000,102,2,13.94000000,110,2,13.98000000,10,1,14.00000000,101,2,14.01000000,100,1,14.08000000,1,1,ARL,168141389
717,2025-07-17T15:01:12.948386121Z,2025-07-17T15:01:12.948220412Z,160,2,1108,A,A,0,13.99000000,100,130,165709,201642675,13.38000000,33,1,13.37000000,100,1,13.28000000,11,2,13.26000000,4,2,13.25000000,111,2,13.20000000,30,2,13.15000000,2,1,13.14000000,100,1,13.12000000,4,2,13.11000000,100,1,13.40000000,208,12,13.67000000,100,1,13.71000000,1,1,13.78000000,2,1,13.93000000,102,2,13.94000000,110,2,13.98000000,10,1,13.99000000,100,1,14.00000000,101,2,14.01000000,100,1,ARL,237978541
718,2025-07-17T15:01:12.949124493Z,2025-07-17T15:01:12.948959226Z,160,2,1108,C,A,0,14.83000000,100,130,165267,201642712,13.38000000,33,1,13.37000000,100,1,13.28000000,11,2,13.26000000,4,2,13.25000000,111,2,13.20000000,30,2,13.15000000,2,1,13.14000000,100,1,13.12000000,4,2,13.11000000,100,1,13.40000000,208,12,13.67000000,100,1,13.71000000,1,1,13.78000000,2,1,13.93000000,102,2,13.94000000,110,2,13.98000000,10,1,13.99000000,100,1,14.00000000,101,2,14.01000000,100,1,ARL,84628793
719,2025-07-17T15:01:12.949484115Z,2025-07-17T15:01:12.949317198Z,160,2,1108,A,A,0,14.61000000,100,130,166917,201642747,13.38000000,33,1,13.37000000,100,1,13.28000000,11,2,13.26000000,4,2,13.25000000,111,2,13.20000000,30,2,13.15000000,2,1,13.14000000,100,1,13.12000000,4,2,13.11000000,100,1,13.40000000,208,12,13.67000000,100,1,13.71000000,1,1,13.78000000,2,1,13.93000000,102,2,13.94000000,110,2,13.98000000,10,1,13.99000000,100,1,14.00000000,101,2,14.01000000,100,1,ARL,237978629
720,2025-07-17T15:01:26.963916368Z,2025-07-17T15:01:26.963746832Z,160,2,1108,C,A,0,13.98000000,10,128,169536,201984003,13.38000000,33,1,13.37000000,100,1,13.28000000,11,2,13.26000000,4,2,13.25000000,111,2,13.20000000,30,2,13.15000000,2,1,13.14000000,100,1,13.12000000,4,2,13.11000000,100,1,13.40000000,208,12,13.67000000,100,1,13.71000000,1,1,13.78000000,2,1,13.93000000,102,2,13.94000000,110,2,13.98000000,10,1,13.99000000,100,1,14.00000000,101,2,14.01000000,100,1,ARL,237940713
721,2025-07-17T15:01:37.513312432Z,2025-07-17T15:01:37.513147090Z,160,2,1108,A,A,0,13.98000000,10,130,165342,202186180,13.38000000,33,1,13.37000000,100,1,13.28000000,11,2,13.26000000,4,2,13.25000000,111,2,13.20000000,30,2,13.15000000,2,1,13.14000000,100,1,13.12000000,4,2,13.11000000,100,1,13.40000000,208,12,13.67000000,100,1,13.71000000,1,1,13.78000000,2,1,13.93000000,102,2,13.94000000,110,2,13.98000000,20,2,13.99000000,100,1,14.00000000,101,2,14.01000000,100,1,ARL,238668633
722,2025-07-17T15:05:36.047202557Z,2025-07-17T15:05:36.047029298Z,160,2,1108,C,A,0,13.98000000,10,128,173259,207097179,13.38000000,33,1,13.37000000,100,1,13.28000000,11,2,13.26000000,4,2,13.25000000,111,2,13.20000000,30,2,13.15000000,2,1,13.14000000,100,1,13.12000000,4,2,13.11000000,100,1,13.40000000,208,12,13.67000000,100,1,13.71000000,1,1,13.78000000,2,1,13.93000000,102,2,13.94000000,110,2,13.98000000,20,2,13.99000000,100,1,14.00000000,101,2,14.01000000,100,1,ARL,238668633
723,2025-07-17T15:10:34.469866273Z,2025-07-17T15:10:34.469700487Z,160,2,1108,C,A,0,14.26000000,2,0,165786,213735006,13.38000000,33,1,13.37000000,100,1,13.28000000,11,2,13.26000000,4,2,13.25000000,111,2,13.20000000,30,2,13.15000000,2,1,13.14000000,100,1,13.12000000,4,2,13.11000000,100,1,13.40000000,208,12,13.67000000,100,1,13.71000000,1,1,13.78000000,2,1,13.93000000,102,2,13.94000000,110,2,13.98000000,20,2,13.99000000,100,1,14.00000000,101,2,14.01000000,100,1,ARL,129518753
724,2025-07-17T15:10:34.469866273Z,2025-07-17T15:10:34.469700487Z,160,2,1108,A,A,0,14.17000000,2,130,165786,213735006,13.38000000,33,1,13.37000000,100,1,13.28000000,11,2,13.26000000,4,2,13.25000000,111,2,13.20000000,30,2,13.15000000,2,1,13.14000000,100,1,13.12000000,4,2,13.11000000,100,1,13.40000000,208,12,13.67000000,100,1,13.71000000,1,1,13.78000000,2,1,13.93000000,102,2,13.94000000,110,2,13.98000000,20,2,13.99000000,100,1,14.00000000,101,2,14.01000000,100,1,ARL,252720897
725,2025-07-17T15:12:52.735414592Z,2025-07-17T15:12:52.735249178Z,160,2,1108,A,A,0,14.03000000,100,130,165414,216651092,13.38000000,33,1,13.37000000,100,1,13.28000000,11,2,13.26000000,4,2,13.25000000,111,2,13.20000000,30,2,13.15000000,2,1,13.14000000,100,1,13.12000000,4,2,13.11000000,100,1,13.40000000,208,12,13.67000000,100,1,13.71000000,1,1,13.78000000,2,1,13.93000000,102,2,13.94000000,110,2,13.98000000,20,2,13.99000000,100,1,14.00000000,101,2,14.01000000,100,1,ARL,256325129
726,2025-07-17T15:13:06.511853457Z,2025-07-17T15:13:06.511687613Z,160,2,1108,A,A,0,13.98000000,10,130,165844,216995105,13.38000000,33,1,13.37000000,100,1,13.28000000,11,2,13.26000000,4,2,13.25000000,111,2,13.20000000,30,2,13.15000000,2,1,13.14000000,100,1,13.12000000,4,2,13.11000000,100,1,13.40000000,208,12,13.67000000,100,1,13.71000000,1,1,13.78000000,2,1,13.93000000,102,2,13.94000000,110,2,13.98000000,30,3,13.99000000,100,1,14.00000000,101,2,14.01000000,100,1,ARL,256739841
727,2025-07-17T15:13:08.654089411Z,2025-07-17T15:13:08.653923821Z,160,2,1108,A,A,0,14.01000000,100,130,165590,217058300,13.38000000,33,1,13.37000000,100,1,13.28000000,11,2,13.26000000,4,2,13.25000000,111,2,13.20000000,30,2,13.15000000,2,1,13.14000000,100,1,13.12000000,4,2,13.11000000,100,1,13.40000000,208,12,13.67000000,100,1,13.71000000,1,1,13.78000000,2,1,13.93000000,102,2,13.94000000,110,2,13.98000000,30,3,13.99000000,100,1,14.00000000,101,2,14.01000000,200,2,ARL,256818881
728,2025-07-17T15:13:08.661686458Z,2025-07-17T15:13:08.661521116Z,160,2,1108,C,A,0,14.03000000,100,130,165342,217058550,13.38000000,33,1,13.37000000,100,1,13.28000000,11,2,13.26000000,4,2,13.25000000,111,2,13.20000000,30,2,13.15000000,2,1,13.14000000,100,1,13.12000000,4,2,13.11000000,100,1,13.40000000,208,12,13.67000000,100,1,13.71000000,1,1,13.78000000,2,1,13.93000000,102,2,13.94000000,110,2,13.98000000,30,3,13.99000000,100,1,14.00000000,101,2,14.01000000,200,2,ARL,256325129
729,2025-07-17T15:14:00.440728359Z,2025-07-17T15:14:00.440563034Z,160,2,1108,C,A,0,13.98000000,10,130,165325,218096891,13.38000000,33,1,13.37000000,100,1,13.28000000,11,2,13.26000000,4,2,13.25000000,111,2,13.20000000,30,2,13.15000000,2,1,13.14000000,100,1,13.12000000,4,2,13.11000000,100,1,13.40000000,208,12,13.67000000,100,1,13.71000000,1,1,13.78000000,2,1,13.93000000,102,2,13.94000000,110,2,13.98000000,30,3,13.99000000,100,1,14.00000000,101,2,14.01000000,200,2,ARL,256739841
730,2025-07-17T15:14:52.382139830Z,2025-07-17T15:14:52.381974473Z,160,2,1108,A,A,0,13.98000000,10,130,165357,219204095,13.38000000,33,1,13.37000000,100,1,13.28000000,11,2,13.26000000,4,2,13.25000000,111,2,13.20000000,30,2,13.15000000,2,1,13.14000000,100,1,13.12000000,4,2,13.11000000,100,1,13.40000000,208,12,13.67000000,100,1,13.71000000,1,1,13.78000000,2,1,13.93000000,102,2,13.94000000,110,2,13.98000000,40,4,13.99000000,100,1,14.00000000,101,2,14.01000000,200,2,ARL,259546169
731,2025-07-17T15:14:56.683309707Z,2025-07-17T15:14:56.683144163Z,160,2,1108,C,A,0,14.01000000,100,130,165544,219317677,13.38000000,33,1,13.37000000,100,1,13.28000000,11,2,13.26000000,4,2,13.25000000,111,2,13.20000000,30,2,13.15000000,2,1,13.14000000,100,1,13.12000000,4,2,13.11000000,100,1,13.40000000,208,12,13.67000000,100,1,13.71000000,1,1,13.78000000,2,1,13.93000000,102,2,13.94000000,110,2,13.98000000,40,4,13.99000000,100,1,14.00000000,101,2,14.01000000,200,2,ARL,256818881
732,2025-07-17T15:15:11.661118778Z,2025-07-17T15:15:11.660953613Z,160,2,1108,A,A,0,14.02000000,100,130,165165,219726276,13.38000000,33,1,13.37000000,100,1,13.28000000,11,2,13.26000000,4,2,13.25000000,111,2,13.20000000,30,2,13.15000000,2,1,13.14000000,100,1,13.12000000,4,2,13.11000000,100,1,13.40000000,208,12,13.67000000,100,1,13.71000000,1,1,13.78000000,2,1,13.93000000,102,2,13.94000000,110,2,13.98000000,40,4,13.99000000,100,1,14.00000000,101,2,14.01000000,200,2,ARL,260184621
733,2025-07-17T15:15:32.408863263Z,2025-07-17T15:15:32.408694312Z,160,2,1108,C,A,0,13.98000000,10,128,168951,220152194,13.38000000,33,1,13.37000000,100,1,13.28000000,11,2,13.26000000,4,2,13.25000000,111,2,13.20000000,30,2,13.15000000,2,1,13.14000000,100,1,13.12000000,4,2,13.11000000,100,1,13.40000000,208,12,13.67000000,100,1,13.71000000,1,1,13.78000000,2,1,13.93000000,102,2,13.94000000,110,2,13.98000000,40,4,13.99000000,100,1,14.00000000,101,2,14.01000000,200,2,ARL,259546169
734,2025-07-17T15:16:31.607242914Z,2025-07-17T15:16:31.607077080Z,160,2,1108,A,A,0,14.00000000,100,130,165834,221423516,13.38000000,33,1,13.37000000,100,1,13.28000000,11,2,13.26000000,4,2,13.25000000,111,2,13.20000000,30,2,13.15000000,2,1,13.14000000,100,1,13.12000000,4,2,13.11000000,100,1,13.40000000,208,12,13.67000000,100,1,13.71000000,1,1,13.78000000,2,1,13.93000000,102,2,13.94000000,110,2,13.98000000,40,4,13.99000000,100,1,14.00000000,201,3,14.01000000,200,2,ARL,262279553
735,2025-07-17T15:16:31.614370696Z,2025-07-17T15:16:31.614205345Z,160,2,1108,C,A,0,14.02000000,100,130,165351,221423706,13.38000000,33,1,13.37000000,100,1,13.28000000,11,2,13.26000000,4,2,13.25000000,111,2,13.20000000,30,2,13.15000000,2,1,13.14000000,100,1,13.12000000,4,2,13.11000000,100,1,13.40000000,208,12,13.67000000,100,1,13.71000000,1,1,13.78000000,2,1,13.93000000,102,2,13.94000000,110,2,13.98000000,40,4,13.99000000,100,1,14.00000000,201,3,14.01000000,200,2,ARL,260184621
736,2025-07-17T15:16:39.373467449Z,2025-07-17T15:16:39.373301585Z,160,2,1108,A,A,0,13.98000000,10,130,165864,221549244,13.38000000,33,1,13.37000000,100,1,13.28000000,11,2,13.26000000,4,2,13.25000000,111,2,13.20000000,30,2,13.15000000,2,1,13.14000000,100,1,13.12000000,4,2,13.11000000,100,1,13.40000000,208,12,13.67000000,100,1,13.71000000,1,1,13.78000000,2,1,13.93000000,102,2,13.94000000,110,2,13.98000000,50,5,13.99000000,100,1,14.00000000,201,3,14.01000000,200,2,ARL,262432821
737,2025-07-17T15:17:50.916325497Z,2025-07-17T15:17:50.916157330Z,160,2,1108,C,A,0,13.98000000,10,130,168167,223060323,13.38000000,33,1,13.37000000,100,1,13.28000000,11,2,13.26000000,4,2,13.25000000,111,2,13.20000000,30,2,13.15000000,2,1,13.14000000,100,1,13.12000000,4,2,13.11000000,100,1,13.40000000,208,12,13.67000000,100,1,13.71000000,1,1,13.78000000,2,1,13.93000000,102,2,13.94000000,110,2,13.98000000,50,5,13.99000000,100,1,14.00000000,201,3,14.01000000,200,2,ARL,262432821
738,2025-07-17T15:17:51.938467389Z,2025-07-17T15:17:51.938301087Z,160,2,1108,C,A,0,14.00000000,100,130,166302,223092013,13.38000000,33,1,13.37000000,100,1,13.28000000,11,2,13.26000000,4,2,13.25000000,111,2,13.20000000,30,2,13.15000000,2,1,13.14000000,100,1,13.12000000,4,2,13.11000000,100,1,13.40000000,208,12,13.67000000,100,1,13.71000000,1,1,13.78000000,2,1,13.93000000,102,2,13.94000000,110,2,13.98000000,50,5,13.99000000,100,1,14.00000000,201,3,14.01000000,200,2,ARL,262279553
739,2025-07-17T15:17:55.957423821Z,2025-07-17T15:17:55.957258362Z,160,2,1108,A,A,0,14.01000000,100,130,165459,223181022,13.38000000,33,1,13.37000000,100,1,13.28000000,11,2,13.26000000,4,2,13.25000000,111,2,13.20000000,30,2,13.15000000,2,1,13.14000000,100,1,13.12000000,4,2,13.11000000,100,1,13.40000000,208,12,13.67000000,100,1,13.71000000,1,1,13.78000000,2,1,13.93000000,102,2,13.94000000,110,2,13.98000000,50,5,13.99000000,100,1,14.00000000,201,3,14.01000000,300,3,ARL,264420961
740,2025-07-17T15:19:23.618380576Z,2025-07-17T15:19:23.618215364Z,160,2,1108,C,A,0,14.01000000,100,130,165212,224925658,13.38000000,33,1,13.37000000,100,1,13.28000000,11,2,13.26000000,4,2,13.25000000,111,2,13.20000000,30,2,13.15000000,2,1,13.14000000,100,1,13.12000000,4,2,13.11000000,100,1,13.40000000,208,12,13.67000000,100,1,13.71000000,1,1,13.78000000,2,1,13.93000000,102,2,13.94000000,110,2,13.98000000,50,5,13.99000000,100,1,14.00000000,201,3,14.01000000,300,3,ARL,264420961
741,2025-07-17T15:19:27.663790911Z,2025-07-17T15:19:27.663625107Z,160,2,1108,A,A,0,14.03000000,100,130,165804,224999109,13.38000000,33,1,13.37000000,100,1,13.28000000,11,2,13.26000000,4,2,13.25000000,111,2,13.20000000,30,2,13.15000000,2,1,13.14000000,100,1,13.12000000,4,2,13.11000000,100,1,13.40000000,208,12,13.67000000,100,1,13.71000000,1,1,13.78000000,2,1,13.93000000,102,2,13.94000000,110,2,13.98000000,50,5,13.99000000,100,1,14.00000000,201,3,14.01000000,300,3,ARL,266714557
742,2025-07-17T15:20:46.705145876Z,2025-07-17T15:20:46.704980311Z,160,2,1108,A,A,0,14.01000000,100,130,165565,226851430,13.38000000,33,1,13.37000000,100,1,13.28000000,11,2,13.26000000,4,2,13.25000000,111,2,13.20000000,30,2,13.15000000,2,1,13.14000000,100,1,13.12000000,4,2,13.11000000,100,1,13.40000000,208,12,13.67000000,100,1,13.71000000,1,1,13.78000000,2,1,13.93000000,102,2,13.94000000,110,2,13.98000000,50,5,13.99000000,100,1,14.00000000,201,3,14.01000000,400,4,ARL,269075833
743,2025-07-17T15:20:46.716698477Z,2025-07-17T15:20:46.716532886Z,160,2,1108,C,A,0,14.03000000,100,130,165591,226851533,13.38000000,33,1,13.37000000,100,1,13.28000000,11,2,13.26000000,4,2,13.25000000,111,2,13.20000000,30,2,13.15000000,2,1,13.14000000,100,1,13.12000000,4,2,13.11000000,100,1,13.40000000,208,12,13.67000000,100,1,13.71000000,1,1,13.78000000,2,1,13.93000000,102,2,13.94000000,110,2,13.98000000,50,5,13.99000000,100,1,14.00000000,201,3,14.01000000,400,4,ARL,266714557
744,2025-07-17T15:23:00.249962772Z,2025-07-17T15:23:00.249796874Z,160,2,1108,C,B,0,13.15000000,2,0,165898,229397485,13.38000000,33,1,13.37000000,100,1,13.28000000,11,2,13.26000000,4,2,13.25000000,111,2,13.20000000,30,2,13.15000000,2,1,13.14000000,100,1,13.12000000,4,2,13.11000000,100,1,13.40000000,208,12,13.67000000,100,1,13.71000000,1,1,13.78000000,2,1,13.93000000,102,2,13.94000000,110,2,13.98000000,50,5,13.99000000,100,1,14.00000000,201,3,14.01000000,400,4,ARL,130693973
745,2025-07-17T15:23:00.249962772Z,2025-07-17T15:23:00.249796874Z,160,2,1108,A,B,0,13.23000000,2,130,165898,229397485,13.38000000,33,1,13.37000000,100,1,13.28000000,11,2,13.26000000,4,2,13.25000000,111,2,13.23000000,2,1,13.20000000,30,2,13.15000000,2,1,13.14000000,100,1,13.12000000,4,2,13.40000000,208,12,13.67000000,100,1,13.71000000,1,1,13.78000000,2,1,13.93000000,102,2,13.94000000,110,2,13.98000000,50,5,13.99000000,100,1,14.00000000,201,3,14.01000000,400,4,ARL,272263853
746,2025-07-17T15:26:04.666158860Z,2025-07-17T15:26:04.665993515Z,160,2,1108,C,A,0,14.17000000,2,0,165345,232977340,13.38000000,33,1,13.37000000,100,1,13.28000000,11,2,13.26000000,4,2,13.25000000,111,2,13.23000000,2,1,13.20000000,30,2,13.15000000,2,1,13.14000000,100,1,13.12000000,4,2,13.40000000,208,12,13.67000000,100,1,13.71000000,1,1,13.78000000,2,1,13.93000000,102,2,13.94000000,110,2,13.98000000,50,5,13.99000000,100,1,14.00000000,201,3,14.01000000,400,4,ARL,252720897
747,2025-07-17T15:26:04.666158860Z,2025-07-17T15:26:04.665993515Z,160,2,1108,A,A,0,14.09000000,2,130,165345,232977340,13.38000000,33,1,13.37000000,100,1,13.28000000,11,2,13.26000000,4,2,13.25000000,111,2,13.23000000,2,1,13.20000000,30,2,13.15000000,2,1,13.14000000,100,1,13.12000000,4,2,13.40000000,208,12,13.67000000,100,1,13.71000000,1,1,13.78000000,2,1,13.93000000,102,2,13.94000000,110,2,13.98000000,50,5,13.99000000,100,1,14.00000000,201,3,14.01000000,400,4,ARL,276751517
748,2025-07-17T15:28:38.882985923Z,2025-07-17T15:28:38.882820591Z,160,2,1108,A,A,0,13.99000000,100,130,165332,235874491,13.38000000,33,1,13.37000000,100,1,13.28000000,11,2,13.26000000,4,2,13.25000000,111,2,13.23000000,2,1,13.20000000,30,2,13.15000000,2,1,13.14000000,100,1,13.12000000,4,2,13.40000000,208,12,13.67000000,100,1,13.71000000,1,1,13.78000000,2,1,13.93000000,102,2,13.94000000,110,2,13.98000000,50,5,13.99000000,200,2,14.00000000,201,3,14.01000000,400,4,ARL,280387693
749,2025-07-17T15:28:38.890789214Z,2025-07-17T15:28:38.890623989Z,160,2,1108,C,A,0,14.01000000,100,130,165225,235874556,13.38000000,33,1,13.37000000,100,1,13.28000000,11,2,13.26000000,4,2,13.25000000,111,2,13.23000000,2,1,13.20000000,30,2,13.15000000,2,1,13.14000000,100,1,13.12000000,4,2,13.40000000,208,12,13.67000000,100,1,13.71000000,1,1,13.78000000,2,1,13.93000000,102,2,13.94000000,110,2,13.98000000,50,5,13.99000000,200,2,14.00000000,201,3,14.01000000,400,4,ARL,269075833
750,2025-07-17T15:28:44.820934614Z,2025-07-17T15:28:44.820769301Z,160,2,1108,C,A,0,13.99000000,100,130,165313,235961324,13.38000000,33,1,13.37000000,100,1,13.28000000,11,2,13.26000000,4,2,13.25000000,111,2,13.23000000,2,1,13.20000000,30,2,13.15000000,2,1,13.14000000,100,1,13.12000000,4,2,13.40000000,208,12,13.67000000,100,1,13.71000000,1,1,13.78000000,2,1,13.93000000,102,2,13.94000000,110,2,13.98000000,50,5,13.99000000,200,2,14.00000000,201,3,14.01000000,400,4,ARL,280387693
751,2025-07-17T15:28:48.918811203Z,2025-07-17T15:28:48.918645728Z,160,2,1108,A,A,0,14.01000000,100,130,165475,236028551,13.38000000,33,1,13.37000000,100,1,13.28000000,11,2,13.26000000,4,2,13.25000000,111,2,13.23000000,2,1,13.20000000,30,2,13.15000000,2,1,13.14000000,100,1,13.12000000,4,2,13.40000000,208,12,13.67000000,100,1,13.71000000,1,1,13.78000000,2,1,13.93000000,102,2,13.94000000,110,2,13.98000000,50,5,13.99000000,200,2,14.00000000,201,3,14.01000000,500,5,ARL,280580873
752,2025-07-17T15:30:23.573233259Z,2025-07-17T15:30:23.573067851Z,160,2,1108,A,A,0,13.82000000,10,130,165408,237754758,13.38000000,33,1,13.37000000,100,1,13.28000000,11,2,13.26000000,4,2,13.25000000,111,2,13.23000000,2,1,13.20000000,30,2,13.15000000,2,1,13.14000000,100,1,13.12000000,4,2,13.40000000,208,12,13.67000000,100,1,13.71000000,1,1,13.78000000,2,1,13.82000000,10,1,13.93000000,102,2,13.94000000,110,2,13.98000000,50,5,13.99000000,200,2,14.00000000,201,3,ARL,282775557
753,2025-07-17T15:30:23.573528359Z,2025-07-17T15:30:23.573362522Z,160,2,1108,C,A,0,14.98000000,100,0,165837,237754762,13.38000000,33,1,13.37000000,100,1,13.28000000,11,2,13.26000000,4,2,13.25000000,111,2,13.23000000,2,1,13.20000000,30,2,13.15000000,2,1,13.14000000,100,1,13.12000000,4,2,13.40000000,208,12,13.67000000,100,1,13.71000000,1,1,13.78000000,2,1,13.82000000,10,1,13.93000000,102,2,13.94000000,110,2,13.98000000,50,5,13.99000000,200,2,14.00000000,201,3,ARL,128570237
754,2025-07-17T15:30:23.573528359Z,2025-07-17T15:30:23.573362522Z,160,2,1108,A,A,0,14.72000000,100,130,165837,237754762,13.38000000,33,1,13.37000000,100,1,13.28000000,11,2,13.26000000,4,2,13.25000000,111,2,13.23000000,2,1,13.20000000,30,2,13.15000000,2,1,13.14000000,100,1,13.12000000,4,2,13.40000000,208,12,13.67000000,100,1,13.71000000,1,1,13.78000000,2,1,13.82000000,10,1,13.93000000,102,2,13.94000000,110,2,13.98000000,50,5,13.99000000,200,2,14.00000000,201,3,ARL,282775561
755,2025-07-17T15:30:23.574854165Z,2025-07-17T15:30:23.574688647Z,160,2,1108,C,A,0,14.98000000,100,0,165518,237754776,13.38000000,33,1,13.37000000,100,1,13.28000000,11,2,13.26000000,4,2,13.25000000,111,2,13.23000000,2,1,13.20000000,30,2,13.15000000,2,1,13.14000000,100,1,13.12000000,4,2,13.40000000,208,12,13.67000000,100,1,13.71000000,1,1,13.78000000,2,1,13.82000000,10,1,13.93000000,102,2,13.94000000,110,2,13.98000000,50,5,13.99000000,200,2,14.00000000,201,3,ARL,128570229
756,2025-07-17T15:30:23.574854165Z,2025-07-17T15:30:23.574688647Z,160,2,1108,A,A,0,14.72000000,100,130,165518,237754776,13.38000000,33,1,13.37000000,100,1,13.28000000,11,2,13.26000000,4,2,13.25000000,111,2,13.23000000,2,1,13.20000000,30,2,13.15000000,2,1,13.14000000,100,1,13.12000000,4,2,13.40000000,208,12,13.67000000,100,1,13.71000000,1,1,13.78000000,2,1,13.82000000,10,1,13.93000000,102,2,13.94000000,110,2,13.98000000,50,5,13.99000000,200,2,14.00000000,201,3,ARL,282775577
757,2025-07-17T15:30:23.585191081Z,2025-07-17T15:30:23.585025490Z,160,2,1108,A,A,0,13.84000000,100,130,165591,237755075,13.38000000,33,1,13.37000000,100,1,13.28000000,11,2,13.26000000,4,2,13.25000000,111,2,13.23000000,2,1,13.20000000,30,2,13.15000000,2,1,13.14000000,100,1,13.12000000,4,2,13.40000000,208,12,13.67000000,100,1,13.71000000,1,1,13.78000000,2,1,13.82000000,10,1,13.84000000,100,1,13.93000000,102,2,13.94000000,110,2,13.98000000,50,5,13.99000000,200,2,ARL,282775973
758,2025-07-17T15:30:23.585960886Z,2025-07-17T15:30:23.585795327Z,160,2,1108,C,A,0,15.09000000,100,0,165559,237755081,13.38000000,33,1,13.37000000,100,1,13.28000000,11,2,13.26000000,4,2,13.25000000,111,2,13.23000000,2,1,13.20000000,30,2,13.15000000,2,1,13.14000000,100,1,13.12000000,4,2,13.40000000,208,12,13.67000000,100,1,13.71000000,1,1,13.78000000,2,1,13.82000000,10,1,13.84000000,100,1,13.93000000,102,2,13.94000000,110,2,13.98000000,50,5,13.99000000,200,2,ARL,146955361
759,2025-07-17T15:30:23.585960886Z,2025-07-17T15:30:23.585795327Z,160,2,1108,A,A,0,14.91000000,100,130,165559,237755081,13.38000000,33,1,13.37000000,100,1,13.28000000,11,2,13.26000000,4,2,13.25000000,111,2,13.23000000,2,1,13.20000000,30,2,13.15000000,2,1,13.14000000,100,1,13.12000000,4,2,13.40000000,208,12,13.67000000,100,1,13.71000000,1,1,13.78000000,2,1,13.82000000,10,1,13.84000000,100,1,13.93000000,102,2,13.94000000,110,2,13.98000000,50,5,13.99000000,200,2,ARL,282776009
760,2025-07-17T15:30:23.586719371Z,2025-07-17T15:30:23.586553674Z,160,2,1108,C,A,0,14.89000000,100,0,165697,237755086,13.38000000,33,1,13.37000000,100,1,13.28000000,11,2,13.26000000,4,2,13.25000000,111,2,13.23000000,2,1,13.20000000,30,2,13.15000000,2,1,13.14000000,100,1,13.12000000,4,2,13.40000000,208,12,13.67000000,100,1,13.71000000,1,1,13.78000000,2,1,13.82000000,10,1,13.84000000,100,1,13.93000000,102,2,13.94000000,110,2,13.98000000,50,5,13.99000000,200,2,ARL,128570453
761,2025-07-17T15:30:23.586719371Z,2025-07-17T15:30:23.586553674Z,160,2,1108,A,A,0,14.65000000,100,130,165697,237755086,13.38000000,33,1,13.37000000,100,1,13.28000000,11,2,13.26000000,4,2,13.25000000,111,2,13.23000000,2,1,13.20000000,30,2,13.15000000,2,1,13.14000000,100,1,13.12000000,4,2,13.40000000,208,12,13.67000000,100,1,13.71000000,1,1,13.78000000,2,1,13.82000000,10,1,13.84000000,100,1,13.93000000,102,2,13.94000000,110,2,13.98000000,50,5,13.99000000,200,2,ARL,282776013
762,2025-07-17T15:30:23.586762105Z,2025-07-17T15:30:23.586596452Z,160,2,1108,C,A,0,15.64000000,100,0,165653,237755087,13.38000000,33,1,13.37000000,100,1,13.28000000,11,2,13.26000000,4,2,13.25000000,111,2,13.23000000,2,1,13.20000000,30,2,13.15000000,2,1,13.14000000,100,1,13.12000000,4,2,13.40000000,208,12,13.67000000,100,1,13.71000000,1,1,13.78000000,2,1,13.82000000,10,1,13.84000000,100,1,13.93000000,102,2,13.94000000,110,2,13.98000000,50,5,13.99000000,200,2,ARL,84628833
763,2025-07-17T15:30:23.586762105Z,2025-07-17T15:30:23.586596452Z,160,2,1108,A,A,0,15.23000000,100,130,165653,237755087,13.38000000,33,1,13.37000000,100,1,13.28000000,11,2,13.26000000,4,2,13.25000000,111,2,13.23000000,2,1,13.20000000,30,2,13.15000000,2,1,13.14000000,100,1,13.12000000,4,2,13.40000000,208,12,13.67000000,100,1,13.71000000,1,1,13.78000000,2,1,13.82000000,10,1,13.84000000,100,1,13.93000000,102,2,13.94000000,110,2,13.98000000,50,5,13.99000000,200,2,ARL,282776017
764,2025-07-17T15:30:23.587432517Z,2025-07-17T15:30:23.587267064Z,160,2,1108,C,A,0,17.90000000,100,0,165453,237755097,13.38000000,33,1,13.37000000,100,1,13.28000000,11,2,13.26000000,4,2,13.25000000,111,2,13.23000000,2,1,13.20000000,30,2,13.15000000,2,1,13.14000000,100,1,13.12000000,4,2,13.40000000,208,12,13.67000000,100,1,13.71000000,1,1,13.78000000,2,1,13.82000000,10,1,13.84000000,100,1,13.93000000,102,2,13.94000000,110,2,13.98000000,50,5,13.99000000,200,2,ARL,128570685
765,2025-07-17T15:30:23.587432517Z,2025-07-17T15:30:23.587267064Z,160,2,1108,A,A,0,17.58000000,100,130,165453,237755097,13.38000000,33,1,13.37000000,100,1,13.28000000,11,2,13.26000000,4,2,13.25000000,111,2,13.23000000,2,1,13.20000000,30,2,13.15000000,2,1,13.14000000,100,1,13.12000000,4,2,13.40000000,208,12,13.67000000,100,1,13.71000000,1,1,13.78000000,2,1,13.82000000,10,1,13.84000000,100,1,13.93000000,102,2,13.94000000,110,2,13.98000000,50,5,13.99000000,200,2,ARL,282776025
766,2025-07-17T15:30:23.587581881Z,2025-07-17T15:30:23.587416236Z,160,2,1108,C,A,0,15.08000000,100,0,165645,237755098,13.38000000,33,1,13.37000000,100,1,13.28000000,11,2,13.26000000,4,2,13.25000000,111,2,13.23000000,2,1,13.20000000,30,2,13.15000000,2,1,13.14000000,100,1,13.12000000,4,2,13.40000000,208,12,13.67000000,100,1,13.71000000,1,1,13.78000000,2,1,13.82000000,10,1,13.84000000,100,1,13.93000000,102,2,13.94000000,110,2,13.98000000,50,5,13.99000000,200,2,ARL,128570449
767,2025-07-17T15:30:23.587581881Z,2025-07-17T15:30:23.587416236Z,160,2,1108,A,A,0,14.81000000,100,130,165645,237755098,13.38000000,33,1,13.37000000,100,1,13.28000000,11,2,13.26000000,4,2,13.25000000,111,2,13.23000000,2,1,13.20000000,30,2,13.15000000,2,1,13.14000000,100,1,13.12000000,4,2,13.40000000,208,12,13.67000000,100,1,13.71000000,1,1,13.78000000,2,1,13.82000000,10,1,13.84000000,100,1,13.93000000,102,2,13.94000000,110,2,13.98000000,50,5,13.99000000,200,2,ARL,282776029
768,2025-07-17T15:30:23.587611440Z,2025-07-17T15:30:23.587445922Z,160,2,1108,C,A,0,16.21000000,100,0,165518,237755099,13.38000000,33,1,13.37000000,100,1,13.28000000,11,2,13.26000000,4,2,13.25000000,111,2,13.23000000,2,1,13.20000000,30,2,13.15000000,2,1,13.14000000,100,1,13.12000000,4,2,13.40000000,208,12,13.67000000,100,1,13.71000000,1,1,13.78000000,2,1,13.82000000,10,1,13.84000000,100,1,13.93000000,102,2,13.94000000,110,2,13.98000000,50,5,13.99000000,200,2,ARL,128570977
769,2025-07-17T15:30:23.587611440Z,2025-07-17T15:30:23.587445922Z,160,2,1108,A,A,0,15.92000000,100,130,165518,237755099,13.38000000,33,1,13.37000000,100,1,13.28000000,11,2,13.26000000,4,2,13.25000000,111,2,13.23000000,2,1,13.20000000,30,2,13.15000000,2,1,13.14000000,100,1,13.12000000,4,2,13.40000000,208,12,13.67000000,100,1,13.71000000,1,1,13.78000000,2,1,13.82000000,10,1,13.84000000,100,1,13.93000000,102,2,13.94000000,110,2,13.98000000,50,5,13.99000000,200,2,ARL,282776033
770,2025-07-17T15:30:23.590261792Z,2025-07-17T15:30:23.590096343Z,160,2,1108,C,A,0,15.08000000,100,0,165449,237755128,13.38000000,33,1,13.37000000,100,1,13.28000000,11,2,13.26000000,4,2,13.25000000,111,2,13.23000000,2,1,13.20000000,30,2,13.15000000,2,1,13.14000000,100,1,13.12000000,4,2,13.40000000,208,12,13.67000000,100,1,13.71000000,1,1,13.78000000,2,1,13.82000000,10,1,13.84000000,100,1,13.93000000,102,2,13.94000000,110,2,13.98000000,50,5,13.99000000,200,2,ARL,128573957
771,2025-07-17T15:30:23.590261792Z,2025-07-17T15:30:23.590096343Z,160,2,1108,A,A,0,14.81000000,100,130,165449,237755128,13.38000000,33,1,13.37000000,100,1,13.28000000,11,2,13.26000000,4,2,13.25000000,111,2,13.23000000,2,1,13.20000000,30,2,13.15000000,2,1,13.14000000,100,1,13.12000000,4,2,13.40000000,208,12,13.67000000,100,1,13.71000000,1,1,13.78000000,2,1,13.82000000,10,1,13.84000000,100,1,13.93000000,102,2,13.94000000,110,2,13.98000000,50,5,13.99000000,200,2,ARL,282776089
772,2025-07-17T15:30:23.591959120Z,2025-07-17T15:30:23.591793735Z,160,2,1108,C,A,0,14.01000000,100,130,165385,237755138,13.38000000,33,1,13.37000000,100,1,13.28000000,11,2,13.26000000,4,2,13.25000000,111,2,13.23000000,2,1,13.20000000,30,2,13.15000000,2,1,13.14000000,100,1,13.12000000,4,2,13.40000000,208,12,13.67000000,100,1,13.71000000,1,1,13.78000000,2,1,13.82000000,10,1,13.84000000,100,1,13.93000000,102,2,13.94000000,110,2,13.98000000,50,5,13.99000000,200,2,ARL,280580873
773,2025-07-17T15:30:23.602992439Z,2025-07-17T15:30:23.602827102Z,160,2,1108,C,A,0,14.28000000,100,130,165337,237755229,13.38000000,33,1,13.37000000,100,1,13.28000000,11,2,13.26000000,4,2,13.25000000,111,2,13.23000000,2,1,13.20000000,30,2,13.15000000,2,1,13.14000000,100,1,13.12000000,4,2,13.40000000,208,12,13.67000000,100,1,13.71000000,1,1,13.78000000,2,1,13.82000000,10,1,13.84000000,100,1,13.93000000,102,2,13.94000000,110,2,13.98000000,50,5,13.99000000,200,2,ARL,146956357
774,2025-07-17T15:30:23.603046460Z,2025-07-17T15:30:23.602881129Z,160,2,1108,A,A,0,14.12000000,100,130,165331,237755230,13.38000000,33,1,13.37000000,100,1,13.28000000,11,2,13.26000000,4,2,13.25000000,111,2,13.23000000,2,1,13.20000000,30,2,13.15000000,2,1,13.14000000,100,1,13.12000000,4,2,13.40000000,208,12,13.67000000,100,1,13.71000000,1,1,13.78000000,2,1,13.82000000,10,1,13.84000000,100,1,13.93000000,102,2,13.94000000,110,2,13.98000000,50,5,13.99000000,200,2,ARL,282776285
775,2025-07-17T15:30:23.628720816Z,2025-07-17T15:30:23.628555135Z,160,2,1108,A,A,0,15.78000000,100,130,165681,237755415,13.38000000,33,1,13.37000000,100,1,13.28000000,11,2,13.26000000,4,2,13.25000000,111,2,13.23000000,2,1,13.20000000,30,2,13.15000000,2,1,13.14000000,100,1,13.12000000,4,2,13.40000000,208,12,13.67000000,100,1,13.71000000,1,1,13.78000000,2,1,13.82000000,10,1,13.84000000,100,1,13.93000000,102,2,13.94000000,110,2,13.98000000,50,5,13.99000000,200,2,ARL,282776733
776,2025-07-17T15:30:23.628732597Z,2025-07-17T15:30:23.628567293Z,160,2,1108,C,A,0,16.20000000,100,130,165304,237755416,13.38000000,33,1,13.37000000,100,1,13.28000000,11,2,13.26000000,4,2,13.25000000,111,2,13.23000000,2,1,13.20000000,30,2,13.15000000,2,1,13.14000000,100,1,13.12000000,4,2,13.40000000,208,12,13.67000000,100,1,13.71000000,1,1,13.78000000,2,1,13.82000000,10,1,13.84000000,100,1,13.93000000,102,2,13.94000000,110,2,13.98000000,50,5,13.99000000,200,2,ARL,84628765
777,2025-07-17T15:30:23.952122580Z,2025-07-17T15:30:23.951957017Z,160,2,1108,C,A,0,13.99000000,100,0,165563,237759683,13.38000000,33,1,13.37000000,100,1,13.28000000,11,2,13.26000000,4,2,13.25000000,111,2,13.23000000,2,1,13.20000000,30,2,13.15000000,2,1,13.14000000,100,1,13.12000000,4,2,13.40000000,208,12,13.67000000,100,1,13.71000000,1,1,13.78000000,2,1,13.82000000,10,1,13.84000000,100,1,13.93000000,102,2,13.94000000,110,2,13.98000000,50,5,13.99000000,200,2,ARL,237978541
778,2025-07-17T15:30:23.952122580Z,2025-07-17T15:30:23.951957017Z,160,2,1108,A,A,0,13.83000000,100,130,165563,237759683,13.38000000,33,1,13.37000000,100,1,13.28000000,11,2,13.26000000,4,2,13.25000000,111,2,13.23000000,2,1,13.20000000,30,2,13.15000000,2,1,13.14000000,100,1,13.12000000,4,2,13.40000000,208,12,13.67000000,100,1,13.71000000,1,1,13.78000000,2,1,13.82000000,10,1,13.83000000,100,1,13.84000000,100,1,13.93000000,102,2,13.94000000,110,2,13.98000000,50,5,ARL,282781741
779,2025-07-17T15:30:24.769074814Z,2025-07-17T15:30:24.768909757Z,160,2,1108,C,A,0,13.82000000,10,130,165057,237771822,13.38000000,33,1,13.37000000,100,1,13.28000000,11,2,13.26000000,4,2,13.25000000,111,2,13.23000000,2,1,13.20000000,30,2,13.15000000,2,1,13.14000000,100,1,13.12000000,4,2,13.40000000,208,12,13.67000000,100,1,13.71000000,1,1,13.78000000,2,1,13.82000000,10,1,13.83000000,100,1,13.84000000,100,1,13.93000000,102,2,13.94000000,110,2,13.98000000,50,5,ARL,282775557
780,2025-07-17T15:30:28.617337198Z,2025-07-17T15:30:28.617171810Z,160,2,1108,A,A,0,14.53000000,700,130,165388,237840336,13.38000000,33,1,13.37000000,100,1,13.28000000,11,2,13.26000000,4,2,13.25000000,111,2,13.23000000,2,1,13.20000000,30,2,13.15000000,2,1,13.14000000,100,1,13.12000000,4,2,13.40000000,208,12,13.67000000,100,1,13.71000000,1,1,13.78000000,2,1,13.82000000,10,1,13.83000000,100,1,13.84000000,100,1,13.93000000,102,2,13.94000000,110,2,13.98000000,50,5,ARL,282881853
781,2025-07-17T15:30:28.617387294Z,2025-07-17T15:30:28.617221981Z,160,2,1108,C,A,0,15.07000000,700,130,165313,237840337,13.38000000,33,1,13.37000000,100,1,13.28000000,11,2,13.26000000,4,2,13.25000000,111,2,13.23000000,2,1,13.20000000,30,2,13.15000000,2,1,13.14000000,100,1,13.12000000,4,2,13.40000000,208,12,13.67000000,100,1,13.71000000,1,1,13.78000000,2,1,13.82000000,10,1,13.83000000,100,1,13.84000000,100,1,13.93000000,102,2,13.94000000,110,2,13.98000000,50,5,ARL,92510741
782,2025-07-17T15:30:30.767213907Z,2025-07-17T15:30:30.767048606Z,160,2,1108,A,A,0,14.60000000,700,130,165301,237873135,13.38000000,33,1,13.37000000,100,1,13.28000000,11,2,13.26000000,4,2,13.25000000,111,2,13.23000000,2,1,13.20000000,30,2,13.15000000,2,1,13.14000000,100,1,13.12000000,4,2,13.40000000,208,12,13.67000000,100,1,13.71000000,1,1,13.78000000,2,1,13.82000000,10,1,13.83000000,100,1,13.84000000,100,1,13.93000000,102,2,13.94000000,110,2,13.98000000,50,5,ARL,282920685
783,2025-07-17T15:30:30.767267001Z,2025-07-17T15:30:30.767101317Z,160,2,1108,C,A,0,14.99000000,700,130,165684,237873136,13.38000000,33,1,13.37000000,100,1,13.28000000,11,2,13.26000000,4,2,13.25000000,111,2,13.23000000,2,1,13.20000000,30,2,13.15000000,2,1,13.14000000,100,1,13.12000000,4,2,13.40000000,208,12,13.67000000,100,1,13.71000000,1,1,13.78000000,2,1,13.82000000,10,1,13.83000000,100,1,13.84000000,100,1,13.93000000,102,2,13.94000000,110,2,13.98000000,50,5,ARL,84628757
784,2025-07-17T15:30:33.016987097Z,2025-07-17T15:30:33.016821395Z,160,2,1108,A,A,0,14.56000000,700,130,165702,237915946,13.38000000,33,1,13.37000000,100,1,13.28000000,11,2,13.26000000,4,2,13.25000000,111,2,13.23000000,2,1,13.20000000,30,2,13.15000000,2,1,13.14000000,100,1,13.12000000,4,2,13.40000000,208,12,13.67000000,100,1,13.71000000,1,1,13.78000000,2,1,13.82000000,10,1,13.83000000,100,1,13.84000000,100,1,13.93000000,102,2,13.94000000,110,2,13.98000000,50,5,ARL,282969973
785,2025-07-17T15:30:33.017384279Z,2025-07-17T15:30:33.017218657Z,160,2,1108,C,A,0,14.95000000,700,130,165622,237915951,13.38000000,33,1,13.37000000,100,1,13.28000000,11,2,13.26000000,4,2,13.25000000,111,2,13.23000000,2,1,13.20000000,30,2,13.15000000,2,1,13.14000000,100,1,13.12000000,4,2,13.40000000,208,12,13.67000000,100,1,13.71000000,1,1,13.78000000,2,1,13.82000000,10,1,13.83000000,100,1,13.84000000,100,1,13.93000000,102,2,13.94000000,110,2,13.98000000,50,5,ARL,84628797
786,2025-07-17T15:30:49.985906754Z,2025-07-17T15:30:49.985741094Z,160,2,1108,C,A,0,14.09000000,2,0,165660,238230724,13.38000000,33,1,13.37000000,100,1,13.28000000,11,2,13.26000000,4,2,13.25000000,111,2,13.23000000,2,1,13.20000000,30,2,13.15000000,2,1,13.14000000,100,1,13.12000000,4,2,13.40000000,208,12,13.67000000,100,1,13.71000000,1,1,13.78000000,2,1,13.82000000,10,1,13.83000000,100,1,13.84000000,100,1,13.93000000,102,2,13.94000000,110,2,13.98000000,50,5,ARL,276751517
787,2025-07-17T15:30:49.985906754Z,2025-07-17T15:30:49.985741094Z,160,2,1108,A,A,0,14.02000000,2,130,165660,238230724,13.38000000,33,1,13.37000000,100,1,13.28000000,11,2,13.26000000,4,2,13.25000000,111,2,13.23000000,2,1,13.20000000,30,2,13.15000000,2,1,13.14000000,100,1,13.12000000,4,2,13.40000000,208,12,13.67000000,100,1,13.71000000,1,1,13.78000000,2,1,13.82000000,10,1,13.83000000,100,1,13.84000000,100,1,13.93000000,102,2,13.94000000,110,2,13.98000000,50,5,ARL,283348193
788,2025-07-17T15:30:59.996516554Z,2025-07-17T15:30:59.996351383Z,160,2,1108,C,A,0,13.83000000,100,130,165171,238442318,13.38000000,33,1,13.37000000,100,1,13.28000000,11,2,13.26000000,4,2,13.25000000,111,2,13.23000000,2,1,13.20000000,30,2,13.15000000,2,1,13.14000000,100,1,13.12000000,4,2,13.40000000,208,12,13.67000000,100,1,13.71000000,1,1,13.78000000,2,1,13.82000000,10,1,13.83000000,100,1,13.84000000,100,1,13.93000000,102,2,13.94000000,110,2,13.98000000,50,5,ARL,282781741
789,2025-07-17T15:31:00.002203922Z,2025-07-17T15:31:00.002038446Z,160,2,1108,C,A,0,13.84000000,100,130,165476,238442443,13.38000000,33,1,13.37000000,100,1,13.28000000,11,2,13.26000000,4,2,13.25000000,111,2,13.23000000,2,1,13.20000000,30,2,13.15000000,2,1,13.14000000,100,1,13.12000000,4,2,13.40000000,208,12,13.67000000,100,1,13.71000000,1,1,13.78000000,2,1,13.82000000,10,1,13.83000000,100,1,13.84000000,100,1,13.93000000,102,2,13.94000000,110,2,13.98000000,50,5,ARL,282775973
790,2025-07-17T15:31:00.002478393Z,2025-07-17T15:31:00.002313250Z,160,2,1108,C,A,0,14.53000000,700,130,165143,238442461,13.38000000,33,1,13.37000000,100,1,13.28000000,11,2,13.26000000,4,2,13.25000000,111,2,13.23000000,2,1,13.20000000,30,2,13.15000000,2,1,13.14000000,100,1,13.12000000,4,2,13.40000000,208,12,13.67000000,100,1,13.71000000,1,1,13.78000000,2,1,13.82000000,10,1,13.83000000,100,1,13.84000000,100,1,13.93000000,102,2,13.94000000,110,2,13.98000000,50,5,ARL,282881853
791,2025-07-17T15:31:00.002525213Z,2025-07-17T15:31:00.002359969Z,160,2,1108,A,A,0,14.68000000,700,130,165244,238442467,13.38000000,33,1,13.37000000,100,1,13.28000000,11,2,13.26000000,4,2,13.25000000,111,2,13.23000000,2,1,13.20000000,30,2,13.15000000,2,1,13.14000000,100,1,13.12000000,4,2,13.40000000,208,12,13.67000000,100,1,13.71000000,1,1,13.78000000,2,1,13.82000000,10,1,13.83000000,100,1,13.84000000,100,1,13.93000000,102,2,13.94000000,110,2,13.98000000,50,5,ARL,283592941
792,2025-07-17T15:31:00.002938332Z,2025-07-17T15:31:00.002772683Z,160,2,1108,C,A,0,14.72000000,100,0,165649,238442486,13.38000000,33,1,13.37000000,100,1,13.28000000,11,2,13.26000000,4,2,13.25000000,111,2,13.23000000,2,1,13.20000000,30,2,13.15000000,2,1,13.14000000,100,1,13.12000000,4,2,13.40000000,208,12,13.67000000,100,1,13.71000000,1,1,13.78000000,2,1,13.82000000,10,1,13.83000000,100,1,13.84000000,100,1,13.93000000,102,2,13.94000000,110,2,13.98000000,50,5,ARL,282775577
793,2025-07-17T15:31:00.002938332Z,2025-07-17T15:31:00.002772683Z,160,2,1108,A,A,0,14.97000000,100,130,165649,238442486,13.38000000,33,1,13.37000000,100,1,13.28000000,11,2,13.26000000,4,2,13.25000000,111,2,13.23000000,2,1,13.20000000,30,2,13.15000000,2,1,13.14000000,100,1,13.12000000,4,2,13.40000000,208,12,13.67000000,100,1,13.71000000,1,1,13.78000000,2,1,13.82000000,10,1,13.83000000,100,1,13.84000000,100,1,13.93000000,102,2,13.94000000,110,2,13.98000000,50,5,ARL,283592993
794,2025-07-17T15:31:00.002953704Z,2025-07-17T15:31:00.002788190Z,160,2,1108,C,A,0,14.91000000,100,0,165514,238442490,13.38000000,33,1,13.37000000,100,1,13.28000000,11,2,13.26000000,4,2,13.25000000,111,2,13.23000000,2,1,13.20000000,30,2,13.15000000,2,1,13.14000000,100,1,13.12000000,4,2,13.40000000,208,12,13.67000000,100,1,13.71000000,1,1,13.78000000,2,1,13.82000000,10,1,13.83000000,100,1,13.84000000,100,1,13.93000000,102,2,13.94000000,110,2,13.98000000,50,5,ARL,282776009
795,2025-07-17T15:31:00.002953704Z,2025-07-17T15:31:00.002788190Z,160,2,1108,A,A,0,14.96000000,100,130,165514,238442490,13.38000000,33,1,13.37000000,100,1,13.28000000,11,2,13.26000000,4,2,13.25000000,111,2,13.23000000,2,1,13.20000000,30,2,13.15000000,2,1,13.14000000,100,1,13.12000000,4,2,13.40000000,208,12,13.67000000,100,1,13.71000000,1,1,13.78000000,2,1,13.82000000,10,1,13.83000000,100,1,13.84000000,100,1,13.93000000,102,2,13.94000000,110,2,13.98000000,50,5,ARL,283592997
796,2025-07-17T15:31:00.003368272Z,2025-07-17T15:31:00.003202003Z,160,2,1108,C,A,0,14.72000000,100,0,166269,238442510,13.38000000,33,1,13.37000000,100,1,13.28000000,11,2,13.26000000,4,2,13.25000000,111,2,13.23000000,2,1,13.20000000,30,2,13.15000000,2,1,13.14000000,100,1,13.12000000,4,2,13.40000000,208,12,13.67000000,100,1,13.71000000,1,1,13.78000000,2,1,13.82000000,10,1,13.83000000,100,1,13.84000000,100,1,13.93000000,102,2,13.94000000,110,2,13.98000000,50,5,ARL,282775561
797,2025-07-17T15:31:00.003368272Z,2025-07-17T15:31:00.003202003Z,160,2,1108,A,A,0,14.97000000,100,130,166269,238442510,13.38000000,33,1,13.37000000,100,1,13.28000000,11,2,13.26000000,4,2,13.25000000,111,2,13.23000000,2,1,13.20000000,30,2,13.15000000,2,1,13.14000000,100,1,13.12000000,4,2,13.40000000,208,12,13.67000000,100,1,13.71000000,1,1,13.78000000,2,1,13.82000000,10,1,13.83000000,100,1,13.84000000,100,1,13.93000000,102,2,13.94000000,110,2,13.98000000,50,5,ARL,283593041
798,2025-07-17T15:31:00.006784947Z,2025-07-17T15:31:00.006618398Z,160,2,1108,C,A,0,14.65000000,100,130,166549,238442608,13.38000000,33,1,13.37000000,100,1,13.28000000,11,2,13.26000000,4,2,13.25000000,111,2,13.23000000,2,1,13.20000000,30,2,13.15000000,2,1,13.14000000,100,1,13.12000000,4,2,13.40000000,208,12,13.67000000,100,1,13.71000000,1,1,13.78000000,2,1,13.82000000,10,1,13.83000000,100,1,13.84000000,100,1,13.93000000,102,2,13.94000000,110,2,13.98000000,50,5,ARL,282776013
799,2025-07-17T15:31:00.006950491Z,2025-07-17T15:31:00.006784814Z,160,2,1108,A,A,0,14.79000000,100,130,165677,238442616,13.38000000,33,1,13.37000000,100,1,13.28000000,11,2,13.26000000,4,2,13.25000000,111,2,13.23000000,2,1,13.20000000,30,2,13.15000000,2,1,13.14000000,100,1,13.12000000,4,2,13.40000000,208,12,13.67000000,100,1,13.71000000,1,1,13.78000000,2,1,13.82000000,10,1,13.83000000,100,1,13.84000000,100,1,13.93000000,102,2,13.94000000,110,2,13.98000000,50,5,ARL,283593313
800,2025-07-17T15:31:00.017759891Z,2025-07-17T15:31:00.017594312Z,160,2,1108,C,A,0,17.58000000,100,0,165579,238443214,13.38000000,33,1,13.37000000,100,1,13.28000000,11,2,13.26000000,4,2,13.25000000,111,2,13.23000000,2,1,13.20000000,30,2,13.15000000,2,1,13.14000000,100,1,13.12000000,4,2,13.40000000,208,12,13.67000000,100,1,13.71000000,1,1,13.78000000,2,1,13.82000000,10,1,13.83000000,100,1,13.84000000,100,1,13.93000000,102,2,13.94000000,110,2,13.98000000,50,5,ARL,282776025
801,2025-07-17T15:31:00.017759891Z,2025-07-17T15:31:00.017594312Z,160,2,1108,A,A,0,17.76000000,100,130,165579,238443214,13.38000000,33,1,13.37000000,100,1,13.28000000,11,2,13.26000000,4,2,13.25000000,111,2,13.23000000,2,1,13.20000000,30,2,13.15000000,2,1,13.14000000,100,1,13.12000000,4,2,13.40000000,208,12,13.67000000,100,1,13.71000000,1,1,13.78000000,2,1,13.82000000,10,1,13.83000000,100,1,13.84000000,100,1,13.93000000,102,2,13.94000000,110,2,13.98000000,50,5,ARL,283594173
802,2025-07-17T15:31:00.028894478Z,2025-07-17T15:31:00.028729168Z,160,2,1108,C,A,0,14.12000000,100,130,165310,238443996,13.38000000,33,1,13.37000000,100,1,13.28000000,11,2,13.26000000,4,2,13.25000000,111,2,13.23000000,2,1,13.20000000,30,2,13.15000000,2,1,13.14000000,100,1,13.12000000,4,2,13.40000000,208,12,13.67000000,100,1,13.71000000,1,1,13.78000000,2,1,13.82000000,10,1,13.83000000,100,1,13.84000000,100,1,13.93000000,102,2,13.94000000,110,2,13.98000000,50,5,ARL,282776285
803,2025-07-17T15:31:00.028947312Z,2025-07-17T15:31:00.028782030Z,160,2,1108,A,A,0,14.26000000,100,130,165282,238443998,13.38000000,33,1,13.37000000,100,1,13.28000000,11,2,13.26000000,4,2,13.25000000,111,2,13.23000000,2,1,13.20000000,30,2,13.15000000,2,1,13.14000000,100,1,13.12000000,4,2,13.40000000,208,12,13.67000000,100,1,13.71000000,1,1,13.78000000,2,1,13.82000000,10,1,13.83000000,100,1,13.84000000,100,1,13.93000000,102,2,13.94000000,110,2,13.98000000,50,5,ARL,283595181
804,2025-07-17T15:31:00.053107210Z,2025-07-17T15:31:00.052941898Z,160,2,1108,C,A,0,14.96000000,100,0,165312,238444735,13.38000000,33,1,13.37000000,100,1,13.28000000,11,2,13.26000000,4,2,13.25000000,111,2,13.23000000,2,1,13.20000000,30,2,13.15000000,2,1,13.14000000,100,1,13.12000000,4,2,13.40000000,208,12,13.67000000,100,1,13.71000000,1,1,13.78000000,2,1,13.82000000,10,1,13.83000000,100,1,13.84000000,100,1,13.93000000,102,2,13.94000000,110,2,13.98000000,50,5,ARL,283592997
805,2025-07-17T15:31:00.053107210Z,2025-07-17T15:31:00.052941898Z,160,2,1108,A,A,0,15.06000000,100,130,165312,238444735,13.38000000,33,1,13.37000000,100,1,13.28000000,11,2,13.26000000,4,2,13.25000000,111,2,13.23000000,2,1,13.20000000,30,2,13.15000000,2,1,13.14000000,100,1,13.12000000,4,2,13.40000000,208,12,13.67000000,100,1,13.71000000,1,1,13.78000000,2,1,13.82000000,10,1,13.83000000,100,1,13.84000000,100,1,13.93000000,102,2,13.94000000,110,2,13.98000000,50,5,ARL,283596673
806,2025-07-17T15:31:00.054830847Z,2025-07-17T15:31:00.054665340Z,160,2,1108,C,A,0,14.81000000,100,0,165507,238444759,13.38000000,33,1,13.37000000,100,1,13.28000000,11,2,13.26000000,4,2,13.25000000,111,2,13.23000000,2,1,13.20000000,30,2,13.15000000,2,1,13.14000000,100,1,13.12000000,4,2,13.40000000,208,12,13.67000000,100,1,13.71000000,1,1,13.78000000,2,1,13.82000000,10,1,13.83000000,100,1,13.84000000,100,1,13.93000000,102,2,13.94000000,110,2,13.98000000,50,5,ARL,282776089
807,2025-07-17T15:31:00.054830847Z,2025-07-17T15:31:00.054665340Z,160,2,1108,A,A,0,14.96000000,100,130,165507,238444759,13.38000000,33,1,13.37000000,100,1,13.28000000,11,2,13.26000000,4,2,13.25000000,111,2,13.23000000,2,1,13.20000000,30,2,13.15000000,2,1,13.14000000,100,1,13.12000000,4,2,13.40000000,208,12,13.67000000,100,1,13.71000000,1,1,13.78000000,2,1,13.82000000,10,1,13.83000000,100,1,13.84000000,100,1,13.93000000,102,2,13.94000000,110,2,13.98000000,50,5,ARL,283596721
808,2025-07-17T15:31:00.071409275Z,2025-07-17T15:31:00.071243665Z,160,2,1108,C,A,0,14.81000000,100,0,165610,238444961,13.38000000,33,1,13.37000000,100,1,13.28000000,11,2,13.26000000,4,2,13.25000000,111,2,13.23000000,2,1,13.20000000,30,2,13.15000000,2,1,13.14000000,100,1,13.12000000,4,2,13.40000000,208,12,13.67000000,100,1,13.71000000,1,1,13.78000000,2,1,13.82000000,10,1,13.83000000,100,1,13.84000000,100,1,13.93000000,102,2,13.94000000,110,2,13.98000000,50,5,ARL,282776029
809,2025-07-17T15:31:00.071409275Z,2025-07-17T15:31:00.071243665Z,160,2,1108,A,A,0,14.96000000,100,130,165610,238444961,13.38000000,33,1,13.37000000,100,1,13.28000000,11,2,13.26000000,4,2,13.25000000,111,2,13.23000000,2,1,13.20000000,30,2,13.15000000,2,1,13.14000000,100,1,13.12000000,4,2,13.40000000,208,12,13.67000000,100,1,13.71000000,1,1,13.78000000,2,1,13.82000000,10,1,13.83000000,100,1,13.84000000,100,1,13.93000000,102,2,13.94000000,110,2,13.98000000,50,5,ARL,283596945
810,2025-07-17T15:31:00.243369582Z,2025-07-17T15:31:00.243203860Z,160,2,1108,C,A,0,15.92000000,100,0,165722,238447595,13.38000000,33,1,13.37000000,100,1,13.28000000,11,2,13.26000000,4,2,13.25000000,111,2,13.23000000,2,1,13.20000000,30,2,13.15000000,2,1,13.14000000,100,1,13.12000000,4,2,13.40000000,208,12,13.67000000,100,1,13.71000000,1,1,13.78000000,2,1,13.82000000,10,1,13.83000000,100,1,13.84000000,100,1,13.93000000,102,2,13.94000000,110,2,13.98000000,50,5,ARL,282776033
811,2025-07-17T15:31:00.243369582Z,2025-07-17T15:31:00.243203860Z,160,2,1108,A,A,0,16.08000000,100,130,165722,238447595,13.38000000,33,1,13.37000000,100,1,13.28000000,11,2,13.26000000,4,2,13.25000000,111,2,13.23000000,2,1,13.20000000,30,2,13.15000000,2,1,13.14000000,100,1,13.12000000,4,2,13.40000000,208,12,13.67000000,100,1,13.71000000,1,1,13.78000000,2,1,13.82000000,10,1,13.83000000,100,1,13.84000000,100,1,13.93000000,102,2,13.94000000,110,2,13.98000000,50,5,ARL,283599609
812,2025-07-17T15:31:00.347828545Z,2025-07-17T15:31:00.347663441Z,160,2,1108,A,A,0,14.03000000,100,130,165104,238450791,13.38000000,33,1,13.37000000,100,1,13.28000000,11,2,13.26000000,4,2,13.25000000,111,2,13.23000000,2,1,13.20000000,30,2,13.15000000,2,1,13.14000000,100,1,13.12000000,4,2,13.40000000,208,12,13.67000000,100,1,13.71000000,1,1,13.78000000,2,1,13.82000000,10,1,13.83000000,100,1,13.84000000,100,1,13.93000000,102,2,13.94000000,110,2,13.98000000,50,5,ARL,283604173
813,2025-07-17T15:31:04.014590575Z,2025-07-17T15:31:04.014425425Z,160,2,1108,A,A,0,14.00000000,100,130,165150,238529875,13.38000000,33,1,13.37000000,100,1,13.28000000,11,2,13.26000000,4,2,13.25000000,111,2,13.23000000,2,1,13.20000000,30,2,13.15000000,2,1,13.14000000,100,1,13.12000000,4,2,13.40000000,208,12,13.67000000,100,1,13.71000000,1,1,13.78000000,2,1,13.82000000,10,1,13.83000000,100,1,13.84000000,100,1,13.93000000,102,2,13.94000000,110,2,13.98000000,50,5,ARL,283694233
814,2025-07-17T15:31:04.124577845Z,2025-07-17T15:31:04.124411850Z,160,2,1108,C,A,0,14.03000000,100,0,165995,238531822,13.38000000,33,1,13.37000000,100,1,13.28000000,11,2,13.26000000,4,2,13.25000000,111,2,13.23000000,2,1,13.20000000,30,2,13.15000000,2,1,13.14000000,100,1,13.12000000,4,2,13.40000000,208,12,13.67000000,100,1,13.71000000,1,1,13.78000000,2,1,13.82000000,10,1,13.83000000,100,1,13.84000000,100,1,13.93000000,102,2,13.94000000,110,2,13.98000000,50,5,ARL,283604173
815,2025-07-17T15:31:04.124577845Z,2025-07-17T15:31:04.124411850Z,160,2,1108,A,A,0,14.01000000,100,130,165995,238531822,13.38000000,33,1,13.37000000,100,1,13.28000000,11,2,13.26000000,4,2,13.25000000,111,2,13.23000000,2,1,13.20000000,30,2,13.15000000,2,1,13.14000000,100,1,13.12000000,4,2,13.40000000,208,12,13.67000000,100,1,13.71000000,1,1,13.78000000,2,1,13.82000000,10,1,13.83000000,100,1,13.84000000,100,1,13.93000000,102,2,13.94000000,110,2,13.98000000,50,5,ARL,283695933
816,2025-07-17T15:32:28.644506279Z,2025-07-17T15:32:28.644335983Z,160,2,1108,A,B,0,13.55000000,10,128,170296,239938946,13.55000000,10,1,13.38000000,33,1,13.37000000,100,1,13.28000000,11,2,13.26000000,4,2,13.25000000,111,2,13.23000000,2,1,13.20000000,30,2,13.15000000,2,1,13.14000000,100,1,13.40000000,208,12,13.67000000,100,1,13.71000000,1,1,13.78000000,2,1,13.82000000,10,1,13.83000000,100,1,13.84000000,100,1,13.93000000,102,2,13.94000000,110,2,13.98000000,50,5,ARL,285545121
817,2025-07-17T15:32:28.653238729Z,2025-07-17T15:32:28.653073176Z,160,2,1108,C,B,0,13.37000000,100,0,165553,239940048,13.55000000,10,1,13.38000000,33,1,13.37000000,100,1,13.28000000,11,2,13.26000000,4,2,13.25000000,111,2,13.23000000,2,1,13.20000000,30,2,13.15000000,2,1,13.14000000,100,1,13.40000000,208,12,13.67000000,100,1,13.71000000,1,1,13.78000000,2,1,13.82000000,10,1,13.83000000,100,1,13.84000000,100,1,13.93000000,102,2,13.94000000,110,2,13.98000000,50,5,ARL,215999737
818,2025-07-17T15:32:28.653238729Z,2025-07-17T15:32:28.653073176Z,160,2,1108,A,B,0,13.54000000,100,130,165553,239940048,13.55000000,10,1,13.54000000,100,1,13.38000000,33,1,13.37000000,100,1,13.28000000,11,2,13.26000000,4,2,13.25000000,111,2,13.23000000,2,1,13.20000000,30,2,13.15000000,2,1,13.40000000,208,12,13.67000000,100,1,13.71000000,1,1,13.78000000,2,1,13.82000000,10,1,13.83000000,100,1,13.84000000,100,1,13.93000000,102,2,13.94000000,110,2,13.98000000,50,5,ARL,285545885
819,2025-07-17T15:32:28.653978501Z,2025-07-17T15:32:28.653812889Z,160,2,1108,C,B,0,12.33000000,100,0,165612,239940096,13.55000000,10,1,13.54000000,100,1,13.38000000,33,1,13.37000000,100,1,13.28000000,11,2,13.26000000,4,2,13.25000000,111,2,13.23000000,2,1,13.20000000,30,2,13.15000000,2,1,13.40000000,208,12,13.67000000,100,1,13.71000000,1,1,13.78000000,2,1,13.82000000,10,1,13.83000000,100,1,13.84000000,100,1,13.93000000,102,2,13.94000000,110,2,13.98000000,50,5,ARL,215999753
820,2025-07-17T15:32:28.653978501Z,2025-07-17T15:32:28.653812889Z,160,2,1108,A,B,0,12.49000000,100,130,165612,239940096,13.55000000,10,1,13.54000000,100,1,13.38000000,33,1,13.37000000,100,1,13.28000000,11,2,13.26000000,4,2,13.25000000,111,2,13.23000000,2,1,13.20000000,30,2,13.15000000,2,1,13.40000000,208,12,13.67000000,100,1,13.71000000,1,1,13.78000000,2,1,13.82000000,10,1,13.83000000,100,1,13.84000000,100,1,13.93000000,102,2,13.94000000,110,2,13.98000000,50,5,ARL,285545945
821,2025-07-17T15:32:28.653980648Z,2025-07-17T15:32:28.653815154Z,160,2,1108,C,B,0,12.67000000,100,130,165494,239940097,13.55000000,10,1,13.54000000,100,1,13.38000000,33,1,13.37000000,100,1,13.28000000,11,2,13.26000000,4,2,13.25000000,111,2,13.23000000,2,1,13.20000000,30,2,13.15000000,2,1,13.40000000,208,12,13.67000000,100,1,13.71000000,1,1,13.78000000,2,1,13.82000000,10,1,13.83000000,100,1,13.84000000,100,1,13.93000000,102,2,13.94000000,110,2,13.98000000,50,5,ARL,43663229
822,2025-07-17T15:32:28.654336987Z,2025-07-17T15:32:28.654171723Z,160,2,1108,A,B,0,12.94000000,100,130,165264,239940109,13.55000000,10,1,13.54000000,100,1,13.38000000,33,1,13.37000000,100,1,13.28000000,11,2,13.26000000,4,2,13.25000000,111,2,13.23000000,2,1,13.20000000,30,2,13.15000000,2,1,13.40000000,208,12,13.67000000,100,1,13.71000000,1,1,13.78000000,2,1,13.82000000,10,1,13.83000000,100,1,13.84000000,100,1,13.93000000,102,2,13.94000000,110,2,13.98000000,50,5,ARL,285545953
823,2025-07-17T15:32:28.657073743Z,2025-07-17T15:32:28.656908386Z,160,2,1108,C,B,0,12.47000000,100,130,165357,239940358,13.55000000,10,1,13.54000000,100,1,13.38000000,33,1,13.37000000,100,1,13.28000000,11,2,13.26000000,4,2,13.25000000,111,2,13.23000000,2,1,13.20000000,30,2,13.15000000,2,1,13.40000000,208,12,13.67000000,100,1,13.71000000,1,1,13.78000000,2,1,13.82000000,10,1,13.83000000,100,1,13.84000000,100,1,13.93000000,102,2,13.94000000,110,2,13.98000000,50,5,ARL,43554133
824,2025-07-17T15:32:28.657173856Z,2025-07-17T15:32:28.657008222Z,160,2,1108,A,B,0,12.73000000,100,130,165634,239940359,13.55000000,10,1,13.54000000,100,1,13.38000000,33,1,13.37000000,100,1,13.28000000,11,2,13.26000000,4,2,13.25000000,111,2,13.23000000,2,1,13.20000000,30,2,13.15000000,2,1,13.40000000,208,12,13.67000000,100,1,13.71000000,1,1,13.78000000,2,1,13.82000000,10,1,13.83000000,100,1,13.84000000,100,1,13.93000000,102,2,13.94000000,110,2,13.98000000,50,5,ARL,285546061
825,2025-07-17T15:32:28.667074437Z,2025-07-17T15:32:28.666909194Z,160,2,1108,C,B,0,13.10000000,100,130,165243,239940810,13.55000000,10,1,13.54000000,100,1,13.38000000,33,1,13.37000000,100,1,13.28000000,11,2,13.26000000,4,2,13.25000000,111,2,13.23000000,2,1,13.20000000,30,2,13.15000000,2,1,13.40000000,208,12,13.67000000,100,1,13.71000000,1,1,13.78000000,2,1,13.82000000,10,1,13.83000000,100,1,13.84000000,100,1,13.93000000,102,2,13.94000000,110,2,13.98000000,50,5,ARL,216001413
826,2025-07-17T15:32:28.667126637Z,2025-07-17T15:32:28.666961018Z,160,2,1108,A,B,0,13.27000000,100,130,165619,239940813,13.55000000,10,1,13.54000000,100,1,13.38000000,33,1,13.37000000,100,1,13.28000000,11,2,13.27000000,100,1,13.26000000,4,2,13.25000000,111,2,13.23000000,2,1,13.20000000,30,2,13.40000000,208,12,13.67000000,100,1,13.71000000,1,1,13.78000000,2,1,13.82000000,10,1,13.83000000,100,1,13.84000000,100,1,13.93000000,102,2,13.94000000,110,2,13.98000000,50,5,ARL,285546673
827,2025-07-17T15:32:28.674444711Z,2025-07-17T15:32:28.674279259Z,160,2,1108,C,B,0,12.33000000,100,0,165452,239941057,13.55000000,10,1,13.54000000,100,1,13.38000000,33,1,13.37000000,100,1,13.28000000,11,2,13.27000000,100,1,13.26000000,4,2,13.25000000,111,2,13.23000000,2,1,13.20000000,30,2,13.40000000,208,12,13.67000000,100,1,13.71000000,1,1,13.78000000,2,1,13.82000000,10,1,13.83000000,100,1,13.84000000,100,1,13.93000000,102,2,13.94000000,110,2,13.98000000,50,5,ARL,43755813
828,2025-07-17T15:32:28.674444711Z,2025-07-17T15:32:28.674279259Z,160,2,1108,A,B,0,12.59000000,100,130,165452,239941057,13.55000000,10,1,13.54000000,100,1,13.38000000,33,1,13.37000000,100,1,13.28000000,11,2,13.27000000,100,1,13.26000000,4,2,13.25000000,111,2,13.23000000,2,1,13.20000000,30,2,13.40000000,208,12,13.67000000,100,1,13.71000000,1,1,13.78000000,2,1,13.82000000,10,1,13.83000000,100,1,13.84000000,100,1,13.93000000,102,2,13.94000000,110,2,13.98000000,50,5,ARL,285546893
829,2025-07-17T15:32:28.691264796Z,2025-07-17T15:32:28.691099298Z,160,2,1108,C,B,0,9.67000000,100,0,165498,239941825,13.55000000,10,1,13.54000000,100,1,13.38000000,33,1,13.37000000,100,1,13.28000000,11,2,13.27000000,100,1,13.26000000,4,2,13.25000000,111,2,13.23000000,2,1,13.20000000,30,2,13.40000000,208,12,13.67000000,100,1,13.71000000,1,1,13.78000000,2,1,13.82000000,10,1,13.83000000,100,1,13.84000000,100,1,13.93000000,102,2,13.94000000,110,2,13.98000000,50,5,ARL,44082961
830,2025-07-17T15:32:28.691264796Z,2025-07-17T15:32:28.691099298Z,160,2,1108,A,B,0,9.88000000,100,130,165498,239941825,13.55000000,10,1,13.54000000,100,1,13.38000000,33,1,13.37000000,100,1,13.28000000,11,2,13.27000000,100,1,13.26000000,4,2,13.25000000,111,2,13.23000000,2,1,13.20000000,30,2,13.40000000,208,12,13.67000000,100,1,13.71000000,1,1,13.78000000,2,1,13.82000000,10,1,13.83000000,100,1,13.84000000,100,1,13.93000000,102,2,13.94000000,110,2,13.98000000,50,5,ARL,285548137
831,2025-07-17T15:32:28.711494526Z,2025-07-17T15:32:28.711329066Z,160,2,1108,C,B,0,11.27000000,100,0,165460,239942732,13.55000000,10,1,13.54000000,100,1,13.38000000,33,1,13.37000000,100,1,13.28000000,11,2,13.27000000,100,1,13.26000000,4,2,13.25000000,111,2,13.23000000,2,1,13.20000000,30,2,13.40000000,208,12,13.67000000,100,1,13.71000000,1,1,13.78000000,2,1,13.82000000,10,1,13.83000000,100,1,13.84000000,100,1,13.93000000,102,2,13.94000000,110,2,13.98000000,50,5,ARL,43826785
832,2025-07-17T15:32:28.711494526Z,2025-07-17T15:32:28.711329066Z,160,2,1108,A,B,0,11.50000000,100,130,165460,239942732,13.55000000,10,1,13.54000000,100,1,13.38000000,33,1,13.37000000,100,1,13.28000000,11,2,13.27000000,100,1,13.26000000,4,2,13.25000000,111,2,13.23000000,2,1,13.20000000,30,2,13.40000000,208,12,13.67000000,100,1,13.71000000,1,1,13.78000000,2,1,13.82000000,10,1,13.83000000,100,1,13.84000000,100,1,13.93000000,102,2,13.94000000,110,2,13.98000000,50,5,ARL,285549537
833,2025-07-17T15:32:28.771995987Z,2025-07-17T15:32:28.771830554Z,160,2,1108,C,B,0,13.55000000,10,128,165433,239945992,13.55000000,10,1,13.54000000,100,1,13.38000000,33,1,13.37000000,100,1,13.28000000,11,2,13.27000000,100,1,13.26000000,4,2,13.25000000,111,2,13.23000000,2,1,13.20000000,30,2,13.40000000,208,12,13.67000000,100,1,13.71000000,1,1,13.78000000,2,1,13.82000000,10,1,13.83000000,100,1,13.84000000,100,1,13.93000000,102,2,13.94000000,110,2,13.98000000,50,5,ARL,285545121
834,2025-07-17T15:32:28.806930722Z,2025-07-17T15:32:28.806765209Z,160,2,1108,C,B,0,12.33000000,100,0,165513,239948319,13.55000000,10,1,13.54000000,100,1,13.38000000,33,1,13.37000000,100,1,13.28000000,11,2,13.27000000,100,1,13.26000000,4,2,13.25000000,111,2,13.23000000,2,1,13.20000000,30,2,13.40000000,208,12,13.67000000,100,1,13.71000000,1,1,13.78000000,2,1,13.82000000,10,1,13.83000000,100,1,13.84000000,100,1,13.93000000,102,2,13.94000000,110,2,13.98000000,50,5,ARL,44088633
