,ts_recv,ts_event,rtype,publisher_id,instrument_id,action,side,depth,price,size,flags,ts_in_delta,sequence,bid_px_00,bid_sz_00,bid_ct_00,ask_px_00,ask_sz_00,ask_ct_00,bid_px_01,bid_sz_01,bid_ct_01,ask_px_01,ask_sz_01,ask_ct_01,bid_px_02,bid_sz_02,bid_ct_02,ask_px_02,ask_sz_02,ask_ct_02,bid_px_03,bid_sz_03,bid_ct_03,ask_px_03,ask_sz_03,ask_ct_03,bid_px_04,bid_sz_04,bid_ct_04,ask_px_04,ask_sz_04,ask_ct_04,bid_px_05,bid_sz_05,bid_ct_05,ask_px_05,ask_sz_05,ask_ct_05,bid_px_06,bid_sz_06,bid_ct_06,ask_px_06,ask_sz_06,ask_ct_06,bid_px_07,bid_sz_07,bid_ct_07,ask_px_07,ask_sz_07,ask_ct_07,bid_px_08,bid_sz_08,bid_ct_08,ask_px_08,ask_sz_08,ask_ct_08,bid_px_09,bid_sz_09,bid_ct_09,ask_px_09,ask_sz_09,ask_ct_09,symbol,order_id
835,2025-07-17T15:32:28.806930722Z,2025-07-17T15:32:28.806765209Z,160,2,1108,A,B,0,12.59000000,100,130,165513,239948319,13.55000000,10,1,13.54000000,100,1,13.38000000,33,1,13.37000000,100,1,13.28000000,11,2,13.27000000,100,1,13.26000000,4,2,13.25000000,111,2,13.23000000,2,1,13.20000000,30,2,13.40000000,208,12,13.67000000,100,1,13.71000000,1,1,13.78000000,2,1,13.82000000,10,1,13.83000000,100,1,13.84000000,100,1,13.93000000,102,2,13.94000000,110,2,13.98000000,50,5,ARL,285553901
836,2025-07-17T15:32:28.850288215Z,2025-07-17T15:32:28.850122877Z,160,2,1108,A,A,0,13.98000000,100,130,165338,239950805,13.55000000,10,1,13.54000000,100,1,13.38000000,33,1,13.37000000,100,1,13.28000000,11,2,13.27000000,100,1,13.26000000,4,2,13.25000000,111,2,13.23000000,2,1,13.20000000,30,2,13.40000000,208,12,13.67000000,100,1,13.71000000,1,1,13.78000000,2,1,13.82000000,10,1,13.83000000,100,1,13.84000000,100,1,13.93000000,102,2,13.94000000,110,2,13.98000000,150,6,ARL,285556869
837,2025-07-17T15:32:28.857140107Z,2025-07-17T15:32:28.856973845Z,160,2,1108,C,A,0,14.00000000,100,130,166262,239951361,13.55000000,10,1,13.54000000,100,1,13.38000000,33,1,13.37000000,100,1,13.28000000,11,2,13.27000000,100,1,13.26000000,4,2,13.25000000,111,2,13.23000000,2,1,13.20000000,30,2,13.40000000,208,12,13.67000000,100,1,13.71000000,1,1,13.78000000,2,1,13.82000000,10,1,13.83000000,100,1,13.84000000,100,1,13.93000000,102,2,13.94000000,110,2,13.98000000,150,6,ARL,283694233
838,2025-07-17T15:32:29.573634202Z,2025-07-17T15:32:29.573469021Z,160,2,1108,C,B,0,13.54000000,100,130,165181,239975997,13.55000000,10,1,13.54000000,100,1,13.38000000,33,1,13.37000000,100,1,13.28000000,11,2,13.27000000,100,1,13.26000000,4,2,13.25000000,111,2,13.23000000,2,1,13.20000000,30,2,13.40000000,208,12,13.67000000,100,1,13.71000000,1,1,13.78000000,2,1,13.82000000,10,1,13.83000000,100,1,13.84000000,100,1,13.93000000,102,2,13.94000000,110,2,13.98000000,150,6,ARL,285545885
839,2025-07-17T15:32:29.574368326Z,2025-07-17T15:32:29.574202467Z,160,2,1108,C,B,0,12.49000000,100,0,165859,239976004,13.55000000,10,1,13.54000000,100,1,13.38000000,33,1,13.37000000,100,1,13.28000000,11,2,13.27000000,100,1,13.26000000,4,2,13.25000000,111,2,13.23000000,2,1,13.20000000,30,2,13.40000000,208,12,13.67000000,100,1,13.71000000,1,1,13.78000000,2,1,13.82000000,10,1,13.83000000,100,1,13.84000000,100,1,13.93000000,102,2,13.94000000,110,2,13.98000000,150,6,ARL,285545945
840,2025-07-17T15:32:29.574368326Z,2025-07-17T15:32:29.574202467Z,160,2,1108,A,B,0,12.27000000,100,130,165859,239976004,13.55000000,10,1,13.54000000,100,1,13.38000000,33,1,13.37000000,100,1,13.28000000,11,2,13.27000000,100,1,13.26000000,4,2,13.25000000,111,2,13.23000000,2,1,13.20000000,30,2,13.40000000,208,12,13.67000000,100,1,13.71000000,1,1,13.78000000,2,1,13.82000000,10,1,13.83000000,100,1,13.84000000,100,1,13.93000000,102,2,13.94000000,110,2,13.98000000,150,6,ARL,285586089
841,2025-07-17T15:32:29.574371866Z,2025-07-17T15:32:29.574206685Z,160,2,1108,C,B,0,12.94000000,100,130,165181,239976005,13.55000000,10,1,13.54000000,100,1,13.38000000,33,1,13.37000000,100,1,13.28000000,11,2,13.27000000,100,1,13.26000000,4,2,13.25000000,111,2,13.23000000,2,1,13.20000000,30,2,13.40000000,208,12,13.67000000,100,1,13.71000000,1,1,13.78000000,2,1,13.82000000,10,1,13.83000000,100,1,13.84000000,100,1,13.93000000,102,2,13.94000000,110,2,13.98000000,150,6,ARL,285545953
842,2025-07-17T15:32:29.574722141Z,2025-07-17T15:32:29.574556760Z,160,2,1108,A,B,0,12.71000000,100,130,165381,239976069,13.55000000,10,1,13.54000000,100,1,13.38000000,33,1,13.37000000,100,1,13.28000000,11,2,13.27000000,100,1,13.26000000,4,2,13.25000000,111,2,13.23000000,2,1,13.20000000,30,2,13.40000000,208,12,13.67000000,100,1,13.71000000,1,1,13.78000000,2,1,13.82000000,10,1,13.83000000,100,1,13.84000000,100,1,13.93000000,102,2,13.94000000,110,2,13.98000000,150,6,ARL,285586093
843,2025-07-17T15:32:29.575134655Z,2025-07-17T15:32:29.574968914Z,160,2,1108,C,B,0,12.59000000,100,0,165741,239976143,13.55000000,10,1,13.54000000,100,1,13.38000000,33,1,13.37000000,100,1,13.28000000,11,2,13.27000000,100,1,13.26000000,4,2,13.25000000,111,2,13.23000000,2,1,13.20000000,30,2,13.40000000,208,12,13.67000000,100,1,13.71000000,1,1,13.78000000,2,1,13.82000000,10,1,13.83000000,100,1,13.84000000,100,1,13.93000000,102,2,13.94000000,110,2,13.98000000,150,6,ARL,285546893
844,2025-07-17T15:32:29.575134655Z,2025-07-17T15:32:29.574968914Z,160,2,1108,A,B,0,12.34000000,100,130,165741,239976143,13.55000000,10,1,13.54000000,100,1,13.38000000,33,1,13.37000000,100,1,13.28000000,11,2,13.27000000,100,1,13.26000000,4,2,13.25000000,111,2,13.23000000,2,1,13.20000000,30,2,13.40000000,208,12,13.67000000,100,1,13.71000000,1,1,13.78000000,2,1,13.82000000,10,1,13.83000000,100,1,13.84000000,100,1,13.93000000,102,2,13.94000000,110,2,13.98000000,150,6,ARL,285586113
845,2025-07-17T15:32:29.575550333Z,2025-07-17T15:32:29.575384940Z,160,2,1108,C,B,0,11.50000000,100,0,165393,239976173,13.55000000,10,1,13.54000000,100,1,13.38000000,33,1,13.37000000,100,1,13.28000000,11,2,13.27000000,100,1,13.26000000,4,2,13.25000000,111,2,13.23000000,2,1,13.20000000,30,2,13.40000000,208,12,13.67000000,100,1,13.71000000,1,1,13.78000000,2,1,13.82000000,10,1,13.83000000,100,1,13.84000000,100,1,13.93000000,102,2,13.94000000,110,2,13.98000000,150,6,ARL,285549537
846,2025-07-17T15:32:29.575550333Z,2025-07-17T15:32:29.575384940Z,160,2,1108,A,B,0,11.27000000,100,130,165393,239976173,13.55000000,10,1,13.54000000,100,1,13.38000000,33,1,13.37000000,100,1,13.28000000,11,2,13.27000000,100,1,13.26000000,4,2,13.25000000,111,2,13.23000000,2,1,13.20000000,30,2,13.40000000,208,12,13.67000000,100,1,13.71000000,1,1,13.78000000,2,1,13.82000000,10,1,13.83000000,100,1,13.84000000,100,1,13.93000000,102,2,13.94000000,110,2,13.98000000,150,6,ARL,285586145
847,2025-07-17T15:32:29.575821091Z,2025-07-17T15:32:29.575655631Z,160,2,1108,C,B,0,9.88000000,100,0,165460,239976183,13.55000000,10,1,13.54000000,100,1,13.38000000,33,1,13.37000000,100,1,13.28000000,11,2,13.27000000,100,1,13.26000000,4,2,13.25000000,111,2,13.23000000,2,1,13.20000000,30,2,13.40000000,208,12,13.67000000,100,1,13.71000000,1,1,13.78000000,2,1,13.82000000,10,1,13.83000000,100,1,13.84000000,100,1,13.93000000,102,2,13.94000000,110,2,13.98000000,150,6,ARL,285548137
848,2025-07-17T15:32:29.575821091Z,2025-07-17T15:32:29.575655631Z,160,2,1108,A,B,0,9.68000000,100,130,165460,239976183,13.55000000,10,1,13.54000000,100,1,13.38000000,33,1,13.37000000,100,1,13.28000000,11,2,13.27000000,100,1,13.26000000,4,2,13.25000000,111,2,13.23000000,2,1,13.20000000,30,2,13.40000000,208,12,13.67000000,100,1,13.71000000,1,1,13.78000000,2,1,13.82000000,10,1,13.83000000,100,1,13.84000000,100,1,13.93000000,102,2,13.94000000,110,2,13.98000000,150,6,ARL,285586157
849,2025-07-17T15:32:29.578317238Z,2025-07-17T15:32:29.578151593Z,160,2,1108,C,B,0,12.59000000,100,0,165645,239976225,13.55000000,10,1,13.54000000,100,1,13.38000000,33,1,13.37000000,100,1,13.28000000,11,2,13.27000000,100,1,13.26000000,4,2,13.25000000,111,2,13.23000000,2,1,13.20000000,30,2,13.40000000,208,12,13.67000000,100,1,13.71000000,1,1,13.78000000,2,1,13.82000000,10,1,13.83000000,100,1,13.84000000,100,1,13.93000000,102,2,13.94000000,110,2,13.98000000,150,6,ARL,285553901
850,2025-07-17T15:32:29.578317238Z,2025-07-17T15:32:29.578151593Z,160,2,1108,A,B,0,12.34000000,100,130,165645,239976225,13.55000000,10,1,13.54000000,100,1,13.38000000,33,1,13.37000000,100,1,13.28000000,11,2,13.27000000,100,1,13.26000000,4,2,13.25000000,111,2,13.23000000,2,1,13.20000000,30,2,13.40000000,208,12,13.67000000,100,1,13.71000000,1,1,13.78000000,2,1,13.82000000,10,1,13.83000000,100,1,13.84000000,100,1,13.93000000,102,2,13.94000000,110,2,13.98000000,150,6,ARL,285586189
851,2025-07-17T15:32:29.580933155Z,2025-07-17T15:32:29.580767960Z,160,2,1108,A,B,0,13.26000000,100,130,165195,239976262,13.55000000,10,1,13.54000000,100,1,13.38000000,33,1,13.37000000,100,1,13.28000000,11,2,13.27000000,100,1,13.26000000,104,3,13.25000000,111,2,13.23000000,2,1,13.20000000,30,2,13.40000000,208,12,13.67000000,100,1,13.71000000,1,1,13.78000000,2,1,13.82000000,10,1,13.83000000,100,1,13.84000000,100,1,13.93000000,102,2,13.94000000,110,2,13.98000000,150,6,ARL,285586221
852,2025-07-17T15:32:29.580952045Z,2025-07-17T15:32:29.580786478Z,160,2,1108,C,A,0,14.01000000,100,0,165567,239976263,13.55000000,10,1,13.54000000,100,1,13.38000000,33,1,13.37000000,100,1,13.28000000,11,2,13.27000000,100,1,13.26000000,104,3,13.25000000,111,2,13.23000000,2,1,13.20000000,30,2,13.40000000,208,12,13.67000000,100,1,13.71000000,1,1,13.78000000,2,1,13.82000000,10,1,13.83000000,100,1,13.84000000,100,1,13.93000000,102,2,13.94000000,110,2,13.98000000,150,6,ARL,283695933
853,2025-07-17T15:32:29.580952045Z,2025-07-17T15:32:29.580786478Z,160,2,1108,A,A,0,13.99000000,100,130,165567,239976263,13.55000000,10,1,13.54000000,100,1,13.38000000,33,1,13.37000000,100,1,13.28000000,11,2,13.27000000,100,1,13.26000000,104,3,13.25000000,111,2,13.23000000,2,1,13.20000000,30,2,13.40000000,208,12,13.67000000,100,1,13.71000000,1,1,13.78000000,2,1,13.82000000,10,1,13.83000000,100,1,13.84000000,100,1,13.93000000,102,2,13.94000000,110,2,13.98000000,150,6,ARL,285586225
854,2025-07-17T15:32:29.587192852Z,2025-07-17T15:32:29.587027681Z,160,2,1108,C,B,0,13.27000000,100,130,165171,239976327,13.55000000,10,1,13.54000000,100,1,13.38000000,33,1,13.37000000,100,1,13.28000000,11,2,13.27000000,100,1,13.26000000,104,3,13.25000000,111,2,13.23000000,2,1,13.20000000,30,2,13.40000000,208,12,13.67000000,100,1,13.71000000,1,1,13.78000000,2,1,13.82000000,10,1,13.83000000,100,1,13.84000000,100,1,13.93000000,102,2,13.94000000,110,2,13.98000000,150,6,ARL,285546673
855,2025-07-17T15:32:29.587246470Z,2025-07-17T15:32:29.587081086Z,160,2,1108,A,B,0,13.03000000,100,130,165384,239976336,13.55000000,10,1,13.54000000,100,1,13.38000000,33,1,13.37000000,100,1,13.28000000,11,2,13.27000000,100,1,13.26000000,104,3,13.25000000,111,2,13.23000000,2,1,13.20000000,30,2,13.40000000,208,12,13.67000000,100,1,13.71000000,1,1,13.78000000,2,1,13.82000000,10,1,13.83000000,100,1,13.84000000,100,1,13.93000000,102,2,13.94000000,110,2,13.98000000,150,6,ARL,285586293
856,2025-07-17T15:32:29.659679280Z,2025-07-17T15:32:29.659513918Z,160,2,1108,C,B,0,12.73000000,100,0,165362,239977574,13.55000000,10,1,13.54000000,100,1,13.38000000,33,1,13.37000000,100,1,13.28000000,11,2,13.27000000,100,1,13.26000000,104,3,13.25000000,111,2,13.23000000,2,1,13.20000000,30,2,13.40000000,208,12,13.67000000,100,1,13.71000000,1,1,13.78000000,2,1,13.82000000,10,1,13.83000000,100,1,13.84000000,100,1,13.93000000,102,2,13.94000000,110,2,13.98000000,150,6,ARL,285546061
857,2025-07-17T15:32:29.659679280Z,2025-07-17T15:32:29.659513918Z,160,2,1108,A,B,0,12.46000000,100,130,165362,239977574,13.55000000,10,1,13.54000000,100,1,13.38000000,33,1,13.37000000,100,1,13.28000000,11,2,13.27000000,100,1,13.26000000,104,3,13.25000000,111,2,13.23000000,2,1,13.20000000,30,2,13.40000000,208,12,13.67000000,100,1,13.71000000,1,1,13.78000000,2,1,13.82000000,10,1,13.83000000,100,1,13.84000000,100,1,13.93000000,102,2,13.94000000,110,2,13.98000000,150,6,ARL,285587281
858,2025-07-17T15:33:04.248156868Z,2025-07-17T15:33:04.247990788Z,160,2,1108,C,A,0,14.97000000,100,0,166080,240885845,13.55000000,10,1,13.54000000,100,1,13.38000000,33,1,13.37000000,100,1,13.28000000,11,2,13.27000000,100,1,13.26000000,104,3,13.25000000,111,2,13.23000000,2,1,13.20000000,30,2,13.40000000,208,12,13.67000000,100,1,13.71000000,1,1,13.78000000,2,1,13.82000000,10,1,13.83000000,100,1,13.84000000,100,1,13.93000000,102,2,13.94000000,110,2,13.98000000,150,6,ARL,283592993
859,2025-07-17T15:33:04.248156868Z,2025-07-17T15:33:04.247990788Z,160,2,1108,A,A,0,14.72000000,100,130,166080,240885845,13.55000000,10,1,13.54000000,100,1,13.38000000,33,1,13.37000000,100,1,13.28000000,11,2,13.27000000,100,1,13.26000000,104,3,13.25000000,111,2,13.23000000,2,1,13.20000000,30,2,13.40000000,208,12,13.67000000,100,1,13.71000000,1,1,13.78000000,2,1,13.82000000,10,1,13.83000000,100,1,13.84000000,100,1,13.93000000,102,2,13.94000000,110,2,13.98000000,150,6,ARL,286680573
860,2025-07-17T15:33:04.248189408Z,2025-07-17T15:33:04.248023883Z,160,2,1108,C,A,0,14.97000000,100,0,165525,240885847,13.55000000,10,1,13.54000000,100,1,13.38000000,33,1,13.37000000,100,1,13.28000000,11,2,13.27000000,100,1,13.26000000,104,3,13.25000000,111,2,13.23000000,2,1,13.20000000,30,2,13.40000000,208,12,13.67000000,100,1,13.71000000,1,1,13.78000000,2,1,13.82000000,10,1,13.83000000,100,1,13.84000000,100,1,13.93000000,102,2,13.94000000,110,2,13.98000000,150,6,ARL,283593041
861,2025-07-17T15:33:04.248189408Z,2025-07-17T15:33:04.248023883Z,160,2,1108,A,A,0,14.72000000,100,130,165525,240885847,13.55000000,10,1,13.54000000,100,1,13.38000000,33,1,13.37000000,100,1,13.28000000,11,2,13.27000000,100,1,13.26000000,104,3,13.25000000,111,2,13.23000000,2,1,13.20000000,30,2,13.40000000,208,12,13.67000000,100,1,13.71000000,1,1,13.78000000,2,1,13.82000000,10,1,13.83000000,100,1,13.84000000,100,1,13.93000000,102,2,13.94000000,110,2,13.98000000,150,6,ARL,286680577
862,2025-07-17T15:33:04.255712050Z,2025-07-17T15:33:04.255546094Z,160,2,1108,A,A,0,13.84000000,100,130,165956,240886132,13.55000000,10,1,13.54000000,100,1,13.38000000,33,1,13.37000000,100,1,13.28000000,11,2,13.27000000,100,1,13.26000000,104,3,13.25000000,111,2,13.23000000,2,1,13.20000000,30,2,13.40000000,208,12,13.67000000,100,1,13.71000000,1,1,13.78000000,2,1,13.82000000,10,1,13.83000000,100,1,13.84000000,200,2,13.93000000,102,2,13.94000000,110,2,13.98000000,150,6,ARL,286680685
863,2025-07-17T15:33:04.255777981Z,2025-07-17T15:33:04.255612126Z,160,2,1108,C,B,0,12.27000000,100,0,165855,240886133,13.55000000,10,1,13.54000000,100,1,13.38000000,33,1,13.37000000,100,1,13.28000000,11,2,13.27000000,100,1,13.26000000,104,3,13.25000000,111,2,13.23000000,2,1,13.20000000,30,2,13.40000000,208,12,13.67000000,100,1,13.71000000,1,1,13.78000000,2,1,13.82000000,10,1,13.83000000,100,1,13.84000000,200,2,13.93000000,102,2,13.94000000,110,2,13.98000000,150,6,ARL,285586089
864,2025-07-17T15:33:04.255777981Z,2025-07-17T15:33:04.255612126Z,160,2,1108,A,B,0,12.23000000,100,130,165855,240886133,13.55000000,10,1,13.54000000,100,1,13.38000000,33,1,13.37000000,100,1,13.28000000,11,2,13.27000000,100,1,13.26000000,104,3,13.25000000,111,2,13.23000000,2,1,13.20000000,30,2,13.40000000,208,12,13.67000000,100,1,13.71000000,1,1,13.78000000,2,1,13.82000000,10,1,13.83000000,100,1,13.84000000,200,2,13.93000000,102,2,13.94000000,110,2,13.98000000,150,6,ARL,286680693
865,2025-07-17T15:33:04.256438228Z,2025-07-17T15:33:04.256272676Z,160,2,1108,C,A,0,15.06000000,100,0,165552,240886147,13.55000000,10,1,13.54000000,100,1,13.38000000,33,1,13.37000000,100,1,13.28000000,11,2,13.27000000,100,1,13.26000000,104,3,13.25000000,111,2,13.23000000,2,1,13.20000000,30,2,13.40000000,208,12,13.67000000,100,1,13.71000000,1,1,13.78000000,2,1,13.82000000,10,1,13.83000000,100,1,13.84000000,200,2,13.93000000,102,2,13.94000000,110,2,13.98000000,150,6,ARL,283596673
866,2025-07-17T15:33:04.256438228Z,2025-07-17T15:33:04.256272676Z,160,2,1108,A,A,0,14.91000000,100,130,165552,240886147,13.55000000,10,1,13.54000000,100,1,13.38000000,33,1,13.37000000,100,1,13.28000000,11,2,13.27000000,100,1,13.26000000,104,3,13.25000000,111,2,13.23000000,2,1,13.20000000,30,2,13.40000000,208,12,13.67000000,100,1,13.71000000,1,1,13.78000000,2,1,13.82000000,10,1,13.83000000,100,1,13.84000000,200,2,13.93000000,102,2,13.94000000,110,2,13.98000000,150,6,ARL,286680721
867,2025-07-17T15:33:04.258080504Z,2025-07-17T15:33:04.257914956Z,160,2,1108,C,A,0,14.96000000,100,0,165548,240886188,13.55000000,10,1,13.54000000,100,1,13.38000000,33,1,13.37000000,100,1,13.28000000,11,2,13.27000000,100,1,13.26000000,104,3,13.25000000,111,2,13.23000000,2,1,13.20000000,30,2,13.40000000,208,12,13.67000000,100,1,13.71000000,1,1,13.78000000,2,1,13.82000000,10,1,13.83000000,100,1,13.84000000,200,2,13.93000000,102,2,13.94000000,110,2,13.98000000,150,6,ARL,283596945
868,2025-07-17T15:33:04.258080504Z,2025-07-17T15:33:04.257914956Z,160,2,1108,A,A,0,14.81000000,100,130,165548,240886188,13.55000000,10,1,13.54000000,100,1,13.38000000,33,1,13.37000000,100,1,13.28000000,11,2,13.27000000,100,1,13.26000000,104,3,13.25000000,111,2,13.23000000,2,1,13.20000000,30,2,13.40000000,208,12,13.67000000,100,1,13.71000000,1,1,13.78000000,2,1,13.82000000,10,1,13.83000000,100,1,13.84000000,200,2,13.93000000,102,2,13.94000000,110,2,13.98000000,150,6,ARL,286680741
869,2025-07-17T15:33:04.261684319Z,2025-07-17T15:33:04.261518776Z,160,2,1108,C,A,0,14.79000000,100,0,165543,240886271,13.55000000,10,1,13.54000000,100,1,13.38000000,33,1,13.37000000,100,1,13.28000000,11,2,13.27000000,100,1,13.26000000,104,3,13.25000000,111,2,13.23000000,2,1,13.20000000,30,2,13.40000000,208,12,13.67000000,100,1,13.71000000,1,1,13.78000000,2,1,13.82000000,10,1,13.83000000,100,1,13.84000000,200,2,13.93000000,102,2,13.94000000,110,2,13.98000000,150,6,ARL,283593313
870,2025-07-17T15:33:04.261684319Z,2025-07-17T15:33:04.261518776Z,160,2,1108,A,A,0,14.65000000,100,130,165543,240886271,13.55000000,10,1,13.54000000,100,1,13.38000000,33,1,13.37000000,100,1,13.28000000,11,2,13.27000000,100,1,13.26000000,104,3,13.25000000,111,2,13.23000000,2,1,13.20000000,30,2,13.40000000,208,12,13.67000000,100,1,13.71000000,1,1,13.78000000,2,1,13.82000000,10,1,13.83000000,100,1,13.84000000,200,2,13.93000000,102,2,13.94000000,110,2,13.98000000,150,6,ARL,286680905
871,2025-07-17T15:33:04.263011314Z,2025-07-17T15:33:04.262845834Z,160,2,1108,C,A,0,14.26000000,100,130,165480,240886294,13.55000000,10,1,13.54000000,100,1,13.38000000,33,1,13.37000000,100,1,13.28000000,11,2,13.27000000,100,1,13.26000000,104,3,13.25000000,111,2,13.23000000,2,1,13.20000000,30,2,13.40000000,208,12,13.67000000,100,1,13.71000000,1,1,13.78000000,2,1,13.82000000,10,1,13.83000000,100,1,13.84000000,200,2,13.93000000,102,2,13.94000000,110,2,13.98000000,150,6,ARL,283595181
872,2025-07-17T15:33:04.263052660Z,2025-07-17T15:33:04.262887184Z,160,2,1108,C,A,0,13.98000000,100,130,165476,240886296,13.55000000,10,1,13.54000000,100,1,13.38000000,33,1,13.37000000,100,1,13.28000000,11,2,13.27000000,100,1,13.26000000,104,3,13.25000000,111,2,13.23000000,2,1,13.20000000,30,2,13.40000000,208,12,13.67000000,100,1,13.71000000,1,1,13.78000000,2,1,13.82000000,10,1,13.83000000,100,1,13.84000000,200,2,13.93000000,102,2,13.94000000,110,2,13.98000000,150,6,ARL,285556869
873,2025-07-17T15:33:04.263065252Z,2025-07-17T15:33:04.262899981Z,160,2,1108,A,A,0,14.12000000,100,130,165271,240886297,13.55000000,10,1,13.54000000,100,1,13.38000000,33,1,13.37000000,100,1,13.28000000,11,2,13.27000000,100,1,13.26000000,104,3,13.25000000,111,2,13.23000000,2,1,13.20000000,30,2,13.40000000,208,12,13.67000000,100,1,13.71000000,1,1,13.78000000,2,1,13.82000000,10,1,13.83000000,100,1,13.84000000,200,2,13.93000000,102,2,13.94000000,110,2,13.98000000,150,6,ARL,286680917
874,2025-07-17T15:33:04.271212113Z,2025-07-17T15:33:04.271046430Z,160,2,1108,C,A,0,17.76000000,100,0,165683,240886583,13.55000000,10,1,13.54000000,100,1,13.38000000,33,1,13.37000000,100,1,13.28000000,11,2,13.27000000,100,1,13.26000000,104,3,13.25000000,111,2,13.23000000,2,1,13.20000000,30,2,13.40000000,208,12,13.67000000,100,1,13.71000000,1,1,13.78000000,2,1,13.82000000,10,1,13.83000000,100,1,13.84000000,200,2,13.93000000,102,2,13.94000000,110,2,13.98000000,150,6,ARL,283594173
875,2025-07-17T15:33:04.271212113Z,2025-07-17T15:33:04.271046430Z,160,2,1108,A,A,0,17.58000000,100,130,165683,240886583,13.55000000,10,1,13.54000000,100,1,13.38000000,33,1,13.37000000,100,1,13.28000000,11,2,13.27000000,100,1,13.26000000,104,3,13.25000000,111,2,13.23000000,2,1,13.20000000,30,2,13.40000000,208,12,13.67000000,100,1,13.71000000,1,1,13.78000000,2,1,13.82000000,10,1,13.83000000,100,1,13.84000000,200,2,13.93000000,102,2,13.94000000,110,2,13.98000000,150,6,ARL,286681057
876,2025-07-17T15:33:04.277880725Z,2025-07-17T15:33:04.277715123Z,160,2,1108,C,A,0,16.08000000,100,0,165602,240886720,13.55000000,10,1,13.54000000,100,1,13.38000000,33,1,13.37000000,100,1,13.28000000,11,2,13.27000000,100,1,13.26000000,104,3,13.25000000,111,2,13.23000000,2,1,13.20000000,30,2,13.40000000,208,12,13.67000000,100,1,13.71000000,1,1,13.78000000,2,1,13.82000000,10,1,13.83000000,100,1,13.84000000,200,2,13.93000000,102,2,13.94000000,110,2,13.98000000,150,6,ARL,283599609
877,2025-07-17T15:33:04.277880725Z,2025-07-17T15:33:04.277715123Z,160,2,1108,A,A,0,15.92000000,100,130,165602,240886720,13.55000000,10,1,13.54000000,100,1,13.38000000,33,1,13.37000000,100,1,13.28000000,11,2,13.27000000,100,1,13.26000000,104,3,13.25000000,111,2,13.23000000,2,1,13.20000000,30,2,13.40000000,208,12,13.67000000,100,1,13.71000000,1,1,13.78000000,2,1,13.82000000,10,1,13.83000000,100,1,13.84000000,200,2,13.93000000,102,2,13.94000000,110,2,13.98000000,150,6,ARL,286681229
878,2025-07-17T15:33:04.418840148Z,2025-07-17T15:33:04.418674487Z,160,2,1108,C,A,0,14.96000000,100,0,165661,240888774,13.55000000,10,1,13.54000000,100,1,13.38000000,33,1,13.37000000,100,1,13.28000000,11,2,13.27000000,100,1,13.26000000,104,3,13.25000000,111,2,13.23000000,2,1,13.20000000,30,2,13.40000000,208,12,13.67000000,100,1,13.71000000,1,1,13.78000000,2,1,13.82000000,10,1,13.83000000,100,1,13.84000000,200,2,13.93000000,102,2,13.94000000,110,2,13.98000000,150,6,ARL,283596721
879,2025-07-17T15:33:04.418840148Z,2025-07-17T15:33:04.418674487Z,160,2,1108,A,A,0,14.81000000,100,130,165661,240888774,13.55000000,10,1,13.54000000,100,1,13.38000000,33,1,13.37000000,100,1,13.28000000,11,2,13.27000000,100,1,13.26000000,104,3,13.25000000,111,2,13.23000000,2,1,13.20000000,30,2,13.40000000,208,12,13.67000000,100,1,13.71000000,1,1,13.78000000,2,1,13.82000000,10,1,13.83000000,100,1,13.84000000,200,2,13.93000000,102,2,13.94000000,110,2,13.98000000,150,6,ARL,286684005
880,2025-07-17T15:33:05.330854217Z,2025-07-17T15:33:05.330688486Z,160,2,1108,C,A,0,13.99000000,100,0,165731,240911093,13.55000000,10,1,13.54000000,100,1,13.38000000,33,1,13.37000000,100,1,13.28000000,11,2,13.27000000,100,1,13.26000000,104,3,13.25000000,111,2,13.23000000,2,1,13.20000000,30,2,13.40000000,208,12,13.67000000,100,1,13.71000000,1,1,13.78000000,2,1,13.82000000,10,1,13.83000000,100,1,13.84000000,200,2,13.93000000,102,2,13.94000000,110,2,13.98000000,150,6,ARL,285586225
881,2025-07-17T15:33:05.330854217Z,2025-07-17T15:33:05.330688486Z,160,2,1108,A,A,0,13.85000000,100,130,165731,240911093,13.55000000,10,1,13.54000000,100,1,13.38000000,33,1,13.37000000,100,1,13.28000000,11,2,13.27000000,100,1,13.26000000,104,3,13.25000000,111,2,13.23000000,2,1,13.20000000,30,2,13.40000000,208,12,13.67000000,100,1,13.71000000,1,1,13.78000000,2,1,13.82000000,10,1,13.83000000,100,1,13.84000000,200,2,13.85000000,100,1,13.93000000,102,2,13.94000000,110,2,ARL,286704785
882,2025-07-17T15:33:06.455979270Z,2025-07-17T15:33:06.455814002Z,160,2,1108,C,A,0,13.84000000,100,130,165268,240936407,13.55000000,10,1,13.54000000,100,1,13.38000000,33,1,13.37000000,100,1,13.28000000,11,2,13.27000000,100,1,13.26000000,104,3,13.25000000,111,2,13.23000000,2,1,13.20000000,30,2,13.40000000,208,12,13.67000000,100,1,13.71000000,1,1,13.78000000,2,1,13.82000000,10,1,13.83000000,100,1,13.84000000,200,2,13.85000000,100,1,13.93000000,102,2,13.94000000,110,2,ARL,286680685
883,2025-07-17T15:33:10.468005342Z,2025-07-17T15:33:10.467840054Z,160,2,1108,A,A,0,13.87000000,100,130,165288,241000095,13.55000000,10,1,13.54000000,100,1,13.38000000,33,1,13.37000000,100,1,13.28000000,11,2,13.27000000,100,1,13.26000000,104,3,13.25000000,111,2,13.23000000,2,1,13.20000000,30,2,13.40000000,208,12,13.67000000,100,1,13.71000000,1,1,13.78000000,2,1,13.82000000,10,1,13.83000000,100,1,13.84000000,200,2,13.85000000,100,1,13.87000000,100,1,13.93000000,102,2,ARL,286828253
884,2025-07-17T15:33:40.986585803Z,2025-07-17T15:33:40.986420127Z,160,2,1108,C,A,0,14.02000000,2,0,165676,241593788,13.55000000,10,1,13.54000000,100,1,13.38000000,33,1,13.37000000,100,1,13.28000000,11,2,13.27000000,100,1,13.26000000,104,3,13.25000000,111,2,13.23000000,2,1,13.20000000,30,2,13.40000000,208,12,13.67000000,100,1,13.71000000,1,1,13.78000000,2,1,13.82000000,10,1,13.83000000,100,1,13.84000000,200,2,13.85000000,100,1,13.87000000,100,1,13.93000000,102,2,ARL,283348193
885,2025-07-17T15:33:40.986585803Z,2025-07-17T15:33:40.986420127Z,160,2,1108,A,A,0,13.95000000,2,130,165676,241593788,13.55000000,10,1,13.54000000,100,1,13.38000000,33,1,13.37000000,100,1,13.28000000,11,2,13.27000000,100,1,13.26000000,104,3,13.25000000,111,2,13.23000000,2,1,13.20000000,30,2,13.40000000,208,12,13.67000000,100,1,13.71000000,1,1,13.78000000,2,1,13.82000000,10,1,13.83000000,100,1,13.84000000,200,2,13.85000000,100,1,13.87000000,100,1,13.93000000,102,2,ARL,287540393
886,2025-07-17T15:33:41.766184571Z,2025-07-17T15:33:41.766018916Z,160,2,1108,A,A,0,13.82000000,10,130,165655,241612289,13.55000000,10,1,13.54000000,100,1,13.38000000,33,1,13.37000000,100,1,13.28000000,11,2,13.27000000,100,1,13.26000000,104,3,13.25000000,111,2,13.23000000,2,1,13.20000000,30,2,13.40000000,208,12,13.67000000,100,1,13.71000000,1,1,13.78000000,2,1,13.82000000,20,2,13.83000000,100,1,13.84000000,200,2,13.85000000,100,1,13.87000000,100,1,13.93000000,102,2,ARL,287560109
887,2025-07-17T15:33:41.766265703Z,2025-07-17T15:33:41.766100204Z,160,2,1108,C,A,0,13.85000000,100,0,165499,241612294,13.55000000,10,1,13.54000000,100,1,13.38000000,33,1,13.37000000,100,1,13.28000000,11,2,13.27000000,100,1,13.26000000,104,3,13.25000000,111,2,13.23000000,2,1,13.20000000,30,2,13.40000000,208,12,13.67000000,100,1,13.71000000,1,1,13.78000000,2,1,13.82000000,20,2,13.83000000,100,1,13.84000000,200,2,13.85000000,100,1,13.87000000,100,1,13.93000000,102,2,ARL,286704785
888,2025-07-17T15:33:41.766265703Z,2025-07-17T15:33:41.766100204Z,160,2,1108,A,A,0,13.83000000,100,130,165499,241612294,13.55000000,10,1,13.54000000,100,1,13.38000000,33,1,13.37000000,100,1,13.28000000,11,2,13.27000000,100,1,13.26000000,104,3,13.25000000,111,2,13.23000000,2,1,13.20000000,30,2,13.40000000,208,12,13.67000000,100,1,13.71000000,1,1,13.78000000,2,1,13.82000000,20,2,13.83000000,200,2,13.84000000,200,2,13.85000000,100,1,13.87000000,100,1,13.93000000,102,2,ARL,287560121
889,2025-07-17T15:33:41.777404666Z,2025-07-17T15:33:41.777239400Z,160,2,1108,A,A,0,13.85000000,100,130,165266,241612426,13.55000000,10,1,13.54000000,100,1,13.38000000,33,1,13.37000000,100,1,13.28000000,11,2,13.27000000,100,1,13.26000000,104,3,13.25000000,111,2,13.23000000,2,1,13.20000000,30,2,13.40000000,208,12,13.67000000,100,1,13.71000000,1,1,13.78000000,2,1,13.82000000,20,2,13.83000000,200,2,13.84000000,200,2,13.85000000,200,2,13.87000000,100,1,13.93000000,102,2,ARL,287560333
890,2025-07-17T15:33:41.784121031Z,2025-07-17T15:33:41.783955668Z,160,2,1108,C,A,0,13.87000000,100,130,165363,241612450,13.55000000,10,1,13.54000000,100,1,13.38000000,33,1,13.37000000,100,1,13.28000000,11,2,13.27000000,100,1,13.26000000,104,3,13.25000000,111,2,13.23000000,2,1,13.20000000,30,2,13.40000000,208,12,13.67000000,100,1,13.71000000,1,1,13.78000000,2,1,13.82000000,20,2,13.83000000,200,2,13.84000000,200,2,13.85000000,200,2,13.87000000,100,1,13.93000000,102,2,ARL,286828253
891,2025-07-17T15:33:42.773141775Z,2025-07-17T15:33:42.772976862Z,160,2,1108,C,A,0,13.82000000,10,130,164913,241630390,13.55000000,10,1,13.54000000,100,1,13.38000000,33,1,13.37000000,100,1,13.28000000,11,2,13.27000000,100,1,13.26000000,104,3,13.25000000,111,2,13.23000000,2,1,13.20000000,30,2,13.40000000,208,12,13.67000000,100,1,13.71000000,1,1,13.78000000,2,1,13.82000000,20,2,13.83000000,200,2,13.84000000,200,2,13.85000000,200,2,13.87000000,100,1,13.93000000,102,2,ARL,287560109
892,2025-07-17T15:34:28.155773560Z,2025-07-17T15:34:28.155608087Z,160,2,1108,A,A,0,14.20000000,50,130,165473,242513312,13.55000000,10,1,13.54000000,100,1,13.38000000,33,1,13.37000000,100,1,13.28000000,11,2,13.27000000,100,1,13.26000000,104,3,13.25000000,111,2,13.23000000,2,1,13.20000000,30,2,13.40000000,208,12,13.67000000,100,1,13.71000000,1,1,13.78000000,2,1,13.82000000,20,2,13.83000000,200,2,13.84000000,200,2,13.85000000,200,2,13.87000000,100,1,13.93000000,102,2,ARL,288723725
893,2025-07-17T15:34:28.156815057Z,2025-07-17T15:34:28.156649544Z,160,2,1108,C,B,0,12.65000000,100,0,165513,242513329,13.55000000,10,1,13.54000000,100,1,13.38000000,33,1,13.37000000,100,1,13.28000000,11,2,13.27000000,100,1,13.26000000,104,3,13.25000000,111,2,13.23000000,2,1,13.20000000,30,2,13.40000000,208,12,13.67000000,100,1,13.71000000,1,1,13.78000000,2,1,13.82000000,20,2,13.83000000,200,2,13.84000000,200,2,13.85000000,200,2,13.87000000,100,1,13.93000000,102,2,ARL,236206261
894,2025-07-17T15:34:28.156815057Z,2025-07-17T15:34:28.156649544Z,160,2,1108,A,B,0,12.36000000,100,130,165513,242513329,13.55000000,10,1,13.54000000,100,1,13.38000000,33,1,13.37000000,100,1,13.28000000,11,2,13.27000000,100,1,13.26000000,104,3,13.25000000,111,2,13.23000000,2,1,13.20000000,30,2,13.40000000,208,12,13.67000000,100,1,13.71000000,1,1,13.78000000,2,1,13.82000000,20,2,13.83000000,200,2,13.84000000,200,2,13.85000000,200,2,13.87000000,100,1,13.93000000,102,2,ARL,288723813
895,2025-07-17T15:34:28.156884900Z,2025-07-17T15:34:28.156719339Z,160,2,1108,C,B,0,12.65000000,100,0,165561,242513330,13.55000000,10,1,13.54000000,100,1,13.38000000,33,1,13.37000000,100,1,13.28000000,11,2,13.27000000,100,1,13.26000000,104,3,13.25000000,111,2,13.23000000,2,1,13.20000000,30,2,13.40000000,208,12,13.67000000,100,1,13.71000000,1,1,13.78000000,2,1,13.82000000,20,2,13.83000000,200,2,13.84000000,200,2,13.85000000,200,2,13.87000000,100,1,13.93000000,102,2,ARL,236179089
896,2025-07-17T15:34:28.156884900Z,2025-07-17T15:34:28.156719339Z,160,2,1108,A,B,0,12.36000000,100,130,165561,242513330,13.55000000,10,1,13.54000000,100,1,13.38000000,33,1,13.37000000,100,1,13.28000000,11,2,13.27000000,100,1,13.26000000,104,3,13.25000000,111,2,13.23000000,2,1,13.20000000,30,2,13.40000000,208,12,13.67000000,100,1,13.71000000,1,1,13.78000000,2,1,13.82000000,20,2,13.83000000,200,2,13.84000000,200,2,13.85000000,200,2,13.87000000,100,1,13.93000000,102,2,ARL,288723817
897,2025-07-17T15:34:28.164796058Z,2025-07-17T15:34:28.164629965Z,160,2,1108,T,N,0,13.41000000,43,130,166093,242513452,13.55000000,10,1,13.54000000,100,1,13.38000000,33,1,13.37000000,100,1,13.28000000,11,2,13.27000000,100,1,13.26000000,104,3,13.25000000,111,2,13.23000000,2,1,13.20000000,30,2,13.40000000,208,12,13.67000000,100,1,13.71000000,1,1,13.78000000,2,1,13.82000000,20,2,13.83000000,200,2,13.84000000,200,2,13.85000000,200,2,13.87000000,100,1,13.93000000,102,2,ARL,0
898,2025-07-17T15:34:28.165386986Z,2025-07-17T15:34:28.165221345Z,160,2,1108,T,N,0,13.41000000,100,130,165641,242513454,13.55000000,10,1,13.54000000,100,1,13.38000000,33,1,13.37000000,100,1,13.28000000,11,2,13.27000000,100,1,13.26000000,104,3,13.25000000,111,2,13.23000000,2,1,13.20000000,30,2,13.40000000,208,12,13.67000000,100,1,13.71000000,1,1,13.78000000,2,1,13.82000000,20,2,13.83000000,200,2,13.84000000,200,2,13.85000000,200,2,13.87000000,100,1,13.93000000,102,2,ARL,0
899,2025-07-17T15:34:28.166683461Z,2025-07-17T15:34:28.166516235Z,160,2,1108,T,N,0,13.41000000,56,0,167226,242513557,13.55000000,10,1,13.54000000,100,1,13.38000000,33,1,13.37000000,100,1,13.28000000,11,2,13.27000000,100,1,13.26000000,104,3,13.25000000,111,2,13.23000000,2,1,13.20000000,30,2,13.40000000,208,12,13.67000000,100,1,13.71000000,1,1,13.78000000,2,1,13.82000000,20,2,13.83000000,200,2,13.84000000,200,2,13.85000000,200,2,13.87000000,100,1,13.93000000,102,2,ARL,0
900,2025-07-17T15:34:28.166683461Z,2025-07-17T15:34:28.166516235Z,160,2,1108,T,N,0,13.41000000,28,130,167226,242513558,13.55000000,10,1,13.54000000,100,1,13.38000000,33,1,13.37000000,100,1,13.28000000,11,2,13.27000000,100,1,13.26000000,104,3,13.25000000,111,2,13.23000000,2,1,13.20000000,30,2,13.40000000,208,12,13.67000000,100,1,13.71000000,1,1,13.78000000,2,1,13.82000000,20,2,13.83000000,200,2,13.84000000,200,2,13.85000000,200,2,13.87000000,100,1,13.93000000,102,2,ARL,0
901,2025-07-17T15:34:28.170740864Z,2025-07-17T15:34:28.170575785Z,160,2,1108,A,A,0,13.81000000,50,130,165079,242513651,13.55000000,10,1,13.54000000,100,1,13.38000000,33,1,13.37000000,100,1,13.28000000,11,2,13.27000000,100,1,13.26000000,104,3,13.25000000,111,2,13.23000000,2,1,13.20000000,30,2,13.40000000,208,12,13.67000000,100,1,13.71000000,1,1,13.78000000,2,1,13.81000000,50,1,13.82000000,20,2,13.83000000,200,2,13.84000000,200,2,13.85000000,200,2,13.87000000,100,1,ARL,288724173
902,2025-07-17T15:34:28.170792211Z,2025-07-17T15:34:28.170626756Z,160,2,1108,C,B,0,13.26000000,100,130,165455,242513653,13.55000000,10,1,13.54000000,100,1,13.38000000,33,1,13.37000000,100,1,13.28000000,11,2,13.27000000,100,1,13.26000000,104,3,13.25000000,111,2,13.23000000,2,1,13.20000000,30,2,13.40000000,208,12,13.67000000,100,1,13.71000000,1,1,13.78000000,2,1,13.81000000,50,1,13.82000000,20,2,13.83000000,200,2,13.84000000,200,2,13.85000000,200,2,13.87000000,100,1,ARL,285586221
903,2025-07-17T15:34:28.171437442Z,2025-07-17T15:34:28.171272157Z,160,2,1108,A,A,0,13.78000000,2,130,165285,242513665,13.55000000,10,1,13.54000000,100,1,13.38000000,33,1,13.37000000,100,1,13.28000000,11,2,13.27000000,100,1,13.26000000,104,3,13.25000000,111,2,13.23000000,2,1,13.20000000,30,2,13.40000000,208,12,13.67000000,100,1,13.71000000,1,1,13.78000000,4,2,13.81000000,50,1,13.82000000,20,2,13.83000000,200,2,13.84000000,200,2,13.85000000,200,2,13.87000000,100,1,ARL,288724201
904,2025-07-17T15:34:28.171604993Z,2025-07-17T15:34:28.171439252Z,160,2,1108,T,N,0,13.41000000,13,130,165741,242513674,13.55000000,10,1,13.54000000,100,1,13.38000000,33,1,13.37000000,100,1,13.28000000,11,2,13.27000000,100,1,13.26000000,104,3,13.25000000,111,2,13.23000000,2,1,13.20000000,30,2,13.40000000,208,12,13.67000000,100,1,13.71000000,1,1,13.78000000,4,2,13.81000000,50,1,13.82000000,20,2,13.83000000,200,2,13.84000000,200,2,13.85000000,200,2,13.87000000,100,1,ARL,0
905,2025-07-17T15:34:28.172057926Z,2025-07-17T15:34:28.171892519Z,160,2,1108,A,B,0,13.31000000,10,130,165407,242513691,13.55000000,10,1,13.54000000,100,1,13.38000000,33,1,13.37000000,100,1,13.31000000,10,1,13.28000000,11,2,13.27000000,100,1,13.26000000,104,3,13.25000000,111,2,13.23000000,2,1,13.40000000,208,12,13.67000000,100,1,13.71000000,1,1,13.78000000,4,2,13.81000000,50,1,13.82000000,20,2,13.83000000,200,2,13.84000000,200,2,13.85000000,200,2,13.87000000,100,1,ARL,288724225
906,2025-07-17T15:34:28.172058708Z,2025-07-17T15:34:28.171893498Z,160,2,1108,A,A,0,13.82000000,10,130,165210,242513692,13.55000000,10,1,13.54000000,100,1,13.38000000,33,1,13.37000000,100,1,13.31000000,10,1,13.28000000,11,2,13.27000000,100,1,13.26000000,104,3,13.25000000,111,2,13.23000000,2,1,13.40000000,208,12,13.67000000,100,1,13.71000000,1,1,13.78000000,4,2,13.81000000,50,1,13.82000000,30,3,13.83000000,200,2,13.84000000,200,2,13.85000000,200,2,13.87000000,100,1,ARL,288724229
907,2025-07-17T15:34:28.175011712Z,2025-07-17T15:34:28.174846475Z,160,2,1108,A,B,0,13.30000000,100,130,165237,242513742,13.55000000,10,1,13.54000000,100,1,13.38000000,33,1,13.37000000,100,1,13.31000000,10,1,13.30000000,100,1,13.28000000,11,2,13.27000000,100,1,13.26000000,104,3,13.25000000,111,2,13.40000000,208,12,13.67000000,100,1,13.71000000,1,1,13.78000000,4,2,13.81000000,50,1,13.82000000,30,3,13.83000000,200,2,13.84000000,200,2,13.85000000,200,2,13.87000000,100,1,ARL,288724429
908,2025-07-17T15:34:28.175030125Z,2025-07-17T15:34:28.174864618Z,160,2,1108,C,A,0,13.83000000,100,0,165507,242513743,13.55000000,10,1,13.54000000,100,1,13.38000000,33,1,13.37000000,100,1,13.31000000,10,1,13.30000000,100,1,13.28000000,11,2,13.27000000,100,1,13.26000000,104,3,13.25000000,111,2,13.40000000,208,12,13.67000000,100,1,13.71000000,1,1,13.78000000,4,2,13.81000000,50,1,13.82000000,30,3,13.83000000,200,2,13.84000000,200,2,13.85000000,200,2,13.87000000,100,1,ARL,287560121
909,2025-07-17T15:34:28.175030125Z,2025-07-17T15:34:28.174864618Z,160,2,1108,A,A,0,13.79000000,100,130,165507,242513743,13.55000000,10,1,13.54000000,100,1,13.38000000,33,1,13.37000000,100,1,13.31000000,10,1,13.30000000,100,1,13.28000000,11,2,13.27000000,100,1,13.26000000,104,3,13.25000000,111,2,13.40000000,208,12,13.67000000,100,1,13.71000000,1,1,13.78000000,4,2,13.79000000,100,1,13.81000000,50,1,13.82000000,30,3,13.83000000,200,2,13.84000000,200,2,13.85000000,200,2,ARL,288724433
910,2025-07-17T15:34:28.175329569Z,2025-07-17T15:34:28.175164464Z,160,2,1108,C,A,0,13.78000000,2,130,165105,242513747,13.55000000,10,1,13.54000000,100,1,13.38000000,33,1,13.37000000,100,1,13.31000000,10,1,13.30000000,100,1,13.28000000,11,2,13.27000000,100,1,13.26000000,104,3,13.25000000,111,2,13.40000000,208,12,13.67000000,100,1,13.71000000,1,1,13.78000000,4,2,13.79000000,100,1,13.81000000,50,1,13.82000000,30,3,13.83000000,200,2,13.84000000,200,2,13.85000000,200,2,ARL,288724201
911,2025-07-17T15:34:28.175752130Z,2025-07-17T15:34:28.175586497Z,160,2,1108,C,B,0,12.23000000,100,0,165633,242513748,13.55000000,10,1,13.54000000,100,1,13.38000000,33,1,13.37000000,100,1,13.31000000,10,1,13.30000000,100,1,13.28000000,11,2,13.27000000,100,1,13.26000000,104,3,13.25000000,111,2,13.40000000,208,12,13.67000000,100,1,13.71000000,1,1,13.78000000,4,2,13.79000000,100,1,13.81000000,50,1,13.82000000,30,3,13.83000000,200,2,13.84000000,200,2,13.85000000,200,2,ARL,286680693
912,2025-07-17T15:34:28.175752130Z,2025-07-17T15:34:28.175586497Z,160,2,1108,A,B,0,12.27000000,100,130,165633,242513748,13.55000000,10,1,13.54000000,100,1,13.38000000,33,1,13.37000000,100,1,13.31000000,10,1,13.30000000,100,1,13.28000000,11,2,13.27000000,100,1,13.26000000,104,3,13.25000000,111,2,13.40000000,208,12,13.67000000,100,1,13.71000000,1,1,13.78000000,4,2,13.79000000,100,1,13.81000000,50,1,13.82000000,30,3,13.83000000,200,2,13.84000000,200,2,13.85000000,200,2,ARL,288724485
913,2025-07-17T15:34:28.175767666Z,2025-07-17T15:34:28.175602100Z,160,2,1108,C,A,0,14.91000000,100,0,165566,242513749,13.55000000,10,1,13.54000000,100,1,13.38000000,33,1,13.37000000,100,1,13.31000000,10,1,13.30000000,100,1,13.28000000,11,2,13.27000000,100,1,13.26000000,104,3,13.25000000,111,2,13.40000000,208,12,13.67000000,100,1,13.71000000,1,1,13.78000000,4,2,13.79000000,100,1,13.81000000,50,1,13.82000000,30,3,13.83000000,200,2,13.84000000,200,2,13.85000000,200,2,ARL,286680721
914,2025-07-17T15:34:28.175767666Z,2025-07-17T15:34:28.175602100Z,160,2,1108,A,A,0,14.86000000,100,130,165566,242513749,13.55000000,10,1,13.54000000,100,1,13.38000000,33,1,13.37000000,100,1,13.31000000,10,1,13.30000000,100,1,13.28000000,11,2,13.27000000,100,1,13.26000000,104,3,13.25000000,111,2,13.40000000,208,12,13.67000000,100,1,13.71000000,1,1,13.78000000,4,2,13.79000000,100,1,13.81000000,50,1,13.82000000,30,3,13.83000000,200,2,13.84000000,200,2,13.85000000,200,2,ARL,288724489
915,2025-07-17T15:34:28.180356536Z,2025-07-17T15:34:28.180191067Z,160,2,1108,A,A,0,13.80000000,100,130,165469,242513781,13.55000000,10,1,13.54000000,100,1,13.38000000,33,1,13.37000000,100,1,13.31000000,10,1,13.30000000,100,1,13.28000000,11,2,13.27000000,100,1,13.26000000,104,3,13.25000000,111,2,13.40000000,208,12,13.67000000,100,1,13.71000000,1,1,13.78000000,4,2,13.79000000,100,1,13.80000000,100,1,13.81000000,50,1,13.82000000,30,3,13.83000000,200,2,13.84000000,200,2,ARL,288724565
916,2025-07-17T15:34:28.187237384Z,2025-07-17T15:34:28.187072050Z,160,2,1108,C,A,0,13.85000000,100,130,165334,242513907,13.55000000,10,1,13.54000000,100,1,13.38000000,33,1,13.37000000,100,1,13.31000000,10,1,13.30000000,100,1,13.28000000,11,2,13.27000000,100,1,13.26000000,104,3,13.25000000,111,2,13.40000000,208,12,13.67000000,100,1,13.71000000,1,1,13.78000000,4,2,13.79000000,100,1,13.80000000,100,1,13.81000000,50,1,13.82000000,30,3,13.83000000,200,2,13.84000000,200,2,ARL,287560333
917,2025-07-17T15:34:28.192269421Z,2025-07-17T15:34:28.192104387Z,160,2,1108,C,A,0,13.79000000,100,130,165034,242513974,13.55000000,10,1,13.54000000,100,1,13.38000000,33,1,13.37000000,100,1,13.31000000,10,1,13.30000000,100,1,13.28000000,11,2,13.27000000,100,1,13.26000000,104,3,13.25000000,111,2,13.40000000,208,12,13.67000000,100,1,13.71000000,1,1,13.78000000,4,2,13.79000000,100,1,13.80000000,100,1,13.81000000,50,1,13.82000000,30,3,13.83000000,200,2,13.84000000,200,2,ARL,288724433
918,2025-07-17T15:34:28.231601320Z,2025-07-17T15:34:28.231436134Z,160,2,1108,A,A,0,13.83000000,100,130,165186,242514372,13.55000000,10,1,13.54000000,100,1,13.38000000,33,1,13.37000000,100,1,13.31000000,10,1,13.30000000,100,1,13.28000000,11,2,13.27000000,100,1,13.26000000,104,3,13.25000000,111,2,13.40000000,208,12,13.67000000,100,1,13.71000000,1,1,13.78000000,4,2,13.79000000,100,1,13.80000000,100,1,13.81000000,50,1,13.82000000,30,3,13.83000000,300,3,13.84000000,200,2,ARL,288725173
919,2025-07-17T15:34:28.256123809Z,2025-07-17T15:34:28.255958718Z,160,2,1108,C,A,0,14.20000000,50,130,165091,242514761,13.55000000,10,1,13.54000000,100,1,13.38000000,33,1,13.37000000,100,1,13.31000000,10,1,13.30000000,100,1,13.28000000,11,2,13.27000000,100,1,13.26000000,104,3,13.25000000,111,2,13.40000000,208,12,13.67000000,100,1,13.71000000,1,1,13.78000000,4,2,13.79000000,100,1,13.80000000,100,1,13.81000000,50,1,13.82000000,30,3,13.83000000,300,3,13.84000000,200,2,ARL,288723725
920,2025-07-17T15:34:28.271275449Z,2025-07-17T15:34:28.271110273Z,160,2,1108,C,A,0,13.81000000,50,130,165176,242515164,13.55000000,10,1,13.54000000,100,1,13.38000000,33,1,13.37000000,100,1,13.31000000,10,1,13.30000000,100,1,13.28000000,11,2,13.27000000,100,1,13.26000000,104,3,13.25000000,111,2,13.40000000,208,12,13.67000000,100,1,13.71000000,1,1,13.78000000,4,2,13.79000000,100,1,13.80000000,100,1,13.81000000,50,1,13.82000000,30,3,13.83000000,300,3,13.84000000,200,2,ARL,288724173
921,2025-07-17T15:34:28.281217370Z,2025-07-17T15:34:28.281052249Z,160,2,1108,C,A,0,13.80000000,100,130,165121,242515254,13.55000000,10,1,13.54000000,100,1,13.38000000,33,1,13.37000000,100,1,13.31000000,10,1,13.30000000,100,1,13.28000000,11,2,13.27000000,100,1,13.26000000,104,3,13.25000000,111,2,13.40000000,208,12,13.67000000,100,1,13.71000000,1,1,13.78000000,4,2,13.79000000,100,1,13.80000000,100,1,13.81000000,50,1,13.82000000,30,3,13.83000000,300,3,13.84000000,200,2,ARL,288724565
922,2025-07-17T15:34:28.281945481Z,2025-07-17T15:34:28.281780230Z,160,2,1108,C,A,0,14.86000000,100,0,165251,242515263,13.55000000,10,1,13.54000000,100,1,13.38000000,33,1,13.37000000,100,1,13.31000000,10,1,13.30000000,100,1,13.28000000,11,2,13.27000000,100,1,13.26000000,104,3,13.25000000,111,2,13.40000000,208,12,13.67000000,100,1,13.71000000,1,1,13.78000000,4,2,13.79000000,100,1,13.80000000,100,1,13.81000000,50,1,13.82000000,30,3,13.83000000,300,3,13.84000000,200,2,ARL,288724489
923,2025-07-17T15:34:28.281945481Z,2025-07-17T15:34:28.281780230Z,160,2,1108,A,A,0,14.90000000,100,130,165251,242515263,13.55000000,10,1,13.54000000,100,1,13.38000000,33,1,13.37000000,100,1,13.31000000,10,1,13.30000000,100,1,13.28000000,11,2,13.27000000,100,1,13.26000000,104,3,13.25000000,111,2,13.40000000,208,12,13.67000000,100,1,13.71000000,1,1,13.78000000,4,2,13.79000000,100,1,13.80000000,100,1,13.81000000,50,1,13.82000000,30,3,13.83000000,300,3,13.84000000,200,2,ARL,288726085
924,2025-07-17T15:34:32.289409612Z,2025-07-17T15:34:32.289244370Z,160,2,1108,A,A,0,13.84000000,100,130,165242,242598225,13.55000000,10,1,13.54000000,100,1,13.38000000,33,1,13.37000000,100,1,13.31000000,10,1,13.30000000,100,1,13.28000000,11,2,13.27000000,100,1,13.26000000,104,3,13.25000000,111,2,13.40000000,208,12,13.67000000,100,1,13.71000000,1,1,13.78000000,4,2,13.79000000,100,1,13.80000000,100,1,13.81000000,50,1,13.82000000,30,3,13.83000000,300,3,13.84000000,300,3,ARL,288845417
925,2025-07-17T15:34:39.864692027Z,2025-07-17T15:34:39.864526516Z,160,2,1108,A,A,0,13.80000000,15,130,165511,242774235,13.55000000,10,1,13.54000000,100,1,13.38000000,33,1,13.37000000,100,1,13.31000000,10,1,13.30000000,100,1,13.28000000,11,2,13.27000000,100,1,13.26000000,104,3,13.25000000,111,2,13.40000000,208,12,13.67000000,100,1,13.71000000,1,1,13.78000000,4,2,13.79000000,100,1,13.80000000,115,2,13.81000000,50,1,13.82000000,30,3,13.83000000,300,3,13.84000000,300,3,ARL,289055901
926,2025-07-17T15:34:39.865337932Z,2025-07-17T15:34:39.865171719Z,160,2,1108,C,A,0,13.83000000,100,0,166213,242774299,13.55000000,10,1,13.54000000,100,1,13.38000000,33,1,13.37000000,100,1,13.31000000,10,1,13.30000000,100,1,13.28000000,11,2,13.27000000,100,1,13.26000000,104,3,13.25000000,111,2,13.40000000,208,12,13.67000000,100,1,13.71000000,1,1,13.78000000,4,2,13.79000000,100,1,13.80000000,115,2,13.81000000,50,1,13.82000000,30,3,13.83000000,300,3,13.84000000,300,3,ARL,288725173
927,2025-07-17T15:34:39.865337932Z,2025-07-17T15:34:39.865171719Z,160,2,1108,A,A,0,13.81000000,100,130,166213,242774299,13.55000000,10,1,13.54000000,100,1,13.38000000,33,1,13.37000000,100,1,13.31000000,10,1,13.30000000,100,1,13.28000000,11,2,13.27000000,100,1,13.26000000,104,3,13.25000000,111,2,13.40000000,208,12,13.67000000,100,1,13.71000000,1,1,13.78000000,4,2,13.79000000,100,1,13.80000000,115,2,13.81000000,150,2,13.82000000,30,3,13.83000000,300,3,13.84000000,300,3,ARL,289056097
928,2025-07-17T15:34:39.869175972Z,2025-07-17T15:34:39.869009668Z,160,2,1108,T,N,0,13.41000000,1,130,166304,242774413,13.55000000,10,1,13.54000000,100,1,13.38000000,33,1,13.37000000,100,1,13.31000000,10,1,13.30000000,100,1,13.28000000,11,2,13.27000000,100,1,13.26000000,104,3,13.25000000,111,2,13.40000000,208,12,13.67000000,100,1,13.71000000,1,1,13.78000000,4,2,13.79000000,100,1,13.80000000,115,2,13.81000000,150,2,13.82000000,30,3,13.83000000,300,3,13.84000000,300,3,ARL,0
929,2025-07-17T15:34:39.871606986Z,2025-07-17T15:34:39.871441822Z,160,2,1108,A,A,0,13.81000000,100,130,165164,242774468,13.55000000,10,1,13.54000000,100,1,13.38000000,33,1,13.37000000,100,1,13.31000000,10,1,13.30000000,100,1,13.28000000,11,2,13.27000000,100,1,13.26000000,104,3,13.25000000,111,2,13.40000000,208,12,13.67000000,100,1,13.71000000,1,1,13.78000000,4,2,13.79000000,100,1,13.80000000,115,2,13.81000000,250,3,13.82000000,30,3,13.83000000,300,3,13.84000000,300,3,ARL,289056353
930,2025-07-17T15:34:39.878645012Z,2025-07-17T15:34:39.878479562Z,160,2,1108,C,A,0,13.84000000,100,130,165450,242774619,13.55000000,10,1,13.54000000,100,1,13.38000000,33,1,13.37000000,100,1,13.31000000,10,1,13.30000000,100,1,13.28000000,11,2,13.27000000,100,1,13.26000000,104,3,13.25000000,111,2,13.40000000,208,12,13.67000000,100,1,13.71000000,1,1,13.78000000,4,2,13.79000000,100,1,13.80000000,115,2,13.81000000,250,3,13.82000000,30,3,13.83000000,300,3,13.84000000,300,3,ARL,288845417
931,2025-07-17T15:34:42.774190041Z,2025-07-17T15:34:42.774024574Z,160,2,1108,C,B,0,13.31000000,10,130,165467,242816556,13.55000000,10,1,13.54000000,100,1,13.38000000,33,1,13.37000000,100,1,13.31000000,10,1,13.30000000,100,1,13.28000000,11,2,13.27000000,100,1,13.26000000,104,3,13.25000000,111,2,13.40000000,208,12,13.67000000,100,1,13.71000000,1,1,13.78000000,4,2,13.79000000,100,1,13.80000000,115,2,13.81000000,250,3,13.82000000,30,3,13.83000000,300,3,13.84000000,300,3,ARL,288724225
932,2025-07-17T15:34:42.775304741Z,2025-07-17T15:34:42.775139521Z,160,2,1108,C,A,0,13.81000000,100,130,165220,242816563,13.55000000,10,1,13.54000000,100,1,13.38000000,33,1,13.37000000,100,1,13.31000000,10,1,13.30000000,100,1,13.28000000,11,2,13.27000000,100,1,13.26000000,104,3,13.25000000,111,2,13.40000000,208,12,13.67000000,100,1,13.71000000,1,1,13.78000000,4,2,13.79000000,100,1,13.80000000,115,2,13.81000000,250,3,13.82000000,30,3,13.83000000,300,3,13.84000000,300,3,ARL,289056353
933,2025-07-17T15:34:46.774087945Z,2025-07-17T15:34:46.773922586Z,160,2,1108,C,A,0,13.80000000,15,130,165359,242893860,13.55000000,10,1,13.54000000,100,1,13.38000000,33,1,13.37000000,100,1,13.31000000,10,1,13.30000000,100,1,13.28000000,11,2,13.27000000,100,1,13.26000000,104,3,13.25000000,111,2,13.40000000,208,12,13.67000000,100,1,13.71000000,1,1,13.78000000,4,2,13.79000000,100,1,13.80000000,115,2,13.81000000,250,3,13.82000000,30,3,13.83000000,300,3,13.84000000,300,3,ARL,289055901
934,2025-07-17T15:34:46.800955057Z,2025-07-17T15:34:46.800789632Z,160,2,1108,A,A,0,13.83000000,100,130,165425,242894153,13.55000000,10,1,13.54000000,100,1,13.38000000,33,1,13.37000000,100,1,13.31000000,10,1,13.30000000,100,1,13.28000000,11,2,13.27000000,100,1,13.26000000,104,3,13.25000000,111,2,13.40000000,208,12,13.67000000,100,1,13.71000000,1,1,13.78000000,4,2,13.79000000,100,1,13.80000000,115,2,13.81000000,250,3,13.82000000,30,3,13.83000000,400,4,13.84000000,300,3,ARL,289199221
935,2025-07-17T15:34:53.545830704Z,2025-07-17T15:34:53.545665068Z,160,2,1108,C,A,0,13.82000000,10,130,165636,243011340,13.55000000,10,1,13.54000000,100,1,13.38000000,33,1,13.37000000,100,1,13.31000000,10,1,13.30000000,100,1,13.28000000,11,2,13.27000000,100,1,13.26000000,104,3,13.25000000,111,2,13.40000000,208,12,13.67000000,100,1,13.71000000,1,1,13.78000000,4,2,13.79000000,100,1,13.80000000,115,2,13.81000000,250,3,13.82000000,30,3,13.83000000,400,4,13.84000000,300,3,ARL,288724229
936,2025-07-17T15:35:05.620763928Z,2025-07-17T15:35:05.620598378Z,160,2,1108,A,A,0,13.77000000,15,130,165550,243344672,13.55000000,10,1,13.54000000,100,1,13.38000000,33,1,13.37000000,100,1,13.31000000,10,1,13.30000000,100,1,13.28000000,11,2,13.27000000,100,1,13.26000000,104,3,13.25000000,111,2,13.40000000,208,12,13.67000000,100,1,13.71000000,1,1,13.77000000,15,1,13.78000000,4,2,13.79000000,100,1,13.80000000,115,2,13.81000000,250,3,13.82000000,30,3,13.83000000,400,4,ARL,289722397
937,2025-07-17T15:35:05.712575243Z,2025-07-17T15:35:05.712409728Z,160,2,1108,C,A,0,13.81000000,100,0,165515,243347940,13.55000000,10,1,13.54000000,100,1,13.38000000,33,1,13.37000000,100,1,13.31000000,10,1,13.30000000,100,1,13.28000000,11,2,13.27000000,100,1,13.26000000,104,3,13.25000000,111,2,13.40000000,208,12,13.67000000,100,1,13.71000000,1,1,13.77000000,15,1,13.78000000,4,2,13.79000000,100,1,13.80000000,115,2,13.81000000,250,3,13.82000000,30,3,13.83000000,400,4,ARL,289056097
938,2025-07-17T15:35:05.712575243Z,2025-07-17T15:35:05.712409728Z,160,2,1108,A,A,0,13.78000000,100,130,165515,243347940,13.55000000,10,1,13.54000000,100,1,13.38000000,33,1,13.37000000,100,1,13.31000000,10,1,13.30000000,100,1,13.28000000,11,2,13.27000000,100,1,13.26000000,104,3,13.25000000,111,2,13.40000000,208,12,13.67000000,100,1,13.71000000,1,1,13.77000000,15,1,13.78000000,104,3,13.79000000,100,1,13.80000000,115,2,13.81000000,250,3,13.82000000,30,3,13.83000000,400,4,ARL,289726281
939,2025-07-17T15:35:05.713315450Z,2025-07-17T15:35:05.713150123Z,160,2,1108,C,A,0,14.61000000,100,130,165327,243347987,13.55000000,10,1,13.54000000,100,1,13.38000000,33,1,13.37000000,100,1,13.31000000,10,1,13.30000000,100,1,13.28000000,11,2,13.27000000,100,1,13.26000000,104,3,13.25000000,111,2,13.40000000,208,12,13.67000000,100,1,13.71000000,1,1,13.77000000,15,1,13.78000000,104,3,13.79000000,100,1,13.80000000,115,2,13.81000000,250,3,13.82000000,30,3,13.83000000,400,4,ARL,237978629
940,2025-07-17T15:35:05.713322577Z,2025-07-17T15:35:05.713157077Z,160,2,1108,C,A,0,14.90000000,100,0,165500,243347988,13.55000000,10,1,13.54000000,100,1,13.38000000,33,1,13.37000000,100,1,13.31000000,10,1,13.30000000,100,1,13.28000000,11,2,13.27000000,100,1,13.26000000,104,3,13.25000000,111,2,13.40000000,208,12,13.67000000,100,1,13.71000000,1,1,13.77000000,15,1,13.78000000,104,3,13.79000000,100,1,13.80000000,115,2,13.81000000,250,3,13.82000000,30,3,13.83000000,400,4,ARL,288726085
941,2025-07-17T15:35:05.713322577Z,2025-07-17T15:35:05.713157077Z,160,2,1108,A,A,0,14.85000000,100,130,165500,243347988,13.55000000,10,1,13.54000000,100,1,13.38000000,33,1,13.37000000,100,1,13.31000000,10,1,13.30000000,100,1,13.28000000,11,2,13.27000000,100,1,13.26000000,104,3,13.25000000,111,2,13.40000000,208,12,13.67000000,100,1,13.71000000,1,1,13.77000000,15,1,13.78000000,104,3,13.79000000,100,1,13.80000000,115,2,13.81000000,250,3,13.82000000,30,3,13.83000000,400,4,ARL,289726349
942,2025-07-17T15:35:05.713677091Z,2025-07-17T15:35:05.713508657Z,160,2,1108,A,A,0,14.40000000,100,128,168434,243348032,13.55000000,10,1,13.54000000,100,1,13.38000000,33,1,13.37000000,100,1,13.31000000,10,1,13.30000000,100,1,13.28000000,11,2,13.27000000,100,1,13.26000000,104,3,13.25000000,111,2,13.40000000,208,12,13.67000000,100,1,13.71000000,1,1,13.77000000,15,1,13.78000000,104,3,13.79000000,100,1,13.80000000,115,2,13.81000000,250,3,13.82000000,30,3,13.83000000,400,4,ARL,289726421
943,2025-07-17T15:35:05.729568877Z,2025-07-17T15:35:05.729398505Z,160,2,1108,A,A,0,13.80000000,100,128,170372,243351264,13.55000000,10,1,13.54000000,100,1,13.38000000,33,1,13.37000000,100,1,13.31000000,10,1,13.30000000,100,1,13.28000000,11,2,13.27000000,100,1,13.26000000,104,3,13.25000000,111,2,13.40000000,208,12,13.67000000,100,1,13.71000000,1,1,13.77000000,15,1,13.78000000,104,3,13.79000000,100,1,13.80000000,215,3,13.81000000,250,3,13.82000000,30,3,13.83000000,400,4,ARL,289730309
944,2025-07-17T15:35:05.737967956Z,2025-07-17T15:35:05.737802616Z,160,2,1108,C,A,0,13.83000000,100,130,165340,243352644,13.55000000,10,1,13.54000000,100,1,13.38000000,33,1,13.37000000,100,1,13.31000000,10,1,13.30000000,100,1,13.28000000,11,2,13.27000000,100,1,13.26000000,104,3,13.25000000,111,2,13.40000000,208,12,13.67000000,100,1,13.71000000,1,1,13.77000000,15,1,13.78000000,104,3,13.79000000,100,1,13.80000000,215,3,13.81000000,250,3,13.82000000,30,3,13.83000000,400,4,ARL,289199221
945,2025-07-17T15:35:06.286572335Z,2025-07-17T15:35:06.286407017Z,160,2,1108,C,A,0,13.77000000,15,130,165318,243362628,13.55000000,10,1,13.54000000,100,1,13.38000000,33,1,13.37000000,100,1,13.31000000,10,1,13.30000000,100,1,13.28000000,11,2,13.27000000,100,1,13.26000000,104,3,13.25000000,111,2,13.40000000,208,12,13.67000000,100,1,13.71000000,1,1,13.77000000,15,1,13.78000000,104,3,13.79000000,100,1,13.80000000,215,3,13.81000000,250,3,13.82000000,30,3,13.83000000,400,4,ARL,289722397
946,2025-07-17T15:35:09.788280931Z,2025-07-17T15:35:09.788115219Z,160,2,1108,C,B,0,13.23000000,2,0,165712,243432828,13.55000000,10,1,13.54000000,100,1,13.38000000,33,1,13.37000000,100,1,13.31000000,10,1,13.30000000,100,1,13.28000000,11,2,13.27000000,100,1,13.26000000,104,3,13.25000000,111,2,13.40000000,208,12,13.67000000,100,1,13.71000000,1,1,13.77000000,15,1,13.78000000,104,3,13.79000000,100,1,13.80000000,215,3,13.81000000,250,3,13.82000000,30,3,13.83000000,400,4,ARL,272263853
947,2025-07-17T15:35:09.788280931Z,2025-07-17T15:35:09.788115219Z,160,2,1108,A,B,0,13.14000000,2,130,165712,243432828,13.55000000,10,1,13.54000000,100,1,13.38000000,33,1,13.37000000,100,1,13.31000000,10,1,13.30000000,100,1,13.28000000,11,2,13.27000000,100,1,13.26000000,104,3,13.25000000,111,2,13.40000000,208,12,13.67000000,100,1,13.71000000,1,1,13.77000000,15,1,13.78000000,104,3,13.79000000,100,1,13.80000000,215,3,13.81000000,250,3,13.82000000,30,3,13.83000000,400,4,ARL,289828293
948,2025-07-17T15:35:11.891867009Z,2025-07-17T15:35:11.891701845Z,160,2,1108,C,A,0,13.80000000,100,130,165164,243482295,13.55000000,10,1,13.54000000,100,1,13.38000000,33,1,13.37000000,100,1,13.31000000,10,1,13.30000000,100,1,13.28000000,11,2,13.27000000,100,1,13.26000000,104,3,13.25000000,111,2,13.40000000,208,12,13.67000000,100,1,13.71000000,1,1,13.77000000,15,1,13.78000000,104,3,13.79000000,100,1,13.80000000,215,3,13.81000000,250,3,13.82000000,30,3,13.83000000,400,4,ARL,289730309
949,2025-07-17T15:35:14.301647013Z,2025-07-17T15:35:14.301481698Z,160,2,1108,A,A,0,14.68000000,700,130,165315,243521615,13.55000000,10,1,13.54000000,100,1,13.38000000,33,1,13.37000000,100,1,13.31000000,10,1,13.30000000,100,1,13.28000000,11,2,13.27000000,100,1,13.26000000,104,3,13.25000000,111,2,13.40000000,208,12,13.67000000,100,1,13.71000000,1,1,13.77000000,15,1,13.78000000,104,3,13.79000000,100,1,13.80000000,215,3,13.81000000,250,3,13.82000000,30,3,13.83000000,400,4,ARL,289932801
950,2025-07-17T15:35:14.302443648Z,2025-07-17T15:35:14.302278179Z,160,2,1108,C,A,0,14.91000000,700,130,165469,243521616,13.55000000,10,1,13.54000000,100,1,13.38000000,33,1,13.37000000,100,1,13.31000000,10,1,13.30000000,100,1,13.28000000,11,2,13.27000000,100,1,13.26000000,104,3,13.25000000,111,2,13.40000000,208,12,13.67000000,100,1,13.71000000,1,1,13.77000000,15,1,13.78000000,104,3,13.79000000,100,1,13.80000000,215,3,13.81000000,250,3,13.82000000,30,3,13.83000000,400,4,ARL,147217629
951,2025-07-17T15:35:15.940644416Z,2025-07-17T15:35:15.940479233Z,160,2,1108,A,A,0,13.82000000,100,130,165183,243557058,13.55000000,10,1,13.54000000,100,1,13.38000000,33,1,13.37000000,100,1,13.31000000,10,1,13.30000000,100,1,13.28000000,11,2,13.27000000,100,1,13.26000000,104,3,13.25000000,111,2,13.40000000,208,12,13.67000000,100,1,13.71000000,1,1,13.77000000,15,1,13.78000000,104,3,13.79000000,100,1,13.80000000,215,3,13.81000000,250,3,13.82000000,130,4,13.83000000,400,4,ARL,289976125
952,2025-07-17T15:35:23.746674314Z,2025-07-17T15:35:23.746509184Z,160,2,1108,A,A,0,13.80000000,100,130,165130,243692012,13.55000000,10,1,13.54000000,100,1,13.38000000,33,1,13.37000000,100,1,13.31000000,10,1,13.30000000,100,1,13.28000000,11,2,13.27000000,100,1,13.26000000,104,3,13.25000000,111,2,13.40000000,208,12,13.67000000,100,1,13.71000000,1,1,13.77000000,15,1,13.78000000,104,3,13.79000000,100,1,13.80000000,315,4,13.81000000,250,3,13.82000000,130,4,13.83000000,400,4,ARL,290159301
953,2025-07-17T15:35:23.754618546Z,2025-07-17T15:35:23.754453294Z,160,2,1108,C,A,0,13.82000000,100,130,165252,243692501,13.55000000,10,1,13.54000000,100,1,13.38000000,33,1,13.37000000,100,1,13.31000000,10,1,13.30000000,100,1,13.28000000,11,2,13.27000000,100,1,13.26000000,104,3,13.25000000,111,2,13.40000000,208,12,13.67000000,100,1,13.71000000,1,1,13.77000000,15,1,13.78000000,104,3,13.79000000,100,1,13.80000000,315,4,13.81000000,250,3,13.82000000,130,4,13.83000000,400,4,ARL,289976125
954,2025-07-17T15:35:39.056679600Z,2025-07-17T15:35:39.056513985Z,160,2,1108,C,A,0,13.80000000,100,130,165615,243992725,13.55000000,10,1,13.54000000,100,1,13.38000000,33,1,13.37000000,100,1,13.31000000,10,1,13.30000000,100,1,13.28000000,11,2,13.27000000,100,1,13.26000000,104,3,13.25000000,111,2,13.40000000,208,12,13.67000000,100,1,13.71000000,1,1,13.77000000,15,1,13.78000000,104,3,13.79000000,100,1,13.80000000,315,4,13.81000000,250,3,13.82000000,130,4,13.83000000,400,4,ARL,290159301
955,2025-07-17T15:35:43.128809717Z,2025-07-17T15:35:43.128644252Z,160,2,1108,A,A,0,13.82000000,100,130,165465,244078096,13.55000000,10,1,13.54000000,100,1,13.38000000,33,1,13.37000000,100,1,13.31000000,10,1,13.30000000,100,1,13.28000000,11,2,13.27000000,100,1,13.26000000,104,3,13.25000000,111,2,13.40000000,208,12,13.67000000,100,1,13.71000000,1,1,13.77000000,15,1,13.78000000,104,3,13.79000000,100,1,13.80000000,315,4,13.81000000,250,3,13.82000000,230,5,13.83000000,400,4,ARL,290630573
956,2025-07-17T15:36:30.044094509Z,2025-07-17T15:36:30.043928872Z,160,2,1108,A,A,0,13.80000000,100,130,165637,245013624,13.55000000,10,1,13.54000000,100,1,13.38000000,33,1,13.37000000,100,1,13.31000000,10,1,13.30000000,100,1,13.28000000,11,2,13.27000000,100,1,13.26000000,104,3,13.25000000,111,2,13.40000000,208,12,13.67000000,100,1,13.71000000,1,1,13.77000000,15,1,13.78000000,104,3,13.79000000,100,1,13.80000000,415,5,13.81000000,250,3,13.82000000,230,5,13.83000000,400,4,ARL,291778909
957,2025-07-17T15:36:30.051045453Z,2025-07-17T15:36:30.050880126Z,160,2,1108,C,A,0,13.82000000,100,130,165327,245013914,13.55000000,10,1,13.54000000,100,1,13.38000000,33,1,13.37000000,100,1,13.31000000,10,1,13.30000000,100,1,13.28000000,11,2,13.27000000,100,1,13.26000000,104,3,13.25000000,111,2,13.40000000,208,12,13.67000000,100,1,13.71000000,1,1,13.77000000,15,1,13.78000000,104,3,13.79000000,100,1,13.80000000,415,5,13.81000000,250,3,13.82000000,230,5,13.83000000,400,4,ARL,290630573
958,2025-07-17T15:36:34.298010005Z,2025-07-17T15:36:34.297844579Z,160,2,1108,C,B,0,13.30000000,100,130,165426,245144122,13.55000000,10,1,13.54000000,100,1,13.38000000,33,1,13.37000000,100,1,13.31000000,10,1,13.30000000,100,1,13.28000000,11,2,13.27000000,100,1,13.26000000,104,3,13.25000000,111,2,13.40000000,208,12,13.67000000,100,1,13.71000000,1,1,13.77000000,15,1,13.78000000,104,3,13.79000000,100,1,13.80000000,415,5,13.81000000,250,3,13.82000000,230,5,13.83000000,400,4,ARL,288724429
959,2025-07-17T15:36:35.381330809Z,2025-07-17T15:36:35.381165559Z,160,2,1108,A,B,0,13.13000000,100,130,165250,245161447,13.55000000,10,1,13.54000000,100,1,13.38000000,33,1,13.37000000,100,1,13.31000000,10,1,13.30000000,100,1,13.28000000,11,2,13.27000000,100,1,13.26000000,104,3,13.25000000,111,2,13.40000000,208,12,13.67000000,100,1,13.71000000,1,1,13.77000000,15,1,13.78000000,104,3,13.79000000,100,1,13.80000000,415,5,13.81000000,250,3,13.82000000,230,5,13.83000000,400,4,ARL,291951937
960,2025-07-17T15:36:35.532851032Z,2025-07-17T15:36:35.532685683Z,160,2,1108,A,B,0,13.27000000,10,130,165349,245174454,13.55000000,10,1,13.54000000,100,1,13.38000000,33,1,13.37000000,100,1,13.31000000,10,1,13.30000000,100,1,13.28000000,11,2,13.27000000,110,2,13.26000000,104,3,13.25000000,111,2,13.40000000,208,12,13.67000000,100,1,13.71000000,1,1,13.77000000,15,1,13.78000000,104,3,13.79000000,100,1,13.80000000,415,5,13.81000000,250,3,13.82000000,230,5,13.83000000,400,4,ARL,291964737
961,2025-07-17T15:36:35.532926951Z,2025-07-17T15:36:35.532761335Z,160,2,1108,C,B,0,12.27000000,100,0,165616,245174461,13.55000000,10,1,13.54000000,100,1,13.38000000,33,1,13.37000000,100,1,13.31000000,10,1,13.30000000,100,1,13.28000000,11,2,13.27000000,110,2,13.26000000,104,3,13.25000000,111,2,13.40000000,208,12,13.67000000,100,1,13.71000000,1,1,13.77000000,15,1,13.78000000,104,3,13.79000000,100,1,13.80000000,415,5,13.81000000,250,3,13.82000000,230,5,13.83000000,400,4,ARL,288724485
962,2025-07-17T15:36:35.532926951Z,2025-07-17T15:36:35.532761335Z,160,2,1108,A,B,0,12.23000000,100,130,165616,245174461,13.55000000,10,1,13.54000000,100,1,13.38000000,33,1,13.37000000,100,1,13.31000000,10,1,13.30000000,100,1,13.28000000,11,2,13.27000000,110,2,13.26000000,104,3,13.25000000,111,2,13.40000000,208,12,13.67000000,100,1,13.71000000,1,1,13.77000000,15,1,13.78000000,104,3,13.79000000,100,1,13.80000000,415,5,13.81000000,250,3,13.82000000,230,5,13.83000000,400,4,ARL,291964745
963,2025-07-17T15:36:36.152132527Z,2025-07-17T15:36:36.151966883Z,160,2,1108,C,B,0,13.13000000,100,0,165644,245183955,13.55000000,10,1,13.54000000,100,1,13.38000000,33,1,13.37000000,100,1,13.31000000,10,1,13.30000000,100,1,13.28000000,11,2,13.27000000,110,2,13.26000000,104,3,13.25000000,111,2,13.40000000,208,12,13.67000000,100,1,13.71000000,1,1,13.77000000,15,1,13.78000000,104,3,13.79000000,100,1,13.80000000,415,5,13.81000000,250,3,13.82000000,230,5,13.83000000,400,4,ARL,291951937
964,2025-07-17T15:36:36.152132527Z,2025-07-17T15:36:36.151966883Z,160,2,1108,A,B,0,13.26000000,100,130,165644,245183955,13.55000000,10,1,13.54000000,100,1,13.38000000,33,1,13.37000000,100,1,13.31000000,10,1,13.30000000,100,1,13.28000000,11,2,13.27000000,110,2,13.26000000,204,4,13.25000000,111,2,13.40000000,208,12,13.67000000,100,1,13.71000000,1,1,13.77000000,15,1,13.78000000,104,3,13.79000000,100,1,13.80000000,415,5,13.81000000,250,3,13.82000000,230,5,13.83000000,400,4,ARL,291975017
965,2025-07-17T15:36:46.889917278Z,2025-07-17T15:36:46.889749756Z,160,2,1108,C,B,0,13.27000000,10,128,167522,245499598,13.55000000,10,1,13.54000000,100,1,13.38000000,33,1,13.37000000,100,1,13.31000000,10,1,13.30000000,100,1,13.28000000,11,2,13.27000000,110,2,13.26000000,204,4,13.25000000,111,2,13.40000000,208,12,13.67000000,100,1,13.71000000,1,1,13.77000000,15,1,13.78000000,104,3,13.79000000,100,1,13.80000000,415,5,13.81000000,250,3,13.82000000,230,5,13.83000000,400,4,ARL,291964737
966,2025-07-17T15:36:46.986820391Z,2025-07-17T15:36:46.986655137Z,160,2,1108,C,A,0,13.80000000,100,130,165254,245503745,13.55000000,10,1,13.54000000,100,1,13.38000000,33,1,13.37000000,100,1,13.31000000,10,1,13.30000000,100,1,13.28000000,11,2,13.27000000,110,2,13.26000000,204,4,13.25000000,111,2,13.40000000,208,12,13.67000000,100,1,13.71000000,1,1,13.77000000,15,1,13.78000000,104,3,13.79000000,100,1,13.80000000,415,5,13.81000000,250,3,13.82000000,230,5,13.83000000,400,4,ARL,291778909
967,2025-07-17T15:36:50.997434689Z,2025-07-17T15:36:50.997269299Z,160,2,1108,A,A,0,13.82000000,100,130,165390,245564901,13.55000000,10,1,13.54000000,100,1,13.38000000,33,1,13.37000000,100,1,13.31000000,10,1,13.30000000,100,1,13.28000000,11,2,13.27000000,110,2,13.26000000,204,4,13.25000000,111,2,13.40000000,208,12,13.67000000,100,1,13.71000000,1,1,13.77000000,15,1,13.78000000,104,3,13.79000000,100,1,13.80000000,415,5,13.81000000,250,3,13.82000000,330,6,13.83000000,400,4,ARL,292434813
968,2025-07-17T15:37:40.389737573Z,2025-07-17T15:37:40.389572053Z,160,2,1108,C,B,0,13.14000000,2,0,165520,246491394,13.55000000,10,1,13.54000000,100,1,13.38000000,33,1,13.37000000,100,1,13.31000000,10,1,13.30000000,100,1,13.28000000,11,2,13.27000000,110,2,13.26000000,204,4,13.25000000,111,2,13.40000000,208,12,13.67000000,100,1,13.71000000,1,1,13.77000000,15,1,13.78000000,104,3,13.79000000,100,1,13.80000000,415,5,13.81000000,250,3,13.82000000,330,6,13.83000000,400,4,ARL,289828293
969,2025-07-17T15:37:40.389737573Z,2025-07-17T15:37:40.389572053Z,160,2,1108,A,B,0,13.04000000,2,130,165520,246491394,13.55000000,10,1,13.54000000,100,1,13.38000000,33,1,13.37000000,100,1,13.31000000,10,1,13.30000000,100,1,13.28000000,11,2,13.27000000,110,2,13.26000000,204,4,13.25000000,111,2,13.40000000,208,12,13.67000000,100,1,13.71000000,1,1,13.77000000,15,1,13.78000000,104,3,13.79000000,100,1,13.80000000,415,5,13.81000000,250,3,13.82000000,330,6,13.83000000,400,4,ARL,293594281
970,2025-07-17T15:39:27.070109669Z,2025-07-17T15:39:27.069942913Z,160,2,1108,A,A,0,13.80000000,100,128,166756,248436908,13.55000000,10,1,13.54000000,100,1,13.38000000,33,1,13.37000000,100,1,13.31000000,10,1,13.30000000,100,1,13.28000000,11,2,13.27000000,110,2,13.26000000,204,4,13.25000000,111,2,13.40000000,208,12,13.67000000,100,1,13.71000000,1,1,13.77000000,15,1,13.78000000,104,3,13.79000000,100,1,13.80000000,515,6,13.81000000,250,3,13.82000000,330,6,13.83000000,400,4,ARL,296059685
971,2025-07-17T15:39:27.077565902Z,2025-07-17T15:39:27.077400388Z,160,2,1108,C,A,0,13.82000000,100,130,165514,248437548,13.55000000,10,1,13.54000000,100,1,13.38000000,33,1,13.37000000,100,1,13.31000000,10,1,13.30000000,100,1,13.28000000,11,2,13.27000000,110,2,13.26000000,204,4,13.25000000,111,2,13.40000000,208,12,13.67000000,100,1,13.71000000,1,1,13.77000000,15,1,13.78000000,104,3,13.79000000,100,1,13.80000000,515,6,13.81000000,250,3,13.82000000,330,6,13.83000000,400,4,ARL,292434813
972,2025-07-17T15:39:30.509853083Z,2025-07-17T15:39:30.509687817Z,160,2,1108,A,A,0,13.76000000,15,130,165266,248491930,13.55000000,10,1,13.54000000,100,1,13.38000000,33,1,13.37000000,100,1,13.31000000,10,1,13.30000000,100,1,13.28000000,11,2,13.27000000,110,2,13.26000000,204,4,13.25000000,111,2,13.40000000,208,12,13.67000000,100,1,13.71000000,1,1,13.76000000,15,1,13.77000000,15,1,13.78000000,104,3,13.79000000,100,1,13.80000000,515,6,13.81000000,250,3,13.82000000,330,6,ARL,296136617
973,2025-07-17T15:39:30.573217843Z,2025-07-17T15:39:30.573052284Z,160,2,1108,C,A,0,13.78000000,100,0,165559,248492793,13.55000000,10,1,13.54000000,100,1,13.38000000,33,1,13.37000000,100,1,13.31000000,10,1,13.30000000,100,1,13.28000000,11,2,13.27000000,110,2,13.26000000,204,4,13.25000000,111,2,13.40000000,208,12,13.67000000,100,1,13.71000000,1,1,13.76000000,15,1,13.77000000,15,1,13.78000000,104,3,13.79000000,100,1,13.80000000,515,6,13.81000000,250,3,13.82000000,330,6,ARL,289726281
974,2025-07-17T15:39:30.573217843Z,2025-07-17T15:39:30.573052284Z,160,2,1108,A,A,0,13.77000000,100,130,165559,248492793,13.55000000,10,1,13.54000000,100,1,13.38000000,33,1,13.37000000,100,1,13.31000000,10,1,13.30000000,100,1,13.28000000,11,2,13.27000000,110,2,13.26000000,204,4,13.25000000,111,2,13.40000000,208,12,13.67000000,100,1,13.71000000,1,1,13.76000000,15,1,13.77000000,115,2,13.78000000,104,3,13.79000000,100,1,13.80000000,515,6,13.81000000,250,3,13.82000000,330,6,ARL,296137537
975,2025-07-17T15:39:30.589169820Z,2025-07-17T15:39:30.589004378Z,160,2,1108,C,A,0,14.12000000,100,130,165442,248493012,13.55000000,10,1,13.54000000,100,1,13.38000000,33,1,13.37000000,100,1,13.31000000,10,1,13.30000000,100,1,13.28000000,11,2,13.27000000,110,2,13.26000000,204,4,13.25000000,111,2,13.40000000,208,12,13.67000000,100,1,13.71000000,1,1,13.76000000,15,1,13.77000000,115,2,13.78000000,104,3,13.79000000,100,1,13.80000000,515,6,13.81000000,250,3,13.82000000,330,6,ARL,286680917
976,2025-07-17T15:39:30.589224596Z,2025-07-17T15:39:30.589059301Z,160,2,1108,A,A,0,14.05000000,100,130,165295,248493014,13.55000000,10,1,13.54000000,100,1,13.38000000,33,1,13.37000000,100,1,13.31000000,10,1,13.30000000,100,1,13.28000000,11,2,13.27000000,110,2,13.26000000,204,4,13.25000000,111,2,13.40000000,208,12,13.67000000,100,1,13.71000000,1,1,13.76000000,15,1,13.77000000,115,2,13.78000000,104,3,13.79000000,100,1,13.80000000,515,6,13.81000000,250,3,13.82000000,330,6,ARL,296137769
977,2025-07-17T15:39:31.092010369Z,2025-07-17T15:39:31.091844988Z,160,2,1108,A,A,0,13.78000000,100,130,165381,248502203,13.55000000,10,1,13.54000000,100,1,13.38000000,33,1,13.37000000,100,1,13.31000000,10,1,13.30000000,100,1,13.28000000,11,2,13.27000000,110,2,13.26000000,204,4,13.25000000,111,2,13.40000000,208,12,13.67000000,100,1,13.71000000,1,1,13.76000000,15,1,13.77000000,115,2,13.78000000,204,4,13.79000000,100,1,13.80000000,515,6,13.81000000,250,3,13.82000000,330,6,ARL,296149845
978,2025-07-17T15:39:31.098856641Z,2025-07-17T15:39:31.098691429Z,160,2,1108,C,A,0,13.80000000,100,130,165212,248502510,13.55000000,10,1,13.54000000,100,1,13.38000000,33,1,13.37000000,100,1,13.31000000,10,1,13.30000000,100,1,13.28000000,11,2,13.27000000,110,2,13.26000000,204,4,13.25000000,111,2,13.40000000,208,12,13.67000000,100,1,13.71000000,1,1,13.76000000,15,1,13.77000000,115,2,13.78000000,204,4,13.79000000,100,1,13.80000000,515,6,13.81000000,250,3,13.82000000,330,6,ARL,296059685
979,2025-07-17T15:39:40.691151435Z,2025-07-17T15:39:40.690971606Z,160,2,1108,A,A,0,13.73000000,15,128,179829,248666930,13.55000000,10,1,13.54000000,100,1,13.38000000,33,1,13.37000000,100,1,13.31000000,10,1,13.30000000,100,1,13.28000000,11,2,13.27000000,110,2,13.26000000,204,4,13.25000000,111,2,13.40000000,208,12,13.67000000,100,1,13.71000000,1,1,13.73000000,15,1,13.76000000,15,1,13.77000000,115,2,13.78000000,204,4,13.79000000,100,1,13.80000000,515,6,13.81000000,250,3,ARL,296365029
980,2025-07-17T15:39:40.696349429Z,2025-07-17T15:39:40.696182148Z,160,2,1108,C,A,0,13.77000000,100,0,167281,248669978,13.55000000,10,1,13.54000000,100,1,13.38000000,33,1,13.37000000,100,1,13.31000000,10,1,13.30000000,100,1,13.28000000,11,2,13.27000000,110,2,13.26000000,204,4,13.25000000,111,2,13.40000000,208,12,13.67000000,100,1,13.71000000,1,1,13.73000000,15,1,13.76000000,15,1,13.77000000,115,2,13.78000000,204,4,13.79000000,100,1,13.80000000,515,6,13.81000000,250,3,ARL,296137537
981,2025-07-17T15:39:40.696349429Z,2025-07-17T15:39:40.696182148Z,160,2,1108,A,A,0,13.74000000,100,130,167281,248669978,13.55000000,10,1,13.54000000,100,1,13.38000000,33,1,13.37000000,100,1,13.31000000,10,1,13.30000000,100,1,13.28000000,11,2,13.27000000,110,2,13.26000000,204,4,13.25000000,111,2,13.40000000,208,12,13.67000000,100,1,13.71000000,1,1,13.73000000,15,1,13.74000000,100,1,13.76000000,15,1,13.77000000,115,2,13.78000000,204,4,13.79000000,100,1,13.80000000,515,6,ARL,296368281
982,2025-07-17T15:39:40.697414147Z,2025-07-17T15:39:40.697247480Z,160,2,1108,C,A,0,14.85000000,100,0,166667,248670386,13.55000000,10,1,13.54000000,100,1,13.38000000,33,1,13.37000000,100,1,13.31000000,10,1,13.30000000,100,1,13.28000000,11,2,13.27000000,110,2,13.26000000,204,4,13.25000000,111,2,13.40000000,208,12,13.67000000,100,1,13.71000000,1,1,13.73000000,15,1,13.74000000,100,1,13.76000000,15,1,13.77000000,115,2,13.78000000,204,4,13.79000000,100,1,13.80000000,515,6,ARL,289726349
983,2025-07-17T15:39:40.697414147Z,2025-07-17T15:39:40.697247480Z,160,2,1108,A,A,0,14.81000000,100,128,166667,248670386,13.55000000,10,1,13.54000000,100,1,13.38000000,33,1,13.37000000,100,1,13.31000000,10,1,13.30000000,100,1,13.28000000,11,2,13.27000000,110,2,13.26000000,204,4,13.25000000,111,2,13.40000000,208,12,13.67000000,100,1,13.71000000,1,1,13.73000000,15,1,13.74000000,100,1,13.76000000,15,1,13.77000000,115,2,13.78000000,204,4,13.79000000,100,1,13.80000000,515,6,ARL,296368709
984,2025-07-17T15:39:40.708810377Z,2025-07-17T15:39:40.708645114Z,160,2,1108,A,A,0,13.76000000,100,130,165263,248674504,13.55000000,10,1,13.54000000,100,1,13.38000000,33,1,13.37000000,100,1,13.31000000,10,1,13.30000000,100,1,13.28000000,11,2,13.27000000,110,2,13.26000000,204,4,13.25000000,111,2,13.40000000,208,12,13.67000000,100,1,13.71000000,1,1,13.73000000,15,1,13.74000000,100,1,13.76000000,115,2,13.77000000,115,2,13.78000000,204,4,13.79000000,100,1,13.80000000,515,6,ARL,296372577
985,2025-07-17T15:39:40.731431547Z,2025-07-17T15:39:40.731266408Z,160,2,1108,C,A,0,13.78000000,100,130,165139,248676672,13.55000000,10,1,13.54000000,100,1,13.38000000,33,1,13.37000000,100,1,13.31000000,10,1,13.30000000,100,1,13.28000000,11,2,13.27000000,110,2,13.26000000,204,4,13.25000000,111,2,13.40000000,208,12,13.67000000,100,1,13.71000000,1,1,13.73000000,15,1,13.74000000,100,1,13.76000000,115,2,13.77000000,115,2,13.78000000,204,4,13.79000000,100,1,13.80000000,515,6,ARL,296149845
986,2025-07-17T15:39:40.908095999Z,2025-07-17T15:39:40.907929975Z,160,2,1108,C,A,0,15.40000000,100,0,166024,248685584,13.55000000,10,1,13.54000000,100,1,13.38000000,33,1,13.37000000,100,1,13.31000000,10,1,13.30000000,100,1,13.28000000,11,2,13.27000000,110,2,13.26000000,204,4,13.25000000,111,2,13.40000000,208,12,13.67000000,100,1,13.71000000,1,1,13.73000000,15,1,13.74000000,100,1,13.76000000,115,2,13.77000000,115,2,13.78000000,204,4,13.79000000,100,1,13.80000000,515,6,ARL,146959177
987,2025-07-17T15:39:40.908095999Z,2025-07-17T15:39:40.907929975Z,160,2,1108,A,A,0,15.12000000,100,130,166024,248685584,13.55000000,10,1,13.54000000,100,1,13.38000000,33,1,13.37000000,100,1,13.31000000,10,1,13.30000000,100,1,13.28000000,11,2,13.27000000,110,2,13.26000000,204,4,13.25000000,111,2,13.40000000,208,12,13.67000000,100,1,13.71000000,1,1,13.73000000,15,1,13.74000000,100,1,13.76000000,115,2,13.77000000,115,2,13.78000000,204,4,13.79000000,100,1,13.80000000,515,6,ARL,296387089
988,2025-07-17T15:39:41.085864728Z,2025-07-17T15:39:41.085699437Z,160,2,1108,A,A,0,14.56000000,100,130,165291,248688410,13.55000000,10,1,13.54000000,100,1,13.38000000,33,1,13.37000000,100,1,13.31000000,10,1,13.30000000,100,1,13.28000000,11,2,13.27000000,110,2,13.26000000,204,4,13.25000000,111,2,13.40000000,208,12,13.67000000,100,1,13.71000000,1,1,13.73000000,15,1,13.74000000,100,1,13.76000000,115,2,13.77000000,115,2,13.78000000,204,4,13.79000000,100,1,13.80000000,515,6,ARL,296391881
989,2025-07-17T15:39:41.085877317Z,2025-07-17T15:39:41.085711985Z,160,2,1108,C,A,0,14.84000000,100,130,165332,248688411,13.55000000,10,1,13.54000000,100,1,13.38000000,33,1,13.37000000,100,1,13.31000000,10,1,13.30000000,100,1,13.28000000,11,2,13.27000000,110,2,13.26000000,204,4,13.25000000,111,2,13.40000000,208,12,13.67000000,100,1,13.71000000,1,1,13.73000000,15,1,13.74000000,100,1,13.76000000,115,2,13.77000000,115,2,13.78000000,204,4,13.79000000,100,1,13.80000000,515,6,ARL,146962993
990,2025-07-17T15:39:43.773811774Z,2025-07-17T15:39:43.773645905Z,160,2,1108,C,A,0,14.72000000,100,0,165869,248737506,13.55000000,10,1,13.54000000,100,1,13.38000000,33,1,13.37000000,100,1,13.31000000,10,1,13.30000000,100,1,13.28000000,11,2,13.27000000,110,2,13.26000000,204,4,13.25000000,111,2,13.40000000,208,12,13.67000000,100,1,13.71000000,1,1,13.73000000,15,1,13.74000000,100,1,13.76000000,115,2,13.77000000,115,2,13.78000000,204,4,13.79000000,100,1,13.80000000,515,6,ARL,286680577
991,2025-07-17T15:39:43.773811774Z,2025-07-17T15:39:43.773645905Z,160,2,1108,A,A,0,14.61000000,100,130,165869,248737506,13.55000000,10,1,13.54000000,100,1,13.38000000,33,1,13.37000000,100,1,13.31000000,10,1,13.30000000,100,1,13.28000000,11,2,13.27000000,110,2,13.26000000,204,4,13.25000000,111,2,13.40000000,208,12,13.67000000,100,1,13.71000000,1,1,13.73000000,15,1,13.74000000,100,1,13.76000000,115,2,13.77000000,115,2,13.78000000,204,4,13.79000000,100,1,13.80000000,515,6,ARL,296455037
992,2025-07-17T15:39:43.773904473Z,2025-07-17T15:39:43.773738855Z,160,2,1108,C,A,0,14.72000000,100,0,165618,248737508,13.55000000,10,1,13.54000000,100,1,13.38000000,33,1,13.37000000,100,1,13.31000000,10,1,13.30000000,100,1,13.28000000,11,2,13.27000000,110,2,13.26000000,204,4,13.25000000,111,2,13.40000000,208,12,13.67000000,100,1,13.71000000,1,1,13.73000000,15,1,13.74000000,100,1,13.76000000,115,2,13.77000000,115,2,13.78000000,204,4,13.79000000,100,1,13.80000000,515,6,ARL,286680573
993,2025-07-17T15:39:43.773904473Z,2025-07-17T15:39:43.773738855Z,160,2,1108,A,A,0,14.61000000,100,130,165618,248737508,13.55000000,10,1,13.54000000,100,1,13.38000000,33,1,13.37000000,100,1,13.31000000,10,1,13.30000000,100,1,13.28000000,11,2,13.27000000,110,2,13.26000000,204,4,13.25000000,111,2,13.40000000,208,12,13.67000000,100,1,13.71000000,1,1,13.73000000,15,1,13.74000000,100,1,13.76000000,115,2,13.77000000,115,2,13.78000000,204,4,13.79000000,100,1,13.80000000,515,6,ARL,296455041
994,2025-07-17T15:39:44.428670900Z,2025-07-17T15:39:44.428505546Z,160,2,1108,C,A,0,13.76000000,15,130,165354,248751670,13.55000000,10,1,13.54000000,100,1,13.38000000,33,1,13.37000000,100,1,13.31000000,10,1,13.30000000,100,1,13.28000000,11,2,13.27000000,110,2,13.26000000,204,4,13.25000000,111,2,13.40000000,208,12,13.67000000,100,1,13.71000000,1,1,13.73000000,15,1,13.74000000,100,1,13.76000000,115,2,13.77000000,115,2,13.78000000,204,4,13.79000000,100,1,13.80000000,515,6,ARL,296136617
995,2025-07-17T15:39:44.433539292Z,2025-07-17T15:39:44.433372235Z,160,2,1108,C,A,0,13.73000000,15,128,167057,248752483,13.55000000,10,1,13.54000000,100,1,13.38000000,33,1,13.37000000,100,1,13.31000000,10,1,13.30000000,100,1,13.28000000,11,2,13.27000000,110,2,13.26000000,204,4,13.25000000,111,2,13.40000000,208,12,13.67000000,100,1,13.71000000,1,1,13.73000000,15,1,13.74000000,100,1,13.76000000,115,2,13.77000000,115,2,13.78000000,204,4,13.79000000,100,1,13.80000000,515,6,ARL,296365029
996,2025-07-17T15:39:44.436054885Z,2025-07-17T15:39:44.435889060Z,160,2,1108,C,A,0,13.74000000,100,130,165825,248752938,13.55000000,10,1,13.54000000,100,1,13.38000000,33,1,13.37000000,100,1,13.31000000,10,1,13.30000000,100,1,13.28000000,11,2,13.27000000,110,2,13.26000000,204,4,13.25000000,111,2,13.40000000,208,12,13.67000000,100,1,13.71000000,1,1,13.73000000,15,1,13.74000000,100,1,13.76000000,115,2,13.77000000,115,2,13.78000000,204,4,13.79000000,100,1,13.80000000,515,6,ARL,296368281
997,2025-07-17T15:39:44.450239090Z,2025-07-17T15:39:44.450073949Z,160,2,1108,C,A,0,13.76000000,100,130,165141,248753643,13.55000000,10,1,13.54000000,100,1,13.38000000,33,1,13.37000000,100,1,13.31000000,10,1,13.30000000,100,1,13.28000000,11,2,13.27000000,110,2,13.26000000,204,4,13.25000000,111,2,13.40000000,208,12,13.67000000,100,1,13.71000000,1,1,13.73000000,15,1,13.74000000,100,1,13.76000000,115,2,13.77000000,115,2,13.78000000,204,4,13.79000000,100,1,13.80000000,515,6,ARL,296372577
998,2025-07-17T15:39:44.450972330Z,2025-07-17T15:39:44.450806746Z,160,2,1108,C,A,0,14.81000000,100,0,165584,248753673,13.55000000,10,1,13.54000000,100,1,13.38000000,33,1,13.37000000,100,1,13.31000000,10,1,13.30000000,100,1,13.28000000,11,2,13.27000000,110,2,13.26000000,204,4,13.25000000,111,2,13.40000000,208,12,13.67000000,100,1,13.71000000,1,1,13.73000000,15,1,13.74000000,100,1,13.76000000,115,2,13.77000000,115,2,13.78000000,204,4,13.79000000,100,1,13.80000000,515,6,ARL,296368709
999,2025-07-17T15:39:44.450972330Z,2025-07-17T15:39:44.450806746Z,160,2,1108,A,A,0,15.06000000,100,130,165584,248753673,13.55000000,10,1,13.54000000,100,1,13.38000000,33,1,13.37000000,100,1,13.31000000,10,1,13.30000000,100,1,13.28000000,11,2,13.27000000,110,2,13.26000000,204,4,13.25000000,111,2,13.40000000,208,12,13.67000000,100,1,13.71000000,1,1,13.73000000,15,1,13.74000000,100,1,13.76000000,115,2,13.77000000,115,2,13.78000000,204,4,13.79000000,100,1,13.80000000,515,6,ARL,296478965
1000,2025-07-17T15:39:44.451075992Z,2025-07-17T15:39:44.450910591Z,160,2,1108,C,A,0,13.95000000,2,0,165401,248753678,13.55000000,10,1,13.54000000,100,1,13.38000000,33,1,13.37000000,100,1,13.31000000,10,1,13.30000000,100,1,13.28000000,11,2,13.27000000,110,2,13.26000000,204,4,13.25000000,111,2,13.40000000,208,12,13.67000000,100,1,13.71000000,1,1,13.73000000,15,1,13.74000000,100,1,13.76000000,115,2,13.77000000,115,2,13.78000000,204,4,13.79000000,100,1,13.80000000,515,6,ARL,287540393
1001,2025-07-17T15:39:44.451075992Z,2025-07-17T15:39:44.450910591Z,160,2,1108,A,A,0,14.07000000,2,130,165401,248753678,13.55000000,10,1,13.54000000,100,1,13.38000000,33,1,13.37000000,100,1,13.31000000,10,1,13.30000000,100,1,13.28000000,11,2,13.27000000,110,2,13.26000000,204,4,13.25000000,111,2,13.40000000,208,12,13.67000000,100,1,13.71000000,1,1,13.73000000,15,1,13.74000000,100,1,13.76000000,115,2,13.77000000,115,2,13.78000000,204,4,13.79000000,100,1,13.80000000,515,6,ARL,296478973
1002,2025-07-17T15:39:44.455130297Z,2025-07-17T15:39:44.454964327Z,160,2,1108,C,A,0,14.81000000,100,0,165970,248753748,13.55000000,10,1,13.54000000,100,1,13.38000000,33,1,13.37000000,100,1,13.31000000,10,1,13.30000000,100,1,13.28000000,11,2,13.27000000,110,2,13.26000000,204,4,13.25000000,111,2,13.40000000,208,12,13.67000000,100,1,13.71000000,1,1,13.73000000,15,1,13.74000000,100,1,13.76000000,115,2,13.77000000,115,2,13.78000000,204,4,13.79000000,100,1,13.80000000,515,6,ARL,286680741
1003,2025-07-17T15:39:44.455130297Z,2025-07-17T15:39:44.454964327Z,160,2,1108,A,A,0,14.96000000,100,130,165970,248753748,13.55000000,10,1,13.54000000,100,1,13.38000000,33,1,13.37000000,100,1,13.31000000,10,1,13.30000000,100,1,13.28000000,11,2,13.27000000,110,2,13.26000000,204,4,13.25000000,111,2,13.40000000,208,12,13.67000000,100,1,13.71000000,1,1,13.73000000,15,1,13.74000000,100,1,13.76000000,115,2,13.77000000,115,2,13.78000000,204,4,13.79000000,100,1,13.80000000,515,6,ARL,296479053
1004,2025-07-17T15:39:44.456288062Z,2025-07-17T15:39:44.456122660Z,160,2,1108,C,A,0,14.65000000,100,130,165402,248753812,13.55000000,10,1,13.54000000,100,1,13.38000000,33,1,13.37000000,100,1,13.31000000,10,1,13.30000000,100,1,13.28000000,11,2,13.27000000,110,2,13.26000000,204,4,13.25000000,111,2,13.40000000,208,12,13.67000000,100,1,13.71000000,1,1,13.73000000,15,1,13.74000000,100,1,13.76000000,115,2,13.77000000,115,2,13.78000000,204,4,13.79000000,100,1,13.80000000,515,6,ARL,286680905
1005,2025-07-17T15:39:44.456377500Z,2025-07-17T15:39:44.456211953Z,160,2,1108,A,A,0,14.78000000,100,130,165547,248753815,13.55000000,10,1,13.54000000,100,1,13.38000000,33,1,13.37000000,100,1,13.31000000,10,1,13.30000000,100,1,13.28000000,11,2,13.27000000,110,2,13.26000000,204,4,13.25000000,111,2,13.40000000,208,12,13.67000000,100,1,13.71000000,1,1,13.73000000,15,1,13.74000000,100,1,13.76000000,115,2,13.77000000,115,2,13.78000000,204,4,13.79000000,100,1,13.80000000,515,6,ARL,296479285
1006,2025-07-17T15:39:44.462055094Z,2025-07-17T15:39:44.461889886Z,160,2,1108,C,A,0,14.05000000,100,130,165208,248753947,13.55000000,10,1,13.54000000,100,1,13.38000000,33,1,13.37000000,100,1,13.31000000,10,1,13.30000000,100,1,13.28000000,11,2,13.27000000,110,2,13.26000000,204,4,13.25000000,111,2,13.40000000,208,12,13.67000000,100,1,13.71000000,1,1,13.73000000,15,1,13.74000000,100,1,13.76000000,115,2,13.77000000,115,2,13.78000000,204,4,13.79000000,100,1,13.80000000,515,6,ARL,296137769
1007,2025-07-17T15:39:44.462108809Z,2025-07-17T15:39:44.461943584Z,160,2,1108,A,A,0,14.26000000,100,130,165225,248753952,13.55000000,10,1,13.54000000,100,1,13.38000000,33,1,13.37000000,100,1,13.31000000,10,1,13.30000000,100,1,13.28000000,11,2,13.27000000,110,2,13.26000000,204,4,13.25000000,111,2,13.40000000,208,12,13.67000000,100,1,13.71000000,1,1,13.73000000,15,1,13.74000000,100,1,13.76000000,115,2,13.77000000,115,2,13.78000000,204,4,13.79000000,100,1,13.80000000,515,6,ARL,296479425
1008,2025-07-17T15:39:44.478923366Z,2025-07-17T15:39:44.478757958Z,160,2,1108,C,A,0,17.58000000,100,0,165408,248754361,13.55000000,10,1,13.54000000,100,1,13.38000000,33,1,13.37000000,100,1,13.31000000,10,1,13.30000000,100,1,13.28000000,11,2,13.27000000,110,2,13.26000000,204,4,13.25000000,111,2,13.40000000,208,12,13.67000000,100,1,13.71000000,1,1,13.73000000,15,1,13.74000000,100,1,13.76000000,115,2,13.77000000,115,2,13.78000000,204,4,13.79000000,100,1,13.80000000,515,6,ARL,286681057
1009,2025-07-17T15:39:44.478923366Z,2025-07-17T15:39:44.478757958Z,160,2,1108,A,A,0,17.76000000,100,130,165408,248754361,13.55000000,10,1,13.54000000,100,1,13.38000000,33,1,13.37000000,100,1,13.31000000,10,1,13.30000000,100,1,13.28000000,11,2,13.27000000,110,2,13.26000000,204,4,13.25000000,111,2,13.40000000,208,12,13.67000000,100,1,13.71000000,1,1,13.73000000,15,1,13.74000000,100,1,13.76000000,115,2,13.77000000,115,2,13.78000000,204,4,13.79000000,100,1,13.80000000,515,6,ARL,296479893
1010,2025-07-17T15:39:44.491018431Z,2025-07-17T15:39:44.490852860Z,160,2,1108,C,A,0,15.92000000,100,0,165571,248754608,13.55000000,10,1,13.54000000,100,1,13.38000000,33,1,13.37000000,100,1,13.31000000,10,1,13.30000000,100,1,13.28000000,11,2,13.27000000,110,2,13.26000000,204,4,13.25000000,111,2,13.40000000,208,12,13.67000000,100,1,13.71000000,1,1,13.73000000,15,1,13.74000000,100,1,13.76000000,115,2,13.77000000,115,2,13.78000000,204,4,13.79000000,100,1,13.80000000,515,6,ARL,286681229
1011,2025-07-17T15:39:44.491018431Z,2025-07-17T15:39:44.490852860Z,160,2,1108,A,A,0,16.08000000,100,130,165571,248754608,13.55000000,10,1,13.54000000,100,1,13.38000000,33,1,13.37000000,100,1,13.31000000,10,1,13.30000000,100,1,13.28000000,11,2,13.27000000,110,2,13.26000000,204,4,13.25000000,111,2,13.40000000,208,12,13.67000000,100,1,13.71000000,1,1,13.73000000,15,1,13.74000000,100,1,13.76000000,115,2,13.77000000,115,2,13.78000000,204,4,13.79000000,100,1,13.80000000,515,6,ARL,296480097
1012,2025-07-17T15:39:44.593773213Z,2025-07-17T15:39:44.593607433Z,160,2,1108,C,A,0,14.81000000,100,0,165780,248756227,13.55000000,10,1,13.54000000,100,1,13.38000000,33,1,13.37000000,100,1,13.31000000,10,1,13.30000000,100,1,13.28000000,11,2,13.27000000,110,2,13.26000000,204,4,13.25000000,111,2,13.40000000,208,12,13.67000000,100,1,13.71000000,1,1,13.73000000,15,1,13.74000000,100,1,13.76000000,115,2,13.77000000,115,2,13.78000000,204,4,13.79000000,100,1,13.80000000,515,6,ARL,286684005
1013,2025-07-17T15:39:44.593773213Z,2025-07-17T15:39:44.593607433Z,160,2,1108,A,A,0,14.96000000,100,130,165780,248756227,13.55000000,10,1,13.54000000,100,1,13.38000000,33,1,13.37000000,100,1,13.31000000,10,1,13.30000000,100,1,13.28000000,11,2,13.27000000,110,2,13.26000000,204,4,13.25000000,111,2,13.40000000,208,12,13.67000000,100,1,13.71000000,1,1,13.73000000,15,1,13.74000000,100,1,13.76000000,115,2,13.77000000,115,2,13.78000000,204,4,13.79000000,100,1,13.80000000,515,6,ARL,296482509
1014,2025-07-17T15:39:44.859886562Z,2025-07-17T15:39:44.859720946Z,160,2,1108,C,A,0,14.61000000,100,0,165616,248760319,13.55000000,10,1,13.54000000,100,1,13.38000000,33,1,13.37000000,100,1,13.31000000,10,1,13.30000000,100,1,13.28000000,11,2,13.27000000,110,2,13.26000000,204,4,13.25000000,111,2,13.40000000,208,12,13.67000000,100,1,13.71000000,1,1,13.73000000,15,1,13.74000000,100,1,13.76000000,115,2,13.77000000,115,2,13.78000000,204,4,13.79000000,100,1,13.80000000,515,6,ARL,296455041
1015,2025-07-17T15:39:44.859886562Z,2025-07-17T15:39:44.859720946Z,160,2,1108,A,A,0,15.10000000,100,130,165616,248760319,13.55000000,10,1,13.54000000,100,1,13.38000000,33,1,13.37000000,100,1,13.31000000,10,1,13.30000000,100,1,13.28000000,11,2,13.27000000,110,2,13.26000000,204,4,13.25000000,111,2,13.40000000,208,12,13.67000000,100,1,13.71000000,1,1,13.73000000,15,1,13.74000000,100,1,13.76000000,115,2,13.77000000,115,2,13.78000000,204,4,13.79000000,100,1,13.80000000,515,6,ARL,296485621
1016,2025-07-17T15:39:44.860160096Z,2025-07-17T15:39:44.859994671Z,160,2,1108,A,A,0,14.08000000,100,130,165425,248760324,13.55000000,10,1,13.54000000,100,1,13.38000000,33,1,13.37000000,100,1,13.31000000,10,1,13.30000000,100,1,13.28000000,11,2,13.27000000,110,2,13.26000000,204,4,13.25000000,111,2,13.40000000,208,12,13.67000000,100,1,13.71000000,1,1,13.73000000,15,1,13.74000000,100,1,13.76000000,115,2,13.77000000,115,2,13.78000000,204,4,13.79000000,100,1,13.80000000,515,6,ARL,296485629
1017,2025-07-17T15:39:44.863678795Z,2025-07-17T15:39:44.863513587Z,160,2,1108,C,A,0,14.61000000,100,0,165208,248760417,13.55000000,10,1,13.54000000,100,1,13.38000000,33,1,13.37000000,100,1,13.31000000,10,1,13.30000000,100,1,13.28000000,11,2,13.27000000,110,2,13.26000000,204,4,13.25000000,111,2,13.40000000,208,12,13.67000000,100,1,13.71000000,1,1,13.73000000,15,1,13.74000000,100,1,13.76000000,115,2,13.77000000,115,2,13.78000000,204,4,13.79000000,100,1,13.80000000,515,6,ARL,296455037
1018,2025-07-17T15:39:44.863678795Z,2025-07-17T15:39:44.863513587Z,160,2,1108,A,A,0,15.10000000,100,130,165208,248760417,13.55000000,10,1,13.54000000,100,1,13.38000000,33,1,13.37000000,100,1,13.31000000,10,1,13.30000000,100,1,13.28000000,11,2,13.27000000,110,2,13.26000000,204,4,13.25000000,111,2,13.40000000,208,12,13.67000000,100,1,13.71000000,1,1,13.73000000,15,1,13.74000000,100,1,13.76000000,115,2,13.77000000,115,2,13.78000000,204,4,13.79000000,100,1,13.80000000,515,6,ARL,296485649
1019,2025-07-17T15:39:54.187008224Z,2025-07-17T15:39:54.186842327Z,160,2,1108,C,A,0,15.10000000,100,0,165897,248915116,13.55000000,10,1,13.54000000,100,1,13.38000000,33,1,13.37000000,100,1,13.31000000,10,1,13.30000000,100,1,13.28000000,11,2,13.27000000,110,2,13.26000000,204,4,13.25000000,111,2,13.40000000,208,12,13.67000000,100,1,13.71000000,1,1,13.73000000,15,1,13.74000000,100,1,13.76000000,115,2,13.77000000,115,2,13.78000000,204,4,13.79000000,100,1,13.80000000,515,6,ARL,296485649
1020,2025-07-17T15:39:54.187008224Z,2025-07-17T15:39:54.186842327Z,160,2,1108,A,A,0,14.88000000,100,130,165897,248915116,13.55000000,10,1,13.54000000,100,1,13.38000000,33,1,13.37000000,100,1,13.31000000,10,1,13.30000000,100,1,13.28000000,11,2,13.27000000,110,2,13.26000000,204,4,13.25000000,111,2,13.40000000,208,12,13.67000000,100,1,13.71000000,1,1,13.73000000,15,1,13.74000000,100,1,13.76000000,115,2,13.77000000,115,2,13.78000000,204,4,13.79000000,100,1,13.80000000,515,6,ARL,296679277
1021,2025-07-17T15:39:54.187557412Z,2025-07-17T15:39:54.187391707Z,160,2,1108,C,A,0,15.10000000,100,0,165705,248915126,13.55000000,10,1,13.54000000,100,1,13.38000000,33,1,13.37000000,100,1,13.31000000,10,1,13.30000000,100,1,13.28000000,11,2,13.27000000,110,2,13.26000000,204,4,13.25000000,111,2,13.40000000,208,12,13.67000000,100,1,13.71000000,1,1,13.73000000,15,1,13.74000000,100,1,13.76000000,115,2,13.77000000,115,2,13.78000000,204,4,13.79000000,100,1,13.80000000,515,6,ARL,296485621
1022,2025-07-17T15:39:54.187557412Z,2025-07-17T15:39:54.187391707Z,160,2,1108,A,A,0,14.88000000,100,130,165705,248915126,13.55000000,10,1,13.54000000,100,1,13.38000000,33,1,13.37000000,100,1,13.31000000,10,1,13.30000000,100,1,13.28000000,11,2,13.27000000,110,2,13.26000000,204,4,13.25000000,111,2,13.40000000,208,12,13.67000000,100,1,13.71000000,1,1,13.73000000,15,1,13.74000000,100,1,13.76000000,115,2,13.77000000,115,2,13.78000000,204,4,13.79000000,100,1,13.80000000,515,6,ARL,296679285
1023,2025-07-17T15:42:06.780503054Z,2025-07-17T15:42:06.780337543Z,160,2,1108,A,A,0,13.90000000,15,130,165511,251407709,13.55000000,10,1,13.54000000,100,1,13.38000000,33,1,13.37000000,100,1,13.31000000,10,1,13.30000000,100,1,13.28000000,11,2,13.27000000,110,2,13.26000000,204,4,13.25000000,111,2,13.40000000,208,12,13.67000000,100,1,13.71000000,1,1,13.73000000,15,1,13.74000000,100,1,13.76000000,115,2,13.77000000,115,2,13.78000000,204,4,13.79000000,100,1,13.80000000,515,6,ARL,299689753
1024,2025-07-17T15:42:06.780767761Z,2025-07-17T15:42:06.780602350Z,160,2,1108,C,A,0,14.08000000,100,0,165411,251407713,13.55000000,10,1,13.54000000,100,1,13.38000000,33,1,13.37000000,100,1,13.31000000,10,1,13.30000000,100,1,13.28000000,11,2,13.27000000,110,2,13.26000000,204,4,13.25000000,111,2,13.40000000,208,12,13.67000000,100,1,13.71000000,1,1,13.73000000,15,1,13.74000000,100,1,13.76000000,115,2,13.77000000,115,2,13.78000000,204,4,13.79000000,100,1,13.80000000,515,6,ARL,296485629
1025,2025-07-17T15:42:06.780767761Z,2025-07-17T15:42:06.780602350Z,160,2,1108,A,A,0,13.91000000,100,130,165411,251407713,13.55000000,10,1,13.54000000,100,1,13.38000000,33,1,13.37000000,100,1,13.31000000,10,1,13.30000000,100,1,13.28000000,11,2,13.27000000,110,2,13.26000000,204,4,13.25000000,111,2,13.40000000,208,12,13.67000000,100,1,13.71000000,1,1,13.73000000,15,1,13.74000000,100,1,13.76000000,115,2,13.77000000,115,2,13.78000000,204,4,13.79000000,100,1,13.80000000,515,6,ARL,299689769
1026,2025-07-17T15:42:06.781502831Z,2025-07-17T15:42:06.781336642Z,160,2,1108,C,A,0,15.06000000,100,0,166189,251407747,13.55000000,10,1,13.54000000,100,1,13.38000000,33,1,13.37000000,100,1,13.31000000,10,1,13.30000000,100,1,13.28000000,11,2,13.27000000,110,2,13.26000000,204,4,13.25000000,111,2,13.40000000,208,12,13.67000000,100,1,13.71000000,1,1,13.73000000,15,1,13.74000000,100,1,13.76000000,115,2,13.77000000,115,2,13.78000000,204,4,13.79000000,100,1,13.80000000,515,6,ARL,296478965
1027,2025-07-17T15:42:06.781502831Z,2025-07-17T15:42:06.781336642Z,160,2,1108,A,A,0,14.99000000,100,130,166189,251407747,13.55000000,10,1,13.54000000,100,1,13.38000000,33,1,13.37000000,100,1,13.31000000,10,1,13.30000000,100,1,13.28000000,11,2,13.27000000,110,2,13.26000000,204,4,13.25000000,111,2,13.40000000,208,12,13.67000000,100,1,13.71000000,1,1,13.73000000,15,1,13.74000000,100,1,13.76000000,115,2,13.77000000,115,2,13.78000000,204,4,13.79000000,100,1,13.80000000,515,6,ARL,299689857
1028,2025-07-17T15:42:06.795521307Z,2025-07-17T15:42:06.795355762Z,160,2,1108,C,A,0,14.26000000,100,130,165545,251408268,13.55000000,10,1,13.54000000,100,1,13.38000000,33,1,13.37000000,100,1,13.31000000,10,1,13.30000000,100,1,13.28000000,11,2,13.27000000,110,2,13.26000000,204,4,13.25000000,111,2,13.40000000,208,12,13.67000000,100,1,13.71000000,1,1,13.73000000,15,1,13.74000000,100,1,13.76000000,115,2,13.77000000,115,2,13.78000000,204,4,13.79000000,100,1,13.80000000,515,6,ARL,296479425
1029,2025-07-17T15:42:06.795573392Z,2025-07-17T15:42:06.795408057Z,160,2,1108,A,A,0,14.19000000,100,130,165335,251408269,13.55000000,10,1,13.54000000,100,1,13.38000000,33,1,13.37000000,100,1,13.31000000,10,1,13.30000000,100,1,13.28000000,11,2,13.27000000,110,2,13.26000000,204,4,13.25000000,111,2,13.40000000,208,12,13.67000000,100,1,13.71000000,1,1,13.73000000,15,1,13.74000000,100,1,13.76000000,115,2,13.77000000,115,2,13.78000000,204,4,13.79000000,100,1,13.80000000,515,6,ARL,299690593
1030,2025-07-17T15:42:16.264132159Z,2025-07-17T15:42:16.263966448Z,160,2,1108,C,A,0,14.88000000,100,0,165711,251574391,13.55000000,10,1,13.54000000,100,1,13.38000000,33,1,13.37000000,100,1,13.31000000,10,1,13.30000000,100,1,13.28000000,11,2,13.27000000,110,2,13.26000000,204,4,13.25000000,111,2,13.40000000,208,12,13.67000000,100,1,13.71000000,1,1,13.73000000,15,1,13.74000000,100,1,13.76000000,115,2,13.77000000,115,2,13.78000000,204,4,13.79000000,100,1,13.80000000,515,6,ARL,296679285
1031,2025-07-17T15:42:16.264132159Z,2025-07-17T15:42:16.263966448Z,160,2,1108,A,A,0,14.76000000,100,130,165711,251574391,13.55000000,10,1,13.54000000,100,1,13.38000000,33,1,13.37000000,100,1,13.31000000,10,1,13.30000000,100,1,13.28000000,11,2,13.27000000,110,2,13.26000000,204,4,13.25000000,111,2,13.40000000,208,12,13.67000000,100,1,13.71000000,1,1,13.73000000,15,1,13.74000000,100,1,13.76000000,115,2,13.77000000,115,2,13.78000000,204,4,13.79000000,100,1,13.80000000,515,6,ARL,299903169
1032,2025-07-17T15:42:17.356766715Z,2025-07-17T15:42:17.356601231Z,160,2,1108,A,A,0,13.83000000,15,130,165484,251593608,13.55000000,10,1,13.54000000,100,1,13.38000000,33,1,13.37000000,100,1,13.31000000,10,1,13.30000000,100,1,13.28000000,11,2,13.27000000,110,2,13.26000000,204,4,13.25000000,111,2,13.40000000,208,12,13.67000000,100,1,13.71000000,1,1,13.73000000,15,1,13.74000000,100,1,13.76000000,115,2,13.77000000,115,2,13.78000000,204,4,13.79000000,100,1,13.80000000,515,6,ARL,299923773
1033,2025-07-17T15:42:17.577474246Z,2025-07-17T15:42:17.577308779Z,160,2,1108,C,A,0,13.91000000,100,0,165467,251595553,13.55000000,10,1,13.54000000,100,1,13.38000000,33,1,13.37000000,100,1,13.31000000,10,1,13.30000000,100,1,13.28000000,11,2,13.27000000,110,2,13.26000000,204,4,13.25000000,111,2,13.40000000,208,12,13.67000000,100,1,13.71000000,1,1,13.73000000,15,1,13.74000000,100,1,13.76000000,115,2,13.77000000,115,2,13.78000000,204,4,13.79000000,100,1,13.80000000,515,6,ARL,299689769
1034,2025-07-17T15:42:17.577474246Z,2025-07-17T15:42:17.577308779Z,160,2,1108,A,A,0,13.84000000,100,130,165467,251595553,13.55000000,10,1,13.54000000,100,1,13.38000000,33,1,13.37000000,100,1,13.31000000,10,1,13.30000000,100,1,13.28000000,11,2,13.27000000,110,2,13.26000000,204,4,13.25000000,111,2,13.40000000,208,12,13.67000000,100,1,13.71000000,1,1,13.73000000,15,1,13.74000000,100,1,13.76000000,115,2,13.77000000,115,2,13.78000000,204,4,13.79000000,100,1,13.80000000,515,6,ARL,299926781
1035,2025-07-17T15:42:17.578219175Z,2025-07-17T15:42:17.578053644Z,160,2,1108,C,A,0,14.99000000,100,0,165531,251595563,13.55000000,10,1,13.54000000,100,1,13.38000000,33,1,13.37000000,100,1,13.31000000,10,1,13.30000000,100,1,13.28000000,11,2,13.27000000,110,2,13.26000000,204,4,13.25000000,111,2,13.40000000,208,12,13.67000000,100,1,13.71000000,1,1,13.73000000,15,1,13.74000000,100,1,13.76000000,115,2,13.77000000,115,2,13.78000000,204,4,13.79000000,100,1,13.80000000,515,6,ARL,299689857
1036,2025-07-17T15:42:17.578219175Z,2025-07-17T15:42:17.578053644Z,160,2,1108,A,A,0,14.91000000,100,130,165531,251595563,13.55000000,10,1,13.54000000,100,1,13.38000000,33,1,13.37000000,100,1,13.31000000,10,1,13.30000000,100,1,13.28000000,11,2,13.27000000,110,2,13.26000000,204,4,13.25000000,111,2,13.40000000,208,12,13.67000000,100,1,13.71000000,1,1,13.73000000,15,1,13.74000000,100,1,13.76000000,115,2,13.77000000,115,2,13.78000000,204,4,13.79000000,100,1,13.80000000,515,6,ARL,299926801
1037,2025-07-17T15:42:17.579343189Z,2025-07-17T15:42:17.579177582Z,160,2,1108,C,A,0,14.78000000,100,0,165607,251595571,13.55000000,10,1,13.54000000,100,1,13.38000000,33,1,13.37000000,100,1,13.31000000,10,1,13.30000000,100,1,13.28000000,11,2,13.27000000,110,2,13.26000000,204,4,13.25000000,111,2,13.40000000,208,12,13.67000000,100,1,13.71000000,1,1,13.73000000,15,1,13.74000000,100,1,13.76000000,115,2,13.77000000,115,2,13.78000000,204,4,13.79000000,100,1,13.80000000,515,6,ARL,296479285
1038,2025-07-17T15:42:17.579343189Z,2025-07-17T15:42:17.579177582Z,160,2,1108,A,A,0,14.64000000,100,130,165607,251595571,13.55000000,10,1,13.54000000,100,1,13.38000000,33,1,13.37000000,100,1,13.31000000,10,1,13.30000000,100,1,13.28000000,11,2,13.27000000,110,2,13.26000000,204,4,13.25000000,111,2,13.40000000,208,12,13.67000000,100,1,13.71000000,1,1,13.73000000,15,1,13.74000000,100,1,13.76000000,115,2,13.77000000,115,2,13.78000000,204,4,13.79000000,100,1,13.80000000,515,6,ARL,299926813
1039,2025-07-17T15:42:17.580008869Z,2025-07-17T15:42:17.579843331Z,160,2,1108,C,A,0,14.96000000,100,0,165538,251595576,13.55000000,10,1,13.54000000,100,1,13.38000000,33,1,13.37000000,100,1,13.31000000,10,1,13.30000000,100,1,13.28000000,11,2,13.27000000,110,2,13.26000000,204,4,13.25000000,111,2,13.40000000,208,12,13.67000000,100,1,13.71000000,1,1,13.73000000,15,1,13.74000000,100,1,13.76000000,115,2,13.77000000,115,2,13.78000000,204,4,13.79000000,100,1,13.80000000,515,6,ARL,296479053
1040,2025-07-17T15:42:17.580008869Z,2025-07-17T15:42:17.579843331Z,160,2,1108,A,A,0,14.81000000,100,130,165538,251595576,13.55000000,10,1,13.54000000,100,1,13.38000000,33,1,13.37000000,100,1,13.31000000,10,1,13.30000000,100,1,13.28000000,11,2,13.27000000,110,2,13.26000000,204,4,13.25000000,111,2,13.40000000,208,12,13.67000000,100,1,13.71000000,1,1,13.73000000,15,1,13.74000000,100,1,13.76000000,115,2,13.77000000,115,2,13.78000000,204,4,13.79000000,100,1,13.80000000,515,6,ARL,299926849
1041,2025-07-17T15:42:17.580035793Z,2025-07-17T15:42:17.579870309Z,160,2,1108,C,A,0,16.08000000,100,0,165484,251595577,13.55000000,10,1,13.54000000,100,1,13.38000000,33,1,13.37000000,100,1,13.31000000,10,1,13.30000000,100,1,13.28000000,11,2,13.27000000,110,2,13.26000000,204,4,13.25000000,111,2,13.40000000,208,12,13.67000000,100,1,13.71000000,1,1,13.73000000,15,1,13.74000000,100,1,13.76000000,115,2,13.77000000,115,2,13.78000000,204,4,13.79000000,100,1,13.80000000,515,6,ARL,296480097
1042,2025-07-17T15:42:17.580035793Z,2025-07-17T15:42:17.579870309Z,160,2,1108,A,A,0,15.92000000,100,130,165484,251595577,13.55000000,10,1,13.54000000,100,1,13.38000000,33,1,13.37000000,100,1,13.31000000,10,1,13.30000000,100,1,13.28000000,11,2,13.27000000,110,2,13.26000000,204,4,13.25000000,111,2,13.40000000,208,12,13.67000000,100,1,13.71000000,1,1,13.73000000,15,1,13.74000000,100,1,13.76000000,115,2,13.77000000,115,2,13.78000000,204,4,13.79000000,100,1,13.80000000,515,6,ARL,299926853
1043,2025-07-17T15:42:17.580061097Z,2025-07-17T15:42:17.579895610Z,160,2,1108,C,A,0,14.96000000,100,0,165487,251595578,13.55000000,10,1,13.54000000,100,1,13.38000000,33,1,13.37000000,100,1,13.31000000,10,1,13.30000000,100,1,13.28000000,11,2,13.27000000,110,2,13.26000000,204,4,13.25000000,111,2,13.40000000,208,12,13.67000000,100,1,13.71000000,1,1,13.73000000,15,1,13.74000000,100,1,13.76000000,115,2,13.77000000,115,2,13.78000000,204,4,13.79000000,100,1,13.80000000,515,6,ARL,296482509
1044,2025-07-17T15:42:17.580061097Z,2025-07-17T15:42:17.579895610Z,160,2,1108,A,A,0,14.81000000,100,130,165487,251595578,13.55000000,10,1,13.54000000,100,1,13.38000000,33,1,13.37000000,100,1,13.31000000,10,1,13.30000000,100,1,13.28000000,11,2,13.27000000,110,2,13.26000000,204,4,13.25000000,111,2,13.40000000,208,12,13.67000000,100,1,13.71000000,1,1,13.73000000,15,1,13.74000000,100,1,13.76000000,115,2,13.77000000,115,2,13.78000000,204,4,13.79000000,100,1,13.80000000,515,6,ARL,299926857
1045,2025-07-17T15:42:17.580093535Z,2025-07-17T15:42:17.579928136Z,160,2,1108,C,A,0,17.76000000,100,0,165399,251595580,13.55000000,10,1,13.54000000,100,1,13.38000000,33,1,13.37000000,100,1,13.31000000,10,1,13.30000000,100,1,13.28000000,11,2,13.27000000,110,2,13.26000000,204,4,13.25000000,111,2,13.40000000,208,12,13.67000000,100,1,13.71000000,1,1,13.73000000,15,1,13.74000000,100,1,13.76000000,115,2,13.77000000,115,2,13.78000000,204,4,13.79000000,100,1,13.80000000,515,6,ARL,296479893
1046,2025-07-17T15:42:17.580093535Z,2025-07-17T15:42:17.579928136Z,160,2,1108,A,A,0,17.58000000,100,130,165399,251595580,13.55000000,10,1,13.54000000,100,1,13.38000000,33,1,13.37000000,100,1,13.31000000,10,1,13.30000000,100,1,13.28000000,11,2,13.27000000,110,2,13.26000000,204,4,13.25000000,111,2,13.40000000,208,12,13.67000000,100,1,13.71000000,1,1,13.73000000,15,1,13.74000000,100,1,13.76000000,115,2,13.77000000,115,2,13.78000000,204,4,13.79000000,100,1,13.80000000,515,6,ARL,299926861
1047,2025-07-17T15:42:17.589263550Z,2025-07-17T15:42:17.589098227Z,160,2,1108,C,A,0,14.19000000,100,130,165323,251595691,13.55000000,10,1,13.54000000,100,1,13.38000000,33,1,13.37000000,100,1,13.31000000,10,1,13.30000000,100,1,13.28000000,11,2,13.27000000,110,2,13.26000000,204,4,13.25000000,111,2,13.40000000,208,12,13.67000000,100,1,13.71000000,1,1,13.73000000,15,1,13.74000000,100,1,13.76000000,115,2,13.77000000,115,2,13.78000000,204,4,13.79000000,100,1,13.80000000,515,6,ARL,299690593
1048,2025-07-17T15:42:17.589316911Z,2025-07-17T15:42:17.589151325Z,160,2,1108,A,A,0,14.12000000,100,130,165586,251595692,13.55000000,10,1,13.54000000,100,1,13.38000000,33,1,13.37000000,100,1,13.31000000,10,1,13.30000000,100,1,13.28000000,11,2,13.27000000,110,2,13.26000000,204,4,13.25000000,111,2,13.40000000,208,12,13.67000000,100,1,13.71000000,1,1,13.73000000,15,1,13.74000000,100,1,13.76000000,115,2,13.77000000,115,2,13.78000000,204,4,13.79000000,100,1,13.80000000,515,6,ARL,299926965
1049,2025-07-17T15:42:18.398220000Z,2025-07-17T15:42:18.398054465Z,160,2,1108,C,A,0,14.88000000,100,0,165535,251612478,13.55000000,10,1,13.54000000,100,1,13.38000000,33,1,13.37000000,100,1,13.31000000,10,1,13.30000000,100,1,13.28000000,11,2,13.27000000,110,2,13.26000000,204,4,13.25000000,111,2,13.40000000,208,12,13.67000000,100,1,13.71000000,1,1,13.73000000,15,1,13.74000000,100,1,13.76000000,115,2,13.77000000,115,2,13.78000000,204,4,13.79000000,100,1,13.80000000,515,6,ARL,296679277
1050,2025-07-17T15:42:18.398220000Z,2025-07-17T15:42:18.398054465Z,160,2,1108,A,A,0,14.73000000,100,130,165535,251612478,13.55000000,10,1,13.54000000,100,1,13.38000000,33,1,13.37000000,100,1,13.31000000,10,1,13.30000000,100,1,13.28000000,11,2,13.27000000,110,2,13.26000000,204,4,13.25000000,111,2,13.40000000,208,12,13.67000000,100,1,13.71000000,1,1,13.73000000,15,1,13.74000000,100,1,13.76000000,115,2,13.77000000,115,2,13.78000000,204,4,13.79000000,100,1,13.80000000,515,6,ARL,299945073
1051,2025-07-17T15:42:21.517871714Z,2025-07-17T15:42:21.517706139Z,160,2,1108,C,A,0,13.90000000,15,130,165575,251668179,13.55000000,10,1,13.54000000,100,1,13.38000000,33,1,13.37000000,100,1,13.31000000,10,1,13.30000000,100,1,13.28000000,11,2,13.27000000,110,2,13.26000000,204,4,13.25000000,111,2,13.40000000,208,12,13.67000000,100,1,13.71000000,1,1,13.73000000,15,1,13.74000000,100,1,13.76000000,115,2,13.77000000,115,2,13.78000000,204,4,13.79000000,100,1,13.80000000,515,6,ARL,299689753
1052,2025-07-17T15:42:22.522744242Z,2025-07-17T15:42:22.522578675Z,160,2,1108,A,A,0,13.79000000,15,130,165567,251690950,13.55000000,10,1,13.54000000,100,1,13.38000000,33,1,13.37000000,100,1,13.31000000,10,1,13.30000000,100,1,13.28000000,11,2,13.27000000,110,2,13.26000000,204,4,13.25000000,111,2,13.40000000,208,12,13.67000000,100,1,13.71000000,1,1,13.73000000,15,1,13.74000000,100,1,13.76000000,115,2,13.77000000,115,2,13.78000000,204,4,13.79000000,115,2,13.80000000,515,6,ARL,300042293
1053,2025-07-17T15:42:22.533681479Z,2025-07-17T15:42:22.533515955Z,160,2,1108,A,A,0,13.82000000,100,130,165524,251691033,13.55000000,10,1,13.54000000,100,1,13.38000000,33,1,13.37000000,100,1,13.31000000,10,1,13.30000000,100,1,13.28000000,11,2,13.27000000,110,2,13.26000000,204,4,13.25000000,111,2,13.40000000,208,12,13.67000000,100,1,13.71000000,1,1,13.73000000,15,1,13.74000000,100,1,13.76000000,115,2,13.77000000,115,2,13.78000000,204,4,13.79000000,115,2,13.80000000,515,6,ARL,300042385
1054,2025-07-17T15:42:23.490247121Z,2025-07-17T15:42:23.490079821Z,160,2,1108,C,A,0,13.84000000,100,0,167300,251710173,13.55000000,10,1,13.54000000,100,1,13.38000000,33,1,13.37000000,100,1,13.31000000,10,1,13.30000000,100,1,13.28000000,11,2,13.27000000,110,2,13.26000000,204,4,13.25000000,111,2,13.40000000,208,12,13.67000000,100,1,13.71000000,1,1,13.73000000,15,1,13.74000000,100,1,13.76000000,115,2,13.77000000,115,2,13.78000000,204,4,13.79000000,115,2,13.80000000,515,6,ARL,299926781
1055,2025-07-17T15:42:23.490247121Z,2025-07-17T15:42:23.490079821Z,160,2,1108,A,A,0,13.80000000,100,128,167300,251710173,13.55000000,10,1,13.54000000,100,1,13.38000000,33,1,13.37000000,100,1,13.31000000,10,1,13.30000000,100,1,13.28000000,11,2,13.27000000,110,2,13.26000000,204,4,13.25000000,111,2,13.40000000,208,12,13.67000000,100,1,13.71000000,1,1,13.73000000,15,1,13.74000000,100,1,13.76000000,115,2,13.77000000,115,2,13.78000000,204,4,13.79000000,115,2,13.80000000,615,7,ARL,300061581
1056,2025-07-17T15:42:23.491451368Z,2025-07-17T15:42:23.491285065Z,160,2,1108,C,A,0,14.91000000,100,0,166303,251710647,13.55000000,10,1,13.54000000,100,1,13.38000000,33,1,13.37000000,100,1,13.31000000,10,1,13.30000000,100,1,13.28000000,11,2,13.27000000,110,2,13.26000000,204,4,13.25000000,111,2,13.40000000,208,12,13.67000000,100,1,13.71000000,1,1,13.73000000,15,1,13.74000000,100,1,13.76000000,115,2,13.77000000,115,2,13.78000000,204,4,13.79000000,115,2,13.80000000,615,7,ARL,299926801
1057,2025-07-17T15:42:23.491451368Z,2025-07-17T15:42:23.491285065Z,160,2,1108,A,A,0,14.87000000,100,128,166303,251710647,13.55000000,10,1,13.54000000,100,1,13.38000000,33,1,13.37000000,100,1,13.31000000,10,1,13.30000000,100,1,13.28000000,11,2,13.27000000,110,2,13.26000000,204,4,13.25000000,111,2,13.40000000,208,12,13.67000000,100,1,13.71000000,1,1,13.73000000,15,1,13.74000000,100,1,13.76000000,115,2,13.77000000,115,2,13.78000000,204,4,13.79000000,115,2,13.80000000,615,7,ARL,300061989
1058,2025-07-17T15:42:23.589065154Z,2025-07-17T15:42:23.588899941Z,160,2,1108,C,A,0,13.79000000,15,130,165213,251718746,13.55000000,10,1,13.54000000,100,1,13.38000000,33,1,13.37000000,100,1,13.31000000,10,1,13.30000000,100,1,13.28000000,11,2,13.27000000,110,2,13.26000000,204,4,13.25000000,111,2,13.40000000,208,12,13.67000000,100,1,13.71000000,1,1,13.73000000,15,1,13.74000000,100,1,13.76000000,115,2,13.77000000,115,2,13.78000000,204,4,13.79000000,115,2,13.80000000,615,7,ARL,300042293
1059,2025-07-17T15:42:23.589220778Z,2025-07-17T15:42:23.589055082Z,160,2,1108,C,A,0,13.83000000,15,130,165696,251718767,13.55000000,10,1,13.54000000,100,1,13.38000000,33,1,13.37000000,100,1,13.31000000,10,1,13.30000000,100,1,13.28000000,11,2,13.27000000,110,2,13.26000000,204,4,13.25000000,111,2,13.40000000,208,12,13.67000000,100,1,13.71000000,1,1,13.73000000,15,1,13.74000000,100,1,13.76000000,115,2,13.77000000,115,2,13.78000000,204,4,13.79000000,115,2,13.80000000,615,7,ARL,299923773
1060,2025-07-17T15:42:34.003710081Z,2025-07-17T15:42:34.003544527Z,160,2,1108,C,A,0,13.80000000,100,130,165554,251901273,13.55000000,10,1,13.54000000,100,1,13.38000000,33,1,13.37000000,100,1,13.31000000,10,1,13.30000000,100,1,13.28000000,11,2,13.27000000,110,2,13.26000000,204,4,13.25000000,111,2,13.40000000,208,12,13.67000000,100,1,13.71000000,1,1,13.73000000,15,1,13.74000000,100,1,13.76000000,115,2,13.77000000,115,2,13.78000000,204,4,13.79000000,115,2,13.80000000,615,7,ARL,300061581
1061,2025-07-17T15:42:34.003949340Z,2025-07-17T15:42:34.003783950Z,160,2,1108,C,A,0,13.82000000,100,130,165390,251901275,13.55000000,10,1,13.54000000,100,1,13.38000000,33,1,13.37000000,100,1,13.31000000,10,1,13.30000000,100,1,13.28000000,11,2,13.27000000,110,2,13.26000000,204,4,13.25000000,111,2,13.40000000,208,12,13.67000000,100,1,13.71000000,1,1,13.73000000,15,1,13.74000000,100,1,13.76000000,115,2,13.77000000,115,2,13.78000000,204,4,13.79000000,115,2,13.80000000,615,7,ARL,300042385
1062,2025-07-17T15:42:34.004225180Z,2025-07-17T15:42:34.004059450Z,160,2,1108,C,A,0,14.73000000,100,0,165730,251901280,13.55000000,10,1,13.54000000,100,1,13.38000000,33,1,13.37000000,100,1,13.31000000,10,1,13.30000000,100,1,13.28000000,11,2,13.27000000,110,2,13.26000000,204,4,13.25000000,111,2,13.40000000,208,12,13.67000000,100,1,13.71000000,1,1,13.73000000,15,1,13.74000000,100,1,13.76000000,115,2,13.77000000,115,2,13.78000000,204,4,13.79000000,115,2,13.80000000,615,7,ARL,299945073
1063,2025-07-17T15:42:34.004225180Z,2025-07-17T15:42:34.004059450Z,160,2,1108,A,A,0,14.88000000,100,130,165730,251901280,13.55000000,10,1,13.54000000,100,1,13.38000000,33,1,13.37000000,100,1,13.31000000,10,1,13.30000000,100,1,13.28000000,11,2,13.27000000,110,2,13.26000000,204,4,13.25000000,111,2,13.40000000,208,12,13.67000000,100,1,13.71000000,1,1,13.73000000,15,1,13.74000000,100,1,13.76000000,115,2,13.77000000,115,2,13.78000000,204,4,13.79000000,115,2,13.80000000,615,7,ARL,300280745
1064,2025-07-17T15:42:34.004671652Z,2025-07-17T15:42:34.004506043Z,160,2,1108,C,A,0,14.87000000,100,0,165609,251901285,13.55000000,10,1,13.54000000,100,1,13.38000000,33,1,13.37000000,100,1,13.31000000,10,1,13.30000000,100,1,13.28000000,11,2,13.27000000,110,2,13.26000000,204,4,13.25000000,111,2,13.40000000,208,12,13.67000000,100,1,13.71000000,1,1,13.73000000,15,1,13.74000000,100,1,13.76000000,115,2,13.77000000,115,2,13.78000000,204,4,13.79000000,115,2,13.80000000,615,7,ARL,300061989
1065,2025-07-17T15:42:34.004671652Z,2025-07-17T15:42:34.004506043Z,160,2,1108,A,A,0,15.06000000,100,130,165609,251901285,13.55000000,10,1,13.54000000,100,1,13.38000000,33,1,13.37000000,100,1,13.31000000,10,1,13.30000000,100,1,13.28000000,11,2,13.27000000,110,2,13.26000000,204,4,13.25000000,111,2,13.40000000,208,12,13.67000000,100,1,13.71000000,1,1,13.73000000,15,1,13.74000000,100,1,13.76000000,115,2,13.77000000,115,2,13.78000000,204,4,13.79000000,115,2,13.80000000,615,7,ARL,300280757
1066,2025-07-17T15:42:34.004677786Z,2025-07-17T15:42:34.004512153Z,160,2,1108,C,A,0,14.76000000,100,0,165633,251901286,13.55000000,10,1,13.54000000,100,1,13.38000000,33,1,13.37000000,100,1,13.31000000,10,1,13.30000000,100,1,13.28000000,11,2,13.27000000,110,2,13.26000000,204,4,13.25000000,111,2,13.40000000,208,12,13.67000000,100,1,13.71000000,1,1,13.73000000,15,1,13.74000000,100,1,13.76000000,115,2,13.77000000,115,2,13.78000000,204,4,13.79000000,115,2,13.80000000,615,7,ARL,299903169
1067,2025-07-17T15:42:34.004677786Z,2025-07-17T15:42:34.004512153Z,160,2,1108,A,A,0,14.88000000,100,130,165633,251901286,13.55000000,10,1,13.54000000,100,1,13.38000000,33,1,13.37000000,100,1,13.31000000,10,1,13.30000000,100,1,13.28000000,11,2,13.27000000,110,2,13.26000000,204,4,13.25000000,111,2,13.40000000,208,12,13.67000000,100,1,13.71000000,1,1,13.73000000,15,1,13.74000000,100,1,13.76000000,115,2,13.77000000,115,2,13.78000000,204,4,13.79000000,115,2,13.80000000,615,7,ARL,300280761
1068,2025-07-17T15:42:34.005574760Z,2025-07-17T15:42:34.005409139Z,160,2,1108,C,A,0,15.92000000,100,0,165621,251901302,13.55000000,10,1,13.54000000,100,1,13.38000000,33,1,13.37000000,100,1,13.31000000,10,1,13.30000000,100,1,13.28000000,11,2,13.27000000,110,2,13.26000000,204,4,13.25000000,111,2,13.40000000,208,12,13.67000000,100,1,13.71000000,1,1,13.73000000,15,1,13.74000000,100,1,13.76000000,115,2,13.77000000,115,2,13.78000000,204,4,13.79000000,115,2,13.80000000,615,7,ARL,299926853
1069,2025-07-17T15:42:34.005574760Z,2025-07-17T15:42:34.005409139Z,160,2,1108,A,A,0,16.08000000,100,130,165621,251901302,13.55000000,10,1,13.54000000,100,1,13.38000000,33,1,13.37000000,100,1,13.31000000,10,1,13.30000000,100,1,13.28000000,11,2,13.27000000,110,2,13.26000000,204,4,13.25000000,111,2,13.40000000,208,12,13.67000000,100,1,13.71000000,1,1,13.73000000,15,1,13.74000000,100,1,13.76000000,115,2,13.77000000,115,2,13.78000000,204,4,13.79000000,115,2,13.80000000,615,7,ARL,300280773
1070,2025-07-17T15:42:34.005832926Z,2025-07-17T15:42:34.005667449Z,160,2,1108,C,A,0,14.81000000,100,0,165477,251901305,13.55000000,10,1,13.54000000,100,1,13.38000000,33,1,13.37000000,100,1,13.31000000,10,1,13.30000000,100,1,13.28000000,11,2,13.27000000,110,2,13.26000000,204,4,13.25000000,111,2,13.40000000,208,12,13.67000000,100,1,13.71000000,1,1,13.73000000,15,1,13.74000000,100,1,13.76000000,115,2,13.77000000,115,2,13.78000000,204,4,13.79000000,115,2,13.80000000,615,7,ARL,299926849
1071,2025-07-17T15:42:34.005832926Z,2025-07-17T15:42:34.005667449Z,160,2,1108,A,A,0,14.96000000,100,130,165477,251901305,13.55000000,10,1,13.54000000,100,1,13.38000000,33,1,13.37000000,100,1,13.31000000,10,1,13.30000000,100,1,13.28000000,11,2,13.27000000,110,2,13.26000000,204,4,13.25000000,111,2,13.40000000,208,12,13.67000000,100,1,13.71000000,1,1,13.73000000,15,1,13.74000000,100,1,13.76000000,115,2,13.77000000,115,2,13.78000000,204,4,13.79000000,115,2,13.80000000,615,7,ARL,300280777
1072,2025-07-17T15:42:34.006831024Z,2025-07-17T15:42:34.006665512Z,160,2,1108,C,A,0,17.58000000,100,0,165512,251901319,13.55000000,10,1,13.54000000,100,1,13.38000000,33,1,13.37000000,100,1,13.31000000,10,1,13.30000000,100,1,13.28000000,11,2,13.27000000,110,2,13.26000000,204,4,13.25000000,111,2,13.40000000,208,12,13.67000000,100,1,13.71000000,1,1,13.73000000,15,1,13.74000000,100,1,13.76000000,115,2,13.77000000,115,2,13.78000000,204,4,13.79000000,115,2,13.80000000,615,7,ARL,299926861
1073,2025-07-17T15:42:34.006831024Z,2025-07-17T15:42:34.006665512Z,160,2,1108,A,A,0,17.76000000,100,130,165512,251901319,13.55000000,10,1,13.54000000,100,1,13.38000000,33,1,13.37000000,100,1,13.31000000,10,1,13.30000000,100,1,13.28000000,11,2,13.27000000,110,2,13.26000000,204,4,13.25000000,111,2,13.40000000,208,12,13.67000000,100,1,13.71000000,1,1,13.73000000,15,1,13.74000000,100,1,13.76000000,115,2,13.77000000,115,2,13.78000000,204,4,13.79000000,115,2,13.80000000,615,7,ARL,300280797
1074,2025-07-17T15:42:34.007908678Z,2025-07-17T15:42:34.007743383Z,160,2,1108,C,A,0,14.64000000,100,130,165295,251901330,13.55000000,10,1,13.54000000,100,1,13.38000000,33,1,13.37000000,100,1,13.31000000,10,1,13.30000000,100,1,13.28000000,11,2,13.27000000,110,2,13.26000000,204,4,13.25000000,111,2,13.40000000,208,12,13.67000000,100,1,13.71000000,1,1,13.73000000,15,1,13.74000000,100,1,13.76000000,115,2,13.77000000,115,2,13.78000000,204,4,13.79000000,115,2,13.80000000,615,7,ARL,299926813
1075,2025-07-17T15:42:34.008072663Z,2025-07-17T15:42:34.007907269Z,160,2,1108,A,A,0,14.78000000,100,130,165394,251901331,13.55000000,10,1,13.54000000,100,1,13.38000000,33,1,13.37000000,100,1,13.31000000,10,1,13.30000000,100,1,13.28000000,11,2,13.27000000,110,2,13.26000000,204,4,13.25000000,111,2,13.40000000,208,12,13.67000000,100,1,13.71000000,1,1,13.73000000,15,1,13.74000000,100,1,13.76000000,115,2,13.77000000,115,2,13.78000000,204,4,13.79000000,115,2,13.80000000,615,7,ARL,300280825
1076,2025-07-17T15:42:34.010196831Z,2025-07-17T15:42:34.010031518Z,160,2,1108,C,A,0,14.12000000,100,130,165313,251901352,13.55000000,10,1,13.54000000,100,1,13.38000000,33,1,13.37000000,100,1,13.31000000,10,1,13.30000000,100,1,13.28000000,11,2,13.27000000,110,2,13.26000000,204,4,13.25000000,111,2,13.40000000,208,12,13.67000000,100,1,13.71000000,1,1,13.73000000,15,1,13.74000000,100,1,13.76000000,115,2,13.77000000,115,2,13.78000000,204,4,13.79000000,115,2,13.80000000,615,7,ARL,299926965
1077,2025-07-17T15:42:34.010248842Z,2025-07-17T15:42:34.010083409Z,160,2,1108,A,A,0,14.26000000,100,130,165433,251901353,13.55000000,10,1,13.54000000,100,1,13.38000000,33,1,13.37000000,100,1,13.31000000,10,1,13.30000000,100,1,13.28000000,11,2,13.27000000,110,2,13.26000000,204,4,13.25000000,111,2,13.40000000,208,12,13.67000000,100,1,13.71000000,1,1,13.73000000,15,1,13.74000000,100,1,13.76000000,115,2,13.77000000,115,2,13.78000000,204,4,13.79000000,115,2,13.80000000,615,7,ARL,300280857
1078,2025-07-17T15:42:34.010572370Z,2025-07-17T15:42:34.010406771Z,160,2,1108,C,A,0,14.81000000,100,0,165599,251901355,13.55000000,10,1,13.54000000,100,1,13.38000000,33,1,13.37000000,100,1,13.31000000,10,1,13.30000000,100,1,13.28000000,11,2,13.27000000,110,2,13.26000000,204,4,13.25000000,111,2,13.40000000,208,12,13.67000000,100,1,13.71000000,1,1,13.73000000,15,1,13.74000000,100,1,13.76000000,115,2,13.77000000,115,2,13.78000000,204,4,13.79000000,115,2,13.80000000,615,7,ARL,299926857
1079,2025-07-17T15:42:34.010572370Z,2025-07-17T15:42:34.010406771Z,160,2,1108,A,A,0,14.96000000,100,130,165599,251901355,13.55000000,10,1,13.54000000,100,1,13.38000000,33,1,13.37000000,100,1,13.31000000,10,1,13.30000000,100,1,13.28000000,11,2,13.27000000,110,2,13.26000000,204,4,13.25000000,111,2,13.40000000,208,12,13.67000000,100,1,13.71000000,1,1,13.73000000,15,1,13.74000000,100,1,13.76000000,115,2,13.77000000,115,2,13.78000000,204,4,13.79000000,115,2,13.80000000,615,7,ARL,300280873
1080,2025-07-17T15:42:34.952098027Z,2025-07-17T15:42:34.951932909Z,160,2,1108,A,A,0,14.08000000,100,130,165118,251912292,13.55000000,10,1,13.54000000,100,1,13.38000000,33,1,13.37000000,100,1,13.31000000,10,1,13.30000000,100,1,13.28000000,11,2,13.27000000,110,2,13.26000000,204,4,13.25000000,111,2,13.40000000,208,12,13.67000000,100,1,13.71000000,1,1,13.73000000,15,1,13.74000000,100,1,13.76000000,115,2,13.77000000,115,2,13.78000000,204,4,13.79000000,115,2,13.80000000,615,7,ARL,300294885
1081,2025-07-17T15:43:21.513838949Z,2025-07-17T15:43:21.513673603Z,160,2,1108,A,A,0,13.92000000,15,130,165346,252622568,13.55000000,10,1,13.54000000,100,1,13.38000000,33,1,13.37000000,100,1,13.31000000,10,1,13.30000000,100,1,13.28000000,11,2,13.27000000,110,2,13.26000000,204,4,13.25000000,111,2,13.40000000,208,12,13.67000000,100,1,13.71000000,1,1,13.73000000,15,1,13.74000000,100,1,13.76000000,115,2,13.77000000,115,2,13.78000000,204,4,13.79000000,115,2,13.80000000,615,7,ARL,301218889
1082,2025-07-17T15:43:24.878236760Z,2025-07-17T15:43:24.878071152Z,160,2,1108,C,A,0,14.08000000,100,0,165608,252681819,13.55000000,10,1,13.54000000,100,1,13.38000000,33,1,13.37000000,100,1,13.31000000,10,1,13.30000000,100,1,13.28000000,11,2,13.27000000,110,2,13.26000000,204,4,13.25000000,111,2,13.40000000,208,12,13.67000000,100,1,13.71000000,1,1,13.73000000,15,1,13.74000000,100,1,13.76000000,115,2,13.77000000,115,2,13.78000000,204,4,13.79000000,115,2,13.80000000,615,7,ARL,300294885
1083,2025-07-17T15:43:24.878236760Z,2025-07-17T15:43:24.878071152Z,160,2,1108,A,A,0,13.93000000,100,130,165608,252681819,13.55000000,10,1,13.54000000,100,1,13.38000000,33,1,13.37000000,100,1,13.31000000,10,1,13.30000000,100,1,13.28000000,11,2,13.27000000,110,2,13.26000000,204,4,13.25000000,111,2,13.40000000,208,12,13.67000000,100,1,13.71000000,1,1,13.73000000,15,1,13.74000000,100,1,13.76000000,115,2,13.77000000,115,2,13.78000000,204,4,13.79000000,115,2,13.80000000,615,7,ARL,301295841
1084,2025-07-17T15:43:24.879003443Z,2025-07-17T15:43:24.878837670Z,160,2,1108,C,A,0,15.06000000,100,0,165773,252681832,13.55000000,10,1,13.54000000,100,1,13.38000000,33,1,13.37000000,100,1,13.31000000,10,1,13.30000000,100,1,13.28000000,11,2,13.27000000,110,2,13.26000000,204,4,13.25000000,111,2,13.40000000,208,12,13.67000000,100,1,13.71000000,1,1,13.73000000,15,1,13.74000000,100,1,13.76000000,115,2,13.77000000,115,2,13.78000000,204,4,13.79000000,115,2,13.80000000,615,7,ARL,300280757
1085,2025-07-17T15:43:24.879003443Z,2025-07-17T15:43:24.878837670Z,160,2,1108,A,A,0,15.01000000,100,130,165773,252681832,13.55000000,10,1,13.54000000,100,1,13.38000000,33,1,13.37000000,100,1,13.31000000,10,1,13.30000000,100,1,13.28000000,11,2,13.27000000,110,2,13.26000000,204,4,13.25000000,111,2,13.40000000,208,12,13.67000000,100,1,13.71000000,1,1,13.73000000,15,1,13.74000000,100,1,13.76000000,115,2,13.77000000,115,2,13.78000000,204,4,13.79000000,115,2,13.80000000,615,7,ARL,301295873
1086,2025-07-17T15:43:32.780372412Z,2025-07-17T15:43:32.780206927Z,160,2,1108,A,A,0,13.88000000,15,130,165485,252800884,13.55000000,10,1,13.54000000,100,1,13.38000000,33,1,13.37000000,100,1,13.31000000,10,1,13.30000000,100,1,13.28000000,11,2,13.27000000,110,2,13.26000000,204,4,13.25000000,111,2,13.40000000,208,12,13.67000000,100,1,13.71000000,1,1,13.73000000,15,1,13.74000000,100,1,13.76000000,115,2,13.77000000,115,2,13.78000000,204,4,13.79000000,115,2,13.80000000,615,7,ARL,301451057
1087,2025-07-17T15:43:32.780639619Z,2025-07-17T15:43:32.780474141Z,160,2,1108,C,A,0,13.93000000,100,0,165478,252800887,13.55000000,10,1,13.54000000,100,1,13.38000000,33,1,13.37000000,100,1,13.31000000,10,1,13.30000000,100,1,13.28000000,11,2,13.27000000,110,2,13.26000000,204,4,13.25000000,111,2,13.40000000,208,12,13.67000000,100,1,13.71000000,1,1,13.73000000,15,1,13.74000000,100,1,13.76000000,115,2,13.77000000,115,2,13.78000000,204,4,13.79000000,115,2,13.80000000,615,7,ARL,301295841
1088,2025-07-17T15:43:32.780639619Z,2025-07-17T15:43:32.780474141Z,160,2,1108,A,A,0,13.89000000,100,130,165478,252800887,13.55000000,10,1,13.54000000,100,1,13.38000000,33,1,13.37000000,100,1,13.31000000,10,1,13.30000000,100,1,13.28000000,11,2,13.27000000,110,2,13.26000000,204,4,13.25000000,111,2,13.40000000,208,12,13.67000000,100,1,13.71000000,1,1,13.73000000,15,1,13.74000000,100,1,13.76000000,115,2,13.77000000,115,2,13.78000000,204,4,13.79000000,115,2,13.80000000,615,7,ARL,301451061
1089,2025-07-17T15:43:32.781382162Z,2025-07-17T15:43:32.781216589Z,160,2,1108,C,A,0,15.01000000,100,0,165573,252800892,13.55000000,10,1,13.54000000,100,1,13.38000000,33,1,13.37000000,100,1,13.31000000,10,1,13.30000000,100,1,13.28000000,11,2,13.27000000,110,2,13.26000000,204,4,13.25000000,111,2,13.40000000,208,12,13.67000000,100,1,13.71000000,1,1,13.73000000,15,1,13.74000000,100,1,13.76000000,115,2,13.77000000,115,2,13.78000000,204,4,13.79000000,115,2,13.80000000,615,7,ARL,301295873
1090,2025-07-17T15:43:32.781382162Z,2025-07-17T15:43:32.781216589Z,160,2,1108,A,A,0,14.97000000,100,130,165573,252800892,13.55000000,10,1,13.54000000,100,1,13.38000000,33,1,13.37000000,100,1,13.31000000,10,1,13.30000000,100,1,13.28000000,11,2,13.27000000,110,2,13.26000000,204,4,13.25000000,111,2,13.40000000,208,12,13.67000000,100,1,13.71000000,1,1,13.73000000,15,1,13.74000000,100,1,13.76000000,115,2,13.77000000,115,2,13.78000000,204,4,13.79000000,115,2,13.80000000,615,7,ARL,301451077
1091,2025-07-17T15:43:32.792119698Z,2025-07-17T15:43:32.791954053Z,160,2,1108,C,A,0,14.26000000,100,130,165645,252801681,13.55000000,10,1,13.54000000,100,1,13.38000000,33,1,13.37000000,100,1,13.31000000,10,1,13.30000000,100,1,13.28000000,11,2,13.27000000,110,2,13.26000000,204,4,13.25000000,111,2,13.40000000,208,12,13.67000000,100,1,13.71000000,1,1,13.73000000,15,1,13.74000000,100,1,13.76000000,115,2,13.77000000,115,2,13.78000000,204,4,13.79000000,115,2,13.80000000,615,7,ARL,300280857
1092,2025-07-17T15:43:32.792174617Z,2025-07-17T15:43:32.792008881Z,160,2,1108,A,A,0,14.17000000,100,130,165736,252801689,13.55000000,10,1,13.54000000,100,1,13.38000000,33,1,13.37000000,100,1,13.31000000,10,1,13.30000000,100,1,13.28000000,11,2,13.27000000,110,2,13.26000000,204,4,13.25000000,111,2,13.40000000,208,12,13.67000000,100,1,13.71000000,1,1,13.73000000,15,1,13.74000000,100,1,13.76000000,115,2,13.77000000,115,2,13.78000000,204,4,13.79000000,115,2,13.80000000,615,7,ARL,301452785
1093,2025-07-17T15:43:44.004832641Z,2025-07-17T15:43:44.004667259Z,160,2,1108,C,A,0,13.92000000,15,130,165382,252977583,13.55000000,10,1,13.54000000,100,1,13.38000000,33,1,13.37000000,100,1,13.31000000,10,1,13.30000000,100,1,13.28000000,11,2,13.27000000,110,2,13.26000000,204,4,13.25000000,111,2,13.40000000,208,12,13.67000000,100,1,13.71000000,1,1,13.73000000,15,1,13.74000000,100,1,13.76000000,115,2,13.77000000,115,2,13.78000000,204,4,13.79000000,115,2,13.80000000,615,7,ARL,301218889
1094,2025-07-17T15:43:44.005191111Z,2025-07-17T15:43:44.005025587Z,160,2,1108,C,A,0,14.88000000,100,0,165524,252977592,13.55000000,10,1,13.54000000,100,1,13.38000000,33,1,13.37000000,100,1,13.31000000,10,1,13.30000000,100,1,13.28000000,11,2,13.27000000,110,2,13.26000000,204,4,13.25000000,111,2,13.40000000,208,12,13.67000000,100,1,13.71000000,1,1,13.73000000,15,1,13.74000000,100,1,13.76000000,115,2,13.77000000,115,2,13.78000000,204,4,13.79000000,115,2,13.80000000,615,7,ARL,300280761
1095,2025-07-17T15:43:44.005191111Z,2025-07-17T15:43:44.005025587Z,160,2,1108,A,A,0,14.77000000,100,130,165524,252977592,13.55000000,10,1,13.54000000,100,1,13.38000000,33,1,13.37000000,100,1,13.31000000,10,1,13.30000000,100,1,13.28000000,11,2,13.27000000,110,2,13.26000000,204,4,13.25000000,111,2,13.40000000,208,12,13.67000000,100,1,13.71000000,1,1,13.73000000,15,1,13.74000000,100,1,13.76000000,115,2,13.77000000,115,2,13.78000000,204,4,13.79000000,115,2,13.80000000,615,7,ARL,301671709
1096,2025-07-17T15:43:44.005313071Z,2025-07-17T15:43:44.005147707Z,160,2,1108,C,A,0,14.88000000,100,0,165364,252977595,13.55000000,10,1,13.54000000,100,1,13.38000000,33,1,13.37000000,100,1,13.31000000,10,1,13.30000000,100,1,13.28000000,11,2,13.27000000,110,2,13.26000000,204,4,13.25000000,111,2,13.40000000,208,12,13.67000000,100,1,13.71000000,1,1,13.73000000,15,1,13.74000000,100,1,13.76000000,115,2,13.77000000,115,2,13.78000000,204,4,13.79000000,115,2,13.80000000,615,7,ARL,300280745
1097,2025-07-17T15:43:44.005313071Z,2025-07-17T15:43:44.005147707Z,160,2,1108,A,A,0,14.77000000,100,130,165364,252977595,13.55000000,10,1,13.54000000,100,1,13.38000000,33,1,13.37000000,100,1,13.31000000,10,1,13.30000000,100,1,13.28000000,11,2,13.27000000,110,2,13.26000000,204,4,13.25000000,111,2,13.40000000,208,12,13.67000000,100,1,13.71000000,1,1,13.73000000,15,1,13.74000000,100,1,13.76000000,115,2,13.77000000,115,2,13.78000000,204,4,13.79000000,115,2,13.80000000,615,7,ARL,301671713
1098,2025-07-17T15:43:48.787497664Z,2025-07-17T15:43:48.787332399Z,160,2,1108,A,A,0,13.83000000,15,130,165265,253027890,13.55000000,10,1,13.54000000,100,1,13.38000000,33,1,13.37000000,100,1,13.31000000,10,1,13.30000000,100,1,13.28000000,11,2,13.27000000,110,2,13.26000000,204,4,13.25000000,111,2,13.40000000,208,12,13.67000000,100,1,13.71000000,1,1,13.73000000,15,1,13.74000000,100,1,13.76000000,115,2,13.77000000,115,2,13.78000000,204,4,13.79000000,115,2,13.80000000,615,7,ARL,301746941
1099,2025-07-17T15:43:48.787766907Z,2025-07-17T15:43:48.787601640Z,160,2,1108,C,A,0,13.89000000,100,0,165267,253027924,13.55000000,10,1,13.54000000,100,1,13.38000000,33,1,13.37000000,100,1,13.31000000,10,1,13.30000000,100,1,13.28000000,11,2,13.27000000,110,2,13.26000000,204,4,13.25000000,111,2,13.40000000,208,12,13.67000000,100,1,13.71000000,1,1,13.73000000,15,1,13.74000000,100,1,13.76000000,115,2,13.77000000,115,2,13.78000000,204,4,13.79000000,115,2,13.80000000,615,7,ARL,301451061
1100,2025-07-17T15:43:48.787766907Z,2025-07-17T15:43:48.787601640Z,160,2,1108,A,A,0,13.84000000,100,130,165267,253027924,13.55000000,10,1,13.54000000,100,1,13.38000000,33,1,13.37000000,100,1,13.31000000,10,1,13.30000000,100,1,13.28000000,11,2,13.27000000,110,2,13.26000000,204,4,13.25000000,111,2,13.40000000,208,12,13.67000000,100,1,13.71000000,1,1,13.73000000,15,1,13.74000000,100,1,13.76000000,115,2,13.77000000,115,2,13.78000000,204,4,13.79000000,115,2,13.80000000,615,7,ARL,301746949
1101,2025-07-17T15:43:48.788512022Z,2025-07-17T15:43:48.788345787Z,160,2,1108,C,A,0,14.97000000,100,0,166235,253027959,13.55000000,10,1,13.54000000,100,1,13.38000000,33,1,13.37000000,100,1,13.31000000,10,1,13.30000000,100,1,13.28000000,11,2,13.27000000,110,2,13.26000000,204,4,13.25000000,111,2,13.40000000,208,12,13.67000000,100,1,13.71000000,1,1,13.73000000,15,1,13.74000000,100,1,13.76000000,115,2,13.77000000,115,2,13.78000000,204,4,13.79000000,115,2,13.80000000,615,7,ARL,301451077
1102,2025-07-17T15:43:48.788512022Z,2025-07-17T15:43:48.788345787Z,160,2,1108,A,A,0,14.91000000,100,128,166235,253027959,13.55000000,10,1,13.54000000,100,1,13.38000000,33,1,13.37000000,100,1,13.31000000,10,1,13.30000000,100,1,13.28000000,11,2,13.27000000,110,2,13.26000000,204,4,13.25000000,111,2,13.40000000,208,12,13.67000000,100,1,13.71000000,1,1,13.73000000,15,1,13.74000000,100,1,13.76000000,115,2,13.77000000,115,2,13.78000000,204,4,13.79000000,115,2,13.80000000,615,7,ARL,301746969
1103,2025-07-17T15:43:48.790573820Z,2025-07-17T15:43:48.790408191Z,160,2,1108,C,A,0,14.96000000,100,0,165629,253028026,13.55000000,10,1,13.54000000,100,1,13.38000000,33,1,13.37000000,100,1,13.31000000,10,1,13.30000000,100,1,13.28000000,11,2,13.27000000,110,2,13.26000000,204,4,13.25000000,111,2,13.40000000,208,12,13.67000000,100,1,13.71000000,1,1,13.73000000,15,1,13.74000000,100,1,13.76000000,115,2,13.77000000,115,2,13.78000000,204,4,13.79000000,115,2,13.80000000,615,7,ARL,300280777
1104,2025-07-17T15:43:48.790573820Z,2025-07-17T15:43:48.790408191Z,160,2,1108,A,A,0,14.81000000,100,130,165629,253028026,13.55000000,10,1,13.54000000,100,1,13.38000000,33,1,13.37000000,100,1,13.31000000,10,1,13.30000000,100,1,13.28000000,11,2,13.27000000,110,2,13.26000000,204,4,13.25000000,111,2,13.40000000,208,12,13.67000000,100,1,13.71000000,1,1,13.73000000,15,1,13.74000000,100,1,13.76000000,115,2,13.77000000,115,2,13.78000000,204,4,13.79000000,115,2,13.80000000,615,7,ARL,301747001
1105,2025-07-17T15:43:48.790600546Z,2025-07-17T15:43:48.790434947Z,160,2,1108,C,A,0,14.78000000,100,0,165599,253028027,13.55000000,10,1,13.54000000,100,1,13.38000000,33,1,13.37000000,100,1,13.31000000,10,1,13.30000000,100,1,13.28000000,11,2,13.27000000,110,2,13.26000000,204,4,13.25000000,111,2,13.40000000,208,12,13.67000000,100,1,13.71000000,1,1,13.73000000,15,1,13.74000000,100,1,13.76000000,115,2,13.77000000,115,2,13.78000000,204,4,13.79000000,115,2,13.80000000,615,7,ARL,300280825
1106,2025-07-17T15:43:48.790600546Z,2025-07-17T15:43:48.790434947Z,160,2,1108,A,A,0,14.64000000,100,130,165599,253028027,13.55000000,10,1,13.54000000,100,1,13.38000000,33,1,13.37000000,100,1,13.31000000,10,1,13.30000000,100,1,13.28000000,11,2,13.27000000,110,2,13.26000000,204,4,13.25000000,111,2,13.40000000,208,12,13.67000000,100,1,13.71000000,1,1,13.73000000,15,1,13.74000000,100,1,13.76000000,115,2,13.77000000,115,2,13.78000000,204,4,13.79000000,115,2,13.80000000,615,7,ARL,301747005
1107,2025-07-17T15:43:48.800959598Z,2025-07-17T15:43:48.800794196Z,160,2,1108,C,A,0,17.76000000,100,0,165402,253028707,13.55000000,10,1,13.54000000,100,1,13.38000000,33,1,13.37000000,100,1,13.31000000,10,1,13.30000000,100,1,13.28000000,11,2,13.27000000,110,2,13.26000000,204,4,13.25000000,111,2,13.40000000,208,12,13.67000000,100,1,13.71000000,1,1,13.73000000,15,1,13.74000000,100,1,13.76000000,115,2,13.77000000,115,2,13.78000000,204,4,13.79000000,115,2,13.80000000,615,7,ARL,300280797
1108,2025-07-17T15:43:48.800959598Z,2025-07-17T15:43:48.800794196Z,160,2,1108,A,A,0,17.58000000,100,130,165402,253028707,13.55000000,10,1,13.54000000,100,1,13.38000000,33,1,13.37000000,100,1,13.31000000,10,1,13.30000000,100,1,13.28000000,11,2,13.27000000,110,2,13.26000000,204,4,13.25000000,111,2,13.40000000,208,12,13.67000000,100,1,13.71000000,1,1,13.73000000,15,1,13.74000000,100,1,13.76000000,115,2,13.77000000,115,2,13.78000000,204,4,13.79000000,115,2,13.80000000,615,7,ARL,301747261
1109,2025-07-17T15:43:48.806845249Z,2025-07-17T15:43:48.806679708Z,160,2,1108,C,A,0,16.08000000,100,0,165541,253028803,13.55000000,10,1,13.54000000,100,1,13.38000000,33,1,13.37000000,100,1,13.31000000,10,1,13.30000000,100,1,13.28000000,11,2,13.27000000,110,2,13.26000000,204,4,13.25000000,111,2,13.40000000,208,12,13.67000000,100,1,13.71000000,1,1,13.73000000,15,1,13.74000000,100,1,13.76000000,115,2,13.77000000,115,2,13.78000000,204,4,13.79000000,115,2,13.80000000,615,7,ARL,300280773
1110,2025-07-17T15:43:48.806845249Z,2025-07-17T15:43:48.806679708Z,160,2,1108,A,A,0,15.92000000,100,130,165541,253028803,13.55000000,10,1,13.54000000,100,1,13.38000000,33,1,13.37000000,100,1,13.31000000,10,1,13.30000000,100,1,13.28000000,11,2,13.27000000,110,2,13.26000000,204,4,13.25000000,111,2,13.40000000,208,12,13.67000000,100,1,13.71000000,1,1,13.73000000,15,1,13.74000000,100,1,13.76000000,115,2,13.77000000,115,2,13.78000000,204,4,13.79000000,115,2,13.80000000,615,7,ARL,301747301
1111,2025-07-17T15:43:48.852570853Z,2025-07-17T15:43:48.852405047Z,160,2,1108,C,A,0,14.96000000,100,0,165806,253029437,13.55000000,10,1,13.54000000,100,1,13.38000000,33,1,13.37000000,100,1,13.31000000,10,1,13.30000000,100,1,13.28000000,11,2,13.27000000,110,2,13.26000000,204,4,13.25000000,111,2,13.40000000,208,12,13.67000000,100,1,13.71000000,1,1,13.73000000,15,1,13.74000000,100,1,13.76000000,115,2,13.77000000,115,2,13.78000000,204,4,13.79000000,115,2,13.80000000,615,7,ARL,300280873
1112,2025-07-17T15:43:48.852570853Z,2025-07-17T15:43:48.852405047Z,160,2,1108,A,A,0,14.81000000,100,130,165806,253029437,13.55000000,10,1,13.54000000,100,1,13.38000000,33,1,13.37000000,100,1,13.31000000,10,1,13.30000000,100,1,13.28000000,11,2,13.27000000,110,2,13.26000000,204,4,13.25000000,111,2,13.40000000,208,12,13.67000000,100,1,13.71000000,1,1,13.73000000,15,1,13.74000000,100,1,13.76000000,115,2,13.77000000,115,2,13.78000000,204,4,13.79000000,115,2,13.80000000,615,7,ARL,301747957
1113,2025-07-17T15:43:53.123817759Z,2025-07-17T15:43:53.123652480Z,160,2,1108,C,A,0,13.88000000,15,130,165279,253100941,13.55000000,10,1,13.54000000,100,1,13.38000000,33,1,13.37000000,100,1,13.31000000,10,1,13.30000000,100,1,13.28000000,11,2,13.27000000,110,2,13.26000000,204,4,13.25000000,111,2,13.40000000,208,12,13.67000000,100,1,13.71000000,1,1,13.73000000,15,1,13.74000000,100,1,13.76000000,115,2,13.77000000,115,2,13.78000000,204,4,13.79000000,115,2,13.80000000,615,7,ARL,301451057
1114,2025-07-17T15:43:54.126276976Z,2025-07-17T15:43:54.126111293Z,160,2,1108,A,A,0,13.81000000,15,130,165683,253121467,13.55000000,10,1,13.54000000,100,1,13.38000000,33,1,13.37000000,100,1,13.31000000,10,1,13.30000000,100,1,13.28000000,11,2,13.27000000,110,2,13.26000000,204,4,13.25000000,111,2,13.40000000,208,12,13.67000000,100,1,13.71000000,1,1,13.73000000,15,1,13.74000000,100,1,13.76000000,115,2,13.77000000,115,2,13.78000000,204,4,13.79000000,115,2,13.80000000,615,7,ARL,301867541
1115,2025-07-17T15:43:54.998238933Z,2025-07-17T15:43:54.998073317Z,160,2,1108,C,A,0,13.84000000,100,0,165616,253137948,13.55000000,10,1,13.54000000,100,1,13.38000000,33,1,13.37000000,100,1,13.31000000,10,1,13.30000000,100,1,13.28000000,11,2,13.27000000,110,2,13.26000000,204,4,13.25000000,111,2,13.40000000,208,12,13.67000000,100,1,13.71000000,1,1,13.73000000,15,1,13.74000000,100,1,13.76000000,115,2,13.77000000,115,2,13.78000000,204,4,13.79000000,115,2,13.80000000,615,7,ARL,301746949
1116,2025-07-17T15:43:54.998238933Z,2025-07-17T15:43:54.998073317Z,160,2,1108,A,A,0,13.82000000,100,130,165616,253137948,13.55000000,10,1,13.54000000,100,1,13.38000000,33,1,13.37000000,100,1,13.31000000,10,1,13.30000000,100,1,13.28000000,11,2,13.27000000,110,2,13.26000000,204,4,13.25000000,111,2,13.40000000,208,12,13.67000000,100,1,13.71000000,1,1,13.73000000,15,1,13.74000000,100,1,13.76000000,115,2,13.77000000,115,2,13.78000000,204,4,13.79000000,115,2,13.80000000,615,7,ARL,301885353
1117,2025-07-17T15:43:55.019172741Z,2025-07-17T15:43:55.019007300Z,160,2,1108,C,A,0,14.17000000,100,130,165441,253138492,13.55000000,10,1,13.54000000,100,1,13.38000000,33,1,13.37000000,100,1,13.31000000,10,1,13.30000000,100,1,13.28000000,11,2,13.27000000,110,2,13.26000000,204,4,13.25000000,111,2,13.40000000,208,12,13.67000000,100,1,13.71000000,1,1,13.73000000,15,1,13.74000000,100,1,13.76000000,115,2,13.77000000,115,2,13.78000000,204,4,13.79000000,115,2,13.80000000,615,7,ARL,301452785
1118,2025-07-17T15:43:55.019225935Z,2025-07-17T15:43:55.019060515Z,160,2,1108,A,A,0,14.10000000,100,130,165420,253138493,13.55000000,10,1,13.54000000,100,1,13.38000000,33,1,13.37000000,100,1,13.31000000,10,1,13.30000000,100,1,13.28000000,11,2,13.27000000,110,2,13.26000000,204,4,13.25000000,111,2,13.40000000,208,12,13.67000000,100,1,13.71000000,1,1,13.73000000,15,1,13.74000000,100,1,13.76000000,115,2,13.77000000,115,2,13.78000000,204,4,13.79000000,115,2,13.80000000,615,7,ARL,301886057
1119,2025-07-17T15:44:01.698791467Z,2025-07-17T15:44:01.698626200Z,160,2,1108,C,A,0,13.83000000,15,130,165267,253246317,13.55000000,10,1,13.54000000,100,1,13.38000000,33,1,13.37000000,100,1,13.31000000,10,1,13.30000000,100,1,13.28000000,11,2,13.27000000,110,2,13.26000000,204,4,13.25000000,111,2,13.40000000,208,12,13.67000000,100,1,13.71000000,1,1,13.73000000,15,1,13.74000000,100,1,13.76000000,115,2,13.77000000,115,2,13.78000000,204,4,13.79000000,115,2,13.80000000,615,7,ARL,301746941
1120,2025-07-17T15:44:04.014878156Z,2025-07-17T15:44:04.014712730Z,160,2,1108,A,A,0,13.83000000,100,130,165426,253292355,13.55000000,10,1,13.54000000,100,1,13.38000000,33,1,13.37000000,100,1,13.31000000,10,1,13.30000000,100,1,13.28000000,11,2,13.27000000,110,2,13.26000000,204,4,13.25000000,111,2,13.40000000,208,12,13.67000000,100,1,13.71000000,1,1,13.73000000,15,1,13.74000000,100,1,13.76000000,115,2,13.77000000,115,2,13.78000000,204,4,13.79000000,115,2,13.80000000,615,7,ARL,302078553
1121,2025-07-17T15:44:05.055626948Z,2025-07-17T15:44:05.055461574Z,160,2,1108,A,A,0,13.81000000,100,130,165374,253307083,13.55000000,10,1,13.54000000,100,1,13.38000000,33,1,13.37000000,100,1,13.31000000,10,1,13.30000000,100,1,13.28000000,11,2,13.27000000,110,2,13.26000000,204,4,13.25000000,111,2,13.40000000,208,12,13.67000000,100,1,13.71000000,1,1,13.73000000,15,1,13.74000000,100,1,13.76000000,115,2,13.77000000,115,2,13.78000000,204,4,13.79000000,115,2,13.80000000,615,7,ARL,302100649
1122,2025-07-17T15:44:05.062431949Z,2025-07-17T15:44:05.062266845Z,160,2,1108,C,A,0,13.83000000,100,130,165104,253307147,13.55000000,10,1,13.54000000,100,1,13.38000000,33,1,13.37000000,100,1,13.31000000,10,1,13.30000000,100,1,13.28000000,11,2,13.27000000,110,2,13.26000000,204,4,13.25000000,111,2,13.40000000,208,12,13.67000000,100,1,13.71000000,1,1,13.73000000,15,1,13.74000000,100,1,13.76000000,115,2,13.77000000,115,2,13.78000000,204,4,13.79000000,115,2,13.80000000,615,7,ARL,302078553
1123,2025-07-17T15:44:09.389713730Z,2025-07-17T15:44:09.389548394Z,160,2,1108,A,A,0,13.76000000,15,130,165336,253384422,13.55000000,10,1,13.54000000,100,1,13.38000000,33,1,13.37000000,100,1,13.31000000,10,1,13.30000000,100,1,13.28000000,11,2,13.27000000,110,2,13.26000000,204,4,13.25000000,111,2,13.40000000,208,12,13.67000000,100,1,13.71000000,1,1,13.73000000,15,1,13.74000000,100,1,13.76000000,130,3,13.77000000,115,2,13.78000000,204,4,13.79000000,115,2,13.80000000,615,7,ARL,302205249
1124,2025-07-17T15:44:09.390496140Z,2025-07-17T15:44:09.390329935Z,160,2,1108,C,A,0,14.77000000,100,0,166205,253384438,13.55000000,10,1,13.54000000,100,1,13.38000000,33,1,13.37000000,100,1,13.31000000,10,1,13.30000000,100,1,13.28000000,11,2,13.27000000,110,2,13.26000000,204,4,13.25000000,111,2,13.40000000,208,12,13.67000000,100,1,13.71000000,1,1,13.73000000,15,1,13.74000000,100,1,13.76000000,130,3,13.77000000,115,2,13.78000000,204,4,13.79000000,115,2,13.80000000,615,7,ARL,301671709
1125,2025-07-17T15:44:09.390496140Z,2025-07-17T15:44:09.390329935Z,160,2,1108,A,A,0,14.66000000,100,128,166205,253384438,13.55000000,10,1,13.54000000,100,1,13.38000000,33,1,13.37000000,100,1,13.31000000,10,1,13.30000000,100,1,13.28000000,11,2,13.27000000,110,2,13.26000000,204,4,13.25000000,111,2,13.40000000,208,12,13.67000000,100,1,13.71000000,1,1,13.73000000,15,1,13.74000000,100,1,13.76000000,130,3,13.77000000,115,2,13.78000000,204,4,13.79000000,115,2,13.80000000,615,7,ARL,302205289
1126,2025-07-17T15:44:09.391058486Z,2025-07-17T15:44:09.390893172Z,160,2,1108,C,A,0,14.77000000,100,0,165314,253384456,13.55000000,10,1,13.54000000,100,1,13.38000000,33,1,13.37000000,100,1,13.31000000,10,1,13.30000000,100,1,13.28000000,11,2,13.27000000,110,2,13.26000000,204,4,13.25000000,111,2,13.40000000,208,12,13.67000000,100,1,13.71000000,1,1,13.73000000,15,1,13.74000000,100,1,13.76000000,130,3,13.77000000,115,2,13.78000000,204,4,13.79000000,115,2,13.80000000,615,7,ARL,301671713
1127,2025-07-17T15:44:09.391058486Z,2025-07-17T15:44:09.390893172Z,160,2,1108,A,A,0,14.66000000,100,130,165314,253384456,13.55000000,10,1,13.54000000,100,1,13.38000000,33,1,13.37000000,100,1,13.31000000,10,1,13.30000000,100,1,13.28000000,11,2,13.27000000,110,2,13.26000000,204,4,13.25000000,111,2,13.40000000,208,12,13.67000000,100,1,13.71000000,1,1,13.73000000,15,1,13.74000000,100,1,13.76000000,130,3,13.77000000,115,2,13.78000000,204,4,13.79000000,115,2,13.80000000,615,7,ARL,302205309
1128,2025-07-17T15:44:09.395447612Z,2025-07-17T15:44:09.395281780Z,160,2,1108,C,A,0,13.82000000,100,0,165832,253384698,13.55000000,10,1,13.54000000,100,1,13.38000000,33,1,13.37000000,100,1,13.31000000,10,1,13.30000000,100,1,13.28000000,11,2,13.27000000,110,2,13.26000000,204,4,13.25000000,111,2,13.40000000,208,12,13.67000000,100,1,13.71000000,1,1,13.73000000,15,1,13.74000000,100,1,13.76000000,130,3,13.77000000,115,2,13.78000000,204,4,13.79000000,115,2,13.80000000,615,7,ARL,301885353
1129,2025-07-17T15:44:09.395447612Z,2025-07-17T15:44:09.395281780Z,160,2,1108,A,A,0,13.77000000,100,130,165832,253384698,13.55000000,10,1,13.54000000,100,1,13.38000000,33,1,13.37000000,100,1,13.31000000,10,1,13.30000000,100,1,13.28000000,11,2,13.27000000,110,2,13.26000000,204,4,13.25000000,111,2,13.40000000,208,12,13.67000000,100,1,13.71000000,1,1,13.73000000,15,1,13.74000000,100,1,13.76000000,130,3,13.77000000,215,3,13.78000000,204,4,13.79000000,115,2,13.80000000,615,7,ARL,302205493
1130,2025-07-17T15:44:09.396195647Z,2025-07-17T15:44:09.396030225Z,160,2,1108,C,A,0,14.91000000,100,0,165422,253384731,13.55000000,10,1,13.54000000,100,1,13.38000000,33,1,13.37000000,100,1,13.31000000,10,1,13.30000000,100,1,13.28000000,11,2,13.27000000,110,2,13.26000000,204,4,13.25000000,111,2,13.40000000,208,12,13.67000000,100,1,13.71000000,1,1,13.73000000,15,1,13.74000000,100,1,13.76000000,130,3,13.77000000,215,3,13.78000000,204,4,13.79000000,115,2,13.80000000,615,7,ARL,301746969
1131,2025-07-17T15:44:09.396195647Z,2025-07-17T15:44:09.396030225Z,160,2,1108,A,A,0,14.84000000,100,130,165422,253384731,13.55000000,10,1,13.54000000,100,1,13.38000000,33,1,13.37000000,100,1,13.31000000,10,1,13.30000000,100,1,13.28000000,11,2,13.27000000,110,2,13.26000000,204,4,13.25000000,111,2,13.40000000,208,12,13.67000000,100,1,13.71000000,1,1,13.73000000,15,1,13.74000000,100,1,13.76000000,130,3,13.77000000,215,3,13.78000000,204,4,13.79000000,115,2,13.80000000,615,7,ARL,302205537
1132,2025-07-17T15:44:09.398011186Z,2025-07-17T15:44:09.397845986Z,160,2,1108,A,A,0,13.79000000,100,130,165200,253384788,13.55000000,10,1,13.54000000,100,1,13.38000000,33,1,13.37000000,100,1,13.31000000,10,1,13.30000000,100,1,13.28000000,11,2,13.27000000,110,2,13.26000000,204,4,13.25000000,111,2,13.40000000,208,12,13.67000000,100,1,13.71000000,1,1,13.73000000,15,1,13.74000000,100,1,13.76000000,130,3,13.77000000,215,3,13.78000000,204,4,13.79000000,215,3,13.80000000,615,7,ARL,302205561
1133,2025-07-17T15:44:09.404828956Z,2025-07-17T15:44:09.404663816Z,160,2,1108,C,A,0,13.81000000,100,130,165140,253385013,13.55000000,10,1,13.54000000,100,1,13.38000000,33,1,13.37000000,100,1,13.31000000,10,1,13.30000000,100,1,13.28000000,11,2,13.27000000,110,2,13.26000000,204,4,13.25000000,111,2,13.40000000,208,12,13.67000000,100,1,13.71000000,1,1,13.73000000,15,1,13.74000000,100,1,13.76000000,130,3,13.77000000,215,3,13.78000000,204,4,13.79000000,215,3,13.80000000,615,7,ARL,302100649
1134,2025-07-17T15:44:20.402535831Z,2025-07-17T15:44:20.402370565Z,160,2,1108,C,A,0,13.81000000,15,130,165266,253562230,13.55000000,10,1,13.54000000,100,1,13.38000000,33,1,13.37000000,100,1,13.31000000,10,1,13.30000000,100,1,13.28000000,11,2,13.27000000,110,2,13.26000000,204,4,13.25000000,111,2,13.40000000,208,12,13.67000000,100,1,13.71000000,1,1,13.73000000,15,1,13.74000000,100,1,13.76000000,130,3,13.77000000,215,3,13.78000000,204,4,13.79000000,215,3,13.80000000,615,7,ARL,301867541
1135,2025-07-17T15:44:21.405486122Z,2025-07-17T15:44:21.405320730Z,160,2,1108,A,A,0,13.74000000,15,130,165392,253582427,13.55000000,10,1,13.54000000,100,1,13.38000000,33,1,13.37000000,100,1,13.31000000,10,1,13.30000000,100,1,13.28000000,11,2,13.27000000,110,2,13.26000000,204,4,13.25000000,111,2,13.40000000,208,12,13.67000000,100,1,13.71000000,1,1,13.73000000,15,1,13.74000000,115,2,13.76000000,130,3,13.77000000,215,3,13.78000000,204,4,13.79000000,215,3,13.80000000,615,7,ARL,302458113
1136,2025-07-17T15:44:21.843235911Z,2025-07-17T15:44:21.843070079Z,160,2,1108,C,A,0,13.77000000,100,0,165832,253590641,13.55000000,10,1,13.54000000,100,1,13.38000000,33,1,13.37000000,100,1,13.31000000,10,1,13.30000000,100,1,13.28000000,11,2,13.27000000,110,2,13.26000000,204,4,13.25000000,111,2,13.40000000,208,12,13.67000000,100,1,13.71000000,1,1,13.73000000,15,1,13.74000000,115,2,13.76000000,130,3,13.77000000,215,3,13.78000000,204,4,13.79000000,215,3,13.80000000,615,7,ARL,302205493
1137,2025-07-17T15:44:21.843235911Z,2025-07-17T15:44:21.843070079Z,160,2,1108,A,A,0,13.75000000,100,130,165832,253590641,13.55000000,10,1,13.54000000,100,1,13.38000000,33,1,13.37000000,100,1,13.31000000,10,1,13.30000000,100,1,13.28000000,11,2,13.27000000,110,2,13.26000000,204,4,13.25000000,111,2,13.40000000,208,12,13.67000000,100,1,13.71000000,1,1,13.73000000,15,1,13.74000000,115,2,13.75000000,100,1,13.76000000,130,3,13.77000000,215,3,13.78000000,204,4,13.79000000,215,3,ARL,302466045
1138,2025-07-17T15:44:21.855416093Z,2025-07-17T15:44:21.855250804Z,160,2,1108,C,A,0,14.10000000,100,130,165289,253590837,13.55000000,10,1,13.54000000,100,1,13.38000000,33,1,13.37000000,100,1,13.31000000,10,1,13.30000000,100,1,13.28000000,11,2,13.27000000,110,2,13.26000000,204,4,13.25000000,111,2,13.40000000,208,12,13.67000000,100,1,13.71000000,1,1,13.73000000,15,1,13.74000000,115,2,13.75000000,100,1,13.76000000,130,3,13.77000000,215,3,13.78000000,204,4,13.79000000,215,3,ARL,301886057
1139,2025-07-17T15:44:21.855471158Z,2025-07-17T15:44:21.855305995Z,160,2,1108,A,A,0,14.03000000,100,130,165163,253590838,13.55000000,10,1,13.54000000,100,1,13.38000000,33,1,13.37000000,100,1,13.31000000,10,1,13.30000000,100,1,13.28000000,11,2,13.27000000,110,2,13.26000000,204,4,13.25000000,111,2,13.40000000,208,12,13.67000000,100,1,13.71000000,1,1,13.73000000,15,1,13.74000000,115,2,13.75000000,100,1,13.76000000,130,3,13.77000000,215,3,13.78000000,204,4,13.79000000,215,3,ARL,302466157
1140,2025-07-17T15:44:24.447075532Z,2025-07-17T15:44:24.446910206Z,160,2,1108,A,A,0,13.77000000,100,130,165326,253614407,13.55000000,10,1,13.54000000,100,1,13.38000000,33,1,13.37000000,100,1,13.31000000,10,1,13.30000000,100,1,13.28000000,11,2,13.27000000,110,2,13.26000000,204,4,13.25000000,111,2,13.40000000,208,12,13.67000000,100,1,13.71000000,1,1,13.73000000,15,1,13.74000000,115,2,13.75000000,100,1,13.76000000,130,3,13.77000000,315,4,13.78000000,204,4,13.79000000,215,3,ARL,302500469
1141,2025-07-17T15:44:24.465555818Z,2025-07-17T15:44:24.465390625Z,160,2,1108,C,A,0,13.79000000,100,130,165193,253614591,13.55000000,10,1,13.54000000,100,1,13.38000000,33,1,13.37000000,100,1,13.31000000,10,1,13.30000000,100,1,13.28000000,11,2,13.27000000,110,2,13.26000000,204,4,13.25000000,111,2,13.40000000,208,12,13.67000000,100,1,13.71000000,1,1,13.73000000,15,1,13.74000000,115,2,13.75000000,100,1,13.76000000,130,3,13.77000000,315,4,13.78000000,204,4,13.79000000,215,3,ARL,302205561
1142,2025-07-17T15:44:30.846822983Z,2025-07-17T15:44:30.846657613Z,160,2,1108,C,A,0,13.76000000,15,130,165370,253704439,13.55000000,10,1,13.54000000,100,1,13.38000000,33,1,13.37000000,100,1,13.31000000,10,1,13.30000000,100,1,13.28000000,11,2,13.27000000,110,2,13.26000000,204,4,13.25000000,111,2,13.40000000,208,12,13.67000000,100,1,13.71000000,1,1,13.73000000,15,1,13.74000000,115,2,13.75000000,100,1,13.76000000,130,3,13.77000000,315,4,13.78000000,204,4,13.79000000,215,3,ARL,302205249
1143,2025-07-17T15:44:31.849784693Z,2025-07-17T15:44:31.849618640Z,160,2,1108,A,A,0,13.72000000,15,130,166053,253721156,13.55000000,10,1,13.54000000,100,1,13.38000000,33,1,13.37000000,100,1,13.31000000,10,1,13.30000000,100,1,13.28000000,11,2,13.27000000,110,2,13.26000000,204,4,13.25000000,111,2,13.40000000,208,12,13.67000000,100,1,13.71000000,1,1,13.72000000,15,1,13.73000000,15,1,13.74000000,115,2,13.75000000,100,1,13.76000000,130,3,13.77000000,315,4,13.78000000,204,4,ARL,302649021
1144,2025-07-17T15:44:31.849921857Z,2025-07-17T15:44:31.849756452Z,160,2,1108,A,A,0,13.75000000,100,130,165405,253721157,13.55000000,10,1,13.54000000,100,1,13.38000000,33,1,13.37000000,100,1,13.31000000,10,1,13.30000000,100,1,13.28000000,11,2,13.27000000,110,2,13.26000000,204,4,13.25000000,111,2,13.40000000,208,12,13.67000000,100,1,13.71000000,1,1,13.72000000,15,1,13.73000000,15,1,13.74000000,115,2,13.75000000,200,2,13.76000000,130,3,13.77000000,315,4,13.78000000,204,4,ARL,302649029
1145,2025-07-17T15:44:31.910124978Z,2025-07-17T15:44:31.909959614Z,160,2,1108,C,A,0,13.77000000,100,130,165364,253722140,13.55000000,10,1,13.54000000,100,1,13.38000000,33,1,13.37000000,100,1,13.31000000,10,1,13.30000000,100,1,13.28000000,11,2,13.27000000,110,2,13.26000000,204,4,13.25000000,111,2,13.40000000,208,12,13.67000000,100,1,13.71000000,1,1,13.72000000,15,1,13.73000000,15,1,13.74000000,115,2,13.75000000,200,2,13.76000000,130,3,13.77000000,315,4,13.78000000,204,4,ARL,302500469
1146,2025-07-17T15:44:32.484497230Z,2025-07-17T15:44:32.484331764Z,160,2,1108,C,A,0,13.75000000,100,0,165466,253730877,13.55000000,10,1,13.54000000,100,1,13.38000000,33,1,13.37000000,100,1,13.31000000,10,1,13.30000000,100,1,13.28000000,11,2,13.27000000,110,2,13.26000000,204,4,13.25000000,111,2,13.40000000,208,12,13.67000000,100,1,13.71000000,1,1,13.72000000,15,1,13.73000000,15,1,13.74000000,115,2,13.75000000,200,2,13.76000000,130,3,13.77000000,315,4,13.78000000,204,4,ARL,302466045
1147,2025-07-17T15:44:32.484497230Z,2025-07-17T15:44:32.484331764Z,160,2,1108,A,A,0,13.73000000,100,130,165466,253730877,13.55000000,10,1,13.54000000,100,1,13.38000000,33,1,13.37000000,100,1,13.31000000,10,1,13.30000000,100,1,13.28000000,11,2,13.27000000,110,2,13.26000000,204,4,13.25000000,111,2,13.40000000,208,12,13.67000000,100,1,13.71000000,1,1,13.72000000,15,1,13.73000000,115,2,13.74000000,115,2,13.75000000,200,2,13.76000000,130,3,13.77000000,315,4,13.78000000,204,4,ARL,302662769
1148,2025-07-17T15:44:32.485238209Z,2025-07-17T15:44:32.485072552Z,160,2,1108,C,A,0,14.84000000,100,0,165657,253730907,13.55000000,10,1,13.54000000,100,1,13.38000000,33,1,13.37000000,100,1,13.31000000,10,1,13.30000000,100,1,13.28000000,11,2,13.27000000,110,2,13.26000000,204,4,13.25000000,111,2,13.40000000,208,12,13.67000000,100,1,13.71000000,1,1,13.72000000,15,1,13.73000000,115,2,13.74000000,115,2,13.75000000,200,2,13.76000000,130,3,13.77000000,315,4,13.78000000,204,4,ARL,302205537
1149,2025-07-17T15:44:32.485238209Z,2025-07-17T15:44:32.485072552Z,160,2,1108,A,A,0,14.79000000,100,130,165657,253730907,13.55000000,10,1,13.54000000,100,1,13.38000000,33,1,13.37000000,100,1,13.31000000,10,1,13.30000000,100,1,13.28000000,11,2,13.27000000,110,2,13.26000000,204,4,13.25000000,111,2,13.40000000,208,12,13.67000000,100,1,13.71000000,1,1,13.72000000,15,1,13.73000000,115,2,13.74000000,115,2,13.75000000,200,2,13.76000000,130,3,13.77000000,315,4,13.78000000,204,4,ARL,302662821
1150,2025-07-17T15:44:33.389387814Z,2025-07-17T15:44:33.389222513Z,160,2,1108,A,A,0,14.28000000,100,130,165301,253745665,13.55000000,10,1,13.54000000,100,1,13.38000000,33,1,13.37000000,100,1,13.31000000,10,1,13.30000000,100,1,13.28000000,11,2,13.27000000,110,2,13.26000000,204,4,13.25000000,111,2,13.40000000,208,12,13.67000000,100,1,13.71000000,1,1,13.72000000,15,1,13.73000000,115,2,13.74000000,115,2,13.75000000,200,2,13.76000000,130,3,13.77000000,315,4,13.78000000,204,4,ARL,302681357
1151,2025-07-17T15:44:33.389389030Z,2025-07-17T15:44:33.389223581Z,160,2,1108,C,A,0,14.56000000,100,130,165449,253745666,13.55000000,10,1,13.54000000,100,1,13.38000000,33,1,13.37000000,100,1,13.31000000,10,1,13.30000000,100,1,13.28000000,11,2,13.27000000,110,2,13.26000000,204,4,13.25000000,111,2,13.40000000,208,12,13.67000000,100,1,13.71000000,1,1,13.72000000,15,1,13.73000000,115,2,13.74000000,115,2,13.75000000,200,2,13.76000000,130,3,13.77000000,315,4,13.78000000,204,4,ARL,146960005
1152,2025-07-17T15:44:36.362187673Z,2025-07-17T15:44:36.362022168Z,160,2,1108,C,A,0,13.74000000,15,130,165505,253783635,13.55000000,10,1,13.54000000,100,1,13.38000000,33,1,13.37000000,100,1,13.31000000,10,1,13.30000000,100,1,13.28000000,11,2,13.27000000,110,2,13.26000000,204,4,13.25000000,111,2,13.40000000,208,12,13.67000000,100,1,13.71000000,1,1,13.72000000,15,1,13.73000000,115,2,13.74000000,115,2,13.75000000,200,2,13.76000000,130,3,13.77000000,315,4,13.78000000,204,4,ARL,302458113
1153,2025-07-17T15:44:37.364377419Z,2025-07-17T15:44:37.364212109Z,160,2,1108,A,A,0,13.70000000,15,130,165310,253797506,13.55000000,10,1,13.54000000,100,1,13.38000000,33,1,13.37000000,100,1,13.31000000,10,1,13.30000000,100,1,13.28000000,11,2,13.27000000,110,2,13.26000000,204,4,13.25000000,111,2,13.40000000,208,12,13.67000000,100,1,13.70000000,15,1,13.71000000,1,1,13.72000000,15,1,13.73000000,115,2,13.74000000,115,2,13.75000000,200,2,13.76000000,130,3,13.77000000,315,4,ARL,302750929
1154,2025-07-17T15:44:37.364519067Z,2025-07-17T15:44:37.364353897Z,160,2,1108,A,A,0,13.73000000,100,130,165170,253797510,13.55000000,10,1,13.54000000,100,1,13.38000000,33,1,13.37000000,100,1,13.31000000,10,1,13.30000000,100,1,13.28000000,11,2,13.27000000,110,2,13.26000000,204,4,13.25000000,111,2,13.40000000,208,12,13.67000000,100,1,13.70000000,15,1,13.71000000,1,1,13.72000000,15,1,13.73000000,215,3,13.74000000,115,2,13.75000000,200,2,13.76000000,130,3,13.77000000,315,4,ARL,302750937
1155,2025-07-17T15:44:37.458119494Z,2025-07-17T15:44:37.457954350Z,160,2,1108,C,A,0,13.75000000,100,130,165144,253798432,13.55000000,10,1,13.54000000,100,1,13.38000000,33,1,13.37000000,100,1,13.31000000,10,1,13.30000000,100,1,13.28000000,11,2,13.27000000,110,2,13.26000000,204,4,13.25000000,111,2,13.40000000,208,12,13.67000000,100,1,13.70000000,15,1,13.71000000,1,1,13.72000000,15,1,13.73000000,215,3,13.74000000,115,2,13.75000000,200,2,13.76000000,130,3,13.77000000,315,4,ARL,302649029
1156,2025-07-17T15:44:38.432460509Z,2025-07-17T15:44:38.432294362Z,160,2,1108,C,A,0,13.73000000,100,0,166147,253807786,13.55000000,10,1,13.54000000,100,1,13.38000000,33,1,13.37000000,100,1,13.31000000,10,1,13.30000000,100,1,13.28000000,11,2,13.27000000,110,2,13.26000000,204,4,13.25000000,111,2,13.40000000,208,12,13.67000000,100,1,13.70000000,15,1,13.71000000,1,1,13.72000000,15,1,13.73000000,215,3,13.74000000,115,2,13.75000000,200,2,13.76000000,130,3,13.77000000,315,4,ARL,302662769
1157,2025-07-17T15:44:38.432460509Z,2025-07-17T15:44:38.432294362Z,160,2,1108,A,A,0,13.71000000,100,130,166147,253807786,13.55000000,10,1,13.54000000,100,1,13.38000000,33,1,13.37000000,100,1,13.31000000,10,1,13.30000000,100,1,13.28000000,11,2,13.27000000,110,2,13.26000000,204,4,13.25000000,111,2,13.40000000,208,12,13.67000000,100,1,13.70000000,15,1,13.71000000,101,2,13.72000000,15,1,13.73000000,215,3,13.74000000,115,2,13.75000000,200,2,13.76000000,130,3,13.77000000,315,4,ARL,302763889
1158,2025-07-17T15:44:38.439253975Z,2025-07-17T15:44:38.439088042Z,160,2,1108,C,A,0,15.92000000,100,0,165933,253808105,13.55000000,10,1,13.54000000,100,1,13.38000000,33,1,13.37000000,100,1,13.31000000,10,1,13.30000000,100,1,13.28000000,11,2,13.27000000,110,2,13.26000000,204,4,13.25000000,111,2,13.40000000,208,12,13.67000000,100,1,13.70000000,15,1,13.71000000,101,2,13.72000000,15,1,13.73000000,215,3,13.74000000,115,2,13.75000000,200,2,13.76000000,130,3,13.77000000,315,4,ARL,301747301
1159,2025-07-17T15:44:38.439253975Z,2025-07-17T15:44:38.439088042Z,160,2,1108,A,A,0,15.77000000,100,130,165933,253808105,13.55000000,10,1,13.54000000,100,1,13.38000000,33,1,13.37000000,100,1,13.31000000,10,1,13.30000000,100,1,13.28000000,11,2,13.27000000,110,2,13.26000000,204,4,13.25000000,111,2,13.40000000,208,12,13.67000000,100,1,13.70000000,15,1,13.71000000,101,2,13.72000000,15,1,13.73000000,215,3,13.74000000,115,2,13.75000000,200,2,13.76000000,130,3,13.77000000,315,4,ARL,302764121
1160,2025-07-17T15:44:38.440321697Z,2025-07-17T15:44:38.440156077Z,160,2,1108,C,A,0,17.58000000,100,0,165620,253808122,13.55000000,10,1,13.54000000,100,1,13.38000000,33,1,13.37000000,100,1,13.31000000,10,1,13.30000000,100,1,13.28000000,11,2,13.27000000,110,2,13.26000000,204,4,13.25000000,111,2,13.40000000,208,12,13.67000000,100,1,13.70000000,15,1,13.71000000,101,2,13.72000000,15,1,13.73000000,215,3,13.74000000,115,2,13.75000000,200,2,13.76000000,130,3,13.77000000,315,4,ARL,301747261
1161,2025-07-17T15:44:38.440321697Z,2025-07-17T15:44:38.440156077Z,160,2,1108,A,A,0,17.42000000,100,130,165620,253808122,13.55000000,10,1,13.54000000,100,1,13.38000000,33,1,13.37000000,100,1,13.31000000,10,1,13.30000000,100,1,13.28000000,11,2,13.27000000,110,2,13.26000000,204,4,13.25000000,111,2,13.40000000,208,12,13.67000000,100,1,13.70000000,15,1,13.71000000,101,2,13.72000000,15,1,13.73000000,215,3,13.74000000,115,2,13.75000000,200,2,13.76000000,130,3,13.77000000,315,4,ARL,302764137
1162,2025-07-17T15:44:43.019262217Z,2025-07-17T15:44:43.019083502Z,160,2,1108,C,A,0,13.70000000,15,128,178715,253875920,13.55000000,10,1,13.54000000,100,1,13.38000000,33,1,13.37000000,100,1,13.31000000,10,1,13.30000000,100,1,13.28000000,11,2,13.27000000,110,2,13.26000000,204,4,13.25000000,111,2,13.40000000,208,12,13.67000000,100,1,13.70000000,15,1,13.71000000,101,2,13.72000000,15,1,13.73000000,215,3,13.74000000,115,2,13.75000000,200,2,13.76000000,130,3,13.77000000,315,4,ARL,302750929
1163,2025-07-17T15:44:43.019352658Z,2025-07-17T15:44:43.019184132Z,160,2,1108,C,A,0,13.72000000,15,128,168526,253876010,13.55000000,10,1,13.54000000,100,1,13.38000000,33,1,13.37000000,100,1,13.31000000,10,1,13.30000000,100,1,13.28000000,11,2,13.27000000,110,2,13.26000000,204,4,13.25000000,111,2,13.40000000,208,12,13.67000000,100,1,13.70000000,15,1,13.71000000,101,2,13.72000000,15,1,13.73000000,215,3,13.74000000,115,2,13.75000000,200,2,13.76000000,130,3,13.77000000,315,4,ARL,302649021
1164,2025-07-17T15:44:44.076009999Z,2025-07-17T15:44:44.075843113Z,160,2,1108,A,A,0,13.70000000,15,128,166886,253892869,13.55000000,10,1,13.54000000,100,1,13.38000000,33,1,13.37000000,100,1,13.31000000,10,1,13.30000000,100,1,13.28000000,11,2,13.27000000,110,2,13.26000000,204,4,13.25000000,111,2,13.40000000,208,12,13.67000000,100,1,13.70000000,30,2,13.71000000,101,2,13.72000000,15,1,13.73000000,215,3,13.74000000,115,2,13.75000000,200,2,13.76000000,130,3,13.77000000,315,4,ARL,302867209
1165,2025-07-17T15:44:44.781630732Z,2025-07-17T15:44:44.781464821Z,160,2,1108,C,A,0,13.70000000,15,130,165911,253901222,13.55000000,10,1,13.54000000,100,1,13.38000000,33,1,13.37000000,100,1,13.31000000,10,1,13.30000000,100,1,13.28000000,11,2,13.27000000,110,2,13.26000000,204,4,13.25000000,111,2,13.40000000,208,12,13.67000000,100,1,13.70000000,30,2,13.71000000,101,2,13.72000000,15,1,13.73000000,215,3,13.74000000,115,2,13.75000000,200,2,13.76000000,130,3,13.77000000,315,4,ARL,302867209
1166,2025-07-17T15:44:53.143249270Z,2025-07-17T15:44:53.143083969Z,160,2,1108,C,A,0,13.73000000,100,130,165301,254011871,13.55000000,10,1,13.54000000,100,1,13.38000000,33,1,13.37000000,100,1,13.31000000,10,1,13.30000000,100,1,13.28000000,11,2,13.27000000,110,2,13.26000000,204,4,13.25000000,111,2,13.40000000,208,12,13.67000000,100,1,13.70000000,30,2,13.71000000,101,2,13.72000000,15,1,13.73000000,215,3,13.74000000,115,2,13.75000000,200,2,13.76000000,130,3,13.77000000,315,4,ARL,302750937
1167,2025-07-17T15:44:57.191188470Z,2025-07-17T15:44:57.191023026Z,160,2,1108,A,A,0,13.75000000,100,130,165444,254079162,13.55000000,10,1,13.54000000,100,1,13.38000000,33,1,13.37000000,100,1,13.31000000,10,1,13.30000000,100,1,13.28000000,11,2,13.27000000,110,2,13.26000000,204,4,13.25000000,111,2,13.40000000,208,12,13.67000000,100,1,13.70000000,30,2,13.71000000,101,2,13.72000000,15,1,13.73000000,215,3,13.74000000,115,2,13.75000000,300,3,13.76000000,130,3,13.77000000,315,4,ARL,303118785
1168,2025-07-17T15:45:07.065756574Z,2025-07-17T15:45:07.065587919Z,160,2,1108,C,A,0,13.71000000,100,128,168655,254244597,13.55000000,10,1,13.54000000,100,1,13.38000000,33,1,13.37000000,100,1,13.31000000,10,1,13.30000000,100,1,13.28000000,11,2,13.27000000,110,2,13.26000000,204,4,13.25000000,111,2,13.40000000,208,12,13.67000000,100,1,13.70000000,30,2,13.71000000,101,2,13.72000000,15,1,13.73000000,215,3,13.74000000,115,2,13.75000000,300,3,13.76000000,130,3,13.77000000,315,4,ARL,302763889
1169,2025-07-17T15:45:07.080131505Z,2025-07-17T15:45:07.079966224Z,160,2,1108,C,A,0,13.75000000,100,130,165281,254245492,13.55000000,10,1,13.54000000,100,1,13.38000000,33,1,13.37000000,100,1,13.31000000,10,1,13.30000000,100,1,13.28000000,11,2,13.27000000,110,2,13.26000000,204,4,13.25000000,111,2,13.40000000,208,12,13.67000000,100,1,13.70000000,30,2,13.71000000,101,2,13.72000000,15,1,13.73000000,215,3,13.74000000,115,2,13.75000000,300,3,13.76000000,130,3,13.77000000,315,4,ARL,303118785
1170,2025-07-17T15:45:07.080687215Z,2025-07-17T15:45:07.080521807Z,160,2,1108,C,A,0,14.66000000,100,0,165408,254245505,13.55000000,10,1,13.54000000,100,1,13.38000000,33,1,13.37000000,100,1,13.31000000,10,1,13.30000000,100,1,13.28000000,11,2,13.27000000,110,2,13.26000000,204,4,13.25000000,111,2,13.40000000,208,12,13.67000000,100,1,13.70000000,30,2,13.71000000,101,2,13.72000000,15,1,13.73000000,215,3,13.74000000,115,2,13.75000000,300,3,13.76000000,130,3,13.77000000,315,4,ARL,302205289
1171,2025-07-17T15:45:07.080687215Z,2025-07-17T15:45:07.080521807Z,160,2,1108,A,A,0,14.89000000,100,130,165408,254245505,13.55000000,10,1,13.54000000,100,1,13.38000000,33,1,13.37000000,100,1,13.31000000,10,1,13.30000000,100,1,13.28000000,11,2,13.27000000,110,2,13.26000000,204,4,13.25000000,111,2,13.40000000,208,12,13.67000000,100,1,13.70000000,30,2,13.71000000,101,2,13.72000000,15,1,13.73000000,215,3,13.74000000,115,2,13.75000000,300,3,13.76000000,130,3,13.77000000,315,4,ARL,303330477
1172,2025-07-17T15:45:07.080872245Z,2025-07-17T15:45:07.080706110Z,160,2,1108,C,A,0,14.79000000,100,0,166135,254245511,13.55000000,10,1,13.54000000,100,1,13.38000000,33,1,13.37000000,100,1,13.31000000,10,1,13.30000000,100,1,13.28000000,11,2,13.27000000,110,2,13.26000000,204,4,13.25000000,111,2,13.40000000,208,12,13.67000000,100,1,13.70000000,30,2,13.71000000,101,2,13.72000000,15,1,13.73000000,215,3,13.74000000,115,2,13.75000000,300,3,13.76000000,130,3,13.77000000,315,4,ARL,302662821
1173,2025-07-17T15:45:07.080872245Z,2025-07-17T15:45:07.080706110Z,160,2,1108,A,A,0,15.06000000,100,130,166135,254245511,13.55000000,10,1,13.54000000,100,1,13.38000000,33,1,13.37000000,100,1,13.31000000,10,1,13.30000000,100,1,13.28000000,11,2,13.27000000,110,2,13.26000000,204,4,13.25000000,111,2,13.40000000,208,12,13.67000000,100,1,13.70000000,30,2,13.71000000,101,2,13.72000000,15,1,13.73000000,215,3,13.74000000,115,2,13.75000000,300,3,13.76000000,130,3,13.77000000,315,4,ARL,303330485
1174,2025-07-17T15:45:07.081578064Z,2025-07-17T15:45:07.081407507Z,160,2,1108,C,A,0,14.81000000,100,0,170557,254245568,13.55000000,10,1,13.54000000,100,1,13.38000000,33,1,13.37000000,100,1,13.31000000,10,1,13.30000000,100,1,13.28000000,11,2,13.27000000,110,2,13.26000000,204,4,13.25000000,111,2,13.40000000,208,12,13.67000000,100,1,13.70000000,30,2,13.71000000,101,2,13.72000000,15,1,13.73000000,215,3,13.74000000,115,2,13.75000000,300,3,13.76000000,130,3,13.77000000,315,4,ARL,301747001
1175,2025-07-17T15:45:07.081578064Z,2025-07-17T15:45:07.081407507Z,160,2,1108,A,A,0,14.96000000,100,128,170557,254245568,13.55000000,10,1,13.54000000,100,1,13.38000000,33,1,13.37000000,100,1,13.31000000,10,1,13.30000000,100,1,13.28000000,11,2,13.27000000,110,2,13.26000000,204,4,13.25000000,111,2,13.40000000,208,12,13.67000000,100,1,13.70000000,30,2,13.71000000,101,2,13.72000000,15,1,13.73000000,215,3,13.74000000,115,2,13.75000000,300,3,13.76000000,130,3,13.77000000,315,4,ARL,303330509
1176,2025-07-17T15:45:07.081607970Z,2025-07-17T15:45:07.081441134Z,160,2,1108,C,A,0,14.66000000,100,0,166836,254245576,13.55000000,10,1,13.54000000,100,1,13.38000000,33,1,13.37000000,100,1,13.31000000,10,1,13.30000000,100,1,13.28000000,11,2,13.27000000,110,2,13.26000000,204,4,13.25000000,111,2,13.40000000,208,12,13.67000000,100,1,13.70000000,30,2,13.71000000,101,2,13.72000000,15,1,13.73000000,215,3,13.74000000,115,2,13.75000000,300,3,13.76000000,130,3,13.77000000,315,4,ARL,302205309
1177,2025-07-17T15:45:07.081607970Z,2025-07-17T15:45:07.081441134Z,160,2,1108,A,A,0,14.89000000,100,130,166836,254245576,13.55000000,10,1,13.54000000,100,1,13.38000000,33,1,13.37000000,100,1,13.31000000,10,1,13.30000000,100,1,13.28000000,11,2,13.27000000,110,2,13.26000000,204,4,13.25000000,111,2,13.40000000,208,12,13.67000000,100,1,13.70000000,30,2,13.71000000,101,2,13.72000000,15,1,13.73000000,215,3,13.74000000,115,2,13.75000000,300,3,13.76000000,130,3,13.77000000,315,4,ARL,303330521
1178,2025-07-17T15:45:07.083898999Z,2025-07-17T15:45:07.083732443Z,160,2,1108,C,A,0,17.42000000,100,0,166556,254246327,13.55000000,10,1,13.54000000,100,1,13.38000000,33,1,13.37000000,100,1,13.31000000,10,1,13.30000000,100,1,13.28000000,11,2,13.27000000,110,2,13.26000000,204,4,13.25000000,111,2,13.40000000,208,12,13.67000000,100,1,13.70000000,30,2,13.71000000,101,2,13.72000000,15,1,13.73000000,215,3,13.74000000,115,2,13.75000000,300,3,13.76000000,130,3,13.77000000,315,4,ARL,302764137
1179,2025-07-17T15:45:07.083898999Z,2025-07-17T15:45:07.083732443Z,160,2,1108,A,A,0,17.76000000,100,130,166556,254246327,13.55000000,10,1,13.54000000,100,1,13.38000000,33,1,13.37000000,100,1,13.31000000,10,1,13.30000000,100,1,13.28000000,11,2,13.27000000,110,2,13.26000000,204,4,13.25000000,111,2,13.40000000,208,12,13.67000000,100,1,13.70000000,30,2,13.71000000,101,2,13.72000000,15,1,13.73000000,215,3,13.74000000,115,2,13.75000000,300,3,13.76000000,130,3,13.77000000,315,4,ARL,303331309
1180,2025-07-17T15:45:07.085222525Z,2025-07-17T15:45:07.085057258Z,160,2,1108,C,A,0,14.03000000,100,130,165267,254246434,13.55000000,10,1,13.54000000,100,1,13.38000000,33,1,13.37000000,100,1,13.31000000,10,1,13.30000000,100,1,13.28000000,11,2,13.27000000,110,2,13.26000000,204,4,13.25000000,111,2,13.40000000,208,12,13.67000000,100,1,13.70000000,30,2,13.71000000,101,2,13.72000000,15,1,13.73000000,215,3,13.74000000,115,2,13.75000000,300,3,13.76000000,130,3,13.77000000,315,4,ARL,302466157
1181,2025-07-17T15:45:07.085274852Z,2025-07-17T15:45:07.085109545Z,160,2,1108,A,A,0,14.26000000,100,130,165307,254246437,13.55000000,10,1,13.54000000,100,1,13.38000000,33,1,13.37000000,100,1,13.31000000,10,1,13.30000000,100,1,13.28000000,11,2,13.27000000,110,2,13.26000000,204,4,13.25000000,111,2,13.40000000,208,12,13.67000000,100,1,13.70000000,30,2,13.71000000,101,2,13.72000000,15,1,13.73000000,215,3,13.74000000,115,2,13.75000000,300,3,13.76000000,130,3,13.77000000,315,4,ARL,303331401
1182,2025-07-17T15:45:07.086534700Z,2025-07-17T15:45:07.086368957Z,160,2,1108,C,A,0,14.64000000,100,130,165743,254246501,13.55000000,10,1,13.54000000,100,1,13.38000000,33,1,13.37000000,100,1,13.31000000,10,1,13.30000000,100,1,13.28000000,11,2,13.27000000,110,2,13.26000000,204,4,13.25000000,111,2,13.40000000,208,12,13.67000000,100,1,13.70000000,30,2,13.71000000,101,2,13.72000000,15,1,13.73000000,215,3,13.74000000,115,2,13.75000000,300,3,13.76000000,130,3,13.77000000,315,4,ARL,301747005
1183,2025-07-17T15:45:07.086660325Z,2025-07-17T15:45:07.086494745Z,160,2,1108,A,A,0,14.78000000,100,130,165580,254246502,13.55000000,10,1,13.54000000,100,1,13.38000000,33,1,13.37000000,100,1,13.31000000,10,1,13.30000000,100,1,13.28000000,11,2,13.27000000,110,2,13.26000000,204,4,13.25000000,111,2,13.40000000,208,12,13.67000000,100,1,13.70000000,30,2,13.71000000,101,2,13.72000000,15,1,13.73000000,215,3,13.74000000,115,2,13.75000000,300,3,13.76000000,130,3,13.77000000,315,4,ARL,303331425
1184,2025-07-17T15:45:07.087389466Z,2025-07-17T15:45:07.087223859Z,160,2,1108,C,A,0,15.77000000,100,0,165607,254246529,13.55000000,10,1,13.54000000,100,1,13.38000000,33,1,13.37000000,100,1,13.31000000,10,1,13.30000000,100,1,13.28000000,11,2,13.27000000,110,2,13.26000000,204,4,13.25000000,111,2,13.40000000,208,12,13.67000000,100,1,13.70000000,30,2,13.71000000,101,2,13.72000000,15,1,13.73000000,215,3,13.74000000,115,2,13.75000000,300,3,13.76000000,130,3,13.77000000,315,4,ARL,302764121
1185,2025-07-17T15:45:07.087389466Z,2025-07-17T15:45:07.087223859Z,160,2,1108,A,A,0,16.08000000,100,130,165607,254246529,13.55000000,10,1,13.54000000,100,1,13.38000000,33,1,13.37000000,100,1,13.31000000,10,1,13.30000000,100,1,13.28000000,11,2,13.27000000,110,2,13.26000000,204,4,13.25000000,111,2,13.40000000,208,12,13.67000000,100,1,13.70000000,30,2,13.71000000,101,2,13.72000000,15,1,13.73000000,215,3,13.74000000,115,2,13.75000000,300,3,13.76000000,130,3,13.77000000,315,4,ARL,303331429
1186,2025-07-17T15:45:07.133978488Z,2025-07-17T15:45:07.133812895Z,160,2,1108,C,A,0,14.81000000,100,0,165593,254250625,13.55000000,10,1,13.54000000,100,1,13.38000000,33,1,13.37000000,100,1,13.31000000,10,1,13.30000000,100,1,13.28000000,11,2,13.27000000,110,2,13.26000000,204,4,13.25000000,111,2,13.40000000,208,12,13.67000000,100,1,13.70000000,30,2,13.71000000,101,2,13.72000000,15,1,13.73000000,215,3,13.74000000,115,2,13.75000000,300,3,13.76000000,130,3,13.77000000,315,4,ARL,301747957
1187,2025-07-17T15:45:07.133978488Z,2025-07-17T15:45:07.133812895Z,160,2,1108,A,A,0,14.96000000,100,130,165593,254250625,13.55000000,10,1,13.54000000,100,1,13.38000000,33,1,13.37000000,100,1,13.31000000,10,1,13.30000000,100,1,13.28000000,11,2,13.27000000,110,2,13.26000000,204,4,13.25000000,111,2,13.40000000,208,12,13.67000000,100,1,13.70000000,30,2,13.71000000,101,2,13.72000000,15,1,13.73000000,215,3,13.74000000,115,2,13.75000000,300,3,13.76000000,130,3,13.77000000,315,4,ARL,303334253
1188,2025-07-17T15:45:07.469961302Z,2025-07-17T15:45:07.469796155Z,160,2,1108,A,A,0,14.08000000,100,130,165147,254258029,13.55000000,10,1,13.54000000,100,1,13.38000000,33,1,13.37000000,100,1,13.31000000,10,1,13.30000000,100,1,13.28000000,11,2,13.27000000,110,2,13.26000000,204,4,13.25000000,111,2,13.40000000,208,12,13.67000000,100,1,13.70000000,30,2,13.71000000,101,2,13.72000000,15,1,13.73000000,215,3,13.74000000,115,2,13.75000000,300,3,13.76000000,130,3,13.77000000,315,4,ARL,303340405
1189,2025-07-17T15:45:08.094768552Z,2025-07-17T15:45:08.094603115Z,160,2,1108,C,A,0,14.89000000,100,0,165437,254266885,13.55000000,10,1,13.54000000,100,1,13.38000000,33,1,13.37000000,100,1,13.31000000,10,1,13.30000000,100,1,13.28000000,11,2,13.27000000,110,2,13.26000000,204,4,13.25000000,111,2,13.40000000,208,12,13.67000000,100,1,13.70000000,30,2,13.71000000,101,2,13.72000000,15,1,13.73000000,215,3,13.74000000,115,2,13.75000000,300,3,13.76000000,130,3,13.77000000,315,4,ARL,303330521
1190,2025-07-17T15:45:08.094768552Z,2025-07-17T15:45:08.094603115Z,160,2,1108,A,A,0,15.10000000,100,130,165437,254266885,13.55000000,10,1,13.54000000,100,1,13.38000000,33,1,13.37000000,100,1,13.31000000,10,1,13.30000000,100,1,13.28000000,11,2,13.27000000,110,2,13.26000000,204,4,13.25000000,111,2,13.40000000,208,12,13.67000000,100,1,13.70000000,30,2,13.71000000,101,2,13.72000000,15,1,13.73000000,215,3,13.74000000,115,2,13.75000000,300,3,13.76000000,130,3,13.77000000,315,4,ARL,303349309
1191,2025-07-17T15:45:08.103306644Z,2025-07-17T15:45:08.103141155Z,160,2,1108,C,A,0,14.89000000,100,0,165489,254266971,13.55000000,10,1,13.54000000,100,1,13.38000000,33,1,13.37000000,100,1,13.31000000,10,1,13.30000000,100,1,13.28000000,11,2,13.27000000,110,2,13.26000000,204,4,13.25000000,111,2,13.40000000,208,12,13.67000000,100,1,13.70000000,30,2,13.71000000,101,2,13.72000000,15,1,13.73000000,215,3,13.74000000,115,2,13.75000000,300,3,13.76000000,130,3,13.77000000,315,4,ARL,303330477
1192,2025-07-17T15:45:08.103306644Z,2025-07-17T15:45:08.103141155Z,160,2,1108,A,A,0,15.10000000,100,130,165489,254266971,13.55000000,10,1,13.54000000,100,1,13.38000000,33,1,13.37000000,100,1,13.31000000,10,1,13.30000000,100,1,13.28000000,11,2,13.27000000,110,2,13.26000000,204,4,13.25000000,111,2,13.40000000,208,12,13.67000000,100,1,13.70000000,30,2,13.71000000,101,2,13.72000000,15,1,13.73000000,215,3,13.74000000,115,2,13.75000000,300,3,13.76000000,130,3,13.77000000,315,4,ARL,303349377
1193,2025-07-17T15:45:24.187008278Z,2025-07-17T15:45:24.186842413Z,160,2,1108,C,A,0,15.10000000,100,0,165865,254547413,13.55000000,10,1,13.54000000,100,1,13.38000000,33,1,13.37000000,100,1,13.31000000,10,1,13.30000000,100,1,13.28000000,11,2,13.27000000,110,2,13.26000000,204,4,13.25000000,111,2,13.40000000,208,12,13.67000000,100,1,13.70000000,30,2,13.71000000,101,2,13.72000000,15,1,13.73000000,215,3,13.74000000,115,2,13.75000000,300,3,13.76000000,130,3,13.77000000,315,4,ARL,303349309
1194,2025-07-17T15:45:24.187008278Z,2025-07-17T15:45:24.186842413Z,160,2,1108,A,A,0,14.88000000,100,130,165865,254547413,13.55000000,10,1,13.54000000,100,1,13.38000000,33,1,13.37000000,100,1,13.31000000,10,1,13.30000000,100,1,13.28000000,11,2,13.27000000,110,2,13.26000000,204,4,13.25000000,111,2,13.40000000,208,12,13.67000000,100,1,13.70000000,30,2,13.71000000,101,2,13.72000000,15,1,13.73000000,215,3,13.74000000,115,2,13.75000000,300,3,13.76000000,130,3,13.77000000,315,4,ARL,303682385
1195,2025-07-17T15:45:24.187441892Z,2025-07-17T15:45:24.187276389Z,160,2,1108,C,A,0,15.10000000,100,0,165503,254547415,13.55000000,10,1,13.54000000,100,1,13.38000000,33,1,13.37000000,100,1,13.31000000,10,1,13.30000000,100,1,13.28000000,11,2,13.27000000,110,2,13.26000000,204,4,13.25000000,111,2,13.40000000,208,12,13.67000000,100,1,13.70000000,30,2,13.71000000,101,2,13.72000000,15,1,13.73000000,215,3,13.74000000,115,2,13.75000000,300,3,13.76000000,130,3,13.77000000,315,4,ARL,303349377
1196,2025-07-17T15:45:24.187441892Z,2025-07-17T15:45:24.187276389Z,160,2,1108,A,A,0,14.88000000,100,130,165503,254547415,13.55000000,10,1,13.54000000,100,1,13.38000000,33,1,13.37000000,100,1,13.31000000,10,1,13.30000000,100,1,13.28000000,11,2,13.27000000,110,2,13.26000000,204,4,13.25000000,111,2,13.40000000,208,12,13.67000000,100,1,13.70000000,30,2,13.71000000,101,2,13.72000000,15,1,13.73000000,215,3,13.74000000,115,2,13.75000000,300,3,13.76000000,130,3,13.77000000,315,4,ARL,303682389
1197,2025-07-17T15:45:37.509454888Z,2025-07-17T15:45:37.509289536Z,160,2,1108,A,A,0,13.94000000,15,130,165352,254851462,13.55000000,10,1,13.54000000,100,1,13.38000000,33,1,13.37000000,100,1,13.31000000,10,1,13.30000000,100,1,13.28000000,11,2,13.27000000,110,2,13.26000000,204,4,13.25000000,111,2,13.40000000,208,12,13.67000000,100,1,13.70000000,30,2,13.71000000,101,2,13.72000000,15,1,13.73000000,215,3,13.74000000,115,2,13.75000000,300,3,13.76000000,130,3,13.77000000,315,4,ARL,304056997
1198,2025-07-17T15:45:37.998133497Z,2025-07-17T15:45:37.997967775Z,160,2,1108,C,A,0,14.08000000,100,0,165722,254864588,13.55000000,10,1,13.54000000,100,1,13.38000000,33,1,13.37000000,100,1,13.31000000,10,1,13.30000000,100,1,13.28000000,11,2,13.27000000,110,2,13.26000000,204,4,13.25000000,111,2,13.40000000,208,12,13.67000000,100,1,13.70000000,30,2,13.71000000,101,2,13.72000000,15,1,13.73000000,215,3,13.74000000,115,2,13.75000000,300,3,13.76000000,130,3,13.77000000,315,4,ARL,303340405
1199,2025-07-17T15:45:37.998133497Z,2025-07-17T15:45:37.997967775Z,160,2,1108,A,A,0,13.95000000,100,130,165722,254864588,13.55000000,10,1,13.54000000,100,1,13.38000000,33,1,13.37000000,100,1,13.31000000,10,1,13.30000000,100,1,13.28000000,11,2,13.27000000,110,2,13.26000000,204,4,13.25000000,111,2,13.40000000,208,12,13.67000000,100,1,13.70000000,30,2,13.71000000,101,2,13.72000000,15,1,13.73000000,215,3,13.74000000,115,2,13.75000000,300,3,13.76000000,130,3,13.77000000,315,4,ARL,304072245
1200,2025-07-17T15:45:44.700593408Z,2025-07-17T15:45:44.700428155Z,160,2,1108,A,A,0,13.89000000,15,130,165253,254999429,13.55000000,10,1,13.54000000,100,1,13.38000000,33,1,13.37000000,100,1,13.31000000,10,1,13.30000000,100,1,13.28000000,11,2,13.27000000,110,2,13.26000000,204,4,13.25000000,111,2,13.40000000,208,12,13.67000000,100,1,13.70000000,30,2,13.71000000,101,2,13.72000000,15,1,13.73000000,215,3,13.74000000,115,2,13.75000000,300,3,13.76000000,130,3,13.77000000,315,4,ARL,304238913
1201,2025-07-17T15:45:45.262537122Z,2025-07-17T15:45:45.262371701Z,160,2,1108,C,A,0,13.95000000,100,0,165421,255010979,13.55000000,10,1,13.54000000,100,1,13.38000000,33,1,13.37000000,100,1,13.31000000,10,1,13.30000000,100,1,13.28000000,11,2,13.27000000,110,2,13.26000000,204,4,13.25000000,111,2,13.40000000,208,12,13.67000000,100,1,13.70000000,30,2,13.71000000,101,2,13.72000000,15,1,13.73000000,215,3,13.74000000,115,2,13.75000000,300,3,13.76000000,130,3,13.77000000,315,4,ARL,304072245
1202,2025-07-17T15:45:45.262537122Z,2025-07-17T15:45:45.262371701Z,160,2,1108,A,A,0,13.90000000,100,130,165421,255010979,13.55000000,10,1,13.54000000,100,1,13.38000000,33,1,13.37000000,100,1,13.31000000,10,1,13.30000000,100,1,13.28000000,11,2,13.27000000,110,2,13.26000000,204,4,13.25000000,111,2,13.40000000,208,12,13.67000000,100,1,13.70000000,30,2,13.71000000,101,2,13.72000000,15,1,13.73000000,215,3,13.74000000,115,2,13.75000000,300,3,13.76000000,130,3,13.77000000,315,4,ARL,304252313
1203,2025-07-17T15:45:45.263289023Z,2025-07-17T15:45:45.263123432Z,160,2,1108,C,A,0,15.06000000,100,0,165591,255010987,13.55000000,10,1,13.54000000,100,1,13.38000000,33,1,13.37000000,100,1,13.31000000,10,1,13.30000000,100,1,13.28000000,11,2,13.27000000,110,2,13.26000000,204,4,13.25000000,111,2,13.40000000,208,12,13.67000000,100,1,13.70000000,30,2,13.71000000,101,2,13.72000000,15,1,13.73000000,215,3,13.74000000,115,2,13.75000000,300,3,13.76000000,130,3,13.77000000,315,4,ARL,303330485
1204,2025-07-17T15:45:45.263289023Z,2025-07-17T15:45:45.263123432Z,160,2,1108,A,A,0,14.98000000,100,130,165591,255010987,13.55000000,10,1,13.54000000,100,1,13.38000000,33,1,13.37000000,100,1,13.31000000,10,1,13.30000000,100,1,13.28000000,11,2,13.27000000,110,2,13.26000000,204,4,13.25000000,111,2,13.40000000,208,12,13.67000000,100,1,13.70000000,30,2,13.71000000,101,2,13.72000000,15,1,13.73000000,215,3,13.74000000,115,2,13.75000000,300,3,13.76000000,130,3,13.77000000,315,4,ARL,304252333
1205,2025-07-17T15:45:45.274360382Z,2025-07-17T15:45:45.274194870Z,160,2,1108,C,A,0,14.26000000,100,130,165512,255011158,13.55000000,10,1,13.54000000,100,1,13.38000000,33,1,13.37000000,100,1,13.31000000,10,1,13.30000000,100,1,13.28000000,11,2,13.27000000,110,2,13.26000000,204,4,13.25000000,111,2,13.40000000,208,12,13.67000000,100,1,13.70000000,30,2,13.71000000,101,2,13.72000000,15,1,13.73000000,215,3,13.74000000,115,2,13.75000000,300,3,13.76000000,130,3,13.77000000,315,4,ARL,303331401
1206,2025-07-17T15:45:45.274410721Z,2025-07-17T15:45:45.274245387Z,160,2,1108,A,A,0,14.18000000,100,130,165334,255011161,13.55000000,10,1,13.54000000,100,1,13.38000000,33,1,13.37000000,100,1,13.31000000,10,1,13.30000000,100,1,13.28000000,11,2,13.27000000,110,2,13.26000000,204,4,13.25000000,111,2,13.40000000,208,12,13.67000000,100,1,13.70000000,30,2,13.71000000,101,2,13.72000000,15,1,13.73000000,215,3,13.74000000,115,2,13.75000000,300,3,13.76000000,130,3,13.77000000,315,4,ARL,304252469
1207,2025-07-17T15:45:58.419783333Z,2025-07-17T15:45:58.419617935Z,160,2,1108,C,A,0,13.94000000,15,130,165398,255183198,13.55000000,10,1,13.54000000,100,1,13.38000000,33,1,13.37000000,100,1,13.31000000,10,1,13.30000000,100,1,13.28000000,11,2,13.27000000,110,2,13.26000000,204,4,13.25000000,111,2,13.40000000,208,12,13.67000000,100,1,13.70000000,30,2,13.71000000,101,2,13.72000000,15,1,13.73000000,215,3,13.74000000,115,2,13.75000000,300,3,13.76000000,130,3,13.77000000,315,4,ARL,304056997
1208,2025-07-17T15:45:58.420278691Z,2025-07-17T15:45:58.420113307Z,160,2,1108,C,A,0,14.88000000,100,0,165384,255183203,13.55000000,10,1,13.54000000,100,1,13.38000000,33,1,13.37000000,100,1,13.31000000,10,1,13.30000000,100,1,13.28000000,11,2,13.27000000,110,2,13.26000000,204,4,13.25000000,111,2,13.40000000,208,12,13.67000000,100,1,13.70000000,30,2,13.71000000,101,2,13.72000000,15,1,13.73000000,215,3,13.74000000,115,2,13.75000000,300,3,13.76000000,130,3,13.77000000,315,4,ARL,303682389
1209,2025-07-17T15:45:58.420278691Z,2025-07-17T15:45:58.420113307Z,160,2,1108,A,A,0,14.77000000,100,130,165384,255183203,13.55000000,10,1,13.54000000,100,1,13.38000000,33,1,13.37000000,100,1,13.31000000,10,1,13.30000000,100,1,13.28000000,11,2,13.27000000,110,2,13.26000000,204,4,13.25000000,111,2,13.40000000,208,12,13.67000000,100,1,13.70000000,30,2,13.71000000,101,2,13.72000000,15,1,13.73000000,215,3,13.74000000,115,2,13.75000000,300,3,13.76000000,130,3,13.77000000,315,4,ARL,304503585
1210,2025-07-17T15:45:58.420755889Z,2025-07-17T15:45:58.420590199Z,160,2,1108,C,A,0,14.88000000,100,0,165690,255183204,13.55000000,10,1,13.54000000,100,1,13.38000000,33,1,13.37000000,100,1,13.31000000,10,1,13.30000000,100,1,13.28000000,11,2,13.27000000,110,2,13.26000000,204,4,13.25000000,111,2,13.40000000,208,12,13.67000000,100,1,13.70000000,30,2,13.71000000,101,2,13.72000000,15,1,13.73000000,215,3,13.74000000,115,2,13.75000000,300,3,13.76000000,130,3,13.77000000,315,4,ARL,303682385
1211,2025-07-17T15:45:58.420755889Z,2025-07-17T15:45:58.420590199Z,160,2,1108,A,A,0,14.77000000,100,130,165690,255183204,13.55000000,10,1,13.54000000,100,1,13.38000000,33,1,13.37000000,100,1,13.31000000,10,1,13.30000000,100,1,13.28000000,11,2,13.27000000,110,2,13.26000000,204,4,13.25000000,111,2,13.40000000,208,12,13.67000000,100,1,13.70000000,30,2,13.71000000,101,2,13.72000000,15,1,13.73000000,215,3,13.74000000,115,2,13.75000000,300,3,13.76000000,130,3,13.77000000,315,4,ARL,304503593
1212,2025-07-17T15:45:58.782892109Z,2025-07-17T15:45:58.782726994Z,160,2,1108,C,A,0,13.89000000,15,130,165115,255189425,13.55000000,10,1,13.54000000,100,1,13.38000000,33,1,13.37000000,100,1,13.31000000,10,1,13.30000000,100,1,13.28000000,11,2,13.27000000,110,2,13.26000000,204,4,13.25000000,111,2,13.40000000,208,12,13.67000000,100,1,13.70000000,30,2,13.71000000,101,2,13.72000000,15,1,13.73000000,215,3,13.74000000,115,2,13.75000000,300,3,13.76000000,130,3,13.77000000,315,4,ARL,304238913
1213,2025-07-17T15:46:16.783057616Z,2025-07-17T15:46:16.782892334Z,160,2,1108,A,A,0,13.88000000,15,130,165282,255552962,13.55000000,10,1,13.54000000,100,1,13.38000000,33,1,13.37000000,100,1,13.31000000,10,1,13.30000000,100,1,13.28000000,11,2,13.27000000,110,2,13.26000000,204,4,13.25000000,111,2,13.40000000,208,12,13.67000000,100,1,13.70000000,30,2,13.71000000,101,2,13.72000000,15,1,13.73000000,215,3,13.74000000,115,2,13.75000000,300,3,13.76000000,130,3,13.77000000,315,4,ARL,304949689
1214,2025-07-17T15:46:16.783326241Z,2025-07-17T15:46:16.783160795Z,160,2,1108,C,A,0,13.90000000,100,0,165446,255552970,13.55000000,10,1,13.54000000,100,1,13.38000000,33,1,13.37000000,100,1,13.31000000,10,1,13.30000000,100,1,13.28000000,11,2,13.27000000,110,2,13.26000000,204,4,13.25000000,111,2,13.40000000,208,12,13.67000000,100,1,13.70000000,30,2,13.71000000,101,2,13.72000000,15,1,13.73000000,215,3,13.74000000,115,2,13.75000000,300,3,13.76000000,130,3,13.77000000,315,4,ARL,304252313
1215,2025-07-17T15:46:16.783326241Z,2025-07-17T15:46:16.783160795Z,160,2,1108,A,A,0,13.89000000,100,130,165446,255552970,13.55000000,10,1,13.54000000,100,1,13.38000000,33,1,13.37000000,100,1,13.31000000,10,1,13.30000000,100,1,13.28000000,11,2,13.27000000,110,2,13.26000000,204,4,13.25000000,111,2,13.40000000,208,12,13.67000000,100,1,13.70000000,30,2,13.71000000,101,2,13.72000000,15,1,13.73000000,215,3,13.74000000,115,2,13.75000000,300,3,13.76000000,130,3,13.77000000,315,4,ARL,304949697
1216,2025-07-17T15:46:18.782897570Z,2025-07-17T15:46:18.782732218Z,160,2,1108,C,A,0,13.88000000,15,130,165352,255587336,13.55000000,10,1,13.54000000,100,1,13.38000000,33,1,13.37000000,100,1,13.31000000,10,1,13.30000000,100,1,13.28000000,11,2,13.27000000,110,2,13.26000000,204,4,13.25000000,111,2,13.40000000,208,12,13.67000000,100,1,13.70000000,30,2,13.71000000,101,2,13.72000000,15,1,13.73000000,215,3,13.74000000,115,2,13.75000000,300,3,13.76000000,130,3,13.77000000,315,4,ARL,304949689
1217,2025-07-17T15:46:28.474166897Z,2025-07-17T15:46:28.474001551Z,160,2,1108,C,A,0,13.89000000,100,130,165346,255746167,13.55000000,10,1,13.54000000,100,1,13.38000000,33,1,13.37000000,100,1,13.31000000,10,1,13.30000000,100,1,13.28000000,11,2,13.27000000,110,2,13.26000000,204,4,13.25000000,111,2,13.40000000,208,12,13.67000000,100,1,13.70000000,30,2,13.71000000,101,2,13.72000000,15,1,13.73000000,215,3,13.74000000,115,2,13.75000000,300,3,13.76000000,130,3,13.77000000,315,4,ARL,304949697
1218,2025-07-17T15:46:28.474726594Z,2025-07-17T15:46:28.474561156Z,160,2,1108,C,A,0,14.77000000,100,0,165438,255746173,13.55000000,10,1,13.54000000,100,1,13.38000000,33,1,13.37000000,100,1,13.31000000,10,1,13.30000000,100,1,13.28000000,11,2,13.27000000,110,2,13.26000000,204,4,13.25000000,111,2,13.40000000,208,12,13.67000000,100,1,13.70000000,30,2,13.71000000,101,2,13.72000000,15,1,13.73000000,215,3,13.74000000,115,2,13.75000000,300,3,13.76000000,130,3,13.77000000,315,4,ARL,304503593
1219,2025-07-17T15:46:28.474726594Z,2025-07-17T15:46:28.474561156Z,160,2,1108,A,A,0,14.88000000,100,130,165438,255746173,13.55000000,10,1,13.54000000,100,1,13.38000000,33,1,13.37000000,100,1,13.31000000,10,1,13.30000000,100,1,13.28000000,11,2,13.27000000,110,2,13.26000000,204,4,13.25000000,111,2,13.40000000,208,12,13.67000000,100,1,13.70000000,30,2,13.71000000,101,2,13.72000000,15,1,13.73000000,215,3,13.74000000,115,2,13.75000000,300,3,13.76000000,130,3,13.77000000,315,4,ARL,305184937
1220,2025-07-17T15:46:28.474896460Z,2025-07-17T15:46:28.474730225Z,160,2,1108,C,A,0,14.77000000,100,0,166235,255746176,13.55000000,10,1,13.54000000,100,1,13.38000000,33,1,13.37000000,100,1,13.31000000,10,1,13.30000000,100,1,13.28000000,11,2,13.27000000,110,2,13.26000000,204,4,13.25000000,111,2,13.40000000,208,12,13.67000000,100,1,13.70000000,30,2,13.71000000,101,2,13.72000000,15,1,13.73000000,215,3,13.74000000,115,2,13.75000000,300,3,13.76000000,130,3,13.77000000,315,4,ARL,304503585
1221,2025-07-17T15:46:28.474896460Z,2025-07-17T15:46:28.474730225Z,160,2,1108,A,A,0,14.88000000,100,130,166235,255746176,13.55000000,10,1,13.54000000,100,1,13.38000000,33,1,13.37000000,100,1,13.31000000,10,1,13.30000000,100,1,13.28000000,11,2,13.27000000,110,2,13.26000000,204,4,13.25000000,111,2,13.40000000,208,12,13.67000000,100,1,13.70000000,30,2,13.71000000,101,2,13.72000000,15,1,13.73000000,215,3,13.74000000,115,2,13.75000000,300,3,13.76000000,130,3,13.77000000,315,4,ARL,305184953
1222,2025-07-17T15:46:28.474902154Z,2025-07-17T15:46:28.474736101Z,160,2,1108,C,A,0,14.98000000,100,0,166053,255746178,13.55000000,10,1,13.54000000,100,1,13.38000000,33,1,13.37000000,100,1,13.31000000,10,1,13.30000000,100,1,13.28000000,11,2,13.27000000,110,2,13.26000000,204,4,13.25000000,111,2,13.40000000,208,12,13.67000000,100,1,13.70000000,30,2,13.71000000,101,2,13.72000000,15,1,13.73000000,215,3,13.74000000,115,2,13.75000000,300,3,13.76000000,130,3,13.77000000,315,4,ARL,304252333
1223,2025-07-17T15:46:28.474902154Z,2025-07-17T15:46:28.474736101Z,160,2,1108,A,A,0,15.03000000,100,128,166053,255746178,13.55000000,10,1,13.54000000,100,1,13.38000000,33,1,13.37000000,100,1,13.31000000,10,1,13.30000000,100,1,13.28000000,11,2,13.27000000,110,2,13.26000000,204,4,13.25000000,111,2,13.40000000,208,12,13.67000000,100,1,13.70000000,30,2,13.71000000,101,2,13.72000000,15,1,13.73000000,215,3,13.74000000,115,2,13.75000000,300,3,13.76000000,130,3,13.77000000,315,4,ARL,305184957
1224,2025-07-17T15:46:28.492881980Z,2025-07-17T15:46:28.492716775Z,160,2,1108,C,A,0,14.18000000,100,130,165205,255746619,13.55000000,10,1,13.54000000,100,1,13.38000000,33,1,13.37000000,100,1,13.31000000,10,1,13.30000000,100,1,13.28000000,11,2,13.27000000,110,2,13.26000000,204,4,13.25000000,111,2,13.40000000,208,12,13.67000000,100,1,13.70000000,30,2,13.71000000,101,2,13.72000000,15,1,13.73000000,215,3,13.74000000,115,2,13.75000000,300,3,13.76000000,130,3,13.77000000,315,4,ARL,304252469
1225,2025-07-17T15:46:28.492931279Z,2025-07-17T15:46:28.492765859Z,160,2,1108,A,A,0,14.26000000,100,130,165420,255746621,13.55000000,10,1,13.54000000,100,1,13.38000000,33,1,13.37000000,100,1,13.31000000,10,1,13.30000000,100,1,13.28000000,11,2,13.27000000,110,2,13.26000000,204,4,13.25000000,111,2,13.40000000,208,12,13.67000000,100,1,13.70000000,30,2,13.71000000,101,2,13.72000000,15,1,13.73000000,215,3,13.74000000,115,2,13.75000000,300,3,13.76000000,130,3,13.77000000,315,4,ARL,305185529
1226,2025-07-17T15:46:28.646273467Z,2025-07-17T15:46:28.646108242Z,160,2,1108,A,A,0,14.08000000,100,130,165225,255748568,13.55000000,10,1,13.54000000,100,1,13.38000000,33,1,13.37000000,100,1,13.31000000,10,1,13.30000000,100,1,13.28000000,11,2,13.27000000,110,2,13.26000000,204,4,13.25000000,111,2,13.40000000,208,12,13.67000000,100,1,13.70000000,30,2,13.71000000,101,2,13.72000000,15,1,13.73000000,215,3,13.74000000,115,2,13.75000000,300,3,13.76000000,130,3,13.77000000,315,4,ARL,305187077
1227,2025-07-17T15:46:57.524024658Z,2025-07-17T15:46:57.523859388Z,160,2,1108,A,A,0,13.92000000,15,130,165270,256268482,13.55000000,10,1,13.54000000,100,1,13.38000000,33,1,13.37000000,100,1,13.31000000,10,1,13.30000000,100,1,13.28000000,11,2,13.27000000,110,2,13.26000000,204,4,13.25000000,111,2,13.40000000,208,12,13.67000000,100,1,13.70000000,30,2,13.71000000,101,2,13.72000000,15,1,13.73000000,215,3,13.74000000,115,2,13.75000000,300,3,13.76000000,130,3,13.77000000,315,4,ARL,305862145
1228,2025-07-17T15:46:57.932842994Z,2025-07-17T15:46:57.932677299Z,160,2,1108,C,A,0,14.08000000,100,0,165695,256280751,13.55000000,10,1,13.54000000,100,1,13.38000000,33,1,13.37000000,100,1,13.31000000,10,1,13.30000000,100,1,13.28000000,11,2,13.27000000,110,2,13.26000000,204,4,13.25000000,111,2,13.40000000,208,12,13.67000000,100,1,13.70000000,30,2,13.71000000,101,2,13.72000000,15,1,13.73000000,215,3,13.74000000,115,2,13.75000000,300,3,13.76000000,130,3,13.77000000,315,4,ARL,305187077
1229,2025-07-17T15:46:57.932842994Z,2025-07-17T15:46:57.932677299Z,160,2,1108,A,A,0,13.93000000,100,130,165695,256280751,13.55000000,10,1,13.54000000,100,1,13.38000000,33,1,13.37000000,100,1,13.31000000,10,1,13.30000000,100,1,13.28000000,11,2,13.27000000,110,2,13.26000000,204,4,13.25000000,111,2,13.40000000,208,12,13.67000000,100,1,13.70000000,30,2,13.71000000,101,2,13.72000000,15,1,13.73000000,215,3,13.74000000,115,2,13.75000000,300,3,13.76000000,130,3,13.77000000,315,4,ARL,305878881
1230,2025-07-17T15:47:06.609456251Z,2025-07-17T15:47:06.609290857Z,160,2,1108,A,A,0,13.88000000,15,130,165394,256488374,13.55000000,10,1,13.54000000,100,1,13.38000000,33,1,13.37000000,100,1,13.31000000,10,1,13.30000000,100,1,13.28000000,11,2,13.27000000,110,2,13.26000000,204,4,13.25000000,111,2,13.40000000,208,12,13.67000000,100,1,13.70000000,30,2,13.71000000,101,2,13.72000000,15,1,13.73000000,215,3,13.74000000,115,2,13.75000000,300,3,13.76000000,130,3,13.77000000,315,4,ARL,306121113
1231,2025-07-17T15:47:08.787695144Z,2025-07-17T15:47:08.787529505Z,160,2,1108,C,A,0,13.93000000,100,0,165639,256532991,13.55000000,10,1,13.54000000,100,1,13.38000000,33,1,13.37000000,100,1,13.31000000,10,1,13.30000000,100,1,13.28000000,11,2,13.27000000,110,2,13.26000000,204,4,13.25000000,111,2,13.40000000,208,12,13.67000000,100,1,13.70000000,30,2,13.71000000,101,2,13.72000000,15,1,13.73000000,215,3,13.74000000,115,2,13.75000000,300,3,13.76000000,130,3,13.77000000,315,4,ARL,305878881
1232,2025-07-17T15:47:08.787695144Z,2025-07-17T15:47:08.787529505Z,160,2,1108,A,A,0,13.89000000,100,130,165639,256532991,13.55000000,10,1,13.54000000,100,1,13.38000000,33,1,13.37000000,100,1,13.31000000,10,1,13.30000000,100,1,13.28000000,11,2,13.27000000,110,2,13.26000000,204,4,13.25000000,111,2,13.40000000,208,12,13.67000000,100,1,13.70000000,30,2,13.71000000,101,2,13.72000000,15,1,13.73000000,215,3,13.74000000,115,2,13.75000000,300,3,13.76000000,130,3,13.77000000,315,4,ARL,306170837
1233,2025-07-17T15:47:08.788440762Z,2025-07-17T15:47:08.788275184Z,160,2,1108,C,A,0,15.03000000,100,0,165578,256533005,13.55000000,10,1,13.54000000,100,1,13.38000000,33,1,13.37000000,100,1,13.31000000,10,1,13.30000000,100,1,13.28000000,11,2,13.27000000,110,2,13.26000000,204,4,13.25000000,111,2,13.40000000,208,12,13.67000000,100,1,13.70000000,30,2,13.71000000,101,2,13.72000000,15,1,13.73000000,215,3,13.74000000,115,2,13.75000000,300,3,13.76000000,130,3,13.77000000,315,4,ARL,305184957
1234,2025-07-17T15:47:08.788440762Z,2025-07-17T15:47:08.788275184Z,160,2,1108,A,A,0,14.97000000,100,130,165578,256533005,13.55000000,10,1,13.54000000,100,1,13.38000000,33,1,13.37000000,100,1,13.31000000,10,1,13.30000000,100,1,13.28000000,11,2,13.27000000,110,2,13.26000000,204,4,13.25000000,111,2,13.40000000,208,12,13.67000000,100,1,13.70000000,30,2,13.71000000,101,2,13.72000000,15,1,13.73000000,215,3,13.74000000,115,2,13.75000000,300,3,13.76000000,130,3,13.77000000,315,4,ARL,306170869
1235,2025-07-17T15:47:08.805983406Z,2025-07-17T15:47:08.805818249Z,160,2,1108,C,A,0,14.26000000,100,130,165157,256533442,13.55000000,10,1,13.54000000,100,1,13.38000000,33,1,13.37000000,100,1,13.31000000,10,1,13.30000000,100,1,13.28000000,11,2,13.27000000,110,2,13.26000000,204,4,13.25000000,111,2,13.40000000,208,12,13.67000000,100,1,13.70000000,30,2,13.71000000,101,2,13.72000000,15,1,13.73000000,215,3,13.74000000,115,2,13.75000000,300,3,13.76000000,130,3,13.77000000,315,4,ARL,305185529
1236,2025-07-17T15:47:08.806033773Z,2025-07-17T15:47:08.805868059Z,160,2,1108,A,A,0,14.17000000,100,130,165714,256533443,13.55000000,10,1,13.54000000,100,1,13.38000000,33,1,13.37000000,100,1,13.31000000,10,1,13.30000000,100,1,13.28000000,11,2,13.27000000,110,2,13.26000000,204,4,13.25000000,111,2,13.40000000,208,12,13.67000000,100,1,13.70000000,30,2,13.71000000,101,2,13.72000000,15,1,13.73000000,215,3,13.74000000,115,2,13.75000000,300,3,13.76000000,130,3,13.77000000,315,4,ARL,306171457
1237,2025-07-17T15:47:13.121454355Z,2025-07-17T15:47:13.121288953Z,160,2,1108,C,A,0,13.88000000,15,130,165402,256612694,13.55000000,10,1,13.54000000,100,1,13.38000000,33,1,13.37000000,100,1,13.31000000,10,1,13.30000000,100,1,13.28000000,11,2,13.27000000,110,2,13.26000000,204,4,13.25000000,111,2,13.40000000,208,12,13.67000000,100,1,13.70000000,30,2,13.71000000,101,2,13.72000000,15,1,13.73000000,215,3,13.74000000,115,2,13.75000000,300,3,13.76000000,130,3,13.77000000,315,4,ARL,306121113
1238,2025-07-17T15:47:13.122562533Z,2025-07-17T15:47:13.122396816Z,160,2,1108,C,A,0,13.92000000,15,130,165717,256612757,13.55000000,10,1,13.54000000,100,1,13.38000000,33,1,13.37000000,100,1,13.31000000,10,1,13.30000000,100,1,13.28000000,11,2,13.27000000,110,2,13.26000000,204,4,13.25000000,111,2,13.40000000,208,12,13.67000000,100,1,13.70000000,30,2,13.71000000,101,2,13.72000000,15,1,13.73000000,215,3,13.74000000,115,2,13.75000000,300,3,13.76000000,130,3,13.77000000,315,4,ARL,305862145
1239,2025-07-17T15:47:24.786476266Z,2025-07-17T15:47:24.786310694Z,160,2,1108,A,A,0,13.87000000,15,130,165572,256812416,13.55000000,10,1,13.54000000,100,1,13.38000000,33,1,13.37000000,100,1,13.31000000,10,1,13.30000000,100,1,13.28000000,11,2,13.27000000,110,2,13.26000000,204,4,13.25000000,111,2,13.40000000,208,12,13.67000000,100,1,13.70000000,30,2,13.71000000,101,2,13.72000000,15,1,13.73000000,215,3,13.74000000,115,2,13.75000000,300,3,13.76000000,130,3,13.77000000,315,4,ARL,306519385
1240,2025-07-17T15:47:24.786745657Z,2025-07-17T15:47:24.786580061Z,160,2,1108,C,A,0,13.89000000,100,0,165596,256812420,13.55000000,10,1,13.54000000,100,1,13.38000000,33,1,13.37000000,100,1,13.31000000,10,1,13.30000000,100,1,13.28000000,11,2,13.27000000,110,2,13.26000000,204,4,13.25000000,111,2,13.40000000,208,12,13.67000000,100,1,13.70000000,30,2,13.71000000,101,2,13.72000000,15,1,13.73000000,215,3,13.74000000,115,2,13.75000000,300,3,13.76000000,130,3,13.77000000,315,4,ARL,306170837
1241,2025-07-17T15:47:24.786745657Z,2025-07-17T15:47:24.786580061Z,160,2,1108,A,A,0,13.88000000,100,130,165596,256812420,13.55000000,10,1,13.54000000,100,1,13.38000000,33,1,13.37000000,100,1,13.31000000,10,1,13.30000000,100,1,13.28000000,11,2,13.27000000,110,2,13.26000000,204,4,13.25000000,111,2,13.40000000,208,12,13.67000000,100,1,13.70000000,30,2,13.71000000,101,2,13.72000000,15,1,13.73000000,215,3,13.74000000,115,2,13.75000000,300,3,13.76000000,130,3,13.77000000,315,4,ARL,306519397
1242,2025-07-17T15:47:24.786925729Z,2025-07-17T15:47:24.786759805Z,160,2,1108,C,A,0,14.88000000,100,0,165924,256812422,13.55000000,10,1,13.54000000,100,1,13.38000000,33,1,13.37000000,100,1,13.31000000,10,1,13.30000000,100,1,13.28000000,11,2,13.27000000,110,2,13.26000000,204,4,13.25000000,111,2,13.40000000,208,12,13.67000000,100,1,13.70000000,30,2,13.71000000,101,2,13.72000000,15,1,13.73000000,215,3,13.74000000,115,2,13.75000000,300,3,13.76000000,130,3,13.77000000,315,4,ARL,305184937
1243,2025-07-17T15:47:24.786925729Z,2025-07-17T15:47:24.786759805Z,160,2,1108,A,A,0,14.77000000,100,130,165924,256812422,13.55000000,10,1,13.54000000,100,1,13.38000000,33,1,13.37000000,100,1,13.31000000,10,1,13.30000000,100,1,13.28000000,11,2,13.27000000,110,2,13.26000000,204,4,13.25000000,111,2,13.40000000,208,12,13.67000000,100,1,13.70000000,30,2,13.71000000,101,2,13.72000000,15,1,13.73000000,215,3,13.74000000,115,2,13.75000000,300,3,13.76000000,130,3,13.77000000,315,4,ARL,306519409
