,ts_recv,ts_event,rtype,publisher_id,instrument_id,action,side,depth,price,size,flags,ts_in_delta,sequence,bid_px_00,bid_sz_00,bid_ct_00,ask_px_00,ask_sz_00,ask_ct_00,bid_px_01,bid_sz_01,bid_ct_01,ask_px_01,ask_sz_01,ask_ct_01,bid_px_02,bid_sz_02,bid_ct_02,ask_px_02,ask_sz_02,ask_ct_02,bid_px_03,bid_sz_03,bid_ct_03,ask_px_03,ask_sz_03,ask_ct_03,bid_px_04,bid_sz_04,bid_ct_04,ask_px_04,ask_sz_04,ask_ct_04,bid_px_05,bid_sz_05,bid_ct_05,ask_px_05,ask_sz_05,ask_ct_05,bid_px_06,bid_sz_06,bid_ct_06,ask_px_06,ask_sz_06,ask_ct_06,bid_px_07,bid_sz_07,bid_ct_07,ask_px_07,ask_sz_07,ask_ct_07,bid_px_08,bid_sz_08,bid_ct_08,ask_px_08,ask_sz_08,ask_ct_08,bid_px_09,bid_sz_09,bid_ct_09,ask_px_09,ask_sz_09,ask_ct_09,symbol,order_id
1244,2025-07-17T15:47:24.800616004Z,2025-07-17T15:47:24.800449950Z,160,2,1108,C,A,0,14.88000000,100,0,166054,256812578,13.55000000,10,1,13.54000000,100,1,13.38000000,33,1,13.37000000,100,1,13.31000000,10,1,13.30000000,100,1,13.28000000,11,2,13.27000000,110,2,13.26000000,204,4,13.25000000,111,2,13.40000000,208,12,13.67000000,100,1,13.70000000,30,2,13.71000000,101,2,13.72000000,15,1,13.73000000,215,3,13.74000000,115,2,13.75000000,300,3,13.76000000,130,3,13.77000000,315,4,ARL,305184953
1245,2025-07-17T15:47:24.800616004Z,2025-07-17T15:47:24.800449950Z,160,2,1108,A,A,0,14.75000000,100,130,166054,256812578,13.55000000,10,1,13.54000000,100,1,13.38000000,33,1,13.37000000,100,1,13.31000000,10,1,13.30000000,100,1,13.28000000,11,2,13.27000000,110,2,13.26000000,204,4,13.25000000,111,2,13.40000000,208,12,13.67000000,100,1,13.70000000,30,2,13.71000000,101,2,13.72000000,15,1,13.73000000,215,3,13.74000000,115,2,13.75000000,300,3,13.76000000,130,3,13.77000000,315,4,ARL,306519741
1246,2025-07-17T15:47:27.860272892Z,2025-07-17T15:47:27.860107552Z,160,2,1108,A,A,0,13.83000000,15,130,165340,256866835,13.55000000,10,1,13.54000000,100,1,13.38000000,33,1,13.37000000,100,1,13.31000000,10,1,13.30000000,100,1,13.28000000,11,2,13.27000000,110,2,13.26000000,204,4,13.25000000,111,2,13.40000000,208,12,13.67000000,100,1,13.70000000,30,2,13.71000000,101,2,13.72000000,15,1,13.73000000,215,3,13.74000000,115,2,13.75000000,300,3,13.76000000,130,3,13.77000000,315,4,ARL,306587393
1247,2025-07-17T15:47:31.407029312Z,2025-07-17T15:47:31.406863918Z,160,2,1108,C,A,0,13.88000000,100,0,165394,256910124,13.55000000,10,1,13.54000000,100,1,13.38000000,33,1,13.37000000,100,1,13.31000000,10,1,13.30000000,100,1,13.28000000,11,2,13.27000000,110,2,13.26000000,204,4,13.25000000,111,2,13.40000000,208,12,13.67000000,100,1,13.70000000,30,2,13.71000000,101,2,13.72000000,15,1,13.73000000,215,3,13.74000000,115,2,13.75000000,300,3,13.76000000,130,3,13.77000000,315,4,ARL,306519397
1248,2025-07-17T15:47:31.407029312Z,2025-07-17T15:47:31.406863918Z,160,2,1108,A,A,0,13.84000000,100,130,165394,256910124,13.55000000,10,1,13.54000000,100,1,13.38000000,33,1,13.37000000,100,1,13.31000000,10,1,13.30000000,100,1,13.28000000,11,2,13.27000000,110,2,13.26000000,204,4,13.25000000,111,2,13.40000000,208,12,13.67000000,100,1,13.70000000,30,2,13.71000000,101,2,13.72000000,15,1,13.73000000,215,3,13.74000000,115,2,13.75000000,300,3,13.76000000,130,3,13.77000000,315,4,ARL,306647425
1249,2025-07-17T15:47:31.407771110Z,2025-07-17T15:47:31.407605685Z,160,2,1108,C,A,0,14.97000000,100,0,165425,256910129,13.55000000,10,1,13.54000000,100,1,13.38000000,33,1,13.37000000,100,1,13.31000000,10,1,13.30000000,100,1,13.28000000,11,2,13.27000000,110,2,13.26000000,204,4,13.25000000,111,2,13.40000000,208,12,13.67000000,100,1,13.70000000,30,2,13.71000000,101,2,13.72000000,15,1,13.73000000,215,3,13.74000000,115,2,13.75000000,300,3,13.76000000,130,3,13.77000000,315,4,ARL,306170869
1250,2025-07-17T15:47:31.407771110Z,2025-07-17T15:47:31.407605685Z,160,2,1108,A,A,0,14.91000000,100,130,165425,256910129,13.55000000,10,1,13.54000000,100,1,13.38000000,33,1,13.37000000,100,1,13.31000000,10,1,13.30000000,100,1,13.28000000,11,2,13.27000000,110,2,13.26000000,204,4,13.25000000,111,2,13.40000000,208,12,13.67000000,100,1,13.70000000,30,2,13.71000000,101,2,13.72000000,15,1,13.73000000,215,3,13.74000000,115,2,13.75000000,300,3,13.76000000,130,3,13.77000000,315,4,ARL,306647445
1251,2025-07-17T15:47:31.413491477Z,2025-07-17T15:47:31.413325908Z,160,2,1108,C,A,0,14.78000000,100,0,165569,256910184,13.55000000,10,1,13.54000000,100,1,13.38000000,33,1,13.37000000,100,1,13.31000000,10,1,13.30000000,100,1,13.28000000,11,2,13.27000000,110,2,13.26000000,204,4,13.25000000,111,2,13.40000000,208,12,13.67000000,100,1,13.70000000,30,2,13.71000000,101,2,13.72000000,15,1,13.73000000,215,3,13.74000000,115,2,13.75000000,300,3,13.76000000,130,3,13.77000000,315,4,ARL,303331425
1252,2025-07-17T15:47:31.413491477Z,2025-07-17T15:47:31.413325908Z,160,2,1108,A,A,0,14.64000000,100,130,165569,256910184,13.55000000,10,1,13.54000000,100,1,13.38000000,33,1,13.37000000,100,1,13.31000000,10,1,13.30000000,100,1,13.28000000,11,2,13.27000000,110,2,13.26000000,204,4,13.25000000,111,2,13.40000000,208,12,13.67000000,100,1,13.70000000,30,2,13.71000000,101,2,13.72000000,15,1,13.73000000,215,3,13.74000000,115,2,13.75000000,300,3,13.76000000,130,3,13.77000000,315,4,ARL,306647521
1253,2025-07-17T15:47:31.433486283Z,2025-07-17T15:47:31.433320466Z,160,2,1108,C,A,0,14.96000000,100,0,165817,256910721,13.55000000,10,1,13.54000000,100,1,13.38000000,33,1,13.37000000,100,1,13.31000000,10,1,13.30000000,100,1,13.28000000,11,2,13.27000000,110,2,13.26000000,204,4,13.25000000,111,2,13.40000000,208,12,13.67000000,100,1,13.70000000,30,2,13.71000000,101,2,13.72000000,15,1,13.73000000,215,3,13.74000000,115,2,13.75000000,300,3,13.76000000,130,3,13.77000000,315,4,ARL,303330509
1254,2025-07-17T15:47:31.433486283Z,2025-07-17T15:47:31.433320466Z,160,2,1108,A,A,0,14.81000000,100,130,165817,256910721,13.55000000,10,1,13.54000000,100,1,13.38000000,33,1,13.37000000,100,1,13.31000000,10,1,13.30000000,100,1,13.28000000,11,2,13.27000000,110,2,13.26000000,204,4,13.25000000,111,2,13.40000000,208,12,13.67000000,100,1,13.70000000,30,2,13.71000000,101,2,13.72000000,15,1,13.73000000,215,3,13.74000000,115,2,13.75000000,300,3,13.76000000,130,3,13.77000000,315,4,ARL,306649913
1255,2025-07-17T15:47:31.574128504Z,2025-07-17T15:47:31.573963059Z,160,2,1108,C,A,0,16.08000000,100,0,165445,256912087,13.55000000,10,1,13.54000000,100,1,13.38000000,33,1,13.37000000,100,1,13.31000000,10,1,13.30000000,100,1,13.28000000,11,2,13.27000000,110,2,13.26000000,204,4,13.25000000,111,2,13.40000000,208,12,13.67000000,100,1,13.70000000,30,2,13.71000000,101,2,13.72000000,15,1,13.73000000,215,3,13.74000000,115,2,13.75000000,300,3,13.76000000,130,3,13.77000000,315,4,ARL,303331429
1256,2025-07-17T15:47:31.574128504Z,2025-07-17T15:47:31.573963059Z,160,2,1108,A,A,0,15.92000000,100,130,165445,256912087,13.55000000,10,1,13.54000000,100,1,13.38000000,33,1,13.37000000,100,1,13.31000000,10,1,13.30000000,100,1,13.28000000,11,2,13.27000000,110,2,13.26000000,204,4,13.25000000,111,2,13.40000000,208,12,13.67000000,100,1,13.70000000,30,2,13.71000000,101,2,13.72000000,15,1,13.73000000,215,3,13.74000000,115,2,13.75000000,300,3,13.76000000,130,3,13.77000000,315,4,ARL,306652001
1257,2025-07-17T15:47:31.575374481Z,2025-07-17T15:47:31.575209032Z,160,2,1108,C,A,0,17.76000000,100,0,165449,256912094,13.55000000,10,1,13.54000000,100,1,13.38000000,33,1,13.37000000,100,1,13.31000000,10,1,13.30000000,100,1,13.28000000,11,2,13.27000000,110,2,13.26000000,204,4,13.25000000,111,2,13.40000000,208,12,13.67000000,100,1,13.70000000,30,2,13.71000000,101,2,13.72000000,15,1,13.73000000,215,3,13.74000000,115,2,13.75000000,300,3,13.76000000,130,3,13.77000000,315,4,ARL,303331309
1258,2025-07-17T15:47:31.575374481Z,2025-07-17T15:47:31.575209032Z,160,2,1108,A,A,0,17.58000000,100,130,165449,256912094,13.55000000,10,1,13.54000000,100,1,13.38000000,33,1,13.37000000,100,1,13.31000000,10,1,13.30000000,100,1,13.28000000,11,2,13.27000000,110,2,13.26000000,204,4,13.25000000,111,2,13.40000000,208,12,13.67000000,100,1,13.70000000,30,2,13.71000000,101,2,13.72000000,15,1,13.73000000,215,3,13.74000000,115,2,13.75000000,300,3,13.76000000,130,3,13.77000000,315,4,ARL,306652017
1259,2025-07-17T15:47:31.740095714Z,2025-07-17T15:47:31.739930142Z,160,2,1108,C,A,0,14.96000000,100,0,165572,256914067,13.55000000,10,1,13.54000000,100,1,13.38000000,33,1,13.37000000,100,1,13.31000000,10,1,13.30000000,100,1,13.28000000,11,2,13.27000000,110,2,13.26000000,204,4,13.25000000,111,2,13.40000000,208,12,13.67000000,100,1,13.70000000,30,2,13.71000000,101,2,13.72000000,15,1,13.73000000,215,3,13.74000000,115,2,13.75000000,300,3,13.76000000,130,3,13.77000000,315,4,ARL,303334253
1260,2025-07-17T15:47:31.740095714Z,2025-07-17T15:47:31.739930142Z,160,2,1108,A,A,0,14.81000000,100,130,165572,256914067,13.55000000,10,1,13.54000000,100,1,13.38000000,33,1,13.37000000,100,1,13.31000000,10,1,13.30000000,100,1,13.28000000,11,2,13.27000000,110,2,13.26000000,204,4,13.25000000,111,2,13.40000000,208,12,13.67000000,100,1,13.70000000,30,2,13.71000000,101,2,13.72000000,15,1,13.73000000,215,3,13.74000000,115,2,13.75000000,300,3,13.76000000,130,3,13.77000000,315,4,ARL,306653713
1261,2025-07-17T15:47:37.159589804Z,2025-07-17T15:47:37.159424166Z,160,2,1108,C,A,0,13.87000000,15,130,165638,256983942,13.55000000,10,1,13.54000000,100,1,13.38000000,33,1,13.37000000,100,1,13.31000000,10,1,13.30000000,100,1,13.28000000,11,2,13.27000000,110,2,13.26000000,204,4,13.25000000,111,2,13.40000000,208,12,13.67000000,100,1,13.70000000,30,2,13.71000000,101,2,13.72000000,15,1,13.73000000,215,3,13.74000000,115,2,13.75000000,300,3,13.76000000,130,3,13.77000000,315,4,ARL,306519385
1262,2025-07-17T15:47:37.172000440Z,2025-07-17T15:47:37.171834941Z,160,2,1108,A,A,0,13.85000000,100,130,165499,256984053,13.55000000,10,1,13.54000000,100,1,13.38000000,33,1,13.37000000,100,1,13.31000000,10,1,13.30000000,100,1,13.28000000,11,2,13.27000000,110,2,13.26000000,204,4,13.25000000,111,2,13.40000000,208,12,13.67000000,100,1,13.70000000,30,2,13.71000000,101,2,13.72000000,15,1,13.73000000,215,3,13.74000000,115,2,13.75000000,300,3,13.76000000,130,3,13.77000000,315,4,ARL,306749753
1263,2025-07-17T15:47:38.161181283Z,2025-07-17T15:47:38.161015969Z,160,2,1108,A,A,0,13.79000000,15,130,165314,256998606,13.55000000,10,1,13.54000000,100,1,13.38000000,33,1,13.37000000,100,1,13.31000000,10,1,13.30000000,100,1,13.28000000,11,2,13.27000000,110,2,13.26000000,204,4,13.25000000,111,2,13.40000000,208,12,13.67000000,100,1,13.70000000,30,2,13.71000000,101,2,13.72000000,15,1,13.73000000,215,3,13.74000000,115,2,13.75000000,300,3,13.76000000,130,3,13.77000000,315,4,ARL,306770041
1264,2025-07-17T15:47:38.794962245Z,2025-07-17T15:47:38.794795887Z,160,2,1108,C,A,0,13.84000000,100,0,166358,257010989,13.55000000,10,1,13.54000000,100,1,13.38000000,33,1,13.37000000,100,1,13.31000000,10,1,13.30000000,100,1,13.28000000,11,2,13.27000000,110,2,13.26000000,204,4,13.25000000,111,2,13.40000000,208,12,13.67000000,100,1,13.70000000,30,2,13.71000000,101,2,13.72000000,15,1,13.73000000,215,3,13.74000000,115,2,13.75000000,300,3,13.76000000,130,3,13.77000000,315,4,ARL,306647425
1265,2025-07-17T15:47:38.794962245Z,2025-07-17T15:47:38.794795887Z,160,2,1108,A,A,0,13.80000000,100,128,166358,257010989,13.55000000,10,1,13.54000000,100,1,13.38000000,33,1,13.37000000,100,1,13.31000000,10,1,13.30000000,100,1,13.28000000,11,2,13.27000000,110,2,13.26000000,204,4,13.25000000,111,2,13.40000000,208,12,13.67000000,100,1,13.70000000,30,2,13.71000000,101,2,13.72000000,15,1,13.73000000,215,3,13.74000000,115,2,13.75000000,300,3,13.76000000,130,3,13.77000000,315,4,ARL,306784133
1266,2025-07-17T15:47:38.795723570Z,2025-07-17T15:47:38.795557785Z,160,2,1108,C,A,0,14.91000000,100,0,165785,257011058,13.55000000,10,1,13.54000000,100,1,13.38000000,33,1,13.37000000,100,1,13.31000000,10,1,13.30000000,100,1,13.28000000,11,2,13.27000000,110,2,13.26000000,204,4,13.25000000,111,2,13.40000000,208,12,13.67000000,100,1,13.70000000,30,2,13.71000000,101,2,13.72000000,15,1,13.73000000,215,3,13.74000000,115,2,13.75000000,300,3,13.76000000,130,3,13.77000000,315,4,ARL,306647445
1267,2025-07-17T15:47:38.795723570Z,2025-07-17T15:47:38.795557785Z,160,2,1108,A,A,0,14.87000000,100,130,165785,257011058,13.55000000,10,1,13.54000000,100,1,13.38000000,33,1,13.37000000,100,1,13.31000000,10,1,13.30000000,100,1,13.28000000,11,2,13.27000000,110,2,13.26000000,204,4,13.25000000,111,2,13.40000000,208,12,13.67000000,100,1,13.70000000,30,2,13.71000000,101,2,13.72000000,15,1,13.73000000,215,3,13.74000000,115,2,13.75000000,300,3,13.76000000,130,3,13.77000000,315,4,ARL,306784201
1268,2025-07-17T15:47:38.804624258Z,2025-07-17T15:47:38.804458744Z,160,2,1108,C,A,0,14.17000000,100,130,165514,257011716,13.55000000,10,1,13.54000000,100,1,13.38000000,33,1,13.37000000,100,1,13.31000000,10,1,13.30000000,100,1,13.28000000,11,2,13.27000000,110,2,13.26000000,204,4,13.25000000,111,2,13.40000000,208,12,13.67000000,100,1,13.70000000,30,2,13.71000000,101,2,13.72000000,15,1,13.73000000,215,3,13.74000000,115,2,13.75000000,300,3,13.76000000,130,3,13.77000000,315,4,ARL,306171457
1269,2025-07-17T15:47:38.804679592Z,2025-07-17T15:47:38.804513793Z,160,2,1108,A,A,0,14.08000000,100,130,165799,257011717,13.55000000,10,1,13.54000000,100,1,13.38000000,33,1,13.37000000,100,1,13.31000000,10,1,13.30000000,100,1,13.28000000,11,2,13.27000000,110,2,13.26000000,204,4,13.25000000,111,2,13.40000000,208,12,13.67000000,100,1,13.70000000,30,2,13.71000000,101,2,13.72000000,15,1,13.73000000,215,3,13.74000000,115,2,13.75000000,300,3,13.76000000,130,3,13.77000000,315,4,ARL,306784853
1270,2025-07-17T15:47:39.092472059Z,2025-07-17T15:47:39.092305947Z,160,2,1108,C,A,0,13.79000000,15,130,166112,257018687,13.55000000,10,1,13.54000000,100,1,13.38000000,33,1,13.37000000,100,1,13.31000000,10,1,13.30000000,100,1,13.28000000,11,2,13.27000000,110,2,13.26000000,204,4,13.25000000,111,2,13.40000000,208,12,13.67000000,100,1,13.70000000,30,2,13.71000000,101,2,13.72000000,15,1,13.73000000,215,3,13.74000000,115,2,13.75000000,300,3,13.76000000,130,3,13.77000000,315,4,ARL,306770041
1271,2025-07-17T15:47:39.095920859Z,2025-07-17T15:47:39.095755335Z,160,2,1108,C,A,0,13.83000000,15,130,165524,257018796,13.55000000,10,1,13.54000000,100,1,13.38000000,33,1,13.37000000,100,1,13.31000000,10,1,13.30000000,100,1,13.28000000,11,2,13.27000000,110,2,13.26000000,204,4,13.25000000,111,2,13.40000000,208,12,13.67000000,100,1,13.70000000,30,2,13.71000000,101,2,13.72000000,15,1,13.73000000,215,3,13.74000000,115,2,13.75000000,300,3,13.76000000,130,3,13.77000000,315,4,ARL,306587393
1272,2025-07-17T15:48:08.909366905Z,2025-07-17T15:48:08.909201576Z,160,2,1108,A,A,0,13.83000000,100,130,165329,257603755,13.55000000,10,1,13.54000000,100,1,13.38000000,33,1,13.37000000,100,1,13.31000000,10,1,13.30000000,100,1,13.28000000,11,2,13.27000000,110,2,13.26000000,204,4,13.25000000,111,2,13.40000000,208,12,13.67000000,100,1,13.70000000,30,2,13.71000000,101,2,13.72000000,15,1,13.73000000,215,3,13.74000000,115,2,13.75000000,300,3,13.76000000,130,3,13.77000000,315,4,ARL,307567929
1273,2025-07-17T15:48:08.916721098Z,2025-07-17T15:48:08.916555821Z,160,2,1108,C,A,0,13.85000000,100,130,165277,257604057,13.55000000,10,1,13.54000000,100,1,13.38000000,33,1,13.37000000,100,1,13.31000000,10,1,13.30000000,100,1,13.28000000,11,2,13.27000000,110,2,13.26000000,204,4,13.25000000,111,2,13.40000000,208,12,13.67000000,100,1,13.70000000,30,2,13.71000000,101,2,13.72000000,15,1,13.73000000,215,3,13.74000000,115,2,13.75000000,300,3,13.76000000,130,3,13.77000000,315,4,ARL,306749753
1274,2025-07-17T15:48:09.653473465Z,2025-07-17T15:48:09.653308042Z,160,2,1108,A,A,0,13.78000000,15,130,165423,257621095,13.55000000,10,1,13.54000000,100,1,13.38000000,33,1,13.37000000,100,1,13.31000000,10,1,13.30000000,100,1,13.28000000,11,2,13.27000000,110,2,13.26000000,204,4,13.25000000,111,2,13.40000000,208,12,13.67000000,100,1,13.70000000,30,2,13.71000000,101,2,13.72000000,15,1,13.73000000,215,3,13.74000000,115,2,13.75000000,300,3,13.76000000,130,3,13.77000000,315,4,ARL,307587873
1275,2025-07-17T15:48:11.166689254Z,2025-07-17T15:48:11.166517494Z,160,2,1108,C,A,0,13.78000000,15,128,171760,257644020,13.55000000,10,1,13.54000000,100,1,13.38000000,33,1,13.37000000,100,1,13.31000000,10,1,13.30000000,100,1,13.28000000,11,2,13.27000000,110,2,13.26000000,204,4,13.25000000,111,2,13.40000000,208,12,13.67000000,100,1,13.70000000,30,2,13.71000000,101,2,13.72000000,15,1,13.73000000,215,3,13.74000000,115,2,13.75000000,300,3,13.76000000,130,3,13.77000000,315,4,ARL,307587873
1276,2025-07-17T15:48:13.509078553Z,2025-07-17T15:48:13.508913083Z,160,2,1108,A,A,0,13.78000000,15,130,165470,257727039,13.55000000,10,1,13.54000000,100,1,13.38000000,33,1,13.37000000,100,1,13.31000000,10,1,13.30000000,100,1,13.28000000,11,2,13.27000000,110,2,13.26000000,204,4,13.25000000,111,2,13.40000000,208,12,13.67000000,100,1,13.70000000,30,2,13.71000000,101,2,13.72000000,15,1,13.73000000,215,3,13.74000000,115,2,13.75000000,300,3,13.76000000,130,3,13.77000000,315,4,ARL,307714769
1277,2025-07-17T15:48:13.525953545Z,2025-07-17T15:48:13.525788139Z,160,2,1108,A,A,0,13.81000000,100,130,165406,257727301,13.55000000,10,1,13.54000000,100,1,13.38000000,33,1,13.37000000,100,1,13.31000000,10,1,13.30000000,100,1,13.28000000,11,2,13.27000000,110,2,13.26000000,204,4,13.25000000,111,2,13.40000000,208,12,13.67000000,100,1,13.70000000,30,2,13.71000000,101,2,13.72000000,15,1,13.73000000,215,3,13.74000000,115,2,13.75000000,300,3,13.76000000,130,3,13.77000000,315,4,ARL,307715101
1278,2025-07-17T15:48:13.532608874Z,2025-07-17T15:48:13.532443045Z,160,2,1108,C,A,0,13.83000000,100,130,165829,257727457,13.55000000,10,1,13.54000000,100,1,13.38000000,33,1,13.37000000,100,1,13.31000000,10,1,13.30000000,100,1,13.28000000,11,2,13.27000000,110,2,13.26000000,204,4,13.25000000,111,2,13.40000000,208,12,13.67000000,100,1,13.70000000,30,2,13.71000000,101,2,13.72000000,15,1,13.73000000,215,3,13.74000000,115,2,13.75000000,300,3,13.76000000,130,3,13.77000000,315,4,ARL,307567929
1279,2025-07-17T15:48:15.568544154Z,2025-07-17T15:48:15.568378275Z,160,2,1108,C,A,0,13.80000000,100,0,165879,257757458,13.55000000,10,1,13.54000000,100,1,13.38000000,33,1,13.37000000,100,1,13.31000000,10,1,13.30000000,100,1,13.28000000,11,2,13.27000000,110,2,13.26000000,204,4,13.25000000,111,2,13.40000000,208,12,13.67000000,100,1,13.70000000,30,2,13.71000000,101,2,13.72000000,15,1,13.73000000,215,3,13.74000000,115,2,13.75000000,300,3,13.76000000,130,3,13.77000000,315,4,ARL,306784133
1280,2025-07-17T15:48:15.568544154Z,2025-07-17T15:48:15.568378275Z,160,2,1108,A,A,0,13.79000000,100,130,165879,257757458,13.55000000,10,1,13.54000000,100,1,13.38000000,33,1,13.37000000,100,1,13.31000000,10,1,13.30000000,100,1,13.28000000,11,2,13.27000000,110,2,13.26000000,204,4,13.25000000,111,2,13.40000000,208,12,13.67000000,100,1,13.70000000,30,2,13.71000000,101,2,13.72000000,15,1,13.73000000,215,3,13.74000000,115,2,13.75000000,300,3,13.76000000,130,3,13.77000000,315,4,ARL,307753241
1281,2025-07-17T15:48:24.009355346Z,2025-07-17T15:48:24.009190157Z,160,2,1108,A,A,0,13.75000000,15,130,165189,257928318,13.55000000,10,1,13.54000000,100,1,13.38000000,33,1,13.37000000,100,1,13.31000000,10,1,13.30000000,100,1,13.28000000,11,2,13.27000000,110,2,13.26000000,204,4,13.25000000,111,2,13.40000000,208,12,13.67000000,100,1,13.70000000,30,2,13.71000000,101,2,13.72000000,15,1,13.73000000,215,3,13.74000000,115,2,13.75000000,315,4,13.76000000,130,3,13.77000000,315,4,ARL,307964605
1282,2025-07-17T15:48:24.009522633Z,2025-07-17T15:48:24.009357442Z,160,2,1108,A,A,0,13.79000000,100,130,165191,257928319,13.55000000,10,1,13.54000000,100,1,13.38000000,33,1,13.37000000,100,1,13.31000000,10,1,13.30000000,100,1,13.28000000,11,2,13.27000000,110,2,13.26000000,204,4,13.25000000,111,2,13.40000000,208,12,13.67000000,100,1,13.70000000,30,2,13.71000000,101,2,13.72000000,15,1,13.73000000,215,3,13.74000000,115,2,13.75000000,315,4,13.76000000,130,3,13.77000000,315,4,ARL,307964609
1283,2025-07-17T15:48:24.009944381Z,2025-07-17T15:48:24.009778967Z,160,2,1108,C,A,0,13.79000000,100,0,165414,257928325,13.55000000,10,1,13.54000000,100,1,13.38000000,33,1,13.37000000,100,1,13.31000000,10,1,13.30000000,100,1,13.28000000,11,2,13.27000000,110,2,13.26000000,204,4,13.25000000,111,2,13.40000000,208,12,13.67000000,100,1,13.70000000,30,2,13.71000000,101,2,13.72000000,15,1,13.73000000,215,3,13.74000000,115,2,13.75000000,315,4,13.76000000,130,3,13.77000000,315,4,ARL,307753241
1284,2025-07-17T15:48:24.009944381Z,2025-07-17T15:48:24.009778967Z,160,2,1108,A,A,0,13.76000000,100,130,165414,257928325,13.55000000,10,1,13.54000000,100,1,13.38000000,33,1,13.37000000,100,1,13.31000000,10,1,13.30000000,100,1,13.28000000,11,2,13.27000000,110,2,13.26000000,204,4,13.25000000,111,2,13.40000000,208,12,13.67000000,100,1,13.70000000,30,2,13.71000000,101,2,13.72000000,15,1,13.73000000,215,3,13.74000000,115,2,13.75000000,315,4,13.76000000,230,4,13.77000000,315,4,ARL,307964621
1285,2025-07-17T15:48:24.009974166Z,2025-07-17T15:48:24.009808793Z,160,2,1108,C,A,0,13.81000000,100,130,165373,257928326,13.55000000,10,1,13.54000000,100,1,13.38000000,33,1,13.37000000,100,1,13.31000000,10,1,13.30000000,100,1,13.28000000,11,2,13.27000000,110,2,13.26000000,204,4,13.25000000,111,2,13.40000000,208,12,13.67000000,100,1,13.70000000,30,2,13.71000000,101,2,13.72000000,15,1,13.73000000,215,3,13.74000000,115,2,13.75000000,315,4,13.76000000,230,4,13.77000000,315,4,ARL,307715101
1286,2025-07-17T15:48:24.010555416Z,2025-07-17T15:48:24.010390029Z,160,2,1108,C,A,0,14.77000000,100,0,165387,257928333,13.55000000,10,1,13.54000000,100,1,13.38000000,33,1,13.37000000,100,1,13.31000000,10,1,13.30000000,100,1,13.28000000,11,2,13.27000000,110,2,13.26000000,204,4,13.25000000,111,2,13.40000000,208,12,13.67000000,100,1,13.70000000,30,2,13.71000000,101,2,13.72000000,15,1,13.73000000,215,3,13.74000000,115,2,13.75000000,315,4,13.76000000,230,4,13.77000000,315,4,ARL,306519409
1287,2025-07-17T15:48:24.010555416Z,2025-07-17T15:48:24.010390029Z,160,2,1108,A,A,0,14.65000000,100,130,165387,257928333,13.55000000,10,1,13.54000000,100,1,13.38000000,33,1,13.37000000,100,1,13.31000000,10,1,13.30000000,100,1,13.28000000,11,2,13.27000000,110,2,13.26000000,204,4,13.25000000,111,2,13.40000000,208,12,13.67000000,100,1,13.70000000,30,2,13.71000000,101,2,13.72000000,15,1,13.73000000,215,3,13.74000000,115,2,13.75000000,315,4,13.76000000,230,4,13.77000000,315,4,ARL,307964661
1288,2025-07-17T15:48:24.010677522Z,2025-07-17T15:48:24.010512050Z,160,2,1108,C,A,0,14.87000000,100,0,165472,257928340,13.55000000,10,1,13.54000000,100,1,13.38000000,33,1,13.37000000,100,1,13.31000000,10,1,13.30000000,100,1,13.28000000,11,2,13.27000000,110,2,13.26000000,204,4,13.25000000,111,2,13.40000000,208,12,13.67000000,100,1,13.70000000,30,2,13.71000000,101,2,13.72000000,15,1,13.73000000,215,3,13.74000000,115,2,13.75000000,315,4,13.76000000,230,4,13.77000000,315,4,ARL,306784201
1289,2025-07-17T15:48:24.010677522Z,2025-07-17T15:48:24.010512050Z,160,2,1108,A,A,0,14.83000000,100,130,165472,257928340,13.55000000,10,1,13.54000000,100,1,13.38000000,33,1,13.37000000,100,1,13.31000000,10,1,13.30000000,100,1,13.28000000,11,2,13.27000000,110,2,13.26000000,204,4,13.25000000,111,2,13.40000000,208,12,13.67000000,100,1,13.70000000,30,2,13.71000000,101,2,13.72000000,15,1,13.73000000,215,3,13.74000000,115,2,13.75000000,315,4,13.76000000,230,4,13.77000000,315,4,ARL,307964665
1290,2025-07-17T15:48:42.009954046Z,2025-07-17T15:48:42.009788565Z,160,2,1108,C,A,0,13.78000000,15,130,165481,258199397,13.55000000,10,1,13.54000000,100,1,13.38000000,33,1,13.37000000,100,1,13.31000000,10,1,13.30000000,100,1,13.28000000,11,2,13.27000000,110,2,13.26000000,204,4,13.25000000,111,2,13.40000000,208,12,13.67000000,100,1,13.70000000,30,2,13.71000000,101,2,13.72000000,15,1,13.73000000,215,3,13.74000000,115,2,13.75000000,315,4,13.76000000,230,4,13.77000000,315,4,ARL,307714769
1291,2025-07-17T15:48:42.011846392Z,2025-07-17T15:48:42.011680742Z,160,2,1108,C,A,0,14.75000000,100,0,165650,258199535,13.55000000,10,1,13.54000000,100,1,13.38000000,33,1,13.37000000,100,1,13.31000000,10,1,13.30000000,100,1,13.28000000,11,2,13.27000000,110,2,13.26000000,204,4,13.25000000,111,2,13.40000000,208,12,13.67000000,100,1,13.70000000,30,2,13.71000000,101,2,13.72000000,15,1,13.73000000,215,3,13.74000000,115,2,13.75000000,315,4,13.76000000,230,4,13.77000000,315,4,ARL,306519741
1292,2025-07-17T15:48:42.011846392Z,2025-07-17T15:48:42.011680742Z,160,2,1108,A,A,0,14.64000000,100,130,165650,258199535,13.55000000,10,1,13.54000000,100,1,13.38000000,33,1,13.37000000,100,1,13.31000000,10,1,13.30000000,100,1,13.28000000,11,2,13.27000000,110,2,13.26000000,204,4,13.25000000,111,2,13.40000000,208,12,13.67000000,100,1,13.70000000,30,2,13.71000000,101,2,13.72000000,15,1,13.73000000,215,3,13.74000000,115,2,13.75000000,315,4,13.76000000,230,4,13.77000000,315,4,ARL,308296381
1293,2025-07-17T15:48:42.016761374Z,2025-07-17T15:48:42.016595806Z,160,2,1108,A,A,0,13.77000000,100,130,165568,258199787,13.55000000,10,1,13.54000000,100,1,13.38000000,33,1,13.37000000,100,1,13.31000000,10,1,13.30000000,100,1,13.28000000,11,2,13.27000000,110,2,13.26000000,204,4,13.25000000,111,2,13.40000000,208,12,13.67000000,100,1,13.70000000,30,2,13.71000000,101,2,13.72000000,15,1,13.73000000,215,3,13.74000000,115,2,13.75000000,315,4,13.76000000,230,4,13.77000000,415,5,ARL,308296741
1294,2025-07-17T15:48:42.023432407Z,2025-07-17T15:48:42.023266760Z,160,2,1108,C,A,0,13.79000000,100,130,165647,258199990,13.55000000,10,1,13.54000000,100,1,13.38000000,33,1,13.37000000,100,1,13.31000000,10,1,13.30000000,100,1,13.28000000,11,2,13.27000000,110,2,13.26000000,204,4,13.25000000,111,2,13.40000000,208,12,13.67000000,100,1,13.70000000,30,2,13.71000000,101,2,13.72000000,15,1,13.73000000,215,3,13.74000000,115,2,13.75000000,315,4,13.76000000,230,4,13.77000000,415,5,ARL,307964609
1295,2025-07-17T15:48:46.750088490Z,2025-07-17T15:48:46.749922127Z,160,2,1108,A,A,0,13.73000000,15,128,166363,258260871,13.55000000,10,1,13.54000000,100,1,13.38000000,33,1,13.37000000,100,1,13.31000000,10,1,13.30000000,100,1,13.28000000,11,2,13.27000000,110,2,13.26000000,204,4,13.25000000,111,2,13.40000000,208,12,13.67000000,100,1,13.70000000,30,2,13.71000000,101,2,13.72000000,15,1,13.73000000,230,4,13.74000000,115,2,13.75000000,315,4,13.76000000,230,4,13.77000000,415,5,ARL,308374537
1296,2025-07-17T15:48:46.758551033Z,2025-07-17T15:48:46.758385367Z,160,2,1108,C,A,0,13.76000000,100,0,165666,258261154,13.55000000,10,1,13.54000000,100,1,13.38000000,33,1,13.37000000,100,1,13.31000000,10,1,13.30000000,100,1,13.28000000,11,2,13.27000000,110,2,13.26000000,204,4,13.25000000,111,2,13.40000000,208,12,13.67000000,100,1,13.70000000,30,2,13.71000000,101,2,13.72000000,15,1,13.73000000,230,4,13.74000000,115,2,13.75000000,315,4,13.76000000,230,4,13.77000000,415,5,ARL,307964621
1297,2025-07-17T15:48:46.758551033Z,2025-07-17T15:48:46.758385367Z,160,2,1108,A,A,0,13.74000000,100,130,165666,258261154,13.55000000,10,1,13.54000000,100,1,13.38000000,33,1,13.37000000,100,1,13.31000000,10,1,13.30000000,100,1,13.28000000,11,2,13.27000000,110,2,13.26000000,204,4,13.25000000,111,2,13.40000000,208,12,13.67000000,100,1,13.70000000,30,2,13.71000000,101,2,13.72000000,15,1,13.73000000,230,4,13.74000000,215,3,13.75000000,315,4,13.76000000,230,4,13.77000000,415,5,ARL,308374881
1298,2025-07-17T15:48:46.773668988Z,2025-07-17T15:48:46.773503306Z,160,2,1108,C,A,0,14.08000000,100,130,165682,258261538,13.55000000,10,1,13.54000000,100,1,13.38000000,33,1,13.37000000,100,1,13.31000000,10,1,13.30000000,100,1,13.28000000,11,2,13.27000000,110,2,13.26000000,204,4,13.25000000,111,2,13.40000000,208,12,13.67000000,100,1,13.70000000,30,2,13.71000000,101,2,13.72000000,15,1,13.73000000,230,4,13.74000000,215,3,13.75000000,315,4,13.76000000,230,4,13.77000000,415,5,ARL,306784853
1299,2025-07-17T15:48:46.773720726Z,2025-07-17T15:48:46.773555566Z,160,2,1108,A,A,0,14.01000000,100,130,165160,258261539,13.55000000,10,1,13.54000000,100,1,13.38000000,33,1,13.37000000,100,1,13.31000000,10,1,13.30000000,100,1,13.28000000,11,2,13.27000000,110,2,13.26000000,204,4,13.25000000,111,2,13.40000000,208,12,13.67000000,100,1,13.70000000,30,2,13.71000000,101,2,13.72000000,15,1,13.73000000,230,4,13.74000000,215,3,13.75000000,315,4,13.76000000,230,4,13.77000000,415,5,ARL,308375185
1300,2025-07-17T15:49:02.010494480Z,2025-07-17T15:49:02.010329052Z,160,2,1108,A,A,0,13.75000000,100,130,165428,258502869,13.55000000,10,1,13.54000000,100,1,13.38000000,33,1,13.37000000,100,1,13.31000000,10,1,13.30000000,100,1,13.28000000,11,2,13.27000000,110,2,13.26000000,204,4,13.25000000,111,2,13.40000000,208,12,13.67000000,100,1,13.70000000,30,2,13.71000000,101,2,13.72000000,15,1,13.73000000,230,4,13.74000000,215,3,13.75000000,415,5,13.76000000,230,4,13.77000000,415,5,ARL,308705489
1301,2025-07-17T15:49:02.019989567Z,2025-07-17T15:49:02.019824230Z,160,2,1108,C,A,0,13.77000000,100,130,165337,258502929,13.55000000,10,1,13.54000000,100,1,13.38000000,33,1,13.37000000,100,1,13.31000000,10,1,13.30000000,100,1,13.28000000,11,2,13.27000000,110,2,13.26000000,204,4,13.25000000,111,2,13.40000000,208,12,13.67000000,100,1,13.70000000,30,2,13.71000000,101,2,13.72000000,15,1,13.73000000,230,4,13.74000000,215,3,13.75000000,415,5,13.76000000,230,4,13.77000000,415,5,ARL,308296741
1302,2025-07-17T15:49:03.406005590Z,2025-07-17T15:49:03.405840358Z,160,2,1108,C,A,0,13.75000000,15,130,165232,258527308,13.55000000,10,1,13.54000000,100,1,13.38000000,33,1,13.37000000,100,1,13.31000000,10,1,13.30000000,100,1,13.28000000,11,2,13.27000000,110,2,13.26000000,204,4,13.25000000,111,2,13.40000000,208,12,13.67000000,100,1,13.70000000,30,2,13.71000000,101,2,13.72000000,15,1,13.73000000,230,4,13.74000000,215,3,13.75000000,415,5,13.76000000,230,4,13.77000000,415,5,ARL,307964605
1303,2025-07-17T15:49:04.713997925Z,2025-07-17T15:49:04.713831675Z,160,2,1108,A,A,0,13.71000000,15,128,166250,258547335,13.55000000,10,1,13.54000000,100,1,13.38000000,33,1,13.37000000,100,1,13.31000000,10,1,13.30000000,100,1,13.28000000,11,2,13.27000000,110,2,13.26000000,204,4,13.25000000,111,2,13.40000000,208,12,13.67000000,100,1,13.70000000,30,2,13.71000000,116,3,13.72000000,15,1,13.73000000,230,4,13.74000000,215,3,13.75000000,415,5,13.76000000,230,4,13.77000000,415,5,ARL,308763065
1304,2025-07-17T15:49:06.013111941Z,2025-07-17T15:49:06.012946379Z,160,2,1108,A,A,0,13.73000000,100,130,165562,258567259,13.55000000,10,1,13.54000000,100,1,13.38000000,33,1,13.37000000,100,1,13.31000000,10,1,13.30000000,100,1,13.28000000,11,2,13.27000000,110,2,13.26000000,204,4,13.25000000,111,2,13.40000000,208,12,13.67000000,100,1,13.70000000,30,2,13.71000000,116,3,13.72000000,15,1,13.73000000,330,5,13.74000000,215,3,13.75000000,415,5,13.76000000,230,4,13.77000000,415,5,ARL,308786185
1305,2025-07-17T15:49:06.023292147Z,2025-07-17T15:49:06.023126600Z,160,2,1108,C,A,0,13.75000000,100,130,165547,258567405,13.55000000,10,1,13.54000000,100,1,13.38000000,33,1,13.37000000,100,1,13.31000000,10,1,13.30000000,100,1,13.28000000,11,2,13.27000000,110,2,13.26000000,204,4,13.25000000,111,2,13.40000000,208,12,13.67000000,100,1,13.70000000,30,2,13.71000000,116,3,13.72000000,15,1,13.73000000,330,5,13.74000000,215,3,13.75000000,415,5,13.76000000,230,4,13.77000000,415,5,ARL,308705489
1306,2025-07-17T15:49:06.344356890Z,2025-07-17T15:49:06.344191321Z,160,2,1108,C,A,0,13.74000000,100,0,165569,258574949,13.55000000,10,1,13.54000000,100,1,13.38000000,33,1,13.37000000,100,1,13.31000000,10,1,13.30000000,100,1,13.28000000,11,2,13.27000000,110,2,13.26000000,204,4,13.25000000,111,2,13.40000000,208,12,13.67000000,100,1,13.70000000,30,2,13.71000000,116,3,13.72000000,15,1,13.73000000,330,5,13.74000000,215,3,13.75000000,415,5,13.76000000,230,4,13.77000000,415,5,ARL,308374881
1307,2025-07-17T15:49:06.344356890Z,2025-07-17T15:49:06.344191321Z,160,2,1108,A,A,0,13.72000000,100,130,165569,258574949,13.55000000,10,1,13.54000000,100,1,13.38000000,33,1,13.37000000,100,1,13.31000000,10,1,13.30000000,100,1,13.28000000,11,2,13.27000000,110,2,13.26000000,204,4,13.25000000,111,2,13.40000000,208,12,13.67000000,100,1,13.70000000,30,2,13.71000000,116,3,13.72000000,115,2,13.73000000,330,5,13.74000000,215,3,13.75000000,415,5,13.76000000,230,4,13.77000000,415,5,ARL,308797069
1308,2025-07-17T15:49:06.345104491Z,2025-07-17T15:49:06.344938975Z,160,2,1108,C,A,0,14.83000000,100,0,165516,258575013,13.55000000,10,1,13.54000000,100,1,13.38000000,33,1,13.37000000,100,1,13.31000000,10,1,13.30000000,100,1,13.28000000,11,2,13.27000000,110,2,13.26000000,204,4,13.25000000,111,2,13.40000000,208,12,13.67000000,100,1,13.70000000,30,2,13.71000000,116,3,13.72000000,115,2,13.73000000,330,5,13.74000000,215,3,13.75000000,415,5,13.76000000,230,4,13.77000000,415,5,ARL,307964665
1309,2025-07-17T15:49:06.345104491Z,2025-07-17T15:49:06.344938975Z,160,2,1108,A,A,0,14.78000000,100,130,165516,258575013,13.55000000,10,1,13.54000000,100,1,13.38000000,33,1,13.37000000,100,1,13.31000000,10,1,13.30000000,100,1,13.28000000,11,2,13.27000000,110,2,13.26000000,204,4,13.25000000,111,2,13.40000000,208,12,13.67000000,100,1,13.70000000,30,2,13.71000000,116,3,13.72000000,115,2,13.73000000,330,5,13.74000000,215,3,13.75000000,415,5,13.76000000,230,4,13.77000000,415,5,ARL,308797245
1310,2025-07-17T15:49:06.362945410Z,2025-07-17T15:49:06.362779870Z,160,2,1108,C,A,0,17.58000000,100,0,165540,258575963,13.55000000,10,1,13.54000000,100,1,13.38000000,33,1,13.37000000,100,1,13.31000000,10,1,13.30000000,100,1,13.28000000,11,2,13.27000000,110,2,13.26000000,204,4,13.25000000,111,2,13.40000000,208,12,13.67000000,100,1,13.70000000,30,2,13.71000000,116,3,13.72000000,115,2,13.73000000,330,5,13.74000000,215,3,13.75000000,415,5,13.76000000,230,4,13.77000000,415,5,ARL,306652017
1311,2025-07-17T15:49:06.362945410Z,2025-07-17T15:49:06.362779870Z,160,2,1108,A,A,0,17.43000000,100,130,165540,258575963,13.55000000,10,1,13.54000000,100,1,13.38000000,33,1,13.37000000,100,1,13.31000000,10,1,13.30000000,100,1,13.28000000,11,2,13.27000000,110,2,13.26000000,204,4,13.25000000,111,2,13.40000000,208,12,13.67000000,100,1,13.70000000,30,2,13.71000000,116,3,13.72000000,115,2,13.73000000,330,5,13.74000000,215,3,13.75000000,415,5,13.76000000,230,4,13.77000000,415,5,ARL,308799373
1312,2025-07-17T15:49:10.459317885Z,2025-07-17T15:49:10.459152457Z,160,2,1108,C,A,0,13.73000000,15,130,165428,258636400,13.55000000,10,1,13.54000000,100,1,13.38000000,33,1,13.37000000,100,1,13.31000000,10,1,13.30000000,100,1,13.28000000,11,2,13.27000000,110,2,13.26000000,204,4,13.25000000,111,2,13.40000000,208,12,13.67000000,100,1,13.70000000,30,2,13.71000000,116,3,13.72000000,115,2,13.73000000,330,5,13.74000000,215,3,13.75000000,415,5,13.76000000,230,4,13.77000000,415,5,ARL,308374537
1313,2025-07-17T15:49:11.460597600Z,2025-07-17T15:49:11.460432218Z,160,2,1108,A,A,0,13.69000000,15,130,165382,258650544,13.55000000,10,1,13.54000000,100,1,13.38000000,33,1,13.37000000,100,1,13.31000000,10,1,13.30000000,100,1,13.28000000,11,2,13.27000000,110,2,13.26000000,204,4,13.25000000,111,2,13.40000000,208,12,13.67000000,100,1,13.69000000,15,1,13.70000000,30,2,13.71000000,116,3,13.72000000,115,2,13.73000000,330,5,13.74000000,215,3,13.75000000,415,5,13.76000000,230,4,ARL,308893737
1314,2025-07-17T15:49:11.891643099Z,2025-07-17T15:49:11.891477604Z,160,2,1108,C,A,0,13.72000000,100,0,165495,258658721,13.55000000,10,1,13.54000000,100,1,13.38000000,33,1,13.37000000,100,1,13.31000000,10,1,13.30000000,100,1,13.28000000,11,2,13.27000000,110,2,13.26000000,204,4,13.25000000,111,2,13.40000000,208,12,13.67000000,100,1,13.69000000,15,1,13.70000000,30,2,13.71000000,116,3,13.72000000,115,2,13.73000000,330,5,13.74000000,215,3,13.75000000,415,5,13.76000000,230,4,ARL,308797069
1315,2025-07-17T15:49:11.891643099Z,2025-07-17T15:49:11.891477604Z,160,2,1108,A,A,0,13.70000000,100,130,165495,258658721,13.55000000,10,1,13.54000000,100,1,13.38000000,33,1,13.37000000,100,1,13.31000000,10,1,13.30000000,100,1,13.28000000,11,2,13.27000000,110,2,13.26000000,204,4,13.25000000,111,2,13.40000000,208,12,13.67000000,100,1,13.69000000,15,1,13.70000000,130,3,13.71000000,116,3,13.72000000,115,2,13.73000000,330,5,13.74000000,215,3,13.75000000,415,5,13.76000000,230,4,ARL,308901793
1316,2025-07-17T15:49:11.893989071Z,2025-07-17T15:49:11.893823458Z,160,2,1108,C,A,0,14.81000000,100,0,165613,258658835,13.55000000,10,1,13.54000000,100,1,13.38000000,33,1,13.37000000,100,1,13.31000000,10,1,13.30000000,100,1,13.28000000,11,2,13.27000000,110,2,13.26000000,204,4,13.25000000,111,2,13.40000000,208,12,13.67000000,100,1,13.69000000,15,1,13.70000000,130,3,13.71000000,116,3,13.72000000,115,2,13.73000000,330,5,13.74000000,215,3,13.75000000,415,5,13.76000000,230,4,ARL,306649913
1317,2025-07-17T15:49:11.893989071Z,2025-07-17T15:49:11.893823458Z,160,2,1108,A,A,0,14.66000000,100,130,165613,258658835,13.55000000,10,1,13.54000000,100,1,13.38000000,33,1,13.37000000,100,1,13.31000000,10,1,13.30000000,100,1,13.28000000,11,2,13.27000000,110,2,13.26000000,204,4,13.25000000,111,2,13.40000000,208,12,13.67000000,100,1,13.69000000,15,1,13.70000000,130,3,13.71000000,116,3,13.72000000,115,2,13.73000000,330,5,13.74000000,215,3,13.75000000,415,5,13.76000000,230,4,ARL,308901981
1318,2025-07-17T15:49:11.904231149Z,2025-07-17T15:49:11.904065674Z,160,2,1108,C,A,0,15.92000000,100,0,165475,258659039,13.55000000,10,1,13.54000000,100,1,13.38000000,33,1,13.37000000,100,1,13.31000000,10,1,13.30000000,100,1,13.28000000,11,2,13.27000000,110,2,13.26000000,204,4,13.25000000,111,2,13.40000000,208,12,13.67000000,100,1,13.69000000,15,1,13.70000000,130,3,13.71000000,116,3,13.72000000,115,2,13.73000000,330,5,13.74000000,215,3,13.75000000,415,5,13.76000000,230,4,ARL,306652001
1319,2025-07-17T15:49:11.904231149Z,2025-07-17T15:49:11.904065674Z,160,2,1108,A,A,0,15.76000000,100,130,165475,258659039,13.55000000,10,1,13.54000000,100,1,13.38000000,33,1,13.37000000,100,1,13.31000000,10,1,13.30000000,100,1,13.28000000,11,2,13.27000000,110,2,13.26000000,204,4,13.25000000,111,2,13.40000000,208,12,13.67000000,100,1,13.69000000,15,1,13.70000000,130,3,13.71000000,116,3,13.72000000,115,2,13.73000000,330,5,13.74000000,215,3,13.75000000,415,5,13.76000000,230,4,ARL,308902229
1320,2025-07-17T15:49:11.935521687Z,2025-07-17T15:49:11.935356090Z,160,2,1108,C,A,0,14.81000000,100,0,165597,258659320,13.55000000,10,1,13.54000000,100,1,13.38000000,33,1,13.37000000,100,1,13.31000000,10,1,13.30000000,100,1,13.28000000,11,2,13.27000000,110,2,13.26000000,204,4,13.25000000,111,2,13.40000000,208,12,13.67000000,100,1,13.69000000,15,1,13.70000000,130,3,13.71000000,116,3,13.72000000,115,2,13.73000000,330,5,13.74000000,215,3,13.75000000,415,5,13.76000000,230,4,ARL,306653713
1321,2025-07-17T15:49:11.935521687Z,2025-07-17T15:49:11.935356090Z,160,2,1108,A,A,0,14.66000000,100,130,165597,258659320,13.55000000,10,1,13.54000000,100,1,13.38000000,33,1,13.37000000,100,1,13.31000000,10,1,13.30000000,100,1,13.28000000,11,2,13.27000000,110,2,13.26000000,204,4,13.25000000,111,2,13.40000000,208,12,13.67000000,100,1,13.69000000,15,1,13.70000000,130,3,13.71000000,116,3,13.72000000,115,2,13.73000000,330,5,13.74000000,215,3,13.75000000,415,5,13.76000000,230,4,ARL,308903001
1322,2025-07-17T15:49:11.948701049Z,2025-07-17T15:49:11.948535655Z,160,2,1108,C,A,0,14.64000000,100,130,165394,258659496,13.55000000,10,1,13.54000000,100,1,13.38000000,33,1,13.37000000,100,1,13.31000000,10,1,13.30000000,100,1,13.28000000,11,2,13.27000000,110,2,13.26000000,204,4,13.25000000,111,2,13.40000000,208,12,13.67000000,100,1,13.69000000,15,1,13.70000000,130,3,13.71000000,116,3,13.72000000,115,2,13.73000000,330,5,13.74000000,215,3,13.75000000,415,5,13.76000000,230,4,ARL,306647521
1323,2025-07-17T15:49:11.948829112Z,2025-07-17T15:49:11.948663655Z,160,2,1108,A,A,0,14.50000000,100,130,165457,258659499,13.55000000,10,1,13.54000000,100,1,13.38000000,33,1,13.37000000,100,1,13.31000000,10,1,13.30000000,100,1,13.28000000,11,2,13.27000000,110,2,13.26000000,204,4,13.25000000,111,2,13.40000000,208,12,13.67000000,100,1,13.69000000,15,1,13.70000000,130,3,13.71000000,116,3,13.72000000,115,2,13.73000000,330,5,13.74000000,215,3,13.75000000,415,5,13.76000000,230,4,ARL,308903349
1324,2025-07-17T15:49:12.221221367Z,2025-07-17T15:49:12.221056085Z,160,2,1108,A,A,0,13.71000000,100,130,165282,258663292,13.55000000,10,1,13.54000000,100,1,13.38000000,33,1,13.37000000,100,1,13.31000000,10,1,13.30000000,100,1,13.28000000,11,2,13.27000000,110,2,13.26000000,204,4,13.25000000,111,2,13.40000000,208,12,13.67000000,100,1,13.69000000,15,1,13.70000000,130,3,13.71000000,216,4,13.72000000,115,2,13.73000000,330,5,13.74000000,215,3,13.75000000,415,5,13.76000000,230,4,ARL,308909249
1325,2025-07-17T15:49:12.227986905Z,2025-07-17T15:49:12.227821500Z,160,2,1108,C,A,0,13.73000000,100,130,165405,258663378,13.55000000,10,1,13.54000000,100,1,13.38000000,33,1,13.37000000,100,1,13.31000000,10,1,13.30000000,100,1,13.28000000,11,2,13.27000000,110,2,13.26000000,204,4,13.25000000,111,2,13.40000000,208,12,13.67000000,100,1,13.69000000,15,1,13.70000000,130,3,13.71000000,216,4,13.72000000,115,2,13.73000000,330,5,13.74000000,215,3,13.75000000,415,5,13.76000000,230,4,ARL,308786185
1326,2025-07-17T15:49:14.463229121Z,2025-07-17T15:49:14.463063539Z,160,2,1108,C,A,0,13.71000000,15,130,165582,258702625,13.55000000,10,1,13.54000000,100,1,13.38000000,33,1,13.37000000,100,1,13.31000000,10,1,13.30000000,100,1,13.28000000,11,2,13.27000000,110,2,13.26000000,204,4,13.25000000,111,2,13.40000000,208,12,13.67000000,100,1,13.69000000,15,1,13.70000000,130,3,13.71000000,216,4,13.72000000,115,2,13.73000000,330,5,13.74000000,215,3,13.75000000,415,5,13.76000000,230,4,ARL,308763065
1327,2025-07-17T15:49:15.466365122Z,2025-07-17T15:49:15.466199239Z,160,2,1108,A,A,0,13.67000000,15,130,165883,258716863,13.55000000,10,1,13.54000000,100,1,13.38000000,33,1,13.37000000,100,1,13.31000000,10,1,13.30000000,100,1,13.28000000,11,2,13.27000000,110,2,13.26000000,204,4,13.25000000,111,2,13.40000000,208,12,13.67000000,115,2,13.69000000,15,1,13.70000000,130,3,13.71000000,216,4,13.72000000,115,2,13.73000000,330,5,13.74000000,215,3,13.75000000,415,5,13.76000000,230,4,ARL,308980305
1328,2025-07-17T15:49:16.351024588Z,2025-07-17T15:49:16.350859152Z,160,2,1108,C,A,0,13.70000000,100,0,165436,258727929,13.55000000,10,1,13.54000000,100,1,13.38000000,33,1,13.37000000,100,1,13.31000000,10,1,13.30000000,100,1,13.28000000,11,2,13.27000000,110,2,13.26000000,204,4,13.25000000,111,2,13.40000000,208,12,13.67000000,115,2,13.69000000,15,1,13.70000000,130,3,13.71000000,216,4,13.72000000,115,2,13.73000000,330,5,13.74000000,215,3,13.75000000,415,5,13.76000000,230,4,ARL,308901793
1329,2025-07-17T15:49:16.351024588Z,2025-07-17T15:49:16.350859152Z,160,2,1108,A,A,0,13.68000000,100,130,165436,258727929,13.55000000,10,1,13.54000000,100,1,13.38000000,33,1,13.37000000,100,1,13.31000000,10,1,13.30000000,100,1,13.28000000,11,2,13.27000000,110,2,13.26000000,204,4,13.25000000,111,2,13.40000000,208,12,13.67000000,115,2,13.68000000,100,1,13.69000000,15,1,13.70000000,130,3,13.71000000,216,4,13.72000000,115,2,13.73000000,330,5,13.74000000,215,3,13.75000000,415,5,ARL,308998225
1330,2025-07-17T15:49:16.351759618Z,2025-07-17T15:49:16.351594042Z,160,2,1108,C,A,0,14.78000000,100,0,165576,258727956,13.55000000,10,1,13.54000000,100,1,13.38000000,33,1,13.37000000,100,1,13.31000000,10,1,13.30000000,100,1,13.28000000,11,2,13.27000000,110,2,13.26000000,204,4,13.25000000,111,2,13.40000000,208,12,13.67000000,115,2,13.68000000,100,1,13.69000000,15,1,13.70000000,130,3,13.71000000,216,4,13.72000000,115,2,13.73000000,330,5,13.74000000,215,3,13.75000000,415,5,ARL,308797245
1331,2025-07-17T15:49:16.351759618Z,2025-07-17T15:49:16.351594042Z,160,2,1108,A,A,0,14.74000000,100,130,165576,258727956,13.55000000,10,1,13.54000000,100,1,13.38000000,33,1,13.37000000,100,1,13.31000000,10,1,13.30000000,100,1,13.28000000,11,2,13.27000000,110,2,13.26000000,204,4,13.25000000,111,2,13.40000000,208,12,13.67000000,115,2,13.68000000,100,1,13.69000000,15,1,13.70000000,130,3,13.71000000,216,4,13.72000000,115,2,13.73000000,330,5,13.74000000,215,3,13.75000000,415,5,ARL,308998341
1332,2025-07-17T15:49:16.494111490Z,2025-07-17T15:49:16.493946243Z,160,2,1108,A,A,0,13.69000000,100,130,165247,258729266,13.55000000,10,1,13.54000000,100,1,13.38000000,33,1,13.37000000,100,1,13.31000000,10,1,13.30000000,100,1,13.28000000,11,2,13.27000000,110,2,13.26000000,204,4,13.25000000,111,2,13.40000000,208,12,13.67000000,115,2,13.68000000,100,1,13.69000000,115,2,13.70000000,130,3,13.71000000,216,4,13.72000000,115,2,13.73000000,330,5,13.74000000,215,3,13.75000000,415,5,ARL,309001525
1333,2025-07-17T15:49:16.557924863Z,2025-07-17T15:49:16.557759633Z,160,2,1108,C,A,0,13.71000000,100,130,165230,258730034,13.55000000,10,1,13.54000000,100,1,13.38000000,33,1,13.37000000,100,1,13.31000000,10,1,13.30000000,100,1,13.28000000,11,2,13.27000000,110,2,13.26000000,204,4,13.25000000,111,2,13.40000000,208,12,13.67000000,115,2,13.68000000,100,1,13.69000000,115,2,13.70000000,130,3,13.71000000,216,4,13.72000000,115,2,13.73000000,330,5,13.74000000,215,3,13.75000000,415,5,ARL,308909249
1334,2025-07-17T15:49:21.186150487Z,2025-07-17T15:49:21.185984774Z,160,2,1108,C,A,0,14.07000000,2,0,165713,258786552,13.55000000,10,1,13.54000000,100,1,13.38000000,33,1,13.37000000,100,1,13.31000000,10,1,13.30000000,100,1,13.28000000,11,2,13.27000000,110,2,13.26000000,204,4,13.25000000,111,2,13.40000000,208,12,13.67000000,115,2,13.68000000,100,1,13.69000000,115,2,13.70000000,130,3,13.71000000,216,4,13.72000000,115,2,13.73000000,330,5,13.74000000,215,3,13.75000000,415,5,ARL,296478973
1335,2025-07-17T15:49:21.186150487Z,2025-07-17T15:49:21.185984774Z,160,2,1108,A,A,0,13.98000000,2,130,165713,258786552,13.55000000,10,1,13.54000000,100,1,13.38000000,33,1,13.37000000,100,1,13.31000000,10,1,13.30000000,100,1,13.28000000,11,2,13.27000000,110,2,13.26000000,204,4,13.25000000,111,2,13.40000000,208,12,13.67000000,115,2,13.68000000,100,1,13.69000000,115,2,13.70000000,130,3,13.71000000,216,4,13.72000000,115,2,13.73000000,330,5,13.74000000,215,3,13.75000000,415,5,ARL,309091513
1336,2025-07-17T15:49:24.283152112Z,2025-07-17T15:49:24.282985894Z,160,2,1108,C,A,0,13.69000000,15,130,166218,258838460,13.55000000,10,1,13.54000000,100,1,13.38000000,33,1,13.37000000,100,1,13.31000000,10,1,13.30000000,100,1,13.28000000,11,2,13.27000000,110,2,13.26000000,204,4,13.25000000,111,2,13.40000000,208,12,13.67000000,115,2,13.68000000,100,1,13.69000000,115,2,13.70000000,130,3,13.71000000,216,4,13.72000000,115,2,13.73000000,330,5,13.74000000,215,3,13.75000000,415,5,ARL,308893737
1337,2025-07-17T15:49:34.570197134Z,2025-07-17T15:49:34.570031718Z,160,2,1108,C,A,0,13.67000000,15,130,165416,258980876,13.55000000,10,1,13.54000000,100,1,13.38000000,33,1,13.37000000,100,1,13.31000000,10,1,13.30000000,100,1,13.28000000,11,2,13.27000000,110,2,13.26000000,204,4,13.25000000,111,2,13.40000000,208,12,13.67000000,115,2,13.68000000,100,1,13.69000000,115,2,13.70000000,130,3,13.71000000,216,4,13.72000000,115,2,13.73000000,330,5,13.74000000,215,3,13.75000000,415,5,ARL,308980305
1338,2025-07-17T15:49:34.591512915Z,2025-07-17T15:49:34.591347169Z,160,2,1108,C,A,0,13.69000000,100,130,165746,258983321,13.55000000,10,1,13.54000000,100,1,13.38000000,33,1,13.37000000,100,1,13.31000000,10,1,13.30000000,100,1,13.28000000,11,2,13.27000000,110,2,13.26000000,204,4,13.25000000,111,2,13.40000000,208,12,13.67000000,115,2,13.68000000,100,1,13.69000000,115,2,13.70000000,130,3,13.71000000,216,4,13.72000000,115,2,13.73000000,330,5,13.74000000,215,3,13.75000000,415,5,ARL,309001525
1339,2025-07-17T15:49:38.610017394Z,2025-07-17T15:49:38.609851985Z,160,2,1108,A,A,0,13.72000000,100,130,165409,259031220,13.55000000,10,1,13.54000000,100,1,13.38000000,33,1,13.37000000,100,1,13.31000000,10,1,13.30000000,100,1,13.28000000,11,2,13.27000000,110,2,13.26000000,204,4,13.25000000,111,2,13.40000000,208,12,13.67000000,115,2,13.68000000,100,1,13.69000000,115,2,13.70000000,130,3,13.71000000,216,4,13.72000000,215,3,13.73000000,330,5,13.74000000,215,3,13.75000000,415,5,ARL,309410565
1340,2025-07-17T15:49:38.610073334Z,2025-07-17T15:49:38.609907720Z,160,2,1108,C,B,0,13.26000000,100,130,165614,259031221,13.55000000,10,1,13.54000000,100,1,13.38000000,33,1,13.37000000,100,1,13.31000000,10,1,13.30000000,100,1,13.28000000,11,2,13.27000000,110,2,13.26000000,204,4,13.25000000,111,2,13.40000000,208,12,13.67000000,115,2,13.68000000,100,1,13.69000000,115,2,13.70000000,130,3,13.71000000,216,4,13.72000000,215,3,13.73000000,330,5,13.74000000,215,3,13.75000000,415,5,ARL,291975017
1341,2025-07-17T15:49:39.068515005Z,2025-07-17T15:49:39.068349660Z,160,2,1108,A,B,0,13.02000000,100,130,165345,259035032,13.55000000,10,1,13.54000000,100,1,13.38000000,33,1,13.37000000,100,1,13.31000000,10,1,13.30000000,100,1,13.28000000,11,2,13.27000000,110,2,13.26000000,204,4,13.25000000,111,2,13.40000000,208,12,13.67000000,115,2,13.68000000,100,1,13.69000000,115,2,13.70000000,130,3,13.71000000,216,4,13.72000000,215,3,13.73000000,330,5,13.74000000,215,3,13.75000000,415,5,ARL,309415429
1342,2025-07-17T15:49:44.788414401Z,2025-07-17T15:49:44.788249210Z,160,2,1108,A,A,0,13.67000000,15,130,165191,259105347,13.55000000,10,1,13.54000000,100,1,13.38000000,33,1,13.37000000,100,1,13.31000000,10,1,13.30000000,100,1,13.28000000,11,2,13.27000000,110,2,13.26000000,204,4,13.25000000,111,2,13.40000000,208,12,13.67000000,130,3,13.68000000,100,1,13.69000000,115,2,13.70000000,130,3,13.71000000,216,4,13.72000000,215,3,13.73000000,330,5,13.74000000,215,3,13.75000000,415,5,ARL,309524921
1343,2025-07-17T15:49:44.789020757Z,2025-07-17T15:49:44.788855587Z,160,2,1108,A,A,0,13.70000000,100,130,165170,259105361,13.55000000,10,1,13.54000000,100,1,13.38000000,33,1,13.37000000,100,1,13.31000000,10,1,13.30000000,100,1,13.28000000,11,2,13.27000000,110,2,13.26000000,204,4,13.25000000,111,2,13.40000000,208,12,13.67000000,130,3,13.68000000,100,1,13.69000000,115,2,13.70000000,230,4,13.71000000,216,4,13.72000000,215,3,13.73000000,330,5,13.74000000,215,3,13.75000000,415,5,ARL,309524933
1344,2025-07-17T15:49:44.789702916Z,2025-07-17T15:49:44.789537536Z,160,2,1108,C,A,0,13.72000000,100,130,165380,259105380,13.55000000,10,1,13.54000000,100,1,13.38000000,33,1,13.37000000,100,1,13.31000000,10,1,13.30000000,100,1,13.28000000,11,2,13.27000000,110,2,13.26000000,204,4,13.25000000,111,2,13.40000000,208,12,13.67000000,130,3,13.68000000,100,1,13.69000000,115,2,13.70000000,230,4,13.71000000,216,4,13.72000000,215,3,13.73000000,330,5,13.74000000,215,3,13.75000000,415,5,ARL,309410565
1345,2025-07-17T15:49:54.788658841Z,2025-07-17T15:49:54.788493605Z,160,2,1108,A,A,0,13.65000000,15,130,165236,259253294,13.55000000,10,1,13.54000000,100,1,13.38000000,33,1,13.37000000,100,1,13.31000000,10,1,13.30000000,100,1,13.28000000,11,2,13.27000000,110,2,13.26000000,204,4,13.25000000,111,2,13.40000000,208,12,13.65000000,15,1,13.67000000,130,3,13.68000000,100,1,13.69000000,115,2,13.70000000,230,4,13.71000000,216,4,13.72000000,215,3,13.73000000,330,5,13.74000000,215,3,ARL,309707269
1346,2025-07-17T15:49:54.799535744Z,2025-07-17T15:49:54.799370442Z,160,2,1108,A,A,0,13.68000000,100,130,165302,259253527,13.55000000,10,1,13.54000000,100,1,13.38000000,33,1,13.37000000,100,1,13.31000000,10,1,13.30000000,100,1,13.28000000,11,2,13.27000000,110,2,13.26000000,204,4,13.25000000,111,2,13.40000000,208,12,13.65000000,15,1,13.67000000,130,3,13.68000000,200,2,13.69000000,115,2,13.70000000,230,4,13.71000000,216,4,13.72000000,215,3,13.73000000,330,5,13.74000000,215,3,ARL,309707413
1347,2025-07-17T15:49:54.820634917Z,2025-07-17T15:49:54.820469390Z,160,2,1108,C,A,0,13.70000000,100,130,165527,259253732,13.55000000,10,1,13.54000000,100,1,13.38000000,33,1,13.37000000,100,1,13.31000000,10,1,13.30000000,100,1,13.28000000,11,2,13.27000000,110,2,13.26000000,204,4,13.25000000,111,2,13.40000000,208,12,13.65000000,15,1,13.67000000,130,3,13.68000000,200,2,13.69000000,115,2,13.70000000,230,4,13.71000000,216,4,13.72000000,215,3,13.73000000,330,5,13.74000000,215,3,ARL,309524933
1348,2025-07-17T15:49:59.512104064Z,2025-07-17T15:49:59.511938438Z,160,2,1108,C,A,0,13.68000000,100,0,165626,259313537,13.55000000,10,1,13.54000000,100,1,13.38000000,33,1,13.37000000,100,1,13.31000000,10,1,13.30000000,100,1,13.28000000,11,2,13.27000000,110,2,13.26000000,204,4,13.25000000,111,2,13.40000000,208,12,13.65000000,15,1,13.67000000,130,3,13.68000000,200,2,13.69000000,115,2,13.70000000,230,4,13.71000000,216,4,13.72000000,215,3,13.73000000,330,5,13.74000000,215,3,ARL,308998225
1349,2025-07-17T15:49:59.512104064Z,2025-07-17T15:49:59.511938438Z,160,2,1108,A,A,0,13.66000000,100,130,165626,259313537,13.55000000,10,1,13.54000000,100,1,13.38000000,33,1,13.37000000,100,1,13.31000000,10,1,13.30000000,100,1,13.28000000,11,2,13.27000000,110,2,13.26000000,204,4,13.25000000,111,2,13.40000000,208,12,13.65000000,15,1,13.66000000,100,1,13.67000000,130,3,13.68000000,200,2,13.69000000,115,2,13.70000000,230,4,13.71000000,216,4,13.72000000,215,3,13.73000000,330,5,ARL,309782481
1350,2025-07-17T15:49:59.534062634Z,2025-07-17T15:49:59.533897369Z,160,2,1108,C,A,0,14.01000000,100,130,165265,259314032,13.55000000,10,1,13.54000000,100,1,13.38000000,33,1,13.37000000,100,1,13.31000000,10,1,13.30000000,100,1,13.28000000,11,2,13.27000000,110,2,13.26000000,204,4,13.25000000,111,2,13.40000000,208,12,13.65000000,15,1,13.66000000,100,1,13.67000000,130,3,13.68000000,200,2,13.69000000,115,2,13.70000000,230,4,13.71000000,216,4,13.72000000,215,3,13.73000000,330,5,ARL,308375185
1351,2025-07-17T15:49:59.534115275Z,2025-07-17T15:49:59.533948952Z,160,2,1108,A,A,0,13.93000000,100,130,166323,259314033,13.55000000,10,1,13.54000000,100,1,13.38000000,33,1,13.37000000,100,1,13.31000000,10,1,13.30000000,100,1,13.28000000,11,2,13.27000000,110,2,13.26000000,204,4,13.25000000,111,2,13.40000000,208,12,13.65000000,15,1,13.66000000,100,1,13.67000000,130,3,13.68000000,200,2,13.69000000,115,2,13.70000000,230,4,13.71000000,216,4,13.72000000,215,3,13.73000000,330,5,ARL,309782973
1352,2025-07-17T15:50:00.547404972Z,2025-07-17T15:50:00.547239401Z,160,2,1108,C,A,0,13.67000000,15,130,165571,259349868,13.55000000,10,1,13.54000000,100,1,13.38000000,33,1,13.37000000,100,1,13.31000000,10,1,13.30000000,100,1,13.28000000,11,2,13.27000000,110,2,13.26000000,204,4,13.25000000,111,2,13.40000000,208,12,13.65000000,15,1,13.66000000,100,1,13.67000000,130,3,13.68000000,200,2,13.69000000,115,2,13.70000000,230,4,13.71000000,216,4,13.72000000,215,3,13.73000000,330,5,ARL,309524921
1353,2025-07-17T15:50:00.555536688Z,2025-07-17T15:50:00.555363249Z,160,2,1108,C,A,0,14.65000000,100,0,173439,259353226,13.55000000,10,1,13.54000000,100,1,13.38000000,33,1,13.37000000,100,1,13.31000000,10,1,13.30000000,100,1,13.28000000,11,2,13.27000000,110,2,13.26000000,204,4,13.25000000,111,2,13.40000000,208,12,13.65000000,15,1,13.66000000,100,1,13.67000000,130,3,13.68000000,200,2,13.69000000,115,2,13.70000000,230,4,13.71000000,216,4,13.72000000,215,3,13.73000000,330,5,ARL,307964661
1354,2025-07-17T15:50:00.555536688Z,2025-07-17T15:50:00.555363249Z,160,2,1108,A,A,0,14.54000000,100,128,173439,259353226,13.55000000,10,1,13.54000000,100,1,13.38000000,33,1,13.37000000,100,1,13.31000000,10,1,13.30000000,100,1,13.28000000,11,2,13.27000000,110,2,13.26000000,204,4,13.25000000,111,2,13.40000000,208,12,13.65000000,15,1,13.66000000,100,1,13.67000000,130,3,13.68000000,200,2,13.69000000,115,2,13.70000000,230,4,13.71000000,216,4,13.72000000,215,3,13.73000000,330,5,ARL,309823025
1355,2025-07-17T15:50:03.412422880Z,2025-07-17T15:50:03.412257475Z,160,2,1108,A,A,0,13.63000000,15,130,165405,259413272,13.55000000,10,1,13.54000000,100,1,13.38000000,33,1,13.37000000,100,1,13.31000000,10,1,13.30000000,100,1,13.28000000,11,2,13.27000000,110,2,13.26000000,204,4,13.25000000,111,2,13.40000000,208,12,13.63000000,15,1,13.65000000,15,1,13.66000000,100,1,13.67000000,130,3,13.68000000,200,2,13.69000000,115,2,13.70000000,230,4,13.71000000,216,4,13.72000000,215,3,ARL,309899025
1356,2025-07-17T15:50:03.415527372Z,2025-07-17T15:50:03.415361851Z,160,2,1108,C,A,0,14.64000000,100,0,165521,259413427,13.55000000,10,1,13.54000000,100,1,13.38000000,33,1,13.37000000,100,1,13.31000000,10,1,13.30000000,100,1,13.28000000,11,2,13.27000000,110,2,13.26000000,204,4,13.25000000,111,2,13.40000000,208,12,13.63000000,15,1,13.65000000,15,1,13.66000000,100,1,13.67000000,130,3,13.68000000,200,2,13.69000000,115,2,13.70000000,230,4,13.71000000,216,4,13.72000000,215,3,ARL,308296381
1357,2025-07-17T15:50:03.415527372Z,2025-07-17T15:50:03.415361851Z,160,2,1108,A,A,0,14.53000000,100,130,165521,259413427,13.55000000,10,1,13.54000000,100,1,13.38000000,33,1,13.37000000,100,1,13.31000000,10,1,13.30000000,100,1,13.28000000,11,2,13.27000000,110,2,13.26000000,204,4,13.25000000,111,2,13.40000000,208,12,13.63000000,15,1,13.65000000,15,1,13.66000000,100,1,13.67000000,130,3,13.68000000,200,2,13.69000000,115,2,13.70000000,230,4,13.71000000,216,4,13.72000000,215,3,ARL,309899141
1358,2025-07-17T15:50:03.824292152Z,2025-07-17T15:50:03.824126753Z,160,2,1108,C,A,0,13.66000000,100,0,165399,259418661,13.55000000,10,1,13.54000000,100,1,13.38000000,33,1,13.37000000,100,1,13.31000000,10,1,13.30000000,100,1,13.28000000,11,2,13.27000000,110,2,13.26000000,204,4,13.25000000,111,2,13.40000000,208,12,13.63000000,15,1,13.65000000,15,1,13.66000000,100,1,13.67000000,130,3,13.68000000,200,2,13.69000000,115,2,13.70000000,230,4,13.71000000,216,4,13.72000000,215,3,ARL,309782481
1359,2025-07-17T15:50:03.824292152Z,2025-07-17T15:50:03.824126753Z,160,2,1108,A,A,0,13.64000000,100,130,165399,259418661,13.55000000,10,1,13.54000000,100,1,13.38000000,33,1,13.37000000,100,1,13.31000000,10,1,13.30000000,100,1,13.28000000,11,2,13.27000000,110,2,13.26000000,204,4,13.25000000,111,2,13.40000000,208,12,13.63000000,15,1,13.64000000,100,1,13.65000000,15,1,13.66000000,100,1,13.67000000,130,3,13.68000000,200,2,13.69000000,115,2,13.70000000,230,4,13.71000000,216,4,ARL,309903973
1360,2025-07-17T15:50:03.825028460Z,2025-07-17T15:50:03.824863026Z,160,2,1108,C,A,0,14.74000000,100,0,165434,259418664,13.55000000,10,1,13.54000000,100,1,13.38000000,33,1,13.37000000,100,1,13.31000000,10,1,13.30000000,100,1,13.28000000,11,2,13.27000000,110,2,13.26000000,204,4,13.25000000,111,2,13.40000000,208,12,13.63000000,15,1,13.64000000,100,1,13.65000000,15,1,13.66000000,100,1,13.67000000,130,3,13.68000000,200,2,13.69000000,115,2,13.70000000,230,4,13.71000000,216,4,ARL,308998341
1361,2025-07-17T15:50:03.825028460Z,2025-07-17T15:50:03.824863026Z,160,2,1108,A,A,0,14.70000000,100,130,165434,259418664,13.55000000,10,1,13.54000000,100,1,13.38000000,33,1,13.37000000,100,1,13.31000000,10,1,13.30000000,100,1,13.28000000,11,2,13.27000000,110,2,13.26000000,204,4,13.25000000,111,2,13.40000000,208,12,13.63000000,15,1,13.64000000,100,1,13.65000000,15,1,13.66000000,100,1,13.67000000,130,3,13.68000000,200,2,13.69000000,115,2,13.70000000,230,4,13.71000000,216,4,ARL,309903993
1362,2025-07-17T15:50:04.484898759Z,2025-07-17T15:50:04.484733438Z,160,2,1108,A,A,0,13.66000000,100,130,165321,259433904,13.55000000,10,1,13.54000000,100,1,13.38000000,33,1,13.37000000,100,1,13.31000000,10,1,13.30000000,100,1,13.28000000,11,2,13.27000000,110,2,13.26000000,204,4,13.25000000,111,2,13.40000000,208,12,13.63000000,15,1,13.64000000,100,1,13.65000000,15,1,13.66000000,200,2,13.67000000,130,3,13.68000000,200,2,13.69000000,115,2,13.70000000,230,4,13.71000000,216,4,ARL,309922345
1363,2025-07-17T15:50:04.524729039Z,2025-07-17T15:50:04.524563568Z,160,2,1108,C,A,0,13.68000000,100,130,165471,259434652,13.55000000,10,1,13.54000000,100,1,13.38000000,33,1,13.37000000,100,1,13.31000000,10,1,13.30000000,100,1,13.28000000,11,2,13.27000000,110,2,13.26000000,204,4,13.25000000,111,2,13.40000000,208,12,13.63000000,15,1,13.64000000,100,1,13.65000000,15,1,13.66000000,200,2,13.67000000,130,3,13.68000000,200,2,13.69000000,115,2,13.70000000,230,4,13.71000000,216,4,ARL,309707413
1364,2025-07-17T15:50:06.787826975Z,2025-07-17T15:50:06.787661846Z,160,2,1108,C,A,0,13.63000000,15,130,165129,259472951,13.55000000,10,1,13.54000000,100,1,13.38000000,33,1,13.37000000,100,1,13.31000000,10,1,13.30000000,100,1,13.28000000,11,2,13.27000000,110,2,13.26000000,204,4,13.25000000,111,2,13.40000000,208,12,13.63000000,15,1,13.64000000,100,1,13.65000000,15,1,13.66000000,200,2,13.67000000,130,3,13.68000000,200,2,13.69000000,115,2,13.70000000,230,4,13.71000000,216,4,ARL,309899025
1365,2025-07-17T15:50:09.185499367Z,2025-07-17T15:50:09.185334126Z,160,2,1108,A,A,0,13.61000000,15,130,165241,259516855,13.55000000,10,1,13.54000000,100,1,13.38000000,33,1,13.37000000,100,1,13.31000000,10,1,13.30000000,100,1,13.28000000,11,2,13.27000000,110,2,13.26000000,204,4,13.25000000,111,2,13.40000000,208,12,13.61000000,15,1,13.63000000,15,1,13.64000000,100,1,13.65000000,15,1,13.66000000,200,2,13.67000000,130,3,13.68000000,200,2,13.69000000,115,2,13.70000000,230,4,ARL,310030465
1366,2025-07-17T15:50:09.198476437Z,2025-07-17T15:50:09.198311198Z,160,2,1108,A,A,0,13.64000000,100,130,165239,259517754,13.55000000,10,1,13.54000000,100,1,13.38000000,33,1,13.37000000,100,1,13.31000000,10,1,13.30000000,100,1,13.28000000,11,2,13.27000000,110,2,13.26000000,204,4,13.25000000,111,2,13.40000000,208,12,13.61000000,15,1,13.63000000,15,1,13.64000000,200,2,13.65000000,15,1,13.66000000,200,2,13.67000000,130,3,13.68000000,200,2,13.69000000,115,2,13.70000000,230,4,ARL,310031625
1367,2025-07-17T15:50:09.205487416Z,2025-07-17T15:50:09.205322092Z,160,2,1108,C,A,0,13.66000000,100,130,165324,259517973,13.55000000,10,1,13.54000000,100,1,13.38000000,33,1,13.37000000,100,1,13.31000000,10,1,13.30000000,100,1,13.28000000,11,2,13.27000000,110,2,13.26000000,204,4,13.25000000,111,2,13.40000000,208,12,13.61000000,15,1,13.63000000,15,1,13.64000000,200,2,13.65000000,15,1,13.66000000,200,2,13.67000000,130,3,13.68000000,200,2,13.69000000,115,2,13.70000000,230,4,ARL,309922345
1368,2025-07-17T15:50:09.330738153Z,2025-07-17T15:50:09.330572653Z,160,2,1108,C,A,0,13.64000000,100,0,165500,259522708,13.55000000,10,1,13.54000000,100,1,13.38000000,33,1,13.37000000,100,1,13.31000000,10,1,13.30000000,100,1,13.28000000,11,2,13.27000000,110,2,13.26000000,204,4,13.25000000,111,2,13.40000000,208,12,13.61000000,15,1,13.63000000,15,1,13.64000000,200,2,13.65000000,15,1,13.66000000,200,2,13.67000000,130,3,13.68000000,200,2,13.69000000,115,2,13.70000000,230,4,ARL,309903973
1369,2025-07-17T15:50:09.330738153Z,2025-07-17T15:50:09.330572653Z,160,2,1108,A,A,0,13.62000000,100,130,165500,259522708,13.55000000,10,1,13.54000000,100,1,13.38000000,33,1,13.37000000,100,1,13.31000000,10,1,13.30000000,100,1,13.28000000,11,2,13.27000000,110,2,13.26000000,204,4,13.25000000,111,2,13.40000000,208,12,13.61000000,15,1,13.62000000,100,1,13.63000000,15,1,13.64000000,200,2,13.65000000,15,1,13.66000000,200,2,13.67000000,130,3,13.68000000,200,2,13.69000000,115,2,ARL,310037965
1370,2025-07-17T15:50:20.204539185Z,2025-07-17T15:50:20.204373858Z,160,2,1108,C,A,0,13.65000000,15,130,165327,259737768,13.55000000,10,1,13.54000000,100,1,13.38000000,33,1,13.37000000,100,1,13.31000000,10,1,13.30000000,100,1,13.28000000,11,2,13.27000000,110,2,13.26000000,204,4,13.25000000,111,2,13.40000000,208,12,13.61000000,15,1,13.62000000,100,1,13.63000000,15,1,13.64000000,200,2,13.65000000,15,1,13.66000000,200,2,13.67000000,130,3,13.68000000,200,2,13.69000000,115,2,ARL,309707269
1371,2025-07-17T15:50:25.935579034Z,2025-07-17T15:50:25.935412900Z,160,2,1108,A,A,0,13.59000000,15,128,166134,259828644,13.55000000,10,1,13.54000000,100,1,13.38000000,33,1,13.37000000,100,1,13.31000000,10,1,13.30000000,100,1,13.28000000,11,2,13.27000000,110,2,13.26000000,204,4,13.25000000,111,2,13.40000000,208,12,13.59000000,15,1,13.61000000,15,1,13.62000000,100,1,13.63000000,15,1,13.64000000,200,2,13.65000000,15,1,13.66000000,200,2,13.67000000,130,3,13.68000000,200,2,ARL,310424077
1372,2025-07-17T15:50:26.954828150Z,2025-07-17T15:50:26.954662143Z,160,2,1108,C,A,0,13.62000000,100,0,166007,259847181,13.55000000,10,1,13.54000000,100,1,13.38000000,33,1,13.37000000,100,1,13.31000000,10,1,13.30000000,100,1,13.28000000,11,2,13.27000000,110,2,13.26000000,204,4,13.25000000,111,2,13.40000000,208,12,13.59000000,15,1,13.61000000,15,1,13.62000000,100,1,13.63000000,15,1,13.64000000,200,2,13.65000000,15,1,13.66000000,200,2,13.67000000,130,3,13.68000000,200,2,ARL,310037965
1373,2025-07-17T15:50:26.954828150Z,2025-07-17T15:50:26.954662143Z,160,2,1108,A,A,0,13.60000000,100,130,166007,259847181,13.55000000,10,1,13.54000000,100,1,13.38000000,33,1,13.37000000,100,1,13.31000000,10,1,13.30000000,100,1,13.28000000,11,2,13.27000000,110,2,13.26000000,204,4,13.25000000,111,2,13.40000000,208,12,13.59000000,15,1,13.60000000,100,1,13.61000000,15,1,13.62000000,100,1,13.63000000,15,1,13.64000000,200,2,13.65000000,15,1,13.66000000,200,2,13.67000000,130,3,ARL,310446249
1374,2025-07-17T15:50:26.955565904Z,2025-07-17T15:50:26.955400327Z,160,2,1108,C,A,0,14.70000000,100,0,165577,259847190,13.55000000,10,1,13.54000000,100,1,13.38000000,33,1,13.37000000,100,1,13.31000000,10,1,13.30000000,100,1,13.28000000,11,2,13.27000000,110,2,13.26000000,204,4,13.25000000,111,2,13.40000000,208,12,13.59000000,15,1,13.60000000,100,1,13.61000000,15,1,13.62000000,100,1,13.63000000,15,1,13.64000000,200,2,13.65000000,15,1,13.66000000,200,2,13.67000000,130,3,ARL,309903993
1375,2025-07-17T15:50:26.955565904Z,2025-07-17T15:50:26.955400327Z,160,2,1108,A,A,0,14.65000000,100,130,165577,259847190,13.55000000,10,1,13.54000000,100,1,13.38000000,33,1,13.37000000,100,1,13.31000000,10,1,13.30000000,100,1,13.28000000,11,2,13.27000000,110,2,13.26000000,204,4,13.25000000,111,2,13.40000000,208,12,13.59000000,15,1,13.60000000,100,1,13.61000000,15,1,13.62000000,100,1,13.63000000,15,1,13.64000000,200,2,13.65000000,15,1,13.66000000,200,2,13.67000000,130,3,ARL,310446269
1376,2025-07-17T15:50:26.956259508Z,2025-07-17T15:50:26.956094101Z,160,2,1108,C,A,0,17.43000000,100,0,165407,259847199,13.55000000,10,1,13.54000000,100,1,13.38000000,33,1,13.37000000,100,1,13.31000000,10,1,13.30000000,100,1,13.28000000,11,2,13.27000000,110,2,13.26000000,204,4,13.25000000,111,2,13.40000000,208,12,13.59000000,15,1,13.60000000,100,1,13.61000000,15,1,13.62000000,100,1,13.63000000,15,1,13.64000000,200,2,13.65000000,15,1,13.66000000,200,2,13.67000000,130,3,ARL,308799373
1377,2025-07-17T15:50:26.956259508Z,2025-07-17T15:50:26.956094101Z,160,2,1108,A,A,0,17.28000000,100,130,165407,259847199,13.55000000,10,1,13.54000000,100,1,13.38000000,33,1,13.37000000,100,1,13.31000000,10,1,13.30000000,100,1,13.28000000,11,2,13.27000000,110,2,13.26000000,204,4,13.25000000,111,2,13.40000000,208,12,13.59000000,15,1,13.60000000,100,1,13.61000000,15,1,13.62000000,100,1,13.63000000,15,1,13.64000000,200,2,13.65000000,15,1,13.66000000,200,2,13.67000000,130,3,ARL,310446293
1378,2025-07-17T15:50:26.983044736Z,2025-07-17T15:50:26.982879448Z,160,2,1108,A,A,0,15.51000000,100,130,165288,259847556,13.55000000,10,1,13.54000000,100,1,13.38000000,33,1,13.37000000,100,1,13.31000000,10,1,13.30000000,100,1,13.28000000,11,2,13.27000000,110,2,13.26000000,204,4,13.25000000,111,2,13.40000000,208,12,13.59000000,15,1,13.60000000,100,1,13.61000000,15,1,13.62000000,100,1,13.63000000,15,1,13.64000000,200,2,13.65000000,15,1,13.66000000,200,2,13.67000000,130,3,ARL,310447441
1379,2025-07-17T15:50:26.983057675Z,2025-07-17T15:50:26.982892468Z,160,2,1108,C,A,0,15.78000000,100,130,165207,259847557,13.55000000,10,1,13.54000000,100,1,13.38000000,33,1,13.37000000,100,1,13.31000000,10,1,13.30000000,100,1,13.28000000,11,2,13.27000000,110,2,13.26000000,204,4,13.25000000,111,2,13.40000000,208,12,13.59000000,15,1,13.60000000,100,1,13.61000000,15,1,13.62000000,100,1,13.63000000,15,1,13.64000000,200,2,13.65000000,15,1,13.66000000,200,2,13.67000000,130,3,ARL,282776733
1380,2025-07-17T15:50:30.046879569Z,2025-07-17T15:50:30.046714265Z,160,2,1108,C,A,0,13.59000000,15,130,165304,259916670,13.55000000,10,1,13.54000000,100,1,13.38000000,33,1,13.37000000,100,1,13.31000000,10,1,13.30000000,100,1,13.28000000,11,2,13.27000000,110,2,13.26000000,204,4,13.25000000,111,2,13.40000000,208,12,13.59000000,15,1,13.60000000,100,1,13.61000000,15,1,13.62000000,100,1,13.63000000,15,1,13.64000000,200,2,13.65000000,15,1,13.66000000,200,2,13.67000000,130,3,ARL,310424077
1381,2025-07-17T15:50:30.047015114Z,2025-07-17T15:50:30.046849726Z,160,2,1108,C,A,0,13.61000000,15,130,165388,259916674,13.55000000,10,1,13.54000000,100,1,13.38000000,33,1,13.37000000,100,1,13.31000000,10,1,13.30000000,100,1,13.28000000,11,2,13.27000000,110,2,13.26000000,204,4,13.25000000,111,2,13.40000000,208,12,13.59000000,15,1,13.60000000,100,1,13.61000000,15,1,13.62000000,100,1,13.63000000,15,1,13.64000000,200,2,13.65000000,15,1,13.66000000,200,2,13.67000000,130,3,ARL,310030465
1382,2025-07-17T15:51:37.986158330Z,2025-07-17T15:51:37.985992174Z,160,2,1108,C,A,0,13.98000000,2,0,166156,261130345,13.55000000,10,1,13.54000000,100,1,13.38000000,33,1,13.37000000,100,1,13.31000000,10,1,13.30000000,100,1,13.28000000,11,2,13.27000000,110,2,13.26000000,204,4,13.25000000,111,2,13.40000000,208,12,13.59000000,15,1,13.60000000,100,1,13.61000000,15,1,13.62000000,100,1,13.63000000,15,1,13.64000000,200,2,13.65000000,15,1,13.66000000,200,2,13.67000000,130,3,ARL,309091513
1383,2025-07-17T15:51:37.986158330Z,2025-07-17T15:51:37.985992174Z,160,2,1108,A,A,0,13.89000000,2,130,166156,261130345,13.55000000,10,1,13.54000000,100,1,13.38000000,33,1,13.37000000,100,1,13.31000000,10,1,13.30000000,100,1,13.28000000,11,2,13.27000000,110,2,13.26000000,204,4,13.25000000,111,2,13.40000000,208,12,13.59000000,15,1,13.60000000,100,1,13.61000000,15,1,13.62000000,100,1,13.63000000,15,1,13.64000000,200,2,13.65000000,15,1,13.66000000,200,2,13.67000000,130,3,ARL,311979125
1384,2025-07-17T15:52:16.371517839Z,2025-07-17T15:52:16.371351021Z,160,2,1108,T,N,0,13.41000000,58,0,166818,261713745,13.55000000,10,1,13.54000000,100,1,13.38000000,33,1,13.37000000,100,1,13.31000000,10,1,13.30000000,100,1,13.28000000,11,2,13.27000000,110,2,13.26000000,204,4,13.25000000,111,2,13.40000000,208,12,13.59000000,15,1,13.60000000,100,1,13.61000000,15,1,13.62000000,100,1,13.63000000,15,1,13.64000000,200,2,13.65000000,15,1,13.66000000,200,2,13.67000000,130,3,ARL,0
1385,2025-07-17T15:52:16.371517839Z,2025-07-17T15:52:16.371351021Z,160,2,1108,T,N,0,13.28000000,12,130,166818,261713746,13.55000000,10,1,13.54000000,100,1,13.38000000,33,1,13.37000000,100,1,13.31000000,10,1,13.30000000,100,1,13.28000000,11,2,13.27000000,110,2,13.26000000,204,4,13.25000000,111,2,13.40000000,208,12,13.59000000,15,1,13.60000000,100,1,13.61000000,15,1,13.62000000,100,1,13.63000000,15,1,13.64000000,200,2,13.65000000,15,1,13.66000000,200,2,13.67000000,130,3,ARL,0
1386,2025-07-17T15:52:16.372434625Z,2025-07-17T15:52:16.372269170Z,160,2,1108,C,A,0,13.60000000,100,130,165455,261713790,13.55000000,10,1,13.54000000,100,1,13.38000000,33,1,13.37000000,100,1,13.31000000,10,1,13.30000000,100,1,13.28000000,11,2,13.27000000,110,2,13.26000000,204,4,13.25000000,111,2,13.40000000,208,12,13.59000000,15,1,13.60000000,100,1,13.61000000,15,1,13.62000000,100,1,13.63000000,15,1,13.64000000,200,2,13.65000000,15,1,13.66000000,200,2,13.67000000,130,3,ARL,310446249
1387,2025-07-17T15:52:16.373188791Z,2025-07-17T15:52:16.373023186Z,160,2,1108,C,A,0,14.65000000,100,0,165605,261713830,13.55000000,10,1,13.54000000,100,1,13.38000000,33,1,13.37000000,100,1,13.31000000,10,1,13.30000000,100,1,13.28000000,11,2,13.27000000,110,2,13.26000000,204,4,13.25000000,111,2,13.40000000,208,12,13.59000000,15,1,13.60000000,100,1,13.61000000,15,1,13.62000000,100,1,13.63000000,15,1,13.64000000,200,2,13.65000000,15,1,13.66000000,200,2,13.67000000,130,3,ARL,310446269
1388,2025-07-17T15:52:16.373188791Z,2025-07-17T15:52:16.373023186Z,160,2,1108,A,A,0,14.70000000,100,130,165605,261713830,13.55000000,10,1,13.54000000,100,1,13.38000000,33,1,13.37000000,100,1,13.31000000,10,1,13.30000000,100,1,13.28000000,11,2,13.27000000,110,2,13.26000000,204,4,13.25000000,111,2,13.40000000,208,12,13.59000000,15,1,13.60000000,100,1,13.61000000,15,1,13.62000000,100,1,13.63000000,15,1,13.64000000,200,2,13.65000000,15,1,13.66000000,200,2,13.67000000,130,3,ARL,312771573
1389,2025-07-17T15:52:16.374353159Z,2025-07-17T15:52:16.374186508Z,160,2,1108,C,A,0,13.64000000,100,130,166651,261713870,13.55000000,10,1,13.54000000,100,1,13.38000000,33,1,13.37000000,100,1,13.31000000,10,1,13.30000000,100,1,13.28000000,11,2,13.27000000,110,2,13.26000000,204,4,13.25000000,111,2,13.40000000,208,12,13.59000000,15,1,13.60000000,100,1,13.61000000,15,1,13.62000000,100,1,13.63000000,15,1,13.64000000,200,2,13.65000000,15,1,13.66000000,200,2,13.67000000,130,3,ARL,310031625
1390,2025-07-17T15:52:16.374480183Z,2025-07-17T15:52:16.374312976Z,160,2,1108,A,A,0,15.86000000,100,128,167207,261713880,13.55000000,10,1,13.54000000,100,1,13.38000000,33,1,13.37000000,100,1,13.31000000,10,1,13.30000000,100,1,13.28000000,11,2,13.27000000,110,2,13.26000000,204,4,13.25000000,111,2,13.40000000,208,12,13.59000000,15,1,13.60000000,100,1,13.61000000,15,1,13.62000000,100,1,13.63000000,15,1,13.64000000,200,2,13.65000000,15,1,13.66000000,200,2,13.67000000,130,3,ARL,312771645
1391,2025-07-17T15:52:16.374493650Z,2025-07-17T15:52:16.374327668Z,160,2,1108,C,A,0,15.51000000,100,130,165982,261713884,13.55000000,10,1,13.54000000,100,1,13.38000000,33,1,13.37000000,100,1,13.31000000,10,1,13.30000000,100,1,13.28000000,11,2,13.27000000,110,2,13.26000000,204,4,13.25000000,111,2,13.40000000,208,12,13.59000000,15,1,13.60000000,100,1,13.61000000,15,1,13.62000000,100,1,13.63000000,15,1,13.64000000,200,2,13.65000000,15,1,13.66000000,200,2,13.67000000,130,3,ARL,310447441
1392,2025-07-17T15:52:16.375388285Z,2025-07-17T15:52:16.375222836Z,160,2,1108,C,A,0,14.54000000,100,0,165449,261713944,13.55000000,10,1,13.54000000,100,1,13.38000000,33,1,13.37000000,100,1,13.31000000,10,1,13.30000000,100,1,13.28000000,11,2,13.27000000,110,2,13.26000000,204,4,13.25000000,111,2,13.40000000,208,12,13.59000000,15,1,13.60000000,100,1,13.61000000,15,1,13.62000000,100,1,13.63000000,15,1,13.64000000,200,2,13.65000000,15,1,13.66000000,200,2,13.67000000,130,3,ARL,309823025
1393,2025-07-17T15:52:16.375388285Z,2025-07-17T15:52:16.375222836Z,160,2,1108,A,A,0,14.81000000,100,130,165449,261713944,13.55000000,10,1,13.54000000,100,1,13.38000000,33,1,13.37000000,100,1,13.31000000,10,1,13.30000000,100,1,13.28000000,11,2,13.27000000,110,2,13.26000000,204,4,13.25000000,111,2,13.40000000,208,12,13.59000000,15,1,13.60000000,100,1,13.61000000,15,1,13.62000000,100,1,13.63000000,15,1,13.64000000,200,2,13.65000000,15,1,13.66000000,200,2,13.67000000,130,3,ARL,312771781
1394,2025-07-17T15:52:16.375414247Z,2025-07-17T15:52:16.375248654Z,160,2,1108,C,A,0,14.66000000,100,0,165593,261713945,13.55000000,10,1,13.54000000,100,1,13.38000000,33,1,13.37000000,100,1,13.31000000,10,1,13.30000000,100,1,13.28000000,11,2,13.27000000,110,2,13.26000000,204,4,13.25000000,111,2,13.40000000,208,12,13.59000000,15,1,13.60000000,100,1,13.61000000,15,1,13.62000000,100,1,13.63000000,15,1,13.64000000,200,2,13.65000000,15,1,13.66000000,200,2,13.67000000,130,3,ARL,308901981
1395,2025-07-17T15:52:16.375414247Z,2025-07-17T15:52:16.375248654Z,160,2,1108,A,A,0,14.89000000,100,130,165593,261713945,13.55000000,10,1,13.54000000,100,1,13.38000000,33,1,13.37000000,100,1,13.31000000,10,1,13.30000000,100,1,13.28000000,11,2,13.27000000,110,2,13.26000000,204,4,13.25000000,111,2,13.40000000,208,12,13.59000000,15,1,13.60000000,100,1,13.61000000,15,1,13.62000000,100,1,13.63000000,15,1,13.64000000,200,2,13.65000000,15,1,13.66000000,200,2,13.67000000,130,3,ARL,312771785
1396,2025-07-17T15:52:16.375828154Z,2025-07-17T15:52:16.375662552Z,160,2,1108,C,A,0,14.53000000,100,0,165602,261713959,13.55000000,10,1,13.54000000,100,1,13.38000000,33,1,13.37000000,100,1,13.31000000,10,1,13.30000000,100,1,13.28000000,11,2,13.27000000,110,2,13.26000000,204,4,13.25000000,111,2,13.40000000,208,12,13.59000000,15,1,13.60000000,100,1,13.61000000,15,1,13.62000000,100,1,13.63000000,15,1,13.64000000,200,2,13.65000000,15,1,13.66000000,200,2,13.67000000,130,3,ARL,309899141
1397,2025-07-17T15:52:16.375828154Z,2025-07-17T15:52:16.375662552Z,160,2,1108,A,A,0,14.76000000,100,130,165602,261713959,13.55000000,10,1,13.54000000,100,1,13.38000000,33,1,13.37000000,100,1,13.31000000,10,1,13.30000000,100,1,13.28000000,11,2,13.27000000,110,2,13.26000000,204,4,13.25000000,111,2,13.40000000,208,12,13.59000000,15,1,13.60000000,100,1,13.61000000,15,1,13.62000000,100,1,13.63000000,15,1,13.64000000,200,2,13.65000000,15,1,13.66000000,200,2,13.67000000,130,3,ARL,312771829
1398,2025-07-17T15:52:16.377345053Z,2025-07-17T15:52:16.377179230Z,160,2,1108,C,A,0,17.28000000,100,0,165823,261714104,13.55000000,10,1,13.54000000,100,1,13.38000000,33,1,13.37000000,100,1,13.31000000,10,1,13.30000000,100,1,13.28000000,11,2,13.27000000,110,2,13.26000000,204,4,13.25000000,111,2,13.40000000,208,12,13.59000000,15,1,13.60000000,100,1,13.61000000,15,1,13.62000000,100,1,13.63000000,15,1,13.64000000,200,2,13.65000000,15,1,13.66000000,200,2,13.67000000,130,3,ARL,310446293
1399,2025-07-17T15:52:16.377345053Z,2025-07-17T15:52:16.377179230Z,160,2,1108,A,A,0,17.70000000,100,130,165823,261714104,13.55000000,10,1,13.54000000,100,1,13.38000000,33,1,13.37000000,100,1,13.31000000,10,1,13.30000000,100,1,13.28000000,11,2,13.27000000,110,2,13.26000000,204,4,13.25000000,111,2,13.40000000,208,12,13.59000000,15,1,13.60000000,100,1,13.61000000,15,1,13.62000000,100,1,13.63000000,15,1,13.64000000,200,2,13.65000000,15,1,13.66000000,200,2,13.67000000,130,3,ARL,312772009
1400,2025-07-17T15:52:16.378239114Z,2025-07-17T15:52:16.378073674Z,160,2,1108,C,A,0,15.76000000,100,0,165440,261714140,13.55000000,10,1,13.54000000,100,1,13.38000000,33,1,13.37000000,100,1,13.31000000,10,1,13.30000000,100,1,13.28000000,11,2,13.27000000,110,2,13.26000000,204,4,13.25000000,111,2,13.40000000,208,12,13.59000000,15,1,13.60000000,100,1,13.61000000,15,1,13.62000000,100,1,13.63000000,15,1,13.64000000,200,2,13.65000000,15,1,13.66000000,200,2,13.67000000,130,3,ARL,308902229
1401,2025-07-17T15:52:16.378239114Z,2025-07-17T15:52:16.378073674Z,160,2,1108,A,A,0,16.02000000,100,130,165440,261714140,13.55000000,10,1,13.54000000,100,1,13.38000000,33,1,13.37000000,100,1,13.31000000,10,1,13.30000000,100,1,13.28000000,11,2,13.27000000,110,2,13.26000000,204,4,13.25000000,111,2,13.40000000,208,12,13.59000000,15,1,13.60000000,100,1,13.61000000,15,1,13.62000000,100,1,13.63000000,15,1,13.64000000,200,2,13.65000000,15,1,13.66000000,200,2,13.67000000,130,3,ARL,312772057
1402,2025-07-17T15:52:16.378385943Z,2025-07-17T15:52:16.378220434Z,160,2,1108,C,A,0,14.50000000,100,0,165509,261714145,13.55000000,10,1,13.54000000,100,1,13.38000000,33,1,13.37000000,100,1,13.31000000,10,1,13.30000000,100,1,13.28000000,11,2,13.27000000,110,2,13.26000000,204,4,13.25000000,111,2,13.40000000,208,12,13.59000000,15,1,13.60000000,100,1,13.61000000,15,1,13.62000000,100,1,13.63000000,15,1,13.64000000,200,2,13.65000000,15,1,13.66000000,200,2,13.67000000,130,3,ARL,308903349
1403,2025-07-17T15:52:16.378385943Z,2025-07-17T15:52:16.378220434Z,160,2,1108,A,A,0,14.72000000,100,130,165509,261714145,13.55000000,10,1,13.54000000,100,1,13.38000000,33,1,13.37000000,100,1,13.31000000,10,1,13.30000000,100,1,13.28000000,11,2,13.27000000,110,2,13.26000000,204,4,13.25000000,111,2,13.40000000,208,12,13.59000000,15,1,13.60000000,100,1,13.61000000,15,1,13.62000000,100,1,13.63000000,15,1,13.64000000,200,2,13.65000000,15,1,13.66000000,200,2,13.67000000,130,3,ARL,312772061
1404,2025-07-17T15:52:16.378870638Z,2025-07-17T15:52:16.378705201Z,160,2,1108,A,B,0,13.27000000,10,130,165437,261714171,13.55000000,10,1,13.54000000,100,1,13.38000000,33,1,13.37000000,100,1,13.31000000,10,1,13.30000000,100,1,13.28000000,11,2,13.27000000,120,3,13.26000000,204,4,13.25000000,111,2,13.40000000,208,12,13.59000000,15,1,13.60000000,100,1,13.61000000,15,1,13.62000000,100,1,13.63000000,15,1,13.64000000,200,2,13.65000000,15,1,13.66000000,200,2,13.67000000,130,3,ARL,312772069
1405,2025-07-17T15:52:16.378872385Z,2025-07-17T15:52:16.378707041Z,160,2,1108,A,A,0,13.86000000,15,130,165344,261714172,13.55000000,10,1,13.54000000,100,1,13.38000000,33,1,13.37000000,100,1,13.31000000,10,1,13.30000000,100,1,13.28000000,11,2,13.27000000,120,3,13.26000000,204,4,13.25000000,111,2,13.40000000,208,12,13.59000000,15,1,13.60000000,100,1,13.61000000,15,1,13.62000000,100,1,13.63000000,15,1,13.64000000,200,2,13.65000000,15,1,13.66000000,200,2,13.67000000,130,3,ARL,312772073
1406,2025-07-17T15:52:16.379127782Z,2025-07-17T15:52:16.378962330Z,160,2,1108,C,B,0,13.02000000,100,0,165452,261714185,13.55000000,10,1,13.54000000,100,1,13.38000000,33,1,13.37000000,100,1,13.31000000,10,1,13.30000000,100,1,13.28000000,11,2,13.27000000,120,3,13.26000000,204,4,13.25000000,111,2,13.40000000,208,12,13.59000000,15,1,13.60000000,100,1,13.61000000,15,1,13.62000000,100,1,13.63000000,15,1,13.64000000,200,2,13.65000000,15,1,13.66000000,200,2,13.67000000,130,3,ARL,309415429
1407,2025-07-17T15:52:16.379127782Z,2025-07-17T15:52:16.378962330Z,160,2,1108,A,B,0,13.26000000,100,130,165452,261714185,13.55000000,10,1,13.54000000,100,1,13.38000000,33,1,13.37000000,100,1,13.31000000,10,1,13.30000000,100,1,13.28000000,11,2,13.27000000,120,3,13.26000000,304,5,13.25000000,111,2,13.40000000,208,12,13.59000000,15,1,13.60000000,100,1,13.61000000,15,1,13.62000000,100,1,13.63000000,15,1,13.64000000,200,2,13.65000000,15,1,13.66000000,200,2,13.67000000,130,3,ARL,312772077
1408,2025-07-17T15:52:16.389025469Z,2025-07-17T15:52:16.388859982Z,160,2,1108,C,A,0,13.93000000,100,130,165487,261714477,13.55000000,10,1,13.54000000,100,1,13.38000000,33,1,13.37000000,100,1,13.31000000,10,1,13.30000000,100,1,13.28000000,11,2,13.27000000,120,3,13.26000000,304,5,13.25000000,111,2,13.40000000,208,12,13.59000000,15,1,13.60000000,100,1,13.61000000,15,1,13.62000000,100,1,13.63000000,15,1,13.64000000,200,2,13.65000000,15,1,13.66000000,200,2,13.67000000,130,3,ARL,309782973
1409,2025-07-17T15:52:16.389082451Z,2025-07-17T15:52:16.388917108Z,160,2,1108,A,A,0,14.19000000,100,130,165343,261714481,13.55000000,10,1,13.54000000,100,1,13.38000000,33,1,13.37000000,100,1,13.31000000,10,1,13.30000000,100,1,13.28000000,11,2,13.27000000,120,3,13.26000000,304,5,13.25000000,111,2,13.40000000,208,12,13.59000000,15,1,13.60000000,100,1,13.61000000,15,1,13.62000000,100,1,13.63000000,15,1,13.64000000,200,2,13.65000000,15,1,13.66000000,200,2,13.67000000,130,3,ARL,312772501
1410,2025-07-17T15:52:16.396174502Z,2025-07-17T15:52:16.396008715Z,160,2,1108,C,A,0,14.66000000,100,0,165787,261714603,13.55000000,10,1,13.54000000,100,1,13.38000000,33,1,13.37000000,100,1,13.31000000,10,1,13.30000000,100,1,13.28000000,11,2,13.27000000,120,3,13.26000000,304,5,13.25000000,111,2,13.40000000,208,12,13.59000000,15,1,13.60000000,100,1,13.61000000,15,1,13.62000000,100,1,13.63000000,15,1,13.64000000,200,2,13.65000000,15,1,13.66000000,200,2,13.67000000,130,3,ARL,308903001
1411,2025-07-17T15:52:16.396174502Z,2025-07-17T15:52:16.396008715Z,160,2,1108,A,A,0,14.96000000,100,130,165787,261714603,13.55000000,10,1,13.54000000,100,1,13.38000000,33,1,13.37000000,100,1,13.31000000,10,1,13.30000000,100,1,13.28000000,11,2,13.27000000,120,3,13.26000000,304,5,13.25000000,111,2,13.40000000,208,12,13.59000000,15,1,13.60000000,100,1,13.61000000,15,1,13.62000000,100,1,13.63000000,15,1,13.64000000,200,2,13.65000000,15,1,13.66000000,200,2,13.67000000,130,3,ARL,312772869
1412,2025-07-17T15:52:16.397677681Z,2025-07-17T15:52:16.397512710Z,160,2,1108,C,A,0,14.19000000,100,130,164971,261714619,13.55000000,10,1,13.54000000,100,1,13.38000000,33,1,13.37000000,100,1,13.31000000,10,1,13.30000000,100,1,13.28000000,11,2,13.27000000,120,3,13.26000000,304,5,13.25000000,111,2,13.40000000,208,12,13.59000000,15,1,13.60000000,100,1,13.61000000,15,1,13.62000000,100,1,13.63000000,15,1,13.64000000,200,2,13.65000000,15,1,13.66000000,200,2,13.67000000,130,3,ARL,312772501
1413,2025-07-17T15:52:16.397727042Z,2025-07-17T15:52:16.397561691Z,160,2,1108,A,A,0,14.26000000,100,130,165351,261714620,13.55000000,10,1,13.54000000,100,1,13.38000000,33,1,13.37000000,100,1,13.31000000,10,1,13.30000000,100,1,13.28000000,11,2,13.27000000,120,3,13.26000000,304,5,13.25000000,111,2,13.40000000,208,12,13.59000000,15,1,13.60000000,100,1,13.61000000,15,1,13.62000000,100,1,13.63000000,15,1,13.64000000,200,2,13.65000000,15,1,13.66000000,200,2,13.67000000,130,3,ARL,312772901
1414,2025-07-17T15:52:16.424137423Z,2025-07-17T15:52:16.423972000Z,160,2,1108,C,A,0,14.70000000,100,0,165423,261714976,13.55000000,10,1,13.54000000,100,1,13.38000000,33,1,13.37000000,100,1,13.31000000,10,1,13.30000000,100,1,13.28000000,11,2,13.27000000,120,3,13.26000000,304,5,13.25000000,111,2,13.40000000,208,12,13.59000000,15,1,13.60000000,100,1,13.61000000,15,1,13.62000000,100,1,13.63000000,15,1,13.64000000,200,2,13.65000000,15,1,13.66000000,200,2,13.67000000,130,3,ARL,312771573
1415,2025-07-17T15:52:16.424137423Z,2025-07-17T15:52:16.423972000Z,160,2,1108,A,A,0,15.06000000,100,130,165423,261714976,13.55000000,10,1,13.54000000,100,1,13.38000000,33,1,13.37000000,100,1,13.31000000,10,1,13.30000000,100,1,13.28000000,11,2,13.27000000,120,3,13.26000000,304,5,13.25000000,111,2,13.40000000,208,12,13.59000000,15,1,13.60000000,100,1,13.61000000,15,1,13.62000000,100,1,13.63000000,15,1,13.64000000,200,2,13.65000000,15,1,13.66000000,200,2,13.67000000,130,3,ARL,312773353
1416,2025-07-17T15:52:16.464781343Z,2025-07-17T15:52:16.464616142Z,160,2,1108,A,A,0,13.87000000,100,130,165201,261715303,13.55000000,10,1,13.54000000,100,1,13.38000000,33,1,13.37000000,100,1,13.31000000,10,1,13.30000000,100,1,13.28000000,11,2,13.27000000,120,3,13.26000000,304,5,13.25000000,111,2,13.40000000,208,12,13.59000000,15,1,13.60000000,100,1,13.61000000,15,1,13.62000000,100,1,13.63000000,15,1,13.64000000,200,2,13.65000000,15,1,13.66000000,200,2,13.67000000,130,3,ARL,312773881
1417,2025-07-17T15:52:16.473556948Z,2025-07-17T15:52:16.473391480Z,160,2,1108,C,A,0,15.06000000,100,0,165468,261715409,13.55000000,10,1,13.54000000,100,1,13.38000000,33,1,13.37000000,100,1,13.31000000,10,1,13.30000000,100,1,13.28000000,11,2,13.27000000,120,3,13.26000000,304,5,13.25000000,111,2,13.40000000,208,12,13.59000000,15,1,13.60000000,100,1,13.61000000,15,1,13.62000000,100,1,13.63000000,15,1,13.64000000,200,2,13.65000000,15,1,13.66000000,200,2,13.67000000,130,3,ARL,312773353
1418,2025-07-17T15:52:16.473556948Z,2025-07-17T15:52:16.473391480Z,160,2,1108,A,A,0,14.95000000,100,130,165468,261715409,13.55000000,10,1,13.54000000,100,1,13.38000000,33,1,13.37000000,100,1,13.31000000,10,1,13.30000000,100,1,13.28000000,11,2,13.27000000,120,3,13.26000000,304,5,13.25000000,111,2,13.40000000,208,12,13.59000000,15,1,13.60000000,100,1,13.61000000,15,1,13.62000000,100,1,13.63000000,15,1,13.64000000,200,2,13.65000000,15,1,13.66000000,200,2,13.67000000,130,3,ARL,312774001
1419,2025-07-17T15:52:16.480090894Z,2025-07-17T15:52:16.479925781Z,160,2,1108,C,A,0,14.26000000,100,130,165113,261715467,13.55000000,10,1,13.54000000,100,1,13.38000000,33,1,13.37000000,100,1,13.31000000,10,1,13.30000000,100,1,13.28000000,11,2,13.27000000,120,3,13.26000000,304,5,13.25000000,111,2,13.40000000,208,12,13.59000000,15,1,13.60000000,100,1,13.61000000,15,1,13.62000000,100,1,13.63000000,15,1,13.64000000,200,2,13.65000000,15,1,13.66000000,200,2,13.67000000,130,3,ARL,312772901
1420,2025-07-17T15:52:16.480140131Z,2025-07-17T15:52:16.479974840Z,160,2,1108,A,A,0,14.15000000,100,130,165291,261715468,13.55000000,10,1,13.54000000,100,1,13.38000000,33,1,13.37000000,100,1,13.31000000,10,1,13.30000000,100,1,13.28000000,11,2,13.27000000,120,3,13.26000000,304,5,13.25000000,111,2,13.40000000,208,12,13.59000000,15,1,13.60000000,100,1,13.61000000,15,1,13.62000000,100,1,13.63000000,15,1,13.64000000,200,2,13.65000000,15,1,13.66000000,200,2,13.67000000,130,3,ARL,312774033
1421,2025-07-17T15:52:28.787316865Z,2025-07-17T15:52:28.787151494Z,160,2,1108,C,B,0,13.27000000,10,130,165371,261883294,13.55000000,10,1,13.54000000,100,1,13.38000000,33,1,13.37000000,100,1,13.31000000,10,1,13.30000000,100,1,13.28000000,11,2,13.27000000,120,3,13.26000000,304,5,13.25000000,111,2,13.40000000,208,12,13.59000000,15,1,13.60000000,100,1,13.61000000,15,1,13.62000000,100,1,13.63000000,15,1,13.64000000,200,2,13.65000000,15,1,13.66000000,200,2,13.67000000,130,3,ARL,312772069
1422,2025-07-17T15:52:28.787317827Z,2025-07-17T15:52:28.787152437Z,160,2,1108,C,A,0,13.86000000,15,130,165390,261883295,13.55000000,10,1,13.54000000,100,1,13.38000000,33,1,13.37000000,100,1,13.31000000,10,1,13.30000000,100,1,13.28000000,11,2,13.27000000,120,3,13.26000000,304,5,13.25000000,111,2,13.40000000,208,12,13.59000000,15,1,13.60000000,100,1,13.61000000,15,1,13.62000000,100,1,13.63000000,15,1,13.64000000,200,2,13.65000000,15,1,13.66000000,200,2,13.67000000,130,3,ARL,312772073
1423,2025-07-17T15:52:43.128371033Z,2025-07-17T15:52:43.128203357Z,160,2,1108,C,A,0,13.89000000,2,0,167676,262115170,13.55000000,10,1,13.54000000,100,1,13.38000000,33,1,13.37000000,100,1,13.31000000,10,1,13.30000000,100,1,13.28000000,11,2,13.27000000,120,3,13.26000000,304,5,13.25000000,111,2,13.40000000,208,12,13.59000000,15,1,13.60000000,100,1,13.61000000,15,1,13.62000000,100,1,13.63000000,15,1,13.64000000,200,2,13.65000000,15,1,13.66000000,200,2,13.67000000,130,3,ARL,311979125
1424,2025-07-17T15:52:43.128371033Z,2025-07-17T15:52:43.128203357Z,160,2,1108,A,A,0,13.99000000,2,128,167676,262115170,13.55000000,10,1,13.54000000,100,1,13.38000000,33,1,13.37000000,100,1,13.31000000,10,1,13.30000000,100,1,13.28000000,11,2,13.27000000,120,3,13.26000000,304,5,13.25000000,111,2,13.40000000,208,12,13.59000000,15,1,13.60000000,100,1,13.61000000,15,1,13.62000000,100,1,13.63000000,15,1,13.64000000,200,2,13.65000000,15,1,13.66000000,200,2,13.67000000,130,3,ARL,313336713
1425,2025-07-17T15:54:24.908483782Z,2025-07-17T15:54:24.908318259Z,160,2,1108,A,B,0,13.29000000,10,130,165523,263863872,13.55000000,10,1,13.54000000,100,1,13.38000000,33,1,13.37000000,100,1,13.31000000,10,1,13.30000000,100,1,13.29000000,10,1,13.28000000,11,2,13.27000000,120,3,13.26000000,304,5,13.40000000,208,12,13.59000000,15,1,13.60000000,100,1,13.61000000,15,1,13.62000000,100,1,13.63000000,15,1,13.64000000,200,2,13.65000000,15,1,13.66000000,200,2,13.67000000,130,3,ARL,315581981
1426,2025-07-17T15:54:26.792478456Z,2025-07-17T15:54:26.792313320Z,160,2,1108,C,B,0,13.29000000,10,130,165136,263895481,13.55000000,10,1,13.54000000,100,1,13.38000000,33,1,13.37000000,100,1,13.31000000,10,1,13.30000000,100,1,13.29000000,10,1,13.28000000,11,2,13.27000000,120,3,13.26000000,304,5,13.40000000,208,12,13.59000000,15,1,13.60000000,100,1,13.61000000,15,1,13.62000000,100,1,13.63000000,15,1,13.64000000,200,2,13.65000000,15,1,13.66000000,200,2,13.67000000,130,3,ARL,315581981
1427,2025-07-17T15:54:52.986116083Z,2025-07-17T15:54:52.985950259Z,160,2,1108,C,A,0,13.99000000,2,0,165824,264262615,13.55000000,10,1,13.54000000,100,1,13.38000000,33,1,13.37000000,100,1,13.31000000,10,1,13.30000000,100,1,13.29000000,10,1,13.28000000,11,2,13.27000000,120,3,13.26000000,304,5,13.40000000,208,12,13.59000000,15,1,13.60000000,100,1,13.61000000,15,1,13.62000000,100,1,13.63000000,15,1,13.64000000,200,2,13.65000000,15,1,13.66000000,200,2,13.67000000,130,3,ARL,313336713
1428,2025-07-17T15:54:52.986116083Z,2025-07-17T15:54:52.985950259Z,160,2,1108,A,A,0,14.10000000,2,130,165824,264262615,13.55000000,10,1,13.54000000,100,1,13.38000000,33,1,13.37000000,100,1,13.31000000,10,1,13.30000000,100,1,13.29000000,10,1,13.28000000,11,2,13.27000000,120,3,13.26000000,304,5,13.40000000,208,12,13.59000000,15,1,13.60000000,100,1,13.61000000,15,1,13.62000000,100,1,13.63000000,15,1,13.64000000,200,2,13.65000000,15,1,13.66000000,200,2,13.67000000,130,3,ARL,316098525
1429,2025-07-17T15:55:33.673598252Z,2025-07-17T15:55:33.673432762Z,160,2,1108,A,B,0,13.29000000,10,130,165490,264905534,13.55000000,10,1,13.54000000,100,1,13.38000000,33,1,13.37000000,100,1,13.31000000,10,1,13.30000000,100,1,13.29000000,20,2,13.28000000,11,2,13.27000000,120,3,13.26000000,304,5,13.40000000,208,12,13.59000000,15,1,13.60000000,100,1,13.61000000,15,1,13.62000000,100,1,13.63000000,15,1,13.64000000,200,2,13.65000000,15,1,13.66000000,200,2,13.67000000,130,3,ARL,316911465
1430,2025-07-17T15:55:34.257417204Z,2025-07-17T15:55:34.257251787Z,160,2,1108,C,B,0,13.26000000,100,0,165417,264919835,13.55000000,10,1,13.54000000,100,1,13.38000000,33,1,13.37000000,100,1,13.31000000,10,1,13.30000000,100,1,13.29000000,20,2,13.28000000,11,2,13.27000000,120,3,13.26000000,304,5,13.40000000,208,12,13.59000000,15,1,13.60000000,100,1,13.61000000,15,1,13.62000000,100,1,13.63000000,15,1,13.64000000,200,2,13.65000000,15,1,13.66000000,200,2,13.67000000,130,3,ARL,312772077
1431,2025-07-17T15:55:34.257417204Z,2025-07-17T15:55:34.257251787Z,160,2,1108,A,B,0,13.28000000,100,130,165417,264919835,13.55000000,10,1,13.54000000,100,1,13.38000000,33,1,13.37000000,100,1,13.31000000,10,1,13.30000000,100,1,13.29000000,20,2,13.28000000,111,3,13.27000000,120,3,13.26000000,304,5,13.40000000,208,12,13.59000000,15,1,13.60000000,100,1,13.61000000,15,1,13.62000000,100,1,13.63000000,15,1,13.64000000,200,2,13.65000000,15,1,13.66000000,200,2,13.67000000,130,3,ARL,316924721
1432,2025-07-17T15:55:40.197750400Z,2025-07-17T15:55:40.197584524Z,160,2,1108,C,B,0,13.29000000,10,130,165876,265015966,13.55000000,10,1,13.54000000,100,1,13.38000000,33,1,13.37000000,100,1,13.31000000,10,1,13.30000000,100,1,13.29000000,20,2,13.28000000,111,3,13.27000000,120,3,13.26000000,304,5,13.40000000,208,12,13.59000000,15,1,13.60000000,100,1,13.61000000,15,1,13.62000000,100,1,13.63000000,15,1,13.64000000,200,2,13.65000000,15,1,13.66000000,200,2,13.67000000,130,3,ARL,316911465
1433,2025-07-17T15:57:51.111288955Z,2025-07-17T15:57:51.111121910Z,160,2,1108,T,N,0,13.60000000,1,0,167045,267268162,13.55000000,10,1,13.54000000,100,1,13.38000000,33,1,13.37000000,100,1,13.31000000,10,1,13.30000000,100,1,13.29000000,20,2,13.28000000,111,3,13.27000000,120,3,13.26000000,304,5,13.40000000,208,12,13.59000000,15,1,13.60000000,100,1,13.61000000,15,1,13.62000000,100,1,13.63000000,15,1,13.64000000,200,2,13.65000000,15,1,13.66000000,200,2,13.67000000,130,3,ARL,0
1434,2025-07-17T15:57:51.111288955Z,2025-07-17T15:57:51.111121910Z,160,2,1108,T,N,0,13.57500000,99,130,167045,267268163,13.55000000,10,1,13.54000000,100,1,13.38000000,33,1,13.37000000,100,1,13.31000000,10,1,13.30000000,100,1,13.29000000,20,2,13.28000000,111,3,13.27000000,120,3,13.26000000,304,5,13.40000000,208,12,13.59000000,15,1,13.60000000,100,1,13.61000000,15,1,13.62000000,100,1,13.63000000,15,1,13.64000000,200,2,13.65000000,15,1,13.66000000,200,2,13.67000000,130,3,ARL,0
1435,2025-07-17T15:57:51.111693755Z,2025-07-17T15:57:51.111527963Z,160,2,1108,T,N,0,13.57500000,100,130,165792,267268168,13.55000000,10,1,13.54000000,100,1,13.38000000,33,1,13.37000000,100,1,13.31000000,10,1,13.30000000,100,1,13.29000000,20,2,13.28000000,111,3,13.27000000,120,3,13.26000000,304,5,13.40000000,208,12,13.59000000,15,1,13.60000000,100,1,13.61000000,15,1,13.62000000,100,1,13.63000000,15,1,13.64000000,200,2,13.65000000,15,1,13.66000000,200,2,13.67000000,130,3,ARL,0
1436,2025-07-17T15:57:51.112077532Z,2025-07-17T15:57:51.111911476Z,160,2,1108,T,N,0,13.57500000,1,130,166056,267268183,13.55000000,10,1,13.54000000,100,1,13.38000000,33,1,13.37000000,100,1,13.31000000,10,1,13.30000000,100,1,13.29000000,20,2,13.28000000,111,3,13.27000000,120,3,13.26000000,304,5,13.40000000,208,12,13.59000000,15,1,13.60000000,100,1,13.61000000,15,1,13.62000000,100,1,13.63000000,15,1,13.64000000,200,2,13.65000000,15,1,13.66000000,200,2,13.67000000,130,3,ARL,0
1437,2025-07-17T15:57:51.328863560Z,2025-07-17T15:57:51.328698198Z,160,2,1108,C,A,0,13.87000000,100,130,165362,267272430,13.55000000,10,1,13.54000000,100,1,13.38000000,33,1,13.37000000,100,1,13.31000000,10,1,13.30000000,100,1,13.29000000,20,2,13.28000000,111,3,13.27000000,120,3,13.26000000,304,5,13.40000000,208,12,13.59000000,15,1,13.60000000,100,1,13.61000000,15,1,13.62000000,100,1,13.63000000,15,1,13.64000000,200,2,13.65000000,15,1,13.66000000,200,2,13.67000000,130,3,ARL,312773881
1438,2025-07-17T15:57:51.329613584Z,2025-07-17T15:57:51.329447325Z,160,2,1108,C,A,0,14.95000000,100,0,166259,267272438,13.55000000,10,1,13.54000000,100,1,13.38000000,33,1,13.37000000,100,1,13.31000000,10,1,13.30000000,100,1,13.29000000,20,2,13.28000000,111,3,13.27000000,120,3,13.26000000,304,5,13.40000000,208,12,13.59000000,15,1,13.60000000,100,1,13.61000000,15,1,13.62000000,100,1,13.63000000,15,1,13.64000000,200,2,13.65000000,15,1,13.66000000,200,2,13.67000000,130,3,ARL,312774001
1439,2025-07-17T15:57:51.329613584Z,2025-07-17T15:57:51.329447325Z,160,2,1108,A,A,0,15.00000000,100,130,166259,267272438,13.55000000,10,1,13.54000000,100,1,13.38000000,33,1,13.37000000,100,1,13.31000000,10,1,13.30000000,100,1,13.29000000,20,2,13.28000000,111,3,13.27000000,120,3,13.26000000,304,5,13.40000000,208,12,13.59000000,15,1,13.60000000,100,1,13.61000000,15,1,13.62000000,100,1,13.63000000,15,1,13.64000000,200,2,13.65000000,15,1,13.66000000,200,2,13.67000000,130,3,ARL,319985021
1440,2025-07-17T15:57:51.329857672Z,2025-07-17T15:57:51.329692071Z,160,2,1108,C,A,0,14.76000000,100,0,165601,267272442,13.55000000,10,1,13.54000000,100,1,13.38000000,33,1,13.37000000,100,1,13.31000000,10,1,13.30000000,100,1,13.29000000,20,2,13.28000000,111,3,13.27000000,120,3,13.26000000,304,5,13.40000000,208,12,13.59000000,15,1,13.60000000,100,1,13.61000000,15,1,13.62000000,100,1,13.63000000,15,1,13.64000000,200,2,13.65000000,15,1,13.66000000,200,2,13.67000000,130,3,ARL,312771829
1441,2025-07-17T15:57:51.329857672Z,2025-07-17T15:57:51.329692071Z,160,2,1108,A,A,0,14.89000000,100,130,165601,267272442,13.55000000,10,1,13.54000000,100,1,13.38000000,33,1,13.37000000,100,1,13.31000000,10,1,13.30000000,100,1,13.29000000,20,2,13.28000000,111,3,13.27000000,120,3,13.26000000,304,5,13.40000000,208,12,13.59000000,15,1,13.60000000,100,1,13.61000000,15,1,13.62000000,100,1,13.63000000,15,1,13.64000000,200,2,13.65000000,15,1,13.66000000,200,2,13.67000000,130,3,ARL,319985025
1442,2025-07-17T15:57:51.339328219Z,2025-07-17T15:57:51.339162512Z,160,2,1108,C,A,0,14.15000000,100,130,165707,267272660,13.55000000,10,1,13.54000000,100,1,13.38000000,33,1,13.37000000,100,1,13.31000000,10,1,13.30000000,100,1,13.29000000,20,2,13.28000000,111,3,13.27000000,120,3,13.26000000,304,5,13.40000000,208,12,13.59000000,15,1,13.60000000,100,1,13.61000000,15,1,13.62000000,100,1,13.63000000,15,1,13.64000000,200,2,13.65000000,15,1,13.66000000,200,2,13.67000000,130,3,ARL,312774033
1443,2025-07-17T15:57:51.339382098Z,2025-07-17T15:57:51.339216923Z,160,2,1108,A,A,0,14.26000000,100,130,165175,267272665,13.55000000,10,1,13.54000000,100,1,13.38000000,33,1,13.37000000,100,1,13.31000000,10,1,13.30000000,100,1,13.29000000,20,2,13.28000000,111,3,13.27000000,120,3,13.26000000,304,5,13.40000000,208,12,13.59000000,15,1,13.60000000,100,1,13.61000000,15,1,13.62000000,100,1,13.63000000,15,1,13.64000000,200,2,13.65000000,15,1,13.66000000,200,2,13.67000000,130,3,ARL,319985165
1444,2025-07-17T15:57:51.379736852Z,2025-07-17T15:57:51.379570470Z,160,2,1108,C,A,0,15.00000000,100,0,166382,267273071,13.55000000,10,1,13.54000000,100,1,13.38000000,33,1,13.37000000,100,1,13.31000000,10,1,13.30000000,100,1,13.29000000,20,2,13.28000000,111,3,13.27000000,120,3,13.26000000,304,5,13.40000000,208,12,13.59000000,15,1,13.60000000,100,1,13.61000000,15,1,13.62000000,100,1,13.63000000,15,1,13.64000000,200,2,13.65000000,15,1,13.66000000,200,2,13.67000000,130,3,ARL,319985021
1445,2025-07-17T15:57:51.379736852Z,2025-07-17T15:57:51.379570470Z,160,2,1108,A,A,0,15.06000000,100,128,166382,267273071,13.55000000,10,1,13.54000000,100,1,13.38000000,33,1,13.37000000,100,1,13.31000000,10,1,13.30000000,100,1,13.29000000,20,2,13.28000000,111,3,13.27000000,120,3,13.26000000,304,5,13.40000000,208,12,13.59000000,15,1,13.60000000,100,1,13.61000000,15,1,13.62000000,100,1,13.63000000,15,1,13.64000000,200,2,13.65000000,15,1,13.66000000,200,2,13.67000000,130,3,ARL,319985497
1446,2025-07-17T15:57:52.378369524Z,2025-07-17T15:57:52.378204338Z,160,2,1108,A,A,0,14.11000000,100,130,165186,267283873,13.55000000,10,1,13.54000000,100,1,13.38000000,33,1,13.37000000,100,1,13.31000000,10,1,13.30000000,100,1,13.29000000,20,2,13.28000000,111,3,13.27000000,120,3,13.26000000,304,5,13.40000000,208,12,13.59000000,15,1,13.60000000,100,1,13.61000000,15,1,13.62000000,100,1,13.63000000,15,1,13.64000000,200,2,13.65000000,15,1,13.66000000,200,2,13.67000000,130,3,ARL,320000233
1447,2025-07-17T15:58:14.483879079Z,2025-07-17T15:58:14.483712278Z,160,2,1108,T,N,0,13.41000000,44,130,166801,267657010,13.55000000,10,1,13.54000000,100,1,13.38000000,33,1,13.37000000,100,1,13.31000000,10,1,13.30000000,100,1,13.29000000,20,2,13.28000000,111,3,13.27000000,120,3,13.26000000,304,5,13.40000000,208,12,13.59000000,15,1,13.60000000,100,1,13.61000000,15,1,13.62000000,100,1,13.63000000,15,1,13.64000000,200,2,13.65000000,15,1,13.66000000,200,2,13.67000000,130,3,ARL,0
1448,2025-07-17T15:58:14.483909354Z,2025-07-17T15:58:14.483743947Z,160,2,1108,A,A,0,13.76000000,4,130,165407,267657011,13.55000000,10,1,13.54000000,100,1,13.38000000,33,1,13.37000000,100,1,13.31000000,10,1,13.30000000,100,1,13.29000000,20,2,13.28000000,111,3,13.27000000,120,3,13.26000000,304,5,13.40000000,208,12,13.59000000,15,1,13.60000000,100,1,13.61000000,15,1,13.62000000,100,1,13.63000000,15,1,13.64000000,200,2,13.65000000,15,1,13.66000000,200,2,13.67000000,130,3,ARL,320484625
1449,2025-07-17T15:58:14.484164551Z,2025-07-17T15:58:14.483999049Z,160,2,1108,C,A,0,14.11000000,100,0,165502,267657013,13.55000000,10,1,13.54000000,100,1,13.38000000,33,1,13.37000000,100,1,13.31000000,10,1,13.30000000,100,1,13.29000000,20,2,13.28000000,111,3,13.27000000,120,3,13.26000000,304,5,13.40000000,208,12,13.59000000,15,1,13.60000000,100,1,13.61000000,15,1,13.62000000,100,1,13.63000000,15,1,13.64000000,200,2,13.65000000,15,1,13.66000000,200,2,13.67000000,130,3,ARL,320000233
1450,2025-07-17T15:58:14.484164551Z,2025-07-17T15:58:14.483999049Z,160,2,1108,A,A,0,13.77000000,100,130,165502,267657013,13.55000000,10,1,13.54000000,100,1,13.38000000,33,1,13.37000000,100,1,13.31000000,10,1,13.30000000,100,1,13.29000000,20,2,13.28000000,111,3,13.27000000,120,3,13.26000000,304,5,13.40000000,208,12,13.59000000,15,1,13.60000000,100,1,13.61000000,15,1,13.62000000,100,1,13.63000000,15,1,13.64000000,200,2,13.65000000,15,1,13.66000000,200,2,13.67000000,130,3,ARL,320484637
1451,2025-07-17T15:58:14.484183413Z,2025-07-17T15:58:14.484017806Z,160,2,1108,C,B,0,13.28000000,100,130,165607,267657014,13.55000000,10,1,13.54000000,100,1,13.38000000,33,1,13.37000000,100,1,13.31000000,10,1,13.30000000,100,1,13.29000000,20,2,13.28000000,111,3,13.27000000,120,3,13.26000000,304,5,13.40000000,208,12,13.59000000,15,1,13.60000000,100,1,13.61000000,15,1,13.62000000,100,1,13.63000000,15,1,13.64000000,200,2,13.65000000,15,1,13.66000000,200,2,13.67000000,130,3,ARL,316924721
1452,2025-07-17T15:58:14.484299450Z,2025-07-17T15:58:14.484133730Z,160,2,1108,T,N,0,13.41000000,8,130,165720,267657017,13.55000000,10,1,13.54000000,100,1,13.38000000,33,1,13.37000000,100,1,13.31000000,10,1,13.30000000,100,1,13.29000000,20,2,13.28000000,111,3,13.27000000,120,3,13.26000000,304,5,13.40000000,208,12,13.59000000,15,1,13.60000000,100,1,13.61000000,15,1,13.62000000,100,1,13.63000000,15,1,13.64000000,200,2,13.65000000,15,1,13.66000000,200,2,13.67000000,130,3,ARL,0
1453,2025-07-17T15:58:14.484312532Z,2025-07-17T15:58:14.484147359Z,160,2,1108,A,A,0,13.79000000,100,130,165173,267657020,13.55000000,10,1,13.54000000,100,1,13.38000000,33,1,13.37000000,100,1,13.31000000,10,1,13.30000000,100,1,13.29000000,20,2,13.28000000,111,3,13.27000000,120,3,13.26000000,304,5,13.40000000,208,12,13.59000000,15,1,13.60000000,100,1,13.61000000,15,1,13.62000000,100,1,13.63000000,15,1,13.64000000,200,2,13.65000000,15,1,13.66000000,200,2,13.67000000,130,3,ARL,320484661
1454,2025-07-17T15:58:14.484902175Z,2025-07-17T15:58:14.484736787Z,160,2,1108,C,A,0,15.06000000,100,0,165388,267657063,13.55000000,10,1,13.54000000,100,1,13.38000000,33,1,13.37000000,100,1,13.31000000,10,1,13.30000000,100,1,13.29000000,20,2,13.28000000,111,3,13.27000000,120,3,13.26000000,304,5,13.40000000,208,12,13.59000000,15,1,13.60000000,100,1,13.61000000,15,1,13.62000000,100,1,13.63000000,15,1,13.64000000,200,2,13.65000000,15,1,13.66000000,200,2,13.67000000,130,3,ARL,319985497
1455,2025-07-17T15:58:14.484902175Z,2025-07-17T15:58:14.484736787Z,160,2,1108,A,A,0,14.84000000,100,130,165388,267657063,13.55000000,10,1,13.54000000,100,1,13.38000000,33,1,13.37000000,100,1,13.31000000,10,1,13.30000000,100,1,13.29000000,20,2,13.28000000,111,3,13.27000000,120,3,13.26000000,304,5,13.40000000,208,12,13.59000000,15,1,13.60000000,100,1,13.61000000,15,1,13.62000000,100,1,13.63000000,15,1,13.64000000,200,2,13.65000000,15,1,13.66000000,200,2,13.67000000,130,3,ARL,320484709
1456,2025-07-17T15:58:14.484927848Z,2025-07-17T15:58:14.484761664Z,160,2,1108,C,A,0,13.76000000,4,128,166184,267657070,13.55000000,10,1,13.54000000,100,1,13.38000000,33,1,13.37000000,100,1,13.31000000,10,1,13.30000000,100,1,13.29000000,20,2,13.28000000,111,3,13.27000000,120,3,13.26000000,304,5,13.40000000,208,12,13.59000000,15,1,13.60000000,100,1,13.61000000,15,1,13.62000000,100,1,13.63000000,15,1,13.64000000,200,2,13.65000000,15,1,13.66000000,200,2,13.67000000,130,3,ARL,320484625
1457,2025-07-17T15:58:14.484963870Z,2025-07-17T15:58:14.484798779Z,160,2,1108,C,A,0,13.77000000,100,130,165091,267657073,13.55000000,10,1,13.54000000,100,1,13.38000000,33,1,13.37000000,100,1,13.31000000,10,1,13.30000000,100,1,13.29000000,20,2,13.28000000,111,3,13.27000000,120,3,13.26000000,304,5,13.40000000,208,12,13.59000000,15,1,13.60000000,100,1,13.61000000,15,1,13.62000000,100,1,13.63000000,15,1,13.64000000,200,2,13.65000000,15,1,13.66000000,200,2,13.67000000,130,3,ARL,320484637
1458,2025-07-17T15:58:14.485392903Z,2025-07-17T15:58:14.485227487Z,160,2,1108,C,A,0,14.81000000,100,0,165416,267657092,13.55000000,10,1,13.54000000,100,1,13.38000000,33,1,13.37000000,100,1,13.31000000,10,1,13.30000000,100,1,13.29000000,20,2,13.28000000,111,3,13.27000000,120,3,13.26000000,304,5,13.40000000,208,12,13.59000000,15,1,13.60000000,100,1,13.61000000,15,1,13.62000000,100,1,13.63000000,15,1,13.64000000,200,2,13.65000000,15,1,13.66000000,200,2,13.67000000,130,3,ARL,312771781
1459,2025-07-17T15:58:14.485392903Z,2025-07-17T15:58:14.485227487Z,160,2,1108,A,A,0,14.68000000,100,130,165416,267657092,13.55000000,10,1,13.54000000,100,1,13.38000000,33,1,13.37000000,100,1,13.31000000,10,1,13.30000000,100,1,13.29000000,20,2,13.28000000,111,3,13.27000000,120,3,13.26000000,304,5,13.40000000,208,12,13.59000000,15,1,13.60000000,100,1,13.61000000,15,1,13.62000000,100,1,13.63000000,15,1,13.64000000,200,2,13.65000000,15,1,13.66000000,200,2,13.67000000,130,3,ARL,320484781
1460,2025-07-17T15:58:14.485831602Z,2025-07-17T15:58:14.485666254Z,160,2,1108,C,A,0,16.02000000,100,0,165348,267657097,13.55000000,10,1,13.54000000,100,1,13.38000000,33,1,13.37000000,100,1,13.31000000,10,1,13.30000000,100,1,13.29000000,20,2,13.28000000,111,3,13.27000000,120,3,13.26000000,304,5,13.40000000,208,12,13.59000000,15,1,13.60000000,100,1,13.61000000,15,1,13.62000000,100,1,13.63000000,15,1,13.64000000,200,2,13.65000000,15,1,13.66000000,200,2,13.67000000,130,3,ARL,312772057
1461,2025-07-17T15:58:14.485831602Z,2025-07-17T15:58:14.485666254Z,160,2,1108,A,A,0,15.86000000,100,130,165348,267657097,13.55000000,10,1,13.54000000,100,1,13.38000000,33,1,13.37000000,100,1,13.31000000,10,1,13.30000000,100,1,13.29000000,20,2,13.28000000,111,3,13.27000000,120,3,13.26000000,304,5,13.40000000,208,12,13.59000000,15,1,13.60000000,100,1,13.61000000,15,1,13.62000000,100,1,13.63000000,15,1,13.64000000,200,2,13.65000000,15,1,13.66000000,200,2,13.67000000,130,3,ARL,320484817
1462,2025-07-17T15:58:14.485850874Z,2025-07-17T15:58:14.485685308Z,160,2,1108,C,A,0,14.96000000,100,0,165566,267657098,13.55000000,10,1,13.54000000,100,1,13.38000000,33,1,13.37000000,100,1,13.31000000,10,1,13.30000000,100,1,13.29000000,20,2,13.28000000,111,3,13.27000000,120,3,13.26000000,304,5,13.40000000,208,12,13.59000000,15,1,13.60000000,100,1,13.61000000,15,1,13.62000000,100,1,13.63000000,15,1,13.64000000,200,2,13.65000000,15,1,13.66000000,200,2,13.67000000,130,3,ARL,312772869
1463,2025-07-17T15:58:14.485850874Z,2025-07-17T15:58:14.485685308Z,160,2,1108,A,A,0,14.76000000,100,130,165566,267657098,13.55000000,10,1,13.54000000,100,1,13.38000000,33,1,13.37000000,100,1,13.31000000,10,1,13.30000000,100,1,13.29000000,20,2,13.28000000,111,3,13.27000000,120,3,13.26000000,304,5,13.40000000,208,12,13.59000000,15,1,13.60000000,100,1,13.61000000,15,1,13.62000000,100,1,13.63000000,15,1,13.64000000,200,2,13.65000000,15,1,13.66000000,200,2,13.67000000,130,3,ARL,320484821
1464,2025-07-17T15:58:14.485989643Z,2025-07-17T15:58:14.485824228Z,160,2,1108,C,A,0,14.89000000,100,0,165415,267657101,13.55000000,10,1,13.54000000,100,1,13.38000000,33,1,13.37000000,100,1,13.31000000,10,1,13.30000000,100,1,13.29000000,20,2,13.28000000,111,3,13.27000000,120,3,13.26000000,304,5,13.40000000,208,12,13.59000000,15,1,13.60000000,100,1,13.61000000,15,1,13.62000000,100,1,13.63000000,15,1,13.64000000,200,2,13.65000000,15,1,13.66000000,200,2,13.67000000,130,3,ARL,319985025
1465,2025-07-17T15:58:14.485989643Z,2025-07-17T15:58:14.485824228Z,160,2,1108,A,A,0,14.69000000,100,130,165415,267657101,13.55000000,10,1,13.54000000,100,1,13.38000000,33,1,13.37000000,100,1,13.31000000,10,1,13.30000000,100,1,13.29000000,20,2,13.28000000,111,3,13.27000000,120,3,13.26000000,304,5,13.40000000,208,12,13.59000000,15,1,13.60000000,100,1,13.61000000,15,1,13.62000000,100,1,13.63000000,15,1,13.64000000,200,2,13.65000000,15,1,13.66000000,200,2,13.67000000,130,3,ARL,320484825
1466,2025-07-17T15:58:14.486406355Z,2025-07-17T15:58:14.486240860Z,160,2,1108,C,A,0,17.70000000,100,0,165495,267657116,13.55000000,10,1,13.54000000,100,1,13.38000000,33,1,13.37000000,100,1,13.31000000,10,1,13.30000000,100,1,13.29000000,20,2,13.28000000,111,3,13.27000000,120,3,13.26000000,304,5,13.40000000,208,12,13.59000000,15,1,13.60000000,100,1,13.61000000,15,1,13.62000000,100,1,13.63000000,15,1,13.64000000,200,2,13.65000000,15,1,13.66000000,200,2,13.67000000,130,3,ARL,312772009
1467,2025-07-17T15:58:14.486406355Z,2025-07-17T15:58:14.486240860Z,160,2,1108,A,A,0,17.52000000,100,130,165495,267657116,13.55000000,10,1,13.54000000,100,1,13.38000000,33,1,13.37000000,100,1,13.31000000,10,1,13.30000000,100,1,13.29000000,20,2,13.28000000,111,3,13.27000000,120,3,13.26000000,304,5,13.40000000,208,12,13.59000000,15,1,13.60000000,100,1,13.61000000,15,1,13.62000000,100,1,13.63000000,15,1,13.64000000,200,2,13.65000000,15,1,13.66000000,200,2,13.67000000,130,3,ARL,320484837
1468,2025-07-17T15:58:14.508177256Z,2025-07-17T15:58:14.508012098Z,160,2,1108,C,A,0,14.26000000,100,130,165158,267657330,13.55000000,10,1,13.54000000,100,1,13.38000000,33,1,13.37000000,100,1,13.31000000,10,1,13.30000000,100,1,13.29000000,20,2,13.28000000,111,3,13.27000000,120,3,13.26000000,304,5,13.40000000,208,12,13.59000000,15,1,13.60000000,100,1,13.61000000,15,1,13.62000000,100,1,13.63000000,15,1,13.64000000,200,2,13.65000000,15,1,13.66000000,200,2,13.67000000,130,3,ARL,319985165
1469,2025-07-17T15:58:14.508227890Z,2025-07-17T15:58:14.508062605Z,160,2,1108,A,A,0,14.05000000,100,130,165285,267657333,13.55000000,10,1,13.54000000,100,1,13.38000000,33,1,13.37000000,100,1,13.31000000,10,1,13.30000000,100,1,13.29000000,20,2,13.28000000,111,3,13.27000000,120,3,13.26000000,304,5,13.40000000,208,12,13.59000000,15,1,13.60000000,100,1,13.61000000,15,1,13.62000000,100,1,13.63000000,15,1,13.64000000,200,2,13.65000000,15,1,13.66000000,200,2,13.67000000,130,3,ARL,320484985
1470,2025-07-17T15:58:14.529557108Z,2025-07-17T15:58:14.529391743Z,160,2,1108,A,B,0,13.02000000,100,130,165365,267657561,13.55000000,10,1,13.54000000,100,1,13.38000000,33,1,13.37000000,100,1,13.31000000,10,1,13.30000000,100,1,13.29000000,20,2,13.28000000,111,3,13.27000000,120,3,13.26000000,304,5,13.40000000,208,12,13.59000000,15,1,13.60000000,100,1,13.61000000,15,1,13.62000000,100,1,13.63000000,15,1,13.64000000,200,2,13.65000000,15,1,13.66000000,200,2,13.67000000,130,3,ARL,320485385
1471,2025-07-17T15:58:14.529578291Z,2025-07-17T15:58:14.529413184Z,160,2,1108,A,A,0,13.80000000,100,130,165107,267657562,13.55000000,10,1,13.54000000,100,1,13.38000000,33,1,13.37000000,100,1,13.31000000,10,1,13.30000000,100,1,13.29000000,20,2,13.28000000,111,3,13.27000000,120,3,13.26000000,304,5,13.40000000,208,12,13.59000000,15,1,13.60000000,100,1,13.61000000,15,1,13.62000000,100,1,13.63000000,15,1,13.64000000,200,2,13.65000000,15,1,13.66000000,200,2,13.67000000,130,3,ARL,320485389
1472,2025-07-17T15:58:14.659899426Z,2025-07-17T15:58:14.659734381Z,160,2,1108,C,A,0,13.79000000,100,130,165045,267658873,13.55000000,10,1,13.54000000,100,1,13.38000000,33,1,13.37000000,100,1,13.31000000,10,1,13.30000000,100,1,13.29000000,20,2,13.28000000,111,3,13.27000000,120,3,13.26000000,304,5,13.40000000,208,12,13.59000000,15,1,13.60000000,100,1,13.61000000,15,1,13.62000000,100,1,13.63000000,15,1,13.64000000,200,2,13.65000000,15,1,13.66000000,200,2,13.67000000,130,3,ARL,320484661
1473,2025-07-17T15:58:14.659939230Z,2025-07-17T15:58:14.659773896Z,160,2,1108,C,A,0,13.80000000,100,130,165334,267658879,13.55000000,10,1,13.54000000,100,1,13.38000000,33,1,13.37000000,100,1,13.31000000,10,1,13.30000000,100,1,13.29000000,20,2,13.28000000,111,3,13.27000000,120,3,13.26000000,304,5,13.40000000,208,12,13.59000000,15,1,13.60000000,100,1,13.61000000,15,1,13.62000000,100,1,13.63000000,15,1,13.64000000,200,2,13.65000000,15,1,13.66000000,200,2,13.67000000,130,3,ARL,320485389
1474,2025-07-17T15:58:14.660667636Z,2025-07-17T15:58:14.660502341Z,160,2,1108,C,A,0,14.84000000,100,0,165295,267658892,13.55000000,10,1,13.54000000,100,1,13.38000000,33,1,13.37000000,100,1,13.31000000,10,1,13.30000000,100,1,13.29000000,20,2,13.28000000,111,3,13.27000000,120,3,13.26000000,304,5,13.40000000,208,12,13.59000000,15,1,13.60000000,100,1,13.61000000,15,1,13.62000000,100,1,13.63000000,15,1,13.64000000,200,2,13.65000000,15,1,13.66000000,200,2,13.67000000,130,3,ARL,320484709
1475,2025-07-17T15:58:14.660667636Z,2025-07-17T15:58:14.660502341Z,160,2,1108,A,A,0,14.91000000,100,130,165295,267658892,13.55000000,10,1,13.54000000,100,1,13.38000000,33,1,13.37000000,100,1,13.31000000,10,1,13.30000000,100,1,13.29000000,20,2,13.28000000,111,3,13.27000000,120,3,13.26000000,304,5,13.40000000,208,12,13.59000000,15,1,13.60000000,100,1,13.61000000,15,1,13.62000000,100,1,13.63000000,15,1,13.64000000,200,2,13.65000000,15,1,13.66000000,200,2,13.67000000,130,3,ARL,320486925
1476,2025-07-17T15:58:14.664378962Z,2025-07-17T15:58:14.664213722Z,160,2,1108,C,A,0,17.52000000,100,0,165240,267658928,13.55000000,10,1,13.54000000,100,1,13.38000000,33,1,13.37000000,100,1,13.31000000,10,1,13.30000000,100,1,13.29000000,20,2,13.28000000,111,3,13.27000000,120,3,13.26000000,304,5,13.40000000,208,12,13.59000000,15,1,13.60000000,100,1,13.61000000,15,1,13.62000000,100,1,13.63000000,15,1,13.64000000,200,2,13.65000000,15,1,13.66000000,200,2,13.67000000,130,3,ARL,320484837
1477,2025-07-17T15:58:14.664378962Z,2025-07-17T15:58:14.664213722Z,160,2,1108,A,A,0,17.76000000,100,130,165240,267658928,13.55000000,10,1,13.54000000,100,1,13.38000000,33,1,13.37000000,100,1,13.31000000,10,1,13.30000000,100,1,13.29000000,20,2,13.28000000,111,3,13.27000000,120,3,13.26000000,304,5,13.40000000,208,12,13.59000000,15,1,13.60000000,100,1,13.61000000,15,1,13.62000000,100,1,13.63000000,15,1,13.64000000,200,2,13.65000000,15,1,13.66000000,200,2,13.67000000,130,3,ARL,320486937
1478,2025-07-17T15:58:14.664939310Z,2025-07-17T15:58:14.664774078Z,160,2,1108,C,A,0,15.86000000,100,0,165232,267658931,13.55000000,10,1,13.54000000,100,1,13.38000000,33,1,13.37000000,100,1,13.31000000,10,1,13.30000000,100,1,13.29000000,20,2,13.28000000,111,3,13.27000000,120,3,13.26000000,304,5,13.40000000,208,12,13.59000000,15,1,13.60000000,100,1,13.61000000,15,1,13.62000000,100,1,13.63000000,15,1,13.64000000,200,2,13.65000000,15,1,13.66000000,200,2,13.67000000,130,3,ARL,320484817
1479,2025-07-17T15:58:14.664939310Z,2025-07-17T15:58:14.664774078Z,160,2,1108,A,A,0,16.08000000,100,130,165232,267658931,13.55000000,10,1,13.54000000,100,1,13.38000000,33,1,13.37000000,100,1,13.31000000,10,1,13.30000000,100,1,13.29000000,20,2,13.28000000,111,3,13.27000000,120,3,13.26000000,304,5,13.40000000,208,12,13.59000000,15,1,13.60000000,100,1,13.61000000,15,1,13.62000000,100,1,13.63000000,15,1,13.64000000,200,2,13.65000000,15,1,13.66000000,200,2,13.67000000,130,3,ARL,320486945
1480,2025-07-17T15:58:14.672315806Z,2025-07-17T15:58:14.672150755Z,160,2,1108,C,A,0,14.05000000,100,130,165051,267658982,13.55000000,10,1,13.54000000,100,1,13.38000000,33,1,13.37000000,100,1,13.31000000,10,1,13.30000000,100,1,13.29000000,20,2,13.28000000,111,3,13.27000000,120,3,13.26000000,304,5,13.40000000,208,12,13.59000000,15,1,13.60000000,100,1,13.61000000,15,1,13.62000000,100,1,13.63000000,15,1,13.64000000,200,2,13.65000000,15,1,13.66000000,200,2,13.67000000,130,3,ARL,320484985
1481,2025-07-17T15:58:14.672365974Z,2025-07-17T15:58:14.672200872Z,160,2,1108,A,A,0,14.12000000,100,130,165102,267658983,13.55000000,10,1,13.54000000,100,1,13.38000000,33,1,13.37000000,100,1,13.31000000,10,1,13.30000000,100,1,13.29000000,20,2,13.28000000,111,3,13.27000000,120,3,13.26000000,304,5,13.40000000,208,12,13.59000000,15,1,13.60000000,100,1,13.61000000,15,1,13.62000000,100,1,13.63000000,15,1,13.64000000,200,2,13.65000000,15,1,13.66000000,200,2,13.67000000,130,3,ARL,320487017
1482,2025-07-17T15:58:14.673184116Z,2025-07-17T15:58:14.673019194Z,160,2,1108,C,A,0,14.12000000,100,130,164922,267658989,13.55000000,10,1,13.54000000,100,1,13.38000000,33,1,13.37000000,100,1,13.31000000,10,1,13.30000000,100,1,13.29000000,20,2,13.28000000,111,3,13.27000000,120,3,13.26000000,304,5,13.40000000,208,12,13.59000000,15,1,13.60000000,100,1,13.61000000,15,1,13.62000000,100,1,13.63000000,15,1,13.64000000,200,2,13.65000000,15,1,13.66000000,200,2,13.67000000,130,3,ARL,320487017
1483,2025-07-17T15:58:14.673230480Z,2025-07-17T15:58:14.673065320Z,160,2,1108,A,A,0,14.26000000,100,130,165160,267658990,13.55000000,10,1,13.54000000,100,1,13.38000000,33,1,13.37000000,100,1,13.31000000,10,1,13.30000000,100,1,13.29000000,20,2,13.28000000,111,3,13.27000000,120,3,13.26000000,304,5,13.40000000,208,12,13.59000000,15,1,13.60000000,100,1,13.61000000,15,1,13.62000000,100,1,13.63000000,15,1,13.64000000,200,2,13.65000000,15,1,13.66000000,200,2,13.67000000,130,3,ARL,320487025
1484,2025-07-17T15:58:14.682945541Z,2025-07-17T15:58:14.682780396Z,160,2,1108,C,A,0,14.76000000,100,0,165145,267659018,13.55000000,10,1,13.54000000,100,1,13.38000000,33,1,13.37000000,100,1,13.31000000,10,1,13.30000000,100,1,13.29000000,20,2,13.28000000,111,3,13.27000000,120,3,13.26000000,304,5,13.40000000,208,12,13.59000000,15,1,13.60000000,100,1,13.61000000,15,1,13.62000000,100,1,13.63000000,15,1,13.64000000,200,2,13.65000000,15,1,13.66000000,200,2,13.67000000,130,3,ARL,320484821
1485,2025-07-17T15:58:14.682945541Z,2025-07-17T15:58:14.682780396Z,160,2,1108,A,A,0,14.96000000,100,130,165145,267659018,13.55000000,10,1,13.54000000,100,1,13.38000000,33,1,13.37000000,100,1,13.31000000,10,1,13.30000000,100,1,13.29000000,20,2,13.28000000,111,3,13.27000000,120,3,13.26000000,304,5,13.40000000,208,12,13.59000000,15,1,13.60000000,100,1,13.61000000,15,1,13.62000000,100,1,13.63000000,15,1,13.64000000,200,2,13.65000000,15,1,13.66000000,200,2,13.67000000,130,3,ARL,320487105
1486,2025-07-17T15:58:14.710787891Z,2025-07-17T15:58:14.710622495Z,160,2,1108,C,A,0,14.91000000,100,0,165396,267659178,13.55000000,10,1,13.54000000,100,1,13.38000000,33,1,13.37000000,100,1,13.31000000,10,1,13.30000000,100,1,13.29000000,20,2,13.28000000,111,3,13.27000000,120,3,13.26000000,304,5,13.40000000,208,12,13.59000000,15,1,13.60000000,100,1,13.61000000,15,1,13.62000000,100,1,13.63000000,15,1,13.64000000,200,2,13.65000000,15,1,13.66000000,200,2,13.67000000,130,3,ARL,320486925
1487,2025-07-17T15:58:14.710787891Z,2025-07-17T15:58:14.710622495Z,160,2,1108,A,A,0,15.06000000,100,130,165396,267659178,13.55000000,10,1,13.54000000,100,1,13.38000000,33,1,13.37000000,100,1,13.31000000,10,1,13.30000000,100,1,13.29000000,20,2,13.28000000,111,3,13.27000000,120,3,13.26000000,304,5,13.40000000,208,12,13.59000000,15,1,13.60000000,100,1,13.61000000,15,1,13.62000000,100,1,13.63000000,15,1,13.64000000,200,2,13.65000000,15,1,13.66000000,200,2,13.67000000,130,3,ARL,320487357
1488,2025-07-17T15:58:15.564070256Z,2025-07-17T15:58:15.563904700Z,160,2,1108,C,A,0,14.68000000,100,0,165556,267672469,13.55000000,10,1,13.54000000,100,1,13.38000000,33,1,13.37000000,100,1,13.31000000,10,1,13.30000000,100,1,13.29000000,20,2,13.28000000,111,3,13.27000000,120,3,13.26000000,304,5,13.40000000,208,12,13.59000000,15,1,13.60000000,100,1,13.61000000,15,1,13.62000000,100,1,13.63000000,15,1,13.64000000,200,2,13.65000000,15,1,13.66000000,200,2,13.67000000,130,3,ARL,320484781
1489,2025-07-17T15:58:15.564070256Z,2025-07-17T15:58:15.563904700Z,160,2,1108,A,A,0,14.87000000,100,130,165556,267672469,13.55000000,10,1,13.54000000,100,1,13.38000000,33,1,13.37000000,100,1,13.31000000,10,1,13.30000000,100,1,13.29000000,20,2,13.28000000,111,3,13.27000000,120,3,13.26000000,304,5,13.40000000,208,12,13.59000000,15,1,13.60000000,100,1,13.61000000,15,1,13.62000000,100,1,13.63000000,15,1,13.64000000,200,2,13.65000000,15,1,13.66000000,200,2,13.67000000,130,3,ARL,320504473
1490,2025-07-17T15:58:15.577719796Z,2025-07-17T15:58:15.577554368Z,160,2,1108,C,A,0,14.69000000,100,0,165428,267672549,13.55000000,10,1,13.54000000,100,1,13.38000000,33,1,13.37000000,100,1,13.31000000,10,1,13.30000000,100,1,13.29000000,20,2,13.28000000,111,3,13.27000000,120,3,13.26000000,304,5,13.40000000,208,12,13.59000000,15,1,13.60000000,100,1,13.61000000,15,1,13.62000000,100,1,13.63000000,15,1,13.64000000,200,2,13.65000000,15,1,13.66000000,200,2,13.67000000,130,3,ARL,320484825
1491,2025-07-17T15:58:15.577719796Z,2025-07-17T15:58:15.577554368Z,160,2,1108,A,A,0,14.88000000,100,130,165428,267672549,13.55000000,10,1,13.54000000,100,1,13.38000000,33,1,13.37000000,100,1,13.31000000,10,1,13.30000000,100,1,13.29000000,20,2,13.28000000,111,3,13.27000000,120,3,13.26000000,304,5,13.40000000,208,12,13.59000000,15,1,13.60000000,100,1,13.61000000,15,1,13.62000000,100,1,13.63000000,15,1,13.64000000,200,2,13.65000000,15,1,13.66000000,200,2,13.67000000,130,3,ARL,320504609
1492,2025-07-17T15:58:16.502080515Z,2025-07-17T15:58:16.501915292Z,160,2,1108,A,A,0,14.11000000,100,130,165223,267685252,13.55000000,10,1,13.54000000,100,1,13.38000000,33,1,13.37000000,100,1,13.31000000,10,1,13.30000000,100,1,13.29000000,20,2,13.28000000,111,3,13.27000000,120,3,13.26000000,304,5,13.40000000,208,12,13.59000000,15,1,13.60000000,100,1,13.61000000,15,1,13.62000000,100,1,13.63000000,15,1,13.64000000,200,2,13.65000000,15,1,13.66000000,200,2,13.67000000,130,3,ARL,320519893
1493,2025-07-17T15:58:19.965200980Z,2025-07-17T15:58:19.965034325Z,160,2,1108,A,A,0,13.94000000,15,130,166655,267738403,13.55000000,10,1,13.54000000,100,1,13.38000000,33,1,13.37000000,100,1,13.31000000,10,1,13.30000000,100,1,13.29000000,20,2,13.28000000,111,3,13.27000000,120,3,13.26000000,304,5,13.40000000,208,12,13.59000000,15,1,13.60000000,100,1,13.61000000,15,1,13.62000000,100,1,13.63000000,15,1,13.64000000,200,2,13.65000000,15,1,13.66000000,200,2,13.67000000,130,3,ARL,320588689
1494,2025-07-17T15:58:20.237833402Z,2025-07-17T15:58:20.237668047Z,160,2,1108,C,A,0,14.11000000,100,0,165355,267745213,13.55000000,10,1,13.54000000,100,1,13.38000000,33,1,13.37000000,100,1,13.31000000,10,1,13.30000000,100,1,13.29000000,20,2,13.28000000,111,3,13.27000000,120,3,13.26000000,304,5,13.40000000,208,12,13.59000000,15,1,13.60000000,100,1,13.61000000,15,1,13.62000000,100,1,13.63000000,15,1,13.64000000,200,2,13.65000000,15,1,13.66000000,200,2,13.67000000,130,3,ARL,320519893
1495,2025-07-17T15:58:20.237833402Z,2025-07-17T15:58:20.237668047Z,160,2,1108,A,A,0,13.95000000,100,130,165355,267745213,13.55000000,10,1,13.54000000,100,1,13.38000000,33,1,13.37000000,100,1,13.31000000,10,1,13.30000000,100,1,13.29000000,20,2,13.28000000,111,3,13.27000000,120,3,13.26000000,304,5,13.40000000,208,12,13.59000000,15,1,13.60000000,100,1,13.61000000,15,1,13.62000000,100,1,13.63000000,15,1,13.64000000,200,2,13.65000000,15,1,13.66000000,200,2,13.67000000,130,3,ARL,320595817
1496,2025-07-17T15:58:20.705512171Z,2025-07-17T15:58:20.705344578Z,160,2,1108,C,A,0,13.94000000,15,128,167593,267754327,13.55000000,10,1,13.54000000,100,1,13.38000000,33,1,13.37000000,100,1,13.31000000,10,1,13.30000000,100,1,13.29000000,20,2,13.28000000,111,3,13.27000000,120,3,13.26000000,304,5,13.40000000,208,12,13.59000000,15,1,13.60000000,100,1,13.61000000,15,1,13.62000000,100,1,13.63000000,15,1,13.64000000,200,2,13.65000000,15,1,13.66000000,200,2,13.67000000,130,3,ARL,320588689
1497,2025-07-17T15:58:30.800053062Z,2025-07-17T15:58:30.799887713Z,160,2,1108,A,A,0,13.89000000,15,130,165349,267913947,13.55000000,10,1,13.54000000,100,1,13.38000000,33,1,13.37000000,100,1,13.31000000,10,1,13.30000000,100,1,13.29000000,20,2,13.28000000,111,3,13.27000000,120,3,13.26000000,304,5,13.40000000,208,12,13.59000000,15,1,13.60000000,100,1,13.61000000,15,1,13.62000000,100,1,13.63000000,15,1,13.64000000,200,2,13.65000000,15,1,13.66000000,200,2,13.67000000,130,3,ARL,320833897
1498,2025-07-17T15:58:30.905657319Z,2025-07-17T15:58:30.905491759Z,160,2,1108,C,A,0,13.95000000,100,0,165560,267919515,13.55000000,10,1,13.54000000,100,1,13.38000000,33,1,13.37000000,100,1,13.31000000,10,1,13.30000000,100,1,13.29000000,20,2,13.28000000,111,3,13.27000000,120,3,13.26000000,304,5,13.40000000,208,12,13.59000000,15,1,13.60000000,100,1,13.61000000,15,1,13.62000000,100,1,13.63000000,15,1,13.64000000,200,2,13.65000000,15,1,13.66000000,200,2,13.67000000,130,3,ARL,320595817
1499,2025-07-17T15:58:30.905657319Z,2025-07-17T15:58:30.905491759Z,160,2,1108,A,A,0,13.90000000,100,130,165560,267919515,13.55000000,10,1,13.54000000,100,1,13.38000000,33,1,13.37000000,100,1,13.31000000,10,1,13.30000000,100,1,13.29000000,20,2,13.28000000,111,3,13.27000000,120,3,13.26000000,304,5,13.40000000,208,12,13.59000000,15,1,13.60000000,100,1,13.61000000,15,1,13.62000000,100,1,13.63000000,15,1,13.64000000,200,2,13.65000000,15,1,13.66000000,200,2,13.67000000,130,3,ARL,320839125
1500,2025-07-17T15:58:30.906412286Z,2025-07-17T15:58:30.906246950Z,160,2,1108,C,A,0,15.06000000,100,0,165336,267919540,13.55000000,10,1,13.54000000,100,1,13.38000000,33,1,13.37000000,100,1,13.31000000,10,1,13.30000000,100,1,13.29000000,20,2,13.28000000,111,3,13.27000000,120,3,13.26000000,304,5,13.40000000,208,12,13.59000000,15,1,13.60000000,100,1,13.61000000,15,1,13.62000000,100,1,13.63000000,15,1,13.64000000,200,2,13.65000000,15,1,13.66000000,200,2,13.67000000,130,3,ARL,320487357
1501,2025-07-17T15:58:30.906412286Z,2025-07-17T15:58:30.906246950Z,160,2,1108,A,A,0,14.98000000,100,130,165336,267919540,13.55000000,10,1,13.54000000,100,1,13.38000000,33,1,13.37000000,100,1,13.31000000,10,1,13.30000000,100,1,13.29000000,20,2,13.28000000,111,3,13.27000000,120,3,13.26000000,304,5,13.40000000,208,12,13.59000000,15,1,13.60000000,100,1,13.61000000,15,1,13.62000000,100,1,13.63000000,15,1,13.64000000,200,2,13.65000000,15,1,13.66000000,200,2,13.67000000,130,3,ARL,320839149
1502,2025-07-17T15:58:30.916726353Z,2025-07-17T15:58:30.916561264Z,160,2,1108,C,A,0,14.26000000,100,130,165089,267919917,13.55000000,10,1,13.54000000,100,1,13.38000000,33,1,13.37000000,100,1,13.31000000,10,1,13.30000000,100,1,13.29000000,20,2,13.28000000,111,3,13.27000000,120,3,13.26000000,304,5,13.40000000,208,12,13.59000000,15,1,13.60000000,100,1,13.61000000,15,1,13.62000000,100,1,13.63000000,15,1,13.64000000,200,2,13.65000000,15,1,13.66000000,200,2,13.67000000,130,3,ARL,320487025
1503,2025-07-17T15:58:30.916784278Z,2025-07-17T15:58:30.916619122Z,160,2,1108,A,A,0,14.18000000,100,130,165156,267919919,13.55000000,10,1,13.54000000,100,1,13.38000000,33,1,13.37000000,100,1,13.31000000,10,1,13.30000000,100,1,13.29000000,20,2,13.28000000,111,3,13.27000000,120,3,13.26000000,304,5,13.40000000,208,12,13.59000000,15,1,13.60000000,100,1,13.61000000,15,1,13.62000000,100,1,13.63000000,15,1,13.64000000,200,2,13.65000000,15,1,13.66000000,200,2,13.67000000,130,3,ARL,320839577
1504,2025-07-17T15:58:31.124388717Z,2025-07-17T15:58:31.124222733Z,160,2,1108,C,A,0,14.87000000,100,0,165984,267925564,13.55000000,10,1,13.54000000,100,1,13.38000000,33,1,13.37000000,100,1,13.31000000,10,1,13.30000000,100,1,13.29000000,20,2,13.28000000,111,3,13.27000000,120,3,13.26000000,304,5,13.40000000,208,12,13.59000000,15,1,13.60000000,100,1,13.61000000,15,1,13.62000000,100,1,13.63000000,15,1,13.64000000,200,2,13.65000000,15,1,13.66000000,200,2,13.67000000,130,3,ARL,320504473
1505,2025-07-17T15:58:31.124388717Z,2025-07-17T15:58:31.124222733Z,160,2,1108,A,A,0,14.76000000,100,130,165984,267925564,13.55000000,10,1,13.54000000,100,1,13.38000000,33,1,13.37000000,100,1,13.31000000,10,1,13.30000000,100,1,13.29000000,20,2,13.28000000,111,3,13.27000000,120,3,13.26000000,304,5,13.40000000,208,12,13.59000000,15,1,13.60000000,100,1,13.61000000,15,1,13.62000000,100,1,13.63000000,15,1,13.64000000,200,2,13.65000000,15,1,13.66000000,200,2,13.67000000,130,3,ARL,320845893
1506,2025-07-17T15:58:31.136439248Z,2025-07-17T15:58:31.136273403Z,160,2,1108,C,A,0,14.88000000,100,0,165845,267925951,13.55000000,10,1,13.54000000,100,1,13.38000000,33,1,13.37000000,100,1,13.31000000,10,1,13.30000000,100,1,13.29000000,20,2,13.28000000,111,3,13.27000000,120,3,13.26000000,304,5,13.40000000,208,12,13.59000000,15,1,13.60000000,100,1,13.61000000,15,1,13.62000000,100,1,13.63000000,15,1,13.64000000,200,2,13.65000000,15,1,13.66000000,200,2,13.67000000,130,3,ARL,320504609
1507,2025-07-17T15:58:31.136439248Z,2025-07-17T15:58:31.136273403Z,160,2,1108,A,A,0,14.77000000,100,130,165845,267925951,13.55000000,10,1,13.54000000,100,1,13.38000000,33,1,13.37000000,100,1,13.31000000,10,1,13.30000000,100,1,13.29000000,20,2,13.28000000,111,3,13.27000000,120,3,13.26000000,304,5,13.40000000,208,12,13.59000000,15,1,13.60000000,100,1,13.61000000,15,1,13.62000000,100,1,13.63000000,15,1,13.64000000,200,2,13.65000000,15,1,13.66000000,200,2,13.67000000,130,3,ARL,320846429
1508,2025-07-17T15:58:40.799952243Z,2025-07-17T15:58:40.799787018Z,160,2,1108,A,A,0,13.83000000,15,130,165225,268074431,13.55000000,10,1,13.54000000,100,1,13.38000000,33,1,13.37000000,100,1,13.31000000,10,1,13.30000000,100,1,13.29000000,20,2,13.28000000,111,3,13.27000000,120,3,13.26000000,304,5,13.40000000,208,12,13.59000000,15,1,13.60000000,100,1,13.61000000,15,1,13.62000000,100,1,13.63000000,15,1,13.64000000,200,2,13.65000000,15,1,13.66000000,200,2,13.67000000,130,3,ARL,321038033
1509,2025-07-17T15:58:43.690244473Z,2025-07-17T15:58:43.690078924Z,160,2,1108,C,A,0,13.90000000,100,0,165549,268115228,13.55000000,10,1,13.54000000,100,1,13.38000000,33,1,13.37000000,100,1,13.31000000,10,1,13.30000000,100,1,13.29000000,20,2,13.28000000,111,3,13.27000000,120,3,13.26000000,304,5,13.40000000,208,12,13.59000000,15,1,13.60000000,100,1,13.61000000,15,1,13.62000000,100,1,13.63000000,15,1,13.64000000,200,2,13.65000000,15,1,13.66000000,200,2,13.67000000,130,3,ARL,320839125
1510,2025-07-17T15:58:43.690244473Z,2025-07-17T15:58:43.690078924Z,160,2,1108,A,A,0,13.84000000,100,130,165549,268115228,13.55000000,10,1,13.54000000,100,1,13.38000000,33,1,13.37000000,100,1,13.31000000,10,1,13.30000000,100,1,13.29000000,20,2,13.28000000,111,3,13.27000000,120,3,13.26000000,304,5,13.40000000,208,12,13.59000000,15,1,13.60000000,100,1,13.61000000,15,1,13.62000000,100,1,13.63000000,15,1,13.64000000,200,2,13.65000000,15,1,13.66000000,200,2,13.67000000,130,3,ARL,321096769
1511,2025-07-17T15:58:43.690988921Z,2025-07-17T15:58:43.690823184Z,160,2,1108,C,A,0,14.98000000,100,0,165737,268115235,13.55000000,10,1,13.54000000,100,1,13.38000000,33,1,13.37000000,100,1,13.31000000,10,1,13.30000000,100,1,13.29000000,20,2,13.28000000,111,3,13.27000000,120,3,13.26000000,304,5,13.40000000,208,12,13.59000000,15,1,13.60000000,100,1,13.61000000,15,1,13.62000000,100,1,13.63000000,15,1,13.64000000,200,2,13.65000000,15,1,13.66000000,200,2,13.67000000,130,3,ARL,320839149
1512,2025-07-17T15:58:43.690988921Z,2025-07-17T15:58:43.690823184Z,160,2,1108,A,A,0,14.91000000,100,130,165737,268115235,13.55000000,10,1,13.54000000,100,1,13.38000000,33,1,13.37000000,100,1,13.31000000,10,1,13.30000000,100,1,13.29000000,20,2,13.28000000,111,3,13.27000000,120,3,13.26000000,304,5,13.40000000,208,12,13.59000000,15,1,13.60000000,100,1,13.61000000,15,1,13.62000000,100,1,13.63000000,15,1,13.64000000,200,2,13.65000000,15,1,13.66000000,200,2,13.67000000,130,3,ARL,321096793
1513,2025-07-17T15:58:43.693394500Z,2025-07-17T15:58:43.693228946Z,160,2,1108,C,A,0,17.76000000,100,0,165554,268115265,13.55000000,10,1,13.54000000,100,1,13.38000000,33,1,13.37000000,100,1,13.31000000,10,1,13.30000000,100,1,13.29000000,20,2,13.28000000,111,3,13.27000000,120,3,13.26000000,304,5,13.40000000,208,12,13.59000000,15,1,13.60000000,100,1,13.61000000,15,1,13.62000000,100,1,13.63000000,15,1,13.64000000,200,2,13.65000000,15,1,13.66000000,200,2,13.67000000,130,3,ARL,320486937
1514,2025-07-17T15:58:43.693394500Z,2025-07-17T15:58:43.693228946Z,160,2,1108,A,A,0,17.58000000,100,130,165554,268115265,13.55000000,10,1,13.54000000,100,1,13.38000000,33,1,13.37000000,100,1,13.31000000,10,1,13.30000000,100,1,13.29000000,20,2,13.28000000,111,3,13.27000000,120,3,13.26000000,304,5,13.40000000,208,12,13.59000000,15,1,13.60000000,100,1,13.61000000,15,1,13.62000000,100,1,13.63000000,15,1,13.64000000,200,2,13.65000000,15,1,13.66000000,200,2,13.67000000,130,3,ARL,321096825
1515,2025-07-17T15:58:43.695055785Z,2025-07-17T15:58:43.694890264Z,160,2,1108,C,A,0,16.08000000,100,0,165521,268115287,13.55000000,10,1,13.54000000,100,1,13.38000000,33,1,13.37000000,100,1,13.31000000,10,1,13.30000000,100,1,13.29000000,20,2,13.28000000,111,3,13.27000000,120,3,13.26000000,304,5,13.40000000,208,12,13.59000000,15,1,13.60000000,100,1,13.61000000,15,1,13.62000000,100,1,13.63000000,15,1,13.64000000,200,2,13.65000000,15,1,13.66000000,200,2,13.67000000,130,3,ARL,320486945
1516,2025-07-17T15:58:43.695055785Z,2025-07-17T15:58:43.694890264Z,160,2,1108,A,A,0,15.92000000,100,130,165521,268115287,13.55000000,10,1,13.54000000,100,1,13.38000000,33,1,13.37000000,100,1,13.31000000,10,1,13.30000000,100,1,13.29000000,20,2,13.28000000,111,3,13.27000000,120,3,13.26000000,304,5,13.40000000,208,12,13.59000000,15,1,13.60000000,100,1,13.61000000,15,1,13.62000000,100,1,13.63000000,15,1,13.64000000,200,2,13.65000000,15,1,13.66000000,200,2,13.67000000,130,3,ARL,321096889
1517,2025-07-17T15:58:43.716437124Z,2025-07-17T15:58:43.716271172Z,160,2,1108,C,A,0,14.96000000,100,0,165952,268115456,13.55000000,10,1,13.54000000,100,1,13.38000000,33,1,13.37000000,100,1,13.31000000,10,1,13.30000000,100,1,13.29000000,20,2,13.28000000,111,3,13.27000000,120,3,13.26000000,304,5,13.40000000,208,12,13.59000000,15,1,13.60000000,100,1,13.61000000,15,1,13.62000000,100,1,13.63000000,15,1,13.64000000,200,2,13.65000000,15,1,13.66000000,200,2,13.67000000,130,3,ARL,320487105
1518,2025-07-17T15:58:43.716437124Z,2025-07-17T15:58:43.716271172Z,160,2,1108,A,A,0,14.81000000,100,130,165952,268115456,13.55000000,10,1,13.54000000,100,1,13.38000000,33,1,13.37000000,100,1,13.31000000,10,1,13.30000000,100,1,13.29000000,20,2,13.28000000,111,3,13.27000000,120,3,13.26000000,304,5,13.40000000,208,12,13.59000000,15,1,13.60000000,100,1,13.61000000,15,1,13.62000000,100,1,13.63000000,15,1,13.64000000,200,2,13.65000000,15,1,13.66000000,200,2,13.67000000,130,3,ARL,321097197
1519,2025-07-17T15:58:44.903740109Z,2025-07-17T15:58:44.903574654Z,160,2,1108,A,A,0,13.83000000,100,130,165455,268129040,13.55000000,10,1,13.54000000,100,1,13.38000000,33,1,13.37000000,100,1,13.31000000,10,1,13.30000000,100,1,13.29000000,20,2,13.28000000,111,3,13.27000000,120,3,13.26000000,304,5,13.40000000,208,12,13.59000000,15,1,13.60000000,100,1,13.61000000,15,1,13.62000000,100,1,13.63000000,15,1,13.64000000,200,2,13.65000000,15,1,13.66000000,200,2,13.67000000,130,3,ARL,321114473
1520,2025-07-17T15:58:44.924114268Z,2025-07-17T15:58:44.923948853Z,160,2,1108,C,A,0,14.18000000,100,130,165415,268129217,13.55000000,10,1,13.54000000,100,1,13.38000000,33,1,13.37000000,100,1,13.31000000,10,1,13.30000000,100,1,13.29000000,20,2,13.28000000,111,3,13.27000000,120,3,13.26000000,304,5,13.40000000,208,12,13.59000000,15,1,13.60000000,100,1,13.61000000,15,1,13.62000000,100,1,13.63000000,15,1,13.64000000,200,2,13.65000000,15,1,13.66000000,200,2,13.67000000,130,3,ARL,320839577
1521,2025-07-17T15:58:44.924165875Z,2025-07-17T15:58:44.924000519Z,160,2,1108,A,A,0,14.11000000,100,130,165356,268129218,13.55000000,10,1,13.54000000,100,1,13.38000000,33,1,13.37000000,100,1,13.31000000,10,1,13.30000000,100,1,13.29000000,20,2,13.28000000,111,3,13.27000000,120,3,13.26000000,304,5,13.40000000,208,12,13.59000000,15,1,13.60000000,100,1,13.61000000,15,1,13.62000000,100,1,13.63000000,15,1,13.64000000,200,2,13.65000000,15,1,13.66000000,200,2,13.67000000,130,3,ARL,321114729
1522,2025-07-17T15:58:51.241342265Z,2025-07-17T15:58:51.241176997Z,160,2,1108,C,A,0,13.89000000,15,130,165268,268212338,13.55000000,10,1,13.54000000,100,1,13.38000000,33,1,13.37000000,100,1,13.31000000,10,1,13.30000000,100,1,13.29000000,20,2,13.28000000,111,3,13.27000000,120,3,13.26000000,304,5,13.40000000,208,12,13.59000000,15,1,13.60000000,100,1,13.61000000,15,1,13.62000000,100,1,13.63000000,15,1,13.64000000,200,2,13.65000000,15,1,13.66000000,200,2,13.67000000,130,3,ARL,320833897
1523,2025-07-17T15:58:51.254127339Z,2025-07-17T15:58:51.253961905Z,160,2,1108,A,A,0,13.80000000,100,130,165434,268212497,13.55000000,10,1,13.54000000,100,1,13.38000000,33,1,13.37000000,100,1,13.31000000,10,1,13.30000000,100,1,13.29000000,20,2,13.28000000,111,3,13.27000000,120,3,13.26000000,304,5,13.40000000,208,12,13.59000000,15,1,13.60000000,100,1,13.61000000,15,1,13.62000000,100,1,13.63000000,15,1,13.64000000,200,2,13.65000000,15,1,13.66000000,200,2,13.67000000,130,3,ARL,321225725
1524,2025-07-17T15:58:51.254871890Z,2025-07-17T15:58:51.254706004Z,160,2,1108,C,A,0,14.91000000,100,0,165886,268212499,13.55000000,10,1,13.54000000,100,1,13.38000000,33,1,13.37000000,100,1,13.31000000,10,1,13.30000000,100,1,13.29000000,20,2,13.28000000,111,3,13.27000000,120,3,13.26000000,304,5,13.40000000,208,12,13.59000000,15,1,13.60000000,100,1,13.61000000,15,1,13.62000000,100,1,13.63000000,15,1,13.64000000,200,2,13.65000000,15,1,13.66000000,200,2,13.67000000,130,3,ARL,321096793
1525,2025-07-17T15:58:51.254871890Z,2025-07-17T15:58:51.254706004Z,160,2,1108,A,A,0,14.87000000,100,130,165886,268212499,13.55000000,10,1,13.54000000,100,1,13.38000000,33,1,13.37000000,100,1,13.31000000,10,1,13.30000000,100,1,13.29000000,20,2,13.28000000,111,3,13.27000000,120,3,13.26000000,304,5,13.40000000,208,12,13.59000000,15,1,13.60000000,100,1,13.61000000,15,1,13.62000000,100,1,13.63000000,15,1,13.64000000,200,2,13.65000000,15,1,13.66000000,200,2,13.67000000,130,3,ARL,321225745
1526,2025-07-17T15:58:51.260753179Z,2025-07-17T15:58:51.260587778Z,160,2,1108,C,A,0,13.83000000,100,130,165401,268212534,13.55000000,10,1,13.54000000,100,1,13.38000000,33,1,13.37000000,100,1,13.31000000,10,1,13.30000000,100,1,13.29000000,20,2,13.28000000,111,3,13.27000000,120,3,13.26000000,304,5,13.40000000,208,12,13.59000000,15,1,13.60000000,100,1,13.61000000,15,1,13.62000000,100,1,13.63000000,15,1,13.64000000,200,2,13.65000000,15,1,13.66000000,200,2,13.67000000,130,3,ARL,321114473
1527,2025-07-17T15:58:53.579628288Z,2025-07-17T15:58:53.579462029Z,160,2,1108,C,A,0,13.83000000,15,130,166259,268250290,13.55000000,10,1,13.54000000,100,1,13.38000000,33,1,13.37000000,100,1,13.31000000,10,1,13.30000000,100,1,13.29000000,20,2,13.28000000,111,3,13.27000000,120,3,13.26000000,304,5,13.40000000,208,12,13.59000000,15,1,13.60000000,100,1,13.61000000,15,1,13.62000000,100,1,13.63000000,15,1,13.64000000,200,2,13.65000000,15,1,13.66000000,200,2,13.67000000,130,3,ARL,321038033
1528,2025-07-17T15:58:53.580217445Z,2025-07-17T15:58:53.580052014Z,160,2,1108,C,A,0,13.84000000,100,0,165431,268250346,13.55000000,10,1,13.54000000,100,1,13.38000000,33,1,13.37000000,100,1,13.31000000,10,1,13.30000000,100,1,13.29000000,20,2,13.28000000,111,3,13.27000000,120,3,13.26000000,304,5,13.40000000,208,12,13.59000000,15,1,13.60000000,100,1,13.61000000,15,1,13.62000000,100,1,13.63000000,15,1,13.64000000,200,2,13.65000000,15,1,13.66000000,200,2,13.67000000,130,3,ARL,321096769
1529,2025-07-17T15:58:53.580217445Z,2025-07-17T15:58:53.580052014Z,160,2,1108,A,A,0,13.81000000,100,130,165431,268250346,13.55000000,10,1,13.54000000,100,1,13.38000000,33,1,13.37000000,100,1,13.31000000,10,1,13.30000000,100,1,13.29000000,20,2,13.28000000,111,3,13.27000000,120,3,13.26000000,304,5,13.40000000,208,12,13.59000000,15,1,13.60000000,100,1,13.61000000,15,1,13.62000000,100,1,13.63000000,15,1,13.64000000,200,2,13.65000000,15,1,13.66000000,200,2,13.67000000,130,3,ARL,321272581
1530,2025-07-17T15:58:54.584124215Z,2025-07-17T15:58:54.583958582Z,160,2,1108,C,A,0,14.77000000,100,0,165633,268265585,13.55000000,10,1,13.54000000,100,1,13.38000000,33,1,13.37000000,100,1,13.31000000,10,1,13.30000000,100,1,13.29000000,20,2,13.28000000,111,3,13.27000000,120,3,13.26000000,304,5,13.40000000,208,12,13.59000000,15,1,13.60000000,100,1,13.61000000,15,1,13.62000000,100,1,13.63000000,15,1,13.64000000,200,2,13.65000000,15,1,13.66000000,200,2,13.67000000,130,3,ARL,320846429
1531,2025-07-17T15:58:54.584124215Z,2025-07-17T15:58:54.583958582Z,160,2,1108,A,A,0,14.65000000,100,130,165633,268265585,13.55000000,10,1,13.54000000,100,1,13.38000000,33,1,13.37000000,100,1,13.31000000,10,1,13.30000000,100,1,13.29000000,20,2,13.28000000,111,3,13.27000000,120,3,13.26000000,304,5,13.40000000,208,12,13.59000000,15,1,13.60000000,100,1,13.61000000,15,1,13.62000000,100,1,13.63000000,15,1,13.64000000,200,2,13.65000000,15,1,13.66000000,200,2,13.67000000,130,3,ARL,321293737
1532,2025-07-17T15:58:54.584260712Z,2025-07-17T15:58:54.584094980Z,160,2,1108,C,A,0,14.76000000,100,0,165732,268265586,13.55000000,10,1,13.54000000,100,1,13.38000000,33,1,13.37000000,100,1,13.31000000,10,1,13.30000000,100,1,13.29000000,20,2,13.28000000,111,3,13.27000000,120,3,13.26000000,304,5,13.40000000,208,12,13.59000000,15,1,13.60000000,100,1,13.61000000,15,1,13.62000000,100,1,13.63000000,15,1,13.64000000,200,2,13.65000000,15,1,13.66000000,200,2,13.67000000,130,3,ARL,320845893
1533,2025-07-17T15:58:54.584260712Z,2025-07-17T15:58:54.584094980Z,160,2,1108,A,A,0,14.64000000,100,130,165732,268265586,13.55000000,10,1,13.54000000,100,1,13.38000000,33,1,13.37000000,100,1,13.31000000,10,1,13.30000000,100,1,13.29000000,20,2,13.28000000,111,3,13.27000000,120,3,13.26000000,304,5,13.40000000,208,12,13.59000000,15,1,13.60000000,100,1,13.61000000,15,1,13.62000000,100,1,13.63000000,15,1,13.64000000,200,2,13.65000000,15,1,13.66000000,200,2,13.67000000,130,3,ARL,321293741
1534,2025-07-17T15:58:55.305104029Z,2025-07-17T15:58:55.304938318Z,160,2,1108,A,A,0,13.78000000,100,130,165711,268277940,13.55000000,10,1,13.54000000,100,1,13.38000000,33,1,13.37000000,100,1,13.31000000,10,1,13.30000000,100,1,13.29000000,20,2,13.28000000,111,3,13.27000000,120,3,13.26000000,304,5,13.40000000,208,12,13.59000000,15,1,13.60000000,100,1,13.61000000,15,1,13.62000000,100,1,13.63000000,15,1,13.64000000,200,2,13.65000000,15,1,13.66000000,200,2,13.67000000,130,3,ARL,321309865
1535,2025-07-17T15:58:55.307508305Z,2025-07-17T15:58:55.307342971Z,160,2,1108,C,A,0,14.72000000,100,130,165334,268277999,13.55000000,10,1,13.54000000,100,1,13.38000000,33,1,13.37000000,100,1,13.31000000,10,1,13.30000000,100,1,13.29000000,20,2,13.28000000,111,3,13.27000000,120,3,13.26000000,304,5,13.40000000,208,12,13.59000000,15,1,13.60000000,100,1,13.61000000,15,1,13.62000000,100,1,13.63000000,15,1,13.64000000,200,2,13.65000000,15,1,13.66000000,200,2,13.67000000,130,3,ARL,312772061
1536,2025-07-17T15:58:55.307637209Z,2025-07-17T15:58:55.307472032Z,160,2,1108,A,A,0,14.58000000,100,130,165177,268278004,13.55000000,10,1,13.54000000,100,1,13.38000000,33,1,13.37000000,100,1,13.31000000,10,1,13.30000000,100,1,13.29000000,20,2,13.28000000,111,3,13.27000000,120,3,13.26000000,304,5,13.40000000,208,12,13.59000000,15,1,13.60000000,100,1,13.61000000,15,1,13.62000000,100,1,13.63000000,15,1,13.64000000,200,2,13.65000000,15,1,13.66000000,200,2,13.67000000,130,3,ARL,321309941
1537,2025-07-17T15:58:55.311899965Z,2025-07-17T15:58:55.311734700Z,160,2,1108,C,A,0,13.80000000,100,130,165265,268278030,13.55000000,10,1,13.54000000,100,1,13.38000000,33,1,13.37000000,100,1,13.31000000,10,1,13.30000000,100,1,13.29000000,20,2,13.28000000,111,3,13.27000000,120,3,13.26000000,304,5,13.40000000,208,12,13.59000000,15,1,13.60000000,100,1,13.61000000,15,1,13.62000000,100,1,13.63000000,15,1,13.64000000,200,2,13.65000000,15,1,13.66000000,200,2,13.67000000,130,3,ARL,321225725
1538,2025-07-17T15:58:58.668252306Z,2025-07-17T15:58:58.668086788Z,160,2,1108,C,A,0,13.81000000,100,0,165518,268321684,13.55000000,10,1,13.54000000,100,1,13.38000000,33,1,13.37000000,100,1,13.31000000,10,1,13.30000000,100,1,13.29000000,20,2,13.28000000,111,3,13.27000000,120,3,13.26000000,304,5,13.40000000,208,12,13.59000000,15,1,13.60000000,100,1,13.61000000,15,1,13.62000000,100,1,13.63000000,15,1,13.64000000,200,2,13.65000000,15,1,13.66000000,200,2,13.67000000,130,3,ARL,321272581
1539,2025-07-17T15:58:58.668252306Z,2025-07-17T15:58:58.668086788Z,160,2,1108,A,A,0,13.79000000,100,130,165518,268321684,13.55000000,10,1,13.54000000,100,1,13.38000000,33,1,13.37000000,100,1,13.31000000,10,1,13.30000000,100,1,13.29000000,20,2,13.28000000,111,3,13.27000000,120,3,13.26000000,304,5,13.40000000,208,12,13.59000000,15,1,13.60000000,100,1,13.61000000,15,1,13.62000000,100,1,13.63000000,15,1,13.64000000,200,2,13.65000000,15,1,13.66000000,200,2,13.67000000,130,3,ARL,321364281
1540,2025-07-17T15:59:03.613692913Z,2025-07-17T15:59:03.613527621Z,160,2,1108,A,A,0,13.72000000,15,130,165292,268437919,13.55000000,10,1,13.54000000,100,1,13.38000000,33,1,13.37000000,100,1,13.31000000,10,1,13.30000000,100,1,13.29000000,20,2,13.28000000,111,3,13.27000000,120,3,13.26000000,304,5,13.40000000,208,12,13.59000000,15,1,13.60000000,100,1,13.61000000,15,1,13.62000000,100,1,13.63000000,15,1,13.64000000,200,2,13.65000000,15,1,13.66000000,200,2,13.67000000,130,3,ARL,321500117
1541,2025-07-17T15:59:03.626346616Z,2025-07-17T15:59:03.626181384Z,160,2,1108,A,A,0,13.76000000,100,130,165232,268438110,13.55000000,10,1,13.54000000,100,1,13.38000000,33,1,13.37000000,100,1,13.31000000,10,1,13.30000000,100,1,13.29000000,20,2,13.28000000,111,3,13.27000000,120,3,13.26000000,304,5,13.40000000,208,12,13.59000000,15,1,13.60000000,100,1,13.61000000,15,1,13.62000000,100,1,13.63000000,15,1,13.64000000,200,2,13.65000000,15,1,13.66000000,200,2,13.67000000,130,3,ARL,321500317
1542,2025-07-17T15:59:03.627086888Z,2025-07-17T15:59:03.626920954Z,160,2,1108,C,A,0,14.87000000,100,0,165934,268438112,13.55000000,10,1,13.54000000,100,1,13.38000000,33,1,13.37000000,100,1,13.31000000,10,1,13.30000000,100,1,13.29000000,20,2,13.28000000,111,3,13.27000000,120,3,13.26000000,304,5,13.40000000,208,12,13.59000000,15,1,13.60000000,100,1,13.61000000,15,1,13.62000000,100,1,13.63000000,15,1,13.64000000,200,2,13.65000000,15,1,13.66000000,200,2,13.67000000,130,3,ARL,321225745
1543,2025-07-17T15:59:03.627086888Z,2025-07-17T15:59:03.626920954Z,160,2,1108,A,A,0,14.83000000,100,130,165934,268438112,13.55000000,10,1,13.54000000,100,1,13.38000000,33,1,13.37000000,100,1,13.31000000,10,1,13.30000000,100,1,13.29000000,20,2,13.28000000,111,3,13.27000000,120,3,13.26000000,304,5,13.40000000,208,12,13.59000000,15,1,13.60000000,100,1,13.61000000,15,1,13.62000000,100,1,13.63000000,15,1,13.64000000,200,2,13.65000000,15,1,13.66000000,200,2,13.67000000,130,3,ARL,321500333
1544,2025-07-17T15:59:03.628945278Z,2025-07-17T15:59:03.628779364Z,160,2,1108,C,A,0,14.89000000,100,0,165914,268438129,13.55000000,10,1,13.54000000,100,1,13.38000000,33,1,13.37000000,100,1,13.31000000,10,1,13.30000000,100,1,13.29000000,20,2,13.28000000,111,3,13.27000000,120,3,13.26000000,304,5,13.40000000,208,12,13.59000000,15,1,13.60000000,100,1,13.61000000,15,1,13.62000000,100,1,13.63000000,15,1,13.64000000,200,2,13.65000000,15,1,13.66000000,200,2,13.67000000,130,3,ARL,312771785
1545,2025-07-17T15:59:03.628945278Z,2025-07-17T15:59:03.628779364Z,160,2,1108,A,A,0,14.73000000,100,130,165914,268438129,13.55000000,10,1,13.54000000,100,1,13.38000000,33,1,13.37000000,100,1,13.31000000,10,1,13.30000000,100,1,13.29000000,20,2,13.28000000,111,3,13.27000000,120,3,13.26000000,304,5,13.40000000,208,12,13.59000000,15,1,13.60000000,100,1,13.61000000,15,1,13.62000000,100,1,13.63000000,15,1,13.64000000,200,2,13.65000000,15,1,13.66000000,200,2,13.67000000,130,3,ARL,321500349
1546,2025-07-17T15:59:03.633093258Z,2025-07-17T15:59:03.632928023Z,160,2,1108,C,A,0,13.78000000,100,130,165235,268438149,13.55000000,10,1,13.54000000,100,1,13.38000000,33,1,13.37000000,100,1,13.31000000,10,1,13.30000000,100,1,13.29000000,20,2,13.28000000,111,3,13.27000000,120,3,13.26000000,304,5,13.40000000,208,12,13.59000000,15,1,13.60000000,100,1,13.61000000,15,1,13.62000000,100,1,13.63000000,15,1,13.64000000,200,2,13.65000000,15,1,13.66000000,200,2,13.67000000,130,3,ARL,321309865
1547,2025-07-17T15:59:03.649282063Z,2025-07-17T15:59:03.649116452Z,160,2,1108,C,A,0,14.11000000,100,130,165611,268438330,13.55000000,10,1,13.54000000,100,1,13.38000000,33,1,13.37000000,100,1,13.31000000,10,1,13.30000000,100,1,13.29000000,20,2,13.28000000,111,3,13.27000000,120,3,13.26000000,304,5,13.40000000,208,12,13.59000000,15,1,13.60000000,100,1,13.61000000,15,1,13.62000000,100,1,13.63000000,15,1,13.64000000,200,2,13.65000000,15,1,13.66000000,200,2,13.67000000,130,3,ARL,321114729
1548,2025-07-17T15:59:03.649332873Z,2025-07-17T15:59:03.649167617Z,160,2,1108,A,A,0,14.04000000,100,130,165256,268438331,13.55000000,10,1,13.54000000,100,1,13.38000000,33,1,13.37000000,100,1,13.31000000,10,1,13.30000000,100,1,13.29000000,20,2,13.28000000,111,3,13.27000000,120,3,13.26000000,304,5,13.40000000,208,12,13.59000000,15,1,13.60000000,100,1,13.61000000,15,1,13.62000000,100,1,13.63000000,15,1,13.64000000,200,2,13.65000000,15,1,13.66000000,200,2,13.67000000,130,3,ARL,321500957
1549,2025-07-17T15:59:04.224000805Z,2025-07-17T15:59:04.223835151Z,160,2,1108,C,A,0,13.79000000,100,0,165654,268447989,13.55000000,10,1,13.54000000,100,1,13.38000000,33,1,13.37000000,100,1,13.31000000,10,1,13.30000000,100,1,13.29000000,20,2,13.28000000,111,3,13.27000000,120,3,13.26000000,304,5,13.40000000,208,12,13.59000000,15,1,13.60000000,100,1,13.61000000,15,1,13.62000000,100,1,13.63000000,15,1,13.64000000,200,2,13.65000000,15,1,13.66000000,200,2,13.67000000,130,3,ARL,321364281
1550,2025-07-17T15:59:04.224000805Z,2025-07-17T15:59:04.223835151Z,160,2,1108,A,A,0,13.73000000,100,130,165654,268447989,13.55000000,10,1,13.54000000,100,1,13.38000000,33,1,13.37000000,100,1,13.31000000,10,1,13.30000000,100,1,13.29000000,20,2,13.28000000,111,3,13.27000000,120,3,13.26000000,304,5,13.40000000,208,12,13.59000000,15,1,13.60000000,100,1,13.61000000,15,1,13.62000000,100,1,13.63000000,15,1,13.64000000,200,2,13.65000000,15,1,13.66000000,200,2,13.67000000,130,3,ARL,321511377
1551,2025-07-17T15:59:04.224749333Z,2025-07-17T15:59:04.224583946Z,160,2,1108,C,A,0,14.83000000,100,0,165387,268448014,13.55000000,10,1,13.54000000,100,1,13.38000000,33,1,13.37000000,100,1,13.31000000,10,1,13.30000000,100,1,13.29000000,20,2,13.28000000,111,3,13.27000000,120,3,13.26000000,304,5,13.40000000,208,12,13.59000000,15,1,13.60000000,100,1,13.61000000,15,1,13.62000000,100,1,13.63000000,15,1,13.64000000,200,2,13.65000000,15,1,13.66000000,200,2,13.67000000,130,3,ARL,321500333
1552,2025-07-17T15:59:04.224749333Z,2025-07-17T15:59:04.224583946Z,160,2,1108,A,A,0,14.79000000,100,130,165387,268448014,13.55000000,10,1,13.54000000,100,1,13.38000000,33,1,13.37000000,100,1,13.31000000,10,1,13.30000000,100,1,13.29000000,20,2,13.28000000,111,3,13.27000000,120,3,13.26000000,304,5,13.40000000,208,12,13.59000000,15,1,13.60000000,100,1,13.61000000,15,1,13.62000000,100,1,13.63000000,15,1,13.64000000,200,2,13.65000000,15,1,13.66000000,200,2,13.67000000,130,3,ARL,321511477
1553,2025-07-17T15:59:04.799998642Z,2025-07-17T15:59:04.799833206Z,160,2,1108,C,A,0,13.72000000,15,130,165436,268457531,13.55000000,10,1,13.54000000,100,1,13.38000000,33,1,13.37000000,100,1,13.31000000,10,1,13.30000000,100,1,13.29000000,20,2,13.28000000,111,3,13.27000000,120,3,13.26000000,304,5,13.40000000,208,12,13.59000000,15,1,13.60000000,100,1,13.61000000,15,1,13.62000000,100,1,13.63000000,15,1,13.64000000,200,2,13.65000000,15,1,13.66000000,200,2,13.67000000,130,3,ARL,321500117
1554,2025-07-17T16:00:13.989937414Z,2025-07-17T16:00:13.989771852Z,160,2,1108,C,A,0,14.10000000,2,0,165562,269514876,13.55000000,10,1,13.54000000,100,1,13.38000000,33,1,13.37000000,100,1,13.31000000,10,1,13.30000000,100,1,13.29000000,20,2,13.28000000,111,3,13.27000000,120,3,13.26000000,304,5,13.40000000,208,12,13.59000000,15,1,13.60000000,100,1,13.61000000,15,1,13.62000000,100,1,13.63000000,15,1,13.64000000,200,2,13.65000000,15,1,13.66000000,200,2,13.67000000,130,3,ARL,316098525
1555,2025-07-17T16:00:13.989937414Z,2025-07-17T16:00:13.989771852Z,160,2,1108,A,A,0,14.01000000,2,130,165562,269514876,13.55000000,10,1,13.54000000,100,1,13.38000000,33,1,13.37000000,100,1,13.31000000,10,1,13.30000000,100,1,13.29000000,20,2,13.28000000,111,3,13.27000000,120,3,13.26000000,304,5,13.40000000,208,12,13.59000000,15,1,13.60000000,100,1,13.61000000,15,1,13.62000000,100,1,13.63000000,15,1,13.64000000,200,2,13.65000000,15,1,13.66000000,200,2,13.67000000,130,3,ARL,322898193
1556,2025-07-17T16:00:28.803015930Z,2025-07-17T16:00:28.802849928Z,160,2,1108,A,A,0,13.72000000,15,130,166002,269765653,13.55000000,10,1,13.54000000,100,1,13.38000000,33,1,13.37000000,100,1,13.31000000,10,1,13.30000000,100,1,13.29000000,20,2,13.28000000,111,3,13.27000000,120,3,13.26000000,304,5,13.40000000,208,12,13.59000000,15,1,13.60000000,100,1,13.61000000,15,1,13.62000000,100,1,13.63000000,15,1,13.64000000,200,2,13.65000000,15,1,13.66000000,200,2,13.67000000,130,3,ARL,323238809
1557,2025-07-17T16:00:32.549412616Z,2025-07-17T16:00:32.549247168Z,160,2,1108,A,A,0,13.74000000,100,130,165448,269878282,13.55000000,10,1,13.54000000,100,1,13.38000000,33,1,13.37000000,100,1,13.31000000,10,1,13.30000000,100,1,13.29000000,20,2,13.28000000,111,3,13.27000000,120,3,13.26000000,304,5,13.40000000,208,12,13.59000000,15,1,13.60000000,100,1,13.61000000,15,1,13.62000000,100,1,13.63000000,15,1,13.64000000,200,2,13.65000000,15,1,13.66000000,200,2,13.67000000,130,3,ARL,323370569
1558,2025-07-17T16:00:32.560989093Z,2025-07-17T16:00:32.560823786Z,160,2,1108,C,A,0,13.76000000,100,130,165307,269878639,13.55000000,10,1,13.54000000,100,1,13.38000000,33,1,13.37000000,100,1,13.31000000,10,1,13.30000000,100,1,13.29000000,20,2,13.28000000,111,3,13.27000000,120,3,13.26000000,304,5,13.40000000,208,12,13.59000000,15,1,13.60000000,100,1,13.61000000,15,1,13.62000000,100,1,13.63000000,15,1,13.64000000,200,2,13.65000000,15,1,13.66000000,200,2,13.67000000,130,3,ARL,321500317
1559,2025-07-17T16:00:35.513164458Z,2025-07-17T16:00:35.512999155Z,160,2,1108,A,A,0,13.69000000,15,130,165303,269940539,13.55000000,10,1,13.54000000,100,1,13.38000000,33,1,13.37000000,100,1,13.31000000,10,1,13.30000000,100,1,13.29000000,20,2,13.28000000,111,3,13.27000000,120,3,13.26000000,304,5,13.40000000,208,12,13.59000000,15,1,13.60000000,100,1,13.61000000,15,1,13.62000000,100,1,13.63000000,15,1,13.64000000,200,2,13.65000000,15,1,13.66000000,200,2,13.67000000,130,3,ARL,323455221
1560,2025-07-17T16:00:42.614229184Z,2025-07-17T16:00:42.614063415Z,160,2,1108,C,A,0,13.73000000,100,0,165769,270051089,13.55000000,10,1,13.54000000,100,1,13.38000000,33,1,13.37000000,100,1,13.31000000,10,1,13.30000000,100,1,13.29000000,20,2,13.28000000,111,3,13.27000000,120,3,13.26000000,304,5,13.40000000,208,12,13.59000000,15,1,13.60000000,100,1,13.61000000,15,1,13.62000000,100,1,13.63000000,15,1,13.64000000,200,2,13.65000000,15,1,13.66000000,200,2,13.67000000,130,3,ARL,321511377
1561,2025-07-17T16:00:42.614229184Z,2025-07-17T16:00:42.614063415Z,160,2,1108,A,A,0,13.70000000,100,130,165769,270051089,13.55000000,10,1,13.54000000,100,1,13.38000000,33,1,13.37000000,100,1,13.31000000,10,1,13.30000000,100,1,13.29000000,20,2,13.28000000,111,3,13.27000000,120,3,13.26000000,304,5,13.40000000,208,12,13.59000000,15,1,13.60000000,100,1,13.61000000,15,1,13.62000000,100,1,13.63000000,15,1,13.64000000,200,2,13.65000000,15,1,13.66000000,200,2,13.67000000,130,3,ARL,323599605
1562,2025-07-17T16:00:42.614254199Z,2025-07-17T16:00:42.614088947Z,160,2,1108,A,A,0,13.72000000,100,130,165252,270051090,13.55000000,10,1,13.54000000,100,1,13.38000000,33,1,13.37000000,100,1,13.31000000,10,1,13.30000000,100,1,13.29000000,20,2,13.28000000,111,3,13.27000000,120,3,13.26000000,304,5,13.40000000,208,12,13.59000000,15,1,13.60000000,100,1,13.61000000,15,1,13.62000000,100,1,13.63000000,15,1,13.64000000,200,2,13.65000000,15,1,13.66000000,200,2,13.67000000,130,3,ARL,323599609
1563,2025-07-17T16:00:42.614396214Z,2025-07-17T16:00:42.614231125Z,160,2,1108,C,A,0,13.74000000,100,130,165089,270051092,13.55000000,10,1,13.54000000,100,1,13.38000000,33,1,13.37000000,100,1,13.31000000,10,1,13.30000000,100,1,13.29000000,20,2,13.28000000,111,3,13.27000000,120,3,13.26000000,304,5,13.40000000,208,12,13.59000000,15,1,13.60000000,100,1,13.61000000,15,1,13.62000000,100,1,13.63000000,15,1,13.64000000,200,2,13.65000000,15,1,13.66000000,200,2,13.67000000,130,3,ARL,323370569
1564,2025-07-17T16:00:42.616178962Z,2025-07-17T16:00:42.616013371Z,160,2,1108,C,A,0,14.81000000,100,0,165591,270051093,13.55000000,10,1,13.54000000,100,1,13.38000000,33,1,13.37000000,100,1,13.31000000,10,1,13.30000000,100,1,13.29000000,20,2,13.28000000,111,3,13.27000000,120,3,13.26000000,304,5,13.40000000,208,12,13.59000000,15,1,13.60000000,100,1,13.61000000,15,1,13.62000000,100,1,13.63000000,15,1,13.64000000,200,2,13.65000000,15,1,13.66000000,200,2,13.67000000,130,3,ARL,321097197
1565,2025-07-17T16:00:42.616178962Z,2025-07-17T16:00:42.616013371Z,160,2,1108,A,A,0,14.66000000,100,130,165591,270051093,13.55000000,10,1,13.54000000,100,1,13.38000000,33,1,13.37000000,100,1,13.31000000,10,1,13.30000000,100,1,13.29000000,20,2,13.28000000,111,3,13.27000000,120,3,13.26000000,304,5,13.40000000,208,12,13.59000000,15,1,13.60000000,100,1,13.61000000,15,1,13.62000000,100,1,13.63000000,15,1,13.64000000,200,2,13.65000000,15,1,13.66000000,200,2,13.67000000,130,3,ARL,323599625
1566,2025-07-17T16:00:42.616321879Z,2025-07-17T16:00:42.616156310Z,160,2,1108,C,A,0,15.92000000,100,0,165569,270051094,13.55000000,10,1,13.54000000,100,1,13.38000000,33,1,13.37000000,100,1,13.31000000,10,1,13.30000000,100,1,13.29000000,20,2,13.28000000,111,3,13.27000000,120,3,13.26000000,304,5,13.40000000,208,12,13.59000000,15,1,13.60000000,100,1,13.61000000,15,1,13.62000000,100,1,13.63000000,15,1,13.64000000,200,2,13.65000000,15,1,13.66000000,200,2,13.67000000,130,3,ARL,321096889
1567,2025-07-17T16:00:42.616321879Z,2025-07-17T16:00:42.616156310Z,160,2,1108,A,A,0,15.76000000,100,130,165569,270051094,13.55000000,10,1,13.54000000,100,1,13.38000000,33,1,13.37000000,100,1,13.31000000,10,1,13.30000000,100,1,13.29000000,20,2,13.28000000,111,3,13.27000000,120,3,13.26000000,304,5,13.40000000,208,12,13.59000000,15,1,13.60000000,100,1,13.61000000,15,1,13.62000000,100,1,13.63000000,15,1,13.64000000,200,2,13.65000000,15,1,13.66000000,200,2,13.67000000,130,3,ARL,323599629
1568,2025-07-17T16:00:42.616352247Z,2025-07-17T16:00:42.616186901Z,160,2,1108,C,A,0,17.58000000,100,0,165346,270051095,13.55000000,10,1,13.54000000,100,1,13.38000000,33,1,13.37000000,100,1,13.31000000,10,1,13.30000000,100,1,13.29000000,20,2,13.28000000,111,3,13.27000000,120,3,13.26000000,304,5,13.40000000,208,12,13.59000000,15,1,13.60000000,100,1,13.61000000,15,1,13.62000000,100,1,13.63000000,15,1,13.64000000,200,2,13.65000000,15,1,13.66000000,200,2,13.67000000,130,3,ARL,321096825
1569,2025-07-17T16:00:42.616352247Z,2025-07-17T16:00:42.616186901Z,160,2,1108,A,A,0,17.40000000,100,130,165346,270051095,13.55000000,10,1,13.54000000,100,1,13.38000000,33,1,13.37000000,100,1,13.31000000,10,1,13.30000000,100,1,13.29000000,20,2,13.28000000,111,3,13.27000000,120,3,13.26000000,304,5,13.40000000,208,12,13.59000000,15,1,13.60000000,100,1,13.61000000,15,1,13.62000000,100,1,13.63000000,15,1,13.64000000,200,2,13.65000000,15,1,13.66000000,200,2,13.67000000,130,3,ARL,323599633
1570,2025-07-17T16:00:42.636761176Z,2025-07-17T16:00:42.636595817Z,160,2,1108,C,A,0,14.04000000,100,130,165359,270051179,13.55000000,10,1,13.54000000,100,1,13.38000000,33,1,13.37000000,100,1,13.31000000,10,1,13.30000000,100,1,13.29000000,20,2,13.28000000,111,3,13.27000000,120,3,13.26000000,304,5,13.40000000,208,12,13.59000000,15,1,13.60000000,100,1,13.61000000,15,1,13.62000000,100,1,13.63000000,15,1,13.64000000,200,2,13.65000000,15,1,13.66000000,200,2,13.67000000,130,3,ARL,321500957
1571,2025-07-17T16:00:42.636814704Z,2025-07-17T16:00:42.636649389Z,160,2,1108,A,A,0,13.97000000,100,130,165315,270051181,13.55000000,10,1,13.54000000,100,1,13.38000000,33,1,13.37000000,100,1,13.31000000,10,1,13.30000000,100,1,13.29000000,20,2,13.28000000,111,3,13.27000000,120,3,13.26000000,304,5,13.40000000,208,12,13.59000000,15,1,13.60000000,100,1,13.61000000,15,1,13.62000000,100,1,13.63000000,15,1,13.64000000,200,2,13.65000000,15,1,13.66000000,200,2,13.67000000,130,3,ARL,323599765
1572,2025-07-17T16:00:46.803262460Z,2025-07-17T16:00:46.803097192Z,160,2,1108,C,A,0,13.72000000,15,130,165268,270102799,13.55000000,10,1,13.54000000,100,1,13.38000000,33,1,13.37000000,100,1,13.31000000,10,1,13.30000000,100,1,13.29000000,20,2,13.28000000,111,3,13.27000000,120,3,13.26000000,304,5,13.40000000,208,12,13.59000000,15,1,13.60000000,100,1,13.61000000,15,1,13.62000000,100,1,13.63000000,15,1,13.64000000,200,2,13.65000000,15,1,13.66000000,200,2,13.67000000,130,3,ARL,323238809
1573,2025-07-17T16:00:49.255631264Z,2025-07-17T16:00:49.255465939Z,160,2,1108,A,A,0,13.66000000,15,130,165325,270140405,13.55000000,10,1,13.54000000,100,1,13.38000000,33,1,13.37000000,100,1,13.31000000,10,1,13.30000000,100,1,13.29000000,20,2,13.28000000,111,3,13.27000000,120,3,13.26000000,304,5,13.40000000,208,12,13.59000000,15,1,13.60000000,100,1,13.61000000,15,1,13.62000000,100,1,13.63000000,15,1,13.64000000,200,2,13.65000000,15,1,13.66000000,215,3,13.67000000,130,3,ARL,323720189
1574,2025-07-17T16:00:49.739644604Z,2025-07-17T16:00:49.739479408Z,160,2,1108,A,A,0,13.70000000,100,130,165196,270146528,13.55000000,10,1,13.54000000,100,1,13.38000000,33,1,13.37000000,100,1,13.31000000,10,1,13.30000000,100,1,13.29000000,20,2,13.28000000,111,3,13.27000000,120,3,13.26000000,304,5,13.40000000,208,12,13.59000000,15,1,13.60000000,100,1,13.61000000,15,1,13.62000000,100,1,13.63000000,15,1,13.64000000,200,2,13.65000000,15,1,13.66000000,215,3,13.67000000,130,3,ARL,323730309
1575,2025-07-17T16:00:49.745038261Z,2025-07-17T16:00:49.744872763Z,160,2,1108,C,A,0,13.70000000,100,0,165498,270146577,13.55000000,10,1,13.54000000,100,1,13.38000000,33,1,13.37000000,100,1,13.31000000,10,1,13.30000000,100,1,13.29000000,20,2,13.28000000,111,3,13.27000000,120,3,13.26000000,304,5,13.40000000,208,12,13.59000000,15,1,13.60000000,100,1,13.61000000,15,1,13.62000000,100,1,13.63000000,15,1,13.64000000,200,2,13.65000000,15,1,13.66000000,215,3,13.67000000,130,3,ARL,323599605
1576,2025-07-17T16:00:49.745038261Z,2025-07-17T16:00:49.744872763Z,160,2,1108,A,A,0,13.67000000,100,130,165498,270146577,13.55000000,10,1,13.54000000,100,1,13.38000000,33,1,13.37000000,100,1,13.31000000,10,1,13.30000000,100,1,13.29000000,20,2,13.28000000,111,3,13.27000000,120,3,13.26000000,304,5,13.40000000,208,12,13.59000000,15,1,13.60000000,100,1,13.61000000,15,1,13.62000000,100,1,13.63000000,15,1,13.64000000,200,2,13.65000000,15,1,13.66000000,215,3,13.67000000,230,4,ARL,323730353
1577,2025-07-17T16:00:49.745778725Z,2025-07-17T16:00:49.745613051Z,160,2,1108,C,A,0,14.79000000,100,0,165674,270146581,13.55000000,10,1,13.54000000,100,1,13.38000000,33,1,13.37000000,100,1,13.31000000,10,1,13.30000000,100,1,13.29000000,20,2,13.28000000,111,3,13.27000000,120,3,13.26000000,304,5,13.40000000,208,12,13.59000000,15,1,13.60000000,100,1,13.61000000,15,1,13.62000000,100,1,13.63000000,15,1,13.64000000,200,2,13.65000000,15,1,13.66000000,215,3,13.67000000,230,4,ARL,321511477
1578,2025-07-17T16:00:49.745778725Z,2025-07-17T16:00:49.745613051Z,160,2,1108,A,A,0,14.73000000,100,130,165674,270146581,13.55000000,10,1,13.54000000,100,1,13.38000000,33,1,13.37000000,100,1,13.31000000,10,1,13.30000000,100,1,13.29000000,20,2,13.28000000,111,3,13.27000000,120,3,13.26000000,304,5,13.40000000,208,12,13.59000000,15,1,13.60000000,100,1,13.61000000,15,1,13.62000000,100,1,13.63000000,15,1,13.64000000,200,2,13.65000000,15,1,13.66000000,215,3,13.67000000,230,4,ARL,323730369
1579,2025-07-17T16:00:49.746422142Z,2025-07-17T16:00:49.746256906Z,160,2,1108,C,A,0,13.72000000,100,130,165236,270146586,13.55000000,10,1,13.54000000,100,1,13.38000000,33,1,13.37000000,100,1,13.31000000,10,1,13.30000000,100,1,13.29000000,20,2,13.28000000,111,3,13.27000000,120,3,13.26000000,304,5,13.40000000,208,12,13.59000000,15,1,13.60000000,100,1,13.61000000,15,1,13.62000000,100,1,13.63000000,15,1,13.64000000,200,2,13.65000000,15,1,13.66000000,215,3,13.67000000,230,4,ARL,323599609
1580,2025-07-17T16:00:49.772631967Z,2025-07-17T16:00:49.772466772Z,160,2,1108,A,A,0,15.59000000,100,130,165195,270146838,13.55000000,10,1,13.54000000,100,1,13.38000000,33,1,13.37000000,100,1,13.31000000,10,1,13.30000000,100,1,13.29000000,20,2,13.28000000,111,3,13.27000000,120,3,13.26000000,304,5,13.40000000,208,12,13.59000000,15,1,13.60000000,100,1,13.61000000,15,1,13.62000000,100,1,13.63000000,15,1,13.64000000,200,2,13.65000000,15,1,13.66000000,215,3,13.67000000,230,4,ARL,323730697
1581,2025-07-17T16:00:49.772645303Z,2025-07-17T16:00:49.772479921Z,160,2,1108,C,A,0,15.86000000,100,130,165382,270146839,13.55000000,10,1,13.54000000,100,1,13.38000000,33,1,13.37000000,100,1,13.31000000,10,1,13.30000000,100,1,13.29000000,20,2,13.28000000,111,3,13.27000000,120,3,13.26000000,304,5,13.40000000,208,12,13.59000000,15,1,13.60000000,100,1,13.61000000,15,1,13.62000000,100,1,13.63000000,15,1,13.64000000,200,2,13.65000000,15,1,13.66000000,215,3,13.67000000,230,4,ARL,312771645
1582,2025-07-17T16:00:51.624811889Z,2025-07-17T16:00:51.624646272Z,160,2,1108,C,A,0,14.65000000,100,0,165617,270181394,13.55000000,10,1,13.54000000,100,1,13.38000000,33,1,13.37000000,100,1,13.31000000,10,1,13.30000000,100,1,13.29000000,20,2,13.28000000,111,3,13.27000000,120,3,13.26000000,304,5,13.40000000,208,12,13.59000000,15,1,13.60000000,100,1,13.61000000,15,1,13.62000000,100,1,13.63000000,15,1,13.64000000,200,2,13.65000000,15,1,13.66000000,215,3,13.67000000,230,4,ARL,321293737
1583,2025-07-17T16:00:51.624811889Z,2025-07-17T16:00:51.624646272Z,160,2,1108,A,A,0,14.54000000,100,130,165617,270181394,13.55000000,10,1,13.54000000,100,1,13.38000000,33,1,13.37000000,100,1,13.31000000,10,1,13.30000000,100,1,13.29000000,20,2,13.28000000,111,3,13.27000000,120,3,13.26000000,304,5,13.40000000,208,12,13.59000000,15,1,13.60000000,100,1,13.61000000,15,1,13.62000000,100,1,13.63000000,15,1,13.64000000,200,2,13.65000000,15,1,13.66000000,215,3,13.67000000,230,4,ARL,323775433
1584,2025-07-17T16:00:51.625372516Z,2025-07-17T16:00:51.625206675Z,160,2,1108,C,A,0,14.64000000,100,0,165841,270181399,13.55000000,10,1,13.54000000,100,1,13.38000000,33,1,13.37000000,100,1,13.31000000,10,1,13.30000000,100,1,13.29000000,20,2,13.28000000,111,3,13.27000000,120,3,13.26000000,304,5,13.40000000,208,12,13.59000000,15,1,13.60000000,100,1,13.61000000,15,1,13.62000000,100,1,13.63000000,15,1,13.64000000,200,2,13.65000000,15,1,13.66000000,215,3,13.67000000,230,4,ARL,321293741
1585,2025-07-17T16:00:51.625372516Z,2025-07-17T16:00:51.625206675Z,160,2,1108,A,A,0,14.53000000,100,130,165841,270181399,13.55000000,10,1,13.54000000,100,1,13.38000000,33,1,13.37000000,100,1,13.31000000,10,1,13.30000000,100,1,13.29000000,20,2,13.28000000,111,3,13.27000000,120,3,13.26000000,304,5,13.40000000,208,12,13.59000000,15,1,13.60000000,100,1,13.61000000,15,1,13.62000000,100,1,13.63000000,15,1,13.64000000,200,2,13.65000000,15,1,13.66000000,215,3,13.67000000,230,4,ARL,323775457
1586,2025-07-17T16:00:53.749335010Z,2025-07-17T16:00:53.749169565Z,160,2,1108,A,A,0,13.67000000,100,130,165445,270204567,13.55000000,10,1,13.54000000,100,1,13.38000000,33,1,13.37000000,100,1,13.31000000,10,1,13.30000000,100,1,13.29000000,20,2,13.28000000,111,3,13.27000000,120,3,13.26000000,304,5,13.40000000,208,12,13.59000000,15,1,13.60000000,100,1,13.61000000,15,1,13.62000000,100,1,13.63000000,15,1,13.64000000,200,2,13.65000000,15,1,13.66000000,215,3,13.67000000,330,5,ARL,323803301
1587,2025-07-17T16:00:53.755966680Z,2025-07-17T16:00:53.755801462Z,160,2,1108,C,A,0,13.70000000,100,130,165218,270204616,13.55000000,10,1,13.54000000,100,1,13.38000000,33,1,13.37000000,100,1,13.31000000,10,1,13.30000000,100,1,13.29000000,20,2,13.28000000,111,3,13.27000000,120,3,13.26000000,304,5,13.40000000,208,12,13.59000000,15,1,13.60000000,100,1,13.61000000,15,1,13.62000000,100,1,13.63000000,15,1,13.64000000,200,2,13.65000000,15,1,13.66000000,215,3,13.67000000,330,5,ARL,323730309
1588,2025-07-17T16:01:00.801342739Z,2025-07-17T16:01:00.801177403Z,160,2,1108,C,A,0,13.69000000,15,130,165336,270319932,13.55000000,10,1,13.54000000,100,1,13.38000000,33,1,13.37000000,100,1,13.31000000,10,1,13.30000000,100,1,13.29000000,20,2,13.28000000,111,3,13.27000000,120,3,13.26000000,304,5,13.40000000,208,12,13.59000000,15,1,13.60000000,100,1,13.61000000,15,1,13.62000000,100,1,13.63000000,15,1,13.64000000,200,2,13.65000000,15,1,13.66000000,215,3,13.67000000,330,5,ARL,323455221
1589,2025-07-17T16:01:10.802877570Z,2025-07-17T16:01:10.802712247Z,160,2,1108,A,A,0,13.62000000,15,130,165323,270493149,13.55000000,10,1,13.54000000,100,1,13.38000000,33,1,13.37000000,100,1,13.31000000,10,1,13.30000000,100,1,13.29000000,20,2,13.28000000,111,3,13.27000000,120,3,13.26000000,304,5,13.40000000,208,12,13.59000000,15,1,13.60000000,100,1,13.61000000,15,1,13.62000000,115,2,13.63000000,15,1,13.64000000,200,2,13.65000000,15,1,13.66000000,215,3,13.67000000,330,5,ARL,324161541
1590,2025-07-17T16:01:11.418837472Z,2025-07-17T16:01:11.418671671Z,160,2,1108,A,A,0,13.65000000,100,130,165801,270503944,13.55000000,10,1,13.54000000,100,1,13.38000000,33,1,13.37000000,100,1,13.31000000,10,1,13.30000000,100,1,13.29000000,20,2,13.28000000,111,3,13.27000000,120,3,13.26000000,304,5,13.40000000,208,12,13.59000000,15,1,13.60000000,100,1,13.61000000,15,1,13.62000000,115,2,13.63000000,15,1,13.64000000,200,2,13.65000000,115,2,13.66000000,215,3,13.67000000,330,5,ARL,324175569
1591,2025-07-17T16:01:11.425922184Z,2025-07-17T16:01:11.425757014Z,160,2,1108,C,A,0,13.67000000,100,130,165170,270504009,13.55000000,10,1,13.54000000,100,1,13.38000000,33,1,13.37000000,100,1,13.31000000,10,1,13.30000000,100,1,13.29000000,20,2,13.28000000,111,3,13.27000000,120,3,13.26000000,304,5,13.40000000,208,12,13.59000000,15,1,13.60000000,100,1,13.61000000,15,1,13.62000000,115,2,13.63000000,15,1,13.64000000,200,2,13.65000000,115,2,13.66000000,215,3,13.67000000,330,5,ARL,323803301
1592,2025-07-17T16:01:11.820753616Z,2025-07-17T16:01:11.820588141Z,160,2,1108,C,A,0,13.67000000,100,0,165475,270509970,13.55000000,10,1,13.54000000,100,1,13.38000000,33,1,13.37000000,100,1,13.31000000,10,1,13.30000000,100,1,13.29000000,20,2,13.28000000,111,3,13.27000000,120,3,13.26000000,304,5,13.40000000,208,12,13.59000000,15,1,13.60000000,100,1,13.61000000,15,1,13.62000000,115,2,13.63000000,15,1,13.64000000,200,2,13.65000000,115,2,13.66000000,215,3,13.67000000,330,5,ARL,323730353
1593,2025-07-17T16:01:11.820753616Z,2025-07-17T16:01:11.820588141Z,160,2,1108,A,A,0,13.63000000,100,130,165475,270509970,13.55000000,10,1,13.54000000,100,1,13.38000000,33,1,13.37000000,100,1,13.31000000,10,1,13.30000000,100,1,13.29000000,20,2,13.28000000,111,3,13.27000000,120,3,13.26000000,304,5,13.40000000,208,12,13.59000000,15,1,13.60000000,100,1,13.61000000,15,1,13.62000000,115,2,13.63000000,115,2,13.64000000,200,2,13.65000000,115,2,13.66000000,215,3,13.67000000,330,5,ARL,324186213
1594,2025-07-17T16:01:11.821515043Z,2025-07-17T16:01:11.821349600Z,160,2,1108,C,A,0,14.73000000,100,0,165443,270509983,13.55000000,10,1,13.54000000,100,1,13.38000000,33,1,13.37000000,100,1,13.31000000,10,1,13.30000000,100,1,13.29000000,20,2,13.28000000,111,3,13.27000000,120,3,13.26000000,304,5,13.40000000,208,12,13.59000000,15,1,13.60000000,100,1,13.61000000,15,1,13.62000000,115,2,13.63000000,115,2,13.64000000,200,2,13.65000000,115,2,13.66000000,215,3,13.67000000,330,5,ARL,323730369
1595,2025-07-17T16:01:11.821515043Z,2025-07-17T16:01:11.821349600Z,160,2,1108,A,A,0,14.69000000,100,130,165443,270509983,13.55000000,10,1,13.54000000,100,1,13.38000000,33,1,13.37000000,100,1,13.31000000,10,1,13.30000000,100,1,13.29000000,20,2,13.28000000,111,3,13.27000000,120,3,13.26000000,304,5,13.40000000,208,12,13.59000000,15,1,13.60000000,100,1,13.61000000,15,1,13.62000000,115,2,13.63000000,115,2,13.64000000,200,2,13.65000000,115,2,13.66000000,215,3,13.67000000,330,5,ARL,324186233
1596,2025-07-17T16:01:11.826399871Z,2025-07-17T16:01:11.826234488Z,160,2,1108,C,A,0,13.97000000,100,130,165383,270510142,13.55000000,10,1,13.54000000,100,1,13.38000000,33,1,13.37000000,100,1,13.31000000,10,1,13.30000000,100,1,13.29000000,20,2,13.28000000,111,3,13.27000000,120,3,13.26000000,304,5,13.40000000,208,12,13.59000000,15,1,13.60000000,100,1,13.61000000,15,1,13.62000000,115,2,13.63000000,115,2,13.64000000,200,2,13.65000000,115,2,13.66000000,215,3,13.67000000,330,5,ARL,323599765
1597,2025-07-17T16:01:11.826451447Z,2025-07-17T16:01:11.826286284Z,160,2,1108,A,A,0,13.90000000,100,130,165163,270510143,13.55000000,10,1,13.54000000,100,1,13.38000000,33,1,13.37000000,100,1,13.31000000,10,1,13.30000000,100,1,13.29000000,20,2,13.28000000,111,3,13.27000000,120,3,13.26000000,304,5,13.40000000,208,12,13.59000000,15,1,13.60000000,100,1,13.61000000,15,1,13.62000000,115,2,13.63000000,115,2,13.64000000,200,2,13.65000000,115,2,13.66000000,215,3,13.67000000,330,5,ARL,324186721
1598,2025-07-17T16:01:11.828630414Z,2025-07-17T16:01:11.828464891Z,160,2,1108,C,A,0,14.58000000,100,0,165523,270510182,13.55000000,10,1,13.54000000,100,1,13.38000000,33,1,13.37000000,100,1,13.31000000,10,1,13.30000000,100,1,13.29000000,20,2,13.28000000,111,3,13.27000000,120,3,13.26000000,304,5,13.40000000,208,12,13.59000000,15,1,13.60000000,100,1,13.61000000,15,1,13.62000000,115,2,13.63000000,115,2,13.64000000,200,2,13.65000000,115,2,13.66000000,215,3,13.67000000,330,5,ARL,321309941
1599,2025-07-17T16:01:11.828630414Z,2025-07-17T16:01:11.828464891Z,160,2,1108,A,A,0,14.43000000,100,130,165523,270510182,13.55000000,10,1,13.54000000,100,1,13.38000000,33,1,13.37000000,100,1,13.31000000,10,1,13.30000000,100,1,13.29000000,20,2,13.28000000,111,3,13.27000000,120,3,13.26000000,304,5,13.40000000,208,12,13.59000000,15,1,13.60000000,100,1,13.61000000,15,1,13.62000000,115,2,13.63000000,115,2,13.64000000,200,2,13.65000000,115,2,13.66000000,215,3,13.67000000,330,5,ARL,324186781
1600,2025-07-17T16:01:22.802518536Z,2025-07-17T16:01:22.802353061Z,160,2,1108,C,A,0,13.66000000,15,130,165475,270674903,13.55000000,10,1,13.54000000,100,1,13.38000000,33,1,13.37000000,100,1,13.31000000,10,1,13.30000000,100,1,13.29000000,20,2,13.28000000,111,3,13.27000000,120,3,13.26000000,304,5,13.40000000,208,12,13.59000000,15,1,13.60000000,100,1,13.61000000,15,1,13.62000000,115,2,13.63000000,115,2,13.64000000,200,2,13.65000000,115,2,13.66000000,215,3,13.67000000,330,5,ARL,323720189
1601,2025-07-17T16:01:32.804004639Z,2025-07-17T16:01:32.803839043Z,160,2,1108,A,A,0,13.60000000,15,130,165596,270824320,13.55000000,10,1,13.54000000,100,1,13.38000000,33,1,13.37000000,100,1,13.31000000,10,1,13.30000000,100,1,13.29000000,20,2,13.28000000,111,3,13.27000000,120,3,13.26000000,304,5,13.40000000,208,12,13.59000000,15,1,13.60000000,115,2,13.61000000,15,1,13.62000000,115,2,13.63000000,115,2,13.64000000,200,2,13.65000000,115,2,13.66000000,215,3,13.67000000,330,5,ARL,324619361
1602,2025-07-17T16:01:32.804274168Z,2025-07-17T16:01:32.804108576Z,160,2,1108,C,A,0,13.63000000,100,0,165592,270824323,13.55000000,10,1,13.54000000,100,1,13.38000000,33,1,13.37000000,100,1,13.31000000,10,1,13.30000000,100,1,13.29000000,20,2,13.28000000,111,3,13.27000000,120,3,13.26000000,304,5,13.40000000,208,12,13.59000000,15,1,13.60000000,115,2,13.61000000,15,1,13.62000000,115,2,13.63000000,115,2,13.64000000,200,2,13.65000000,115,2,13.66000000,215,3,13.67000000,330,5,ARL,324186213
1603,2025-07-17T16:01:32.804274168Z,2025-07-17T16:01:32.804108576Z,160,2,1108,A,A,0,13.61000000,100,130,165592,270824323,13.55000000,10,1,13.54000000,100,1,13.38000000,33,1,13.37000000,100,1,13.31000000,10,1,13.30000000,100,1,13.29000000,20,2,13.28000000,111,3,13.27000000,120,3,13.26000000,304,5,13.40000000,208,12,13.59000000,15,1,13.60000000,115,2,13.61000000,115,2,13.62000000,115,2,13.63000000,115,2,13.64000000,200,2,13.65000000,115,2,13.66000000,215,3,13.67000000,330,5,ARL,324619369
1604,2025-07-17T16:01:32.806299464Z,2025-07-17T16:01:32.806134020Z,160,2,1108,C,A,0,14.73000000,100,0,165444,270824400,13.55000000,10,1,13.54000000,100,1,13.38000000,33,1,13.37000000,100,1,13.31000000,10,1,13.30000000,100,1,13.29000000,20,2,13.28000000,111,3,13.27000000,120,3,13.26000000,304,5,13.40000000,208,12,13.59000000,15,1,13.60000000,115,2,13.61000000,115,2,13.62000000,115,2,13.63000000,115,2,13.64000000,200,2,13.65000000,115,2,13.66000000,215,3,13.67000000,330,5,ARL,321500349
1605,2025-07-17T16:01:32.806299464Z,2025-07-17T16:01:32.806134020Z,160,2,1108,A,A,0,14.57000000,100,130,165444,270824400,13.55000000,10,1,13.54000000,100,1,13.38000000,33,1,13.37000000,100,1,13.31000000,10,1,13.30000000,100,1,13.29000000,20,2,13.28000000,111,3,13.27000000,120,3,13.26000000,304,5,13.40000000,208,12,13.59000000,15,1,13.60000000,115,2,13.61000000,115,2,13.62000000,115,2,13.63000000,115,2,13.64000000,200,2,13.65000000,115,2,13.66000000,215,3,13.67000000,330,5,ARL,324619409
1606,2025-07-17T16:01:32.815913520Z,2025-07-17T16:01:32.815748258Z,160,2,1108,A,A,0,13.63000000,100,130,165262,270824657,13.55000000,10,1,13.54000000,100,1,13.38000000,33,1,13.37000000,100,1,13.31000000,10,1,13.30000000,100,1,13.29000000,20,2,13.28000000,111,3,13.27000000,120,3,13.26000000,304,5,13.40000000,208,12,13.59000000,15,1,13.60000000,115,2,13.61000000,115,2,13.62000000,115,2,13.63000000,215,3,13.64000000,200,2,13.65000000,115,2,13.66000000,215,3,13.67000000,330,5,ARL,324619837
1607,2025-07-17T16:01:32.822608966Z,2025-07-17T16:01:32.822443626Z,160,2,1108,C,A,0,13.65000000,100,130,165340,270824747,13.55000000,10,1,13.54000000,100,1,13.38000000,33,1,13.37000000,100,1,13.31000000,10,1,13.30000000,100,1,13.29000000,20,2,13.28000000,111,3,13.27000000,120,3,13.26000000,304,5,13.40000000,208,12,13.59000000,15,1,13.60000000,115,2,13.61000000,115,2,13.62000000,115,2,13.63000000,215,3,13.64000000,200,2,13.65000000,115,2,13.66000000,215,3,13.67000000,330,5,ARL,324175569
1608,2025-07-17T16:01:37.242690420Z,2025-07-17T16:01:37.242525208Z,160,2,1108,C,A,0,13.62000000,15,130,165212,270889017,13.55000000,10,1,13.54000000,100,1,13.38000000,33,1,13.37000000,100,1,13.31000000,10,1,13.30000000,100,1,13.29000000,20,2,13.28000000,111,3,13.27000000,120,3,13.26000000,304,5,13.40000000,208,12,13.59000000,15,1,13.60000000,115,2,13.61000000,115,2,13.62000000,115,2,13.63000000,215,3,13.64000000,200,2,13.65000000,115,2,13.66000000,215,3,13.67000000,330,5,ARL,324161541
1609,2025-07-17T16:01:40.605797765Z,2025-07-17T16:01:40.605632399Z,160,2,1108,A,A,0,13.61000000,100,130,165366,270946497,13.55000000,10,1,13.54000000,100,1,13.38000000,33,1,13.37000000,100,1,13.31000000,10,1,13.30000000,100,1,13.29000000,20,2,13.28000000,111,3,13.27000000,120,3,13.26000000,304,5,13.40000000,208,12,13.59000000,15,1,13.60000000,115,2,13.61000000,215,3,13.62000000,115,2,13.63000000,215,3,13.64000000,200,2,13.65000000,115,2,13.66000000,215,3,13.67000000,330,5,ARL,324782841
1610,2025-07-17T16:01:40.653738176Z,2025-07-17T16:01:40.653572805Z,160,2,1108,C,A,0,13.63000000,100,130,165371,270946779,13.55000000,10,1,13.54000000,100,1,13.38000000,33,1,13.37000000,100,1,13.31000000,10,1,13.30000000,100,1,13.29000000,20,2,13.28000000,111,3,13.27000000,120,3,13.26000000,304,5,13.40000000,208,12,13.59000000,15,1,13.60000000,115,2,13.61000000,215,3,13.62000000,115,2,13.63000000,215,3,13.64000000,200,2,13.65000000,115,2,13.66000000,215,3,13.67000000,330,5,ARL,324619837
1611,2025-07-17T16:01:47.565991684Z,2025-07-17T16:01:47.565825466Z,160,2,1108,A,A,0,13.57000000,15,128,166218,271062350,13.55000000,10,1,13.54000000,100,1,13.38000000,33,1,13.37000000,100,1,13.31000000,10,1,13.30000000,100,1,13.29000000,20,2,13.28000000,111,3,13.27000000,120,3,13.26000000,304,5,13.40000000,208,12,13.57000000,15,1,13.59000000,15,1,13.60000000,115,2,13.61000000,215,3,13.62000000,115,2,13.63000000,215,3,13.64000000,200,2,13.65000000,115,2,13.66000000,215,3,ARL,324934601
1612,2025-07-17T16:01:47.902969773Z,2025-07-17T16:01:47.902804446Z,160,2,1108,C,A,0,13.61000000,100,0,165327,271068098,13.55000000,10,1,13.54000000,100,1,13.38000000,33,1,13.37000000,100,1,13.31000000,10,1,13.30000000,100,1,13.29000000,20,2,13.28000000,111,3,13.27000000,120,3,13.26000000,304,5,13.40000000,208,12,13.57000000,15,1,13.59000000,15,1,13.60000000,115,2,13.61000000,215,3,13.62000000,115,2,13.63000000,215,3,13.64000000,200,2,13.65000000,115,2,13.66000000,215,3,ARL,324619369
1613,2025-07-17T16:01:47.902969773Z,2025-07-17T16:01:47.902804446Z,160,2,1108,A,A,0,13.58000000,100,130,165327,271068098,13.55000000,10,1,13.54000000,100,1,13.38000000,33,1,13.37000000,100,1,13.31000000,10,1,13.30000000,100,1,13.29000000,20,2,13.28000000,111,3,13.27000000,120,3,13.26000000,304,5,13.40000000,208,12,13.57000000,15,1,13.58000000,100,1,13.59000000,15,1,13.60000000,115,2,13.61000000,215,3,13.62000000,115,2,13.63000000,215,3,13.64000000,200,2,13.65000000,115,2,ARL,324942229
1614,2025-07-17T16:01:47.903711757Z,2025-07-17T16:01:47.903546622Z,160,2,1108,C,A,0,14.40000000,100,130,165135,271068105,13.55000000,10,1,13.54000000,100,1,13.38000000,33,1,13.37000000,100,1,13.31000000,10,1,13.30000000,100,1,13.29000000,20,2,13.28000000,111,3,13.27000000,120,3,13.26000000,304,5,13.40000000,208,12,13.57000000,15,1,13.58000000,100,1,13.59000000,15,1,13.60000000,115,2,13.61000000,215,3,13.62000000,115,2,13.63000000,215,3,13.64000000,200,2,13.65000000,115,2,ARL,289726421
1615,2025-07-17T16:01:47.903714323Z,2025-07-17T16:01:47.903548861Z,160,2,1108,C,A,0,14.69000000,100,0,165462,271068106,13.55000000,10,1,13.54000000,100,1,13.38000000,33,1,13.37000000,100,1,13.31000000,10,1,13.30000000,100,1,13.29000000,20,2,13.28000000,111,3,13.27000000,120,3,13.26000000,304,5,13.40000000,208,12,13.57000000,15,1,13.58000000,100,1,13.59000000,15,1,13.60000000,115,2,13.61000000,215,3,13.62000000,115,2,13.63000000,215,3,13.64000000,200,2,13.65000000,115,2,ARL,324186233
1616,2025-07-17T16:01:47.903714323Z,2025-07-17T16:01:47.903548861Z,160,2,1108,A,A,0,14.63000000,100,130,165462,271068106,13.55000000,10,1,13.54000000,100,1,13.38000000,33,1,13.37000000,100,1,13.31000000,10,1,13.30000000,100,1,13.29000000,20,2,13.28000000,111,3,13.27000000,120,3,13.26000000,304,5,13.40000000,208,12,13.57000000,15,1,13.58000000,100,1,13.59000000,15,1,13.60000000,115,2,13.61000000,215,3,13.62000000,115,2,13.63000000,215,3,13.64000000,200,2,13.65000000,115,2,ARL,324942257
1617,2025-07-17T16:01:47.904067686Z,2025-07-17T16:01:47.903902473Z,160,2,1108,A,A,0,14.19000000,100,130,165213,271068115,13.55000000,10,1,13.54000000,100,1,13.38000000,33,1,13.37000000,100,1,13.31000000,10,1,13.30000000,100,1,13.29000000,20,2,13.28000000,111,3,13.27000000,120,3,13.26000000,304,5,13.40000000,208,12,13.57000000,15,1,13.58000000,100,1,13.59000000,15,1,13.60000000,115,2,13.61000000,215,3,13.62000000,115,2,13.63000000,215,3,13.64000000,200,2,13.65000000,115,2,ARL,324942273
1618,2025-07-17T16:01:47.905355779Z,2025-07-17T16:01:47.905189816Z,160,2,1108,C,A,0,15.23000000,100,0,165963,271068134,13.55000000,10,1,13.54000000,100,1,13.38000000,33,1,13.37000000,100,1,13.31000000,10,1,13.30000000,100,1,13.29000000,20,2,13.28000000,111,3,13.27000000,120,3,13.26000000,304,5,13.40000000,208,12,13.57000000,15,1,13.58000000,100,1,13.59000000,15,1,13.60000000,115,2,13.61000000,215,3,13.62000000,115,2,13.63000000,215,3,13.64000000,200,2,13.65000000,115,2,ARL,282776017
1619,2025-07-17T16:01:47.905355779Z,2025-07-17T16:01:47.905189816Z,160,2,1108,A,A,0,14.94000000,100,130,165963,271068134,13.55000000,10,1,13.54000000,100,1,13.38000000,33,1,13.37000000,100,1,13.31000000,10,1,13.30000000,100,1,13.29000000,20,2,13.28000000,111,3,13.27000000,120,3,13.26000000,304,5,13.40000000,208,12,13.57000000,15,1,13.58000000,100,1,13.59000000,15,1,13.60000000,115,2,13.61000000,215,3,13.62000000,115,2,13.63000000,215,3,13.64000000,200,2,13.65000000,115,2,ARL,324942277
1620,2025-07-17T16:01:47.909479724Z,2025-07-17T16:01:47.909314303Z,160,2,1108,C,A,0,17.40000000,100,0,165421,271068173,13.55000000,10,1,13.54000000,100,1,13.38000000,33,1,13.37000000,100,1,13.31000000,10,1,13.30000000,100,1,13.29000000,20,2,13.28000000,111,3,13.27000000,120,3,13.26000000,304,5,13.40000000,208,12,13.57000000,15,1,13.58000000,100,1,13.59000000,15,1,13.60000000,115,2,13.61000000,215,3,13.62000000,115,2,13.63000000,215,3,13.64000000,200,2,13.65000000,115,2,ARL,323599633
1621,2025-07-17T16:01:47.909479724Z,2025-07-17T16:01:47.909314303Z,160,2,1108,A,A,0,17.25000000,100,130,165421,271068173,13.55000000,10,1,13.54000000,100,1,13.38000000,33,1,13.37000000,100,1,13.31000000,10,1,13.30000000,100,1,13.29000000,20,2,13.28000000,111,3,13.27000000,120,3,13.26000000,304,5,13.40000000,208,12,13.57000000,15,1,13.58000000,100,1,13.59000000,15,1,13.60000000,115,2,13.61000000,215,3,13.62000000,115,2,13.63000000,215,3,13.64000000,200,2,13.65000000,115,2,ARL,324942361
1622,2025-07-17T16:01:50.799100504Z,2025-07-17T16:01:50.798934838Z,160,2,1108,A,A,0,13.59000000,100,130,165666,271131418,13.55000000,10,1,13.54000000,100,1,13.38000000,33,1,13.37000000,100,1,13.31000000,10,1,13.30000000,100,1,13.29000000,20,2,13.28000000,111,3,13.27000000,120,3,13.26000000,304,5,13.40000000,208,12,13.57000000,15,1,13.58000000,100,1,13.59000000,115,2,13.60000000,115,2,13.61000000,215,3,13.62000000,115,2,13.63000000,215,3,13.64000000,200,2,13.65000000,115,2,ARL,325022101
1623,2025-07-17T16:01:50.805653961Z,2025-07-17T16:01:50.805488726Z,160,2,1108,C,A,0,13.61000000,100,130,165235,271131583,13.55000000,10,1,13.54000000,100,1,13.38000000,33,1,13.37000000,100,1,13.31000000,10,1,13.30000000,100,1,13.29000000,20,2,13.28000000,111,3,13.27000000,120,3,13.26000000,304,5,13.40000000,208,12,13.57000000,15,1,13.58000000,100,1,13.59000000,115,2,13.60000000,115,2,13.61000000,215,3,13.62000000,115,2,13.63000000,215,3,13.64000000,200,2,13.65000000,115,2,ARL,324782841
1624,2025-07-17T16:01:52.133063761Z,2025-07-17T16:01:52.132898568Z,160,2,1108,C,A,0,13.60000000,15,130,165193,271153294,13.55000000,10,1,13.54000000,100,1,13.38000000,33,1,13.37000000,100,1,13.31000000,10,1,13.30000000,100,1,13.29000000,20,2,13.28000000,111,3,13.27000000,120,3,13.26000000,304,5,13.40000000,208,12,13.57000000,15,1,13.58000000,100,1,13.59000000,115,2,13.60000000,115,2,13.61000000,215,3,13.62000000,115,2,13.63000000,215,3,13.64000000,200,2,13.65000000,115,2,ARL,324619361
1625,2025-07-17T16:01:53.137501962Z,2025-07-17T16:01:53.137336077Z,160,2,1108,A,A,0,13.55000000,15,130,165885,271200452,13.55000000,10,1,13.54000000,100,1,13.38000000,33,1,13.37000000,100,1,13.31000000,10,1,13.30000000,100,1,13.29000000,20,2,13.28000000,111,3,13.27000000,120,3,13.26000000,304,5,13.40000000,208,12,13.55000000,15,1,13.57000000,15,1,13.58000000,100,1,13.59000000,115,2,13.60000000,115,2,13.61000000,215,3,13.62000000,115,2,13.63000000,215,3,13.64000000,200,2,ARL,325109165
1626,2025-07-17T16:01:56.264154095Z,2025-07-17T16:01:56.263988198Z,160,2,1108,C,A,0,13.58000000,100,0,165897,271251019,13.55000000,10,1,13.54000000,100,1,13.38000000,33,1,13.37000000,100,1,13.31000000,10,1,13.30000000,100,1,13.29000000,20,2,13.28000000,111,3,13.27000000,120,3,13.26000000,304,5,13.40000000,208,12,13.55000000,15,1,13.57000000,15,1,13.58000000,100,1,13.59000000,115,2,13.60000000,115,2,13.61000000,215,3,13.62000000,115,2,13.63000000,215,3,13.64000000,200,2,ARL,324942229
1627,2025-07-17T16:01:56.264154095Z,2025-07-17T16:01:56.263988198Z,160,2,1108,A,A,0,13.56000000,100,130,165897,271251019,13.55000000,10,1,13.54000000,100,1,13.38000000,33,1,13.37000000,100,1,13.31000000,10,1,13.30000000,100,1,13.29000000,20,2,13.28000000,111,3,13.27000000,120,3,13.26000000,304,5,13.40000000,208,12,13.55000000,15,1,13.56000000,100,1,13.57000000,15,1,13.58000000,100,1,13.59000000,115,2,13.60000000,115,2,13.61000000,215,3,13.62000000,115,2,13.63000000,215,3,ARL,325176181
1628,2025-07-17T16:01:56.269623788Z,2025-07-17T16:01:56.269458197Z,160,2,1108,C,A,0,13.90000000,100,130,165591,271251357,13.55000000,10,1,13.54000000,100,1,13.38000000,33,1,13.37000000,100,1,13.31000000,10,1,13.30000000,100,1,13.29000000,20,2,13.28000000,111,3,13.27000000,120,3,13.26000000,304,5,13.40000000,208,12,13.55000000,15,1,13.56000000,100,1,13.57000000,15,1,13.58000000,100,1,13.59000000,115,2,13.60000000,115,2,13.61000000,215,3,13.62000000,115,2,13.63000000,215,3,ARL,324186721
1629,2025-07-17T16:01:56.269674232Z,2025-07-17T16:01:56.269508928Z,160,2,1108,A,A,0,13.83000000,100,130,165304,271251358,13.55000000,10,1,13.54000000,100,1,13.38000000,33,1,13.37000000,100,1,13.31000000,10,1,13.30000000,100,1,13.29000000,20,2,13.28000000,111,3,13.27000000,120,3,13.26000000,304,5,13.40000000,208,12,13.55000000,15,1,13.56000000,100,1,13.57000000,15,1,13.58000000,100,1,13.59000000,115,2,13.60000000,115,2,13.61000000,215,3,13.62000000,115,2,13.63000000,215,3,ARL,325176373
1630,2025-07-17T16:01:56.272340730Z,2025-07-17T16:01:56.272175169Z,160,2,1108,C,A,0,15.76000000,100,0,165561,271251490,13.55000000,10,1,13.54000000,100,1,13.38000000,33,1,13.37000000,100,1,13.31000000,10,1,13.30000000,100,1,13.29000000,20,2,13.28000000,111,3,13.27000000,120,3,13.26000000,304,5,13.40000000,208,12,13.55000000,15,1,13.56000000,100,1,13.57000000,15,1,13.58000000,100,1,13.59000000,115,2,13.60000000,115,2,13.61000000,215,3,13.62000000,115,2,13.63000000,215,3,ARL,323599629
1631,2025-07-17T16:01:56.272340730Z,2025-07-17T16:01:56.272175169Z,160,2,1108,A,A,0,15.60000000,100,130,165561,271251490,13.55000000,10,1,13.54000000,100,1,13.38000000,33,1,13.37000000,100,1,13.31000000,10,1,13.30000000,100,1,13.29000000,20,2,13.28000000,111,3,13.27000000,120,3,13.26000000,304,5,13.40000000,208,12,13.55000000,15,1,13.56000000,100,1,13.57000000,15,1,13.58000000,100,1,13.59000000,115,2,13.60000000,115,2,13.61000000,215,3,13.62000000,115,2,13.63000000,215,3,ARL,325176677
1632,2025-07-17T16:01:56.300889378Z,2025-07-17T16:01:56.300723805Z,160,2,1108,C,A,0,14.66000000,100,0,165573,271252044,13.55000000,10,1,13.54000000,100,1,13.38000000,33,1,13.37000000,100,1,13.31000000,10,1,13.30000000,100,1,13.29000000,20,2,13.28000000,111,3,13.27000000,120,3,13.26000000,304,5,13.40000000,208,12,13.55000000,15,1,13.56000000,100,1,13.57000000,15,1,13.58000000,100,1,13.59000000,115,2,13.60000000,115,2,13.61000000,215,3,13.62000000,115,2,13.63000000,215,3,ARL,323599625
1633,2025-07-17T16:01:56.300889378Z,2025-07-17T16:01:56.300723805Z,160,2,1108,A,A,0,14.51000000,100,130,165573,271252044,13.55000000,10,1,13.54000000,100,1,13.38000000,33,1,13.37000000,100,1,13.31000000,10,1,13.30000000,100,1,13.29000000,20,2,13.28000000,111,3,13.27000000,120,3,13.26000000,304,5,13.40000000,208,12,13.55000000,15,1,13.56000000,100,1,13.57000000,15,1,13.58000000,100,1,13.59000000,115,2,13.60000000,115,2,13.61000000,215,3,13.62000000,115,2,13.63000000,215,3,ARL,325177757
1634,2025-07-17T16:01:56.776980244Z,2025-07-17T16:01:56.776814001Z,160,2,1108,T,N,0,13.41000000,16,130,166243,271255700,13.55000000,10,1,13.54000000,100,1,13.38000000,33,1,13.37000000,100,1,13.31000000,10,1,13.30000000,100,1,13.29000000,20,2,13.28000000,111,3,13.27000000,120,3,13.26000000,304,5,13.40000000,208,12,13.55000000,15,1,13.56000000,100,1,13.57000000,15,1,13.58000000,100,1,13.59000000,115,2,13.60000000,115,2,13.61000000,215,3,13.62000000,115,2,13.63000000,215,3,ARL,0
1635,2025-07-17T16:01:56.777414332Z,2025-07-17T16:01:56.777248616Z,160,2,1108,T,N,0,13.41000000,16,130,165716,271255708,13.55000000,10,1,13.54000000,100,1,13.38000000,33,1,13.37000000,100,1,13.31000000,10,1,13.30000000,100,1,13.29000000,20,2,13.28000000,111,3,13.27000000,120,3,13.26000000,304,5,13.40000000,208,12,13.55000000,15,1,13.56000000,100,1,13.57000000,15,1,13.58000000,100,1,13.59000000,115,2,13.60000000,115,2,13.61000000,215,3,13.62000000,115,2,13.63000000,215,3,ARL,0
1636,2025-07-17T16:01:56.777906069Z,2025-07-17T16:01:56.777739254Z,160,2,1108,T,N,0,13.41000000,4,130,166815,271255712,13.55000000,10,1,13.54000000,100,1,13.38000000,33,1,13.37000000,100,1,13.31000000,10,1,13.30000000,100,1,13.29000000,20,2,13.28000000,111,3,13.27000000,120,3,13.26000000,304,5,13.40000000,208,12,13.55000000,15,1,13.56000000,100,1,13.57000000,15,1,13.58000000,100,1,13.59000000,115,2,13.60000000,115,2,13.61000000,215,3,13.62000000,115,2,13.63000000,215,3,ARL,0
1637,2025-07-17T16:02:01.992544607Z,2025-07-17T16:02:01.992379223Z,160,2,1108,C,A,0,14.01000000,2,0,165384,271343251,13.55000000,10,1,13.54000000,100,1,13.38000000,33,1,13.37000000,100,1,13.31000000,10,1,13.30000000,100,1,13.29000000,20,2,13.28000000,111,3,13.27000000,120,3,13.26000000,304,5,13.40000000,208,12,13.55000000,15,1,13.56000000,100,1,13.57000000,15,1,13.58000000,100,1,13.59000000,115,2,13.60000000,115,2,13.61000000,215,3,13.62000000,115,2,13.63000000,215,3,ARL,322898193
1638,2025-07-17T16:02:01.992544607Z,2025-07-17T16:02:01.992379223Z,160,2,1108,A,A,0,13.92000000,2,130,165384,271343251,13.55000000,10,1,13.54000000,100,1,13.38000000,33,1,13.37000000,100,1,13.31000000,10,1,13.30000000,100,1,13.29000000,20,2,13.28000000,111,3,13.27000000,120,3,13.26000000,304,5,13.40000000,208,12,13.55000000,15,1,13.56000000,100,1,13.57000000,15,1,13.58000000,100,1,13.59000000,115,2,13.60000000,115,2,13.61000000,215,3,13.62000000,115,2,13.63000000,215,3,ARL,325297093
1639,2025-07-17T16:02:03.207720826Z,2025-07-17T16:02:03.207555626Z,160,2,1108,C,A,0,13.57000000,15,130,165200,271367066,13.55000000,10,1,13.54000000,100,1,13.38000000,33,1,13.37000000,100,1,13.31000000,10,1,13.30000000,100,1,13.29000000,20,2,13.28000000,111,3,13.27000000,120,3,13.26000000,304,5,13.40000000,208,12,13.55000000,15,1,13.56000000,100,1,13.57000000,15,1,13.58000000,100,1,13.59000000,115,2,13.60000000,115,2,13.61000000,215,3,13.62000000,115,2,13.63000000,215,3,ARL,324934601
1640,2025-07-17T16:02:04.212956339Z,2025-07-17T16:02:04.212791108Z,160,2,1108,A,A,0,13.53000000,15,130,165231,271415821,13.55000000,10,1,13.54000000,100,1,13.38000000,33,1,13.37000000,100,1,13.31000000,10,1,13.30000000,100,1,13.29000000,20,2,13.28000000,111,3,13.27000000,120,3,13.26000000,304,5,13.40000000,208,12,13.53000000,15,1,13.55000000,15,1,13.56000000,100,1,13.57000000,15,1,13.58000000,100,1,13.59000000,115,2,13.60000000,115,2,13.61000000,215,3,13.62000000,115,2,ARL,325382429
1641,2025-07-17T16:02:04.214348814Z,2025-07-17T16:02:04.214183279Z,160,2,1108,C,A,0,14.54000000,100,0,165535,271415834,13.55000000,10,1,13.54000000,100,1,13.38000000,33,1,13.37000000,100,1,13.31000000,10,1,13.30000000,100,1,13.29000000,20,2,13.28000000,111,3,13.27000000,120,3,13.26000000,304,5,13.40000000,208,12,13.53000000,15,1,13.55000000,15,1,13.56000000,100,1,13.57000000,15,1,13.58000000,100,1,13.59000000,115,2,13.60000000,115,2,13.61000000,215,3,13.62000000,115,2,ARL,323775433
1642,2025-07-17T16:02:04.214348814Z,2025-07-17T16:02:04.214183279Z,160,2,1108,A,A,0,14.43000000,100,130,165535,271415834,13.55000000,10,1,13.54000000,100,1,13.38000000,33,1,13.37000000,100,1,13.31000000,10,1,13.30000000,100,1,13.29000000,20,2,13.28000000,111,3,13.27000000,120,3,13.26000000,304,5,13.40000000,208,12,13.53000000,15,1,13.55000000,15,1,13.56000000,100,1,13.57000000,15,1,13.58000000,100,1,13.59000000,115,2,13.60000000,115,2,13.61000000,215,3,13.62000000,115,2,ARL,325382437
1643,2025-07-17T16:02:04.840132668Z,2025-07-17T16:02:04.839967173Z,160,2,1108,C,A,0,13.56000000,100,0,165495,271432190,13.55000000,10,1,13.54000000,100,1,13.38000000,33,1,13.37000000,100,1,13.31000000,10,1,13.30000000,100,1,13.29000000,20,2,13.28000000,111,3,13.27000000,120,3,13.26000000,304,5,13.40000000,208,12,13.53000000,15,1,13.55000000,15,1,13.56000000,100,1,13.57000000,15,1,13.58000000,100,1,13.59000000,115,2,13.60000000,115,2,13.61000000,215,3,13.62000000,115,2,ARL,325176181
1644,2025-07-17T16:02:04.840132668Z,2025-07-17T16:02:04.839967173Z,160,2,1108,A,A,0,13.54000000,100,130,165495,271432190,13.55000000,10,1,13.54000000,100,1,13.38000000,33,1,13.37000000,100,1,13.31000000,10,1,13.30000000,100,1,13.29000000,20,2,13.28000000,111,3,13.27000000,120,3,13.26000000,304,5,13.40000000,208,12,13.53000000,15,1,13.54000000,100,1,13.55000000,15,1,13.56000000,100,1,13.57000000,15,1,13.58000000,100,1,13.59000000,115,2,13.60000000,115,2,13.61000000,215,3,ARL,325400045
1645,2025-07-17T16:02:04.840171240Z,2025-07-17T16:02:04.840006082Z,160,2,1108,A,A,0,14.27000000,700,130,165158,271432192,13.55000000,10,1,13.54000000,100,1,13.38000000,33,1,13.37000000,100,1,13.31000000,10,1,13.30000000,100,1,13.29000000,20,2,13.28000000,111,3,13.27000000,120,3,13.26000000,304,5,13.40000000,208,12,13.53000000,15,1,13.54000000,100,1,13.55000000,15,1,13.56000000,100,1,13.57000000,15,1,13.58000000,100,1,13.59000000,115,2,13.60000000,115,2,13.61000000,215,3,ARL,325400053
1646,2025-07-17T16:02:04.840210880Z,2025-07-17T16:02:04.840045694Z,160,2,1108,C,A,0,14.68000000,700,130,165186,271432193,13.55000000,10,1,13.54000000,100,1,13.38000000,33,1,13.37000000,100,1,13.31000000,10,1,13.30000000,100,1,13.29000000,20,2,13.28000000,111,3,13.27000000,120,3,13.26000000,304,5,13.40000000,208,12,13.53000000,15,1,13.54000000,100,1,13.55000000,15,1,13.56000000,100,1,13.57000000,15,1,13.58000000,100,1,13.59000000,115,2,13.60000000,115,2,13.61000000,215,3,ARL,283592941
1647,2025-07-17T16:02:04.840877603Z,2025-07-17T16:02:04.840711803Z,160,2,1108,C,A,0,14.63000000,100,0,165800,271432231,13.55000000,10,1,13.54000000,100,1,13.38000000,33,1,13.37000000,100,1,13.31000000,10,1,13.30000000,100,1,13.29000000,20,2,13.28000000,111,3,13.27000000,120,3,13.26000000,304,5,13.40000000,208,12,13.53000000,15,1,13.54000000,100,1,13.55000000,15,1,13.56000000,100,1,13.57000000,15,1,13.58000000,100,1,13.59000000,115,2,13.60000000,115,2,13.61000000,215,3,ARL,324942257
1648,2025-07-17T16:02:04.840877603Z,2025-07-17T16:02:04.840711803Z,160,2,1108,A,A,0,14.59000000,100,130,165800,271432231,13.55000000,10,1,13.54000000,100,1,13.38000000,33,1,13.37000000,100,1,13.31000000,10,1,13.30000000,100,1,13.29000000,20,2,13.28000000,111,3,13.27000000,120,3,13.26000000,304,5,13.40000000,208,12,13.53000000,15,1,13.54000000,100,1,13.55000000,15,1,13.56000000,100,1,13.57000000,15,1,13.58000000,100,1,13.59000000,115,2,13.60000000,115,2,13.61000000,215,3,ARL,325400105
1649,2025-07-17T16:02:11.249291142Z,2025-07-17T16:02:11.249125653Z,160,2,1108,C,A,0,14.53000000,100,0,165489,271526467,13.55000000,10,1,13.54000000,100,1,13.38000000,33,1,13.37000000,100,1,13.31000000,10,1,13.30000000,100,1,13.29000000,20,2,13.28000000,111,3,13.27000000,120,3,13.26000000,304,5,13.40000000,208,12,13.53000000,15,1,13.54000000,100,1,13.55000000,15,1,13.56000000,100,1,13.57000000,15,1,13.58000000,100,1,13.59000000,115,2,13.60000000,115,2,13.61000000,215,3,ARL,323775457
1650,2025-07-17T16:02:11.249291142Z,2025-07-17T16:02:11.249125653Z,160,2,1108,A,A,0,14.42000000,100,130,165489,271526467,13.55000000,10,1,13.54000000,100,1,13.38000000,33,1,13.37000000,100,1,13.31000000,10,1,13.30000000,100,1,13.29000000,20,2,13.28000000,111,3,13.27000000,120,3,13.26000000,304,5,13.40000000,208,12,13.53000000,15,1,13.54000000,100,1,13.55000000,15,1,13.56000000,100,1,13.57000000,15,1,13.58000000,100,1,13.59000000,115,2,13.60000000,115,2,13.61000000,215,3,ARL,325520705
1651,2025-07-17T16:02:15.062774661Z,2025-07-17T16:02:15.062605521Z,160,2,1108,C,A,0,13.53000000,15,128,169140,271576282,13.55000000,10,1,13.54000000,100,1,13.38000000,33,1,13.37000000,100,1,13.31000000,10,1,13.30000000,100,1,13.29000000,20,2,13.28000000,111,3,13.27000000,120,3,13.26000000,304,5,13.40000000,208,12,13.53000000,15,1,13.54000000,100,1,13.55000000,15,1,13.56000000,100,1,13.57000000,15,1,13.58000000,100,1,13.59000000,115,2,13.60000000,115,2,13.61000000,215,3,ARL,325382429
